Workbook

Sheet _Données Employés
B4: Matricule | C4: Civilité | D4: Nom | E4: Prénom | F4: Département | G4: Poste | H4: Salaire Base (FCFA)
B5: EMP-001 | C5: M. | D5: Nganou | E5: Clarisse | F5: Cuisine & Restauration | G5: Chef cuisinier | H5: 450000
B6: EMP-002 | C6: M. | D6: Tchinda | E6: Armand | F6: Réception & Front Office | G6: Réceptionniste | H6: 220000
B7: EMP-003 | C7: Mme | D7: Fotso | E7: Marguerite | F7: Finance & Comptabilité | G7: Comptable senior | H7: 380000
B8: EMP-004 | C8: M. | D8: Nkoulou | E8: Mbarga | F8: Étage & Housekeeping | G8: Gouvernant | H8: 195000
B9: EMP-005 | C9: M. | D9: Kamga | E9: Paul | F9: Maintenance | G9: Technicien maintenance | H9: 165000
B10: EMP-006 | C10: Mme | D10: Ngo | E10: Delphine | F10: Service Client | G10: Conseiller clientèle | H10: 160000
B11: EMP-007 | C11: M. | D11: Essomba | E11: Serge | F11: Maintenance | G11: Agent entretien | H11: 130000
B12: EMP-008 | C12: M. | D12: Tchouankou | E12: Paul | F12: Commercial | G12: Commercial | H12: 150000
B13: EMP-009 | C13: M. | D13: Fokam | E13: Eric | F13: Maintenance | G13: Technicien | H13: 140000
B14: EMP-010 | C14: M. | D14: Tagne | E14: René | F14: Cuisine & Restauration | G14: Plongeur | H14: 90000
B15: EMP-011 | C15: M. | D15: Bouba | E15: Ahmed | F15: Sécurité | G15: Agent Sécurité | H15: 120000
B16: EMP-012 | C16: Mme | D16: Awa | E16: Fatou | F16: Réception & Front Office | G16: Standardiste | H16: 155000
... B18: EMP-029 | C18: M. | D18: Kamga | E18: Patrice | F18: Sécurité | G18: Chef Sécurité | H18: 210000

Sheet 1-Tableau de Bord
B2: DOMAINE 9 — SANTE, SECURITE & CONDITIONS DE TRAVAIL
B3: TABLEAU DE BORD — Vue synthetique de tous les indicateurs du domaine (mis a jour automatiquement)
B5: Accidents travail | E5: Jours arret total | H5: Maladies prof. | K5: Visites medicales
B6: =COUNTA('5-Accidents du Travail'!B5:B104) | E6: =SUM('5-Accidents du Travail'!M5:M104) | H6: =COUNTA('6-Maladies Prof.'!B5:B104) | K6: =COUNTA('7-Visites Medicales'!B5:B104)
B9: Risques eleves | E9: Actions securite en cours | H9: EPI a remplacer | K9: Audits realises
B10: =COUNTIF('3-Evaluations des Risques'!H5:H104,"Eleve")+COUNTIF('3-Evaluations des Risques'!H5:H104,"Tres eleve")+COUNTIF('3-Evaluations des Risques'!H5:H104,"Critique") | E10: =COUNTIF('4-Plan Action Securite'!L5:L104,"En cours") | H10: =COUNTIF('9-Gestion EPI'!L5:L104,"A remplacer") | K10: =COUNTIF('11-Audit Inspection Secur.'!L5:L104,"Valide")
B13: Formations securite | E13: Cout AT (FCFA) | H13: Actions correct. SST | K13: Evenements incendie
B14: =COUNTIF('17-Formation Securite'!B5:B104,"<>") | E14: =SUM('5-Accidents du Travail'!M5:M104)*1500 | H14: =COUNTIF('18-Actions Correct. SST'!B5:B104,"<>") | K14: =COUNTIF('16-Registre Incendie'!B5:B104,"<>")
B18: ACCIDENTS PAR MOIS & RISQUES PAR TYPE
B19: Mois | C19: Nb Accidents
B20: Janv. | C20: =IFERROR(VLOOKUP("Janvier",'12-Suivi AT par Mois'!C5:E104,3,FALSE),0)
B21: Fevr. | C21: =IFERROR(VLOOKUP("Fevrier",'12-Suivi AT par Mois'!C5:E104,3,FALSE),0)
B22: Mars | C22: =IFERROR(VLOOKUP("Mars",'12-Suivi AT par Mois'!C5:E104,3,FALSE),0)
B23: Avr. | C23: =IFERROR(VLOOKUP("Avril",'12-Suivi AT par Mois'!C5:E104,3,FALSE),0)
B24: Mai | C24: =IFERROR(VLOOKUP("Mai",'12-Suivi AT par Mois'!C5:E104,3,FALSE),0)
B25: Juin | C25: =IFERROR(VLOOKUP("Juin",'12-Suivi AT par Mois'!C5:E104,3,FALSE),0)
H27: Type de Risque | I27: Nb
H28: Risque physique | I28: =COUNTIF('3-Evaluations des Risques'!E5:E104,"*Risque physique*")
H29: Risque chimique | I29: =COUNTIF('3-Evaluations des Risques'!E5:E104,"*Risque chimique*")
H30: Risque electrique | I30: =COUNTIF('3-Evaluations des Risques'!E5:E104,"*Risque electrique*")
H31: Risque psychosocial | I31: =COUNTIF('3-Evaluations des Risques'!E5:E104,"*Risque psychosocial*")
H32: Risque thermique | I32: =COUNTIF('3-Evaluations des Risques'!E5:E104,"*Risque thermique*")
H33: Risque chute de hauteur | I33: =COUNTIF('3-Evaluations des Risques'!E5:E104,"*Risque chute de hauteur*")
B35: AT PAR DEPARTEMENT
B36: Département | D36: Nb AT | F36: Nb Maladies | H36: Jours Arret AT | J36: Nb Visites
B37: Cuisine & Restauration | D37: =COUNTIF('5-Accidents du Travail'!E5:E104,"Cuisine & Restauration") | F37: =COUNTIF('6-Maladies Prof.'!E5:E104,"Cuisine & Restauration") | H37: =SUMIF('5-Accidents du Travail'!E5:E104,"Cuisine & Restauration",'5-Accidents du Travail'!M5:M104) | J37: =COUNTIF('7-Visites Medicales'!E5:E104,"Cuisine & Restauration")
B38: Maintenance | D38: =COUNTIF('5-Accidents du Travail'!E5:E104,"Maintenance") | F38: =COUNTIF('6-Maladies Prof.'!E5:E104,"Maintenance") | H38: =SUMIF('5-Accidents du Travail'!E5:E104,"Maintenance",'5-Accidents du Travail'!M5:M104) | J38: =COUNTIF('7-Visites Medicales'!E5:E104,"Maintenance")
B39: Sécurité | D39: =COUNTIF('5-Accidents du Travail'!E5:E104,"Sécurité") | F39: =COUNTIF('6-Maladies Prof.'!E5:E104,"Sécurité") | H39: =SUMIF('5-Accidents du Travail'!E5:E104,"Sécurité",'5-Accidents du Travail'!M5:M104) | J39: =COUNTIF('7-Visites Medicales'!E5:E104,"Sécurité")
B40: Réception & Front Office | D40: =COUNTIF('5-Accidents du Travail'!E5:E104,"Réception & Front Office") | F40: =COUNTIF('6-Maladies Prof.'!E5:E104,"Réception & Front Office") | H40: =SUMIF('5-Accidents du Travail'!E5:E104,"Réception & Front Office",'5-Accidents du Travail'!M5:M104) | J40: =COUNTIF('7-Visites Medicales'!E5:E104,"Réception & Front Office")
B41: Service Client | D41: =COUNTIF('5-Accidents du Travail'!E5:E104,"Service Client") | F41: =COUNTIF('6-Maladies Prof.'!E5:E104,"Service Client") | H41: =SUMIF('5-Accidents du Travail'!E5:E104,"Service Client",'5-Accidents du Travail'!M5:M104) | J41: =COUNTIF('7-Visites Medicales'!E5:E104,"Service Client")
B42: Finance & Comptabilité | D42: =COUNTIF('5-Accidents du Travail'!E5:E104,"Finance & Comptabilité") | F42: =COUNTIF('6-Maladies Prof.'!E5:E104,"Finance & Comptabilité") | H42: =SUMIF('5-Accidents du Travail'!E5:E104,"Finance & Comptabilité",'5-Accidents du Travail'!M5:M104) | J42: =COUNTIF('7-Visites Medicales'!E5:E104,"Finance & Comptabilité")
B43: Étage & Housekeeping | D43: =COUNTIF('5-Accidents du Travail'!E5:E104,"Étage & Housekeeping") | F43: =COUNTIF('6-Maladies Prof.'!E5:E104,"Étage & Housekeeping") | H43: =SUMIF('5-Accidents du Travail'!E5:E104,"Étage & Housekeeping",'5-Accidents du Travail'!M5:M104) | J43: =COUNTIF('7-Visites Medicales'!E5:E104,"Étage & Housekeeping")
B44: Commercial | D44: =COUNTIF('5-Accidents du Travail'!E5:E104,"Commercial") | F44: =COUNTIF('6-Maladies Prof.'!E5:E104,"Commercial") | H44: =SUMIF('5-Accidents du Travail'!E5:E104,"Commercial",'5-Accidents du Travail'!M5:M104) | J44: =COUNTIF('7-Visites Medicales'!E5:E104,"Commercial")

Sheet _Lists
B1: departement | C1: poste_hotel | D1: type_risque | E1: niveau_risque | F1: statut_risque | G1: gravite_accident | H1: lieu_accident | I1: cause_accident | J1: statut_accident | K1: type_maladie_pro | L1: statut_maladie | M1: type_visite | N1: resultat_visite | O1: statut_visite | P1: type_epi | Q1: statut_epi | R1: type_consigne | S1: statut_consigne | T1: statut_action | U1: statut_formation | V1: mois | W1: annee | X1: statut_rapport | Y1: priorite_action
B2: Direction Générale | C2: DG | D2: Risque physique | E2: Faible | F2: Identifie | G2: Bénin (sans arret) | H2: Cuisine | I2: Glissade / chute | J2: Declare | K2: TMS (troubles musculosquelettiques) | L2: Declaree | M2: Visite d'embauche | N2: Apte | O2: Planifiee | P2: Casque | Q2: En stock | R2: Consigne generale | S2: En vigueur | T2: Planifiee | U2: Planifiee | V2: Janvier | W2: 2024 | X2: Brouillon | Y2: Haute
B3: Service Client | C3: DRH | D3: Risque chimique | E3: Moyen | F3: En cours d'evaluation | G3: Mineur (avec arret <8j) | H3: Salle restaurant | I3: Manipulation incorrecte | J3: En cours d'enquete | K3: Maladie respiratoire | L3: En cours d'instruction | M3: Visite periodique | N3: Apte avec restriction | O3: Realisee | P3: Gants | Q3: Attribue | R3: Consigne specifique poste | S3: A revoir | T3: En cours | U3: En cours | V3: Fevrier | W3: 2025 | X3: Valide | Y3: Moyenne
B4: Finance & Comptabilité | C4: Assistante RH | D4: Risque biologique | E4: Eleve | F4: Evalue | G4: Moyen (8-30j) | H4: Reception | I4: Defaut equipement | J4: Enquete terminee | K4: Dermatose professionnelle | L4: Reconnue CNPS | M4: Visite de reprise | N4: Inapte temporaire | O4: Reportee | P4: Chaussures de securite | Q4: En cours de commande | R4: Procedure urgence | S4: Obsolette | T4: Terminee | U4: Realisee | V4: Mars | W4: 2026 | X4: Approuve | Y4: Basse
B5: Marketing & Communication | C5: DAF | D5: Risque ergonomique | E5: Tres eleve | F5: Mesures en place | G5: Grave (>30j) | H5: Lobby | I5: Non respect consignes | J5: Declaration CNPS | K5: Lombalgie chronique | L5: Non reconnue | M5: Visite pre-reprise | N5: Inapte definitif | O5: Absente | P5: Lunettes | Q5: A remplacer | R5: Consine travaux dangereux | S5: En elaboration | T5: Reportee | U5: Annulee | V5: Avril | X5: Rejete
B6: Maintenance | C6: Comptable senior | D6: Risque psychosocial | E6: Critique | F6: Residuel acceptable | G6: Fatal | H6: Chambre etage | I6: Fatigue / inattention | J6: Indemnise | K6: Surdite professionnelle | L6: En contestation | M6: Visite a la demande employe | N6: A renouveler | O6: En attente | P6: Masque respiratoire | Q6: Perdu / vole | R6: Permis de feu | S6: Archivee | T6: Annulee | U6: Reportee | V6: Mai
B7: Commercial | C7: Chef Comptable | D7: Risque electrique | F7: Non traite | H7: Sous-sol | I7: Environnement dangereux | J7: Cloture | K7: Pathologie liée aux produits chimiques | L7: Guerie | M7: Examen special | P7: Gilet haute visibilite | Q7: Rebute | R7: Permis de travail en hauteur | T7: En attente | V7: Juin
B8: Logistique & Approvisionnement | C8: Chef Marketing | D8: Risque incendie | H8: Parking | I8: Contact produit chimique | J8: Conteste | K8: Stress chronique / burnout | M8: Visite de surveillance medicale | P8: Protecteur auditif | V8: Juillet
B9: Cuisine & Restauration | C9: Chef de service IT | D9: Risque chute de plain-pied | H9: Jardin/piscine | I9: Surcharge physique | P9: Tablier | V9: Aout
B10: Réception & Front Office | C10: Technicien IT | D10: Risque chute de hauteur | H10: Local technique | I10: Electrocution | P10: Harnais | V10: Septembre
B11: Sécurité | C11: Chef Commercial | D11: Risque bruit | H11: Bureau | I11: Brulure | P11: Combinaison | V11: Octobre
B12: Étage & Housekeeping | C12: Agent Commercial | D12: Risque thermique | H12: Entrepot | P12: Ecran facial | V12: Novembre
C13: Chef Logistique | H13: Couloirs | V13: Decembre
C14: Magasinier | H14: Salle reunion
C15: Chef Reception | H15: Buanderie
C16: Receptionniste
C17: Concierge
C18: Chef Cuisine
C19: Sous-Chef
C20: Cuisinier
C21: Plongeur
C22: Chef Entretien
C23: Agent Entretien
C24: Chef Securite
C25: Agent Securite

Sheet 2-Registre Securite SST
B2: REGISTRE SECURITE & SANTE AU TRAVAIL (#97)
B3: TABLEAU DYNAMIQUE — Saisissez dans la prochaine ligne jaune. Les calculs se mettent a jour automatiquement.
B4: N° | C4: Date | D4: Heure | E4: Evenement | F4: Lieu | G4: Departement | H4: Personne Concernee | I4: Description | J4: Action Immediate
B5: SST-001 | C5: 45672 | D5: 08:30 | E5: Chute dans cuisine | F5: Cuisine | G5: Cuisine & Restauration | H5: Plongeur Tagne R. | I5: Glissade sur sol mouille, contusion poignet | J5: Nettoyage sol + premiers soins
B6: SST-002 | C6: 45708 | D6: 14:00 | E6: Fuite gaz cuisine | F6: Cuisine | G6: Cuisine & Restauration | H6: Plongeur Tagne R. | I6: Fuite detectee au niveau bouteille gaz | J6: Evacuation cuisine + fermeture vanne
B7: SST-003 | C7: 45726 | D7: 06:45 | E7: Coupure agent entretien | F7: Local technique | G7: Maintenance | H7: Technicien Fokam E. | I7: Coupure lors remplacement vitre | J7: Pansement + envoi infirmerie
B8: SST-004 | C8: 45752 | D8: 22:00 | E8: Client agressif reception | F8: Reception | G8: Réception & Front Office | H8: Réceptionniste Tchinda A. | I8: Client agresse verbalement receptionniste | J8: Intervention securite + rapport
B9: SST-005 | C9: 45795 | D9: 10:15 | E9: Bruit alarme incendie | F9: Etage 3 | G9: Réception & Front Office | H9: Chef Reception | I9: Alarme declenchee par fumee cuisine | J9: Verification + fausse alarme
B10: =IF(C10="","SST-"&TEXT(COUNTA($C$5:C10),"000"))
B11: =IF(C11="","SST-"&TEXT(COUNTA($C$5:C11),"000"))
B12: =IF(C12="","SST-"&TEXT(COUNTA($C$5:C12),"000"))
B13: =IF(C13="","SST-"&TEXT(COUNTA($C$5:C13),"000"))
B14: =IF(C14="","SST-"&TEXT(COUNTA($C$5:C14),"000"))
B15: =IF(C15="","SST-"&TEXT(COUNTA($C$5:C15),"000"))
B16: =IF(C16="","SST-"&TEXT(COUNTA($C$5:C16),"000"))
B17: =IF(C17="","SST-"&TEXT(COUNTA($C$5:C17),"000"))
B18: =IF(C18="","SST-"&TEXT(COUNTA($C$5:C18),"000"))
B19: =IF(C19="","SST-"&TEXT(COUNTA($C$5:C19),"000"))
B20: =IF(C20="","SST-"&TEXT(COUNTA($C$5:C20),"000"))
B21: =IF(C21="","SST-"&TEXT(COUNTA($C$5:C21),"000"))
... B109: =IF(C109="","SST-"&TEXT(COUNTA($C$5:C109),"000"))
B111: INDICATEURS (mis a jour automatiquement)
B112: Evenements | D112: Cuisine | F112: Entretien | H112: Reception
B113: =COUNTIF(B5:B104,"<>") | D113: =COUNTIF(G5:G104,"*Cuisine*") | F113: =COUNTIF(G5:G104,"*Entretien*") | H113: =COUNTIF(G5:G104,"*Reception*")

Sheet 3-Evaluations des Risques
B2: EVALUATIONS DES RISQUES PROFESSIONNELS (#98)
B3: TABLEAU DYNAMIQUE — Saisissez dans la prochaine ligne jaune. Les calculs se mettent a jour automatiquement.
B4: N° | C4: Poste / Zone | D4: Departement | E4: Type de Risque | F4: Danger Identifie | G4: Population Exposee | H4: Niveau de Risque | I4: Mesures Prevention | J4: Mesures Protection | K4: Risque Residuel | L4: Statut
B5: ER-001 | C5: Cuisinier | D5: Cuisine & Restauration | E5: Risque thermique | F5: Brulures plaques & friteuses | G5: 8 cuisiniers | H5: Eleve | I5: Formation manipulation chaud | J5: Gants thermiques, tabliers | K5: Moyen | L5: Mesures en place
B6: ER-002 | C6: Plongeur | D6: Cuisine & Restauration | E6: Risque chimique | F6: Produits detartrants / degreissants | G6: 4 plongeurs | H6: Moyen | I6: Formation manipulation produits | J6: Gants, lunettes, masque | K6: Faible | L6: Mesures en place
B7: ER-003 | C7: Agent Entretien | D7: Maintenance | E7: Risque electrique | F7: Travaux sous tension | G7: 6 agents | H7: Eleve | I7: Consignation equipements | J7: EPI electrique, verifier VAT | K7: Moyen | L7: En cours d'evaluation
B8: ER-004 | C8: Agent Securite | D8: Sécurité | E8: Risque psychosocial | F8: Agressions clients, travail de nuit | G8: 4 agents | H8: Moyen | I8: Formation gestion conflits | J8: Radio, camera, binome | K8: Faible | L8: Mesures en place
B9: ER-005 | C9: Agent Entretien | D9: Maintenance | E9: Risque chute de hauteur | F9: Travaux en hauteur (toiture, echelles) | G9: 6 agents | H9: Eleve | I9: Formation travail hauteur | J9: Harnais, echafaudage | K9: Moyen | L9: En cours d'evaluation
B10: ER-006 | C10: Cuisinier | D10: Cuisine & Restauration | E10: Risque incendie | F10: Flamme nue, huile chaude | G10: 8 cuisiniers | H10: Tres eleve | I10: Formation incendie, extincteurs | J10: Systeme detection, couverture anti-feu | K10: Eleve | L10: Identifie
B11: =IF(C11="","ER-"&TEXT(COUNTA($C$5:C11),"000"))
B12: =IF(C12="","ER-"&TEXT(COUNTA($C$5:C12),"000"))
B13: =IF(C13="","ER-"&TEXT(COUNTA($C$5:C13),"000"))
B14: =IF(C14="","ER-"&TEXT(COUNTA($C$5:C14),"000"))
B15: =IF(C15="","ER-"&TEXT(COUNTA($C$5:C15),"000"))
B16: =IF(C16="","ER-"&TEXT(COUNTA($C$5:C16),"000"))
B17: =IF(C17="","ER-"&TEXT(COUNTA($C$5:C17),"000"))
B18: =IF(C18="","ER-"&TEXT(COUNTA($C$5:C18),"000"))
B19: =IF(C19="","ER-"&TEXT(COUNTA($C$5:C19),"000"))
B20: =IF(C20="","ER-"&TEXT(COUNTA($C$5:C20),"000"))
B21: =IF(C21="","ER-"&TEXT(COUNTA($C$5:C21),"000"))
B22: =IF(C22="","ER-"&TEXT(COUNTA($C$5:C22),"000"))
... B110: =IF(C110="","ER-"&TEXT(COUNTA($C$5:C110),"000"))
B112: INDICATEURS (mis a jour automatiquement)
B113: Risques evalues | D113: Niveau eleve+ | F113: Non traites | H113: Identifies
B114: =COUNTIF(B5:B104,"<>") | D114: =COUNTIF(H5:H104,"Eleve")+COUNTIF(H5:H104,"Tres eleve")+COUNTIF(H5:H104,"Critique") | F114: =COUNTIF(L5:L104,"Non traite") | H114: =COUNTIF(L5:L104,"Identifie")

Sheet 4-Plan Action Securite
B2: PLAN D'ACTION SECURITE (#99)
B3: TABLEAU DYNAMIQUE — Saisissez dans la prochaine ligne jaune. Les calculs se mettent a jour automatiquement.
B4: N° | C4: Risque Lie (N°) | D4: Action a Mener | E4: Responsable | F4: Departement | G4: Priorite | H4: Date Lancement | I4: Echeance | J4: Budget Prevu (FCFA) | K4: Budget Reel (FCFA) | L4: Statut
B5: PAS-001 | C5: ER-006 | D5: Installer systeme detection fumee cuisine | E5: Chef Entretien | F5: Maintenance | G5: Haute | H5: 45778 | I5: 45869 | J5: 350000 | K5: 280000 | L5: En cours
B6: PAS-002 | C6: ER-003 | D6: Former agents entretien travaux electriques | E6: Chef Securite | F6: Maintenance | G6: Haute | H6: 45809 | I6: 45900 | J6: 150000 | K6: 0 | L6: Planifiee
B7: PAS-003 | C7: ER-005 | D7: Acheter harnais & echafaudages certifies | E7: Chef Logistique | F7: Logistique & Approvisionnement | G7: Haute | H7: 45792 | I7: 45853 | J7: 500000 | K7: 320000 | L7: En cours
B8: PAS-004 | C8: ER-004 | D8: Formation gestion aggressions securite | E8: Chef Securite | F8: Sécurité | G8: Moyenne | H8: 45839 | I8: 45930 | J8: 80000 | K8: 0 | L8: Planifiee
B9: PAS-005 | C9: ER-001 | D9: Renvoi cuisiniers formation brulures | E9: Chef Cuisine | F9: Cuisine & Restauration | G9: Moyenne | H9: 45748 | I9: 45838 | J9: 50000 | K9: 50000 | L9: Terminee
B10: =IF(C10="","PAS-"&TEXT(COUNTA($C$5:C10),"000")) | K10: =IF(J10="","",J10-K10)
B11: =IF(C11="","PAS-"&TEXT(COUNTA($C$5:C11),"000")) | K11: =IF(J11="","",J11-K11)
B12: =IF(C12="","PAS-"&TEXT(COUNTA($C$5:C12),"000")) | K12: =IF(J12="","",J12-K12)
B13: =IF(C13="","PAS-"&TEXT(COUNTA($C$5:C13),"000")) | K13: =IF(J13="","",J13-K13)
B14: =IF(C14="","PAS-"&TEXT(COUNTA($C$5:C14),"000")) | K14: =IF(J14="","",J14-K14)
B15: =IF(C15="","PAS-"&TEXT(COUNTA($C$5:C15),"000")) | K15: =IF(J15="","",J15-K15)
B16: =IF(C16="","PAS-"&TEXT(COUNTA($C$5:C16),"000")) | K16: =IF(J16="","",J16-K16)
B17: =IF(C17="","PAS-"&TEXT(COUNTA($C$5:C17),"000")) | K17: =IF(J17="","",J17-K17)
B18: =IF(C18="","PAS-"&TEXT(COUNTA($C$5:C18),"000")) | K18: =IF(J18="","",J18-K18)
B19: =IF(C19="","PAS-"&TEXT(COUNTA($C$5:C19),"000")) | K19: =IF(J19="","",J19-K19)
B20: =IF(C20="","PAS-"&TEXT(COUNTA($C$5:C20),"000")) | K20: =IF(J20="","",J20-K20)
B21: =IF(C21="","PAS-"&TEXT(COUNTA($C$5:C21),"000")) | K21: =IF(J21="","",J21-K21)
... B109: =IF(C109="","PAS-"&TEXT(COUNTA($C$5:C109),"000")) | K109: =IF(J109="","",J109-K109)
B111: TOTAL | J111: =SUM(J5:J104) | K111: =SUM(K5:K104)
B113: INDICATEURS (mis a jour automatiquement)
B114: Actions securite | D114: En cours | F114: Haute priorite | H114: Budget total (FCFA)
B115: =COUNTIF(B5:B104,"<>") | D115: =COUNTIF(L5:L104,"En cours") | F115: =COUNTIF(G5:G104,"Haute") | H115: =SUM(J5:J104)

Sheet 5-Accidents du Travail
B2: ACCIDENTS DU TRAVAIL (#100)
B3: TABLEAU DYNAMIQUE — Saisissez dans la prochaine ligne jaune. Les calculs se mettent a jour automatiquement.
B4: N° | C4: Matricule | D4: Nom Employe | E4: Departement | F4: Poste | G4: Date Accident | H4: Heure | I4: Lieu | J4: Cause | K4: Nature Blessure | L4: Gravite | M4: Nb Jours Arret | N4: Statut | O4: Nb Visites Med. | P4: Dernière Visite
B5: AT-001 | C5: EMP-010 | D5: =IF(C5="","",VLOOKUP(C5,'_Données Employés'!$B$5:$H$18,4,FALSE)&" "&VLOOKUP(C5,'_Données Employés'!$B$5:$H$18,5,FALSE)) | E5: =IF(C5="","",VLOOKUP(C5,'_Données Employés'!$B$5:$H$18,6,FALSE)) | F5: =IF(C5="","",VLOOKUP(C5,'_Données Employés'!$B$5:$H$18,7,FALSE)) | G5: 45672 | H5: 08:30 | I5: Cuisine | J5: Glissade / chute | K5: Contusion poignet droit | L5: Bénin (sans arret) | M5: 0 | N5: Cloture | O5: =IFERROR(COUNTIF('7-Visites Medicales'!C5:C104,C5),0) | P5: =IFERROR(MAXIFS('7-Visites Medicales'!H5:H104,'7-Visites Medicales'!C5:C104,C5),"")
B6: AT-002 | C6: EMP-010 | D6: =IF(C6="","",VLOOKUP(C6,'_Données Employés'!$B$5:$H$18,4,FALSE)&" "&VLOOKUP(C6,'_Données Employés'!$B$5:$H$18,5,FALSE)) | E6: =IF(C6="","",VLOOKUP(C6,'_Données Employés'!$B$5:$H$18,6,FALSE)) | F6: =IF(C6="","",VLOOKUP(C6,'_Données Employés'!$B$5:$H$18,7,FALSE)) | G6: 45708 | H6: 14:00 | I6: Cuisine | J6: Environnement dangereux | K6: Inhalation gaz | L6: Mineur (avec arret <8j) | M6: 3 | N6: Declare | O6: =IFERROR(COUNTIF('7-Visites Medicales'!C5:C104,C6),0) | P6: =IFERROR(MAXIFS('7-Visites Medicales'!H5:H104,'7-Visites Medicales'!C5:C104,C6),"")
B7: AT-003 | C7: EMP-009 | D7: =IF(C7="","",VLOOKUP(C7,'_Données Employés'!$B$5:$H$18,4,FALSE)&" "&VLOOKUP(C7,'_Données Employés'!$B$5:$H$18,5,FALSE)) | E7: =IF(C7="","",VLOOKUP(C7,'_Données Employés'!$B$5:$H$18,6,FALSE)) | F7: =IF(C7="","",VLOOKUP(C7,'_Données Employés'!$B$5:$H$18,7,FALSE)) | G7: 45726 | H7: 06:45 | I7: Local technique | J7: Manipulation incorrecte | K7: Coupure main gauche, 3 points | L7: Mineur (avec arret <8j) | M7: 5 | N7: Declaration CNPS | O7: =IFERROR(COUNTIF('7-Visites Medicales'!C5:C104,C7),0) | P7: =IFERROR(MAXIFS('7-Visites Medicales'!H5:H104,'7-Visites Medicales'!C5:C104,C7),"")
B8: AT-004 | C8: EMP-011 | D8: =IF(C8="","",VLOOKUP(C8,'_Données Employés'!$B$5:$H$18,4,FALSE)&" "&VLOOKUP(C8,'_Données Employés'!$B$5:$H$18,5,FALSE)) | E8: =IF(C8="","",VLOOKUP(C8,'_Données Employés'!$B$5:$H$18,6,FALSE)) | F8: =IF(C8="","",VLOOKUP(C8,'_Données Employés'!$B$5:$H$18,7,FALSE)) | G8: 45769 | H8: 03:00 | I8: Parking | J8: Agression physique externe | K8: Traumatisme crane, sutures | L8: Moyen (8-30j) | M8: 15 | N8: Indemnise | O8: =IFERROR(COUNTIF('7-Visites Medicales'!C5:C104,C8),0) | P8: =IFERROR(MAXIFS('7-Visites Medicales'!H5:H104,'7-Visites Medicales'!C5:C104,C8),"")
B9: AT-005 | C9: EMP-005 | D9: =IF(C9="","",VLOOKUP(C9,'_Données Employés'!$B$5:$H$18,4,FALSE)&" "&VLOOKUP(C9,'_Données Employés'!$B$5:$H$18,5,FALSE)) | E9: =IF(C9="","",VLOOKUP(C9,'_Données Employés'!$B$5:$H$18,6,FALSE)) | F9: =IF(C9="","",VLOOKUP(C9,'_Données Employés'!$B$5:$H$18,7,FALSE)) | G9: 45813 | H9: 10:00 | I9: Etage 4 | J9: Chute de hauteur | K9: Fracture cheville | L9: Grave (>30j) | M9: 45 | N9: En cours d'enquete | O9: =IFERROR(COUNTIF('7-Visites Medicales'!C5:C104,C9),0) | P9: =IFERROR(MAXIFS('7-Visites Medicales'!H5:H104,'7-Visites Medicales'!C5:C104,C9),"")
B10: =IF(C10="","AT-"&TEXT(COUNTA($C$5:C10),"000")) | O10: =IFERROR(COUNTIF('7-Visites Medicales'!C5:C104,C10),0) | P10: =IFERROR(MAXIFS('7-Visites Medicales'!H5:H104,'7-Visites Medicales'!C5:C104,C10),"")
B11: =IF(C11="","AT-"&TEXT(COUNTA($C$5:C11),"000")) | O11: =IFERROR(COUNTIF('7-Visites Medicales'!C5:C104,C11),0) | P11: =IFERROR(MAXIFS('7-Visites Medicales'!H5:H104,'7-Visites Medicales'!C5:C104,C11),"")
B12: =IF(C12="","AT-"&TEXT(COUNTA($C$5:C12),"000")) | O12: =IFERROR(COUNTIF('7-Visites Medicales'!C5:C104,C12),0) | P12: =IFERROR(MAXIFS('7-Visites Medicales'!H5:H104,'7-Visites Medicales'!C5:C104,C12),"")
B13: =IF(C13="","AT-"&TEXT(COUNTA($C$5:C13),"000")) | O13: =IFERROR(COUNTIF('7-Visites Medicales'!C5:C104,C13),0) | P13: =IFERROR(MAXIFS('7-Visites Medicales'!H5:H104,'7-Visites Medicales'!C5:C104,C13),"")
B14: =IF(C14="","AT-"&TEXT(COUNTA($C$5:C14),"000")) | O14: =IFERROR(COUNTIF('7-Visites Medicales'!C5:C104,C14),0) | P14: =IFERROR(MAXIFS('7-Visites Medicales'!H5:H104,'7-Visites Medicales'!C5:C104,C14),"")
B15: =IF(C15="","AT-"&TEXT(COUNTA($C$5:C15),"000")) | O15: =IFERROR(COUNTIF('7-Visites Medicales'!C5:C104,C15),0) | P15: =IFERROR(MAXIFS('7-Visites Medicales'!H5:H104,'7-Visites Medicales'!C5:C104,C15),"")
B16: =IF(C16="","AT-"&TEXT(COUNTA($C$5:C16),"000")) | O16: =IFERROR(COUNTIF('7-Visites Medicales'!C5:C104,C16),0) | P16: =IFERROR(MAXIFS('7-Visites Medicales'!H5:H104,'7-Visites Medicales'!C5:C104,C16),"")
B17: =IF(C17="","AT-"&TEXT(COUNTA($C$5:C17),"000")) | O17: =IFERROR(COUNTIF('7-Visites Medicales'!C5:C104,C17),0) | P17: =IFERROR(MAXIFS('7-Visites Medicales'!H5:H104,'7-Visites Medicales'!C5:C104,C17),"")
B18: =IF(C18="","AT-"&TEXT(COUNTA($C$5:C18),"000")) | O18: =IFERROR(COUNTIF('7-Visites Medicales'!C5:C104,C18),0) | P18: =IFERROR(MAXIFS('7-Visites Medicales'!H5:H104,'7-Visites Medicales'!C5:C104,C18),"")
B19: =IF(C19="","AT-"&TEXT(COUNTA($C$5:C19),"000")) | O19: =IFERROR(COUNTIF('7-Visites Medicales'!C5:C104,C19),0) | P19: =IFERROR(MAXIFS('7-Visites Medicales'!H5:H104,'7-Visites Medicales'!C5:C104,C19),"")
B20: =IF(C20="","AT-"&TEXT(COUNTA($C$5:C20),"000")) | O20: =IFERROR(COUNTIF('7-Visites Medicales'!C5:C104,C20),0) | P20: =IFERROR(MAXIFS('7-Visites Medicales'!H5:H104,'7-Visites Medicales'!C5:C104,C20),"")
B21: =IF(C21="","AT-"&TEXT(COUNTA($C$5:C21),"000")) | O21: =IFERROR(COUNTIF('7-Visites Medicales'!C5:C104,C21),0) | P21: =IFERROR(MAXIFS('7-Visites Medicales'!H5:H104,'7-Visites Medicales'!C5:C104,C21),"")
B22: =IF(C22="","AT-"&TEXT(COUNTA($C$5:C22),"000")) | O22: =IFERROR(COUNTIF('7-Visites Medicales'!C5:C104,C22),0) | P22: =IFERROR(MAXIFS('7-Visites Medicales'!H5:H104,'7-Visites Medicales'!C5:C104,C22),"")
B23: =IF(C23="","AT-"&TEXT(COUNTA($C$5:C23),"000")) | O23: =IFERROR(COUNTIF('7-Visites Medicales'!C5:C104,C23),0) | P23: =IFERROR(MAXIFS('7-Visites Medicales'!H5:H104,'7-Visites Medicales'!C5:C104,C23),"")
B24: =IF(C24="","AT-"&TEXT(COUNTA($C$5:C24),"000")) | O24: =IFERROR(COUNTIF('7-Visites Medicales'!C5:C104,C24),0) | P24: =IFERROR(MAXIFS('7-Visites Medicales'!H5:H104,'7-Visites Medicales'!C5:C104,C24),"")
B25: =IF(C25="","AT-"&TEXT(COUNTA($C$5:C25),"000")) | O25: =IFERROR(COUNTIF('7-Visites Medicales'!C5:C104,C25),0) | P25: =IFERROR(MAXIFS('7-Visites Medicales'!H5:H104,'7-Visites Medicales'!C5:C104,C25),"")
B26: =IF(C26="","AT-"&TEXT(COUNTA($C$5:C26),"000")) | O26: =IFERROR(COUNTIF('7-Visites Medicales'!C5:C104,C26),0) | P26: =IFERROR(MAXIFS('7-Visites Medicales'!H5:H104,'7-Visites Medicales'!C5:C104,C26),"")
B27: =IF(C27="","AT-"&TEXT(COUNTA($C$5:C27),"000")) | O27: =IFERROR(COUNTIF('7-Visites Medicales'!C5:C104,C27),0) | P27: =IFERROR(MAXIFS('7-Visites Medicales'!H5:H104,'7-Visites Medicales'!C5:C104,C27),"")
B28: =IF(C28="","AT-"&TEXT(COUNTA($C$5:C28),"000")) | O28: =IFERROR(COUNTIF('7-Visites Medicales'!C5:C104,C28),0) | P28: =IFERROR(MAXIFS('7-Visites Medicales'!H5:H104,'7-Visites Medicales'!C5:C104,C28),"")
B29: =IF(C29="","AT-"&TEXT(COUNTA($C$5:C29),"000")) | O29: =IFERROR(COUNTIF('7-Visites Medicales'!C5:C104,C29),0) | P29: =IFERROR(MAXIFS('7-Visites Medicales'!H5:H104,'7-Visites Medicales'!C5:C104,C29),"")
B30: =IF(C30="","AT-"&TEXT(COUNTA($C$5:C30),"000")) | O30: =IFERROR(COUNTIF('7-Visites Medicales'!C5:C104,C30),0) | P30: =IFERROR(MAXIFS('7-Visites Medicales'!H5:H104,'7-Visites Medicales'!C5:C104,C30),"")
B31: =IF(C31="","AT-"&TEXT(COUNTA($C$5:C31),"000")) | O31: =IFERROR(COUNTIF('7-Visites Medicales'!C5:C104,C31),0) | P31: =IFERROR(MAXIFS('7-Visites Medicales'!H5:H104,'7-Visites Medicales'!C5:C104,C31),"")
B32: =IF(C32="","AT-"&TEXT(COUNTA($C$5:C32),"000")) | O32: =IFERROR(COUNTIF('7-Visites Medicales'!C5:C104,C32),0) | P32: =IFERROR(MAXIFS('7-Visites Medicales'!H5:H104,'7-Visites Medicales'!C5:C104,C32),"")
B33: =IF(C33="","AT-"&TEXT(COUNTA($C$5:C33),"000")) | O33: =IFERROR(COUNTIF('7-Visites Medicales'!C5:C104,C33),0) | P33: =IFERROR(MAXIFS('7-Visites Medicales'!H5:H104,'7-Visites Medicales'!C5:C104,C33),"")
B34: =IF(C34="","AT-"&TEXT(COUNTA($C$5:C34),"000")) | O34: =IFERROR(COUNTIF('7-Visites Medicales'!C5:C104,C34),0) | P34: =IFERROR(MAXIFS('7-Visites Medicales'!H5:H104,'7-Visites Medicales'!C5:C104,C34),"")
B35: =IF(C35="","AT-"&TEXT(COUNTA($C$5:C35),"000")) | O35: =IFERROR(COUNTIF('7-Visites Medicales'!C5:C104,C35),0) | P35: =IFERROR(MAXIFS('7-Visites Medicales'!H5:H104,'7-Visites Medicales'!C5:C104,C35),"")
B36: =IF(C36="","AT-"&TEXT(COUNTA($C$5:C36),"000")) | O36: =IFERROR(COUNTIF('7-Visites Medicales'!C5:C104,C36),0) | P36: =IFERROR(MAXIFS('7-Visites Medicales'!H5:H104,'7-Visites Medicales'!C5:C104,C36),"")
B37: =IF(C37="","AT-"&TEXT(COUNTA($C$5:C37),"000")) | O37: =IFERROR(COUNTIF('7-Visites Medicales'!C5:C104,C37),0) | P37: =IFERROR(MAXIFS('7-Visites Medicales'!H5:H104,'7-Visites Medicales'!C5:C104,C37),"")
B38: =IF(C38="","AT-"&TEXT(COUNTA($C$5:C38),"000")) | O38: =IFERROR(COUNTIF('7-Visites Medicales'!C5:C104,C38),0) | P38: =IFERROR(MAXIFS('7-Visites Medicales'!H5:H104,'7-Visites Medicales'!C5:C104,C38),"")
B39: =IF(C39="","AT-"&TEXT(COUNTA($C$5:C39),"000")) | O39: =IFERROR(COUNTIF('7-Visites Medicales'!C5:C104,C39),0) | P39: =IFERROR(MAXIFS('7-Visites Medicales'!H5:H104,'7-Visites Medicales'!C5:C104,C39),"")
B40: =IF(C40="","AT-"&TEXT(COUNTA($C$5:C40),"000")) | O40: =IFERROR(COUNTIF('7-Visites Medicales'!C5:C104,C40),0) | P40: =IFERROR(MAXIFS('7-Visites Medicales'!H5:H104,'7-Visites Medicales'!C5:C104,C40),"")
B41: =IF(C41="","AT-"&TEXT(COUNTA($C$5:C41),"000")) | O41: =IFERROR(COUNTIF('7-Visites Medicales'!C5:C104,C41),0) | P41: =IFERROR(MAXIFS('7-Visites Medicales'!H5:H104,'7-Visites Medicales'!C5:C104,C41),"")
...

Sheet 6-Maladies Prof.
B2: MALADIES PROFESSIONNELLES (#101)
B3: TABLEAU DYNAMIQUE — Saisissez dans la prochaine ligne jaune. Les calculs se mettent a jour automatiquement.
B4: N° | C4: Matricule | D4: Nom Employe | E4: Departement | F4: Poste | G4: Type Maladie | H4: Date 1ers Symptomes | I4: Date Declaration | J4: Nb Jours Arret | K4: Medecin Conseil | L4: Statut | M4: Nb AT liés | N4: Total Jours AT
B5: MP-001 | C5: EMP-010 | D5: =IF(C5="","",VLOOKUP(C5,'_Données Employés'!$B$5:$H$18,4,FALSE)&" "&VLOOKUP(C5,'_Données Employés'!$B$5:$H$18,5,FALSE)) | E5: =IF(C5="","",VLOOKUP(C5,'_Données Employés'!$B$5:$H$18,6,FALSE)) | F5: =IF(C5="","",VLOOKUP(C5,'_Données Employés'!$B$5:$H$18,7,FALSE)) | G5: TMS (troubles musculosquelettiques) | H5: 45536 | I5: 45672 | J5: 30 | K5: Dr. Njifenjou | L5: Reconnue CNPS | M5: =IFERROR(COUNTIF('5-Accidents du Travail'!C5:C104,C5),0) | N5: =IFERROR(SUMIF('5-Accidents du Travail'!C5:C104,C5,'5-Accidents du Travail'!M5:M104),0)
B6: MP-002 | C6: EMP-009 | D6: =IF(C6="","",VLOOKUP(C6,'_Données Employés'!$B$5:$H$18,4,FALSE)&" "&VLOOKUP(C6,'_Données Employés'!$B$5:$H$18,5,FALSE)) | E6: =IF(C6="","",VLOOKUP(C6,'_Données Employés'!$B$5:$H$18,6,FALSE)) | F6: =IF(C6="","",VLOOKUP(C6,'_Données Employés'!$B$5:$H$18,7,FALSE)) | G6: Lombalgie chronique | H6: 45444 | I6: 45698 | J6: 60 | K6: Dr. Tchinda | L6: En cours d'instruction | M6: =IFERROR(COUNTIF('5-Accidents du Travail'!C5:C104,C6),0) | N6: =IFERROR(SUMIF('5-Accidents du Travail'!C5:C104,C6,'5-Accidents du Travail'!M5:M104),0)
B7: MP-003 | C7: EMP-007 | D7: =IF(C7="","",VLOOKUP(C7,'_Données Employés'!$B$5:$H$18,4,FALSE)&" "&VLOOKUP(C7,'_Données Employés'!$B$5:$H$18,5,FALSE)) | E7: =IF(C7="","",VLOOKUP(C7,'_Données Employés'!$B$5:$H$18,6,FALSE)) | F7: =IF(C7="","",VLOOKUP(C7,'_Données Employés'!$B$5:$H$18,7,FALSE)) | G7: Dermatose professionnelle | H7: 45717 | I7: 45797 | J7: 15 | K7: Dr. Njifenjou | L7: Reconnue CNPS | M7: =IFERROR(COUNTIF('5-Accidents du Travail'!C5:C104,C7),0) | N7: =IFERROR(SUMIF('5-Accidents du Travail'!C5:C104,C7,'5-Accidents du Travail'!M5:M104),0)
B8: MP-004 | C8: EMP-006 | D8: =IF(C8="","",VLOOKUP(C8,'_Données Employés'!$B$5:$H$18,4,FALSE)&" "&VLOOKUP(C8,'_Données Employés'!$B$5:$H$18,5,FALSE)) | E8: =IF(C8="","",VLOOKUP(C8,'_Données Employés'!$B$5:$H$18,6,FALSE)) | F8: =IF(C8="","",VLOOKUP(C8,'_Données Employés'!$B$5:$H$18,7,FALSE)) | G8: Stress chronique / burnout | H8: 45658 | I8: 45809 | J8: 45 | K8: Dr. Mbarga | L8: En contestation | M8: =IFERROR(COUNTIF('5-Accidents du Travail'!C5:C104,C8),0) | N8: =IFERROR(SUMIF('5-Accidents du Travail'!C5:C104,C8,'5-Accidents du Travail'!M5:M104),0)
B9: =IF(C9="","MP-"&TEXT(COUNTA($C$5:C9),"000")) | M9: =IFERROR(COUNTIF('5-Accidents du Travail'!C5:C104,C9),0) | N9: =IFERROR(SUMIF('5-Accidents du Travail'!C5:C104,C9,'5-Accidents du Travail'!M5:M104),0)
B10: =IF(C10="","MP-"&TEXT(COUNTA($C$5:C10),"000")) | M10: =IFERROR(COUNTIF('5-Accidents du Travail'!C5:C104,C10),0) | N10: =IFERROR(SUMIF('5-Accidents du Travail'!C5:C104,C10,'5-Accidents du Travail'!M5:M104),0)
B11: =IF(C11="","MP-"&TEXT(COUNTA($C$5:C11),"000")) | M11: =IFERROR(COUNTIF('5-Accidents du Travail'!C5:C104,C11),0) | N11: =IFERROR(SUMIF('5-Accidents du Travail'!C5:C104,C11,'5-Accidents du Travail'!M5:M104),0)
B12: =IF(C12="","MP-"&TEXT(COUNTA($C$5:C12),"000")) | M12: =IFERROR(COUNTIF('5-Accidents du Travail'!C5:C104,C12),0) | N12: =IFERROR(SUMIF('5-Accidents du Travail'!C5:C104,C12,'5-Accidents du Travail'!M5:M104),0)
B13: =IF(C13="","MP-"&TEXT(COUNTA($C$5:C13),"000")) | M13: =IFERROR(COUNTIF('5-Accidents du Travail'!C5:C104,C13),0) | N13: =IFERROR(SUMIF('5-Accidents du Travail'!C5:C104,C13,'5-Accidents du Travail'!M5:M104),0)
B14: =IF(C14="","MP-"&TEXT(COUNTA($C$5:C14),"000")) | M14: =IFERROR(COUNTIF('5-Accidents du Travail'!C5:C104,C14),0) | N14: =IFERROR(SUMIF('5-Accidents du Travail'!C5:C104,C14,'5-Accidents du Travail'!M5:M104),0)
B15: =IF(C15="","MP-"&TEXT(COUNTA($C$5:C15),"000")) | M15: =IFERROR(COUNTIF('5-Accidents du Travail'!C5:C104,C15),0) | N15: =IFERROR(SUMIF('5-Accidents du Travail'!C5:C104,C15,'5-Accidents du Travail'!M5:M104),0)
B16: =IF(C16="","MP-"&TEXT(COUNTA($C$5:C16),"000")) | M16: =IFERROR(COUNTIF('5-Accidents du Travail'!C5:C104,C16),0) | N16: =IFERROR(SUMIF('5-Accidents du Travail'!C5:C104,C16,'5-Accidents du Travail'!M5:M104),0)
B17: =IF(C17="","MP-"&TEXT(COUNTA($C$5:C17),"000")) | M17: =IFERROR(COUNTIF('5-Accidents du Travail'!C5:C104,C17),0) | N17: =IFERROR(SUMIF('5-Accidents du Travail'!C5:C104,C17,'5-Accidents du Travail'!M5:M104),0)
B18: =IF(C18="","MP-"&TEXT(COUNTA($C$5:C18),"000")) | M18: =IFERROR(COUNTIF('5-Accidents du Travail'!C5:C104,C18),0) | N18: =IFERROR(SUMIF('5-Accidents du Travail'!C5:C104,C18,'5-Accidents du Travail'!M5:M104),0)
B19: =IF(C19="","MP-"&TEXT(COUNTA($C$5:C19),"000")) | M19: =IFERROR(COUNTIF('5-Accidents du Travail'!C5:C104,C19),0) | N19: =IFERROR(SUMIF('5-Accidents du Travail'!C5:C104,C19,'5-Accidents du Travail'!M5:M104),0)
B20: =IF(C20="","MP-"&TEXT(COUNTA($C$5:C20),"000")) | M20: =IFERROR(COUNTIF('5-Accidents du Travail'!C5:C104,C20),0) | N20: =IFERROR(SUMIF('5-Accidents du Travail'!C5:C104,C20,'5-Accidents du Travail'!M5:M104),0)
B21: =IF(C21="","MP-"&TEXT(COUNTA($C$5:C21),"000")) | M21: =IFERROR(COUNTIF('5-Accidents du Travail'!C5:C104,C21),0) | N21: =IFERROR(SUMIF('5-Accidents du Travail'!C5:C104,C21,'5-Accidents du Travail'!M5:M104),0)
B22: =IF(C22="","MP-"&TEXT(COUNTA($C$5:C22),"000")) | M22: =IFERROR(COUNTIF('5-Accidents du Travail'!C5:C104,C22),0) | N22: =IFERROR(SUMIF('5-Accidents du Travail'!C5:C104,C22,'5-Accidents du Travail'!M5:M104),0)
B23: =IF(C23="","MP-"&TEXT(COUNTA($C$5:C23),"000")) | M23: =IFERROR(COUNTIF('5-Accidents du Travail'!C5:C104,C23),0) | N23: =IFERROR(SUMIF('5-Accidents du Travail'!C5:C104,C23,'5-Accidents du Travail'!M5:M104),0)
B24: =IF(C24="","MP-"&TEXT(COUNTA($C$5:C24),"000")) | M24: =IFERROR(COUNTIF('5-Accidents du Travail'!C5:C104,C24),0) | N24: =IFERROR(SUMIF('5-Accidents du Travail'!C5:C104,C24,'5-Accidents du Travail'!M5:M104),0)
B25: =IF(C25="","MP-"&TEXT(COUNTA($C$5:C25),"000")) | M25: =IFERROR(COUNTIF('5-Accidents du Travail'!C5:C104,C25),0) | N25: =IFERROR(SUMIF('5-Accidents du Travail'!C5:C104,C25,'5-Accidents du Travail'!M5:M104),0)
B26: =IF(C26="","MP-"&TEXT(COUNTA($C$5:C26),"000")) | M26: =IFERROR(COUNTIF('5-Accidents du Travail'!C5:C104,C26),0) | N26: =IFERROR(SUMIF('5-Accidents du Travail'!C5:C104,C26,'5-Accidents du Travail'!M5:M104),0)
B27: =IF(C27="","MP-"&TEXT(COUNTA($C$5:C27),"000")) | M27: =IFERROR(COUNTIF('5-Accidents du Travail'!C5:C104,C27),0) | N27: =IFERROR(SUMIF('5-Accidents du Travail'!C5:C104,C27,'5-Accidents du Travail'!M5:M104),0)
B28: =IF(C28="","MP-"&TEXT(COUNTA($C$5:C28),"000")) | M28: =IFERROR(COUNTIF('5-Accidents du Travail'!C5:C104,C28),0) | N28: =IFERROR(SUMIF('5-Accidents du Travail'!C5:C104,C28,'5-Accidents du Travail'!M5:M104),0)
B29: =IF(C29="","MP-"&TEXT(COUNTA($C$5:C29),"000")) | M29: =IFERROR(COUNTIF('5-Accidents du Travail'!C5:C104,C29),0) | N29: =IFERROR(SUMIF('5-Accidents du Travail'!C5:C104,C29,'5-Accidents du Travail'!M5:M104),0)
B30: =IF(C30="","MP-"&TEXT(COUNTA($C$5:C30),"000")) | M30: =IFERROR(COUNTIF('5-Accidents du Travail'!C5:C104,C30),0) | N30: =IFERROR(SUMIF('5-Accidents du Travail'!C5:C104,C30,'5-Accidents du Travail'!M5:M104),0)
B31: =IF(C31="","MP-"&TEXT(COUNTA($C$5:C31),"000")) | M31: =IFERROR(COUNTIF('5-Accidents du Travail'!C5:C104,C31),0) | N31: =IFERROR(SUMIF('5-Accidents du Travail'!C5:C104,C31,'5-Accidents du Travail'!M5:M104),0)
B32: =IF(C32="","MP-"&TEXT(COUNTA($C$5:C32),"000")) | M32: =IFERROR(COUNTIF('5-Accidents du Travail'!C5:C104,C32),0) | N32: =IFERROR(SUMIF('5-Accidents du Travail'!C5:C104,C32,'5-Accidents du Travail'!M5:M104),0)
B33: =IF(C33="","MP-"&TEXT(COUNTA($C$5:C33),"000")) | M33: =IFERROR(COUNTIF('5-Accidents du Travail'!C5:C104,C33),0) | N33: =IFERROR(SUMIF('5-Accidents du Travail'!C5:C104,C33,'5-Accidents du Travail'!M5:M104),0)
B34: =IF(C34="","MP-"&TEXT(COUNTA($C$5:C34),"000")) | M34: =IFERROR(COUNTIF('5-Accidents du Travail'!C5:C104,C34),0) | N34: =IFERROR(SUMIF('5-Accidents du Travail'!C5:C104,C34,'5-Accidents du Travail'!M5:M104),0)
B35: =IF(C35="","MP-"&TEXT(COUNTA($C$5:C35),"000")) | M35: =IFERROR(COUNTIF('5-Accidents du Travail'!C5:C104,C35),0) | N35: =IFERROR(SUMIF('5-Accidents du Travail'!C5:C104,C35,'5-Accidents du Travail'!M5:M104),0)
B36: =IF(C36="","MP-"&TEXT(COUNTA($C$5:C36),"000")) | M36: =IFERROR(COUNTIF('5-Accidents du Travail'!C5:C104,C36),0) | N36: =IFERROR(SUMIF('5-Accidents du Travail'!C5:C104,C36,'5-Accidents du Travail'!M5:M104),0)
B37: =IF(C37="","MP-"&TEXT(COUNTA($C$5:C37),"000")) | M37: =IFERROR(COUNTIF('5-Accidents du Travail'!C5:C104,C37),0) | N37: =IFERROR(SUMIF('5-Accidents du Travail'!C5:C104,C37,'5-Accidents du Travail'!M5:M104),0)
B38: =IF(C38="","MP-"&TEXT(COUNTA($C$5:C38),"000")) | M38: =IFERROR(COUNTIF('5-Accidents du Travail'!C5:C104,C38),0) | N38: =IFERROR(SUMIF('5-Accidents du Travail'!C5:C104,C38,'5-Accidents du Travail'!M5:M104),0)
B39: =IF(C39="","MP-"&TEXT(COUNTA($C$5:C39),"000")) | M39: =IFERROR(COUNTIF('5-Accidents du Travail'!C5:C104,C39),0) | N39: =IFERROR(SUMIF('5-Accidents du Travail'!C5:C104,C39,'5-Accidents du Travail'!M5:M104),0)
B40: =IF(C40="","MP-"&TEXT(COUNTA($C$5:C40),"000")) | M40: =IFERROR(COUNTIF('5-Accidents du Travail'!C5:C104,C40),0) | N40: =IFERROR(SUMIF('5-Accidents du Travail'!C5:C104,C40,'5-Accidents du Travail'!M5:M104),0)
B41: =IF(C41="","MP-"&TEXT(COUNTA($C$5:C41),"000")) | M41: =IFERROR(COUNTIF('5-Accidents du Travail'!C5:C104,C41),0) | N41: =IFERROR(SUMIF('5-Accidents du Travail'!C5:C104,C41,'5-Accidents du Travail'!M5:M104),0)
...

Sheet 7-Visites Medicales
B2: VISITES MEDICALES (#102)
B3: TABLEAU DYNAMIQUE — Saisissez dans la prochaine ligne jaune. Les calculs se mettent a jour automatiquement.
B4: N° | C4: Matricule | D4: Nom Employe | E4: Departement | F4: Poste | G4: Type Visite | H4: Date Visite | I4: Medecin | J4: Resultat | K4: Restrictions | L4: Nb AT | M4: Nb MP
B5: VM-001 | C5: EMP-002 | D5: =IF(C5="","",VLOOKUP(C5,'_Données Employés'!$B$5:$H$18,4,FALSE)&" "&VLOOKUP(C5,'_Données Employés'!$B$5:$H$18,5,FALSE)) | E5: =IF(C5="","",VLOOKUP(C5,'_Données Employés'!$B$5:$H$18,6,FALSE)) | F5: =IF(C5="","",VLOOKUP(C5,'_Données Employés'!$B$5:$H$18,7,FALSE)) | G5: Visite d'embauche | H5: 45748 | I5: Dr. Njifenjou | J5: Apte | K5: Aucune | L5: =IFERROR(COUNTIF('5-Accidents du Travail'!C5:C104,C5),0) | M5: =IFERROR(COUNTIF('6-Maladies Prof.'!C5:C104,C5),0)
B6: VM-002 | C6: EMP-012 | D6: =IF(C6="","",VLOOKUP(C6,'_Données Employés'!$B$5:$H$18,4,FALSE)&" "&VLOOKUP(C6,'_Données Employés'!$B$5:$H$18,5,FALSE)) | E6: =IF(C6="","",VLOOKUP(C6,'_Données Employés'!$B$5:$H$18,6,FALSE)) | F6: =IF(C6="","",VLOOKUP(C6,'_Données Employés'!$B$5:$H$18,7,FALSE)) | G6: Visite d'embauche | H6: 45778 | I6: Dr. Tchinda | J6: Apte | K6: Port de chaussures confortables | L6: =IFERROR(COUNTIF('5-Accidents du Travail'!C5:C104,C6),0) | M6: =IFERROR(COUNTIF('6-Maladies Prof.'!C5:C104,C6),0)
B7: VM-003 | C7: EMP-010 | D7: =IF(C7="","",VLOOKUP(C7,'_Données Employés'!$B$5:$H$18,4,FALSE)&" "&VLOOKUP(C7,'_Données Employés'!$B$5:$H$18,5,FALSE)) | E7: =IF(C7="","",VLOOKUP(C7,'_Données Employés'!$B$5:$H$18,6,FALSE)) | F7: =IF(C7="","",VLOOKUP(C7,'_Données Employés'!$B$5:$H$18,7,FALSE)) | G7: Visite de reprise | H7: 45708 | I7: Dr. Njifenjou | J7: Apte avec restriction | K7: Pas port de charges >10kg pendant 1 mois | L7: =IFERROR(COUNTIF('5-Accidents du Travail'!C5:C104,C7),0) | M7: =IFERROR(COUNTIF('6-Maladies Prof.'!C5:C104,C7),0)
B8: VM-004 | C8: EMP-009 | D8: =IF(C8="","",VLOOKUP(C8,'_Données Employés'!$B$5:$H$18,4,FALSE)&" "&VLOOKUP(C8,'_Données Employés'!$B$5:$H$18,5,FALSE)) | E8: =IF(C8="","",VLOOKUP(C8,'_Données Employés'!$B$5:$H$18,6,FALSE)) | F8: =IF(C8="","",VLOOKUP(C8,'_Données Employés'!$B$5:$H$18,7,FALSE)) | G8: Visite periodique | H8: 45731 | I8: Dr. Tchinda | J8: Apte | K8: Aucune | L8: =IFERROR(COUNTIF('5-Accidents du Travail'!C5:C104,C8),0) | M8: =IFERROR(COUNTIF('6-Maladies Prof.'!C5:C104,C8),0)
B9: VM-005 | C9: EMP-006 | D9: =IF(C9="","",VLOOKUP(C9,'_Données Employés'!$B$5:$H$18,4,FALSE)&" "&VLOOKUP(C9,'_Données Employés'!$B$5:$H$18,5,FALSE)) | E9: =IF(C9="","",VLOOKUP(C9,'_Données Employés'!$B$5:$H$18,6,FALSE)) | F9: =IF(C9="","",VLOOKUP(C9,'_Données Employés'!$B$5:$H$18,7,FALSE)) | G9: Visite a la demande employe | H9: 45797 | I9: Dr. Mbarga | J9: Inapte temporaire | K9: Arret maladie 15 jours - stress | L9: =IFERROR(COUNTIF('5-Accidents du Travail'!C5:C104,C9),0) | M9: =IFERROR(COUNTIF('6-Maladies Prof.'!C5:C104,C9),0)
B10: VM-006 | C10: EMP-001 | D10: =IF(C10="","",VLOOKUP(C10,'_Données Employés'!$B$5:$H$18,4,FALSE)&" "&VLOOKUP(C10,'_Données Employés'!$B$5:$H$18,5,FALSE)) | E10: =IF(C10="","",VLOOKUP(C10,'_Données Employés'!$B$5:$H$18,6,FALSE)) | F10: =IF(C10="","",VLOOKUP(C10,'_Données Employés'!$B$5:$H$18,7,FALSE)) | G10: Visite periodique | L10: =IFERROR(COUNTIF('5-Accidents du Travail'!C5:C104,C10),0) | M10: =IFERROR(COUNTIF('6-Maladies Prof.'!C5:C104,C10),0)
B11: VM-007 | C11: EMP-002 | D11: =IF(C11="","",VLOOKUP(C11,'_Données Employés'!$B$5:$H$18,4,FALSE)&" "&VLOOKUP(C11,'_Données Employés'!$B$5:$H$18,5,FALSE)) | E11: =IF(C11="","",VLOOKUP(C11,'_Données Employés'!$B$5:$H$18,6,FALSE)) | F11: =IF(C11="","",VLOOKUP(C11,'_Données Employés'!$B$5:$H$18,7,FALSE)) | G11: Visite periodique | L11: =IFERROR(COUNTIF('5-Accidents du Travail'!C5:C104,C11),0) | M11: =IFERROR(COUNTIF('6-Maladies Prof.'!C5:C104,C11),0)
B12: VM-008 | C12: EMP-003 | D12: =IF(C12="","",VLOOKUP(C12,'_Données Employés'!$B$5:$H$18,4,FALSE)&" "&VLOOKUP(C12,'_Données Employés'!$B$5:$H$18,5,FALSE)) | E12: =IF(C12="","",VLOOKUP(C12,'_Données Employés'!$B$5:$H$18,6,FALSE)) | F12: =IF(C12="","",VLOOKUP(C12,'_Données Employés'!$B$5:$H$18,7,FALSE)) | G12: Visite periodique | L12: =IFERROR(COUNTIF('5-Accidents du Travail'!C5:C104,C12),0) | M12: =IFERROR(COUNTIF('6-Maladies Prof.'!C5:C104,C12),0)
B13: VM-009 | C13: EMP-004 | D13: =IF(C13="","",VLOOKUP(C13,'_Données Employés'!$B$5:$H$18,4,FALSE)&" "&VLOOKUP(C13,'_Données Employés'!$B$5:$H$18,5,FALSE)) | E13: =IF(C13="","",VLOOKUP(C13,'_Données Employés'!$B$5:$H$18,6,FALSE)) | F13: =IF(C13="","",VLOOKUP(C13,'_Données Employés'!$B$5:$H$18,7,FALSE)) | G13: Visite periodique | L13: =IFERROR(COUNTIF('5-Accidents du Travail'!C5:C104,C13),0) | M13: =IFERROR(COUNTIF('6-Maladies Prof.'!C5:C104,C13),0)
B14: VM-010 | C14: EMP-005 | D14: =IF(C14="","",VLOOKUP(C14,'_Données Employés'!$B$5:$H$18,4,FALSE)&" "&VLOOKUP(C14,'_Données Employés'!$B$5:$H$18,5,FALSE)) | E14: =IF(C14="","",VLOOKUP(C14,'_Données Employés'!$B$5:$H$18,6,FALSE)) | F14: =IF(C14="","",VLOOKUP(C14,'_Données Employés'!$B$5:$H$18,7,FALSE)) | G14: Visite periodique | L14: =IFERROR(COUNTIF('5-Accidents du Travail'!C5:C104,C14),0) | M14: =IFERROR(COUNTIF('6-Maladies Prof.'!C5:C104,C14),0)
B15: VM-011 | C15: EMP-006 | D15: =IF(C15="","",VLOOKUP(C15,'_Données Employés'!$B$5:$H$18,4,FALSE)&" "&VLOOKUP(C15,'_Données Employés'!$B$5:$H$18,5,FALSE)) | E15: =IF(C15="","",VLOOKUP(C15,'_Données Employés'!$B$5:$H$18,6,FALSE)) | F15: =IF(C15="","",VLOOKUP(C15,'_Données Employés'!$B$5:$H$18,7,FALSE)) | G15: Visite periodique | L15: =IFERROR(COUNTIF('5-Accidents du Travail'!C5:C104,C15),0) | M15: =IFERROR(COUNTIF('6-Maladies Prof.'!C5:C104,C15),0)
B16: VM-012 | C16: EMP-007 | D16: =IF(C16="","",VLOOKUP(C16,'_Données Employés'!$B$5:$H$18,4,FALSE)&" "&VLOOKUP(C16,'_Données Employés'!$B$5:$H$18,5,FALSE)) | E16: =IF(C16="","",VLOOKUP(C16,'_Données Employés'!$B$5:$H$18,6,FALSE)) | F16: =IF(C16="","",VLOOKUP(C16,'_Données Employés'!$B$5:$H$18,7,FALSE)) | G16: Visite periodique | L16: =IFERROR(COUNTIF('5-Accidents du Travail'!C5:C104,C16),0) | M16: =IFERROR(COUNTIF('6-Maladies Prof.'!C5:C104,C16),0)
B17: VM-013 | C17: EMP-008 | D17: =IF(C17="","",VLOOKUP(C17,'_Données Employés'!$B$5:$H$18,4,FALSE)&" "&VLOOKUP(C17,'_Données Employés'!$B$5:$H$18,5,FALSE)) | E17: =IF(C17="","",VLOOKUP(C17,'_Données Employés'!$B$5:$H$18,6,FALSE)) | F17: =IF(C17="","",VLOOKUP(C17,'_Données Employés'!$B$5:$H$18,7,FALSE)) | G17: Visite periodique | L17: =IFERROR(COUNTIF('5-Accidents du Travail'!C5:C104,C17),0) | M17: =IFERROR(COUNTIF('6-Maladies Prof.'!C5:C104,C17),0)
B18: VM-014 | C18: EMP-011 | D18: =IF(C18="","",VLOOKUP(C18,'_Données Employés'!$B$5:$H$18,4,FALSE)&" "&VLOOKUP(C18,'_Données Employés'!$B$5:$H$18,5,FALSE)) | E18: =IF(C18="","",VLOOKUP(C18,'_Données Employés'!$B$5:$H$18,6,FALSE)) | F18: =IF(C18="","",VLOOKUP(C18,'_Données Employés'!$B$5:$H$18,7,FALSE)) | G18: Visite periodique | L18: =IFERROR(COUNTIF('5-Accidents du Travail'!C5:C104,C18),0) | M18: =IFERROR(COUNTIF('6-Maladies Prof.'!C5:C104,C18),0)
B19: VM-015 | C19: EMP-012 | D19: =IF(C19="","",VLOOKUP(C19,'_Données Employés'!$B$5:$H$18,4,FALSE)&" "&VLOOKUP(C19,'_Données Employés'!$B$5:$H$18,5,FALSE)) | E19: =IF(C19="","",VLOOKUP(C19,'_Données Employés'!$B$5:$H$18,6,FALSE)) | F19: =IF(C19="","",VLOOKUP(C19,'_Données Employés'!$B$5:$H$18,7,FALSE)) | G19: Visite periodique | L19: =IFERROR(COUNTIF('5-Accidents du Travail'!C5:C104,C19),0) | M19: =IFERROR(COUNTIF('6-Maladies Prof.'!C5:C104,C19),0)
B20: VM-016 | C20: EMP-028 | D20: =IF(C20="","",VLOOKUP(C20,'_Données Employés'!$B$5:$H$18,4,FALSE)&" "&VLOOKUP(C20,'_Données Employés'!$B$5:$H$18,5,FALSE)) | E20: =IF(C20="","",VLOOKUP(C20,'_Données Employés'!$B$5:$H$18,6,FALSE)) | F20: =IF(C20="","",VLOOKUP(C20,'_Données Employés'!$B$5:$H$18,7,FALSE)) | G20: Visite periodique | L20: =IFERROR(COUNTIF('5-Accidents du Travail'!C5:C104,C20),0) | M20: =IFERROR(COUNTIF('6-Maladies Prof.'!C5:C104,C20),0)
B21: VM-017 | C21: EMP-029 | D21: =IF(C21="","",VLOOKUP(C21,'_Données Employés'!$B$5:$H$18,4,FALSE)&" "&VLOOKUP(C21,'_Données Employés'!$B$5:$H$18,5,FALSE)) | E21: =IF(C21="","",VLOOKUP(C21,'_Données Employés'!$B$5:$H$18,6,FALSE)) | F21: =IF(C21="","",VLOOKUP(C21,'_Données Employés'!$B$5:$H$18,7,FALSE)) | G21: Visite periodique | L21: =IFERROR(COUNTIF('5-Accidents du Travail'!C5:C104,C21),0) | M21: =IFERROR(COUNTIF('6-Maladies Prof.'!C5:C104,C21),0)
B22: =IF(C22="","VM-"&TEXT(COUNTA($C$5:C22),"000")) | L22: =IFERROR(COUNTIF('5-Accidents du Travail'!C5:C104,C22),0) | M22: =IFERROR(COUNTIF('6-Maladies Prof.'!C5:C104,C22),0)
B23: =IF(C23="","VM-"&TEXT(COUNTA($C$5:C23),"000")) | L23: =IFERROR(COUNTIF('5-Accidents du Travail'!C5:C104,C23),0) | M23: =IFERROR(COUNTIF('6-Maladies Prof.'!C5:C104,C23),0)
B24: =IF(C24="","VM-"&TEXT(COUNTA($C$5:C24),"000")) | L24: =IFERROR(COUNTIF('5-Accidents du Travail'!C5:C104,C24),0) | M24: =IFERROR(COUNTIF('6-Maladies Prof.'!C5:C104,C24),0)
B25: =IF(C25="","VM-"&TEXT(COUNTA($C$5:C25),"000")) | L25: =IFERROR(COUNTIF('5-Accidents du Travail'!C5:C104,C25),0) | M25: =IFERROR(COUNTIF('6-Maladies Prof.'!C5:C104,C25),0)
B26: =IF(C26="","VM-"&TEXT(COUNTA($C$5:C26),"000")) | L26: =IFERROR(COUNTIF('5-Accidents du Travail'!C5:C104,C26),0) | M26: =IFERROR(COUNTIF('6-Maladies Prof.'!C5:C104,C26),0)
B27: =IF(C27="","VM-"&TEXT(COUNTA($C$5:C27),"000")) | L27: =IFERROR(COUNTIF('5-Accidents du Travail'!C5:C104,C27),0) | M27: =IFERROR(COUNTIF('6-Maladies Prof.'!C5:C104,C27),0)
B28: =IF(C28="","VM-"&TEXT(COUNTA($C$5:C28),"000")) | L28: =IFERROR(COUNTIF('5-Accidents du Travail'!C5:C104,C28),0) | M28: =IFERROR(COUNTIF('6-Maladies Prof.'!C5:C104,C28),0)
B29: =IF(C29="","VM-"&TEXT(COUNTA($C$5:C29),"000")) | L29: =IFERROR(COUNTIF('5-Accidents du Travail'!C5:C104,C29),0) | M29: =IFERROR(COUNTIF('6-Maladies Prof.'!C5:C104,C29),0)
B30: =IF(C30="","VM-"&TEXT(COUNTA($C$5:C30),"000")) | L30: =IFERROR(COUNTIF('5-Accidents du Travail'!C5:C104,C30),0) | M30: =IFERROR(COUNTIF('6-Maladies Prof.'!C5:C104,C30),0)
B31: =IF(C31="","VM-"&TEXT(COUNTA($C$5:C31),"000")) | L31: =IFERROR(COUNTIF('5-Accidents du Travail'!C5:C104,C31),0) | M31: =IFERROR(COUNTIF('6-Maladies Prof.'!C5:C104,C31),0)
B32: =IF(C32="","VM-"&TEXT(COUNTA($C$5:C32),"000")) | L32: =IFERROR(COUNTIF('5-Accidents du Travail'!C5:C104,C32),0) | M32: =IFERROR(COUNTIF('6-Maladies Prof.'!C5:C104,C32),0)
B33: =IF(C33="","VM-"&TEXT(COUNTA($C$5:C33),"000")) | L33: =IFERROR(COUNTIF('5-Accidents du Travail'!C5:C104,C33),0) | M33: =IFERROR(COUNTIF('6-Maladies Prof.'!C5:C104,C33),0)
B34: =IF(C34="","VM-"&TEXT(COUNTA($C$5:C34),"000")) | L34: =IFERROR(COUNTIF('5-Accidents du Travail'!C5:C104,C34),0) | M34: =IFERROR(COUNTIF('6-Maladies Prof.'!C5:C104,C34),0)
B35: =IF(C35="","VM-"&TEXT(COUNTA($C$5:C35),"000")) | L35: =IFERROR(COUNTIF('5-Accidents du Travail'!C5:C104,C35),0) | M35: =IFERROR(COUNTIF('6-Maladies Prof.'!C5:C104,C35),0)
B36: =IF(C36="","VM-"&TEXT(COUNTA($C$5:C36),"000")) | L36: =IFERROR(COUNTIF('5-Accidents du Travail'!C5:C104,C36),0) | M36: =IFERROR(COUNTIF('6-Maladies Prof.'!C5:C104,C36),0)
B37: =IF(C37="","VM-"&TEXT(COUNTA($C$5:C37),"000")) | L37: =IFERROR(COUNTIF('5-Accidents du Travail'!C5:C104,C37),0) | M37: =IFERROR(COUNTIF('6-Maladies Prof.'!C5:C104,C37),0)
B38: =IF(C38="","VM-"&TEXT(COUNTA($C$5:C38),"000")) | L38: =IFERROR(COUNTIF('5-Accidents du Travail'!C5:C104,C38),0) | M38: =IFERROR(COUNTIF('6-Maladies Prof.'!C5:C104,C38),0)
B39: =IF(C39="","VM-"&TEXT(COUNTA($C$5:C39),"000")) | L39: =IFERROR(COUNTIF('5-Accidents du Travail'!C5:C104,C39),0) | M39: =IFERROR(COUNTIF('6-Maladies Prof.'!C5:C104,C39),0)
B40: =IF(C40="","VM-"&TEXT(COUNTA($C$5:C40),"000")) | L40: =IFERROR(COUNTIF('5-Accidents du Travail'!C5:C104,C40),0) | M40: =IFERROR(COUNTIF('6-Maladies Prof.'!C5:C104,C40),0)
B41: =IF(C41="","VM-"&TEXT(COUNTA($C$5:C41),"000")) | L41: =IFERROR(COUNTIF('5-Accidents du Travail'!C5:C104,C41),0) | M41: =IFERROR(COUNTIF('6-Maladies Prof.'!C5:C104,C41),0)
...

Sheet 8-Fiche Poste Risques
B2: FICHE DE POSTE - RISQUES PROFESSIONNELS (#103)
B3: TABLEAU DYNAMIQUE — Saisissez dans la prochaine ligne jaune. Les calculs se mettent a jour automatiquement.
B4: N° | C4: Poste | D4: Departement | E4: Risques Principaux | F4: EPI Requis | G4: Formation Requise | H4: Frequence Exposition | I4: Niveau Global Risque
B5: FPR-001 | C5: Cuisinier | D5: Cuisine & Restauration | E5: Thermique, incendie, chimique, TMS | F5: Gants thermiques, tablier, chaussures | G5: Incendie, HACCP, manip chaud | H5: Quotidienne | I5: Eleve
B6: FPR-002 | C6: Plongeur | D6: Cuisine & Restauration | E6: Chimique, TMS, glissade | F6: Gants, lunettes, bottes | G6: Manip produits, securite sol | H6: Quotidienne | I6: Moyen
B7: FPR-003 | C7: Agent Entretien | D7: Maintenance | E7: Electrique, chute hauteur, chimique, TMS | F7: EPI electrique, harnais, gants | G7: Habilitation electrique, travail hauteur | H7: Quotidienne | I7: Eleve
B8: FPR-004 | C8: Agent Securite | D8: Sécurité | E8: Psychosocial, agression, travail nuit | F8: Gilet haute visibilite, radio | G8: Gestion conflits, secourisme | H8: Quotidienne | I8: Moyen
B9: FPR-005 | C9: Receptionniste | D9: Réception & Front Office | E9: Psychosocial, TMS (poste assis) | F9: Aucun specifique | G9: Gestion stress, ergonomie poste | H9: Reguliere | I9: Faible
B10: FPR-006 | C10: Technicien IT | D10: Maintenance | E10: Electrique, TMS, visuel | F10: Aucun specifique | G10: Secourisme, ergonomie ecran | H10: Reguliere | I10: Faible
B11: =IF(C11="","FPR-"&TEXT(COUNTA($C$5:C11),"000"))
B12: =IF(C12="","FPR-"&TEXT(COUNTA($C$5:C12),"000"))
B13: =IF(C13="","FPR-"&TEXT(COUNTA($C$5:C13),"000"))
B14: =IF(C14="","FPR-"&TEXT(COUNTA($C$5:C14),"000"))
B15: =IF(C15="","FPR-"&TEXT(COUNTA($C$5:C15),"000"))
B16: =IF(C16="","FPR-"&TEXT(COUNTA($C$5:C16),"000"))
B17: =IF(C17="","FPR-"&TEXT(COUNTA($C$5:C17),"000"))
B18: =IF(C18="","FPR-"&TEXT(COUNTA($C$5:C18),"000"))
B19: =IF(C19="","FPR-"&TEXT(COUNTA($C$5:C19),"000"))
B20: =IF(C20="","FPR-"&TEXT(COUNTA($C$5:C20),"000"))
B21: =IF(C21="","FPR-"&TEXT(COUNTA($C$5:C21),"000"))
B22: =IF(C22="","FPR-"&TEXT(COUNTA($C$5:C22),"000"))
... B110: =IF(C110="","FPR-"&TEXT(COUNTA($C$5:C110),"000"))
B112: INDICATEURS (mis a jour automatiquement)
B113: Fiches de poste | D113: Risque eleve+ | F113: Risque faible | H113: Exposition quotidienne
B114: =COUNTIF(B5:B104,"<>") | D114: =COUNTIF(I5:I104,"Eleve")+COUNTIF(I5:I104,"Tres eleve") | F114: =COUNTIF(I5:I104,"Faible") | H114: =COUNTIF(H5:H104,"Quotidienne")

Sheet 9-Gestion EPI
B2: GESTION DES EQUIPEMENTS DE PROTECTION INDIVIDUELLE (#104)
B3: TABLEAU DYNAMIQUE — Saisissez dans la prochaine ligne jaune. Les calculs se mettent a jour automatiquement.
B4: N° | C4: Type EPI | D4: Marque / Modele | E4: Quantite en Stock | F4: Quantite Attribuee | G4: A Replacer | H4: Date Dernier Approvision. | I4: Fournisseur | J4: Cout Unitaire (FCFA) | K4: Departement Dest. | L4: Statut
B5: EPI-001 | C5: Gants thermiques | D5: HeatPro X200 | E5: 20 | F5: 15 | G5: 5 | H5: 45778 | I5: SecuPro SARL | J5: 5000 | K5: Cuisine & Restauration | L5: En stock
B6: EPI-002 | C6: Chaussures de securite | D6: SafeStep Pro | E6: 30 | F6: 28 | G6: 2 | H6: 45762 | I6: EquipPro | J6: 12000 | K6: Maintenance | L6: En stock
B7: EPI-003 | C7: Masque respiratoire | D7: RespiGuard FFP2 | E7: 50 | F7: 40 | G7: 10 | H7: 45809 | I7: MediMask | J7: 1500 | K7: Maintenance | L7: En stock
B8: EPI-004 | C8: Harnais securite | D8: AltiSafe H-300 | E8: 4 | F8: 4 | G8: 0 | H8: 45717 | I8: HeightPro | J8: 45000 | K8: Maintenance | L8: A remplacer
B9: EPI-005 | C9: Gants nitrile (boite 100) | D9: NitraGuard | E9: 80 | F9: 65 | G9: 15 | H9: 45818 | I9: MediMask | J9: 3500 | K9: Cuisine & Restauration | L9: En stock
B10: EPI-006 | C10: Lunettes protection | D10: ClearVision Pro | E10: 15 | F10: 12 | G10: 3 | H10: 45797 | I10: SecuPro SARL | J10: 8000 | K10: Cuisine & Restauration | L10: En stock
B11: =IF(C11="","EPI-"&TEXT(COUNTA($C$5:C11),"000")) | G11: =IF(E11="","",E11-F11)
B12: =IF(C12="","EPI-"&TEXT(COUNTA($C$5:C12),"000")) | G12: =IF(E12="","",E12-F12)
B13: =IF(C13="","EPI-"&TEXT(COUNTA($C$5:C13),"000")) | G13: =IF(E13="","",E13-F13)
B14: =IF(C14="","EPI-"&TEXT(COUNTA($C$5:C14),"000")) | G14: =IF(E14="","",E14-F14)
B15: =IF(C15="","EPI-"&TEXT(COUNTA($C$5:C15),"000")) | G15: =IF(E15="","",E15-F15)
B16: =IF(C16="","EPI-"&TEXT(COUNTA($C$5:C16),"000")) | G16: =IF(E16="","",E16-F16)
B17: =IF(C17="","EPI-"&TEXT(COUNTA($C$5:C17),"000")) | G17: =IF(E17="","",E17-F17)
B18: =IF(C18="","EPI-"&TEXT(COUNTA($C$5:C18),"000")) | G18: =IF(E18="","",E18-F18)
B19: =IF(C19="","EPI-"&TEXT(COUNTA($C$5:C19),"000")) | G19: =IF(E19="","",E19-F19)
B20: =IF(C20="","EPI-"&TEXT(COUNTA($C$5:C20),"000")) | G20: =IF(E20="","",E20-F20)
B21: =IF(C21="","EPI-"&TEXT(COUNTA($C$5:C21),"000")) | G21: =IF(E21="","",E21-F21)
B22: =IF(C22="","EPI-"&TEXT(COUNTA($C$5:C22),"000")) | G22: =IF(E22="","",E22-F22)
... B110: =IF(C110="","EPI-"&TEXT(COUNTA($C$5:C110),"000")) | G110: =IF(E110="","",E110-F110)
B112: TOTAL | E112: =SUM(E5:E104) | F112: =SUM(F5:F104) | G112: =SUM(G5:G104)
B114: INDICATEURS (mis a jour automatiquement)
B115: Types EPI | D115: Total en stock | F115: Total attribues | H115: A remplacer
B116: Total EPI | D116: =COUNTIF(B5:B104,"<>") | F116: =SUM(F5:F104) | H116: =COUNTIF(L5:L104,"A remplacer")
B117: A remplacer | D117: =COUNTIF(L5:L104,"A remplacer")
B118: En stock | D118: =COUNTIF(L5:L104,"En stock")
B119: Total Qté Stock | D119: =SUM(E5:E104)
B120: Total Qté Attribuée | D120: =SUM(F5:F104)

Sheet 10-Consignes Securite
B2: CONSIGNES DE SECURITE (#105)
B3: TABLEAU DYNAMIQUE — Saisissez dans la prochaine ligne jaune. Les calculs se mettent a jour automatiquement.
B4: N° | C4: Type Consigne | D4: Titre | E4: Departement Concerne | F4: Postes Concernes | G4: Contenu Resume | H4: Date Mise en Vigueur | I4: Date Revision | J4: Statut
B5: CS-001 | C5: Procedure urgence | D5: Procedure evacuation incendie | E5: Tous | F5: Tous | G5: Sonnerie alarme + issue secours + point rassemblement | H5: 45292 | I5: 46023 | J5: En vigueur
B6: CS-002 | C6: Consigne specifique poste | D6: Manipulation produits chimiques cuisine | E6: Cuisine & Restauration | F6: Cuisinier, Plongeur | G6: Port EPI obligatoire, ventilation, stockage | H6: 45366 | I6: 45915 | J6: En vigueur
B7: CS-003 | C7: Permis de feu | D7: Travaux de soudure / meuleuse | E7: Maintenance | F7: Agent Entretien | G7: Surveillance 30min apres, extincteur a proximite | H7: 45444 | I7: 45992 | J7: En vigueur
B8: CS-004 | C8: Permis de travail en hauteur | D8: Travaux > 3 metres | E8: Maintenance | F8: Agent Entretien | G8: Harnais obligatoire, 2 personnes min, balisage | H8: 45444 | I8: 45809 | J8: A revoir
B9: CS-005 | C9: Consigne generale | D9: Regles hygiene et securite alimentaire | E9: Cuisine & Restauration | F9: Cuisinier, Plongeur | G9: Lavage mains, port charlotte, temperature | H9: 45292 | I9: 46022 | J9: En vigueur
B10: =IF(C10="","CS-"&TEXT(COUNTA($C$5:C10),"000"))
B11: =IF(C11="","CS-"&TEXT(COUNTA($C$5:C11),"000"))
B12: =IF(C12="","CS-"&TEXT(COUNTA($C$5:C12),"000"))
B13: =IF(C13="","CS-"&TEXT(COUNTA($C$5:C13),"000"))
B14: =IF(C14="","CS-"&TEXT(COUNTA($C$5:C14),"000"))
B15: =IF(C15="","CS-"&TEXT(COUNTA($C$5:C15),"000"))
B16: =IF(C16="","CS-"&TEXT(COUNTA($C$5:C16),"000"))
B17: =IF(C17="","CS-"&TEXT(COUNTA($C$5:C17),"000"))
B18: =IF(C18="","CS-"&TEXT(COUNTA($C$5:C18),"000"))
B19: =IF(C19="","CS-"&TEXT(COUNTA($C$5:C19),"000"))
B20: =IF(C20="","CS-"&TEXT(COUNTA($C$5:C20),"000"))
B21: =IF(C21="","CS-"&TEXT(COUNTA($C$5:C21),"000"))
... B109: =IF(C109="","CS-"&TEXT(COUNTA($C$5:C109),"000"))
B111: INDICATEURS (mis a jour automatiquement)
B112: Consignes | D112: En vigueur | F112: A revoir | H112: Obsoletes
B113: =COUNTIF(B5:B104,"<>") | D113: =COUNTIF(J5:J104,"En vigueur") | F113: =COUNTIF(J5:J104,"A revoir") | H113: =COUNTIF(J5:J104,"Obsolette")

Sheet 11-Audit Inspection Secur.
B2: AUDIT & INSPECTION SECURITE (#106)
B3: TABLEAU DYNAMIQUE — Saisissez dans la prochaine ligne jaune. Les calculs se mettent a jour automatiquement.
B4: N° | C4: Type Audit | D4: Zone / Departement | E4: Date Inspection | F4: Inspecteur | G4: Nb Constats | H4: Nb Critiques | I4: Actions Correctives | J4: Echeance Actions | K4: Suivi Realise | L4: Statut
B5: AUD-001 | C5: Audit securite cuisine | D5: Cuisine & Restauration | E5: 45757 | F5: Chef Securite + CHSCT | G5: 8 | H5: 3 | I5: 3 actions correctives identifiees | J5: 45848 | K5: Oui | L5: Valide
B6: AUD-002 | C6: Inspection EPI | D6: Maintenance | E6: 45792 | F6: Chef Securite | G6: 5 | H6: 2 | I6: Remplacer 2 harnais + commander gants | J6: 45838 | K6: En cours | L6: Approuve
B7: AUD-003 | C7: Audit incendie | D7: Tous | E7: 45717 | F7: Chef Securite + Sapeurs-pompiers | G7: 12 | H7: 4 | I7: Reviser 4 extincteurs + formation evacuation | J7: 45838 | K7: Oui | L7: Approuve
B8: AUD-004 | C8: Inspection electrique | D8: Maintenance | E8: 45813 | F8: Technicien externe | G8: 6 | H8: 2 | I8: Remettre aux normes 2 prises + 1 tableau | J8: 45900 | K8: Non | L8: Brouillon
B9: =IF(C9="","AUD-"&TEXT(COUNTA($C$5:C9),"000"))
B10: =IF(C10="","AUD-"&TEXT(COUNTA($C$5:C10),"000"))
B11: =IF(C11="","AUD-"&TEXT(COUNTA($C$5:C11),"000"))
B12: =IF(C12="","AUD-"&TEXT(COUNTA($C$5:C12),"000"))
B13: =IF(C13="","AUD-"&TEXT(COUNTA($C$5:C13),"000"))
B14: =IF(C14="","AUD-"&TEXT(COUNTA($C$5:C14),"000"))
B15: =IF(C15="","AUD-"&TEXT(COUNTA($C$5:C15),"000"))
B16: =IF(C16="","AUD-"&TEXT(COUNTA($C$5:C16),"000"))
B17: =IF(C17="","AUD-"&TEXT(COUNTA($C$5:C17),"000"))
B18: =IF(C18="","AUD-"&TEXT(COUNTA($C$5:C18),"000"))
B19: =IF(C19="","AUD-"&TEXT(COUNTA($C$5:C19),"000"))
