Workbook

Sheet F01 - _Données Centrales
A2: DOMAINE 28 — GESTION DE LA MOBILITÉ PROFESSIONNELLE, PLAN DE CARRIÈRE ET SUCCESSION
A3: DONNÉES CENTRALES — Base de référence (toutes les feuilles s'y réfèrent)
A5: Code Employé | B5: Nom & Prénoms | C5: Département | D5: Poste Actuel | E5: Grade | F5: Échelon | G5: Ancienneté (ans) | H5: Date Dernière Promotion | I5: Potentiel | J5: Performance | K5: Statut Carrière | L5: Successeur Désigné | M5: Plan Mobilité | N5: Budget Formation (FCFA) | O5: Manager | P5: Statut
A6: EMP-001 | B6: M. Nkoulou Paul | C6: Direction Générale | D6: Directeur Général | E6: A1 | F6: Éch. 5 | G6: 22 | H6: 2023-01-15 | I6: Très élevé | J6: Excellent | K6: En poste | L6: M. Eyenga | M6: Maintien | N6: 5000000 | O6: Conseil Administration | P6: Actif
A7: EMP-002 | B7: Mme. Mbarga Claire | C7: Ressources Humaines | D7: DRH | E7: B1 | F7: Éch. 4 | G7: 15 | H7: 2022-06-01 | I7: Élevé | J7: Excellent | K7: En poste | L7: Mme. Essomba | M7: Promotion DG | N7: 3500000 | O7: DG | P7: Actif
A8: EMP-003 | B8: M. Eyenga René | C8: Finance & Comptabilité | D8: DAF | E8: B1 | F8: Éch. 4 | G8: 18 | H8: 2022-09-01 | I8: Élevé | J8: Très bon | K8: En poste | L8: M. Fotso | M8: Promotion DG | N8: 3000000 | O8: DG | P8: Actif
A9: EMP-004 | B9: M. Tchinda Jean | C9: Cuisine & Restauration | D9: Chef Cuisinier | E9: C2 | F9: Éch. 3 | G9: 8 | H9: 2023-03-10 | I9: Moyen | J9: Bon | K9: Mobilité demandée | M9: Mutation Technique | N9: 800000 | O9: DRH | P9: Actif
A10: EMP-005 | B10: Mme. Ngassa Marie | C10: Réception & Front Office | D10: Responsable Réception | E10: C1 | F10: Éch. 3 | G10: 10 | H10: 2023-07-01 | I10: Élevé | J10: Bon | K10: En poste | L10: M. Obama | M10: Promotion | N10: 1200000 | O10: DRH | P10: Actif
A11: EMP-006 | B11: M. Ondo Ferdinand | C11: Maintenance & Technique | D11: Chef Maintenance | E11: C1 | F11: Éch. 3 | G11: 12 | H11: 2022-12-15 | I11: Élevé | J11: Très bon | K11: En poste | L11: M. Ndong | M11: Maintien | N11: 1000000 | O11: DG | P11: Actif
A12: EMP-007 | B12: Mme. Essomba Sylvie | C12: Ressources Humaines | D12: Resp. Recrutement | E12: D1 | F12: Éch. 2 | G12: 6 | H12: 2024-01-10 | I12: Très élevé | J12: Excellent | K12: Succession prête | M12: Promotion DRH | N12: 2000000 | O12: DRH | P12: Actif
A13: EMP-008 | B13: M. Fotso Alain | C13: Finance & Comptabilité | D13: Chef Comptable | E13: D1 | F13: Éch. 2 | G13: 7 | H13: 2023-11-01 | I13: Élevé | J13: Très bon | K13: En poste | M13: Promotion DAF | N13: 1500000 | O13: DAF | P13: Actif
A14: EMP-009 | B14: M. Obama Samuel | C14: Réception & Front Office | D14: Réceptionniste Senior | E14: D2 | F14: Éch. 1 | G14: 4 | H14: 2024-03-01 | I14: Moyen | J14: Bon | K14: Mobilité demandée | M14: Mutation Réception | N14: 500000 | O14: Resp. Réception | P14: Actif
A15: EMP-010 | B15: M. Ndong Aurélien | C15: Maintenance & Technique | D15: Technicien Senior | E15: D2 | F15: Éch. 1 | G15: 5 | H15: 2024-02-15 | I15: Moyen | J15: Bon | K15: En formation | M15: Promotion Chef | N15: 700000 | O15: Chef Maint. | P15: Actif
A16: EMP-011 | B16: Mme. Beyala Aïcha | C16: Ressources Humaines | D16: Assistante RH | E16: E1 | F16: Éch. 1 | G16: 3 | H16: 2024-06-01 | I16: Élevé | J16: Très bon | K16: En poste | M16: Promotion | N16: 400000 | O16: DRH | P16: Actif
A17: EMP-012 | B17: M. Manga Patrick | C17: Cuisine & Restauration | D17: Second Cuisinier | E17: D2 | F17: Éch. 1 | G17: 5 | H17: 2023-08-20 | I17: Moyen | J17: Bon | K17: Mobilité demandée | M17: Mutation Resto | N17: 600000 | O17: Chef Cuisin. | P17: Actif
A18: EMP-013 | B18: Mme. Tchakounté Nadège | C18: Direction Générale | D18: Assistante de Direction | E18: D1 | F18: Éch. 2 | G18: 9 | H18: 2023-05-15 | I18: Élevé | J18: Excellent | K18: En poste | M18: Maintien | N18: 350000 | O18: DG | P18: Actif
A19: EMP-014 | B19: M. Nganou Eric | C19: Finance & Comptabilité | D19: Comptable Junior | E19: E2 | F19: Éch. 1 | G19: 2 | H19: 2024-09-01 | I19: Moyen | J19: Satisfaisant | K19: En formation | M19: Formation continue | N19: 300000 | O19: Chef Comptab. | P19: Actif
A20: EMP-015 | B20: Mme. Fomba Hélène | C20: Réception & Front Office | D20: Standardiste | E20: E1 | F20: Éch. 1 | G20: 1 | H20: 2025-01-10 | I20: À évaluer | J20: Satisfaisant | K20: Nouvellement recrutée | M20: Intégration | N20: 200000 | O20: Resp. Réception | P20: Actif

Sheet F02 - _Lists
A2: DOMAINE 28 — LISTES DE RÉFÉRENCE
A3: 21 listes déroulantes pour toutes les feuilles (colonnes A à U, lignes 6 à 35)
A5: Départements | B5: Postes | C5: Grades | D5: Potentiel | E5: Performance | F5: Statut Carrière | G5: Type Mobilité | H5: Motif Mobilité | I5: Priorité Succession | J5: Statut Formation | K5: Niveau Compétence | L5: Type Contrat International | M5: Statut Mentorat | N5: Fréquence Entretien | O5: Catégorie Budget | P5: Statut Demande | Q5: Risque Départ | R5: Action Plan | S5: Période Évaluation | T5: Statut Audit | U5: Conformité
A6: Direction Générale | B6: Directeur Général | C6: A1 | D6: Très élevé | E6: Excellent | F6: En poste | G6: Promotion | H6: Développement carrière | I6: Critique - 0-6 mois | J6: Planifiée | K6: Expert | L6: Expatriation | M6: Actif | N6: Mensuel | O6: Formation | P6: Approuvée | Q6: Très élevé | R6: Formation accélérée | S6: Q1 2025 | T6: Conforme | U6: 100%
A7: Ressources Humaines | B7: DRH | C7: A2 | D7: Élevé | E7: Très bon | F7: Mobilité demandée | G7: Mutation | H7: Élargissement compétences | I7: Élevée - 6-12 mois | J7: En cours | K7: Avancé | L7: Détachement | M7: En pause | N7: Trimestriel | O7: Mobilité | P7: En attente validation | Q7: Élevé | R7: Mentorat assigné | S7: Q2 2025 | T7: Non conforme | U7: 75-99%
A8: Finance & Comptabilité | B8: DAF | C8: B1 | D8: Moyen | E8: Bon | F8: Succession prête | G8: Mutation Technique | H8: Raisons personnelles | I8: Moyenne - 1-2 ans | J8: Terminée | K8: Intermédiaire | L8: Mission courte | M8: Terminé | N8: Semestriel | O8: Coaching | P8: Rejetée | Q8: Moyen | R8: Plan de transition | S8: Q3 2025 | T8: Partiellement conforme | U8: 50-74%
A9: Cuisine & Restauration | B9: Chef Cuisinier | C9: B2 | D9: Faible | E9: Satisfaisant | F9: En formation | G9: Détachement | H9: Réorganisation | I9: Faible - 2+ ans | J9: Reportée | K9: Débutant | L9: V.I.E. | M9: Planifié | N9: Annuel | O9: Mentorat | P9: En cours de traitement | Q9: Faible | R9: Recrutement externe | S9: Q4 2025 | T9: En cours de vérification | U9: 25-49%
A10: Réception & Front Office | B10: Responsable Réception | C10: C1 | D10: À évaluer | E10: Insuffisant | F10: Nouvellement recruté | G10: Mobilité Internationale | H10: Succession | I10: Non identifiée | J10: Annulée | K10: À développer | L10: Consultation technique | M10: Non démarré | N10: Bisannuel | O10: Audit externe | P10: Reportée | R10: Reclassification | S10: Annuel 2025 | T10: Non évalué | U10: < 25%
A11: Maintenance & Technique | B11: Chef Maintenance | C11: C2 | F11: En transition | G11: Rotation | H11: Performance | O11: Outils RH
A12: Service Commercial | B12: Resp. Recrutement | C12: D1 | F12: En attente | G12: Réintégration | H12: Initiative management | O12: Évaluation
A13: Service Juridique | B13: Chef Comptable | C13: D2 | G13: Maintien
B14: Réceptionniste Senior | C14: E1
B15: Technicien Senior | C15: E2
B16: Assistante RH
B17: Second Cuisinier
B18: Assistante Direction
B19: Comptable Junior
B20: Standardiste

Sheet F03 - 1-TdB Mobilité & Carrière
A2: DOMAINE 28 — TABLEAU DE BORD MOBILITÉ & CARRIÈRE
A3: Vue synthétique des indicateurs clés de mobilité et de gestion des carrières
A5: Effectif Total Suivi | B5: En Poste | C5: Mobilité Demandée | D5: Succession Prête | E5: En Formation | F5: Potentiel Élevé+ | G5: Performance Excellent/TB | H5: Budget Total Formation | I5: Taux Mobilité (%) | J5: Taux Successeurs (%)
A6: =COUNTA('F01 - _Données Centrales'!A6:A20) | B6: =COUNTIF('F01 - _Données Centrales'!K6:K20,"En poste") | C6: =COUNTIF('F01 - _Données Centrales'!K6:K20,"Mobilité demandée") | D6: =COUNTIF('F01 - _Données Centrales'!K6:K20,"Succession prête") | E6: =COUNTIF('F01 - _Données Centrales'!K6:K20,"En formation") | F6: =COUNTIF('F01 - _Données Centrales'!I6:I20,"Élevé")+COUNTIF('F01 - _Données Centrales'!I6:I20,"Très élevé") | G6: =COUNTIF('F01 - _Données Centrales'!J6:J20,"Excellent")+COUNTIF('F01 - _Données Centrales'!J6:J20,"Très bon") | H6: =SUM('F01 - _Données Centrales'!N6:N20) | I6: =IFERROR(C6/A6,0) | J6: =IFERROR(D6/A6,0)

Sheet F04 - 2-Registre Dem. Mobilité
A2: DOMAINE 28 — REGISTRE DES DEMANDES DE MOBILITÉ
A3: Suivi de toutes les demandes de mobilité interne et externe
A5: N° Demande | B5: Code Employé | C5: Nom Employé | D5: Département Origine | E5: Département Destination | F5: Type Mobilité | G5: Motif | H5: Date Demande | I5: Date Souhaitee | J5: Statut | K5: Priorité | L5: Validateur | M5: Observations
A6: DM-2025-001 | B6: EMP-004 | C6: =IFERROR(VLOOKUP(B6,'F01 - _Données Centrales'!A6:B20,2,FALSE),"") | D6: =IFERROR(VLOOKUP(B6,'F01 - _Données Centrales'!A6:C20,3,FALSE),"") | E6: Maintenance & Technique | F6: Mutation Technique | G6: Développement carrière | H6: 2025-01-15 | I6: 2025-04-01 | J6: Approuvée | K6: Normale | L6: DRH | M6: Élargissement vers technique
A7: DM-2025-002 | B7: EMP-009 | C7: =IFERROR(VLOOKUP(B7,'F01 - _Données Centrales'!A6:B20,2,FALSE),"") | D7: =IFERROR(VLOOKUP(B7,'F01 - _Données Centrales'!A6:C20,3,FALSE),"") | E7: Cuisine & Restauration | F7: Mutation | G7: Élargissement compétences | H7: 2025-02-01 | I7: 2025-05-01 | J7: En attente validation | K7: Haute | L7: DRH | M7: Polyvalence souhaitée
A8: DM-2025-003 | B8: EMP-012 | C8: =IFERROR(VLOOKUP(B8,'F01 - _Données Centrales'!A6:B20,2,FALSE),"") | D8: =IFERROR(VLOOKUP(B8,'F01 - _Données Centrales'!A6:C20,3,FALSE),"") | E8: Réception & Front Office | F8: Mutation | G8: Raisons personnelles | H8: 2025-03-10 | I8: 2025-06-01 | J8: En cours de traitement | K8: Normale | L8: DRH | M8: Rapprochement géographique
A9: DM-2025-004 | B9: EMP-007 | C9: =IFERROR(VLOOKUP(B9,'F01 - _Données Centrales'!A6:B20,2,FALSE),"") | D9: =IFERROR(VLOOKUP(B9,'F01 - _Données Centrales'!A6:C20,3,FALSE),"") | E9: Direction Générale | F9: Promotion | G9: Succession | H9: 2025-01-20 | I9: 2025-07-01 | J9: Approuvée | K9: Haute | L9: DG | M9: Plan de succession DRH
A10: DM-2025-005 | B10: EMP-010 | C10: =IFERROR(VLOOKUP(B10,'F01 - _Données Centrales'!A6:B20,2,FALSE),"") | D10: =IFERROR(VLOOKUP(B10,'F01 - _Données Centrales'!A6:C20,3,FALSE),"") | E10: Maintenance & Technique | F10: Promotion | G10: Développement carrière | H10: 2025-04-01 | I10: 2025-10-01 | J10: En attente validation | K10: Normale | L10: Chef Maint. | M10: Plan de transition 6 mois
A11: =IF(A10="","",A10) | C11: =IFERROR(VLOOKUP(B11,'F01 - _Données Centrales'!A6:B20,2,FALSE),"") | D11: =IFERROR(VLOOKUP(B11,'F01 - _Données Centrales'!A6:C20,3,FALSE),"")
A12: =IF(A11="","",A11) | C12: =IFERROR(VLOOKUP(B12,'F01 - _Données Centrales'!A6:B20,2,FALSE),"") | D12: =IFERROR(VLOOKUP(B12,'F01 - _Données Centrales'!A6:C20,3,FALSE),"")
A13: =IF(A12="","",A12) | C13: =IFERROR(VLOOKUP(B13,'F01 - _Données Centrales'!A6:B20,2,FALSE),"") | D13: =IFERROR(VLOOKUP(B13,'F01 - _Données Centrales'!A6:C20,3,FALSE),"")
A14: =IF(A13="","",A13) | C14: =IFERROR(VLOOKUP(B14,'F01 - _Données Centrales'!A6:B20,2,FALSE),"") | D14: =IFERROR(VLOOKUP(B14,'F01 - _Données Centrales'!A6:C20,3,FALSE),"")
A15: =IF(A14="","",A14) | C15: =IFERROR(VLOOKUP(B15,'F01 - _Données Centrales'!A6:B20,2,FALSE),"") | D15: =IFERROR(VLOOKUP(B15,'F01 - _Données Centrales'!A6:C20,3,FALSE),"")
A16: =IF(A15="","",A15) | C16: =IFERROR(VLOOKUP(B16,'F01 - _Données Centrales'!A6:B20,2,FALSE),"") | D16: =IFERROR(VLOOKUP(B16,'F01 - _Données Centrales'!A6:C20,3,FALSE),"")
A17: =IF(A16="","",A16) | C17: =IFERROR(VLOOKUP(B17,'F01 - _Données Centrales'!A6:B20,2,FALSE),"") | D17: =IFERROR(VLOOKUP(B17,'F01 - _Données Centrales'!A6:C20,3,FALSE),"")
A18: =IF(A17="","",A17) | C18: =IFERROR(VLOOKUP(B18,'F01 - _Données Centrales'!A6:B20,2,FALSE),"") | D18: =IFERROR(VLOOKUP(B18,'F01 - _Données Centrales'!A6:C20,3,FALSE),"")
A19: =IF(A18="","",A18) | C19: =IFERROR(VLOOKUP(B19,'F01 - _Données Centrales'!A6:B20,2,FALSE),"") | D19: =IFERROR(VLOOKUP(B19,'F01 - _Données Centrales'!A6:C20,3,FALSE),"")
A20: =IF(A19="","",A19) | C20: =IFERROR(VLOOKUP(B20,'F01 - _Données Centrales'!A6:B20,2,FALSE),"") | D20: =IFERROR(VLOOKUP(B20,'F01 - _Données Centrales'!A6:C20,3,FALSE),"")
A21: =IF(A20="","",A20) | C21: =IFERROR(VLOOKUP(B21,'F01 - _Données Centrales'!A6:B20,2,FALSE),"") | D21: =IFERROR(VLOOKUP(B21,'F01 - _Données Centrales'!A6:C20,3,FALSE),"")
A22: =IF(A21="","",A21) | C22: =IFERROR(VLOOKUP(B22,'F01 - _Données Centrales'!A6:B20,2,FALSE),"") | D22: =IFERROR(VLOOKUP(B22,'F01 - _Données Centrales'!A6:C20,3,FALSE),"")
A23: =IF(A22="","",A22) | C23: =IFERROR(VLOOKUP(B23,'F01 - _Données Centrales'!A6:B20,2,FALSE),"") | D23: =IFERROR(VLOOKUP(B23,'F01 - _Données Centrales'!A6:C20,3,FALSE),"")
A24: =IF(A23="","",A23) | C24: =IFERROR(VLOOKUP(B24,'F01 - _Données Centrales'!A6:B20,2,FALSE),"") | D24: =IFERROR(VLOOKUP(B24,'F01 - _Données Centrales'!A6:C20,3,FALSE),"")
A25: =IF(A24="","",A24) | C25: =IFERROR(VLOOKUP(B25,'F01 - _Données Centrales'!A6:B20,2,FALSE),"") | D25: =IFERROR(VLOOKUP(B25,'F01 - _Données Centrales'!A6:C20,3,FALSE),"")
A26: =IF(A25="","",A25) | C26: =IFERROR(VLOOKUP(B26,'F01 - _Données Centrales'!A6:B20,2,FALSE),"") | D26: =IFERROR(VLOOKUP(B26,'F01 - _Données Centrales'!A6:C20,3,FALSE),"")
A27: =IF(A26="","",A26) | C27: =IFERROR(VLOOKUP(B27,'F01 - _Données Centrales'!A6:B20,2,FALSE),"") | D27: =IFERROR(VLOOKUP(B27,'F01 - _Données Centrales'!A6:C20,3,FALSE),"")
A28: =IF(A27="","",A27) | C28: =IFERROR(VLOOKUP(B28,'F01 - _Données Centrales'!A6:B20,2,FALSE),"") | D28: =IFERROR(VLOOKUP(B28,'F01 - _Données Centrales'!A6:C20,3,FALSE),"")
A29: =IF(A28="","",A28) | C29: =IFERROR(VLOOKUP(B29,'F01 - _Données Centrales'!A6:B20,2,FALSE),"") | D29: =IFERROR(VLOOKUP(B29,'F01 - _Données Centrales'!A6:C20,3,FALSE),"")
A30: =IF(A29="","",A29) | C30: =IFERROR(VLOOKUP(B30,'F01 - _Données Centrales'!A6:B20,2,FALSE),"") | D30: =IFERROR(VLOOKUP(B30,'F01 - _Données Centrales'!A6:C20,3,FALSE),"")
A31: =IF(A30="","",A30) | C31: =IFERROR(VLOOKUP(B31,'F01 - _Données Centrales'!A6:B20,2,FALSE),"") | D31: =IFERROR(VLOOKUP(B31,'F01 - _Données Centrales'!A6:C20,3,FALSE),"")
A32: =IF(A31="","",A31) | C32: =IFERROR(VLOOKUP(B32,'F01 - _Données Centrales'!A6:B20,2,FALSE),"") | D32: =IFERROR(VLOOKUP(B32,'F01 - _Données Centrales'!A6:C20,3,FALSE),"")
A33: =IF(A32="","",A32) | C33: =IFERROR(VLOOKUP(B33,'F01 - _Données Centrales'!A6:B20,2,FALSE),"") | D33: =IFERROR(VLOOKUP(B33,'F01 - _Données Centrales'!A6:C20,3,FALSE),"")
A34: =IF(A33="","",A33) | C34: =IFERROR(VLOOKUP(B34,'F01 - _Données Centrales'!A6:B20,2,FALSE),"") | D34: =IFERROR(VLOOKUP(B34,'F01 - _Données Centrales'!A6:C20,3,FALSE),"")
A35: =IF(A34="","",A34) | C35: =IFERROR(VLOOKUP(B35,'F01 - _Données Centrales'!A6:B20,2,FALSE),"") | D35: =IFERROR(VLOOKUP(B35,'F01 - _Données Centrales'!A6:C20,3,FALSE),"")
A36: =IF(A35="","",A35) | C36: =IFERROR(VLOOKUP(B36,'F01 - _Données Centrales'!A6:B20,2,FALSE),"") | D36: =IFERROR(VLOOKUP(B36,'F01 - _Données Centrales'!A6:C20,3,FALSE),"")
A37: =IF(A36="","",A36) | C37: =IFERROR(VLOOKUP(B37,'F01 - _Données Centrales'!A6:B20,2,FALSE),"") | D37: =IFERROR(VLOOKUP(B37,'F01 - _Données Centrales'!A6:C20,3,FALSE),"")
A38: =IF(A37="","",A37) | C38: =IFERROR(VLOOKUP(B38,'F01 - _Données Centrales'!A6:B20,2,FALSE),"") | D38: =IFERROR(VLOOKUP(B38,'F01 - _Données Centrales'!A6:C20,3,FALSE),"")
A39: =IF(A38="","",A38) | C39: =IFERROR(VLOOKUP(B39,'F01 - _Données Centrales'!A6:B20,2,FALSE),"") | D39: =IFERROR(VLOOKUP(B39,'F01 - _Données Centrales'!A6:C20,3,FALSE),"")
A40: =IF(A39="","",A39) | C40: =IFERROR(VLOOKUP(B40,'F01 - _Données Centrales'!A6:B20,2,FALSE),"") | D40: =IFERROR(VLOOKUP(B40,'F01 - _Données Centrales'!A6:C20,3,FALSE),"")
A41: =IF(A40="","",A40) | C41: =IFERROR(VLOOKUP(B41,'F01 - _Données Centrales'!A6:B20,2,FALSE),"") | D41: =IFERROR(VLOOKUP(B41,'F01 - _Données Centrales'!A6:C20,3,FALSE),"")
A42: =IF(A41="","",A41) | C42: =IFERROR(VLOOKUP(B42,'F01 - _Données Centrales'!A6:B20,2,FALSE),"") | D42: =IFERROR(VLOOKUP(B42,'F01 - _Données Centrales'!A6:C20,3,FALSE),"")
...

Sheet F05 - 3-Plan de Succession
A2: DOMAINE 28 — PLAN DE SUCCESSION DES POSTES CLÉS
A3: Identification des successeurs potentiels pour les postes stratégiques
A5: Code Poste | B5: Poste | C5: Département | D5: Titulaire Actuel | E5: Grade Titulaire | F5: Successeur 1 | G5: Potentiel Succ. 1 | H5: Successeur 2 | I5: Potentiel Succ. 2 | J5: Priorité Succ. | K5: Date Disponibilité | L5: Action Plan | M5: Statut Préparation | N5: Écart Compétences
A6: POSTE-001 | B6: Directeur Général | C6: Direction Générale | D6: M. Nkoulou Paul | E6: A1 | F6: Mme. Mbarga Claire | G6: Élevé | H6: M. Eyenga René | I6: Élevé | J6: Critique - 0-6 mois | K6: 2026-01-01 | L6: Formation accélérée | M6: En cours | N6: Leadership stratégique
A7: POSTE-002 | B7: DRH | C7: Ressources Humaines | D7: Mme. Mbarga Claire | E7: B1 | F7: Mme. Essomba Sylvie | G7: Très élevé | H7: Mme. Beyala Aïcha | I7: Élevé | J7: Élevée - 6-12 mois | K7: 2025-12-01 | L7: Mentorat assigné | M7: Avancée | N7: Gestion de la DRH
A8: POSTE-003 | B8: DAF | C8: Finance & Comptabilité | D8: M. Eyenga René | E8: B1 | F8: M. Fotso Alain | G8: Élevé | H8: M. Nganou Eric | I8: Moyen | J8: Moyenne - 1-2 ans | K8: 2026-06-01 | L8: Plan de transition | M8: En cours | N8: Vision financière globale
A9: POSTE-004 | B9: Chef Cuisinier | C9: Cuisine & Restauration | D9: M. Tchinda Jean | E9: C2 | F9: M. Manga Patrick | G9: Moyen | J9: Faible - 2+ ans | K9: 2027-01-01 | L9: Formation accélérée | M9: Non démarré | N9: Gestion équipe cuisine
A10: POSTE-005 | B10: Resp. Réception | C10: Réception & Front Office | D10: Mme. Ngassa Marie | E10: C1 | F10: M. Obama Samuel | G10: Moyen | H10: Mme. Fomba Hélène | I10: À évaluer | J10: Moyenne - 1-2 ans | K10: 2026-03-01 | L10: Plan de transition | M10: En cours | N10: Gestion réception
A11: =IF(A10="","",A10)
A12: =IF(A11="","",A11)
A13: =IF(A12="","",A12)
A14: =IF(A13="","",A13)
A15: =IF(A14="","",A14)
A16: =IF(A15="","",A15)
A17: =IF(A16="","",A16)
A18: =IF(A17="","",A17)
A19: =IF(A18="","",A18)
A20: =IF(A19="","",A19)
A21: =IF(A20="","",A20)
A22: =IF(A21="","",A21)
... A115: =IF(A114="","",A114)

Sheet F06 - 4-Cartographie Postes C.
A2: DOMAINE 28 — CARTOGRAPHIE DES POSTES ET COMPÉTENCES
A3: Mapping des compétences requises par poste et niveau de maîtrise
A5: Code Poste | B5: Poste | C5: Département | D5: Compétence Clé 1 | E5: Niveau Req. 1 | F5: Compétence Clé 2 | G5: Niveau Req. 2 | H5: Compétence Clé 3 | I5: Niveau Req. 3 | J5: Nb Titulaires | K5: Écart Moyen | L5: Action Développement | M5: Priorité
A6: POSTE-001 | B6: Directeur Général | C6: Direction Générale | D6: Leadership stratégique | E6: Expert | F6: Vision financière | G6: Expert | H6: Gouvernance | I6: Expert | J6: 1 | K6: Faible | L6: Mentorat externe | M6: Haute
A7: POSTE-002 | B7: DRH | C7: Ressources Humaines | D7: Droit du travail | E7: Expert | F7: Gestion des talents | G7: Expert | H7: Stratégie RH | I7: Avancé | J7: 1 | K7: Faible | L7: Formation continue | M7: Haute
A8: POSTE-003 | B8: DAF | C8: Finance & Comptabilité | D8: Comptabilité analytique | E8: Expert | F8: Gestion trésorerie | G8: Expert | H8: Fiscalité | I8: Avancé | J8: 1 | K8: Moyen | L8: Certification | M8: Haute
A9: POSTE-004 | B9: Chef Cuisinier | C9: Cuisine & Restauration | D9: Gastronomie | E9: Expert | F9: Hygiène alimentaire | G9: Expert | H9: Gestion équipe | I9: Avancé | J9: 1 | K9: Moyen | L9: Formation HACCP | M9: Moyenne
A10: POSTE-005 | B10: Resp. Réception | C10: Réception & Front Office | D10: Accueil client | E10: Expert | F10: Réservation | G10: Avancé | H10: Anglais | I10: Intermédiaire | J10: 1 | K10: Moyen | L10: Formation langue | M10: Moyenne
A11: =IF(A10="","",A10)
A12: =IF(A11="","",A11)
A13: =IF(A12="","",A12)
A14: =IF(A13="","",A13)
A15: =IF(A14="","",A14)
A16: =IF(A15="","",A15)
A17: =IF(A16="","",A16)
A18: =IF(A17="","",A17)
A19: =IF(A18="","",A18)
A20: =IF(A19="","",A19)
A21: =IF(A20="","",A20)
A22: =IF(A21="","",A21)
... A115: =IF(A114="","",A114)

Sheet F07 - 5-Évaluations Potentiel
A2: DOMAINE 28 — ÉVALUATIONS DU POTENTIEL
A3: Évaluation du potentiel de progression et de la readiness des collaborateurs
A5: Code Employé | B5: Nom | C5: Département | D5: Potentiel | E5: Performance | F5: Score Potentiel (/100) | G5: Score Perf. (/100) | H5: Score Combiné | I5: Catégorie 9-Box | J5: Évaluateur | K5: Date Évaluation | L5: Période | M5: Commentaire | N5: Action Recommandée
A6: EMP-001 | B6: =IFERROR(VLOOKUP(A6,'F01 - _Données Centrales'!A6:B20,2,FALSE),"") | C6: =IFERROR(VLOOKUP(A6,'F01 - _Données Centrales'!A6:C20,3,FALSE),"") | D6: Très élevé | E6: Excellent | F6: 95 | G6: 92 | H6: =IFERROR((F6+G6)/2,0) | I6: =IF(OR(F6="",G6=""),"",IF(AND(F6>=80,G6>=80),"Étoile",IF(AND(F6>=80,G6<80),"Problème de perf.",IF(AND(F6<80,G6>=80),"Travailleur fiable","Sous-performeur")))) | J6: DG | K6: 2025-03-01 | L6: Q1 2025 | M6: Leader inspirant, vision claire | N6: Maintien position clé
A7: EMP-002 | B7: =IFERROR(VLOOKUP(A7,'F01 - _Données Centrales'!A6:B20,2,FALSE),"") | C7: =IFERROR(VLOOKUP(A7,'F01 - _Données Centrales'!A6:C20,3,FALSE),"") | D7: Élevé | E7: Excellent | F7: 88 | G7: 90 | H7: =IFERROR((F7+G7)/2,0) | I7: =IF(OR(F7="",G7=""),"",IF(AND(F7>=80,G7>=80),"Étoile",IF(AND(F7>=80,G7<80),"Problème de perf.",IF(AND(F7<80,G7>=80),"Travailleur fiable","Sous-performeur")))) | J7: DG | K7: 2025-03-01 | L7: Q1 2025 | M7: Prête pour DG adjoint | N7: Accélérer plan succession
A8: EMP-003 | B8: =IFERROR(VLOOKUP(A8,'F01 - _Données Centrales'!A6:B20,2,FALSE),"") | C8: =IFERROR(VLOOKUP(A8,'F01 - _Données Centrales'!A6:C20,3,FALSE),"") | D8: Élevé | E8: Très bon | F8: 85 | G8: 82 | H8: =IFERROR((F8+G8)/2,0) | I8: =IF(OR(F8="",G8=""),"",IF(AND(F8>=80,G8>=80),"Étoile",IF(AND(F8>=80,G8<80),"Problème de perf.",IF(AND(F8<80,G8>=80),"Travailleur fiable","Sous-performeur")))) | J8: DG | K8: 2025-03-15 | L8: Q1 2025 | M8: Solide techniquement | N8: Renforcer leadership
A9: EMP-007 | B9: =IFERROR(VLOOKUP(A9,'F01 - _Données Centrales'!A6:B20,2,FALSE),"") | C9: =IFERROR(VLOOKUP(A9,'F01 - _Données Centrales'!A6:C20,3,FALSE),"") | D9: Très élevé | E9: Excellent | F9: 92 | G9: 91 | H9: =IFERROR((F9+G9)/2,0) | I9: =IF(OR(F9="",G9=""),"",IF(AND(F9>=80,G9>=80),"Étoile",IF(AND(F9>=80,G9<80),"Problème de perf.",IF(AND(F9<80,G9>=80),"Travailleur fiable","Sous-performeur")))) | J9: DRH | K9: 2025-02-20 | L9: Q1 2025 | M9: Étoile montante RH | N9: Programme haut potentiel
A10: EMP-005 | B10: =IFERROR(VLOOKUP(A10,'F01 - _Données Centrales'!A6:B20,2,FALSE),"") | C10: =IFERROR(VLOOKUP(A10,'F01 - _Données Centrales'!A6:C20,3,FALSE),"") | D10: Élevé | E10: Bon | F10: 82 | G10: 78 | H10: =IFERROR((F10+G10)/2,0) | I10: =IF(OR(F10="",G10=""),"",IF(AND(F10>=80,G10>=80),"Étoile",IF(AND(F10>=80,G10<80),"Problème de perf.",IF(AND(F10<80,G10>=80),"Travailleur fiable","Sous-performeur")))) | J10: DRH | K10: 2025-03-01 | L10: Q1 2025 | M10: Bonne progression | N10: Formation management
B11: =IFERROR(VLOOKUP(A11,'F01 - _Données Centrales'!A6:B20,2,FALSE),"") | C11: =IFERROR(VLOOKUP(A11,'F01 - _Données Centrales'!A6:C20,3,FALSE),"") | H11: =IFERROR((F11+G11)/2,0) | I11: =IF(OR(F11="",G11=""),"",IF(AND(F11>=80,G11>=80),"Étoile",IF(AND(F11>=80,G11<80),"Problème de perf.",IF(AND(F11<80,G11>=80),"Travailleur fiable","Sous-performeur"))))
B12: =IFERROR(VLOOKUP(A12,'F01 - _Données Centrales'!A6:B20,2,FALSE),"") | C12: =IFERROR(VLOOKUP(A12,'F01 - _Données Centrales'!A6:C20,3,FALSE),"") | H12: =IFERROR((F12+G12)/2,0) | I12: =IF(OR(F12="",G12=""),"",IF(AND(F12>=80,G12>=80),"Étoile",IF(AND(F12>=80,G12<80),"Problème de perf.",IF(AND(F12<80,G12>=80),"Travailleur fiable","Sous-performeur"))))
B13: =IFERROR(VLOOKUP(A13,'F01 - _Données Centrales'!A6:B20,2,FALSE),"") | C13: =IFERROR(VLOOKUP(A13,'F01 - _Données Centrales'!A6:C20,3,FALSE),"") | H13: =IFERROR((F13+G13)/2,0) | I13: =IF(OR(F13="",G13=""),"",IF(AND(F13>=80,G13>=80),"Étoile",IF(AND(F13>=80,G13<80),"Problème de perf.",IF(AND(F13<80,G13>=80),"Travailleur fiable","Sous-performeur"))))
B14: =IFERROR(VLOOKUP(A14,'F01 - _Données Centrales'!A6:B20,2,FALSE),"") | C14: =IFERROR(VLOOKUP(A14,'F01 - _Données Centrales'!A6:C20,3,FALSE),"") | H14: =IFERROR((F14+G14)/2,0) | I14: =IF(OR(F14="",G14=""),"",IF(AND(F14>=80,G14>=80),"Étoile",IF(AND(F14>=80,G14<80),"Problème de perf.",IF(AND(F14<80,G14>=80),"Travailleur fiable","Sous-performeur"))))
B15: =IFERROR(VLOOKUP(A15,'F01 - _Données Centrales'!A6:B20,2,FALSE),"") | C15: =IFERROR(VLOOKUP(A15,'F01 - _Données Centrales'!A6:C20,3,FALSE),"") | H15: =IFERROR((F15+G15)/2,0) | I15: =IF(OR(F15="",G15=""),"",IF(AND(F15>=80,G15>=80),"Étoile",IF(AND(F15>=80,G15<80),"Problème de perf.",IF(AND(F15<80,G15>=80),"Travailleur fiable","Sous-performeur"))))
B16: =IFERROR(VLOOKUP(A16,'F01 - _Données Centrales'!A6:B20,2,FALSE),"") | C16: =IFERROR(VLOOKUP(A16,'F01 - _Données Centrales'!A6:C20,3,FALSE),"") | H16: =IFERROR((F16+G16)/2,0) | I16: =IF(OR(F16="",G16=""),"",IF(AND(F16>=80,G16>=80),"Étoile",IF(AND(F16>=80,G16<80),"Problème de perf.",IF(AND(F16<80,G16>=80),"Travailleur fiable","Sous-performeur"))))
B17: =IFERROR(VLOOKUP(A17,'F01 - _Données Centrales'!A6:B20,2,FALSE),"") | C17: =IFERROR(VLOOKUP(A17,'F01 - _Données Centrales'!A6:C20,3,FALSE),"") | H17: =IFERROR((F17+G17)/2,0) | I17: =IF(OR(F17="",G17=""),"",IF(AND(F17>=80,G17>=80),"Étoile",IF(AND(F17>=80,G17<80),"Problème de perf.",IF(AND(F17<80,G17>=80),"Travailleur fiable","Sous-performeur"))))
B18: =IFERROR(VLOOKUP(A18,'F01 - _Données Centrales'!A6:B20,2,FALSE),"") | C18: =IFERROR(VLOOKUP(A18,'F01 - _Données Centrales'!A6:C20,3,FALSE),"") | H18: =IFERROR((F18+G18)/2,0) | I18: =IF(OR(F18="",G18=""),"",IF(AND(F18>=80,G18>=80),"Étoile",IF(AND(F18>=80,G18<80),"Problème de perf.",IF(AND(F18<80,G18>=80),"Travailleur fiable","Sous-performeur"))))
B19: =IFERROR(VLOOKUP(A19,'F01 - _Données Centrales'!A6:B20,2,FALSE),"") | C19: =IFERROR(VLOOKUP(A19,'F01 - _Données Centrales'!A6:C20,3,FALSE),"") | H19: =IFERROR((F19+G19)/2,0) | I19: =IF(OR(F19="",G19=""),"",IF(AND(F19>=80,G19>=80),"Étoile",IF(AND(F19>=80,G19<80),"Problème de perf.",IF(AND(F19<80,G19>=80),"Travailleur fiable","Sous-performeur"))))
B20: =IFERROR(VLOOKUP(A20,'F01 - _Données Centrales'!A6:B20,2,FALSE),"") | C20: =IFERROR(VLOOKUP(A20,'F01 - _Données Centrales'!A6:C20,3,FALSE),"") | H20: =IFERROR((F20+G20)/2,0) | I20: =IF(OR(F20="",G20=""),"",IF(AND(F20>=80,G20>=80),"Étoile",IF(AND(F20>=80,G20<80),"Problème de perf.",IF(AND(F20<80,G20>=80),"Travailleur fiable","Sous-performeur"))))
B21: =IFERROR(VLOOKUP(A21,'F01 - _Données Centrales'!A6:B20,2,FALSE),"") | C21: =IFERROR(VLOOKUP(A21,'F01 - _Données Centrales'!A6:C20,3,FALSE),"") | H21: =IFERROR((F21+G21)/2,0) | I21: =IF(OR(F21="",G21=""),"",IF(AND(F21>=80,G21>=80),"Étoile",IF(AND(F21>=80,G21<80),"Problème de perf.",IF(AND(F21<80,G21>=80),"Travailleur fiable","Sous-performeur"))))
B22: =IFERROR(VLOOKUP(A22,'F01 - _Données Centrales'!A6:B20,2,FALSE),"") | C22: =IFERROR(VLOOKUP(A22,'F01 - _Données Centrales'!A6:C20,3,FALSE),"") | H22: =IFERROR((F22+G22)/2,0) | I22: =IF(OR(F22="",G22=""),"",IF(AND(F22>=80,G22>=80),"Étoile",IF(AND(F22>=80,G22<80),"Problème de perf.",IF(AND(F22<80,G22>=80),"Travailleur fiable","Sous-performeur"))))
B23: =IFERROR(VLOOKUP(A23,'F01 - _Données Centrales'!A6:B20,2,FALSE),"") | C23: =IFERROR(VLOOKUP(A23,'F01 - _Données Centrales'!A6:C20,3,FALSE),"") | H23: =IFERROR((F23+G23)/2,0) | I23: =IF(OR(F23="",G23=""),"",IF(AND(F23>=80,G23>=80),"Étoile",IF(AND(F23>=80,G23<80),"Problème de perf.",IF(AND(F23<80,G23>=80),"Travailleur fiable","Sous-performeur"))))
B24: =IFERROR(VLOOKUP(A24,'F01 - _Données Centrales'!A6:B20,2,FALSE),"") | C24: =IFERROR(VLOOKUP(A24,'F01 - _Données Centrales'!A6:C20,3,FALSE),"") | H24: =IFERROR((F24+G24)/2,0) | I24: =IF(OR(F24="",G24=""),"",IF(AND(F24>=80,G24>=80),"Étoile",IF(AND(F24>=80,G24<80),"Problème de perf.",IF(AND(F24<80,G24>=80),"Travailleur fiable","Sous-performeur"))))
B25: =IFERROR(VLOOKUP(A25,'F01 - _Données Centrales'!A6:B20,2,FALSE),"") | C25: =IFERROR(VLOOKUP(A25,'F01 - _Données Centrales'!A6:C20,3,FALSE),"") | H25: =IFERROR((F25+G25)/2,0) | I25: =IF(OR(F25="",G25=""),"",IF(AND(F25>=80,G25>=80),"Étoile",IF(AND(F25>=80,G25<80),"Problème de perf.",IF(AND(F25<80,G25>=80),"Travailleur fiable","Sous-performeur"))))
B26: =IFERROR(VLOOKUP(A26,'F01 - _Données Centrales'!A6:B20,2,FALSE),"") | C26: =IFERROR(VLOOKUP(A26,'F01 - _Données Centrales'!A6:C20,3,FALSE),"") | H26: =IFERROR((F26+G26)/2,0) | I26: =IF(OR(F26="",G26=""),"",IF(AND(F26>=80,G26>=80),"Étoile",IF(AND(F26>=80,G26<80),"Problème de perf.",IF(AND(F26<80,G26>=80),"Travailleur fiable","Sous-performeur"))))
B27: =IFERROR(VLOOKUP(A27,'F01 - _Données Centrales'!A6:B20,2,FALSE),"") | C27: =IFERROR(VLOOKUP(A27,'F01 - _Données Centrales'!A6:C20,3,FALSE),"") | H27: =IFERROR((F27+G27)/2,0) | I27: =IF(OR(F27="",G27=""),"",IF(AND(F27>=80,G27>=80),"Étoile",IF(AND(F27>=80,G27<80),"Problème de perf.",IF(AND(F27<80,G27>=80),"Travailleur fiable","Sous-performeur"))))
B28: =IFERROR(VLOOKUP(A28,'F01 - _Données Centrales'!A6:B20,2,FALSE),"") | C28: =IFERROR(VLOOKUP(A28,'F01 - _Données Centrales'!A6:C20,3,FALSE),"") | H28: =IFERROR((F28+G28)/2,0) | I28: =IF(OR(F28="",G28=""),"",IF(AND(F28>=80,G28>=80),"Étoile",IF(AND(F28>=80,G28<80),"Problème de perf.",IF(AND(F28<80,G28>=80),"Travailleur fiable","Sous-performeur"))))
B29: =IFERROR(VLOOKUP(A29,'F01 - _Données Centrales'!A6:B20,2,FALSE),"") | C29: =IFERROR(VLOOKUP(A29,'F01 - _Données Centrales'!A6:C20,3,FALSE),"") | H29: =IFERROR((F29+G29)/2,0) | I29: =IF(OR(F29="",G29=""),"",IF(AND(F29>=80,G29>=80),"Étoile",IF(AND(F29>=80,G29<80),"Problème de perf.",IF(AND(F29<80,G29>=80),"Travailleur fiable","Sous-performeur"))))
B30: =IFERROR(VLOOKUP(A30,'F01 - _Données Centrales'!A6:B20,2,FALSE),"") | C30: =IFERROR(VLOOKUP(A30,'F01 - _Données Centrales'!A6:C20,3,FALSE),"") | H30: =IFERROR((F30+G30)/2,0) | I30: =IF(OR(F30="",G30=""),"",IF(AND(F30>=80,G30>=80),"Étoile",IF(AND(F30>=80,G30<80),"Problème de perf.",IF(AND(F30<80,G30>=80),"Travailleur fiable","Sous-performeur"))))
B31: =IFERROR(VLOOKUP(A31,'F01 - _Données Centrales'!A6:B20,2,FALSE),"") | C31: =IFERROR(VLOOKUP(A31,'F01 - _Données Centrales'!A6:C20,3,FALSE),"") | H31: =IFERROR((F31+G31)/2,0) | I31: =IF(OR(F31="",G31=""),"",IF(AND(F31>=80,G31>=80),"Étoile",IF(AND(F31>=80,G31<80),"Problème de perf.",IF(AND(F31<80,G31>=80),"Travailleur fiable","Sous-performeur"))))
B32: =IFERROR(VLOOKUP(A32,'F01 - _Données Centrales'!A6:B20,2,FALSE),"") | C32: =IFERROR(VLOOKUP(A32,'F01 - _Données Centrales'!A6:C20,3,FALSE),"") | H32: =IFERROR((F32+G32)/2,0) | I32: =IF(OR(F32="",G32=""),"",IF(AND(F32>=80,G32>=80),"Étoile",IF(AND(F32>=80,G32<80),"Problème de perf.",IF(AND(F32<80,G32>=80),"Travailleur fiable","Sous-performeur"))))
B33: =IFERROR(VLOOKUP(A33,'F01 - _Données Centrales'!A6:B20,2,FALSE),"") | C33: =IFERROR(VLOOKUP(A33,'F01 - _Données Centrales'!A6:C20,3,FALSE),"") | H33: =IFERROR((F33+G33)/2,0) | I33: =IF(OR(F33="",G33=""),"",IF(AND(F33>=80,G33>=80),"Étoile",IF(AND(F33>=80,G33<80),"Problème de perf.",IF(AND(F33<80,G33>=80),"Travailleur fiable","Sous-performeur"))))
B34: =IFERROR(VLOOKUP(A34,'F01 - _Données Centrales'!A6:B20,2,FALSE),"") | C34: =IFERROR(VLOOKUP(A34,'F01 - _Données Centrales'!A6:C20,3,FALSE),"") | H34: =IFERROR((F34+G34)/2,0) | I34: =IF(OR(F34="",G34=""),"",IF(AND(F34>=80,G34>=80),"Étoile",IF(AND(F34>=80,G34<80),"Problème de perf.",IF(AND(F34<80,G34>=80),"Travailleur fiable","Sous-performeur"))))
B35: =IFERROR(VLOOKUP(A35,'F01 - _Données Centrales'!A6:B20,2,FALSE),"") | C35: =IFERROR(VLOOKUP(A35,'F01 - _Données Centrales'!A6:C20,3,FALSE),"") | H35: =IFERROR((F35+G35)/2,0) | I35: =IF(OR(F35="",G35=""),"",IF(AND(F35>=80,G35>=80),"Étoile",IF(AND(F35>=80,G35<80),"Problème de perf.",IF(AND(F35<80,G35>=80),"Travailleur fiable","Sous-performeur"))))
B36: =IFERROR(VLOOKUP(A36,'F01 - _Données Centrales'!A6:B20,2,FALSE),"") | C36: =IFERROR(VLOOKUP(A36,'F01 - _Données Centrales'!A6:C20,3,FALSE),"") | H36: =IFERROR((F36+G36)/2,0) | I36: =IF(OR(F36="",G36=""),"",IF(AND(F36>=80,G36>=80),"Étoile",IF(AND(F36>=80,G36<80),"Problème de perf.",IF(AND(F36<80,G36>=80),"Travailleur fiable","Sous-performeur"))))
B37: =IFERROR(VLOOKUP(A37,'F01 - _Données Centrales'!A6:B20,2,FALSE),"") | C37: =IFERROR(VLOOKUP(A37,'F01 - _Données Centrales'!A6:C20,3,FALSE),"") | H37: =IFERROR((F37+G37)/2,0) | I37: =IF(OR(F37="",G37=""),"",IF(AND(F37>=80,G37>=80),"Étoile",IF(AND(F37>=80,G37<80),"Problème de perf.",IF(AND(F37<80,G37>=80),"Travailleur fiable","Sous-performeur"))))
B38: =IFERROR(VLOOKUP(A38,'F01 - _Données Centrales'!A6:B20,2,FALSE),"") | C38: =IFERROR(VLOOKUP(A38,'F01 - _Données Centrales'!A6:C20,3,FALSE),"") | H38: =IFERROR((F38+G38)/2,0) | I38: =IF(OR(F38="",G38=""),"",IF(AND(F38>=80,G38>=80),"Étoile",IF(AND(F38>=80,G38<80),"Problème de perf.",IF(AND(F38<80,G38>=80),"Travailleur fiable","Sous-performeur"))))
B39: =IFERROR(VLOOKUP(A39,'F01 - _Données Centrales'!A6:B20,2,FALSE),"") | C39: =IFERROR(VLOOKUP(A39,'F01 - _Données Centrales'!A6:C20,3,FALSE),"") | H39: =IFERROR((F39+G39)/2,0) | I39: =IF(OR(F39="",G39=""),"",IF(AND(F39>=80,G39>=80),"Étoile",IF(AND(F39>=80,G39<80),"Problème de perf.",IF(AND(F39<80,G39>=80),"Travailleur fiable","Sous-performeur"))))
B40: =IFERROR(VLOOKUP(A40,'F01 - _Données Centrales'!A6:B20,2,FALSE),"") | C40: =IFERROR(VLOOKUP(A40,'F01 - _Données Centrales'!A6:C20,3,FALSE),"") | H40: =IFERROR((F40+G40)/2,0) | I40: =IF(OR(F40="",G40=""),"",IF(AND(F40>=80,G40>=80),"Étoile",IF(AND(F40>=80,G40<80),"Problème de perf.",IF(AND(F40<80,G40>=80),"Travailleur fiable","Sous-performeur"))))
B41: =IFERROR(VLOOKUP(A41,'F01 - _Données Centrales'!A6:B20,2,FALSE),"") | C41: =IFERROR(VLOOKUP(A41,'F01 - _Données Centrales'!A6:C20,3,FALSE),"") | H41: =IFERROR((F41+G41)/2,0) | I41: =IF(OR(F41="",G41=""),"",IF(AND(F41>=80,G41>=80),"Étoile",IF(AND(F41>=80,G41<80),"Problème de perf.",IF(AND(F41<80,G41>=80),"Travailleur fiable","Sous-performeur"))))
B42: =IFERROR(VLOOKUP(A42,'F01 - _Données Centrales'!A6:B20,2,FALSE),"") | C42: =IFERROR(VLOOKUP(A42,'F01 - _Données Centrales'!A6:C20,3,FALSE),"") | H42: =IFERROR((F42+G42)/2,0) | I42: =IF(OR(F42="",G42=""),"",IF(AND(F42>=80,G42>=80),"Étoile",IF(AND(F42>=80,G42<80),"Problème de perf.",IF(AND(F42<80,G42>=80),"Travailleur fiable","Sous-performeur"))))
...

Sheet F08 - 6-Parcours de Carrière
A2: DOMAINE 28 — PARCOURS DE CARRIÈRE
A3: Historique et planification des trajectoires professionnelles
A5: Code Employé | B5: Nom | C5: Département | D5: Poste Entrée | E5: Date Entrée | F5: Poste Actuel | G5: Date Poste Actuel | H5: Nb Promotions | I5: Nb Mobilités | J5: Prochain Palier | K5: Date Cible | L5: Délai Restant (mois) | M5: Statut Parcours
A6: EMP-001 | B6: =IFERROR(VLOOKUP(A6,'F01 - _Données Centrales'!A6:B20,2,FALSE),"") | C6: =IFERROR(VLOOKUP(A6,'F01 - _Données Centrales'!A6:C20,3,FALSE),"") | D6: Chef de Dept. | E6: 2003-01-15 | F6: Directeur Général | G6: 2015-01-15 | H6: 4 | I6: 2 | J6: Conseil Surveillance | K6: 2027-01-01 | L6: =IF(K6="","",MAX(0,ROUND((DATEVALUE(K6)-TODAY())/30,0))) | M6: En progression
A7: EMP-002 | B7: =IFERROR(VLOOKUP(A7,'F01 - _Données Centrales'!A6:B20,2,FALSE),"") | C7: =IFERROR(VLOOKUP(A7,'F01 - _Données Centrales'!A6:C20,3,FALSE),"") | D7: Assistante RH | E7: 2010-06-01 | F7: DRH | G7: 2018-06-01 | H7: 3 | I7: 1 | J7: DG Adjoint | K7: 2026-01-01 | L7: =IF(K7="","",MAX(0,ROUND((DATEVALUE(K7)-TODAY())/30,0))) | M7: En progression
A8: EMP-007 | B8: =IFERROR(VLOOKUP(A8,'F01 - _Données Centrales'!A6:B20,2,FALSE),"") | C8: =IFERROR(VLOOKUP(A8,'F01 - _Données Centrales'!A6:C20,3,FALSE),"") | D8: Assistante RH | E8: 2019-01-10 | F8: Resp. Recrutement | G8: 2022-01-10 | H8: 1 | I8: 0 | J8: DRH | K8: 2026-06-01 | L8: =IF(K8="","",MAX(0,ROUND((DATEVALUE(K8)-TODAY())/30,0))) | M8: Accéléré
A9: EMP-005 | B9: =IFERROR(VLOOKUP(A9,'F01 - _Données Centrales'!A6:B20,2,FALSE),"") | C9: =IFERROR(VLOOKUP(A9,'F01 - _Données Centrales'!A6:C20,3,FALSE),"") | D9: Réceptionniste | E9: 2015-07-01 | F9: Resp. Réception | G9: 2020-07-01 | H9: 2 | I9: 0 | J9: DRH Adjoint | K9: 2027-07-01 | L9: =IF(K9="","",MAX(0,ROUND((DATEVALUE(K9)-TODAY())/30,0))) | M9: En progression
A10: EMP-004 | B10: =IFERROR(VLOOKUP(A10,'F01 - _Données Centrales'!A6:B20,2,FALSE),"") | C10: =IFERROR(VLOOKUP(A10,'F01 - _Données Centrales'!A6:C20,3,FALSE),"") | D10: Commis Cuisine | E10: 2017-03-10 | F10: Chef Cuisinier | G10: 2021-03-10 | H10: 2 | I10: 1 | J10: Resp. Rest. Hôtellerie | K10: 2026-03-01 | L10: =IF(K10="","",MAX(0,ROUND((DATEVALUE(K10)-TODAY())/30,0))) | M10: En attente
B11: =IFERROR(VLOOKUP(A11,'F01 - _Données Centrales'!A6:B20,2,FALSE),"") | C11: =IFERROR(VLOOKUP(A11,'F01 - _Données Centrales'!A6:C20,3,FALSE),"") | L11: =IF(K11="","",MAX(0,ROUND((DATEVALUE(K11)-TODAY())/30,0)))
B12: =IFERROR(VLOOKUP(A12,'F01 - _Données Centrales'!A6:B20,2,FALSE),"") | C12: =IFERROR(VLOOKUP(A12,'F01 - _Données Centrales'!A6:C20,3,FALSE),"") | L12: =IF(K12="","",MAX(0,ROUND((DATEVALUE(K12)-TODAY())/30,0)))
B13: =IFERROR(VLOOKUP(A13,'F01 - _Données Centrales'!A6:B20,2,FALSE),"") | C13: =IFERROR(VLOOKUP(A13,'F01 - _Données Centrales'!A6:C20,3,FALSE),"") | L13: =IF(K13="","",MAX(0,ROUND((DATEVALUE(K13)-TODAY())/30,0)))
B14: =IFERROR(VLOOKUP(A14,'F01 - _Données Centrales'!A6:B20,2,FALSE),"") | C14: =IFERROR(VLOOKUP(A14,'F01 - _Données Centrales'!A6:C20,3,FALSE),"") | L14: =IF(K14="","",MAX(0,ROUND((DATEVALUE(K14)-TODAY())/30,0)))
B15: =IFERROR(VLOOKUP(A15,'F01 - _Données Centrales'!A6:B20,2,FALSE),"") | C15: =IFERROR(VLOOKUP(A15,'F01 - _Données Centrales'!A6:C20,3,FALSE),"") | L15: =IF(K15="","",MAX(0,ROUND((DATEVALUE(K15)-TODAY())/30,0)))
B16: =IFERROR(VLOOKUP(A16,'F01 - _Données Centrales'!A6:B20,2,FALSE),"") | C16: =IFERROR(VLOOKUP(A16,'F01 - _Données Centrales'!A6:C20,3,FALSE),"") | L16: =IF(K16="","",MAX(0,ROUND((DATEVALUE(K16)-TODAY())/30,0)))
B17: =IFERROR(VLOOKUP(A17,'F01 - _Données Centrales'!A6:B20,2,FALSE),"") | C17: =IFERROR(VLOOKUP(A17,'F01 - _Données Centrales'!A6:C20,3,FALSE),"") | L17: =IF(K17="","",MAX(0,ROUND((DATEVALUE(K17)-TODAY())/30,0)))
B18: =IFERROR(VLOOKUP(A18,'F01 - _Données Centrales'!A6:B20,2,FALSE),"") | C18: =IFERROR(VLOOKUP(A18,'F01 - _Données Centrales'!A6:C20,3,FALSE),"") | L18: =IF(K18="","",MAX(0,ROUND((DATEVALUE(K18)-TODAY())/30,0)))
B19: =IFERROR(VLOOKUP(A19,'F01 - _Données Centrales'!A6:B20,2,FALSE),"") | C19: =IFERROR(VLOOKUP(A19,'F01 - _Données Centrales'!A6:C20,3,FALSE),"") | L19: =IF(K19="","",MAX(0,ROUND((DATEVALUE(K19)-TODAY())/30,0)))
B20: =IFERROR(VLOOKUP(A20,'F01 - _Données Centrales'!A6:B20,2,FALSE),"") | C20: =IFERROR(VLOOKUP(A20,'F01 - _Données Centrales'!A6:C20,3,FALSE),"") | L20: =IF(K20="","",MAX(0,ROUND((DATEVALUE(K20)-TODAY())/30,0)))
B21: =IFERROR(VLOOKUP(A21,'F01 - _Données Centrales'!A6:B20,2,FALSE),"") | C21: =IFERROR(VLOOKUP(A21,'F01 - _Données Centrales'!A6:C20,3,FALSE),"") | L21: =IF(K21="","",MAX(0,ROUND((DATEVALUE(K21)-TODAY())/30,0)))
B22: =IFERROR(VLOOKUP(A22,'F01 - _Données Centrales'!A6:B20,2,FALSE),"") | C22: =IFERROR(VLOOKUP(A22,'F01 - _Données Centrales'!A6:C20,3,FALSE),"") | L22: =IF(K22="","",MAX(0,ROUND((DATEVALUE(K22)-TODAY())/30,0)))
B23: =IFERROR(VLOOKUP(A23,'F01 - _Données Centrales'!A6:B20,2,FALSE),"") | C23: =IFERROR(VLOOKUP(A23,'F01 - _Données Centrales'!A6:C20,3,FALSE),"") | L23: =IF(K23="","",MAX(0,ROUND((DATEVALUE(K23)-TODAY())/30,0)))
B24: =IFERROR(VLOOKUP(A24,'F01 - _Données Centrales'!A6:B20,2,FALSE),"") | C24: =IFERROR(VLOOKUP(A24,'F01 - _Données Centrales'!A6:C20,3,FALSE),"") | L24: =IF(K24="","",MAX(0,ROUND((DATEVALUE(K24)-TODAY())/30,0)))
B25: =IFERROR(VLOOKUP(A25,'F01 - _Données Centrales'!A6:B20,2,FALSE),"") | C25: =IFERROR(VLOOKUP(A25,'F01 - _Données Centrales'!A6:C20,3,FALSE),"") | L25: =IF(K25="","",MAX(0,ROUND((DATEVALUE(K25)-TODAY())/30,0)))
B26: =IFERROR(VLOOKUP(A26,'F01 - _Données Centrales'!A6:B20,2,FALSE),"") | C26: =IFERROR(VLOOKUP(A26,'F01 - _Données Centrales'!A6:C20,3,FALSE),"") | L26: =IF(K26="","",MAX(0,ROUND((DATEVALUE(K26)-TODAY())/30,0)))
B27: =IFERROR(VLOOKUP(A27,'F01 - _Données Centrales'!A6:B20,2,FALSE),"") | C27: =IFERROR(VLOOKUP(A27,'F01 - _Données Centrales'!A6:C20,3,FALSE),"") | L27: =IF(K27="","",MAX(0,ROUND((DATEVALUE(K27)-TODAY())/30,0)))
B28: =IFERROR(VLOOKUP(A28,'F01 - _Données Centrales'!A6:B20,2,FALSE),"") | C28: =IFERROR(VLOOKUP(A28,'F01 - _Données Centrales'!A6:C20,3,FALSE),"") | L28: =IF(K28="","",MAX(0,ROUND((DATEVALUE(K28)-TODAY())/30,0)))
B29: =IFERROR(VLOOKUP(A29,'F01 - _Données Centrales'!A6:B20,2,FALSE),"") | C29: =IFERROR(VLOOKUP(A29,'F01 - _Données Centrales'!A6:C20,3,FALSE),"") | L29: =IF(K29="","",MAX(0,ROUND((DATEVALUE(K29)-TODAY())/30,0)))
B30: =IFERROR(VLOOKUP(A30,'F01 - _Données Centrales'!A6:B20,2,FALSE),"") | C30: =IFERROR(VLOOKUP(A30,'F01 - _Données Centrales'!A6:C20,3,FALSE),"") | L30: =IF(K30="","",MAX(0,ROUND((DATEVALUE(K30)-TODAY())/30,0)))
B31: =IFERROR(VLOOKUP(A31,'F01 - _Données Centrales'!A6:B20,2,FALSE),"") | C31: =IFERROR(VLOOKUP(A31,'F01 - _Données Centrales'!A6:C20,3,FALSE),"") | L31: =IF(K31="","",MAX(0,ROUND((DATEVALUE(K31)-TODAY())/30,0)))
B32: =IFERROR(VLOOKUP(A32,'F01 - _Données Centrales'!A6:B20,2,FALSE),"") | C32: =IFERROR(VLOOKUP(A32,'F01 - _Données Centrales'!A6:C20,3,FALSE),"") | L32: =IF(K32="","",MAX(0,ROUND((DATEVALUE(K32)-TODAY())/30,0)))
B33: =IFERROR(VLOOKUP(A33,'F01 - _Données Centrales'!A6:B20,2,FALSE),"") | C33: =IFERROR(VLOOKUP(A33,'F01 - _Données Centrales'!A6:C20,3,FALSE),"") | L33: =IF(K33="","",MAX(0,ROUND((DATEVALUE(K33)-TODAY())/30,0)))
B34: =IFERROR(VLOOKUP(A34,'F01 - _Données Centrales'!A6:B20,2,FALSE),"") | C34: =IFERROR(VLOOKUP(A34,'F01 - _Données Centrales'!A6:C20,3,FALSE),"") | L34: =IF(K34="","",MAX(0,ROUND((DATEVALUE(K34)-TODAY())/30,0)))
B35: =IFERROR(VLOOKUP(A35,'F01 - _Données Centrales'!A6:B20,2,FALSE),"") | C35: =IFERROR(VLOOKUP(A35,'F01 - _Données Centrales'!A6:C20,3,FALSE),"") | L35: =IF(K35="","",MAX(0,ROUND((DATEVALUE(K35)-TODAY())/30,0)))
B36: =IFERROR(VLOOKUP(A36,'F01 - _Données Centrales'!A6:B20,2,FALSE),"") | C36: =IFERROR(VLOOKUP(A36,'F01 - _Données Centrales'!A6:C20,3,FALSE),"") | L36: =IF(K36="","",MAX(0,ROUND((DATEVALUE(K36)-TODAY())/30,0)))
B37: =IFERROR(VLOOKUP(A37,'F01 - _Données Centrales'!A6:B20,2,FALSE),"") | C37: =IFERROR(VLOOKUP(A37,'F01 - _Données Centrales'!A6:C20,3,FALSE),"") | L37: =IF(K37="","",MAX(0,ROUND((DATEVALUE(K37)-TODAY())/30,0)))
B38: =IFERROR(VLOOKUP(A38,'F01 - _Données Centrales'!A6:B20,2,FALSE),"") | C38: =IFERROR(VLOOKUP(A38,'F01 - _Données Centrales'!A6:C20,3,FALSE),"") | L38: =IF(K38="","",MAX(0,ROUND((DATEVALUE(K38)-TODAY())/30,0)))
B39: =IFERROR(VLOOKUP(A39,'F01 - _Données Centrales'!A6:B20,2,FALSE),"") | C39: =IFERROR(VLOOKUP(A39,'F01 - _Données Centrales'!A6:C20,3,FALSE),"") | L39: =IF(K39="","",MAX(0,ROUND((DATEVALUE(K39)-TODAY())/30,0)))
B40: =IFERROR(VLOOKUP(A40,'F01 - _Données Centrales'!A6:B20,2,FALSE),"") | C40: =IFERROR(VLOOKUP(A40,'F01 - _Données Centrales'!A6:C20,3,FALSE),"") | L40: =IF(K40="","",MAX(0,ROUND((DATEVALUE(K40)-TODAY())/30,0)))
B41: =IFERROR(VLOOKUP(A41,'F01 - _Données Centrales'!A6:B20,2,FALSE),"") | C41: =IFERROR(VLOOKUP(A41,'F01 - _Données Centrales'!A6:C20,3,FALSE),"") | L41: =IF(K41="","",MAX(0,ROUND((DATEVALUE(K41)-TODAY())/30,0)))
B42: =IFERROR(VLOOKUP(A42,'F01 - _Données Centrales'!A6:B20,2,FALSE),"") | C42: =IFERROR(VLOOKUP(A42,'F01 - _Données Centrales'!A6:C20,3,FALSE),"") | L42: =IF(K42="","",MAX(0,ROUND((DATEVALUE(K42)-TODAY())/30,0)))
...

Sheet F09 - 7-Mobilité Internationale
A2: DOMAINE 28 — MOBILITÉ INTERNATIONALE
A3: Gestion des expatriations, détachements et missions internationales
A5: N° Mission | B5: Code Employé | C5: Nom | D5: Pays Destination | E5: Ville | F5: Type Contrat | G5: Date Départ | H5: Date Retour | I5: Durée (mois) | J5: Coût Total (FCFA) | K5: Indemnité Expatriation | L5: Statut | M5: Logement | N5: Scolarité Enfants | O5: Observations
A6: INT-2025-001 | B6: EMP-003 | C6: =IFERROR(VLOOKUP(B6,'F01 - _Données Centrales'!A6:B20,2,FALSE),"") | D6: Côte d'Ivoire | E6: Abidjan | F6: Détachement | G6: 2025-04-01 | H6: 2026-04-01 | I6: 12 | J6: 25000000 | K6: 5000000 | L6: En cours | M6: Pris en charge | N6: Oui | O6: Ouverture filiale Abidjan
A7: INT-2025-002 | B7: EMP-007 | C7: =IFERROR(VLOOKUP(B7,'F01 - _Données Centrales'!A6:B20,2,FALSE),"") | D7: France | E7: Paris | F7: Mission courte | G7: 2025-06-15 | H7: 2025-07-15 | I7: 1 | J7: 3500000 | K7: 0 | L7: Planifié | M7: Hôtel | N7: Non | O7: Formation certifiante DRH
A8: INT-2025-003 | B8: EMP-002 | C8: =IFERROR(VLOOKUP(B8,'F01 - _Données Centrales'!A6:B20,2,FALSE),"") | D8: Cameroun | E8: Douala | F8: Consultation technique | G8: 2025-05-01 | H8: 2025-05-15 | I8: 0.5 | J8: 1500000 | K8: 0 | L8: Terminé | M8: Hôtel | N8: Non | O8: Audit RH filiale Douala
C9: =IFERROR(VLOOKUP(B9,'F01 - _Données Centrales'!A6:B20,2,FALSE),"")
C10: =IFERROR(VLOOKUP(B10,'F01 - _Données Centrales'!A6:B20,2,FALSE),"")
C11: =IFERROR(VLOOKUP(B11,'F01 - _Données Centrales'!A6:B20,2,FALSE),"")
C12: =IFERROR(VLOOKUP(B12,'F01 - _Données Centrales'!A6:B20,2,FALSE),"")
C13: =IFERROR(VLOOKUP(B13,'F01 - _Données Centrales'!A6:B20,2,FALSE),"")
C14: =IFERROR(VLOOKUP(B14,'F01 - _Données Centrales'!A6:B20,2,FALSE),"")
C15: =IFERROR(VLOOKUP(B15,'F01 - _Données Centrales'!A6:B20,2,FALSE),"")
C16: =IFERROR(VLOOKUP(B16,'F01 - _Données Centrales'!A6:B20,2,FALSE),"")
C17: =IFERROR(VLOOKUP(B17,'F01 - _Données Centrales'!A6:B20,2,FALSE),"")
C18: =IFERROR(VLOOKUP(B18,'F01 - _Données Centrales'!A6:B20,2,FALSE),"")
C19: =IFERROR(VLOOKUP(B19,'F01 - _Données Centrales'!A6:B20,2,FALSE),"")
C20: =IFERROR(VLOOKUP(B20,'F01 - _Données Centrales'!A6:B20,2,FALSE),"")
C21: =IFERROR(VLOOKUP(B21,'F01 - _Données Centrales'!A6:B20,2,FALSE),"")
C22: =IFERROR(VLOOKUP(B22,'F01 - _Données Centrales'!A6:B20,2,FALSE),"")
C23: =IFERROR(VLOOKUP(B23,'F01 - _Données Centrales'!A6:B20,2,FALSE),"")
C24: =IFERROR(VLOOKUP(B24,'F01 - _Données Centrales'!A6:B20,2,FALSE),"")
C25: =IFERROR(VLOOKUP(B25,'F01 - _Données Centrales'!A6:B20,2,FALSE),"")
C26: =IFERROR(VLOOKUP(B26,'F01 - _Données Centrales'!A6:B20,2,FALSE),"")
C27: =IFERROR(VLOOKUP(B27,'F01 - _Données Centrales'!A6:B20,2,FALSE),"")
C28: =IFERROR(VLOOKUP(B28,'F01 - _Données Centrales'!A6:B20,2,FALSE),"")
C29: =IFERROR(VLOOKUP(B29,'F01 - _Données Centrales'!A6:B20,2,FALSE),"")
C30: =IFERROR(VLOOKUP(B30,'F01 - _Données Centrales'!A6:B20,2,FALSE),"")
C31: =IFERROR(VLOOKUP(B31,'F01 - _Données Centrales'!A6:B20,2,FALSE),"")
C32: =IFERROR(VLOOKUP(B32,'F01 - _Données Centrales'!A6:B20,2,FALSE),"")
C33: =IFERROR(VLOOKUP(B33,'F01 - _Données Centrales'!A6:B20,2,FALSE),"")
C34: =IFERROR(VLOOKUP(B34,'F01 - _Données Centrales'!A6:B20,2,FALSE),"")
C35: =IFERROR(VLOOKUP(B35,'F01 - _Données Centrales'!A6:B20,2,FALSE),"")
C36: =IFERROR(VLOOKUP(B36,'F01 - _Données Centrales'!A6:B20,2,FALSE),"")
C37: =IFERROR(VLOOKUP(B37,'F01 - _Données Centrales'!A6:B20,2,FALSE),"")
C38: =IFERROR(VLOOKUP(B38,'F01 - _Données Centrales'!A6:B20,2,FALSE),"")
C39: =IFERROR(VLOOKUP(B39,'F01 - _Données Centrales'!A6:B20,2,FALSE),"")
C40: =IFERROR(VLOOKUP(B40,'F01 - _Données Centrales'!A6:B20,2,FALSE),"")
C41: =IFERROR(VLOOKUP(B41,'F01 - _Données Centrales'!A6:B20,2,FALSE),"")
C42: =IFERROR(VLOOKUP(B42,'F01 - _Données Centrales'!A6:B20,2,FALSE),"")
...

Sheet F10 - 8-Gest. Talents Haut Pot.
A2: DOMAINE 28 — GESTION DES TALENTS HAUT POTENTIEL
A3: Identification, développement et rétention des collaborateurs à haut potentiel
A5: Code Employé | B5: Nom | C5: Département | D5: Potentiel | E5: Performance | F5: Date Identification | G5: Programme Développement | H5: Mentor Assigné | I5: Budget Alloué (FCFA) | J5: Budget Consommé (FCFA) | K5: Taux Utilisation (%) | L5: Risque Départ | M5: Date Révision | N5: Statut Talent
A6: EMP-007 | B6: =IFERROR(VLOOKUP(A6,'F01 - _Données Centrales'!A6:B20,2,FALSE),"") | C6: =IFERROR(VLOOKUP(A6,'F01 - _Données Centrales'!A6:C20,3,FALSE),"") | D6: Très élevé | E6: Excellent | F6: 2024-01-15 | G6: Programme Émergence RH | H6: Mme. Mbarga | I6: 5000000 | J6: 3200000 | K6: =IFERROR(J6/I6,0) | L6: Élevé | M6: 2025-09-01 | N6: Actif
A7: EMP-002 | B7: =IFERROR(VLOOKUP(A7,'F01 - _Données Centrales'!A6:B20,2,FALSE),"") | C7: =IFERROR(VLOOKUP(A7,'F01 - _Données Centrales'!A6:C20,3,FALSE),"") | D7: Élevé | E7: Excellent | F7: 2023-06-01 | G7: Programme Leadership | H7: M. Nkoulou | I7: 8000000 | J7: 6400000 | K7: =IFERROR(J7/I7,0) | L7: Faible | M7: 2025-06-01 | N7: Actif
A8: EMP-003 | B8: =IFERROR(VLOOKUP(A8,'F01 - _Données Centrales'!A6:B20,2,FALSE),"") | C8: =IFERROR(VLOOKUP(A8,'F01 - _Données Centrales'!A6:C20,3,FALSE),"") | D8: Élevé | E8: Très bon | F8: 2023-09-01 | G8: Programme Finance Exec. | H8: DG Externe | I8: 6000000 | J8: 4500000 | K8: =IFERROR(J8/I8,0) | L8: Moyen | M8: 2025-12-01 | N8: Actif
A9: EMP-005 | B9: =IFERROR(VLOOKUP(A9,'F01 - _Données Centrales'!A6:B20,2,FALSE),"") | C9: =IFERROR(VLOOKUP(A9,'F01 - _Données Centrales'!A6:C20,3,FALSE),"") | D9: Élevé | E9: Bon | F9: 2024-07-01 | G9: Programme Management | H9: Mme. Mbarga | I9: 3000000 | J9: 1800000 | K9: =IFERROR(J9/I9,0) | L9: Moyen | M9: 2025-07-01 | N9: En observation
A10: EMP-013 | B10: =IFERROR(VLOOKUP(A10,'F01 - _Données Centrales'!A6:B20,2,FALSE),"") | C10: =IFERROR(VLOOKUP(A10,'F01 - _Données Centrales'!A6:C20,3,FALSE),"") | D10: Élevé | E10: Excellent | F10: 2024-03-01 | G10: Programme Adjoint Dir. | H10: M. Nkoulou | I10: 2500000 | J10: 1500000 | K10: =IFERROR(J10/I10,0) | L10: Faible | M10: 2025-09-01 | N10: Actif
B11: =IFERROR(VLOOKUP(A11,'F01 - _Données Centrales'!A6:B20,2,FALSE),"") | C11: =IFERROR(VLOOKUP(A11,'F01 - _Données Centrales'!A6:C20,3,FALSE),"") | K11: =IFERROR(J11/I11,0)
B12: =IFERROR(VLOOKUP(A12,'F01 - _Données Centrales'!A6:B20,2,FALSE),"") | C12: =IFERROR(VLOOKUP(A12,'F01 - _Données Centrales'!A6:C20,3,FALSE),"") | K12: =IFERROR(J12/I12,0)
B13: =IFERROR(VLOOKUP(A13,'F01 - _Données Centrales'!A6:B20,2,FALSE),"") | C13: =IFERROR(VLOOKUP(A13,'F01 - _Données Centrales'!A6:C20,3,FALSE),"") | K13: =IFERROR(J13/I13,0)
B14: =IFERROR(VLOOKUP(A14,'F01 - _Données Centrales'!A6:B20,2,FALSE),"") | C14: =IFERROR(VLOOKUP(A14,'F01 - _Données Centrales'!A6:C20,3,FALSE),"") | K14: =IFERROR(J14/I14,0)
B15: =IFERROR(VLOOKUP(A15,'F01 - _Données Centrales'!A6:B20,2,FALSE),"") | C15: =IFERROR(VLOOKUP(A15,'F01 - _Données Centrales'!A6:C20,3,FALSE),"") | K15: =IFERROR(J15/I15,0)
B16: =IFERROR(VLOOKUP(A16,'F01 - _Données Centrales'!A6:B20,2,FALSE),"") | C16: =IFERROR(VLOOKUP(A16,'F01 - _Données Centrales'!A6:C20,3,FALSE),"") | K16: =IFERROR(J16/I16,0)
B17: =IFERROR(VLOOKUP(A17,'F01 - _Données Centrales'!A6:B20,2,FALSE),"") | C17: =IFERROR(VLOOKUP(A17,'F01 - _Données Centrales'!A6:C20,3,FALSE),"") | K17: =IFERROR(J17/I17,0)
B18: =IFERROR(VLOOKUP(A18,'F01 - _Données Centrales'!A6:B20,2,FALSE),"") | C18: =IFERROR(VLOOKUP(A18,'F01 - _Données Centrales'!A6:C20,3,FALSE),"") | K18: =IFERROR(J18/I18,0)
B19: =IFERROR(VLOOKUP(A19,'F01 - _Données Centrales'!A6:B20,2,FALSE),"") | C19: =IFERROR(VLOOKUP(A19,'F01 - _Données Centrales'!A6:C20,3,FALSE),"") | K19: =IFERROR(J19/I19,0)
B20: =IFERROR(VLOOKUP(A20,'F01 - _Données Centrales'!A6:B20,2,FALSE),"") | C20: =IFERROR(VLOOKUP(A20,'F01 - _Données Centrales'!A6:C20,3,FALSE),"") | K20: =IFERROR(J20/I20,0)
B21: =IFERROR(VLOOKUP(A21,'F01 - _Données Centrales'!A6:B20,2,FALSE),"") | C21: =IFERROR(VLOOKUP(A21,'F01 - _Données Centrales'!A6:C20,3,FALSE),"") | K21: =IFERROR(J21/I21,0)
B22: =IFERROR(VLOOKUP(A22,'F01 - _Données Centrales'!A6:B20,2,FALSE),"") | C22: =IFERROR(VLOOKUP(A22,'F01 - _Données Centrales'!A6:C20,3,FALSE),"") | K22: =IFERROR(J22/I22,0)
B23: =IFERROR(VLOOKUP(A23,'F01 - _Données Centrales'!A6:B20,2,FALSE),"") | C23: =IFERROR(VLOOKUP(A23,'F01 - _Données Centrales'!A6:C20,3,FALSE),"") | K23: =IFERROR(J23/I23,0)
B24: =IFERROR(VLOOKUP(A24,'F01 - _Données Centrales'!A6:B20,2,FALSE),"") | C24: =IFERROR(VLOOKUP(A24,'F01 - _Données Centrales'!A6:C20,3,FALSE),"") | K24: =IFERROR(J24/I24,0)
B25: =IFERROR(VLOOKUP(A25,'F01 - _Données Centrales'!A6:B20,2,FALSE),"") | C25: =IFERROR(VLOOKUP(A25,'F01 - _Données Centrales'!A6:C20,3,FALSE),"") | K25: =IFERROR(J25/I25,0)
B26: =IFERROR(VLOOKUP(A26,'F01 - _Données Centrales'!A6:B20,2,FALSE),"") | C26: =IFERROR(VLOOKUP(A26,'F01 - _Données Centrales'!A6:C20,3,FALSE),"") | K26: =IFERROR(J26/I26,0)
B27: =IFERROR(VLOOKUP(A27,'F01 - _Données Centrales'!A6:B20,2,FALSE),"") | C27: =IFERROR(VLOOKUP(A27,'F01 - _Données Centrales'!A6:C20,3,FALSE),"") | K27: =IFERROR(J27/I27,0)
B28: =IFERROR(VLOOKUP(A28,'F01 - _Données Centrales'!A6:B20,2,FALSE),"") | C28: =IFERROR(VLOOKUP(A28,'F01 - _Données Centrales'!A6:C20,3,FALSE),"") | K28: =IFERROR(J28/I28,0)
B29: =IFERROR(VLOOKUP(A29,'F01 - _Données Centrales'!A6:B20,2,FALSE),"") | C29: =IFERROR(VLOOKUP(A29,'F01 - _Données Centrales'!A6:C20,3,FALSE),"") | K29: =IFERROR(J29/I29,0)
B30: =IFERROR(VLOOKUP(A30,'F01 - _Données Centrales'!A6:B20,2,FALSE),"") | C30: =IFERROR(VLOOKUP(A30,'F01 - _Données Centrales'!A6:C20,3,FALSE),"") | K30: =IFERROR(J30/I30,0)
B31: =IFERROR(VLOOKUP(A31,'F01 - _Données Centrales'!A6:B20,2,FALSE),"") | C31: =IFERROR(VLOOKUP(A31,'F01 - _Données Centrales'!A6:C20,3,FALSE),"") | K31: =IFERROR(J31/I31,0)
B32: =IFERROR(VLOOKUP(A32,'F01 - _Données Centrales'!A6:B20,2,FALSE),"") | C32: =IFERROR(VLOOKUP(A32,'F01 - _Données Centrales'!A6:C20,3,FALSE),"") | K32: =IFERROR(J32/I32,0)
B33: =IFERROR(VLOOKUP(A33,'F01 - _Données Centrales'!A6:B20,2,FALSE),"") | C33: =IFERROR(VLOOKUP(A33,'F01 - _Données Centrales'!A6:C20,3,FALSE),"") | K33: =IFERROR(J33/I33,0)
B34: =IFERROR(VLOOKUP(A34,'F01 - _Données Centrales'!A6:B20,2,FALSE),"") | C34: =IFERROR(VLOOKUP(A34,'F01 - _Données Centrales'!A6:C20,3,FALSE),"") | K34: =IFERROR(J34/I34,0)
B35: =IFERROR(VLOOKUP(A35,'F01 - _Données Centrales'!A6:B20,2,FALSE),"") | C35: =IFERROR(VLOOKUP(A35,'F01 - _Données Centrales'!A6:C20,3,FALSE),"") | K35: =IFERROR(J35/I35,0)
B36: =IFERROR(VLOOKUP(A36,'F01 - _Données Centrales'!A6:B20,2,FALSE),"") | C36: =IFERROR(VLOOKUP(A36,'F01 - _Données Centrales'!A6:C20,3,FALSE),"") | K36: =IFERROR(J36/I36,0)
B37: =IFERROR(VLOOKUP(A37,'F01 - _Données Centrales'!A6:B20,2,FALSE),"") | C37: =IFERROR(VLOOKUP(A37,'F01 - _Données Centrales'!A6:C20,3,FALSE),"") | K37: =IFERROR(J37/I37,0)
B38: =IFERROR(VLOOKUP(A38,'F01 - _Données Centrales'!A6:B20,2,FALSE),"") | C38: =IFERROR(VLOOKUP(A38,'F01 - _Données Centrales'!A6:C20,3,FALSE),"") | K38: =IFERROR(J38/I38,0)
B39: =IFERROR(VLOOKUP(A39,'F01 - _Données Centrales'!A6:B20,2,FALSE),"") | C39: =IFERROR(VLOOKUP(A39,'F01 - _Données Centrales'!A6:C20,3,FALSE),"") | K39: =IFERROR(J39/I39,0)
B40: =IFERROR(VLOOKUP(A40,'F01 - _Données Centrales'!A6:B20,2,FALSE),"") | C40: =IFERROR(VLOOKUP(A40,'F01 - _Données Centrales'!A6:C20,3,FALSE),"") | K40: =IFERROR(J40/I40,0)
B41: =IFERROR(VLOOKUP(A41,'F01 - _Données Centrales'!A6:B20,2,FALSE),"") | C41: =IFERROR(VLOOKUP(A41,'F01 - _Données Centrales'!A6:C20,3,FALSE),"") | K41: =IFERROR(J41/I41,0)
B42: =IFERROR(VLOOKUP(A42,'F01 - _Données Centrales'!A6:B20,2,FALSE),"") | C42: =IFERROR(VLOOKUP(A42,'F01 - _Données Centrales'!A6:C20,3,FALSE),"") | K42: =IFERROR(J42/I42,0)
...

Sheet F11 - 9-Entretiens Annu. Carr.
A2: DOMAINE 28 — ENTRETIENS ANNUELS DE CARRIÈRE
A3: Planification et suivi des entretiens individuels de carrière
A5: Code Employé | B5: Nom | C5: Département | D5: Date Entretien | E5: Évaluateur | F5: Fréquence | G5: Objectifs Fixés | H5: Actions Convenues | I5: Date Prochain Entretien | J5: Statut Réalisation | K5: Note Globale (/20) | L5: Évolution Poste | M5: Observations
A6: EMP-001 | B6: =IFERROR(VLOOKUP(A6,'F01 - _Données Centrales'!A6:B20,2,FALSE),"") | C6: =IFERROR(VLOOKUP(A6,'F01 - _Données Centrales'!A6:C20,3,FALSE),"") | D6: 2025-01-20 | E6: Conseil Administration | F6: Annuel | G6: Stratégie 2025-2027 | H6: Formation executive leadership | I6: 2026-01-20 | J6: Réalisé | K6: 18 | L6: Maintien DG | M6: Excellent leader, vision confirmée
A7: EMP-002 | B7: =IFERROR(VLOOKUP(A7,'F01 - _Données Centrales'!A6:B20,2,FALSE),"") | C7: =IFERROR(VLOOKUP(A7,'F01 - _Données Centrales'!A6:C20,3,FALSE),"") | D7: 2025-02-10 | E7: DG | F7: Annuel | G7: Préparation succession DG | H7: Programme haute direction | I7: 2026-02-10 | J7: Réalisé | K7: 17 | L7: Promotion DG Adjoint | M7: Prête pour niveau supérieur
A8: EMP-003 | B8: =IFERROR(VLOOKUP(A8,'F01 - _Données Centrales'!A6:B20,2,FALSE),"") | C8: =IFERROR(VLOOKUP(A8,'F01 - _Données Centrales'!A6:C20,3,FALSE),"") | D8: 2025-03-01 | E8: DG | F8: Annuel | G8: Optimisation fiscale 2025 | H8: Certification IFRS | I8: 2026-03-01 | J8: Réalisé | K8: 16 | L8: Maintien DAF | M8: Bonne progression technique
A9: EMP-007 | B9: =IFERROR(VLOOKUP(A9,'F01 - _Données Centrales'!A6:B20,2,FALSE),"") | C9: =IFERROR(VLOOKUP(A9,'F01 - _Données Centrales'!A6:C20,3,FALSE),"") | D9: 2025-02-20 | E9: DRH | F9: Semestriel | G9: Plan succession DRH | H9: Formation management avancé | I9: 2025-08-20 | J9: Planifié | K9: 17 | L9: Promotion DRH | M9: Talent émergent confirmé
A10: EMP-005 | B10: =IFERROR(VLOOKUP(A10,'F01 - _Données Centrales'!A6:B20,2,FALSE),"") | C10: =IFERROR(VLOOKUP(A10,'F01 - _Données Centrales'!A6:C20,3,FALSE),"") | D10: 2025-03-15 | E10: DRH | F10: Annuel | G10: Développer leadership | H10: Coaching externe | I10: 2026-03-15 | J10: Reporté | K10: 15 | L10: Promotion | M10: Potentiel confirmé, effort leadership
B11: =IFERROR(VLOOKUP(A11,'F01 - _Données Centrales'!A6:B20,2,FALSE),"") | C11: =IFERROR(VLOOKUP(A11,'F01 - _Données Centrales'!A6:C20,3,FALSE),"")
B12: =IFERROR(VLOOKUP(A12,'F01 - _Données Centrales'!A6:B20,2,FALSE),"") | C12: =IFERROR(VLOOKUP(A12,'F01 - _Données Centrales'!A6:C20,3,FALSE),"")
B13: =IFERROR(VLOOKUP(A13,'F01 - _Données Centrales'!A6:B20,2,FALSE),"") | C13: =IFERROR(VLOOKUP(A13,'F01 - _Données Centrales'!A6:C20,3,FALSE),"")
B14: =IFERROR(VLOOKUP(A14,'F01 - _Données Centrales'!A6:B20,2,FALSE),"") | C14: =IFERROR(VLOOKUP(A14,'F01 - _Données Centrales'!A6:C20,3,FALSE),"")
B15: =IFERROR(VLOOKUP(A15,'F01 - _Données Centrales'!A6:B20,2,FALSE),"") | C15: =IFERROR(VLOOKUP(A15,'F01 - _Données Centrales'!A6:C20,3,FALSE),"")
B16: =IFERROR(VLOOKUP(A16,'F01 - _Données Centrales'!A6:B20,2,FALSE),"") | C16: =IFERROR(VLOOKUP(A16,'F01 - _Données Centrales'!A6:C20,3,FALSE),"")
B17: =IFERROR(VLOOKUP(A17,'F01 - _Données Centrales'!A6:B20,2,FALSE),"") | C17: =IFERROR(VLOOKUP(A17,'F01 - _Données Centrales'!A6:C20,3,FALSE),"")
B18: =IFERROR(VLOOKUP(A18,'F01 - _Données Centrales'!A6:B20,2,FALSE),"") | C18: =IFERROR(VLOOKUP(A18,'F01 - _Données Centrales'!A6:C20,3,FALSE),"")
B19: =IFERROR(VLOOKUP(A19,'F01 - _Données Centrales'!A6:B20,2,FALSE),"") | C19: =IFERROR(VLOOKUP(A19,'F01 - _Données Centrales'!A6:C20,3,FALSE),"")
B20: =IFERROR(VLOOKUP(A20,'F01 - _Données Centrales'!A6:B20,2,FALSE),"") | C20: =IFERROR(VLOOKUP(A20,'F01 - _Données Centrales'!A6:C20,3,FALSE),"")
B21: =IFERROR(VLOOKUP(A21,'F01 - _Données Centrales'!A6:B20,2,FALSE),"") | C21: =IFERROR(VLOOKUP(A21,'F01 - _Données Centrales'!A6:C20,3,FALSE),"")
B22: =IFERROR(VLOOKUP(A22,'F01 - _Données Centrales'!A6:B20,2,FALSE),"") | C22: =IFERROR(VLOOKUP(A22,'F01 - _Données Centrales'!A6:C20,3,FALSE),"")
B23: =IFERROR(VLOOKUP(A23,'F01 - _Données Centrales'!A6:B20,2,FALSE),"") | C23: =IFERROR(VLOOKUP(A23,'F01 - _Données Centrales'!A6:C20,3,FALSE),"")
B24: =IFERROR(VLOOKUP(A24,'F01 - _Données Centrales'!A6:B20,2,FALSE),"") | C24: =IFERROR(VLOOKUP(A24,'F01 - _Données Centrales'!A6:C20,3,FALSE),"")
B25: =IFERROR(VLOOKUP(A25,'F01 - _Données Centrales'!A6:B20,2,FALSE),"") | C25: =IFERROR(VLOOKUP(A25,'F01 - _Données Centrales'!A6:C20,3,FALSE),"")
B26: =IFERROR(VLOOKUP(A26,'F01 - _Données Centrales'!A6:B20,2,FALSE),"") | C26: =IFERROR(VLOOKUP(A26,'F01 - _Données Centrales'!A6:C20,3,FALSE),"")
B27: =IFERROR(VLOOKUP(A27,'F01 - _Données Centrales'!A6:B20,2,FALSE),"") | C27: =IFERROR(VLOOKUP(A27,'F01 - _Données Centrales'!A6:C20,3,FALSE),"")
B28: =IFERROR(VLOOKUP(A28,'F01 - _Données Centrales'!A6:B20,2,FALSE),"") | C28: =IFERROR(VLOOKUP(A28,'F01 - _Données Centrales'!A6:C20,3,FALSE),"")
