Workbook

Sheet F01 - _Données Expatriés
A2: DOMAINE 25 — GESTION DES EXPATRIÉS ET DU PERSONNEL DÉTACHÉ
A3: DONNÉES EXPATRIÉS — Base de référence centrale (toutes les feuilles s'y réfèrent)
A4: TABLEAU DYNAMIQUE — Saisissez dans la zone prévue ci-dessous
A5: Matricule | B5: Nom | C5: Prénom | D5: Nationalité | E5: Pays Origine | F5: Département | G5: Poste | H5: Type Contrat | I5: Date Début | J5: Date Fin | K5: Salaire Base (FCFA) | L5: Statut
A6: EXP-001 | B6: Dupont | C6: Jean-Pierre | D6: Française | E6: France | F6: Direction Générale | G6: Directeur Général | H6: Contrat expatrié | I6: 45306 | J6: 46401 | K6: 5500000 | L6: En poste
A7: EXP-002 | B7: Muller | C7: Hans | D7: Allemande | E7: Allemagne | F7: Cuisine & Restauration | G7: Chef Exécutif | H7: Contrat détaché | I7: 45352 | J7: 46081 | K7: 3800000 | L7: En poste
A8: EXP-003 | B8: Silva | C8: Carlos | D8: Brésilienne | E8: Brésil | F8: Finance & Comptabilité | G8: Directeur Financier | H8: Contrat expatrié | I8: 45444 | J8: 46538 | K8: 4500000 | L8: En poste
A9: EXP-004 | B9: Nakamura | C9: Yuki | D9: Japonaise | E9: Japon | F9: Réception & Front Office | G9: Responsable Réception | H9: Contrat expatrié | I9: 45536 | J9: 46265 | K9: 2800000 | L9: En poste
A10: EXP-005 | B10: Smith | C10: James | D10: Britannique | E10: Royaume-Uni | F10: Revenue Management | G10: Revenue Manager | H10: Contrat détaché | I10: 45658 | J10: 46387 | K10: 3200000 | L10: En poste
A11: EXP-006 | B11: Wang | C11: Mei | D11: Chinoise | E11: Chine | F11: Spa & Bien-être | G11: Directrice Spa | H11: Contrat expatrié | I11: 45689 | J11: 46418 | K11: 2600000 | L11: En poste
A12: EXP-007 | B12: Kowalski | C12: Anna | D12: Polonaise | E12: Pologne | F12: Ressources Humaines | G12: DRH Adjointe | H12: Contrat détaché | I12: 45383 | J12: 46112 | K12: 3000000 | L12: En poste
A13: EXP-008 | B13: Moreau | C13: Sophie | D13: Française | E13: France | F13: Marketing & Communication | G13: Directrice Marketing | H13: Contrat expatrié | I13: 45474 | J13: 46203 | K13: 3500000 | L13: En poste
A14: EXP-009 | B14: Okafor | C14: Chidi | D14: Nigériane | E14: Nigeria | F14: Maintenance & Technique | G14: Directeur Technique | H14: Contrat détaché | I14: 45717 | J14: 46446 | K14: 2900000 | L14: En poste
A15: EXP-010 | B15: Rossi | C15: Marco | D15: Italienne | E15: Italie | F15: Cuisine & Restauration | G15: Sous-Chef Pâtisserie | H15: Contrat expatrié | I15: 45672 | J15: 46036 | K15: 2200000 | L15: En poste

Sheet F02 - _Lists
A2: DOMAINE 25 — LISTES DE RÉFÉRENCE
A3: Valeurs pour listes déroulantes — Saisissez vos propres valeurs
A5: nationalites | B5: pays | C5: departements | D5: postes_exp | E5: types_contrat_exp | F5: statuts_exp | G5: types_visa | H5: statuts_visa | I5: types_permis | J5: niveaux_fiscalite | K5: types_assurance | L5: statuts_logement | M5: criteres_eval | N5: priorites | O5: types_litige_exp | P5: etapes_reloc | Q5: statuts_fin_mission | R5: modes_paiement | S5: origines | T5: tendances | U5: mois | V5: trimestres | W5: annees | X5: conformites | Y5: evaluations | Z5: recommandations | AA5: statuts_actif | AB5: statuts_litige | AC5: motifs_depart
A6: Française | B6: France | C6: Direction Générale | D6: Directeur Général | E6: Contrat expatrié | F6: En poste | G6: Visa travail | H6: Valide | I6: Permis de travail A | J6: Exonération totale | K6: Assurance santé internationale | L6: Villa hôtel | M6: Compétence technique | N6: Haute | O6: Litige contractuel | P6: Demande initiale | Q6: Renouvellement contrat | R6: Virement international | S6: Groupe hôtelier | T6: Hausse | U6: Janvier | V6: T1 | W6: 2024 | X6: Conforme | Y6: Excellent | Z6: Maintien en poste | AA6: Actif | AB6: En cours | AC6: Fin de contrat
A7: Allemande | B7: Allemagne | C7: Cuisine & Restauration | D7: Chef Exécutif | E7: Contrat détaché | F7: En transit | G7: Visa affaires | H7: En cours de renouvellement | I7: Permis de travail B | J7: Exonération partielle | K7: Assurance rapatriement | L7: Appartement meublé | M7: Adaptabilité culturelle | N7: Moyenne | O7: Litige fiscal | P7: Validation RH | Q7: Rapatriement | R7: Virement local | S7: Chaîne internationale | T7: Baisse | U7: Février | V7: T2 | W7: 2025 | X7: Non conforme | Y7: Très bon | Z7: Renouvellement | AA7: Inactif | AB7: Résolu | AC7: Raison personnelle
A8: Brésilienne | B8: Brésil | C8: Finance & Comptabilité | D8: Directeur Financier | E8: Mission technique | F8: En cours de renouvellement | G8: Visa touristique | H8: Expiré | I8: Carte professionnelle | J8: Imposition complète | K8: Assurance responsabilité civile | L8: Logement de fonction | M8: Leadership | N8: Basse | O8: Problème de visa | P8: Validation DG | Q8: Mutation interne | R8: Compte offshore | S8: Recrutement direct | T8: Stable | U8: Mars | V8: T3 | W8: 2026 | X8: En attente | Y8: Bon | Z8: Non renouvelé | AA8: Expiré | AB8: Clôturé | AC8: Mutation interne
A9: Japonaise | B9: Japon | C9: Réception & Front Office | D9: Responsable Réception | E9: Consultant international | F9: Pré-départ | G9: Carte de séjour | H9: En attente | I9: Exemption de permis | J9: Convention fiscale bilatérale | K9: Assurance voyage | L9: Indemnité logement | M9: Communication | N9: Critique | O9: Conflit avec équipe | P9: Obtention visa | Q9: Fin de mission prévue | R9: Mixte | S9: Organisme de placement | T9: En attente | U9: Avril | V9: T4 | W9: 2027 | X9: À régulariser | Y9: Satisfaisant | Z9: Mutation | AA9: Résilié | AB9: En attente | AC9: Fin de mission
A10: Britannique | B10: Royaume-Uni | C10: Revenue Management | D10: Revenue Manager | E10: Volontaire international | F10: En attente visa | G10: Titre de voyage | H10: Refusé | I10: En attente de délivrance | J10: Régime de droit commun | K10: Couverture CNPS locale | L10: Non pris en charge | M10: Respect des normes | O10: Litige salarial | P10: Voyage | Q10: Départ anticipé | S10: Mission tripartite | U10: Mai | Y10: Insuffisant | Z10: Promotion | AA10: En attente | AB10: Réouvert | AC10: Départ anticipé
A11: Chinoise | B11: Chine | C11: Spa & Bien-être | D11: Directrice Spa | F11: Mission terminée | H11: Non applicable | M11: Productivité | O11: Litige logement | P11: Accueil à l'arrivée | Q11: Non renouvelé | U11: Juin | Y11: À améliorer | Z11: Rapatriement | AC11: Non renouvelé
A12: Polonaise | B12: Pologne | C12: Ressources Humaines | D12: DRH Adjointe | M12: Esprit d'équipe | O12: Problème de relocalisation | P12: Installation logement | Q12: Transformation CDI local | U12: Juillet | AC12: Licenciement
A13: Italienne | B13: Italie | C13: Marketing & Communication | D13: Directrice Marketing | M13: Initiative | O13: Harcèlement | P13: Formation sécurité | U13: Août
A14: Nigériane | B14: Nigeria | C14: Maintenance & Technique | D14: Directeur Technique | O14: Autre | P14: Démarrage mission | U14: Septembre
A15: Marocaine | B15: Maroc | C15: Sécurité | D15: Sous-Chef Pâtisserie | P15: Suivi adaptation | U15: Octobre
A16: Américaine | B16: États-Unis | C16: Commerce | D16: Responsable Qualite | U16: Novembre
A17: Indienne | B17: Inde | C17: Gouvernance | D17: Formateur International | U17: Décembre
A18: Sénégalaise | B18: Sénégal
A19: Camerounaise | B19: Cameroun
A20: Sud-Africaine | B20: Afrique du Sud

Sheet F03 - 1-Tableau de Bord
A2: DOMAINE 25 — TABLEAU DE BORD SYNTHÉTIQUE
A3: Suivi des expatriés, coûts, conformité et performance
A6: Total Expatriés en Poste | B6: 10 | C6: Coût Mensuel Salaires (FCFA) | D6: 34000000 | E6: Contrats Actifs | F6: 10 | G6: Taux Conformité Visas | H6: 90% | I6: Coût Moyen/Expatrié (FCFA) | J6: 3400000 | K6: Nationalités Représentées | L6: 8
A9: Alertes Visa Expirant (< 30j) | B9: 2 | C9: Missions en Cours de Renouvellement | D9: 1 | E9: Dossier en Attente Permis | F9: 1 | G9: Litiges Ouverts | H9: 0 | I9: Taux Satisfaction Moyen | J9: 85% | K9: Durée Moyenne Mission (mois) | L9: 24

Sheet F04 - 2-Contrats Missions
A2: DOMAINE 25 — 2-CONTRATS ET MISSIONS EXPATRIÉS
A3: TABLEAU DYNAMIQUE — Saisissez dans la zone prévue ci-dessous
A5: Code Contrat | B5: Matricule | C5: Nom | D5: Département | E5: Poste | F5: Type Contrat | G5: Date Début | H5: Date Fin | I5: Durée (mois) | J5: Salaire Mensuel (FCFA) | K5: Statut
A6: CTR-2024-001 | B6: EXP-001 | C6: Dupont Jean-Pierre | D6: Direction Générale | E6: Directeur Général | F6: Contrat expatrié | G6: 45306 | H6: 46401 | I6: =IF(OR(G6="",H6=""),"",IFERROR((H6-G6)/30.44,0)) | J6: 5500000 | K6: En poste
A7: CTR-2024-002 | B7: EXP-002 | C7: Muller Hans | D7: Cuisine & Restauration | E7: Chef Exécutif | F7: Contrat détaché | G7: 45352 | H7: 46081 | I7: =IF(OR(G7="",H7=""),"",IFERROR((H7-G7)/30.44,0)) | J7: 3800000 | K7: En poste
A8: CTR-2024-003 | B8: EXP-003 | C8: Silva Carlos | D8: Finance & Comptabilité | E8: Directeur Financier | F8: Contrat expatrié | G8: 45444 | H8: 46538 | I8: =IF(OR(G8="",H8=""),"",IFERROR((H8-G8)/30.44,0)) | J8: 4500000 | K8: En poste
A9: CTR-2024-004 | B9: EXP-004 | C9: Nakamura Yuki | D9: Réception & Front Office | E9: Responsable Réception | F9: Contrat expatrié | G9: 45536 | H9: 46265 | I9: =IF(OR(G9="",H9=""),"",IFERROR((H9-G9)/30.44,0)) | J9: 2800000 | K9: En poste
A10: CTR-2025-005 | B10: EXP-005 | C10: Smith James | D10: Revenue Management | E10: Revenue Manager | F10: Contrat détaché | G10: 45658 | H10: 46387 | I10: =IF(OR(G10="",H10=""),"",IFERROR((H10-G10)/30.44,0)) | J10: 3200000 | K10: En poste
A11: =IF(B11="","","CTR-"&TEXT(ROW()-5,"000")) | C11: =IF(B11="","",VLOOKUP(B11,'F01 - _Données Expatriés'!$A$6:$L$15,2,FALSE)) | F11: =IF(B11="","",VLOOKUP(B11,'F01 - _Données Expatriés'!$A$6:$L$15,8,FALSE)) | I11: =IF(OR(G11="",H11=""),"",IFERROR((H11-G11)/30.44,0)) | J11: =IF(B11="","",VLOOKUP(B11,'F01 - _Données Expatriés'!$A$6:$L$15,11,FALSE))
A12: =IF(B12="","","CTR-"&TEXT(ROW()-5,"000")) | C12: =IF(B12="","",VLOOKUP(B12,'F01 - _Données Expatriés'!$A$6:$L$15,2,FALSE)) | F12: =IF(B12="","",VLOOKUP(B12,'F01 - _Données Expatriés'!$A$6:$L$15,8,FALSE)) | I12: =IF(OR(G12="",H12=""),"",IFERROR((H12-G12)/30.44,0)) | J12: =IF(B12="","",VLOOKUP(B12,'F01 - _Données Expatriés'!$A$6:$L$15,11,FALSE))
A13: =IF(B13="","","CTR-"&TEXT(ROW()-5,"000")) | C13: =IF(B13="","",VLOOKUP(B13,'F01 - _Données Expatriés'!$A$6:$L$15,2,FALSE)) | F13: =IF(B13="","",VLOOKUP(B13,'F01 - _Données Expatriés'!$A$6:$L$15,8,FALSE)) | I13: =IF(OR(G13="",H13=""),"",IFERROR((H13-G13)/30.44,0)) | J13: =IF(B13="","",VLOOKUP(B13,'F01 - _Données Expatriés'!$A$6:$L$15,11,FALSE))
A14: =IF(B14="","","CTR-"&TEXT(ROW()-5,"000")) | C14: =IF(B14="","",VLOOKUP(B14,'F01 - _Données Expatriés'!$A$6:$L$15,2,FALSE)) | F14: =IF(B14="","",VLOOKUP(B14,'F01 - _Données Expatriés'!$A$6:$L$15,8,FALSE)) | I14: =IF(OR(G14="",H14=""),"",IFERROR((H14-G14)/30.44,0)) | J14: =IF(B14="","",VLOOKUP(B14,'F01 - _Données Expatriés'!$A$6:$L$15,11,FALSE))
A15: =IF(B15="","","CTR-"&TEXT(ROW()-5,"000")) | C15: =IF(B15="","",VLOOKUP(B15,'F01 - _Données Expatriés'!$A$6:$L$15,2,FALSE)) | F15: =IF(B15="","",VLOOKUP(B15,'F01 - _Données Expatriés'!$A$6:$L$15,8,FALSE)) | I15: =IF(OR(G15="",H15=""),"",IFERROR((H15-G15)/30.44,0)) | J15: =IF(B15="","",VLOOKUP(B15,'F01 - _Données Expatriés'!$A$6:$L$15,11,FALSE))
A16: =IF(B16="","","CTR-"&TEXT(ROW()-5,"000")) | C16: =IF(B16="","",VLOOKUP(B16,'F01 - _Données Expatriés'!$A$6:$L$15,2,FALSE)) | F16: =IF(B16="","",VLOOKUP(B16,'F01 - _Données Expatriés'!$A$6:$L$15,8,FALSE)) | I16: =IF(OR(G16="",H16=""),"",IFERROR((H16-G16)/30.44,0)) | J16: =IF(B16="","",VLOOKUP(B16,'F01 - _Données Expatriés'!$A$6:$L$15,11,FALSE))
A17: =IF(B17="","","CTR-"&TEXT(ROW()-5,"000")) | C17: =IF(B17="","",VLOOKUP(B17,'F01 - _Données Expatriés'!$A$6:$L$15,2,FALSE)) | F17: =IF(B17="","",VLOOKUP(B17,'F01 - _Données Expatriés'!$A$6:$L$15,8,FALSE)) | I17: =IF(OR(G17="",H17=""),"",IFERROR((H17-G17)/30.44,0)) | J17: =IF(B17="","",VLOOKUP(B17,'F01 - _Données Expatriés'!$A$6:$L$15,11,FALSE))
A18: =IF(B18="","","CTR-"&TEXT(ROW()-5,"000")) | C18: =IF(B18="","",VLOOKUP(B18,'F01 - _Données Expatriés'!$A$6:$L$15,2,FALSE)) | F18: =IF(B18="","",VLOOKUP(B18,'F01 - _Données Expatriés'!$A$6:$L$15,8,FALSE)) | I18: =IF(OR(G18="",H18=""),"",IFERROR((H18-G18)/30.44,0)) | J18: =IF(B18="","",VLOOKUP(B18,'F01 - _Données Expatriés'!$A$6:$L$15,11,FALSE))
A19: =IF(B19="","","CTR-"&TEXT(ROW()-5,"000")) | C19: =IF(B19="","",VLOOKUP(B19,'F01 - _Données Expatriés'!$A$6:$L$15,2,FALSE)) | F19: =IF(B19="","",VLOOKUP(B19,'F01 - _Données Expatriés'!$A$6:$L$15,8,FALSE)) | I19: =IF(OR(G19="",H19=""),"",IFERROR((H19-G19)/30.44,0)) | J19: =IF(B19="","",VLOOKUP(B19,'F01 - _Données Expatriés'!$A$6:$L$15,11,FALSE))
A20: =IF(B20="","","CTR-"&TEXT(ROW()-5,"000")) | C20: =IF(B20="","",VLOOKUP(B20,'F01 - _Données Expatriés'!$A$6:$L$15,2,FALSE)) | F20: =IF(B20="","",VLOOKUP(B20,'F01 - _Données Expatriés'!$A$6:$L$15,8,FALSE)) | I20: =IF(OR(G20="",H20=""),"",IFERROR((H20-G20)/30.44,0)) | J20: =IF(B20="","",VLOOKUP(B20,'F01 - _Données Expatriés'!$A$6:$L$15,11,FALSE))
A21: =IF(B21="","","CTR-"&TEXT(ROW()-5,"000")) | C21: =IF(B21="","",VLOOKUP(B21,'F01 - _Données Expatriés'!$A$6:$L$15,2,FALSE)) | F21: =IF(B21="","",VLOOKUP(B21,'F01 - _Données Expatriés'!$A$6:$L$15,8,FALSE)) | I21: =IF(OR(G21="",H21=""),"",IFERROR((H21-G21)/30.44,0)) | J21: =IF(B21="","",VLOOKUP(B21,'F01 - _Données Expatriés'!$A$6:$L$15,11,FALSE))
A22: =IF(B22="","","CTR-"&TEXT(ROW()-5,"000")) | C22: =IF(B22="","",VLOOKUP(B22,'F01 - _Données Expatriés'!$A$6:$L$15,2,FALSE)) | F22: =IF(B22="","",VLOOKUP(B22,'F01 - _Données Expatriés'!$A$6:$L$15,8,FALSE)) | I22: =IF(OR(G22="",H22=""),"",IFERROR((H22-G22)/30.44,0)) | J22: =IF(B22="","",VLOOKUP(B22,'F01 - _Données Expatriés'!$A$6:$L$15,11,FALSE))
... A115: =IF(B115="","","CTR-"&TEXT(ROW()-5,"000")) | C115: =IF(B115="","",VLOOKUP(B115,'F01 - _Données Expatriés'!$A$6:$L$15,2,FALSE)) | F115: =IF(B115="","",VLOOKUP(B115,'F01 - _Données Expatriés'!$A$6:$L$15,8,FALSE)) | I115: =IF(OR(G115="",H115=""),"",IFERROR((H115-G115)/30.44,0)) | J115: =IF(B115="","",VLOOKUP(B115,'F01 - _Données Expatriés'!$A$6:$L$15,11,FALSE))

Sheet F05 - 3-Permis Visa
A2: DOMAINE 25 — 3-PERMIS DE TRAVAIL ET VISAS
A3: TABLEAU DYNAMIQUE — Suivi des autorisations de travail et de séjour
A5: Matricule | B5: Nom | C5: Nationalité | D5: Type Visa | E5: N. Visa | F5: Date Expiration Visa | G5: Jours Restants Visa | H5: Type Permis | I5: N. Permis | J5: Date Expiration Permis | K5: Jours Restants Permis | L5: Statut Conformité
A6: EXP-001 | B6: Dupont Jean-Pierre | C6: Française | D6: Visa travail | E6: V-2024-001 | F6: 46037 | G6: =IF(F6="","",IFERROR(F6-TODAY(),0)) | H6: Permis de travail A | I6: P-2024-001 | J6: 46037 | K6: =IF(J6="","",IFERROR(J6-TODAY(),0)) | L6: =IF(OR(G6="",K6=""),"",IF(AND(G6>30,K6>30),"Conforme",IF(OR(G6<15,K6<15),"CRITIQUE","A régulariser")))
A7: EXP-002 | B7: Muller Hans | C7: Allemande | D7: Visa travail | E7: V-2024-002 | F7: 45900 | G7: =IF(F7="","",IFERROR(F7-TODAY(),0)) | H7: Permis de travail A | I7: P-2024-002 | J7: 45900 | K7: =IF(J7="","",IFERROR(J7-TODAY(),0)) | L7: =IF(OR(G7="",K7=""),"",IF(AND(G7>30,K7>30),"Conforme",IF(OR(G7<15,K7<15),"CRITIQUE","A régulariser")))
A8: EXP-003 | B8: Silva Carlos | C8: Brésilienne | D8: Carte de séjour | E8: V-2024-003 | F8: 46174 | G8: =IF(F8="","",IFERROR(F8-TODAY(),0)) | H8: Permis de travail B | I8: P-2024-003 | J8: 46174 | K8: =IF(J8="","",IFERROR(J8-TODAY(),0)) | L8: =IF(OR(G8="",K8=""),"",IF(AND(G8>30,K8>30),"Conforme",IF(OR(G8<15,K8<15),"CRITIQUE","A régulariser")))
A9: EXP-004 | B9: Nakamura Yuki | C9: Japonaise | D9: Visa travail | E9: V-2024-004 | F9: 46022 | G9: =IF(F9="","",IFERROR(F9-TODAY(),0)) | H9: Carte professionnelle | I9: P-2024-004 | J9: 46022 | K9: =IF(J9="","",IFERROR(J9-TODAY(),0)) | L9: =IF(OR(G9="",K9=""),"",IF(AND(G9>30,K9>30),"Conforme",IF(OR(G9<15,K9<15),"CRITIQUE","A régulariser")))
A10: EXP-005 | B10: Smith James | C10: Britannique | D10: Visa affaires | E10: V-2025-005 | F10: 46203 | G10: =IF(F10="","",IFERROR(F10-TODAY(),0)) | H10: Permis de travail A | I10: P-2025-005 | J10: 46203 | K10: =IF(J10="","",IFERROR(J10-TODAY(),0)) | L10: =IF(OR(G10="",K10=""),"",IF(AND(G10>30,K10>30),"Conforme",IF(OR(G10<15,K10<15),"CRITIQUE","A régulariser")))
B11: =IF(A11="","",VLOOKUP(A11,'F01 - _Données Expatriés'!$A$6:$L$15,2,FALSE)) | C11: =IF(A11="","",VLOOKUP(A11,'F01 - _Données Expatriés'!$A$6:$L$15,4,FALSE)) | G11: =IF(F11="","",IFERROR(F11-TODAY(),0)) | K11: =IF(J11="","",IFERROR(J11-TODAY(),0)) | L11: =IF(OR(G11="",K11=""),"",IF(AND(G11>30,K11>30),"Conforme",IF(OR(G11<15,K11<15),"CRITIQUE","A régulariser")))
B12: =IF(A12="","",VLOOKUP(A12,'F01 - _Données Expatriés'!$A$6:$L$15,2,FALSE)) | C12: =IF(A12="","",VLOOKUP(A12,'F01 - _Données Expatriés'!$A$6:$L$15,4,FALSE)) | G12: =IF(F12="","",IFERROR(F12-TODAY(),0)) | K12: =IF(J12="","",IFERROR(J12-TODAY(),0)) | L12: =IF(OR(G12="",K12=""),"",IF(AND(G12>30,K12>30),"Conforme",IF(OR(G12<15,K12<15),"CRITIQUE","A régulariser")))
B13: =IF(A13="","",VLOOKUP(A13,'F01 - _Données Expatriés'!$A$6:$L$15,2,FALSE)) | C13: =IF(A13="","",VLOOKUP(A13,'F01 - _Données Expatriés'!$A$6:$L$15,4,FALSE)) | G13: =IF(F13="","",IFERROR(F13-TODAY(),0)) | K13: =IF(J13="","",IFERROR(J13-TODAY(),0)) | L13: =IF(OR(G13="",K13=""),"",IF(AND(G13>30,K13>30),"Conforme",IF(OR(G13<15,K13<15),"CRITIQUE","A régulariser")))
B14: =IF(A14="","",VLOOKUP(A14,'F01 - _Données Expatriés'!$A$6:$L$15,2,FALSE)) | C14: =IF(A14="","",VLOOKUP(A14,'F01 - _Données Expatriés'!$A$6:$L$15,4,FALSE)) | G14: =IF(F14="","",IFERROR(F14-TODAY(),0)) | K14: =IF(J14="","",IFERROR(J14-TODAY(),0)) | L14: =IF(OR(G14="",K14=""),"",IF(AND(G14>30,K14>30),"Conforme",IF(OR(G14<15,K14<15),"CRITIQUE","A régulariser")))
B15: =IF(A15="","",VLOOKUP(A15,'F01 - _Données Expatriés'!$A$6:$L$15,2,FALSE)) | C15: =IF(A15="","",VLOOKUP(A15,'F01 - _Données Expatriés'!$A$6:$L$15,4,FALSE)) | G15: =IF(F15="","",IFERROR(F15-TODAY(),0)) | K15: =IF(J15="","",IFERROR(J15-TODAY(),0)) | L15: =IF(OR(G15="",K15=""),"",IF(AND(G15>30,K15>30),"Conforme",IF(OR(G15<15,K15<15),"CRITIQUE","A régulariser")))
B16: =IF(A16="","",VLOOKUP(A16,'F01 - _Données Expatriés'!$A$6:$L$15,2,FALSE)) | C16: =IF(A16="","",VLOOKUP(A16,'F01 - _Données Expatriés'!$A$6:$L$15,4,FALSE)) | G16: =IF(F16="","",IFERROR(F16-TODAY(),0)) | K16: =IF(J16="","",IFERROR(J16-TODAY(),0)) | L16: =IF(OR(G16="",K16=""),"",IF(AND(G16>30,K16>30),"Conforme",IF(OR(G16<15,K16<15),"CRITIQUE","A régulariser")))
B17: =IF(A17="","",VLOOKUP(A17,'F01 - _Données Expatriés'!$A$6:$L$15,2,FALSE)) | C17: =IF(A17="","",VLOOKUP(A17,'F01 - _Données Expatriés'!$A$6:$L$15,4,FALSE)) | G17: =IF(F17="","",IFERROR(F17-TODAY(),0)) | K17: =IF(J17="","",IFERROR(J17-TODAY(),0)) | L17: =IF(OR(G17="",K17=""),"",IF(AND(G17>30,K17>30),"Conforme",IF(OR(G17<15,K17<15),"CRITIQUE","A régulariser")))
B18: =IF(A18="","",VLOOKUP(A18,'F01 - _Données Expatriés'!$A$6:$L$15,2,FALSE)) | C18: =IF(A18="","",VLOOKUP(A18,'F01 - _Données Expatriés'!$A$6:$L$15,4,FALSE)) | G18: =IF(F18="","",IFERROR(F18-TODAY(),0)) | K18: =IF(J18="","",IFERROR(J18-TODAY(),0)) | L18: =IF(OR(G18="",K18=""),"",IF(AND(G18>30,K18>30),"Conforme",IF(OR(G18<15,K18<15),"CRITIQUE","A régulariser")))
B19: =IF(A19="","",VLOOKUP(A19,'F01 - _Données Expatriés'!$A$6:$L$15,2,FALSE)) | C19: =IF(A19="","",VLOOKUP(A19,'F01 - _Données Expatriés'!$A$6:$L$15,4,FALSE)) | G19: =IF(F19="","",IFERROR(F19-TODAY(),0)) | K19: =IF(J19="","",IFERROR(J19-TODAY(),0)) | L19: =IF(OR(G19="",K19=""),"",IF(AND(G19>30,K19>30),"Conforme",IF(OR(G19<15,K19<15),"CRITIQUE","A régulariser")))
B20: =IF(A20="","",VLOOKUP(A20,'F01 - _Données Expatriés'!$A$6:$L$15,2,FALSE)) | C20: =IF(A20="","",VLOOKUP(A20,'F01 - _Données Expatriés'!$A$6:$L$15,4,FALSE)) | G20: =IF(F20="","",IFERROR(F20-TODAY(),0)) | K20: =IF(J20="","",IFERROR(J20-TODAY(),0)) | L20: =IF(OR(G20="",K20=""),"",IF(AND(G20>30,K20>30),"Conforme",IF(OR(G20<15,K20<15),"CRITIQUE","A régulariser")))
B21: =IF(A21="","",VLOOKUP(A21,'F01 - _Données Expatriés'!$A$6:$L$15,2,FALSE)) | C21: =IF(A21="","",VLOOKUP(A21,'F01 - _Données Expatriés'!$A$6:$L$15,4,FALSE)) | G21: =IF(F21="","",IFERROR(F21-TODAY(),0)) | K21: =IF(J21="","",IFERROR(J21-TODAY(),0)) | L21: =IF(OR(G21="",K21=""),"",IF(AND(G21>30,K21>30),"Conforme",IF(OR(G21<15,K21<15),"CRITIQUE","A régulariser")))
B22: =IF(A22="","",VLOOKUP(A22,'F01 - _Données Expatriés'!$A$6:$L$15,2,FALSE)) | C22: =IF(A22="","",VLOOKUP(A22,'F01 - _Données Expatriés'!$A$6:$L$15,4,FALSE)) | G22: =IF(F22="","",IFERROR(F22-TODAY(),0)) | K22: =IF(J22="","",IFERROR(J22-TODAY(),0)) | L22: =IF(OR(G22="",K22=""),"",IF(AND(G22>30,K22>30),"Conforme",IF(OR(G22<15,K22<15),"CRITIQUE","A régulariser")))
... B115: =IF(A115="","",VLOOKUP(A115,'F01 - _Données Expatriés'!$A$6:$L$15,2,FALSE)) | C115: =IF(A115="","",VLOOKUP(A115,'F01 - _Données Expatriés'!$A$6:$L$15,4,FALSE)) | G115: =IF(F115="","",IFERROR(F115-TODAY(),0)) | K115: =IF(J115="","",IFERROR(J115-TODAY(),0)) | L115: =IF(OR(G115="",K115=""),"",IF(AND(G115>30,K115>30),"Conforme",IF(OR(G115<15,K115<15),"CRITIQUE","A régulariser")))

Sheet F06 - 4-Suivi Presence
A2: DOMAINE 25 — 4-SUIVI PRÉSENCE EXPATRIÉS
A3: TABLEAU DYNAMIQUE — Saisissez dans la zone prévue ci-dessous
A5: Matricule | B5: Nom | C5: Prénom | D5: Département | E5: Mois | F5: Jours Ouvrés | G5: Jours Présences | H5: Jours Absences | I5: Jours Congés | J5: Taux Présence (%)
A6: EXP-001 | B6: Dupont | C6: Jean-Pierre | D6: Direction Générale | E6: Janvier 2025 | F6: 22 | G6: 21 | H6: 1 | I6: 0 | J6: =IF(F6="","",IFERROR(G6/F6*100,0))
A7: EXP-002 | B7: Muller | C7: Hans | D7: Cuisine & Restauration | E7: Janvier 2025 | F7: 22 | G7: 20 | H7: 0 | I7: 2 | J7: =IF(F7="","",IFERROR(G7/F7*100,0))
A8: EXP-003 | B8: Silva | C8: Carlos | D8: Finance & Comptabilité | E8: Janvier 2025 | F8: 22 | G8: 22 | H8: 0 | I8: 0 | J8: =IF(F8="","",IFERROR(G8/F8*100,0))
A9: EXP-004 | B9: Nakamura | C9: Yuki | D9: Réception & Front Office | E9: Février 2025 | F9: 20 | G9: 19 | H9: 0 | I9: 1 | J9: =IF(F9="","",IFERROR(G9/F9*100,0))
A10: EXP-005 | B10: Smith | C10: James | D10: Revenue Management | E10: Février 2025 | F10: 20 | G10: 20 | H10: 0 | I10: 0 | J10: =IF(F10="","",IFERROR(G10/F10*100,0))
B11: =IF(A11="","",VLOOKUP(A11,'F01 - _Données Expatriés'!$A$6:$L$15,2,FALSE)) | C11: =IF(A11="","",VLOOKUP(A11,'F01 - _Données Expatriés'!$A$6:$L$15,3,FALSE)) | D11: =IF(A11="","",VLOOKUP(A11,'F01 - _Données Expatriés'!$A$6:$L$15,6,FALSE)) | H11: =IF(F11="","",IFERROR(F11-G11-J11,0)) | J11: =IF(F11="","",IFERROR(G11/F11*100,0))
B12: =IF(A12="","",VLOOKUP(A12,'F01 - _Données Expatriés'!$A$6:$L$15,2,FALSE)) | C12: =IF(A12="","",VLOOKUP(A12,'F01 - _Données Expatriés'!$A$6:$L$15,3,FALSE)) | D12: =IF(A12="","",VLOOKUP(A12,'F01 - _Données Expatriés'!$A$6:$L$15,6,FALSE)) | H12: =IF(F12="","",IFERROR(F12-G12-J12,0)) | J12: =IF(F12="","",IFERROR(G12/F12*100,0))
B13: =IF(A13="","",VLOOKUP(A13,'F01 - _Données Expatriés'!$A$6:$L$15,2,FALSE)) | C13: =IF(A13="","",VLOOKUP(A13,'F01 - _Données Expatriés'!$A$6:$L$15,3,FALSE)) | D13: =IF(A13="","",VLOOKUP(A13,'F01 - _Données Expatriés'!$A$6:$L$15,6,FALSE)) | H13: =IF(F13="","",IFERROR(F13-G13-J13,0)) | J13: =IF(F13="","",IFERROR(G13/F13*100,0))
B14: =IF(A14="","",VLOOKUP(A14,'F01 - _Données Expatriés'!$A$6:$L$15,2,FALSE)) | C14: =IF(A14="","",VLOOKUP(A14,'F01 - _Données Expatriés'!$A$6:$L$15,3,FALSE)) | D14: =IF(A14="","",VLOOKUP(A14,'F01 - _Données Expatriés'!$A$6:$L$15,6,FALSE)) | H14: =IF(F14="","",IFERROR(F14-G14-J14,0)) | J14: =IF(F14="","",IFERROR(G14/F14*100,0))
B15: =IF(A15="","",VLOOKUP(A15,'F01 - _Données Expatriés'!$A$6:$L$15,2,FALSE)) | C15: =IF(A15="","",VLOOKUP(A15,'F01 - _Données Expatriés'!$A$6:$L$15,3,FALSE)) | D15: =IF(A15="","",VLOOKUP(A15,'F01 - _Données Expatriés'!$A$6:$L$15,6,FALSE)) | H15: =IF(F15="","",IFERROR(F15-G15-J15,0)) | J15: =IF(F15="","",IFERROR(G15/F15*100,0))
B16: =IF(A16="","",VLOOKUP(A16,'F01 - _Données Expatriés'!$A$6:$L$15,2,FALSE)) | C16: =IF(A16="","",VLOOKUP(A16,'F01 - _Données Expatriés'!$A$6:$L$15,3,FALSE)) | D16: =IF(A16="","",VLOOKUP(A16,'F01 - _Données Expatriés'!$A$6:$L$15,6,FALSE)) | H16: =IF(F16="","",IFERROR(F16-G16-J16,0)) | J16: =IF(F16="","",IFERROR(G16/F16*100,0))
B17: =IF(A17="","",VLOOKUP(A17,'F01 - _Données Expatriés'!$A$6:$L$15,2,FALSE)) | C17: =IF(A17="","",VLOOKUP(A17,'F01 - _Données Expatriés'!$A$6:$L$15,3,FALSE)) | D17: =IF(A17="","",VLOOKUP(A17,'F01 - _Données Expatriés'!$A$6:$L$15,6,FALSE)) | H17: =IF(F17="","",IFERROR(F17-G17-J17,0)) | J17: =IF(F17="","",IFERROR(G17/F17*100,0))
B18: =IF(A18="","",VLOOKUP(A18,'F01 - _Données Expatriés'!$A$6:$L$15,2,FALSE)) | C18: =IF(A18="","",VLOOKUP(A18,'F01 - _Données Expatriés'!$A$6:$L$15,3,FALSE)) | D18: =IF(A18="","",VLOOKUP(A18,'F01 - _Données Expatriés'!$A$6:$L$15,6,FALSE)) | H18: =IF(F18="","",IFERROR(F18-G18-J18,0)) | J18: =IF(F18="","",IFERROR(G18/F18*100,0))
B19: =IF(A19="","",VLOOKUP(A19,'F01 - _Données Expatriés'!$A$6:$L$15,2,FALSE)) | C19: =IF(A19="","",VLOOKUP(A19,'F01 - _Données Expatriés'!$A$6:$L$15,3,FALSE)) | D19: =IF(A19="","",VLOOKUP(A19,'F01 - _Données Expatriés'!$A$6:$L$15,6,FALSE)) | H19: =IF(F19="","",IFERROR(F19-G19-J19,0)) | J19: =IF(F19="","",IFERROR(G19/F19*100,0))
B20: =IF(A20="","",VLOOKUP(A20,'F01 - _Données Expatriés'!$A$6:$L$15,2,FALSE)) | C20: =IF(A20="","",VLOOKUP(A20,'F01 - _Données Expatriés'!$A$6:$L$15,3,FALSE)) | D20: =IF(A20="","",VLOOKUP(A20,'F01 - _Données Expatriés'!$A$6:$L$15,6,FALSE)) | H20: =IF(F20="","",IFERROR(F20-G20-J20,0)) | J20: =IF(F20="","",IFERROR(G20/F20*100,0))
B21: =IF(A21="","",VLOOKUP(A21,'F01 - _Données Expatriés'!$A$6:$L$15,2,FALSE)) | C21: =IF(A21="","",VLOOKUP(A21,'F01 - _Données Expatriés'!$A$6:$L$15,3,FALSE)) | D21: =IF(A21="","",VLOOKUP(A21,'F01 - _Données Expatriés'!$A$6:$L$15,6,FALSE)) | H21: =IF(F21="","",IFERROR(F21-G21-J21,0)) | J21: =IF(F21="","",IFERROR(G21/F21*100,0))
B22: =IF(A22="","",VLOOKUP(A22,'F01 - _Données Expatriés'!$A$6:$L$15,2,FALSE)) | C22: =IF(A22="","",VLOOKUP(A22,'F01 - _Données Expatriés'!$A$6:$L$15,3,FALSE)) | D22: =IF(A22="","",VLOOKUP(A22,'F01 - _Données Expatriés'!$A$6:$L$15,6,FALSE)) | H22: =IF(F22="","",IFERROR(F22-G22-J22,0)) | J22: =IF(F22="","",IFERROR(G22/F22*100,0))
... B115: =IF(A115="","",VLOOKUP(A115,'F01 - _Données Expatriés'!$A$6:$L$15,2,FALSE)) | C115: =IF(A115="","",VLOOKUP(A115,'F01 - _Données Expatriés'!$A$6:$L$15,3,FALSE)) | D115: =IF(A115="","",VLOOKUP(A115,'F01 - _Données Expatriés'!$A$6:$L$15,6,FALSE)) | H115: =IF(F115="","",IFERROR(F115-G115-J115,0)) | J115: =IF(F115="","",IFERROR(G115/F115*100,0))

Sheet F07 - 5-Éval. Expatriés
A2: DOMAINE 25 — 5-ÉVALUATION EXPATRIÉS
A3: TABLEAU DYNAMIQUE — Saisissez dans la zone prévue ci-dessous
A5: Code Eval. | B5: Matricule | C5: Nom | D5: Département | E5: Critère | F5: Note (1-5) | G5: Commentaire | H5: Date Éval. | I5: Évaluateur | J5: Recommandation
A6: EVA-E-001 | B6: EXP-001 | C6: Dupont Jean-Pierre | D6: Direction Générale | E6: Leadership | F6: 5 | G6: Leadership exceptionnel, vision stratégique claire | H6: 45677 | I6: Conseil de Surveillance | J6: Maintien en poste
A7: EVA-E-002 | B7: EXP-002 | C7: Muller Hans | D7: Cuisine & Restauration | E7: Compétence technique | F7: 5 | G7: Maîtrise parfaite de la cuisine internationale | H7: 45679 | I7: DG Adjoint | J7: Maintien en poste
A8: EVA-E-003 | B8: EXP-003 | C8: Silva Carlos | D8: Finance & Comptabilité | E8: Productivité | F8: 4 | G8: Bon travail, en progression sur les normes locales | H8: 45682 | I8: DG | J8: Maintien en poste
A9: EVA-E-004 | B9: EXP-004 | C9: Nakamura Yuki | D9: Réception & Front Office | E9: Adaptabilité culturelle | F9: 4 | G9: Bonne intégration dans l'équipe ivoirienne | H9: 45693 | I9: DRH | J9: Renouvellement
A10: EVA-E-005 | B10: EXP-005 | C10: Smith James | D10: Revenue Management | E10: Communication | F10: 5 | G10: Excellente communication avec les équipes locales | H10: 45698 | I10: DG | J10: Maintien en poste
C11: =IF(B11="","",VLOOKUP(B11,'F01 - _Données Expatriés'!$A$6:$L$15,2,FALSE)) | D11: =IF(B11="","",VLOOKUP(B11,'F01 - _Données Expatriés'!$A$6:$L$15,6,FALSE))
C12: =IF(B12="","",VLOOKUP(B12,'F01 - _Données Expatriés'!$A$6:$L$15,2,FALSE)) | D12: =IF(B12="","",VLOOKUP(B12,'F01 - _Données Expatriés'!$A$6:$L$15,6,FALSE))
C13: =IF(B13="","",VLOOKUP(B13,'F01 - _Données Expatriés'!$A$6:$L$15,2,FALSE)) | D13: =IF(B13="","",VLOOKUP(B13,'F01 - _Données Expatriés'!$A$6:$L$15,6,FALSE))
C14: =IF(B14="","",VLOOKUP(B14,'F01 - _Données Expatriés'!$A$6:$L$15,2,FALSE)) | D14: =IF(B14="","",VLOOKUP(B14,'F01 - _Données Expatriés'!$A$6:$L$15,6,FALSE))
C15: =IF(B15="","",VLOOKUP(B15,'F01 - _Données Expatriés'!$A$6:$L$15,2,FALSE)) | D15: =IF(B15="","",VLOOKUP(B15,'F01 - _Données Expatriés'!$A$6:$L$15,6,FALSE))
C16: =IF(B16="","",VLOOKUP(B16,'F01 - _Données Expatriés'!$A$6:$L$15,2,FALSE)) | D16: =IF(B16="","",VLOOKUP(B16,'F01 - _Données Expatriés'!$A$6:$L$15,6,FALSE))
C17: =IF(B17="","",VLOOKUP(B17,'F01 - _Données Expatriés'!$A$6:$L$15,2,FALSE)) | D17: =IF(B17="","",VLOOKUP(B17,'F01 - _Données Expatriés'!$A$6:$L$15,6,FALSE))
C18: =IF(B18="","",VLOOKUP(B18,'F01 - _Données Expatriés'!$A$6:$L$15,2,FALSE)) | D18: =IF(B18="","",VLOOKUP(B18,'F01 - _Données Expatriés'!$A$6:$L$15,6,FALSE))
C19: =IF(B19="","",VLOOKUP(B19,'F01 - _Données Expatriés'!$A$6:$L$15,2,FALSE)) | D19: =IF(B19="","",VLOOKUP(B19,'F01 - _Données Expatriés'!$A$6:$L$15,6,FALSE))
C20: =IF(B20="","",VLOOKUP(B20,'F01 - _Données Expatriés'!$A$6:$L$15,2,FALSE)) | D20: =IF(B20="","",VLOOKUP(B20,'F01 - _Données Expatriés'!$A$6:$L$15,6,FALSE))
C21: =IF(B21="","",VLOOKUP(B21,'F01 - _Données Expatriés'!$A$6:$L$15,2,FALSE)) | D21: =IF(B21="","",VLOOKUP(B21,'F01 - _Données Expatriés'!$A$6:$L$15,6,FALSE))
C22: =IF(B22="","",VLOOKUP(B22,'F01 - _Données Expatriés'!$A$6:$L$15,2,FALSE)) | D22: =IF(B22="","",VLOOKUP(B22,'F01 - _Données Expatriés'!$A$6:$L$15,6,FALSE))
... C115: =IF(B115="","",VLOOKUP(B115,'F01 - _Données Expatriés'!$A$6:$L$15,2,FALSE)) | D115: =IF(B115="","",VLOOKUP(B115,'F01 - _Données Expatriés'!$A$6:$L$15,6,FALSE))

Sheet F08 - 6-Plan Relocalisation
A2: DOMAINE 25 — 6-PLAN DE RELOCALISATION
A3: TABLEAU DYNAMIQUE — Saisissez dans la zone prévue ci-dessous
A5: Matricule | B5: Nom | C5: Département | D5: Étape | E5: Activité | F5: Responsable | G5: Date Début | H5: Date Fin | I5: Statut | J5: Coût (FCFA)
A6: EXP-001 | B6: Dupont Jean-Pierre | C6: Direction Générale | D6: Demande initiale | E6: Validation contrat par siège social | F6: Siège Paris | G6: 45231 | H6: 45275 | I6: Terminée | J6: 150000
A7: EXP-001 | B7: Dupont Jean-Pierre | C7: Direction Générale | D7: Obtention visa | E7: Dépôt dossier visa travail ambassade | F7: DRH | G7: 45276 | H7: 45301 | I7: Terminée | J7: 350000
A8: EXP-001 | B8: Dupont Jean-Pierre | C8: Direction Générale | D8: Installation logement | E8: Aménagement villa et meubles | F8: Service Technique | G8: 45296 | H8: 45305 | I8: Terminée | J8: 2500000
A9: EXP-002 | B9: Muller Hans | C9: Cuisine & Restauration | D9: Demande initiale | E9: Validation contrat par siège Berlin | F9: Siège Berlin | G9: 45292 | H9: 45337 | I9: Terminée | J9: 120000
A10: EXP-002 | B10: Muller Hans | C10: Cuisine & Restauration | D10: Voyage | E10: Billet avion et accueil aéroport | F10: DRH | G10: 45347 | H10: 45350 | I10: Terminée | J10: 850000
B11: =IF(A11="","",VLOOKUP(A11,'F01 - _Données Expatriés'!$A$6:$L$15,2,FALSE)) | C11: =IF(A11="","",VLOOKUP(A11,'F01 - _Données Expatriés'!$A$6:$L$15,6,FALSE))
B12: =IF(A12="","",VLOOKUP(A12,'F01 - _Données Expatriés'!$A$6:$L$15,2,FALSE)) | C12: =IF(A12="","",VLOOKUP(A12,'F01 - _Données Expatriés'!$A$6:$L$15,6,FALSE))
B13: =IF(A13="","",VLOOKUP(A13,'F01 - _Données Expatriés'!$A$6:$L$15,2,FALSE)) | C13: =IF(A13="","",VLOOKUP(A13,'F01 - _Données Expatriés'!$A$6:$L$15,6,FALSE))
B14: =IF(A14="","",VLOOKUP(A14,'F01 - _Données Expatriés'!$A$6:$L$15,2,FALSE)) | C14: =IF(A14="","",VLOOKUP(A14,'F01 - _Données Expatriés'!$A$6:$L$15,6,FALSE))
B15: =IF(A15="","",VLOOKUP(A15,'F01 - _Données Expatriés'!$A$6:$L$15,2,FALSE)) | C15: =IF(A15="","",VLOOKUP(A15,'F01 - _Données Expatriés'!$A$6:$L$15,6,FALSE))
B16: =IF(A16="","",VLOOKUP(A16,'F01 - _Données Expatriés'!$A$6:$L$15,2,FALSE)) | C16: =IF(A16="","",VLOOKUP(A16,'F01 - _Données Expatriés'!$A$6:$L$15,6,FALSE))
B17: =IF(A17="","",VLOOKUP(A17,'F01 - _Données Expatriés'!$A$6:$L$15,2,FALSE)) | C17: =IF(A17="","",VLOOKUP(A17,'F01 - _Données Expatriés'!$A$6:$L$15,6,FALSE))
B18: =IF(A18="","",VLOOKUP(A18,'F01 - _Données Expatriés'!$A$6:$L$15,2,FALSE)) | C18: =IF(A18="","",VLOOKUP(A18,'F01 - _Données Expatriés'!$A$6:$L$15,6,FALSE))
B19: =IF(A19="","",VLOOKUP(A19,'F01 - _Données Expatriés'!$A$6:$L$15,2,FALSE)) | C19: =IF(A19="","",VLOOKUP(A19,'F01 - _Données Expatriés'!$A$6:$L$15,6,FALSE))
B20: =IF(A20="","",VLOOKUP(A20,'F01 - _Données Expatriés'!$A$6:$L$15,2,FALSE)) | C20: =IF(A20="","",VLOOKUP(A20,'F01 - _Données Expatriés'!$A$6:$L$15,6,FALSE))
B21: =IF(A21="","",VLOOKUP(A21,'F01 - _Données Expatriés'!$A$6:$L$15,2,FALSE)) | C21: =IF(A21="","",VLOOKUP(A21,'F01 - _Données Expatriés'!$A$6:$L$15,6,FALSE))
B22: =IF(A22="","",VLOOKUP(A22,'F01 - _Données Expatriés'!$A$6:$L$15,2,FALSE)) | C22: =IF(A22="","",VLOOKUP(A22,'F01 - _Données Expatriés'!$A$6:$L$15,6,FALSE))
... B115: =IF(A115="","",VLOOKUP(A115,'F01 - _Données Expatriés'!$A$6:$L$15,2,FALSE)) | C115: =IF(A115="","",VLOOKUP(A115,'F01 - _Données Expatriés'!$A$6:$L$15,6,FALSE))

Sheet F09 - 7-Gestion Logement
A2: DOMAINE 25 — 7-GESTION LOGEMENT EXPATRIÉS
A3: TABLEAU DYNAMIQUE — Saisissez dans la zone prévue ci-dessous
A5: Matricule | B5: Nom | C5: Département | D5: Type Logement | E5: Adresse | F5: Loyer Mensuel (FCFA) | G5: Charges (FCFA) | H5: Total Mensuel (FCFA) | I5: Date Début Bail | J5: Date Fin Bail | K5: Statut
A6: EXP-001 | B6: Dupont Jean-Pierre | C6: Direction Générale | D6: Villa hôtel | E6: Cocody Riviera 3, Abidjan | F6: 1500000 | G6: 250000 | H6: =F6+G6 | I6: 45306 | J6: 46401 | K6: Actif
A7: EXP-002 | B7: Muller Hans | C7: Cuisine & Restauration | D7: Appartement meublé | E7: Plateau, Abidjan | F7: 800000 | G7: 120000 | H7: =F7+G7 | I7: 45352 | J7: 46081 | K7: Actif
A8: EXP-003 | B8: Silva Carlos | C8: Finance & Comptabilité | D8: Villa hôtel | E8: Cocody Palmeraie, Abidjan | F8: 1200000 | G8: 200000 | H8: =F8+G8 | I8: 45444 | J8: 46538 | K8: Actif
A9: EXP-004 | B9: Nakamura Yuki | C9: Réception & Front Office | D9: Appartement meublé | E9: Marcory Zone 4, Abidjan | F9: 600000 | G9: 100000 | H9: =F9+G9 | I9: 45536 | J9: 46265 | K9: Actif
A10: EXP-005 | B10: Smith James | C10: Revenue Management | D10: Logement de fonction | E10: Hotel (suite exec.), Abidjan | F10: 0 | G10: 0 | H10: =F10+G10 | I10: 45658 | J10: 46387 | K10: Actif
B11: =IF(A11="","",VLOOKUP(A11,'F01 - _Données Expatriés'!$A$6:$L$15,2,FALSE)) | C11: =IF(A11="","",VLOOKUP(A11,'F01 - _Données Expatriés'!$A$6:$L$15,6,FALSE)) | H11: =IF(F11="","",F11+G11)
B12: =IF(A12="","",VLOOKUP(A12,'F01 - _Données Expatriés'!$A$6:$L$15,2,FALSE)) | C12: =IF(A12="","",VLOOKUP(A12,'F01 - _Données Expatriés'!$A$6:$L$15,6,FALSE)) | H12: =IF(F12="","",F12+G12)
B13: =IF(A13="","",VLOOKUP(A13,'F01 - _Données Expatriés'!$A$6:$L$15,2,FALSE)) | C13: =IF(A13="","",VLOOKUP(A13,'F01 - _Données Expatriés'!$A$6:$L$15,6,FALSE)) | H13: =IF(F13="","",F13+G13)
B14: =IF(A14="","",VLOOKUP(A14,'F01 - _Données Expatriés'!$A$6:$L$15,2,FALSE)) | C14: =IF(A14="","",VLOOKUP(A14,'F01 - _Données Expatriés'!$A$6:$L$15,6,FALSE)) | H14: =IF(F14="","",F14+G14)
B15: =IF(A15="","",VLOOKUP(A15,'F01 - _Données Expatriés'!$A$6:$L$15,2,FALSE)) | C15: =IF(A15="","",VLOOKUP(A15,'F01 - _Données Expatriés'!$A$6:$L$15,6,FALSE)) | H15: =IF(F15="","",F15+G15)
B16: =IF(A16="","",VLOOKUP(A16,'F01 - _Données Expatriés'!$A$6:$L$15,2,FALSE)) | C16: =IF(A16="","",VLOOKUP(A16,'F01 - _Données Expatriés'!$A$6:$L$15,6,FALSE)) | H16: =IF(F16="","",F16+G16)
B17: =IF(A17="","",VLOOKUP(A17,'F01 - _Données Expatriés'!$A$6:$L$15,2,FALSE)) | C17: =IF(A17="","",VLOOKUP(A17,'F01 - _Données Expatriés'!$A$6:$L$15,6,FALSE)) | H17: =IF(F17="","",F17+G17)
B18: =IF(A18="","",VLOOKUP(A18,'F01 - _Données Expatriés'!$A$6:$L$15,2,FALSE)) | C18: =IF(A18="","",VLOOKUP(A18,'F01 - _Données Expatriés'!$A$6:$L$15,6,FALSE)) | H18: =IF(F18="","",F18+G18)
B19: =IF(A19="","",VLOOKUP(A19,'F01 - _Données Expatriés'!$A$6:$L$15,2,FALSE)) | C19: =IF(A19="","",VLOOKUP(A19,'F01 - _Données Expatriés'!$A$6:$L$15,6,FALSE)) | H19: =IF(F19="","",F19+G19)
B20: =IF(A20="","",VLOOKUP(A20,'F01 - _Données Expatriés'!$A$6:$L$15,2,FALSE)) | C20: =IF(A20="","",VLOOKUP(A20,'F01 - _Données Expatriés'!$A$6:$L$15,6,FALSE)) | H20: =IF(F20="","",F20+G20)
B21: =IF(A21="","",VLOOKUP(A21,'F01 - _Données Expatriés'!$A$6:$L$15,2,FALSE)) | C21: =IF(A21="","",VLOOKUP(A21,'F01 - _Données Expatriés'!$A$6:$L$15,6,FALSE)) | H21: =IF(F21="","",F21+G21)
B22: =IF(A22="","",VLOOKUP(A22,'F01 - _Données Expatriés'!$A$6:$L$15,2,FALSE)) | C22: =IF(A22="","",VLOOKUP(A22,'F01 - _Données Expatriés'!$A$6:$L$15,6,FALSE)) | H22: =IF(F22="","",F22+G22)
... B115: =IF(A115="","",VLOOKUP(A115,'F01 - _Données Expatriés'!$A$6:$L$15,2,FALSE)) | C115: =IF(A115="","",VLOOKUP(A115,'F01 - _Données Expatriés'!$A$6:$L$15,6,FALSE)) | H115: =IF(F115="","",F115+G115)

Sheet F10 - 8-Suivi Remuneration
A2: DOMAINE 25 — 8-SUIVI RÉMUNÉRATION EXPATRIÉS
A3: TABLEAU DYNAMIQUE — Saisissez dans la zone prévue ci-dessous
A5: Code Paiement | B5: Matricule | C5: Nom | D5: Mois | E5: Salaire Base (FCFA) | F5: Prime Expatriation (FCFA) | G5: Indemnité Logement (FCFA) | H5: Indemnité Scolarité (FCFA) | I5: Retenues (FCFA) | J5: Net à Payer (FCFA) | K5: Mode Paiement
A6: PAY-E-2025-001 | B6: EXP-001 | C6: Dupont Jean-Pierre | D6: Janvier 2025 | E6: 5500000 | F6: 1100000 | G6: 350000 | H6: 500000 | I6: =IF(E6="","",IFERROR((E6+F6+G6+H6)*0.08,0)) | J6: =IF(E6="","",E6+F6+G6+H6-I6) | K6: Virement international
A7: PAY-E-2025-002 | B7: EXP-002 | C7: Muller Hans | D7: Janvier 2025 | E7: 3800000 | F7: 760000 | G7: 250000 | H7: 300000 | I7: =IF(E7="","",IFERROR((E7+F7+G7+H7)*0.08,0)) | J7: =IF(E7="","",E7+F7+G7+H7-I7) | K7: Virement international
A8: PAY-E-2025-003 | B8: EXP-003 | C8: Silva Carlos | D8: Janvier 2025 | E8: 4500000 | F8: 900000 | G8: 300000 | H8: 400000 | I8: =IF(E8="","",IFERROR((E8+F8+G8+H8)*0.08,0)) | J8: =IF(E8="","",E8+F8+G8+H8-I8) | K8: Compte offshore
A9: PAY-E-2025-004 | B9: EXP-004 | C9: Nakamura Yuki | D9: Janvier 2025 | E9: 2800000 | F9: 560000 | G9: 200000 | H9: 0 | I9: =IF(E9="","",IFERROR((E9+F9+G9+H9)*0.08,0)) | J9: =IF(E9="","",E9+F9+G9+H9-I9) | K9: Mixte
A10: PAY-E-2025-005 | B10: EXP-005 | C10: Smith James | D10: Janvier 2025 | E10: 3200000 | F10: 640000 | G10: 0 | H10: 350000 | I10: =IF(E10="","",IFERROR((E10+F10+G10+H10)*0.08,0)) | J10: =IF(E10="","",E10+F10+G10+H10-I10) | K10: Virement international
C11: =IF(B11="","",VLOOKUP(B11,'F01 - _Données Expatriés'!$A$6:$L$15,2,FALSE)) | I11: =IF(E11="","",IFERROR((E11+F11+G11+H11)*0.08,0)) | J11: =IF(E11="","",E11+F11+G11+H11-I11)
C12: =IF(B12="","",VLOOKUP(B12,'F01 - _Données Expatriés'!$A$6:$L$15,2,FALSE)) | I12: =IF(E12="","",IFERROR((E12+F12+G12+H12)*0.08,0)) | J12: =IF(E12="","",E12+F12+G12+H12-I12)
C13: =IF(B13="","",VLOOKUP(B13,'F01 - _Données Expatriés'!$A$6:$L$15,2,FALSE)) | I13: =IF(E13="","",IFERROR((E13+F13+G13+H13)*0.08,0)) | J13: =IF(E13="","",E13+F13+G13+H13-I13)
C14: =IF(B14="","",VLOOKUP(B14,'F01 - _Données Expatriés'!$A$6:$L$15,2,FALSE)) | I14: =IF(E14="","",IFERROR((E14+F14+G14+H14)*0.08,0)) | J14: =IF(E14="","",E14+F14+G14+H14-I14)
C15: =IF(B15="","",VLOOKUP(B15,'F01 - _Données Expatriés'!$A$6:$L$15,2,FALSE)) | I15: =IF(E15="","",IFERROR((E15+F15+G15+H15)*0.08,0)) | J15: =IF(E15="","",E15+F15+G15+H15-I15)
C16: =IF(B16="","",VLOOKUP(B16,'F01 - _Données Expatriés'!$A$6:$L$15,2,FALSE)) | I16: =IF(E16="","",IFERROR((E16+F16+G16+H16)*0.08,0)) | J16: =IF(E16="","",E16+F16+G16+H16-I16)
C17: =IF(B17="","",VLOOKUP(B17,'F01 - _Données Expatriés'!$A$6:$L$15,2,FALSE)) | I17: =IF(E17="","",IFERROR((E17+F17+G17+H17)*0.08,0)) | J17: =IF(E17="","",E17+F17+G17+H17-I17)
C18: =IF(B18="","",VLOOKUP(B18,'F01 - _Données Expatriés'!$A$6:$L$15,2,FALSE)) | I18: =IF(E18="","",IFERROR((E18+F18+G18+H18)*0.08,0)) | J18: =IF(E18="","",E18+F18+G18+H18-I18)
C19: =IF(B19="","",VLOOKUP(B19,'F01 - _Données Expatriés'!$A$6:$L$15,2,FALSE)) | I19: =IF(E19="","",IFERROR((E19+F19+G19+H19)*0.08,0)) | J19: =IF(E19="","",E19+F19+G19+H19-I19)
C20: =IF(B20="","",VLOOKUP(B20,'F01 - _Données Expatriés'!$A$6:$L$15,2,FALSE)) | I20: =IF(E20="","",IFERROR((E20+F20+G20+H20)*0.08,0)) | J20: =IF(E20="","",E20+F20+G20+H20-I20)
C21: =IF(B21="","",VLOOKUP(B21,'F01 - _Données Expatriés'!$A$6:$L$15,2,FALSE)) | I21: =IF(E21="","",IFERROR((E21+F21+G21+H21)*0.08,0)) | J21: =IF(E21="","",E21+F21+G21+H21-I21)
C22: =IF(B22="","",VLOOKUP(B22,'F01 - _Données Expatriés'!$A$6:$L$15,2,FALSE)) | I22: =IF(E22="","",IFERROR((E22+F22+G22+H22)*0.08,0)) | J22: =IF(E22="","",E22+F22+G22+H22-I22)
... C115: =IF(B115="","",VLOOKUP(B115,'F01 - _Données Expatriés'!$A$6:$L$15,2,FALSE)) | I115: =IF(E115="","",IFERROR((E115+F115+G115+H115)*0.08,0)) | J115: =IF(E115="","",E115+F115+G115+H115-I115)

Sheet F11 - 9-Fiscalite Internat.
A2: DOMAINE 25 — 9-FISCALITÉ INTERNATIONALE
A3: TABLEAU DYNAMIQUE — Saisissez dans la zone prévue ci-dessous
A5: Matricule | B5: Nom | C5: Nationalité | D5: Pays Imposition | E5: Régime Fiscal | F5: Revenu Imposable (FCFA) | G5: Impôt Estimé (FCFA) | H5: Convention Bilatérale | I5: Taux Effectif (%) | J5: Commentaire
A6: EXP-001 | B6: Dupont Jean-Pierre | C6: Française | D6: France/Côte d'Ivoire | E6: Convention fiscale bilaterale | F6: 7450000 | G6: =IF(F6="","",IFERROR(F6*0.16,0)) | H6: Oui (France-CI) | I6: =IF(OR(F6="",G6=""),"",IFERROR(G6/F6*100,0)) | J6: Élimination double imposition article 15
A7: EXP-002 | B7: Muller Hans | C7: Allemande | D7: Allemagne/Côte d'Ivoire | E7: Exonération partielle | F7: 5110000 | G7: =IF(F7="","",IFERROR(F7*0.16,0)) | H7: Oui (Allemagne-CI) | I7: =IF(OR(F7="",G7=""),"",IFERROR(G7/F7*100,0)) | J7: Exonération 2 premières années
A8: EXP-003 | B8: Silva Carlos | C8: Brésilienne | D8: Côte d'Ivoire | E8: Imposition complète | F8: 6100000 | G8: =IF(F8="","",IFERROR(F8*0.16,0)) | H8: Non | I8: =IF(OR(F8="",G8=""),"",IFERROR(G8/F8*100,0)) | J8: Imposition selon droit commun ivoirien
A9: EXP-004 | B9: Nakamura Yuki | C9: Japonaise | D9: Japon/Côte d'Ivoire | E9: Convention fiscale bilaterale | F9: 3560000 | G9: =IF(F9="","",IFERROR(F9*0.16,0)) | H9: Oui (Japon-CI) | I9: =IF(OR(F9="",G9=""),"",IFERROR(G9/F9*100,0)) | J9: Crédit d'impôt applicable
A10: EXP-005 | B10: Smith James | C10: Britannique | D10: Royaume-Uni/Côte d'Ivoire | E10: Exonération partielle | F10: 4190000 | G10: =IF(F10="","",IFERROR(F10*0.16,0)) | H10: Oui (UK-CI) | I10: =IF(OR(F10="",G10=""),"",IFERROR(G10/F10*100,0)) | J10: Exonération sur prime expatriation
B11: =IF(A11="","",VLOOKUP(A11,'F01 - _Données Expatriés'!$A$6:$L$15,2,FALSE)) | C11: =IF(A11="","",VLOOKUP(A11,'F01 - _Données Expatriés'!$A$6:$L$15,4,FALSE)) | G11: =IF(F11="","",IFERROR(F11*0.16,0)) | I11: =IF(OR(F11="",G11=""),"",IFERROR(G11/F11*100,0))
B12: =IF(A12="","",VLOOKUP(A12,'F01 - _Données Expatriés'!$A$6:$L$15,2,FALSE)) | C12: =IF(A12="","",VLOOKUP(A12,'F01 - _Données Expatriés'!$A$6:$L$15,4,FALSE)) | G12: =IF(F12="","",IFERROR(F12*0.16,0)) | I12: =IF(OR(F12="",G12=""),"",IFERROR(G12/F12*100,0))
B13: =IF(A13="","",VLOOKUP(A13,'F01 - _Données Expatriés'!$A$6:$L$15,2,FALSE)) | C13: =IF(A13="","",VLOOKUP(A13,'F01 - _Données Expatriés'!$A$6:$L$15,4,FALSE)) | G13: =IF(F13="","",IFERROR(F13*0.16,0)) | I13: =IF(OR(F13="",G13=""),"",IFERROR(G13/F13*100,0))
B14: =IF(A14="","",VLOOKUP(A14,'F01 - _Données Expatriés'!$A$6:$L$15,2,FALSE)) | C14: =IF(A14="","",VLOOKUP(A14,'F01 - _Données Expatriés'!$A$6:$L$15,4,FALSE)) | G14: =IF(F14="","",IFERROR(F14*0.16,0)) | I14: =IF(OR(F14="",G14=""),"",IFERROR(G14/F14*100,0))
B15: =IF(A15="","",VLOOKUP(A15,'F01 - _Données Expatriés'!$A$6:$L$15,2,FALSE)) | C15: =IF(A15="","",VLOOKUP(A15,'F01 - _Données Expatriés'!$A$6:$L$15,4,FALSE)) | G15: =IF(F15="","",IFERROR(F15*0.16,0)) | I15: =IF(OR(F15="",G15=""),"",IFERROR(G15/F15*100,0))
B16: =IF(A16="","",VLOOKUP(A16,'F01 - _Données Expatriés'!$A$6:$L$15,2,FALSE)) | C16: =IF(A16="","",VLOOKUP(A16,'F01 - _Données Expatriés'!$A$6:$L$15,4,FALSE)) | G16: =IF(F16="","",IFERROR(F16*0.16,0)) | I16: =IF(OR(F16="",G16=""),"",IFERROR(G16/F16*100,0))
B17: =IF(A17="","",VLOOKUP(A17,'F01 - _Données Expatriés'!$A$6:$L$15,2,FALSE)) | C17: =IF(A17="","",VLOOKUP(A17,'F01 - _Données Expatriés'!$A$6:$L$15,4,FALSE)) | G17: =IF(F17="","",IFERROR(F17*0.16,0)) | I17: =IF(OR(F17="",G17=""),"",IFERROR(G17/F17*100,0))
B18: =IF(A18="","",VLOOKUP(A18,'F01 - _Données Expatriés'!$A$6:$L$15,2,FALSE)) | C18: =IF(A18="","",VLOOKUP(A18,'F01 - _Données Expatriés'!$A$6:$L$15,4,FALSE)) | G18: =IF(F18="","",IFERROR(F18*0.16,0)) | I18: =IF(OR(F18="",G18=""),"",IFERROR(G18/F18*100,0))
B19: =IF(A19="","",VLOOKUP(A19,'F01 - _Données Expatriés'!$A$6:$L$15,2,FALSE)) | C19: =IF(A19="","",VLOOKUP(A19,'F01 - _Données Expatriés'!$A$6:$L$15,4,FALSE)) | G19: =IF(F19="","",IFERROR(F19*0.16,0)) | I19: =IF(OR(F19="",G19=""),"",IFERROR(G19/F19*100,0))
B20: =IF(A20="","",VLOOKUP(A20,'F01 - _Données Expatriés'!$A$6:$L$15,2,FALSE)) | C20: =IF(A20="","",VLOOKUP(A20,'F01 - _Données Expatriés'!$A$6:$L$15,4,FALSE)) | G20: =IF(F20="","",IFERROR(F20*0.16,0)) | I20: =IF(OR(F20="",G20=""),"",IFERROR(G20/F20*100,0))
B21: =IF(A21="","",VLOOKUP(A21,'F01 - _Données Expatriés'!$A$6:$L$15,2,FALSE)) | C21: =IF(A21="","",VLOOKUP(A21,'F01 - _Données Expatriés'!$A$6:$L$15,4,FALSE)) | G21: =IF(F21="","",IFERROR(F21*0.16,0)) | I21: =IF(OR(F21="",G21=""),"",IFERROR(G21/F21*100,0))
B22: =IF(A22="","",VLOOKUP(A22,'F01 - _Données Expatriés'!$A$6:$L$15,2,FALSE)) | C22: =IF(A22="","",VLOOKUP(A22,'F01 - _Données Expatriés'!$A$6:$L$15,4,FALSE)) | G22: =IF(F22="","",IFERROR(F22*0.16,0)) | I22: =IF(OR(F22="",G22=""),"",IFERROR(G22/F22*100,0))
... B115: =IF(A115="","",VLOOKUP(A115,'F01 - _Données Expatriés'!$A$6:$L$15,2,FALSE)) | C115: =IF(A115="","",VLOOKUP(A115,'F01 - _Données Expatriés'!$A$6:$L$15,4,FALSE)) | G115: =IF(F115="","",IFERROR(F115*0.16,0)) | I115: =IF(OR(F115="",G115=""),"",IFERROR(G115/F115*100,0))

Sheet F12 - 10-Analyse Coûts
A2: DOMAINE 25 — 10-ANALYSE COÛTS EXPATRIATION
A3: TABLEAU DYNAMIQUE — Saisissez dans la zone prévue ci-dessous
A5: Mois | B5: Nb Expatriés | C5: Total Salaires (FCFA) | D5: Total Primes (FCFA) | E5: Total Logement (FCFA) | F5: Total Scolarité (FCFA) | G5: Total Coûts (FCFA) | H5: Budget Prévu (FCFA) | I5: Écart (FCFA) | J5: Coût Moyen/Expatrié
A6: Janvier 2025 | B6: 10 | C6: 34000000 | D6: 5800000 | E6: 3200000 | F6: 1550000 | G6: =SUM(C6:F6) | H6: 48000000 | I6: =IF(H6="","",H6-G6) | J6: =IF(B6="","",IFERROR(G6/B6,0))
A7: Février 2025 | B7: 10 | C7: 34000000 | D7: 5800000 | E7: 3200000 | F7: 1550000 | G7: =SUM(C7:F7) | H7: 48000000 | I7: =IF(H7="","",H7-G7) | J7: =IF(B7="","",IFERROR(G7/B7,0))
A8: Mars 2025 | B8: 10 | C8: 34000000 | D8: 5800000 | E8: 3200000 | F8: 1550000 | G8: =SUM(C8:F8) | H8: 48000000 | I8: =IF(H8="","",H8-G8) | J8: =IF(B8="","",IFERROR(G8/B8,0))
G9: =SUM(C9:F9) | I9: =IF(H9="","",H9-G9) | J9: =IF(B9="","",IFERROR(G9/B9,0))
G10: =SUM(C10:F10) | I10: =IF(H10="","",H10-G10) | J10: =IF(B10="","",IFERROR(G10/B10,0))
G11: =SUM(C11:F11) | I11: =IF(H11="","",H11-G11) | J11: =IF(B11="","",IFERROR(G11/B11,0))
G12: =SUM(C12:F12) | I12: =IF(H12="","",H12-G12) | J12: =IF(B12="","",IFERROR(G12/B12,0))
G13: =SUM(C13:F13) | I13: =IF(H13="","",H13-G13) | J13: =IF(B13="","",IFERROR(G13/B13,0))
G14: =SUM(C14:F14) | I14: =IF(H14="","",H14-G14) | J14: =IF(B14="","",IFERROR(G14/B14,0))
G15: =SUM(C15:F15) | I15: =IF(H15="","",H15-G15) | J15: =IF(B15="","",IFERROR(G15/B15,0))
G16: =SUM(C16:F16) | I16: =IF(H16="","",H16-G16) | J16: =IF(B16="","",IFERROR(G16/B16,0))
G17: =SUM(C17:F17) | I17: =IF(H17="","",H17-G17) | J17: =IF(B17="","",IFERROR(G17/B17,0))
G18: =SUM(C18:F18) | I18: =IF(H18="","",H18-G18) | J18: =IF(B18="","",IFERROR(G18/B18,0))
G19: =SUM(C19:F19) | I19: =IF(H19="","",H19-G19) | J19: =IF(B19="","",IFERROR(G19/B19,0))
G20: =SUM(C20:F20) | I20: =IF(H20="","",H20-G20) | J20: =IF(B20="","",IFERROR(G20/B20,0))
... G115: =SUM(C115:F115) | I115: =IF(H115="","",H115-G115) | J115: =IF(B115="","",IFERROR(G115/B115,0))

Sheet F13 - 11-Assurances Couverture
A2: DOMAINE 25 — 11-ASSURANCES ET COUVERTURE SOCIALE
A3: TABLEAU DYNAMIQUE — Saisissez dans la zone prévue ci-dessous
A5: Matricule | B5: Nom | C5: Type Assurance | D5: Compagnie | E5: N. Police | F5: Coût Annuel (FCFA) | G5: Date Expiration | H5: Jours Restants | I5: Couverture CNPS | J5: Statut
A6: EXP-001 | B6: Dupont Jean-Pierre | C6: Assurance santé internationale | D6: AXA Côte d'Ivoire | E6: POL-AXA-001 | F6: 2800000 | G6: 46036 | H6: =IF(G6="","",IFERROR(G6-TODAY(),0)) | I6: Non | J6: Actif
A7: EXP-002 | B7: Muller Hans | C7: Assurance santé internationale | D7: Allianz CI | E7: POL-ALZ-002 | F7: 2200000 | G7: 46081 | H7: =IF(G7="","",IFERROR(G7-TODAY(),0)) | I7: Non | J7: Actif
A8: EXP-003 | B8: Silva Carlos | C8: Assurance rapatriement | D8: MAPFRE CI | E8: POL-MPF-003 | F8: 1800000 | G8: 46173 | H8: =IF(G8="","",IFERROR(G8-TODAY(),0)) | I8: Oui | J8: Actif
A9: EXP-004 | B9: Nakamura Yuki | C9: Assurance santé internationale | D9: AXA Côte d'Ivoire | E9: POL-AXA-004 | F9: 1900000 | G9: 46265 | H9: =IF(G9="","",IFERROR(G9-TODAY(),0)) | I9: Non | J9: Actif
A10: EXP-005 | B10: Smith James | C10: Assurance voyage | D10: AIG CI | E10: POL-AIG-005 | F10: 1500000 | G10: 46387 | H10: =IF(G10="","",IFERROR(G10-TODAY(),0)) | I10: Non | J10: Actif
B11: =IF(A11="","",VLOOKUP(A11,'F01 - _Données Expatriés'!$A$6:$L$15,2,FALSE)) | H11: =IF(G11="","",IFERROR(G11-TODAY(),0))
B12: =IF(A12="","",VLOOKUP(A12,'F01 - _Données Expatriés'!$A$6:$L$15,2,FALSE)) | H12: =IF(G12="","",IFERROR(G12-TODAY(),0))
B13: =IF(A13="","",VLOOKUP(A13,'F01 - _Données Expatriés'!$A$6:$L$15,2,FALSE)) | H13: =IF(G13="","",IFERROR(G13-TODAY(),0))
B14: =IF(A14="","",VLOOKUP(A14,'F01 - _Données Expatriés'!$A$6:$L$15,2,FALSE)) | H14: =IF(G14="","",IFERROR(G14-TODAY(),0))
B15: =IF(A15="","",VLOOKUP(A15,'F01 - _Données Expatriés'!$A$6:$L$15,2,FALSE)) | H15: =IF(G15="","",IFERROR(G15-TODAY(),0))
B16: =IF(A16="","",VLOOKUP(A16,'F01 - _Données Expatriés'!$A$6:$L$15,2,FALSE)) | H16: =IF(G16="","",IFERROR(G16-TODAY(),0))
B17: =IF(A17="","",VLOOKUP(A17,'F01 - _Données Expatriés'!$A$6:$L$15,2,FALSE)) | H17: =IF(G17="","",IFERROR(G17-TODAY(),0))
B18: =IF(A18="","",VLOOKUP(A18,'F01 - _Données Expatriés'!$A$6:$L$15,2,FALSE)) | H18: =IF(G18="","",IFERROR(G18-TODAY(),0))
B19: =IF(A19="","",VLOOKUP(A19,'F01 - _Données Expatriés'!$A$6:$L$15,2,FALSE)) | H19: =IF(G19="","",IFERROR(G19-TODAY(),0))
B20: =IF(A20="","",VLOOKUP(A20,'F01 - _Données Expatriés'!$A$6:$L$15,2,FALSE)) | H20: =IF(G20="","",IFERROR(G20-TODAY(),0))
B21: =IF(A21="","",VLOOKUP(A21,'F01 - _Données Expatriés'!$A$6:$L$15,2,FALSE)) | H21: =IF(G21="","",IFERROR(G21-TODAY(),0))
B22: =IF(A22="","",VLOOKUP(A22,'F01 - _Données Expatriés'!$A$6:$L$15,2,FALSE)) | H22: =IF(G22="","",IFERROR(G22-TODAY(),0))
... B115: =IF(A115="","",VLOOKUP(A115,'F01 - _Données Expatriés'!$A$6:$L$15,2,FALSE)) | H115: =IF(G115="","",IFERROR(G115-TODAY(),0))

Sheet F14 - 12-Suivi Fin Mission
A2: DOMAINE 25 — 12-SUIVI FIN DE MISSION
A3: TABLEAU DYNAMIQUE — Saisissez dans la zone prévue ci-dessous
A5: Matricule | B5: Nom | C5: Département | D5: Date Fin Prévue | E5: Statut Fin Mission | F5: Date Réelle Fin | G5: Motif Départ | H5: Handover Réalisé | I5: Documents Rendus | J5: Commentaire
A6: EXP-011 | B6: Laurent Marie | C6: Marketing & Communication | D6: 45657 | E6: Fin de mission prévue | F6: 45656 | G6: Fin de contrat | H6: Oui | I6: Oui | J6: Excellente mission, remplacée par Moreau
A7: EXP-012 | B7: Fischer Klaus | C7: Maintenance & Technique | D7: 45596 | E7: Départ anticipé | F7: 45550 | G7: Raison personnelle | H7: Partiel | I7: Non | J7: Départ urgent, handover incomplet
C8: =IF(A8="","",VLOOKUP(A8,'F01 - _Données Expatriés'!$A$6:$L$15,6,FALSE))
C9: =IF(A9="","",VLOOKUP(A9,'F01 - _Données Expatriés'!$A$6:$L$15,6,FALSE))
C10: =IF(A10="","",VLOOKUP(A10,'F01 - _Données Expatriés'!$A$6:$L$15,6,FALSE))
C11: =IF(A11="","",VLOOKUP(A11,'F01 - _Données Expatriés'!$A$6:$L$15,6,FALSE))
C12: =IF(A12="","",VLOOKUP(A12,'F01 - _Données Expatriés'!$A$6:$L$15,6,FALSE))
C13: =IF(A13="","",VLOOKUP(A13,'F01 - _Données Expatriés'!$A$6:$L$15,6,FALSE))
C14: =IF(A14="","",VLOOKUP(A14,'F01 - _Données Expatriés'!$A$6:$L$15,6,FALSE))
C15: =IF(A15="","",VLOOKUP(A15,'F01 - _Données Expatriés'!$A$6:$L$15,6,FALSE))
C16: =IF(A16="","",VLOOKUP(A16,'F01 - _Données Expatriés'!$A$6:$L$15,6,FALSE))
C17: =IF(A17="","",VLOOKUP(A17,'F01 - _Données Expatriés'!$A$6:$L$15,6,FALSE))
C18: =IF(A18="","",VLOOKUP(A18,'F01 - _Données Expatriés'!$A$6:$L$15,6,FALSE))
C19: =IF(A19="","",VLOOKUP(A19,'F01 - _Données Expatriés'!$A$6:$L$15,6,FALSE))
... C115: =IF(A115="","",VLOOKUP(A115,'F01 - _Données Expatriés'!$A$6:$L$15,6,FALSE))

Sheet F15 - 13-Plannings Exp.
A2: DOMAINE 25 — 13-PLANNINGS EXPATRIÉS
A3: TABLEAU DYNAMIQUE — Saisissez dans la zone prévue ci-dessous
A5: Matricule | B5: Nom | C5: Département | D5: Lundi | E5: Mardi | F5: Mercredi | G5: Jeudi | H5: Vendredi | I5: Samedi | J5: Dimanche | K5: Total Hebdo | L5: Alerte
A6: EXP-001 | B6: Dupont Jean-Pierre | C6: Direction Générale | D6: 9 | E6: 9 | F6: 9 | G6: 9 | H6: 9 | I6: 4 | J6: 0 | K6: =SUM(D6:J6) | L6: =IF(K6="","",IF(K6>55,"Dépassement",IF(K6>48,"Attention","")))
A7: EXP-002 | B7: Muller Hans | C7: Cuisine & Restauration | D7: 10 | E7: 10 | F7: 10 | G7: 10 | H7: 10 | I7: 10 | J7: 0 | K7: =SUM(D7:J7) | L7: =IF(K7="","",IF(K7>55,"Dépassement",IF(K7>48,"Attention","")))
A8: EXP-003 | B8: Silva Carlos | C8: Finance & Comptabilité | D8: 8 | E8: 8 | F8: 8 | G8: 8 | H8: 8 | I8: 0 | J8: 0 | K8: =SUM(D8:J8) | L8: =IF(K8="","",IF(K8>55,"Dépassement",IF(K8>48,"Attention","")))
A9: EXP-004 | B9: Nakamura Yuki | C9: Réception & Front Office | D9: 8 | E9: 8 | F9: 8 | G9: 8 | H9: 8 | I9: 4 | J9: 0 | K9: =SUM(D9:J9) | L9: =IF(K9="","",IF(K9>55,"Dépassement",IF(K9>48,"Attention","")))
A10: EXP-005 | B10: Smith James | C10: Revenue Management | D10: 8 | E10: 8 | F10: 8 | G10: 8 | H10: 8 | I10: 0 | J10: 0 | K10: =SUM(D10:J10) | L10: =IF(K10="","",IF(K10>55,"Dépassement",IF(K10>48,"Attention","")))
B11: =IF(A11="","",VLOOKUP(A11,'F01 - _Données Expatriés'!$A$6:$L$15,2,FALSE)) | C11: =IF(A11="","",VLOOKUP(A11,'F01 - _Données Expatriés'!$A$6:$L$15,6,FALSE)) | K11: =SUM(D11:J11) | L11: =IF(K11="","",IF(K11>55,"Dépassement",IF(K11>48,"Attention","")))
B12: =IF(A12="","",VLOOKUP(A12,'F01 - _Données Expatriés'!$A$6:$L$15,2,FALSE)) | C12: =IF(A12="","",VLOOKUP(A12,'F01 - _Données Expatriés'!$A$6:$L$15,6,FALSE)) | K12: =SUM(D12:J12) | L12: =IF(K12="","",IF(K12>55,"Dépassement",IF(K12>48,"Attention","")))
B13: =IF(A13="","",VLOOKUP(A13,'F01 - _Données Expatriés'!$A$6:$L$15,2,FALSE)) | C13: =IF(A13="","",VLOOKUP(A13,'F01 - _Données Expatriés'!$A$6:$L$15,6,FALSE)) | K13: =SUM(D13:J13) | L13: =IF(K13="","",IF(K13>55,"Dépassement",IF(K13>48,"Attention","")))
B14: =IF(A14="","",VLOOKUP(A14,'F01 - _Données Expatriés'!$A$6:$L$15,2,FALSE)) | C14: =IF(A14="","",VLOOKUP(A14,'F01 - _Données Expatriés'!$A$6:$L$15,6,FALSE)) | K14: =SUM(D14:J14) | L14: =IF(K14="","",IF(K14>55,"Dépassement",IF(K14>48,"Attention","")))
B15: =IF(A15="","",VLOOKUP(A15,'F01 - _Données Expatriés'!$A$6:$L$15,2,FALSE)) | C15: =IF(A15="","",VLOOKUP(A15,'F01 - _Données Expatriés'!$A$6:$L$15,6,FALSE)) | K15: =SUM(D15:J15) | L15: =IF(K15="","",IF(K15>55,"Dépassement",IF(K15>48,"Attention","")))
B16: =IF(A16="","",VLOOKUP(A16,'F01 - _Données Expatriés'!$A$6:$L$15,2,FALSE)) | C16: =IF(A16="","",VLOOKUP(A16,'F01 - _Données Expatriés'!$A$6:$L$15,6,FALSE)) | K16: =SUM(D16:J16) | L16: =IF(K16="","",IF(K16>55,"Dépassement",IF(K16>48,"Attention","")))
B17: =IF(A17="","",VLOOKUP(A17,'F01 - _Données Expatriés'!$A$6:$L$15,2,FALSE)) | C17: =IF(A17="","",VLOOKUP(A17,'F01 - _Données Expatriés'!$A$6:$L$15,6,FALSE)) | K17: =SUM(D17:J17) | L17: =IF(K17="","",IF(K17>55,"Dépassement",IF(K17>48,"Attention","")))
B18: =IF(A18="","",VLOOKUP(A18,'F01 - _Données Expatriés'!$A$6:$L$15,2,FALSE)) | C18: =IF(A18="","",VLOOKUP(A18,'F01 - _Données Expatriés'!$A$6:$L$15,6,FALSE)) | K18: =SUM(D18:J18) | L18: =IF(K18="","",IF(K18>55,"Dépassement",IF(K18>48,"Attention","")))
B19: =IF(A19="","",VLOOKUP(A19,'F01 - _Données Expatriés'!$A$6:$L$15,2,FALSE)) | C19: =IF(A19="","",VLOOKUP(A19,'F01 - _Données Expatriés'!$A$6:$L$15,6,FALSE)) | K19: =SUM(D19:J19) | L19: =IF(K19="","",IF(K19>55,"Dépassement",IF(K19>48,"Attention","")))
B20: =IF(A20="","",VLOOKUP(A20,'F01 - _Données Expatriés'!$A$6:$L$15,2,FALSE)) | C20: =IF(A20="","",VLOOKUP(A20,'F01 - _Données Expatriés'!$A$6:$L$15,6,FALSE)) | K20: =SUM(D20:J20) | L20: =IF(K20="","",IF(K20>55,"Dépassement",IF(K20>48,"Attention","")))
B21: =IF(A21="","",VLOOKUP(A21,'F01 - _Données Expatriés'!$A$6:$L$15,2,FALSE)) | C21: =IF(A21="","",VLOOKUP(A21,'F01 - _Données Expatriés'!$A$6:$L$15,6,FALSE)) | K21: =SUM(D21:J21) | L21: =IF(K21="","",IF(K21>55,"Dépassement",IF(K21>48,"Attention","")))
B22: =IF(A22="","",VLOOKUP(A22,'F01 - _Données Expatriés'!$A$6:$L$15,2,FALSE)) | C22: =IF(A22="","",VLOOKUP(A22,'F01 - _Données Expatriés'!$A$6:$L$15,6,FALSE)) | K22: =SUM(D22:J22) | L22: =IF(K22="","",IF(K22>55,"Dépassement",IF(K22>48,"Attention","")))
... B115: =IF(A115="","",VLOOKUP(A115,'F01 - _Données Expatriés'!$A$6:$L$15,2,FALSE)) | C115: =IF(A115="","",VLOOKUP(A115,'F01 - _Données Expatriés'!$A$6:$L$15,6,FALSE)) | K115: =SUM(D115:J115) | L115: =IF(K115="","",IF(K115>55,"Dépassement",IF(K115>48,"Attention","")))

Sheet F16 - 14-Litiges Expatriation
A2: DOMAINE 25 — 14-LITIGES EXPATRIATION
A3: TABLEAU DYNAMIQUE — Saisissez dans la zone prévue ci-dessous
A5: Code Litige | B5: Matricule | C5: Nom | D5: Type Litige | E5: Date Signalement | F5: Description | G5: Priorité | H5: Statut | I5: Montant en Jeu (FCFA) | J5: Commentaire
A6: LIT-E-001 | B6: EXP-012 | C6: Fischer Klaus | D6: Litige salarial | E6: 45555 | F6: Différentiel de salaire non versé sur août-septembre | G6: Haute | H6: Résolu | I6: 1200000 | J6: Règlement amiable trouvé
A7: LIT-E-002 | B7: EXP-003 | C7: Silva Carlos | D7: Problème de visa | E7: 45667 | F7: Retard de renouvellement carte de séjour de 3 semaines | G7: Moyenne | H7: En cours | I7: 0 | J7: Dossier en cours à la DDE
A8: LIT-E-003 | B8: EXP-004 | C8: Nakamura Yuki | D8: Litige logement | E8: 45693 | F8: Travaux non réalisés dans l'appartement | G8: Moyenne | H8: En cours | I8: 800000 | J8: Propriétaire contacté
C9: =IF(B9="","",VLOOKUP(B9,'F01 - _Données Expatriés'!$A$6:$L$15,2,FALSE))
C10: =IF(B10="","",VLOOKUP(B10,'F01 - _Données Expatriés'!$A$6:$L$15,2,FALSE))
C11: =IF(B11="","",VLOOKUP(B11,'F01 - _Données Expatriés'!$A$6:$L$15,2,FALSE))
C12: =IF(B12="","",VLOOKUP(B12,'F01 - _Données Expatriés'!$A$6:$L$15,2,FALSE))
C13: =IF(B13="","",VLOOKUP(B13,'F01 - _Données Expatriés'!$A$6:$L$15,2,FALSE))
C14: =IF(B14="","",VLOOKUP(B14,'F01 - _Données Expatriés'!$A$6:$L$15,2,FALSE))
C15: =IF(B15="","",VLOOKUP(B15,'F01 - _Données Expatriés'!$A$6:$L$15,2,FALSE))
C16: =IF(B16="","",VLOOKUP(B16,'F01 - _Données Expatriés'!$A$6:$L$15,2,FALSE))
C17: =IF(B17="","",VLOOKUP(B17,'F01 - _Données Expatriés'!$A$6:$L$15,2,FALSE))
C18: =IF(B18="","",VLOOKUP(B18,'F01 - _Données Expatriés'!$A$6:$L$15,2,FALSE))
C19: =IF(B19="","",VLOOKUP(B19,'F01 - _Données Expatriés'!$A$6:$L$15,2,FALSE))
C20: =IF(B20="","",VLOOKUP(B20,'F01 - _Données Expatriés'!$A$6:$L$15,2,FALSE))
... C115: =IF(B115="","",VLOOKUP(B115,'F01 - _Données Expatriés'!$A$6:$L$15,2,FALSE))

Sheet F17 - 15-Historique Exp.
A2: DOMAINE 25 — 15-HISTORIQUE EXPATRIÉS
A3: TABLEAU DYNAMIQUE — Saisissez dans la zone prévue ci-dessous
A5: Nom | B5: Prénom | C5: Nationalité | D5: Département | E5: Poste | F5: Date Début | G5: Date Fin | H5: Durée (mois) | I5: Motif Départ | J5: Satisfaction
A6: Laurent | B6: Marie | C6: Française | D6: Marketing & Communication | E6: Directrice Marketing | F6: 44621 | G6: 45656 | H6: =IF(OR(G6="",F6=""),"",IFERROR((G6-F6)/30.44,0)) | I6: Fin de contrat | J6: Très bon
