Workbook

Sheet ★ Bulletin de Paie
B2: HÔTEL 4 ÉTOILES — BULLETIN DE PAIE INDIVIDUEL
B3: Domaine 3 — Paie, Rémunération & Avantages Sociaux
B5: RECHERCHER UN EMPLOYÉ | D5: Matricule : | G5: Période :
B6: Employé sélectionné : | D6: =IF(E5="","⚠ Saisir un matricule ci-dessus",IFERROR(VLOOKUP(E5,'_Données Employés'!$B$5:$S$114,3,FALSE)&" "&VLOOKUP(E5,'_Données Employés'!$B$5:$S$114,4,FALSE),"Matricule non trouvé")) | G6: Département : | H6: =IF(E5="","",IFERROR(VLOOKUP(E5,'_Données Employés'!$B$5:$S$114,10,FALSE),""))
B8: IDENTITÉ DU SALARIÉ | G8: INFORMATIONS EMPLOI
B9: Matricule | C9: =IF(E5="","",E5) | D9: Civilité | E9: =IF(E5="","",IFERROR(VLOOKUP(E5,'_Données Employés'!$B$5:$S$114,2,FALSE),"")) | G9: Département | H9: =IF(E5="","",IFERROR(VLOOKUP(E5,'_Données Employés'!$B$5:$S$114,10,FALSE),"")) | I9: Poste | J9: =IF(E5="","",IFERROR(VLOOKUP(E5,'_Données Employés'!$B$5:$S$114,9,FALSE),""))
B10: Nom | C10: =IF(E5="","",IFERROR(VLOOKUP(E5,'_Données Employés'!$B$5:$S$114,3,FALSE),"")) | D10: Prénom | E10: =IF(E5="","",IFERROR(VLOOKUP(E5,'_Données Employés'!$B$5:$S$114,4,FALSE),"")) | G10: Type contrat | H10: =IF(E5="","",IFERROR(VLOOKUP(E5,'_Données Employés'!$B$5:$S$114,11,FALSE),"")) | I10: Régime travail | J10: =IF(E5="","",IFERROR(VLOOKUP(E5,'_Données Employés'!$B$5:$S$114,12,FALSE),""))
B11: Date naissance | C11: =IF(E5="","",IFERROR(VLOOKUP(E5,'_Données Employés'!$B$5:$S$114,5,FALSE),"")) | D11: Nationalité | E11: =IF(E5="","",IFERROR(VLOOKUP(E5,'_Données Employés'!$B$5:$S$114,7,FALSE),"")) | G11: Date embauche | H11: =IF(E5="","",IFERROR(VLOOKUP(E5,'_Données Employés'!$B$5:$S$114,13,FALSE),"")) | I11: Ancienneté | J11: =IF(E5="","",IFERROR(VLOOKUP(E5,'_Données Employés'!$B$5:$S$114,18,FALSE),""))
B12: Échelon | C12: =IF(E5="","",IFERROR(VLOOKUP(E5,'_Données Employés'!$B$5:$S$114,14,FALSE),"")) | D12: Statut | E12: =IF(E5="","",IFERROR(VLOOKUP(E5,'_Données Employés'!$B$5:$S$114,15,FALSE),"")) | G12: Catégorie | H12: =IF(E5="","",IFERROR(VLOOKUP(E5,'_Données Employés'!$B$5:$S$114,8,FALSE),"")) | I12: Salaire base | J12: =IF(E5="","",IFERROR(VLOOKUP(E5,'_Données Employés'!$B$5:$S$114,16,FALSE),""))
B14: DÉTAIL DE LA RÉMUNÉRATION
B15: RUBRIQUE (GAINS) | C15: Base (FCFA) | D15: Taux | E15: Montant (FCFA) | G15: RUBRIQUE (RETENUES) | H15: Base (FCFA) | I15: Taux | J15: Montant (FCFA)
B16: Salaire de base | C16: =IF(E5="","",IFERROR(VLOOKUP(E5,'_Données Employés'!$B$5:$S$114,16,FALSE),"")) | D16: 100% | E16: =IF(E5="","",IFERROR(VLOOKUP(E5,'_Données Employés'!$B$5:$S$114,16,FALSE),"")) | G16: CNPS Employé | H16: =IF(E5="","",E24) | I16: 2,8% | J16: =IF(E5="","",IFERROR(E24*0.028,0))
B17: Prime d'ancienneté | C17: =IF(E5="","",IFERROR(VLOOKUP(E5,'_Données Employés'!$B$5:$S$114,16,FALSE),"")) | D17: 5% | E17: =IF(E5="","",IFERROR(VLOOKUP(E5,'_Données Employés'!$B$5:$S$114,16,FALSE)*0.05,0)) | G17: CNAMGS Employé | H17: =IF(E5="","",E24) | I17: 1,5% | J17: =IF(E5="","",IFERROR(E24*0.015,0))
B18: Indemnité logement | C18: =IF(E5="","",IFERROR(VLOOKUP(E5,'_Données Employés'!$B$5:$S$114,16,FALSE),"")) | D18: 30% | E18: =IF(E5="","",IFERROR(VLOOKUP(E5,'_Données Employés'!$B$5:$S$114,16,FALSE)*0.3,0)) | G18: IR Salaires | H18: =IF(E5="","",E24) | I18: Barème progressif | J18: IF(E5="","",IFERROR(IF(E23<=62000,0,IF(E23<=146000,(E23-62000)*0.1,IF(E23<=236000,8400+(E23-146000)*0.15,IF(E23<=360000,21900+(E23-236000)*0.25,IF(E23<=550000,52900+(E23-360000)*0.35,119400+(E23-550000)*0.4))))),0))
B19: Prime transport | C19: =IF(E5="","",25000) | D19: Fixe | E19: =IF(E5="","",25000) | G19: Acomptes & avances | H19: =IF(E5="","",IFERROR(SUMPRODUCT(('7-Acomptes Avances'!$C$5:$C$104=E5)*('7-Acomptes Avances'!$H$5:$H$104)),0)) | I19: Variable | J19: =IF(E5="","",IFERROR(SUMPRODUCT(('7-Acomptes Avances'!$C$5:$C$104=E5)*('7-Acomptes Avances'!$H$5:$H$104)),0))
B20: Heures supplémentaires | C20: =IF(E5="","",IFERROR(SUMPRODUCT(('4-Heures Supplementaires'!$C$5:$C$104=E5)*('4-Heures Supplementaires'!$L$5:$L$104)),0)) | D20: Variable | E20: =IF(E5="","",IFERROR(SUMPRODUCT(('4-Heures Supplementaires'!$C$5:$C$104=E5)*('4-Heures Supplementaires'!$L$5:$L$104)),0)) | G20: Prêts personnels | H20: =IF(E5="","",IFERROR(SUMPRODUCT(('8-Prets Personnel'!$C$5:$C$104=E5)*('8-Prets Personnel'!$H$5:$H$104)),0)) | I20: Mensualité | J20: =IF(E5="","",IFERROR(SUMPRODUCT(('8-Prets Personnel'!$C$5:$C$104=E5)*('8-Prets Personnel'!$H$5:$H$104)),0))
B21: Primes & indemnités | C21: =IF(E5="","",IFERROR(SUMPRODUCT(('3-Primes & Indemnités'!$C$5:$C$104=E5)*('3-Primes & Indemnités'!$L$5:$L$104)),0)) | D21: Variable | E21: =IF(E5="","",IFERROR(SUMPRODUCT(('3-Primes & Indemnités'!$C$5:$C$104=E5)*('3-Primes & Indemnités'!$L$5:$L$104)),0)) | G21: Autres déductions | H21: =IF(E5="","",IFERROR(SUMPRODUCT(('6-Deductions Retenues'!$C$5:$C$104=E5)*('6-Deductions Retenues'!$H$5:$H$104)),0)) | I21: Variable | J21: =IF(E5="","",IFERROR(SUMPRODUCT(('6-Deductions Retenues'!$C$5:$C$104=E5)*('6-Deductions Retenues'!$H$5:$H$104)),0))
B22: Avantages en nature | C22: =IF(E5="","",IFERROR(SUMPRODUCT(('15-Avantages Nature'!$C$5:$C$104=E5)*('15-Avantages Nature'!$G$5:$G$104)),0)) | D22: Variable | E22: =IF(E5="","",IFERROR(SUMPRODUCT(('15-Avantages Nature'!$C$5:$C$104=E5)*('15-Avantages Nature'!$G$5:$G$104)),0)) | G22: Mutuelle/Prévoyance | H22: =IF(E5="","",IFERROR(SUMPRODUCT(('20-Mutuelle Prevoyance'!$C$5:$C$104=E5)*('20-Mutuelle Prevoyance'!$H$5:$H$104)),0)) | I22: Variable | J22: =IF(E5="","",IFERROR(SUMPRODUCT(('20-Mutuelle Prevoyance'!$C$5:$C$104=E5)*('20-Mutuelle Prevoyance'!$H$5:$H$104)),0))
B23: Variables & pourboires | C23: =IF(E5="","",IFERROR(SUMPRODUCT(('14-Variables Pourboires'!$C$5:$C$104=E5)*('14-Variables Pourboires'!$H$5:$H$104)),0)) | D23: Variable | E23: =IF(E5="","",IFERROR(SUMPRODUCT(('14-Variables Pourboires'!$C$5:$C$104=E5)*('14-Variables Pourboires'!$H$5:$H$104)),0)) | G23: TOTAL RETENUES | J23: =IF(E5="","",SUM(J16:J22))
B24: TOTAL BRUT | E24: =IF(E5="","",SUM(E16:E23))
B26: SALAIRE NET À PAYER | G26: COÛT TOTAL EMPLOYEUR
B27: =IF(E5="","",IFERROR(E24-J23,0)) | G27: =IF(E5="","",IFERROR(E24*1.082,0))
B29: RÉCAPITULATIF MENSUEL
B30: Salaire de base | G30: =IF(E5="","",IFERROR(VLOOKUP(E5,'_Données Employés'!$B$5:$S$114,16,FALSE),""))
B31: Total primes & indemnités réglementaires | G31: =IF(E5="","",IFERROR(SUM(E17:E20),0))
B32: Total primes variables & avantages | G32: =IF(E5="","",IFERROR(SUM(E21:E23),0))
B33: Salaire brut total | G33: =IF(E5="","",E24)
B34: Total cotisations sociales (CNPS+CNAMGS+IR) | G34: =IF(E5="","",IFERROR(SUM(J16:J18),0))
B35: Total déductions diverses | G35: =IF(E5="","",IFERROR(SUM(J19:J22),0))
B36: Total retenues | G36: =IF(E5="","",IFERROR(J23,0))
B37: NET À PAYER | G37: =IF(E5="","",IFERROR(E24-J23,0))
B38: Charges patronales (8,2%) | G38: =IF(E5="","",IFERROR(E24*0.082,0))
B39: Coût total pour l'hôtel | G39: =IF(E5="","",IFERROR(E24*1.082,0))
B41: Mode d'emploi : 1) Cliquer sur la cellule jaune « Matricule » en ligne 5 → 2) Choisir un employé dans la liste déroulante → 3) La fiche de paie se remplit automatiquement

Sheet Tableau de Bord
B2: DOMAINE 3 — PAIE, RÉMUNÉRATION & AVANTAGES SOCIAUX
B3: Tableau de bord — Vue synthétique (toutes les feuilles connectées automatiquement)
B5: Masse brute mensuelle (FCFA) | D5: Masse nette mensuelle (FCFA) | G5: Coût total employeur (FCFA) | I5: Effectif actif
B6: =SUM('2-Calcul des Salaires'!J5:J104) | D6: =SUM('2-Calcul des Salaires'!O5:O104) | G6: =SUM('2-Calcul des Salaires'!Q5:Q104) | I6: =COUNTA('_Données Employés'!B5:B114)
B8: Total primes (FCFA) | D8: Total HS nets (FCFA) | G8: Total cotisations (FCFA) | I8: Prêts en cours
B9: =SUM('3-Primes & Indemnités'!L5:L104) | D9: =SUM('4-Heures Supplementaires'!K5:K104) | G9: =SUM('5-Cotisations Salariales'!J5:J104) | I9: =COUNTIF('8-Prets Personnel'!K5:K104,"En cours")
B11: Avantages nature (FCFA) | D11: Tickets restaurant (FCFA) | G11: Valeur CET totale (FCFA) | I11: Notes de frais (FCFA)
B12: =SUM('15-Avantages Nature'!G5:G104) | D12: =SUM('16-Tickets Restaurant'!K5:K104) | G12: =SUM('17-Compte Epargne Temps'!L5:L104) | I12: =SUM('19-Notes de Frais'!H5:H104)
B15: RÉPARTITION PAR DÉPARTEMENT
B16: Département | C16: Masse Brute (FCFA) | D16: Effectif | G16: Type de Prime | H16: Montant (FCFA)
B17: Ressources Humaines | C17: =SUMPRODUCT(('_Données Employés'!$K$5:$K$114="Ressources Humaines")*('_Données Employés'!$R$5:$R$114)) | D17: =COUNTIF('_Données Employés'!$K$5:$K$114,"Ressources Humaines") | G17: Prime de responsabilite | H17: =SUMPRODUCT(('3-Primes & Indemnités'!$F$5:$F$104=H17)*('3-Primes & Indemnités'!$L$5:$L$104))
B18: Finance & Comptabilite | C18: =SUMPRODUCT(('_Données Employés'!$K$5:$K$114="Finance & Comptabilite")*('_Données Employés'!$R$5:$R$114)) | D18: =COUNTIF('_Données Employés'!$K$5:$K$114,"Finance & Comptabilite") | G18: Prime de rendement | H18: =SUMPRODUCT(('3-Primes & Indemnités'!$F$5:$F$104=H18)*('3-Primes & Indemnités'!$L$5:$L$104))
B19: Reception & Front Office | C19: =SUMPRODUCT(('_Données Employés'!$K$5:$K$114="Reception & Front Office")*('_Données Employés'!$R$5:$R$114)) | D19: =COUNTIF('_Données Employés'!$K$5:$K$114,"Reception & Front Office") | G19: Indemnite de danger | H19: =SUMPRODUCT(('3-Primes & Indemnités'!$F$5:$F$104=H19)*('3-Primes & Indemnités'!$L$5:$L$104))
B20: Cuisine & Restauration | C20: =SUMPRODUCT(('_Données Employés'!$K$5:$K$114="Cuisine & Restauration")*('_Données Employés'!$R$5:$R$114)) | D20: =COUNTIF('_Données Employés'!$K$5:$K$114,"Cuisine & Restauration") | G20: Prime exceptionnelle | H20: =SUMPRODUCT(('3-Primes & Indemnités'!$F$5:$F$104=H20)*('3-Primes & Indemnités'!$L$5:$L$104))
B21: Securite | C21: =SUMPRODUCT(('_Données Employés'!$K$5:$K$114="Securite")*('_Données Employés'!$R$5:$R$114)) | D21: =COUNTIF('_Données Employés'!$K$5:$K$114,"Securite") | G21: Prime d'anciennete | H21: =SUMPRODUCT(('3-Primes & Indemnités'!$F$5:$F$104=H21)*('3-Primes & Indemnités'!$L$5:$L$104))
B22: Entretien & Maintenance | C22: =SUMPRODUCT(('_Données Employés'!$K$5:$K$114="Entretien & Maintenance")*('_Données Employés'!$R$5:$R$114)) | D22: =COUNTIF('_Données Employés'!$K$5:$K$114,"Entretien & Maintenance")

Sheet 1-Grille Salariale
B2: PAIE — 1-Grille Salariale
B4: N° Grille | C4: Poste | D4: Département | E4: Catégorie | F4: Échelon | G4: Salaire Base (FCFA) | H4: Prime Ancienneté (FCFA) | I4: Salaire Total (FCFA) | J4: Nb Postes | K4: Masse Poste (FCFA) | L4: Salaire Marché (FCFA) | M4: Statut
B5: GR-001 | C5: DRH | D5: Ressources Humaines | E5: Cadre superieur | F5: Echelon 5 | G5: 635000 | H5: 31750 | I5: 666750 | J5: 1 | K5: 666750 | L5: 700000 | M5: Actif
B6: GR-002 | C6: Chef Comptable | D6: Finance & Comptabilite | E6: Cadre | F6: Echelon 4 | G6: 484000 | H6: 24200 | I6: 508200 | J6: 1 | K6: 508200 | L6: 520000 | M6: Actif
B7: GR-003 | C7: Receptionniste | D7: Reception & Front Office | E7: Employe | F7: Echelon 3 | G7: 207000 | H7: 10350 | I7: 217350 | J7: 6 | K7: 1304100 | L7: 220000 | M7: Actif
B8: GR-004 | C8: Chef cuisinier | D8: Cuisine & Restauration | E8: Maitrise | F8: Echelon 3 | G8: 253000 | H8: 12650 | I8: 265650 | J8: 5 | K8: 1328250 | L8: 260000 | M8: Actif
B9: GR-005 | C9: Agent securite | D9: Securite | E9: Ouvrier | F9: Echelon 2 | G9: 149500 | H9: 7475 | I9: 156975 | J9: 4 | K9: 627900 | L9: 145000 | M9: Actif
B10: =IF(C10="","GR"&TEXT(COUNTA($C$5:C10),"000")) | H10: =IF(F10="","",IFERROR(F10*0.05,0)) | I10: =IF(F10="","",IFERROR(F10+G10,0)) | K10: =IF(OR(F10="",I10=""),"",IFERROR(H10*I10,0))
B11: =IF(C11="","GR"&TEXT(COUNTA($C$5:C11),"000")) | H11: =IF(F11="","",IFERROR(F11*0.05,0)) | I11: =IF(F11="","",IFERROR(F11+G11,0)) | K11: =IF(OR(F11="",I11=""),"",IFERROR(H11*I11,0))
B12: =IF(C12="","GR"&TEXT(COUNTA($C$5:C12),"000")) | H12: =IF(F12="","",IFERROR(F12*0.05,0)) | I12: =IF(F12="","",IFERROR(F12+G12,0)) | K12: =IF(OR(F12="",I12=""),"",IFERROR(H12*I12,0))
B13: =IF(C13="","GR"&TEXT(COUNTA($C$5:C13),"000")) | H13: =IF(F13="","",IFERROR(F13*0.05,0)) | I13: =IF(F13="","",IFERROR(F13+G13,0)) | K13: =IF(OR(F13="",I13=""),"",IFERROR(H13*I13,0))
B14: =IF(C14="","GR"&TEXT(COUNTA($C$5:C14),"000")) | H14: =IF(F14="","",IFERROR(F14*0.05,0)) | I14: =IF(F14="","",IFERROR(F14+G14,0)) | K14: =IF(OR(F14="",I14=""),"",IFERROR(H14*I14,0))
B15: =IF(C15="","GR"&TEXT(COUNTA($C$5:C15),"000")) | H15: =IF(F15="","",IFERROR(F15*0.05,0)) | I15: =IF(F15="","",IFERROR(F15+G15,0)) | K15: =IF(OR(F15="",I15=""),"",IFERROR(H15*I15,0))
B16: =IF(C16="","GR"&TEXT(COUNTA($C$5:C16),"000")) | H16: =IF(F16="","",IFERROR(F16*0.05,0)) | I16: =IF(F16="","",IFERROR(F16+G16,0)) | K16: =IF(OR(F16="",I16=""),"",IFERROR(H16*I16,0))
B17: =IF(C17="","GR"&TEXT(COUNTA($C$5:C17),"000")) | H17: =IF(F17="","",IFERROR(F17*0.05,0)) | I17: =IF(F17="","",IFERROR(F17+G17,0)) | K17: =IF(OR(F17="",I17=""),"",IFERROR(H17*I17,0))
B18: =IF(C18="","GR"&TEXT(COUNTA($C$5:C18),"000")) | H18: =IF(F18="","",IFERROR(F18*0.05,0)) | I18: =IF(F18="","",IFERROR(F18+G18,0)) | K18: =IF(OR(F18="",I18=""),"",IFERROR(H18*I18,0))
B19: =IF(C19="","GR"&TEXT(COUNTA($C$5:C19),"000")) | H19: =IF(F19="","",IFERROR(F19*0.05,0)) | I19: =IF(F19="","",IFERROR(F19+G19,0)) | K19: =IF(OR(F19="",I19=""),"",IFERROR(H19*I19,0))
B20: =IF(C20="","GR"&TEXT(COUNTA($C$5:C20),"000")) | H20: =IF(F20="","",IFERROR(F20*0.05,0)) | I20: =IF(F20="","",IFERROR(F20+G20,0)) | K20: =IF(OR(F20="",I20=""),"",IFERROR(H20*I20,0))
B21: =IF(C21="","GR"&TEXT(COUNTA($C$5:C21),"000")) | H21: =IF(F21="","",IFERROR(F21*0.05,0)) | I21: =IF(F21="","",IFERROR(F21+G21,0)) | K21: =IF(OR(F21="",I21=""),"",IFERROR(H21*I21,0))
... B104: =IF(C104="","GR"&TEXT(COUNTA($C$5:C104),"000")) | H104: =IF(F104="","",IFERROR(F104*0.05,0)) | I104: =IF(F104="","",IFERROR(F104+G104,0)) | K104: =IF(OR(F104="",I104=""),"",IFERROR(H104*I104,0))
B107: KPI Postes actifs | C107: KPI Masse totale (FCFA) | D107: KPI Écart moyen marché (FCFA)
B108: =COUNTIF(M5:M104,"Actif") | C108: =SUM(K5:K104) | D108: =IFERROR(AVERAGE(L5:L104),0)

Sheet 2-Calcul des Salaires
B2: PAIE — Moteur de calcul des salaires (lié à _Données Employés)
B4: Matricule | C4: Nom Employé | D4: Mois | E4: Salaire Base | F4: Prime Ancienneté 5% | G4: Indemn. Logement 30% | H4: Prime Transport | I4: Total Primes | J4: Salaire Brut | K4: CNPS 2.8% | L4: CNAMGS 1.5% | M4: IR Salaires | N4: Total Retenues | O4: Salaire Net | P4: Charges Patron. 8.2% | Q4: Coût Total Emp.
B5: EMP-001 | C5: Nganou Clarisse | D5: Juin | E5: =VLOOKUP(B5,'_Données Employés'!$B$5:$S$114,16,FALSE) | F5: =IF(E5="","",E5*0.05) | G5: =IF(E5="","",E5*0.3) | H5: =IF(E5="","",25000) | I5: =IF(E5="","",SUM(F5:H5)) | J5: =IF(E5="","",E5+I5) | K5: =IF(J5="","",J5*0.028) | L5: =IF(J5="","",J5*0.015) | M5: =IF(J5="","",IFERROR(IF(J5<=62000,0,IF(J5<=146000,(J5-62000)*0.1,IF(J5<=236000,8400+(J5-146000)*0.15,IF(J5<=360000,21900+(J5-236000)*0.25,IF(J5<=550000,51900+(J5-360000)*0.35,118400+(J5-550000)*0.4))))),0)) | N5: =IF(J5="","",SUM(K5:M5)) | O5: =IF(J5="","",J5-N5) | P5: =IF(J5="","",J5*0.082) | Q5: =IF(J5="","",J5+P5)
B6: EMP-002 | C6: Tchinda Armand | D6: Juin | E6: =VLOOKUP(B6,'_Données Employés'!$B$5:$S$114,16,FALSE) | F6: =IF(E6="","",E6*0.05) | G6: =IF(E6="","",E6*0.3) | H6: =IF(E6="","",25000) | I6: =IF(E6="","",SUM(F6:H6)) | J6: =IF(E6="","",E6+I6) | K6: =IF(J6="","",J6*0.028) | L6: =IF(J6="","",J6*0.015) | M6: =IF(J6="","",IFERROR(IF(J6<=62000,0,IF(J6<=146000,(J6-62000)*0.1,IF(J6<=236000,8400+(J6-146000)*0.15,IF(J6<=360000,21900+(J6-236000)*0.25,IF(J6<=550000,51900+(J6-360000)*0.35,118400+(J6-550000)*0.4))))),0)) | N6: =IF(J6="","",SUM(K6:M6)) | O6: =IF(J6="","",J6-N6) | P6: =IF(J6="","",J6*0.082) | Q6: =IF(J6="","",J6+P6)
B7: EMP-003 | C7: Fotso Marguerite | D7: Juin | E7: =VLOOKUP(B7,'_Données Employés'!$B$5:$S$114,16,FALSE) | F7: =IF(E7="","",E7*0.05) | G7: =IF(E7="","",E7*0.3) | H7: =IF(E7="","",25000) | I7: =IF(E7="","",SUM(F7:H7)) | J7: =IF(E7="","",E7+I7) | K7: =IF(J7="","",J7*0.028) | L7: =IF(J7="","",J7*0.015) | M7: =IF(J7="","",IFERROR(IF(J7<=62000,0,IF(J7<=146000,(J7-62000)*0.1,IF(J7<=236000,8400+(J7-146000)*0.15,IF(J7<=360000,21900+(J7-236000)*0.25,IF(J7<=550000,51900+(J7-360000)*0.35,118400+(J7-550000)*0.4))))),0)) | N7: =IF(J7="","",SUM(K7:M7)) | O7: =IF(J7="","",J7-N7) | P7: =IF(J7="","",J7*0.082) | Q7: =IF(J7="","",J7+P7)
B8: EMP-004 | C8: Ouedraogo Ibrahim | D8: Juin | E8: =VLOOKUP(B8,'_Données Employés'!$B$5:$S$114,16,FALSE) | F8: =IF(E8="","",E8*0.05) | G8: =IF(E8="","",E8*0.3) | H8: =IF(E8="","",25000) | I8: =IF(E8="","",SUM(F8:H8)) | J8: =IF(E8="","",E8+I8) | K8: =IF(J8="","",J8*0.028) | L8: =IF(J8="","",J8*0.015) | M8: =IF(J8="","",IFERROR(IF(J8<=62000,0,IF(J8<=146000,(J8-62000)*0.1,IF(J8<=236000,8400+(J8-146000)*0.15,IF(J8<=360000,21900+(J8-236000)*0.25,IF(J8<=550000,51900+(J8-360000)*0.35,118400+(J8-550000)*0.4))))),0)) | N8: =IF(J8="","",SUM(K8:M8)) | O8: =IF(J8="","",J8-N8) | P8: =IF(J8="","",J8*0.082) | Q8: =IF(J8="","",J8+P8)
B9: EMP-005 | C9: Diallo Moussa | D9: Juin | E9: =VLOOKUP(B9,'_Données Employés'!$B$5:$S$114,16,FALSE) | F9: =IF(E9="","",E9*0.05) | G9: =IF(E9="","",E9*0.3) | H9: =IF(E9="","",25000) | I9: =IF(E9="","",SUM(F9:H9)) | J9: =IF(E9="","",E9+I9) | K9: =IF(J9="","",J9*0.028) | L9: =IF(J9="","",J9*0.015) | M9: =IF(J9="","",IFERROR(IF(J9<=62000,0,IF(J9<=146000,(J9-62000)*0.1,IF(J9<=236000,8400+(J9-146000)*0.15,IF(J9<=360000,21900+(J9-236000)*0.25,IF(J9<=550000,51900+(J9-360000)*0.35,118400+(J9-550000)*0.4))))),0)) | N9: =IF(J9="","",SUM(K9:M9)) | O9: =IF(J9="","",J9-N9) | P9: =IF(J9="","",J9*0.082) | Q9: =IF(J9="","",J9+P9)
B10: EMP-006 | C10: Ngassa Brigitte | D10: Juin | E10: =VLOOKUP(B10,'_Données Employés'!$B$5:$S$114,16,FALSE) | F10: =IF(E10="","",E10*0.05) | G10: =IF(E10="","",E10*0.3) | H10: =IF(E10="","",25000) | I10: =IF(E10="","",SUM(F10:H10)) | J10: =IF(E10="","",E10+I10) | K10: =IF(J10="","",J10*0.028) | L10: =IF(J10="","",J10*0.015) | M10: =IF(J10="","",IFERROR(IF(J10<=62000,0,IF(J10<=146000,(J10-62000)*0.1,IF(J10<=236000,8400+(J10-146000)*0.15,IF(J10<=360000,21900+(J10-236000)*0.25,IF(J10<=550000,51900+(J10-360000)*0.35,118400+(J10-550000)*0.4))))),0)) | N10: =IF(J10="","",SUM(K10:M10)) | O10: =IF(J10="","",J10-N10) | P10: =IF(J10="","",J10*0.082) | Q10: =IF(J10="","",J10+P10)
B11: EMP-007 | C11: Kamga Pierre | D11: Juin | E11: =VLOOKUP(B11,'_Données Employés'!$B$5:$S$114,16,FALSE) | F11: =IF(E11="","",E11*0.05) | G11: =IF(E11="","",E11*0.3) | H11: =IF(E11="","",25000) | I11: =IF(E11="","",SUM(F11:H11)) | J11: =IF(E11="","",E11+I11) | K11: =IF(J11="","",J11*0.028) | L11: =IF(J11="","",J11*0.015) | M11: =IF(J11="","",IFERROR(IF(J11<=62000,0,IF(J11<=146000,(J11-62000)*0.1,IF(J11<=236000,8400+(J11-146000)*0.15,IF(J11<=360000,21900+(J11-236000)*0.25,IF(J11<=550000,51900+(J11-360000)*0.35,118400+(J11-550000)*0.4))))),0)) | N11: =IF(J11="","",SUM(K11:M11)) | O11: =IF(J11="","",J11-N11) | P11: =IF(J11="","",J11*0.082) | Q11: =IF(J11="","",J11+P11)
B12: EMP-008 | C12: Ekode Aline | D12: Juin | E12: =VLOOKUP(B12,'_Données Employés'!$B$5:$S$114,16,FALSE) | F12: =IF(E12="","",E12*0.05) | G12: =IF(E12="","",E12*0.3) | H12: =IF(E12="","",25000) | I12: =IF(E12="","",SUM(F12:H12)) | J12: =IF(E12="","",E12+I12) | K12: =IF(J12="","",J12*0.028) | L12: =IF(J12="","",J12*0.015) | M12: =IF(J12="","",IFERROR(IF(J12<=62000,0,IF(J12<=146000,(J12-62000)*0.1,IF(J12<=236000,8400+(J12-146000)*0.15,IF(J12<=360000,21900+(J12-236000)*0.25,IF(J12<=550000,51900+(J12-360000)*0.35,118400+(J12-550000)*0.4))))),0)) | N12: =IF(J12="","",SUM(K12:M12)) | O12: =IF(J12="","",J12-N12) | P12: =IF(J12="","",J12*0.082) | Q12: =IF(J12="","",J12+P12)
B13: EMP-009 | C13: Bouba Hassan | D13: Juin | E13: =VLOOKUP(B13,'_Données Employés'!$B$5:$S$114,16,FALSE) | F13: =IF(E13="","",E13*0.05) | G13: =IF(E13="","",E13*0.3) | H13: =IF(E13="","",25000) | I13: =IF(E13="","",SUM(F13:H13)) | J13: =IF(E13="","",E13+I13) | K13: =IF(J13="","",J13*0.028) | L13: =IF(J13="","",J13*0.015) | M13: =IF(J13="","",IFERROR(IF(J13<=62000,0,IF(J13<=146000,(J13-62000)*0.1,IF(J13<=236000,8400+(J13-146000)*0.15,IF(J13<=360000,21900+(J13-236000)*0.25,IF(J13<=550000,51900+(J13-360000)*0.35,118400+(J13-550000)*0.4))))),0)) | N13: =IF(J13="","",SUM(K13:M13)) | O13: =IF(J13="","",J13-N13) | P13: =IF(J13="","",J13*0.082) | Q13: =IF(J13="","",J13+P13)
B14: EMP-010 | C14: Atangana Simon | D14: Juin | E14: =VLOOKUP(B14,'_Données Employés'!$B$5:$S$114,16,FALSE) | F14: =IF(E14="","",E14*0.05) | G14: =IF(E14="","",E14*0.3) | H14: =IF(E14="","",25000) | I14: =IF(E14="","",SUM(F14:H14)) | J14: =IF(E14="","",E14+I14) | K14: =IF(J14="","",J14*0.028) | L14: =IF(J14="","",J14*0.015) | M14: =IF(J14="","",IFERROR(IF(J14<=62000,0,IF(J14<=146000,(J14-62000)*0.1,IF(J14<=236000,8400+(J14-146000)*0.15,IF(J14<=360000,21900+(J14-236000)*0.25,IF(J14<=550000,51900+(J14-360000)*0.35,118400+(J14-550000)*0.4))))),0)) | N14: =IF(J14="","",SUM(K14:M14)) | O14: =IF(J14="","",J14-N14) | P14: =IF(J14="","",J14*0.082) | Q14: =IF(J14="","",J14+P14)
C15: =IF(B15="","",VLOOKUP(B15,'_Données Employés'!$B$5:$S$114,3,FALSE)) | E15: =IF(B15="","",VLOOKUP(B15,'_Données Employés'!$B$5:$S$114,16,FALSE)) | F15: =IF(E15="","",E15*0.05) | G15: =IF(E15="","",E15*0.3) | H15: =IF(E15="","",25000) | I15: =IF(E15="","",SUM(F15:H15)) | J15: =IF(E15="","",E15+I15) | K15: =IF(J15="","",J15*0.028) | L15: =IF(J15="","",J15*0.015) | M15: =IF(J15="","",IFERROR(IF(J15<=62000,0,IF(J15<=146000,(J15-62000)*0.1,IF(J15<=236000,8400+(J15-146000)*0.15,IF(J15<=360000,21900+(J15-236000)*0.25,IF(J15<=550000,51900+(J15-360000)*0.35,118400+(J15-550000)*0.4))))),0)) | N15: =IF(J15="","",SUM(K15:M15)) | O15: =IF(J15="","",J15-N15) | P15: =IF(J15="","",J15*0.082) | Q15: =IF(J15="","",J15+P15)
C16: =IF(B16="","",VLOOKUP(B16,'_Données Employés'!$B$5:$S$114,3,FALSE)) | E16: =IF(B16="","",VLOOKUP(B16,'_Données Employés'!$B$5:$S$114,16,FALSE)) | F16: =IF(E16="","",E16*0.05) | G16: =IF(E16="","",E16*0.3) | H16: =IF(E16="","",25000) | I16: =IF(E16="","",SUM(F16:H16)) | J16: =IF(E16="","",E16+I16) | K16: =IF(J16="","",J16*0.028) | L16: =IF(J16="","",J16*0.015) | M16: =IF(J16="","",IFERROR(IF(J16<=62000,0,IF(J16<=146000,(J16-62000)*0.1,IF(J16<=236000,8400+(J16-146000)*0.15,IF(J16<=360000,21900+(J16-236000)*0.25,IF(J16<=550000,51900+(J16-360000)*0.35,118400+(J16-550000)*0.4))))),0)) | N16: =IF(J16="","",SUM(K16:M16)) | O16: =IF(J16="","",J16-N16) | P16: =IF(J16="","",J16*0.082) | Q16: =IF(J16="","",J16+P16)
C17: =IF(B17="","",VLOOKUP(B17,'_Données Employés'!$B$5:$S$114,3,FALSE)) | E17: =IF(B17="","",VLOOKUP(B17,'_Données Employés'!$B$5:$S$114,16,FALSE)) | F17: =IF(E17="","",E17*0.05) | G17: =IF(E17="","",E17*0.3) | H17: =IF(E17="","",25000) | I17: =IF(E17="","",SUM(F17:H17)) | J17: =IF(E17="","",E17+I17) | K17: =IF(J17="","",J17*0.028) | L17: =IF(J17="","",J17*0.015) | M17: =IF(J17="","",IFERROR(IF(J17<=62000,0,IF(J17<=146000,(J17-62000)*0.1,IF(J17<=236000,8400+(J17-146000)*0.15,IF(J17<=360000,21900+(J17-236000)*0.25,IF(J17<=550000,51900+(J17-360000)*0.35,118400+(J17-550000)*0.4))))),0)) | N17: =IF(J17="","",SUM(K17:M17)) | O17: =IF(J17="","",J17-N17) | P17: =IF(J17="","",J17*0.082) | Q17: =IF(J17="","",J17+P17)
C18: =IF(B18="","",VLOOKUP(B18,'_Données Employés'!$B$5:$S$114,3,FALSE)) | E18: =IF(B18="","",VLOOKUP(B18,'_Données Employés'!$B$5:$S$114,16,FALSE)) | F18: =IF(E18="","",E18*0.05) | G18: =IF(E18="","",E18*0.3) | H18: =IF(E18="","",25000) | I18: =IF(E18="","",SUM(F18:H18)) | J18: =IF(E18="","",E18+I18) | K18: =IF(J18="","",J18*0.028) | L18: =IF(J18="","",J18*0.015) | M18: =IF(J18="","",IFERROR(IF(J18<=62000,0,IF(J18<=146000,(J18-62000)*0.1,IF(J18<=236000,8400+(J18-146000)*0.15,IF(J18<=360000,21900+(J18-236000)*0.25,IF(J18<=550000,51900+(J18-360000)*0.35,118400+(J18-550000)*0.4))))),0)) | N18: =IF(J18="","",SUM(K18:M18)) | O18: =IF(J18="","",J18-N18) | P18: =IF(J18="","",J18*0.082) | Q18: =IF(J18="","",J18+P18)
C19: =IF(B19="","",VLOOKUP(B19,'_Données Employés'!$B$5:$S$114,3,FALSE)) | E19: =IF(B19="","",VLOOKUP(B19,'_Données Employés'!$B$5:$S$114,16,FALSE)) | F19: =IF(E19="","",E19*0.05) | G19: =IF(E19="","",E19*0.3) | H19: =IF(E19="","",25000) | I19: =IF(E19="","",SUM(F19:H19)) | J19: =IF(E19="","",E19+I19) | K19: =IF(J19="","",J19*0.028) | L19: =IF(J19="","",J19*0.015) | M19: =IF(J19="","",IFERROR(IF(J19<=62000,0,IF(J19<=146000,(J19-62000)*0.1,IF(J19<=236000,8400+(J19-146000)*0.15,IF(J19<=360000,21900+(J19-236000)*0.25,IF(J19<=550000,51900+(J19-360000)*0.35,118400+(J19-550000)*0.4))))),0)) | N19: =IF(J19="","",SUM(K19:M19)) | O19: =IF(J19="","",J19-N19) | P19: =IF(J19="","",J19*0.082) | Q19: =IF(J19="","",J19+P19)
C20: =IF(B20="","",VLOOKUP(B20,'_Données Employés'!$B$5:$S$114,3,FALSE)) | E20: =IF(B20="","",VLOOKUP(B20,'_Données Employés'!$B$5:$S$114,16,FALSE)) | F20: =IF(E20="","",E20*0.05) | G20: =IF(E20="","",E20*0.3) | H20: =IF(E20="","",25000) | I20: =IF(E20="","",SUM(F20:H20)) | J20: =IF(E20="","",E20+I20) | K20: =IF(J20="","",J20*0.028) | L20: =IF(J20="","",J20*0.015) | M20: =IF(J20="","",IFERROR(IF(J20<=62000,0,IF(J20<=146000,(J20-62000)*0.1,IF(J20<=236000,8400+(J20-146000)*0.15,IF(J20<=360000,21900+(J20-236000)*0.25,IF(J20<=550000,51900+(J20-360000)*0.35,118400+(J20-550000)*0.4))))),0)) | N20: =IF(J20="","",SUM(K20:M20)) | O20: =IF(J20="","",J20-N20) | P20: =IF(J20="","",J20*0.082) | Q20: =IF(J20="","",J20+P20)
C21: =IF(B21="","",VLOOKUP(B21,'_Données Employés'!$B$5:$S$114,3,FALSE)) | E21: =IF(B21="","",VLOOKUP(B21,'_Données Employés'!$B$5:$S$114,16,FALSE)) | F21: =IF(E21="","",E21*0.05) | G21: =IF(E21="","",E21*0.3) | H21: =IF(E21="","",25000) | I21: =IF(E21="","",SUM(F21:H21)) | J21: =IF(E21="","",E21+I21) | K21: =IF(J21="","",J21*0.028) | L21: =IF(J21="","",J21*0.015) | M21: =IF(J21="","",IFERROR(IF(J21<=62000,0,IF(J21<=146000,(J21-62000)*0.1,IF(J21<=236000,8400+(J21-146000)*0.15,IF(J21<=360000,21900+(J21-236000)*0.25,IF(J21<=550000,51900+(J21-360000)*0.35,118400+(J21-550000)*0.4))))),0)) | N21: =IF(J21="","",SUM(K21:M21)) | O21: =IF(J21="","",J21-N21) | P21: =IF(J21="","",J21*0.082) | Q21: =IF(J21="","",J21+P21)
C22: =IF(B22="","",VLOOKUP(B22,'_Données Employés'!$B$5:$S$114,3,FALSE)) | E22: =IF(B22="","",VLOOKUP(B22,'_Données Employés'!$B$5:$S$114,16,FALSE)) | F22: =IF(E22="","",E22*0.05) | G22: =IF(E22="","",E22*0.3) | H22: =IF(E22="","",25000) | I22: =IF(E22="","",SUM(F22:H22)) | J22: =IF(E22="","",E22+I22) | K22: =IF(J22="","",J22*0.028) | L22: =IF(J22="","",J22*0.015) | M22: =IF(J22="","",IFERROR(IF(J22<=62000,0,IF(J22<=146000,(J22-62000)*0.1,IF(J22<=236000,8400+(J22-146000)*0.15,IF(J22<=360000,21900+(J22-236000)*0.25,IF(J22<=550000,51900+(J22-360000)*0.35,118400+(J22-550000)*0.4))))),0)) | N22: =IF(J22="","",SUM(K22:M22)) | O22: =IF(J22="","",J22-N22) | P22: =IF(J22="","",J22*0.082) | Q22: =IF(J22="","",J22+P22)
C23: =IF(B23="","",VLOOKUP(B23,'_Données Employés'!$B$5:$S$114,3,FALSE)) | E23: =IF(B23="","",VLOOKUP(B23,'_Données Employés'!$B$5:$S$114,16,FALSE)) | F23: =IF(E23="","",E23*0.05) | G23: =IF(E23="","",E23*0.3) | H23: =IF(E23="","",25000) | I23: =IF(E23="","",SUM(F23:H23)) | J23: =IF(E23="","",E23+I23) | K23: =IF(J23="","",J23*0.028) | L23: =IF(J23="","",J23*0.015) | M23: =IF(J23="","",IFERROR(IF(J23<=62000,0,IF(J23<=146000,(J23-62000)*0.1,IF(J23<=236000,8400+(J23-146000)*0.15,IF(J23<=360000,21900+(J23-236000)*0.25,IF(J23<=550000,51900+(J23-360000)*0.35,118400+(J23-550000)*0.4))))),0)) | N23: =IF(J23="","",SUM(K23:M23)) | O23: =IF(J23="","",J23-N23) | P23: =IF(J23="","",J23*0.082) | Q23: =IF(J23="","",J23+P23)
C24: =IF(B24="","",VLOOKUP(B24,'_Données Employés'!$B$5:$S$114,3,FALSE)) | E24: =IF(B24="","",VLOOKUP(B24,'_Données Employés'!$B$5:$S$114,16,FALSE)) | F24: =IF(E24="","",E24*0.05) | G24: =IF(E24="","",E24*0.3) | H24: =IF(E24="","",25000) | I24: =IF(E24="","",SUM(F24:H24)) | J24: =IF(E24="","",E24+I24) | K24: =IF(J24="","",J24*0.028) | L24: =IF(J24="","",J24*0.015) | M24: =IF(J24="","",IFERROR(IF(J24<=62000,0,IF(J24<=146000,(J24-62000)*0.1,IF(J24<=236000,8400+(J24-146000)*0.15,IF(J24<=360000,21900+(J24-236000)*0.25,IF(J24<=550000,51900+(J24-360000)*0.35,118400+(J24-550000)*0.4))))),0)) | N24: =IF(J24="","",SUM(K24:M24)) | O24: =IF(J24="","",J24-N24) | P24: =IF(J24="","",J24*0.082) | Q24: =IF(J24="","",J24+P24)
C25: =IF(B25="","",VLOOKUP(B25,'_Données Employés'!$B$5:$S$114,3,FALSE)) | E25: =IF(B25="","",VLOOKUP(B25,'_Données Employés'!$B$5:$S$114,16,FALSE)) | F25: =IF(E25="","",E25*0.05) | G25: =IF(E25="","",E25*0.3) | H25: =IF(E25="","",25000) | I25: =IF(E25="","",SUM(F25:H25)) | J25: =IF(E25="","",E25+I25) | K25: =IF(J25="","",J25*0.028) | L25: =IF(J25="","",J25*0.015) | M25: =IF(J25="","",IFERROR(IF(J25<=62000,0,IF(J25<=146000,(J25-62000)*0.1,IF(J25<=236000,8400+(J25-146000)*0.15,IF(J25<=360000,21900+(J25-236000)*0.25,IF(J25<=550000,51900+(J25-360000)*0.35,118400+(J25-550000)*0.4))))),0)) | N25: =IF(J25="","",SUM(K25:M25)) | O25: =IF(J25="","",J25-N25) | P25: =IF(J25="","",J25*0.082) | Q25: =IF(J25="","",J25+P25)
C26: =IF(B26="","",VLOOKUP(B26,'_Données Employés'!$B$5:$S$114,3,FALSE)) | E26: =IF(B26="","",VLOOKUP(B26,'_Données Employés'!$B$5:$S$114,16,FALSE)) | F26: =IF(E26="","",E26*0.05) | G26: =IF(E26="","",E26*0.3) | H26: =IF(E26="","",25000) | I26: =IF(E26="","",SUM(F26:H26)) | J26: =IF(E26="","",E26+I26) | K26: =IF(J26="","",J26*0.028) | L26: =IF(J26="","",J26*0.015) | M26: =IF(J26="","",IFERROR(IF(J26<=62000,0,IF(J26<=146000,(J26-62000)*0.1,IF(J26<=236000,8400+(J26-146000)*0.15,IF(J26<=360000,21900+(J26-236000)*0.25,IF(J26<=550000,51900+(J26-360000)*0.35,118400+(J26-550000)*0.4))))),0)) | N26: =IF(J26="","",SUM(K26:M26)) | O26: =IF(J26="","",J26-N26) | P26: =IF(J26="","",J26*0.082) | Q26: =IF(J26="","",J26+P26)
... C104: =IF(B104="","",VLOOKUP(B104,'_Données Employés'!$B$5:$S$114,3,FALSE)) | E104: =IF(B104="","",VLOOKUP(B104,'_Données Employés'!$B$5:$S$114,16,FALSE)) | F104: =IF(E104="","",E104*0.05) | G104: =IF(E104="","",E104*0.3) | H104: =IF(E104="","",25000) | I104: =IF(E104="","",SUM(F104:H104)) | J104: =IF(E104="","",E104+I104) | K104: =IF(J104="","",J104*0.028) | L104: =IF(J104="","",J104*0.015) | M104: =IF(J104="","",IFERROR(IF(J104<=62000,0,IF(J104<=146000,(J104-62000)*0.1,IF(J104<=236000,8400+(J104-146000)*0.15,IF(J104<=360000,21900+(J104-236000)*0.25,IF(J104<=550000,51900+(J104-360000)*0.35,118400+(J104-550000)*0.4))))),0)) | N104: =IF(J104="","",SUM(K104:M104)) | O104: =IF(J104="","",J104-N104) | P104: =IF(J104="","",J104*0.082) | Q104: =IF(J104="","",J104+P104)
B107: KPI Masse brute (FCFA) | D107: KPI Masse nette (FCFA) | F107: KPI Coût total employeur (FCFA) | H107: KPI Taux prélèvement moy.
B108: =SUM(J5:J104) | D108: =SUM(O5:O104) | F108: =SUM(Q5:Q104) | H108: =IFERROR(AVERAGE(N5:N104)/AVERAGE(J5:J104),0)

Sheet 3-Primes & Indemnités
B2: PAIE — 3-Primes & Indemnités
B4: N° | C4: Matricule | D4: Nom Employé | E4: Département | F4: Type Prime | G4: Mois | H4: Base Calcul (FCFA) | I4: Taux (%) | J4: Montant Brut (FCFA) | K4: Imposable | L4: Montant Net (FCFA) | M4: Statut
B5: PRI-001 | C5: EMP-001 | D5: Nganou Clarisse | E5: Ressources Humaines | F5: Prime de responsabilite | G5: Juin | H5: 635000 | I5: 10 | J5: 63500 | K5: Oui | L5: 53975 | M5: Approuve
B6: PRI-002 | C6: EMP-002 | D6: Tchinda Armand | E6: Finance & Comptabilite | F6: Prime de rendement | G6: Juin | H6: 484000 | I6: 5 | J6: 24200 | K6: Oui | L6: 20570 | M6: Approuve
B7: PRI-003 | C7: EMP-005 | D7: Diallo Moussa | E7: Cuisine & Restauration | F7: Indemnite de danger | G7: Juin | H7: 253000 | I7: 5 | J7: 12650 | K7: Oui | L7: 10752 | M7: Approuve
B8: PRI-004 | C8: EMP-004 | D8: Ouedraogo Ibrahim | E8: Reception & Front Office | F8: Prime exceptionnelle | G8: Juin | H8: 207000 | I8: 0 | J8: 15000 | K8: Oui | L8: 12750 | M8: Approuve
B9: =IF(C9="","PRI"&TEXT(COUNTA($C$5:C9),"000")) | D9: =IF(C9="","",VLOOKUP(C9,'_Données Employés'!$B$5:$S$114,3,FALSE)) | E9: =IF(C9="","",VLOOKUP(C9,'_Données Employés'!$B$5:$S$114,10,FALSE)) | J9: =IF(OR(G9="",H9=""),"",IFERROR(G9*H9/100,0)) | L9: =IF(I9="","",IF(I9="Non",I9,IFERROR(I9*0.85,0)))
B10: =IF(C10="","PRI"&TEXT(COUNTA($C$5:C10),"000")) | D10: =IF(C10="","",VLOOKUP(C10,'_Données Employés'!$B$5:$S$114,3,FALSE)) | E10: =IF(C10="","",VLOOKUP(C10,'_Données Employés'!$B$5:$S$114,10,FALSE)) | J10: =IF(OR(G10="",H10=""),"",IFERROR(G10*H10/100,0)) | L10: =IF(I10="","",IF(I10="Non",I10,IFERROR(I10*0.85,0)))
B11: =IF(C11="","PRI"&TEXT(COUNTA($C$5:C11),"000")) | D11: =IF(C11="","",VLOOKUP(C11,'_Données Employés'!$B$5:$S$114,3,FALSE)) | E11: =IF(C11="","",VLOOKUP(C11,'_Données Employés'!$B$5:$S$114,10,FALSE)) | J11: =IF(OR(G11="",H11=""),"",IFERROR(G11*H11/100,0)) | L11: =IF(I11="","",IF(I11="Non",I11,IFERROR(I11*0.85,0)))
B12: =IF(C12="","PRI"&TEXT(COUNTA($C$5:C12),"000")) | D12: =IF(C12="","",VLOOKUP(C12,'_Données Employés'!$B$5:$S$114,3,FALSE)) | E12: =IF(C12="","",VLOOKUP(C12,'_Données Employés'!$B$5:$S$114,10,FALSE)) | J12: =IF(OR(G12="",H12=""),"",IFERROR(G12*H12/100,0)) | L12: =IF(I12="","",IF(I12="Non",I12,IFERROR(I12*0.85,0)))
B13: =IF(C13="","PRI"&TEXT(COUNTA($C$5:C13),"000")) | D13: =IF(C13="","",VLOOKUP(C13,'_Données Employés'!$B$5:$S$114,3,FALSE)) | E13: =IF(C13="","",VLOOKUP(C13,'_Données Employés'!$B$5:$S$114,10,FALSE)) | J13: =IF(OR(G13="",H13=""),"",IFERROR(G13*H13/100,0)) | L13: =IF(I13="","",IF(I13="Non",I13,IFERROR(I13*0.85,0)))
B14: =IF(C14="","PRI"&TEXT(COUNTA($C$5:C14),"000")) | D14: =IF(C14="","",VLOOKUP(C14,'_Données Employés'!$B$5:$S$114,3,FALSE)) | E14: =IF(C14="","",VLOOKUP(C14,'_Données Employés'!$B$5:$S$114,10,FALSE)) | J14: =IF(OR(G14="",H14=""),"",IFERROR(G14*H14/100,0)) | L14: =IF(I14="","",IF(I14="Non",I14,IFERROR(I14*0.85,0)))
B15: =IF(C15="","PRI"&TEXT(COUNTA($C$5:C15),"000")) | D15: =IF(C15="","",VLOOKUP(C15,'_Données Employés'!$B$5:$S$114,3,FALSE)) | E15: =IF(C15="","",VLOOKUP(C15,'_Données Employés'!$B$5:$S$114,10,FALSE)) | J15: =IF(OR(G15="",H15=""),"",IFERROR(G15*H15/100,0)) | L15: =IF(I15="","",IF(I15="Non",I15,IFERROR(I15*0.85,0)))
B16: =IF(C16="","PRI"&TEXT(COUNTA($C$5:C16),"000")) | D16: =IF(C16="","",VLOOKUP(C16,'_Données Employés'!$B$5:$S$114,3,FALSE)) | E16: =IF(C16="","",VLOOKUP(C16,'_Données Employés'!$B$5:$S$114,10,FALSE)) | J16: =IF(OR(G16="",H16=""),"",IFERROR(G16*H16/100,0)) | L16: =IF(I16="","",IF(I16="Non",I16,IFERROR(I16*0.85,0)))
B17: =IF(C17="","PRI"&TEXT(COUNTA($C$5:C17),"000")) | D17: =IF(C17="","",VLOOKUP(C17,'_Données Employés'!$B$5:$S$114,3,FALSE)) | E17: =IF(C17="","",VLOOKUP(C17,'_Données Employés'!$B$5:$S$114,10,FALSE)) | J17: =IF(OR(G17="",H17=""),"",IFERROR(G17*H17/100,0)) | L17: =IF(I17="","",IF(I17="Non",I17,IFERROR(I17*0.85,0)))
B18: =IF(C18="","PRI"&TEXT(COUNTA($C$5:C18),"000")) | D18: =IF(C18="","",VLOOKUP(C18,'_Données Employés'!$B$5:$S$114,3,FALSE)) | E18: =IF(C18="","",VLOOKUP(C18,'_Données Employés'!$B$5:$S$114,10,FALSE)) | J18: =IF(OR(G18="",H18=""),"",IFERROR(G18*H18/100,0)) | L18: =IF(I18="","",IF(I18="Non",I18,IFERROR(I18*0.85,0)))
B19: =IF(C19="","PRI"&TEXT(COUNTA($C$5:C19),"000")) | D19: =IF(C19="","",VLOOKUP(C19,'_Données Employés'!$B$5:$S$114,3,FALSE)) | E19: =IF(C19="","",VLOOKUP(C19,'_Données Employés'!$B$5:$S$114,10,FALSE)) | J19: =IF(OR(G19="",H19=""),"",IFERROR(G19*H19/100,0)) | L19: =IF(I19="","",IF(I19="Non",I19,IFERROR(I19*0.85,0)))
B20: =IF(C20="","PRI"&TEXT(COUNTA($C$5:C20),"000")) | D20: =IF(C20="","",VLOOKUP(C20,'_Données Employés'!$B$5:$S$114,3,FALSE)) | E20: =IF(C20="","",VLOOKUP(C20,'_Données Employés'!$B$5:$S$114,10,FALSE)) | J20: =IF(OR(G20="",H20=""),"",IFERROR(G20*H20/100,0)) | L20: =IF(I20="","",IF(I20="Non",I20,IFERROR(I20*0.85,0)))
... B104: =IF(C104="","PRI"&TEXT(COUNTA($C$5:C104),"000")) | D104: =IF(C104="","",VLOOKUP(C104,'_Données Employés'!$B$5:$S$114,3,FALSE)) | E104: =IF(C104="","",VLOOKUP(C104,'_Données Employés'!$B$5:$S$114,10,FALSE)) | J104: =IF(OR(G104="",H104=""),"",IFERROR(G104*H104/100,0)) | L104: =IF(I104="","",IF(I104="Non",I104,IFERROR(I104*0.85,0)))
B107: KPI Total brut (FCFA) | C107: KPI Total net (FCFA) | D107: KPI Primes approuvées
B108: =SUM(J5:J104) | C108: =SUM(L5:L104) | D108: =COUNTIF(M5:M104,"Approuve")

Sheet 4-Heures Supplementaires
B2: PAIE — 4-Heures Supplementaires
B4: N° | C4: Matricule | D4: Nom Employé | E4: Mois | F4: Heures Normales | G4: Heures Supp | H4: Taux Majoration (%) | I4: Taux Horaire (FCFA) | J4: Montant Brut (FCFA) | K4: Cotisations (FCFA) | L4: Montant Net (FCFA) | M4: Statut
B5: HS-001 | C5: EMP-004 | D5: Ouedraogo Ibrahim | E5: Juin | F5: 173 | G5: 12 | H5: 25 | I5: 1197 | J5: 17955 | K5: 1796 | L5: 16160 | M5: Valide
B6: HS-002 | C6: EMP-005 | D6: Diallo Moussa | E6: Juin | F6: 173 | G6: 8 | H6: 25 | I6: 1462 | J6: 23392 | K6: 2339 | L6: 21053 | M6: Valide
B7: HS-003 | C7: EMP-010 | D7: Atangana Simon | E7: Juin | F7: 173 | G7: 10 | H7: 25 | I7: 931 | J7: 23275 | K7: 2328 | L7: 20948 | M7: Valide
B8: =IF(C8="","HS"&TEXT(COUNTA($C$5:C8),"000")) | D8: =IF(C8="","",VLOOKUP(C8,'_Données Employés'!$B$5:$S$114,3,FALSE)) | I8: =IF(OR(F8="",G8=""),"",IFERROR(E8/173,0)) | J8: =IF(H8="","",IFERROR(F8*H8*(1+G8/100)/100,0)) | K8: =IF(I8="","",IFERROR(I8*0.1,0)) | L8: =IF(I8="","",IFERROR(I8-J8,0))
B9: =IF(C9="","HS"&TEXT(COUNTA($C$5:C9),"000")) | D9: =IF(C9="","",VLOOKUP(C9,'_Données Employés'!$B$5:$S$114,3,FALSE)) | I9: =IF(OR(F9="",G9=""),"",IFERROR(E9/173,0)) | J9: =IF(H9="","",IFERROR(F9*H9*(1+G9/100)/100,0)) | K9: =IF(I9="","",IFERROR(I9*0.1,0)) | L9: =IF(I9="","",IFERROR(I9-J9,0))
B10: =IF(C10="","HS"&TEXT(COUNTA($C$5:C10),"000")) | D10: =IF(C10="","",VLOOKUP(C10,'_Données Employés'!$B$5:$S$114,3,FALSE)) | I10: =IF(OR(F10="",G10=""),"",IFERROR(E10/173,0)) | J10: =IF(H10="","",IFERROR(F10*H10*(1+G10/100)/100,0)) | K10: =IF(I10="","",IFERROR(I10*0.1,0)) | L10: =IF(I10="","",IFERROR(I10-J10,0))
B11: =IF(C11="","HS"&TEXT(COUNTA($C$5:C11),"000")) | D11: =IF(C11="","",VLOOKUP(C11,'_Données Employés'!$B$5:$S$114,3,FALSE)) | I11: =IF(OR(F11="",G11=""),"",IFERROR(E11/173,0)) | J11: =IF(H11="","",IFERROR(F11*H11*(1+G11/100)/100,0)) | K11: =IF(I11="","",IFERROR(I11*0.1,0)) | L11: =IF(I11="","",IFERROR(I11-J11,0))
B12: =IF(C12="","HS"&TEXT(COUNTA($C$5:C12),"000")) | D12: =IF(C12="","",VLOOKUP(C12,'_Données Employés'!$B$5:$S$114,3,FALSE)) | I12: =IF(OR(F12="",G12=""),"",IFERROR(E12/173,0)) | J12: =IF(H12="","",IFERROR(F12*H12*(1+G12/100)/100,0)) | K12: =IF(I12="","",IFERROR(I12*0.1,0)) | L12: =IF(I12="","",IFERROR(I12-J12,0))
B13: =IF(C13="","HS"&TEXT(COUNTA($C$5:C13),"000")) | D13: =IF(C13="","",VLOOKUP(C13,'_Données Employés'!$B$5:$S$114,3,FALSE)) | I13: =IF(OR(F13="",G13=""),"",IFERROR(E13/173,0)) | J13: =IF(H13="","",IFERROR(F13*H13*(1+G13/100)/100,0)) | K13: =IF(I13="","",IFERROR(I13*0.1,0)) | L13: =IF(I13="","",IFERROR(I13-J13,0))
B14: =IF(C14="","HS"&TEXT(COUNTA($C$5:C14),"000")) | D14: =IF(C14="","",VLOOKUP(C14,'_Données Employés'!$B$5:$S$114,3,FALSE)) | I14: =IF(OR(F14="",G14=""),"",IFERROR(E14/173,0)) | J14: =IF(H14="","",IFERROR(F14*H14*(1+G14/100)/100,0)) | K14: =IF(I14="","",IFERROR(I14*0.1,0)) | L14: =IF(I14="","",IFERROR(I14-J14,0))
B15: =IF(C15="","HS"&TEXT(COUNTA($C$5:C15),"000")) | D15: =IF(C15="","",VLOOKUP(C15,'_Données Employés'!$B$5:$S$114,3,FALSE)) | I15: =IF(OR(F15="",G15=""),"",IFERROR(E15/173,0)) | J15: =IF(H15="","",IFERROR(F15*H15*(1+G15/100)/100,0)) | K15: =IF(I15="","",IFERROR(I15*0.1,0)) | L15: =IF(I15="","",IFERROR(I15-J15,0))
B16: =IF(C16="","HS"&TEXT(COUNTA($C$5:C16),"000")) | D16: =IF(C16="","",VLOOKUP(C16,'_Données Employés'!$B$5:$S$114,3,FALSE)) | I16: =IF(OR(F16="",G16=""),"",IFERROR(E16/173,0)) | J16: =IF(H16="","",IFERROR(F16*H16*(1+G16/100)/100,0)) | K16: =IF(I16="","",IFERROR(I16*0.1,0)) | L16: =IF(I16="","",IFERROR(I16-J16,0))
B17: =IF(C17="","HS"&TEXT(COUNTA($C$5:C17),"000")) | D17: =IF(C17="","",VLOOKUP(C17,'_Données Employés'!$B$5:$S$114,3,FALSE)) | I17: =IF(OR(F17="",G17=""),"",IFERROR(E17/173,0)) | J17: =IF(H17="","",IFERROR(F17*H17*(1+G17/100)/100,0)) | K17: =IF(I17="","",IFERROR(I17*0.1,0)) | L17: =IF(I17="","",IFERROR(I17-J17,0))
B18: =IF(C18="","HS"&TEXT(COUNTA($C$5:C18),"000")) | D18: =IF(C18="","",VLOOKUP(C18,'_Données Employés'!$B$5:$S$114,3,FALSE)) | I18: =IF(OR(F18="",G18=""),"",IFERROR(E18/173,0)) | J18: =IF(H18="","",IFERROR(F18*H18*(1+G18/100)/100,0)) | K18: =IF(I18="","",IFERROR(I18*0.1,0)) | L18: =IF(I18="","",IFERROR(I18-J18,0))
B19: =IF(C19="","HS"&TEXT(COUNTA($C$5:C19),"000")) | D19: =IF(C19="","",VLOOKUP(C19,'_Données Employés'!$B$5:$S$114,3,FALSE)) | I19: =IF(OR(F19="",G19=""),"",IFERROR(E19/173,0)) | J19: =IF(H19="","",IFERROR(F19*H19*(1+G19/100)/100,0)) | K19: =IF(I19="","",IFERROR(I19*0.1,0)) | L19: =IF(I19="","",IFERROR(I19-J19,0))
... B104: =IF(C104="","HS"&TEXT(COUNTA($C$5:C104),"000")) | D104: =IF(C104="","",VLOOKUP(C104,'_Données Employés'!$B$5:$S$114,3,FALSE)) | I104: =IF(OR(F104="",G104=""),"",IFERROR(E104/173,0)) | J104: =IF(H104="","",IFERROR(F104*H104*(1+G104/100)/100,0)) | K104: =IF(I104="","",IFERROR(I104*0.1,0)) | L104: =IF(I104="","",IFERROR(I104-J104,0))
B107: KPI Total HS (h) | C107: KPI Montant brut HS (FCFA) | D107: KPI Montant net HS (FCFA)
B108: =SUM(G5:G104) | C108: =SUM(I5:I104) | D108: =SUM(K5:K104)

Sheet 5-Cotisations Salariales
B2: PAIE — 5-Cotisations Salariales
B4: N° | C4: Matricule | D4: Nom Employé | E4: Salaire Brut (FCFA) | F4: CNPS 2.8% | G4: CNAMGS 1.5% | H4: IR Salaires | I4: Acomptes (FCFA) | J4: Total Retenues (FCFA) | K4: Salaire Net (FCFA) | L4: Mois | M4: Statut
B5: RET-001 | C5: EMP-001 | D5: Nganou Clarisse | E5: 850750 | F5: 23821 | G5: 12761 | H5: 105400 | I5: 0 | J5: 141982 | K5: 708768 | L5: Juin | M5: Valide
B6: RET-002 | C6: EMP-002 | D6: Tchinda Armand | E6: 648100 | F6: 18147 | G6: 9722 | H6: 52000 | I6: 0 | J6: 79868 | K6: 568233 | L6: Juin | M6: Valide
B7: RET-003 | C7: EMP-003 | D7: Fotso Marguerite | E7: 383125 | F7: 10727 | G7: 5747 | H7: 20000 | I7: 0 | J7: 36474 | K7: 346651 | L7: Juin | M7: Valide
B8: =IF(C8="","RET"&TEXT(COUNTA($C$5:C8),"000")) | D8: =IF(C8="","",VLOOKUP(C8,'_Données Employés'!$B$5:$S$114,3,FALSE)) | J8: =IF(D8="","",IFERROR(SUM(E8:H8),0)) | K8: =IF(D8="","",IFERROR(D8-J8,0))
B9: =IF(C9="","RET"&TEXT(COUNTA($C$5:C9),"000")) | D9: =IF(C9="","",VLOOKUP(C9,'_Données Employés'!$B$5:$S$114,3,FALSE)) | J9: =IF(D9="","",IFERROR(SUM(E9:H9),0)) | K9: =IF(D9="","",IFERROR(D9-J9,0))
B10: =IF(C10="","RET"&TEXT(COUNTA($C$5:C10),"000")) | D10: =IF(C10="","",VLOOKUP(C10,'_Données Employés'!$B$5:$S$114,3,FALSE)) | J10: =IF(D10="","",IFERROR(SUM(E10:H10),0)) | K10: =IF(D10="","",IFERROR(D10-J10,0))
B11: =IF(C11="","RET"&TEXT(COUNTA($C$5:C11),"000")) | D11: =IF(C11="","",VLOOKUP(C11,'_Données Employés'!$B$5:$S$114,3,FALSE)) | J11: =IF(D11="","",IFERROR(SUM(E11:H11),0)) | K11: =IF(D11="","",IFERROR(D11-J11,0))
B12: =IF(C12="","RET"&TEXT(COUNTA($C$5:C12),"000")) | D12: =IF(C12="","",VLOOKUP(C12,'_Données Employés'!$B$5:$S$114,3,FALSE)) | J12: =IF(D12="","",IFERROR(SUM(E12:H12),0)) | K12: =IF(D12="","",IFERROR(D12-J12,0))
B13: =IF(C13="","RET"&TEXT(COUNTA($C$5:C13),"000")) | D13: =IF(C13="","",VLOOKUP(C13,'_Données Employés'!$B$5:$S$114,3,FALSE)) | J13: =IF(D13="","",IFERROR(SUM(E13:H13),0)) | K13: =IF(D13="","",IFERROR(D13-J13,0))
B14: =IF(C14="","RET"&TEXT(COUNTA($C$5:C14),"000")) | D14: =IF(C14="","",VLOOKUP(C14,'_Données Employés'!$B$5:$S$114,3,FALSE)) | J14: =IF(D14="","",IFERROR(SUM(E14:H14),0)) | K14: =IF(D14="","",IFERROR(D14-J14,0))
B15: =IF(C15="","RET"&TEXT(COUNTA($C$5:C15),"000")) | D15: =IF(C15="","",VLOOKUP(C15,'_Données Employés'!$B$5:$S$114,3,FALSE)) | J15: =IF(D15="","",IFERROR(SUM(E15:H15),0)) | K15: =IF(D15="","",IFERROR(D15-J15,0))
B16: =IF(C16="","RET"&TEXT(COUNTA($C$5:C16),"000")) | D16: =IF(C16="","",VLOOKUP(C16,'_Données Employés'!$B$5:$S$114,3,FALSE)) | J16: =IF(D16="","",IFERROR(SUM(E16:H16),0)) | K16: =IF(D16="","",IFERROR(D16-J16,0))
B17: =IF(C17="","RET"&TEXT(COUNTA($C$5:C17),"000")) | D17: =IF(C17="","",VLOOKUP(C17,'_Données Employés'!$B$5:$S$114,3,FALSE)) | J17: =IF(D17="","",IFERROR(SUM(E17:H17),0)) | K17: =IF(D17="","",IFERROR(D17-J17,0))
B18: =IF(C18="","RET"&TEXT(COUNTA($C$5:C18),"000")) | D18: =IF(C18="","",VLOOKUP(C18,'_Données Employés'!$B$5:$S$114,3,FALSE)) | J18: =IF(D18="","",IFERROR(SUM(E18:H18),0)) | K18: =IF(D18="","",IFERROR(D18-J18,0))
B19: =IF(C19="","RET"&TEXT(COUNTA($C$5:C19),"000")) | D19: =IF(C19="","",VLOOKUP(C19,'_Données Employés'!$B$5:$S$114,3,FALSE)) | J19: =IF(D19="","",IFERROR(SUM(E19:H19),0)) | K19: =IF(D19="","",IFERROR(D19-J19,0))
... B104: =IF(C104="","RET"&TEXT(COUNTA($C$5:C104),"000")) | D104: =IF(C104="","",VLOOKUP(C104,'_Données Employés'!$B$5:$S$114,3,FALSE)) | J104: =IF(D104="","",IFERROR(SUM(E104:H104),0)) | K104: =IF(D104="","",IFERROR(D104-J104,0))
B107: KPI Total retenues (FCFA) | C107: KPI Salaire net total (FCFA) | D107: KPI Taux prélèvement moy.
B108: =SUM(J5:J104) | C108: =SUM(K5:K104) | D108: =IFERROR(AVERAGE(J5:J104)/AVERAGE(D5:D104),0)

Sheet 6-Deductions Retenues
B2: PAIE — 6-Deductions Retenues
B4: N° | C4: Matricule | D4: Nom Employé | E4: Type Déduction | F4: Base Calcul (FCFA) | G4: Taux (%) | H4: Montant (FCFA) | I4: Mois | J4: Priorité | K4: Statut
B5: DED-001 | C5: EMP-001 | D5: Nganou Clarisse | E5: Acompte | F5: 635000 | G5: 10 | H5: 63500 | I5: Juin | J5: 1 | K5: Valide
B6: DED-002 | C6: EMP-003 | D6: Fotso Marguerite | E6: Pret personnel | F6: 287500 | G6: 5 | H6: 14375 | I6: Juin | J6: 2 | K6: Valide
B7: DED-003 | C7: EMP-007 | D7: Kamga Pierre | E7: Retard | F7: 149500 | G7: 2 | H7: 2990 | I7: Juin | J7: 3 | K7: Valide
B8: =IF(C8="","DED"&TEXT(COUNTA($C$5:C8),"000")) | D8: =IF(C8="","",VLOOKUP(C8,'_Données Employés'!$B$5:$S$114,3,FALSE)) | H8: =IF(OR(E8="",F8=""),"",IFERROR(E8*F8/100,0))
B9: =IF(C9="","DED"&TEXT(COUNTA($C$5:C9),"000")) | D9: =IF(C9="","",VLOOKUP(C9,'_Données Employés'!$B$5:$S$114,3,FALSE)) | H9: =IF(OR(E9="",F9=""),"",IFERROR(E9*F9/100,0))
B10: =IF(C10="","DED"&TEXT(COUNTA($C$5:C10),"000")) | D10: =IF(C10="","",VLOOKUP(C10,'_Données Employés'!$B$5:$S$114,3,FALSE)) | H10: =IF(OR(E10="",F10=""),"",IFERROR(E10*F10/100,0))
B11: =IF(C11="","DED"&TEXT(COUNTA($C$5:C11),"000")) | D11: =IF(C11="","",VLOOKUP(C11,'_Données Employés'!$B$5:$S$114,3,FALSE)) | H11: =IF(OR(E11="",F11=""),"",IFERROR(E11*F11/100,0))
B12: =IF(C12="","DED"&TEXT(COUNTA($C$5:C12),"000")) | D12: =IF(C12="","",VLOOKUP(C12,'_Données Employés'!$B$5:$S$114,3,FALSE)) | H12: =IF(OR(E12="",F12=""),"",IFERROR(E12*F12/100,0))
B13: =IF(C13="","DED"&TEXT(COUNTA($C$5:C13),"000")) | D13: =IF(C13="","",VLOOKUP(C13,'_Données Employés'!$B$5:$S$114,3,FALSE)) | H13: =IF(OR(E13="",F13=""),"",IFERROR(E13*F13/100,0))
B14: =IF(C14="","DED"&TEXT(COUNTA($C$5:C14),"000")) | D14: =IF(C14="","",VLOOKUP(C14,'_Données Employés'!$B$5:$S$114,3,FALSE)) | H14: =IF(OR(E14="",F14=""),"",IFERROR(E14*F14/100,0))
B15: =IF(C15="","DED"&TEXT(COUNTA($C$5:C15),"000")) | D15: =IF(C15="","",VLOOKUP(C15,'_Données Employés'!$B$5:$S$114,3,FALSE)) | H15: =IF(OR(E15="",F15=""),"",IFERROR(E15*F15/100,0))
B16: =IF(C16="","DED"&TEXT(COUNTA($C$5:C16),"000")) | D16: =IF(C16="","",VLOOKUP(C16,'_Données Employés'!$B$5:$S$114,3,FALSE)) | H16: =IF(OR(E16="",F16=""),"",IFERROR(E16*F16/100,0))
B17: =IF(C17="","DED"&TEXT(COUNTA($C$5:C17),"000")) | D17: =IF(C17="","",VLOOKUP(C17,'_Données Employés'!$B$5:$S$114,3,FALSE)) | H17: =IF(OR(E17="",F17=""),"",IFERROR(E17*F17/100,0))
B18: =IF(C18="","DED"&TEXT(COUNTA($C$5:C18),"000")) | D18: =IF(C18="","",VLOOKUP(C18,'_Données Employés'!$B$5:$S$114,3,FALSE)) | H18: =IF(OR(E18="",F18=""),"",IFERROR(E18*F18/100,0))
B19: =IF(C19="","DED"&TEXT(COUNTA($C$5:C19),"000")) | D19: =IF(C19="","",VLOOKUP(C19,'_Données Employés'!$B$5:$S$114,3,FALSE)) | H19: =IF(OR(E19="",F19=""),"",IFERROR(E19*F19/100,0))
... B104: =IF(C104="","DED"&TEXT(COUNTA($C$5:C104),"000")) | D104: =IF(C104="","",VLOOKUP(C104,'_Données Employés'!$B$5:$S$114,3,FALSE)) | H104: =IF(OR(E104="",F104=""),"",IFERROR(E104*F104/100,0))
B107: KPI Total déductions (FCFA) | C107: KPI Nombre retenues
B108: =SUM(G5:G104) | C108: =COUNTA(C5:C104)

Sheet 7-Acomptes Avances
B2: PAIE — 7-Acomptes Avances
B4: N° | C4: Matricule | D4: Nom Employé | E4: Type | F4: Montant Demandé (FCFA) | G4: Montant Accordé (FCFA) | H4: Date Demande | I4: Date Versement | J4: Statut
B5: ACO-001 | C5: EMP-004 | D5: Ouedraogo Ibrahim | E5: Avance salaire | F5: 50000 | G5: 50000 | H5: 2025-06-01 | I5: 2025-06-15 | J5: Approuve
B6: ACO-002 | C6: EMP-006 | D6: Ngassa Brigitte | E6: Acompte | F6: 30000 | G6: 25000 | H6: 2025-06-10 | I6: 2025-06-20 | J6: Approuve
B7: =IF(C7="","ACO"&TEXT(COUNTA($C$5:C7),"000")) | D7: =IF(C7="","",VLOOKUP(C7,'_Données Employés'!$B$5:$S$114,3,FALSE))
B8: =IF(C8="","ACO"&TEXT(COUNTA($C$5:C8),"000")) | D8: =IF(C8="","",VLOOKUP(C8,'_Données Employés'!$B$5:$S$114,3,FALSE))
B9: =IF(C9="","ACO"&TEXT(COUNTA($C$5:C9),"000")) | D9: =IF(C9="","",VLOOKUP(C9,'_Données Employés'!$B$5:$S$114,3,FALSE))
B10: =IF(C10="","ACO"&TEXT(COUNTA($C$5:C10),"000")) | D10: =IF(C10="","",VLOOKUP(C10,'_Données Employés'!$B$5:$S$114,3,FALSE))
B11: =IF(C11="","ACO"&TEXT(COUNTA($C$5:C11),"000")) | D11: =IF(C11="","",VLOOKUP(C11,'_Données Employés'!$B$5:$S$114,3,FALSE))
B12: =IF(C12="","ACO"&TEXT(COUNTA($C$5:C12),"000")) | D12: =IF(C12="","",VLOOKUP(C12,'_Données Employés'!$B$5:$S$114,3,FALSE))
B13: =IF(C13="","ACO"&TEXT(COUNTA($C$5:C13),"000")) | D13: =IF(C13="","",VLOOKUP(C13,'_Données Employés'!$B$5:$S$114,3,FALSE))
B14: =IF(C14="","ACO"&TEXT(COUNTA($C$5:C14),"000")) | D14: =IF(C14="","",VLOOKUP(C14,'_Données Employés'!$B$5:$S$114,3,FALSE))
B15: =IF(C15="","ACO"&TEXT(COUNTA($C$5:C15),"000")) | D15: =IF(C15="","",VLOOKUP(C15,'_Données Employés'!$B$5:$S$114,3,FALSE))
B16: =IF(C16="","ACO"&TEXT(COUNTA($C$5:C16),"000")) | D16: =IF(C16="","",VLOOKUP(C16,'_Données Employés'!$B$5:$S$114,3,FALSE))
B17: =IF(C17="","ACO"&TEXT(COUNTA($C$5:C17),"000")) | D17: =IF(C17="","",VLOOKUP(C17,'_Données Employés'!$B$5:$S$114,3,FALSE))
B18: =IF(C18="","ACO"&TEXT(COUNTA($C$5:C18),"000")) | D18: =IF(C18="","",VLOOKUP(C18,'_Données Employés'!$B$5:$S$114,3,FALSE))
... B104: =IF(C104="","ACO"&TEXT(COUNTA($C$5:C104),"000")) | D104: =IF(C104="","",VLOOKUP(C104,'_Données Employés'!$B$5:$S$114,3,FALSE))
B107: KPI Total accordé (FCFA) | C107: KPI Acomptes en attente
B108: =SUM(F5:F104) | C108: =COUNTIF(I5:I104,"En attente")

Sheet 8-Prets Personnel
B2: PAIE — 8-Prets Personnel
B4: N° | C4: Matricule | D4: Nom Employé | E4: Type Prêt | F4: Montant (FCFA) | G4: Taux Intérêt (%) | H4: Durée (mois) | I4: Mensualité (FCFA) | J4: Total Remboursé (FCFA) | K4: Capital Restant (FCFA) | L4: Statut
B5: PRET-001 | C5: EMP-003 | D5: Fotso Marguerite | E5: Pret logement | F5: 500000 | G5: 2 | H5: 24 | I5: 21540 | J5: 516960 | K5: 483040 | L5: En cours
B6: PRET-002 | C6: EMP-001 | D6: Nganou Clarisse | E6: Pret social | F6: 200000 | G6: 1.5 | H6: 12 | I6: 16928 | J6: 203136 | K6: 196864 | L6: En cours
B7: =IF(C7="","PRET"&TEXT(COUNTA($C$5:C7),"000")) | D7: =IF(C7="","",VLOOKUP(C7,'_Données Employés'!$B$5:$S$114,3,FALSE)) | I7: =IF(OR(F7="",G7=""),"",IFERROR((F7*(1+G7/100*H7/12))/H7,0)) | K7: =IF(F7="","",IFERROR(F7-I7,0))
B8: =IF(C8="","PRET"&TEXT(COUNTA($C$5:C8),"000")) | D8: =IF(C8="","",VLOOKUP(C8,'_Données Employés'!$B$5:$S$114,3,FALSE)) | I8: =IF(OR(F8="",G8=""),"",IFERROR((F8*(1+G8/100*H8/12))/H8,0)) | K8: =IF(F8="","",IFERROR(F8-I8,0))
B9: =IF(C9="","PRET"&TEXT(COUNTA($C$5:C9),"000")) | D9: =IF(C9="","",VLOOKUP(C9,'_Données Employés'!$B$5:$S$114,3,FALSE)) | I9: =IF(OR(F9="",G9=""),"",IFERROR((F9*(1+G9/100*H9/12))/H9,0)) | K9: =IF(F9="","",IFERROR(F9-I9,0))
B10: =IF(C10="","PRET"&TEXT(COUNTA($C$5:C10),"000")) | D10: =IF(C10="","",VLOOKUP(C10,'_Données Employés'!$B$5:$S$114,3,FALSE)) | I10: =IF(OR(F10="",G10=""),"",IFERROR((F10*(1+G10/100*H10/12))/H10,0)) | K10: =IF(F10="","",IFERROR(F10-I10,0))
B11: =IF(C11="","PRET"&TEXT(COUNTA($C$5:C11),"000")) | D11: =IF(C11="","",VLOOKUP(C11,'_Données Employés'!$B$5:$S$114,3,FALSE)) | I11: =IF(OR(F11="",G11=""),"",IFERROR((F11*(1+G11/100*H11/12))/H11,0)) | K11: =IF(F11="","",IFERROR(F11-I11,0))
B12: =IF(C12="","PRET"&TEXT(COUNTA($C$5:C12),"000")) | D12: =IF(C12="","",VLOOKUP(C12,'_Données Employés'!$B$5:$S$114,3,FALSE)) | I12: =IF(OR(F12="",G12=""),"",IFERROR((F12*(1+G12/100*H12/12))/H12,0)) | K12: =IF(F12="","",IFERROR(F12-I12,0))
B13: =IF(C13="","PRET"&TEXT(COUNTA($C$5:C13),"000")) | D13: =IF(C13="","",VLOOKUP(C13,'_Données Employés'!$B$5:$S$114,3,FALSE)) | I13: =IF(OR(F13="",G13=""),"",IFERROR((F13*(1+G13/100*H13/12))/H13,0)) | K13: =IF(F13="","",IFERROR(F13-I13,0))
B14: =IF(C14="","PRET"&TEXT(COUNTA($C$5:C14),"000")) | D14: =IF(C14="","",VLOOKUP(C14,'_Données Employés'!$B$5:$S$114,3,FALSE)) | I14: =IF(OR(F14="",G14=""),"",IFERROR((F14*(1+G14/100*H14/12))/H14,0)) | K14: =IF(F14="","",IFERROR(F14-I14,0))
B15: =IF(C15="","PRET"&TEXT(COUNTA($C$5:C15),"000")) | D15: =IF(C15="","",VLOOKUP(C15,'_Données Employés'!$B$5:$S$114,3,FALSE)) | I15: =IF(OR(F15="",G15=""),"",IFERROR((F15*(1+G15/100*H15/12))/H15,0)) | K15: =IF(F15="","",IFERROR(F15-I15,0))
B16: =IF(C16="","PRET"&TEXT(COUNTA($C$5:C16),"000")) | D16: =IF(C16="","",VLOOKUP(C16,'_Données Employés'!$B$5:$S$114,3,FALSE)) | I16: =IF(OR(F16="",G16=""),"",IFERROR((F16*(1+G16/100*H16/12))/H16,0)) | K16: =IF(F16="","",IFERROR(F16-I16,0))
B17: =IF(C17="","PRET"&TEXT(COUNTA($C$5:C17),"000")) | D17: =IF(C17="","",VLOOKUP(C17,'_Données Employés'!$B$5:$S$114,3,FALSE)) | I17: =IF(OR(F17="",G17=""),"",IFERROR((F17*(1+G17/100*H17/12))/H17,0)) | K17: =IF(F17="","",IFERROR(F17-I17,0))
B18: =IF(C18="","PRET"&TEXT(COUNTA($C$5:C18),"000")) | D18: =IF(C18="","",VLOOKUP(C18,'_Données Employés'!$B$5:$S$114,3,FALSE)) | I18: =IF(OR(F18="",G18=""),"",IFERROR((F18*(1+G18/100*H18/12))/H18,0)) | K18: =IF(F18="","",IFERROR(F18-I18,0))
... B104: =IF(C104="","PRET"&TEXT(COUNTA($C$5:C104),"000")) | D104: =IF(C104="","",VLOOKUP(C104,'_Données Employés'!$B$5:$S$114,3,FALSE)) | I104: =IF(OR(F104="",G104=""),"",IFERROR((F104*(1+G104/100*H104/12))/H104,0)) | K104: =IF(F104="","",IFERROR(F104-I104,0))
B107: KPI Total prêt en cours (FCFA) | C107: KPI Prêts en retard
B108: =SUM(J5:J104) | C108: =COUNTIF(K5:K104,"En retard")

Sheet 9-Historique Paie
B2: PAIE — 9-Historique Paie
B4: N° | C4: Mois | D4: Année | E4: Effectif Payé | F4: Masse Brute (FCFA) | G4: Total Cotisations (FCFA) | H4: Total Déductions (FCFA) | I4: Masse Nette (FCFA) | J4: Coût Employeur (FCFA) | K4: CA Hôtel (FCFA) | L4: Ratio Masse/CA | M4: Statut
B5: HIS-001 | C5: Janvier | D5: 2025 | E5: =IF(C5="","",COUNTIF('2-Calcul des Salaires'!D5:D104,C5)) | F5: =IF(C5="","",SUMIF('2-Calcul des Salaires'!D5:D104,C5,'2-Calcul des Salaires'!J5:J104)) | G5: =IF(C5="","",SUMIF('2-Calcul des Salaires'!D5:D104,C5,'2-Calcul des Salaires'!N5:N104)) | H5: =IF(C5="","",SUMIF('2-Calcul des Salaires'!D5:D104,C5,'2-Calcul des Salaires'!N5:N104)) | I5: =IF(C5="","",SUMIF('2-Calcul des Salaires'!D5:D104,C5,'2-Calcul des Salaires'!O5:O104)) | J5: =IF(C5="","",SUMIF('2-Calcul des Salaires'!D5:D104,C5,'2-Calcul des Salaires'!Q5:Q104)) | K5: 12000000 | M5: Valide
B6: HIS-002 | C6: Fevrier | D6: 2025 | E6: =IF(C6="","",COUNTIF('2-Calcul des Salaires'!D5:D104,C6)) | F6: =IF(C6="","",SUMIF('2-Calcul des Salaires'!D5:D104,C6,'2-Calcul des Salaires'!J5:J104)) | G6: =IF(C6="","",SUMIF('2-Calcul des Salaires'!D5:D104,C6,'2-Calcul des Salaires'!N5:N104)) | H6: =IF(C6="","",SUMIF('2-Calcul des Salaires'!D5:D104,C6,'2-Calcul des Salaires'!N5:N104)) | I6: =IF(C6="","",SUMIF('2-Calcul des Salaires'!D5:D104,C6,'2-Calcul des Salaires'!O5:O104)) | J6: =IF(C6="","",SUMIF('2-Calcul des Salaires'!D5:D104,C6,'2-Calcul des Salaires'!Q5:Q104)) | K6: 11500000 | M6: Valide
B7: HIS-003 | C7: Mars | D7: 2025 | E7: =IF(C7="","",COUNTIF('2-Calcul des Salaires'!D5:D104,C7)) | F7: =IF(C7="","",SUMIF('2-Calcul des Salaires'!D5:D104,C7,'2-Calcul des Salaires'!J5:J104)) | G7: =IF(C7="","",SUMIF('2-Calcul des Salaires'!D5:D104,C7,'2-Calcul des Salaires'!N5:N104)) | H7: =IF(C7="","",SUMIF('2-Calcul des Salaires'!D5:D104,C7,'2-Calcul des Salaires'!N5:N104)) | I7: =IF(C7="","",SUMIF('2-Calcul des Salaires'!D5:D104,C7,'2-Calcul des Salaires'!O5:O104)) | J7: =IF(C7="","",SUMIF('2-Calcul des Salaires'!D5:D104,C7,'2-Calcul des Salaires'!Q5:Q104)) | K7: 12500000 | M7: Valide
B8: =IF(C8="","HIS"&TEXT(COUNTA($C$5:C8),"000")) | E8: =IF(C8="","",COUNTIF('2-Calcul des Salaires'!D5:D104,C8)) | F8: =IF(C8="","",SUMIF('2-Calcul des Salaires'!D5:D104,C8,'2-Calcul des Salaires'!J5:J104)) | G8: =IF(C8="","",SUMIF('2-Calcul des Salaires'!D5:D104,C8,'2-Calcul des Salaires'!N5:N104)) | H8: =IF(C8="","",SUMIF('2-Calcul des Salaires'!D5:D104,C8,'2-Calcul des Salaires'!N5:N104)) | I8: =IF(C8="","",SUMIF('2-Calcul des Salaires'!D5:D104,C8,'2-Calcul des Salaires'!O5:O104)) | J8: =IF(C8="","",SUMIF('2-Calcul des Salaires'!D5:D104,C8,'2-Calcul des Salaires'!Q5:Q104)) | L8: =IF(OR(E8="",K8=""),"",IFERROR(E8/K8,0))
B9: =IF(C9="","HIS"&TEXT(COUNTA($C$5:C9),"000")) | E9: =IF(C9="","",COUNTIF('2-Calcul des Salaires'!D5:D104,C9)) | F9: =IF(C9="","",SUMIF('2-Calcul des Salaires'!D5:D104,C9,'2-Calcul des Salaires'!J5:J104)) | G9: =IF(C9="","",SUMIF('2-Calcul des Salaires'!D5:D104,C9,'2-Calcul des Salaires'!N5:N104)) | H9: =IF(C9="","",SUMIF('2-Calcul des Salaires'!D5:D104,C9,'2-Calcul des Salaires'!N5:N104)) | I9: =IF(C9="","",SUMIF('2-Calcul des Salaires'!D5:D104,C9,'2-Calcul des Salaires'!O5:O104)) | J9: =IF(C9="","",SUMIF('2-Calcul des Salaires'!D5:D104,C9,'2-Calcul des Salaires'!Q5:Q104)) | L9: =IF(OR(E9="",K9=""),"",IFERROR(E9/K9,0))
B10: =IF(C10="","HIS"&TEXT(COUNTA($C$5:C10),"000")) | E10: =IF(C10="","",COUNTIF('2-Calcul des Salaires'!D5:D104,C10)) | F10: =IF(C10="","",SUMIF('2-Calcul des Salaires'!D5:D104,C10,'2-Calcul des Salaires'!J5:J104)) | G10: =IF(C10="","",SUMIF('2-Calcul des Salaires'!D5:D104,C10,'2-Calcul des Salaires'!N5:N104)) | H10: =IF(C10="","",SUMIF('2-Calcul des Salaires'!D5:D104,C10,'2-Calcul des Salaires'!N5:N104)) | I10: =IF(C10="","",SUMIF('2-Calcul des Salaires'!D5:D104,C10,'2-Calcul des Salaires'!O5:O104)) | J10: =IF(C10="","",SUMIF('2-Calcul des Salaires'!D5:D104,C10,'2-Calcul des Salaires'!Q5:Q104)) | L10: =IF(OR(E10="",K10=""),"",IFERROR(E10/K10,0))
B11: =IF(C11="","HIS"&TEXT(COUNTA($C$5:C11),"000")) | E11: =IF(C11="","",COUNTIF('2-Calcul des Salaires'!D5:D104,C11)) | F11: =IF(C11="","",SUMIF('2-Calcul des Salaires'!D5:D104,C11,'2-Calcul des Salaires'!J5:J104)) | G11: =IF(C11="","",SUMIF('2-Calcul des Salaires'!D5:D104,C11,'2-Calcul des Salaires'!N5:N104)) | H11: =IF(C11="","",SUMIF('2-Calcul des Salaires'!D5:D104,C11,'2-Calcul des Salaires'!N5:N104)) | I11: =IF(C11="","",SUMIF('2-Calcul des Salaires'!D5:D104,C11,'2-Calcul des Salaires'!O5:O104)) | J11: =IF(C11="","",SUMIF('2-Calcul des Salaires'!D5:D104,C11,'2-Calcul des Salaires'!Q5:Q104)) | L11: =IF(OR(E11="",K11=""),"",IFERROR(E11/K11,0))
B12: =IF(C12="","HIS"&TEXT(COUNTA($C$5:C12),"000")) | E12: =IF(C12="","",COUNTIF('2-Calcul des Salaires'!D5:D104,C12)) | F12: =IF(C12="","",SUMIF('2-Calcul des Salaires'!D5:D104,C12,'2-Calcul des Salaires'!J5:J104)) | G12: =IF(C12="","",SUMIF('2-Calcul des Salaires'!D5:D104,C12,'2-Calcul des Salaires'!N5:N104)) | H12: =IF(C12="","",SUMIF('2-Calcul des Salaires'!D5:D104,C12,'2-Calcul des Salaires'!N5:N104)) | I12: =IF(C12="","",SUMIF('2-Calcul des Salaires'!D5:D104,C12,'2-Calcul des Salaires'!O5:O104)) | J12: =IF(C12="","",SUMIF('2-Calcul des Salaires'!D5:D104,C12,'2-Calcul des Salaires'!Q5:Q104)) | L12: =IF(OR(E12="",K12=""),"",IFERROR(E12/K12,0))
B13: =IF(C13="","HIS"&TEXT(COUNTA($C$5:C13),"000")) | E13: =IF(C13="","",COUNTIF('2-Calcul des Salaires'!D5:D104,C13)) | F13: =IF(C13="","",SUMIF('2-Calcul des Salaires'!D5:D104,C13,'2-Calcul des Salaires'!J5:J104)) | G13: =IF(C13="","",SUMIF('2-Calcul des Salaires'!D5:D104,C13,'2-Calcul des Salaires'!N5:N104)) | H13: =IF(C13="","",SUMIF('2-Calcul des Salaires'!D5:D104,C13,'2-Calcul des Salaires'!N5:N104)) | I13: =IF(C13="","",SUMIF('2-Calcul des Salaires'!D5:D104,C13,'2-Calcul des Salaires'!O5:O104)) | J13: =IF(C13="","",SUMIF('2-Calcul des Salaires'!D5:D104,C13,'2-Calcul des Salaires'!Q5:Q104)) | L13: =IF(OR(E13="",K13=""),"",IFERROR(E13/K13,0))
