Workbook

Sheet _Données Employés
B4: Matricule | C4: Civilité | D4: Nom | E4: Prénom | F4: Département | G4: Poste | H4: Salaire Base (FCFA)
B5: EMP-001 | C5: M. | D5: Nganou | E5: Clarisse | F5: Cuisine & Restauration | G5: Chef cuisinier | H5: 450000
B6: EMP-002 | C6: M. | D6: Tchinda | E6: Armand | F6: Réception & Front Office | G6: Réceptionniste | H6: 220000
B7: EMP-003 | C7: Mme | D7: Fotso | E7: Marguerite | F7: Finance & Comptabilité | G7: Comptable senior | H7: 380000
B8: EMP-004 | C8: M. | D8: Nkoulou | E8: Mbarga | F8: Étage & Housekeeping | G8: Gouvernant | H8: 195000
B9: EMP-005 | C9: M. | D9: Kamga | E9: Paul | F9: Maintenance | G9: Technicien maintenance | H9: 165000
B10: EMP-006 | C10: Mme | D10: Ngo | E10: Delphine | F10: Service Client | G10: Conseiller clientèle | H10: 160000
B11: EMP-007 | C11: M. | D11: Essomba | E11: Serge | F11: Maintenance | G11: Agent entretien | H11: 130000
B12: EMP-008 | C12: M. | D12: Tchouankou | E12: Paul | F12: Commercial | G12: Commercial | H12: 150000
B13: EMP-009 | C13: M. | D13: Fokam | E13: Eric | F13: Maintenance | G13: Technicien | H13: 140000
B14: EMP-010 | C14: M. | D14: Tagne | E14: René | F14: Cuisine & Restauration | G14: Plongeur | H14: 90000
B15: EMP-011 | C15: M. | D15: Bouba | E15: Ahmed | F15: Sécurité | G15: Agent Sécurité | H15: 120000
B16: EMP-012 | C16: Mme | D16: Awa | E16: Fatou | F16: Réception & Front Office | G16: Standardiste | H16: 155000
... B18: EMP-029 | C18: M. | D18: Kamga | E18: Patrice | F18: Sécurité | G18: Chef Sécurité | H18: 210000

Sheet 1-Tableau de Bord
B2: DOMAINE 6 — FORMATION, DEVELOPPEMENT & COMPETENCES
B3: TABLEAU DE BORD — Vue synthetique de tous les indicateurs du domaine (mis a jour automatiquement)
B5: Actions PAF | E5: Heures formation (h) | H5: Cout prevu (FCFA) | K5: Besoins identifies
B6: =COUNTIF('2-Plan Annuel Formation (PAF)'!B5:B104,"<>") | E6: =SUM('2-Plan Annuel Formation (PAF)'!I5:I104) | H6: =SUM('2-Plan Annuel Formation (PAF)'!L5:L104) | K6: =COUNTIF('3-Besoins en Formation'!B5:B104,"<>")
B9: Inscriptions | E9: Cout reel inscriptions | H9: Presences formation | K9: Taux presence (%)
B10: =COUNTIF('4-Inscriptions Formation'!B5:B104,"<>") | E10: =SUM('4-Inscriptions Formation'!I5:I104) | H10: =COUNTIF('5-Presence Formation'!B5:B104,"<>") | K10: =IFERROR(COUNTIF('5-Presence Formation'!I5:I104,"Present")/COUNTA('5-Presence Formation'!I5:I104),0)
B13: Eval a chaud (nb) | E13: Score chaud moyen | H13: Eval a froid (nb) | K13: Score froid moyen
B14: =COUNTIF('6-Evaluation a Chaud'!B5:B104,"<>") | E14: =IFERROR(AVERAGE('6-Evaluation a Chaud'!J5:J104),0) | H14: =COUNTIF('7-Evaluation a Froid'!B5:B104,"<>") | K14: =IFERROR(AVERAGE('7-Evaluation a Froid'!I5:I104),0)
B17: Budget alloue (FCFA) | E17: Cout reel (FCFA) | H17: PID suivis | K17: Certifications
B18: =SUM('8-Budget Formation'!F5:F104) | E18: =SUM('8-Budget Formation'!G5:G104) | H18: =COUNTIF('12-Plan Individuel Dev.'!B5:B104,"<>") | K18: =COUNTIF('15-Certifications & Qualif.'!B5:B104,"<>")
B22: FORMATION PAR DEPARTEMENT & PAR TYPE
B23: Service | C23: Heures (h)
B24: RH | C24: =SUMIF('14-Bilan Competences par Dept'!C5:C104,"*RH*",'14-Bilan Competences par Dept'!F5:F104)
B25: Informatique | C25: =SUMIF('14-Bilan Competences par Dept'!C5:C104,"*Informatique*",'14-Bilan Competences par Dept'!F5:F104)
B26: Finance | C26: =SUMIF('14-Bilan Competences par Dept'!C5:C104,"*Finance*",'14-Bilan Competences par Dept'!F5:F104)
B27: Reception | C27: =SUMIF('14-Bilan Competences par Dept'!C5:C104,"*Reception*",'14-Bilan Competences par Dept'!F5:F104)
B28: Cuisine | C28: =SUMIF('14-Bilan Competences par Dept'!C5:C104,"*Cuisine*",'14-Bilan Competences par Dept'!F5:F104)
B29: Entretien | C29: =SUMIF('14-Bilan Competences par Dept'!C5:C104,"*Entretien*",'14-Bilan Competences par Dept'!F5:F104)
B30: Sécurité | C30: =SUMIF('14-Bilan Competences par Dept'!C5:C104,"*Securite*",'14-Bilan Competences par Dept'!F5:F104)
B31: SC | C31: =SUMIF('14-Bilan Competences par Dept'!C5:C104,"*Service Client*",'14-Bilan Competences par Dept'!F5:F104)
H33: Type Formation | I33: Nb Actions
H34: Technique metier | I34: =COUNTIF('2-Plan Annuel Formation (PAF)'!D5:D104,"*technique*")
H35: Langue | I35: =COUNTIF('2-Plan Annuel Formation (PAF)'!D5:D104,"*langue*")
H36: Informatique | I36: =COUNTIF('2-Plan Annuel Formation (PAF)'!D5:D104,"*informatique*")
H37: Service client | I37: =COUNTIF('2-Plan Annuel Formation (PAF)'!D5:D104,"*accueil*")
H38: Securite & HACCP | I38: =COUNTIF('2-Plan Annuel Formation (PAF)'!D5:D104,"*securite*")+COUNTIF('2-Plan Annuel Formation (PAF)'!D5:D104,"*HACCP*")
H39: Management | I39: =COUNTIF('2-Plan Annuel Formation (PAF)'!D5:D104,"*management*")
H40: Hygiene securite | I40: =COUNTIF('2-Plan Annuel Formation (PAF)'!D5:D104,"*hygiene*")
H41: Autre | I41: =COUNTIF('2-Plan Annuel Formation (PAF)'!B5:B104,"<>")-SUM(H34:H40)

Sheet _Lists
B1: departement | C1: poste_hotel | D1: type_formation | E1: modalite_formation | F1: niveau_competence | G1: statut_formation | H1: statut_evaluation | I1: statut_besoin | J1: statut_budget | K1: statut_pid | L1: source_formation | M1: type_formateur | N1: priorite_formation | O1: mois | P1: annee | Q1: statut_rapport | R1: jour_semaine | S1: appreciation | T1: statut_convention
B2: Direction Générale | C2: DG | D2: Formation technique metier | E2: Presentiel interne | F2: Debutant | G2: Planifiee | H2: Non realisee | I2: Identifie | J2: Provisionne | K2: En elaboration | L2: Entretien annuel | M2: Formateur interne | N2: Haute | O2: Janvier | P2: 2024 | Q2: Brouillon | R2: Oui | S2: Excellent | T2: En vigueur
B3: Service Client | C3: DRH | D3: Formation securite & HACCP | E3: Presentiel externe | F3: Intermediaire | G3: En cours | H3: En cours | I3: Priorise | J3: Consomme partiel | K3: Valide par N+1 | L3: Demande employe | M3: Formateur externe | N3: Moyenne | O3: Fevrier | P3: 2025 | Q3: Valide | R3: Non | S3: Tres satisfaisant | T3: Echu
B4: Finance & Comptabilité | C4: Assistante RH | D4: Formation langue etrangere | E4: En ligne (e-learning) | F4: Avance | G4: Terminee | H4: Completee | I4: Planifie | J4: Consomme total | K4: En cours de realisation | L4: Audit interne | M4: Consultant | N4: Basse | O4: Mars | P4: 2026 | Q4: Approuve | S4: Satisfaisant | T4: En negociation
B5: Marketing & Communication | C5: DAF | D5: Formation management & leadership | E5: Mixte (blended learning) | F5: Expert | G5: Annulee | H5: Non applicable | I5: En cours | J5: Depasse | K5: Bilan realise | L5: Plan strategique hotel | M5: Enseignant | N5: Urgente | O5: Avril | Q5: Rejete | S5: Insuffisant | T5: Resilie
B6: Maintenance | C6: Comptable senior | D6: Formation informatique & bureautique | E6: Sur le tas (coaching) | F6: Non evalue | G6: Reportee | I6: Satisfait | J6: Non utilise | K6: Archive | L6: Non conformite detectee | M6: Coach interne | O6: Mai | S6: Non satisfaisant | T6: Suspendu
B7: Commercial | C7: Chef Comptable | D7: Formation accueil & service client | E7: Conference / seminaire | G7: En attente | I7: Non satisfait | L7: Evolution reglementaire | M7: Expert metier | O7: Juin | T7: Renouvele
B8: Logistique & Approvisionnement | C8: Chef Marketing | D8: Formation developpement personnel | E8: Stage pratique | L8: Incident / accident | O8: Juillet
B9: Cuisine & Restauration | C9: Chef de service IT | D9: Formation hygiene & securite | E9: Formation action | L9: Initiative DRH | O9: Aout
B10: Réception & Front Office | C10: Technicien IT | D10: Formation reglementation travail | O10: Septembre
B11: Sécurité | C11: Chef Commercial | D11: Formation certificative / diplome | O11: Octobre
B12: Étage & Housekeeping | C12: Agent Commercial | O12: Novembre
C13: Chef Logistique | O13: Decembre
C14: Magasinier
C15: Chef Reception
C16: Receptionniste
C17: Concierge
C18: Chef Cuisine
C19: Sous-Chef
C20: Cuisinier
C21: Plongeur
C22: Chef Entretien
C23: Agent Entretien
C24: Chef Securite
C25: Agent Securite

Sheet 2-Plan Annuel Formation (PAF)
B2: PLAN ANNUEL DE FORMATION - PAF (#64)
B3: TABLEAU DYNAMIQUE — Saisissez dans la prochaine ligne jaune. Les calculs se mettent a jour automatiquement.
B4: N° Action | C4: Theme Formation | D4: Type Formation | E4: Departement Cible | F4: Nb Participants Prevu | G4: Date Debut | H4: Date Fin | I4: Duree (h) | J4: Formateur | K4: Lieu | L4: Cout Prevu (FCFA) | M4: Statut
B5: PAF-001 | C5: HACCP & Hygiene alimentaire | D5: Formation securite & HACCP | E5: Cuisine & Restauration | F5: 8 | G5: 45726 | H5: 45730 | I5: 20 | J5: Dr. Ngassa (CNPS) | K5: Salle conference A | L5: 250000 | M5: Terminee
B6: PAF-002 | C6: Anglais hotellerie niveau 2 | D6: Formation langue etrangere | E6: Réception & Front Office | F6: 6 | G6: 45754 | H6: 45772 | I6: 30 | J6: British Council | K6: En ligne | L6: 180000 | M6: Terminee
B7: PAF-003 | C7: Gestion des conflits clients | D7: Formation accueil & service client | E7: Service Client | F7: 5 | G7: 45810 | H7: 45812 | I7: 12 | J7: Coach Kamga | K7: Salle formation | L7: 96000 | M7: En cours
B8: PAF-004 | C8: Excel avance & tableaux croises | D8: Formation informatique & bureautique | E8: Finance & Comptabilité | F8: 4 | G8: 45852 | H8: 45854 | I8: 15 | J8: Formateur interne IT | K8: Salle info | L8: 45000 | M8: Planifiee
B9: PAF-005 | C9: Securite incendie & evacuation | D9: Formation hygiene & securite | E9: Tous | F9: 30 | G9: 45901 | H9: 45901 | I9: 4 | J9: Sapeurs-pompiers Douala | K9: Terrain hotel | L9: 150000 | M9: Planifiee
B10: =IF(C10="","PAF-"&TEXT(COUNTA($C$5:C10),"000")) | I10: =IF(G10="","",(H10-G10)*8)
B11: =IF(C11="","PAF-"&TEXT(COUNTA($C$5:C11),"000")) | I11: =IF(G11="","",(H11-G11)*8)
B12: =IF(C12="","PAF-"&TEXT(COUNTA($C$5:C12),"000")) | I12: =IF(G12="","",(H12-G12)*8)
B13: =IF(C13="","PAF-"&TEXT(COUNTA($C$5:C13),"000")) | I13: =IF(G13="","",(H13-G13)*8)
B14: =IF(C14="","PAF-"&TEXT(COUNTA($C$5:C14),"000")) | I14: =IF(G14="","",(H14-G14)*8)
B15: =IF(C15="","PAF-"&TEXT(COUNTA($C$5:C15),"000")) | I15: =IF(G15="","",(H15-G15)*8)
B16: =IF(C16="","PAF-"&TEXT(COUNTA($C$5:C16),"000")) | I16: =IF(G16="","",(H16-G16)*8)
B17: =IF(C17="","PAF-"&TEXT(COUNTA($C$5:C17),"000")) | I17: =IF(G17="","",(H17-G17)*8)
B18: =IF(C18="","PAF-"&TEXT(COUNTA($C$5:C18),"000")) | I18: =IF(G18="","",(H18-G18)*8)
B19: =IF(C19="","PAF-"&TEXT(COUNTA($C$5:C19),"000")) | I19: =IF(G19="","",(H19-G19)*8)
B20: =IF(C20="","PAF-"&TEXT(COUNTA($C$5:C20),"000")) | I20: =IF(G20="","",(H20-G20)*8)
B21: =IF(C21="","PAF-"&TEXT(COUNTA($C$5:C21),"000")) | I21: =IF(G21="","",(H21-G21)*8)
... B109: =IF(C109="","PAF-"&TEXT(COUNTA($C$5:C109),"000")) | I109: =IF(G109="","",(H109-G109)*8)
B111: TOTAL | F111: =SUM(F5:F104) | I111: =SUM(I5:I104) | L111: =SUM(L5:L104)
B113: INDICATEURS (mis a jour automatiquement)
B114: Actions planifiees | D114: Total heures (h) | F114: Cout total prevu (FCFA) | H114: En cours
B115: =COUNTIF(B5:B104,"<>") | D115: =SUM(I5:I104) | F115: =SUM(L5:L104) | H115: =COUNTIF(M5:M104,"En cours")

Sheet 3-Besoins en Formation
B2: IDENTIFICATION DES BESOINS EN FORMATION (#65)
B3: TABLEAU DYNAMIQUE — Saisissez dans la prochaine ligne jaune. Les calculs se mettent a jour automatiquement.
B4: N° Besoin | C4: Departement | D4: Poste Concerne | E4: Theme Souhaite | F4: Source Identification | G4: Priorite | H4: Nb Beneficiaires | I4: Date Souhaite | J4: Cout Estime (FCFA) | K4: Action PAF Liee | L4: Statut
B5: BF-001 | C5: Cuisine & Restauration | D5: Cuisinier | E5: Techniques de cuisson avancees | F5: Audit interne | G5: Haute | H5: 4 | I5: 45870 | J5: 120000 | K5: PAF-006 | L5: Planifie
B6: BF-002 | C6: Réception & Front Office | D6: Receptionniste | E6: Gestion PMS Opera | F6: Entretien annuel | G6: Haute | H6: 6 | I6: 45839 | J6: 200000 | K6: PAF-004 | L6: Priorise
B7: BF-003 | C7: Service Client | D7: Conseiller | E7: Techniques de vente croisee | F7: Plan strategique hotel | G7: Moyenne | H7: 5 | I7: 45931 | J7: 75000 | K7: PAF-007 | L7: Identifie
B8: BF-004 | C8: Sécurité | D8: Agent Securite | E8: Gestion des acces & CCTV | F8: Non conformite detectee | G8: Urgente | H8: 4 | I8: 45823 | J8: 50000 | K8: PAF-008 | L8: En cours
B9: BF-005 | C9: Maintenance | D9: Agent Entretien | E9: Climatisation & CVC | F9: Demande employe | G9: Moyenne | H9: 3 | I9: 45915 | J9: 90000 | L9: Identifie
B10: =IF(C10="","BF-"&TEXT(COUNTA($C$5:C10),"000"))
B11: =IF(C11="","BF-"&TEXT(COUNTA($C$5:C11),"000"))
B12: =IF(C12="","BF-"&TEXT(COUNTA($C$5:C12),"000"))
B13: =IF(C13="","BF-"&TEXT(COUNTA($C$5:C13),"000"))
B14: =IF(C14="","BF-"&TEXT(COUNTA($C$5:C14),"000"))
B15: =IF(C15="","BF-"&TEXT(COUNTA($C$5:C15),"000"))
B16: =IF(C16="","BF-"&TEXT(COUNTA($C$5:C16),"000"))
B17: =IF(C17="","BF-"&TEXT(COUNTA($C$5:C17),"000"))
B18: =IF(C18="","BF-"&TEXT(COUNTA($C$5:C18),"000"))
B19: =IF(C19="","BF-"&TEXT(COUNTA($C$5:C19),"000"))
B20: =IF(C20="","BF-"&TEXT(COUNTA($C$5:C20),"000"))
B21: =IF(C21="","BF-"&TEXT(COUNTA($C$5:C21),"000"))
... B109: =IF(C109="","BF-"&TEXT(COUNTA($C$5:C109),"000"))
B111: TOTAL | H111: =SUM(H5:H104) | J111: =SUM(J5:J104)
B113: INDICATEURS (mis a jour automatiquement)
B114: Total besoins | D114: Haute priorite | F114: Cout total estime (FCFA) | H114: Satisfaits
B115: =COUNTIF(B5:B104,"<>") | D115: =COUNTIF(G5:G104,"Haute") | F115: =SUM(J5:J104) | H115: =COUNTIF(L5:L104,"Satisfait")

Sheet 4-Inscriptions Formation
B2: FICHE D'INSCRIPTION A UNE FORMATION (#66)
B3: TABLEAU DYNAMIQUE — Saisissez dans la prochaine ligne jaune. Les calculs se mettent a jour automatiquement.
B4: N° Inscription | C4: Matricule | D4: Nom Employe | E4: Departement | F4: Poste | G4: Action Formation | H4: Date Inscription | I4: Cout Indiv. (FCFA) | J4: Statut
B5: INS-001 | C5: EMP-010 | D5: =IF(C5="","",VLOOKUP(C5,'_Données Employés'!$B$5:$H$18,4,FALSE)&" "&VLOOKUP(C5,'_Données Employés'!$B$5:$H$18,5,FALSE)) | E5: =IF(C5="","",VLOOKUP(C5,'_Données Employés'!$B$5:$H$18,6,FALSE)) | F5: =IF(C5="","",VLOOKUP(C5,'_Données Employés'!$B$5:$H$18,7,FALSE)) | G5: PAF-001 | H5: 45721 | I5: 31250 | J5: Terminee
B6: INS-002 | C6: EMP-004 | D6: =IF(C6="","",VLOOKUP(C6,'_Données Employés'!$B$5:$H$18,4,FALSE)&" "&VLOOKUP(C6,'_Données Employés'!$B$5:$H$18,5,FALSE)) | E6: =IF(C6="","",VLOOKUP(C6,'_Données Employés'!$B$5:$H$18,6,FALSE)) | F6: =IF(C6="","",VLOOKUP(C6,'_Données Employés'!$B$5:$H$18,7,FALSE)) | G6: PAF-002 | H6: 45748 | I6: 30000 | J6: Terminee
B7: INS-003 | C7: EMP-006 | D7: =IF(C7="","",VLOOKUP(C7,'_Données Employés'!$B$5:$H$18,4,FALSE)&" "&VLOOKUP(C7,'_Données Employés'!$B$5:$H$18,5,FALSE)) | E7: =IF(C7="","",VLOOKUP(C7,'_Données Employés'!$B$5:$H$18,6,FALSE)) | F7: =IF(C7="","",VLOOKUP(C7,'_Données Employés'!$B$5:$H$18,7,FALSE)) | G7: PAF-003 | H7: 45805 | I7: 19200 | J7: En cours
B8: INS-004 | C8: EMP-003 | D8: =IF(C8="","",VLOOKUP(C8,'_Données Employés'!$B$5:$H$18,4,FALSE)&" "&VLOOKUP(C8,'_Données Employés'!$B$5:$H$18,5,FALSE)) | E8: =IF(C8="","",VLOOKUP(C8,'_Données Employés'!$B$5:$H$18,6,FALSE)) | F8: =IF(C8="","",VLOOKUP(C8,'_Données Employés'!$B$5:$H$18,7,FALSE)) | G8: PAF-004 | H8: 45839 | I8: 11250 | J8: Planifiee
B9: INS-005 | C9: EMP-001 | D9: =IF(C9="","",VLOOKUP(C9,'_Données Employés'!$B$5:$H$18,4,FALSE)&" "&VLOOKUP(C9,'_Données Employés'!$B$5:$H$18,5,FALSE)) | E9: =IF(C9="","",VLOOKUP(C9,'_Données Employés'!$B$5:$H$18,6,FALSE)) | F9: =IF(C9="","",VLOOKUP(C9,'_Données Employés'!$B$5:$H$18,7,FALSE)) | G9: PAF-005 | H9: 45894 | I9: 5000 | J9: Planifiee
B10: =IF(C10="","INS-"&TEXT(COUNTA($C$5:C10),"000"))
B11: =IF(C11="","INS-"&TEXT(COUNTA($C$5:C11),"000"))
B12: =IF(C12="","INS-"&TEXT(COUNTA($C$5:C12),"000"))
B13: =IF(C13="","INS-"&TEXT(COUNTA($C$5:C13),"000"))
B14: =IF(C14="","INS-"&TEXT(COUNTA($C$5:C14),"000"))
B15: =IF(C15="","INS-"&TEXT(COUNTA($C$5:C15),"000"))
B16: =IF(C16="","INS-"&TEXT(COUNTA($C$5:C16),"000"))
B17: =IF(C17="","INS-"&TEXT(COUNTA($C$5:C17),"000"))
B18: =IF(C18="","INS-"&TEXT(COUNTA($C$5:C18),"000"))
B19: =IF(C19="","INS-"&TEXT(COUNTA($C$5:C19),"000"))
B20: =IF(C20="","INS-"&TEXT(COUNTA($C$5:C20),"000"))
B21: =IF(C21="","INS-"&TEXT(COUNTA($C$5:C21),"000"))
... B109: =IF(C109="","INS-"&TEXT(COUNTA($C$5:C109),"000"))
B111: TOTAL | I111: =SUM(I5:I104)
B113: INDICATEURS (mis a jour automatiquement)
B114: Inscriptions | D114: Cout total (FCFA) | F114: En cours | H114: Terminees
B115: =COUNTIF(B5:B104,"<>") | D115: =SUM(I5:I104) | F115: =COUNTIF(J5:J104,"En cours") | H115: =COUNTIF(J5:J104,"Terminee")

Sheet 5-Presence Formation
B2: FEUILLE DE PRESENCE EN FORMATION (#67)
B3: TABLEAU DYNAMIQUE — Saisissez dans la prochaine ligne jaune. Les calculs se mettent a jour automatiquement.
B4: N° | C4: Action Formation | D4: Matricule | E4: Nom Employe | F4: Departement | G4: Date Session | H4: Heure Arrivee | I4: Presence
B5: PRES-001 | C5: PAF-001 | D5: EMP-010 | E5: =IF(D5="","",VLOOKUP(D5,'_Données Employés'!$B$5:$H$18,4,FALSE)&" "&VLOOKUP(D5,'_Données Employés'!$B$5:$H$18,5,FALSE)) | F5: =IF(D5="","",VLOOKUP(D5,'_Données Employés'!$B$5:$H$18,6,FALSE)) | G5: 45726 | H5: 08h00 | I5: Present
B6: PRES-002 | C6: PAF-001 | D6: EMP-001 | E6: =IF(D6="","",VLOOKUP(D6,'_Données Employés'!$B$5:$H$18,4,FALSE)&" "&VLOOKUP(D6,'_Données Employés'!$B$5:$H$18,5,FALSE)) | F6: =IF(D6="","",VLOOKUP(D6,'_Données Employés'!$B$5:$H$18,6,FALSE)) | G6: 45726 | H6: 08h05 | I6: Present
B7: PRES-003 | C7: PAF-001 | D7: EMP-011 | E7: =IF(D7="","",VLOOKUP(D7,'_Données Employés'!$B$5:$H$18,4,FALSE)&" "&VLOOKUP(D7,'_Données Employés'!$B$5:$H$18,5,FALSE)) | F7: =IF(D7="","",VLOOKUP(D7,'_Données Employés'!$B$5:$H$18,6,FALSE)) | G7: 45726 | I7: Absent
B8: PRES-004 | C8: PAF-002 | D8: EMP-004 | E8: =IF(D8="","",VLOOKUP(D8,'_Données Employés'!$B$5:$H$18,4,FALSE)&" "&VLOOKUP(D8,'_Données Employés'!$B$5:$H$18,5,FALSE)) | F8: =IF(D8="","",VLOOKUP(D8,'_Données Employés'!$B$5:$H$18,6,FALSE)) | G8: 45754 | H8: 09h00 | I8: Present
B9: PRES-005 | C9: PAF-003 | D9: EMP-006 | E9: =IF(D9="","",VLOOKUP(D9,'_Données Employés'!$B$5:$H$18,4,FALSE)&" "&VLOOKUP(D9,'_Données Employés'!$B$5:$H$18,5,FALSE)) | F9: =IF(D9="","",VLOOKUP(D9,'_Données Employés'!$B$5:$H$18,6,FALSE)) | G9: 45810 | H9: 08h10 | I9: Retard
B10: =IF(C10="","PRES-"&TEXT(COUNTA($C$5:C10),"000"))
B11: =IF(C11="","PRES-"&TEXT(COUNTA($C$5:C11),"000"))
B12: =IF(C12="","PRES-"&TEXT(COUNTA($C$5:C12),"000"))
B13: =IF(C13="","PRES-"&TEXT(COUNTA($C$5:C13),"000"))
B14: =IF(C14="","PRES-"&TEXT(COUNTA($C$5:C14),"000"))
B15: =IF(C15="","PRES-"&TEXT(COUNTA($C$5:C15),"000"))
B16: =IF(C16="","PRES-"&TEXT(COUNTA($C$5:C16),"000"))
B17: =IF(C17="","PRES-"&TEXT(COUNTA($C$5:C17),"000"))
B18: =IF(C18="","PRES-"&TEXT(COUNTA($C$5:C18),"000"))
B19: =IF(C19="","PRES-"&TEXT(COUNTA($C$5:C19),"000"))
B20: =IF(C20="","PRES-"&TEXT(COUNTA($C$5:C20),"000"))
B21: =IF(C21="","PRES-"&TEXT(COUNTA($C$5:C21),"000"))
... B109: =IF(C109="","PRES-"&TEXT(COUNTA($C$5:C109),"000"))
B111: INDICATEURS (mis a jour automatiquement)
B112: Entrees saisies | D112: Presents | F112: Absents | H112: Retards
B113: =COUNTIF(B5:B104,"<>") | D113: =COUNTIF(I5:I104,"Present") | F113: =COUNTIF(I5:I104,"Absent") | H113: =COUNTIF(I5:I104,"Retard")

Sheet 6-Evaluation a Chaud
B2: EVALUATION A CHAUD POST-FORMATION (#68)
B3: TABLEAU DYNAMIQUE — Saisissez dans la prochaine ligne jaune. Les calculs se mettent a jour automatiquement.
B4: N° Eval | C4: Action Formation | D4: Matricule | E4: Nom Employe | F4: Date Formation | G4: Score Contenu (/5) | H4: Score Formateur (/5) | I4: Score Support (/5) | J4: Score General (/5) | K4: Appreciation
B5: EC-001 | C5: PAF-001 | D5: EMP-010 | E5: =IF(D5="","",VLOOKUP(D5,'_Données Employés'!$B$5:$H$18,4,FALSE)&" "&VLOOKUP(D5,'_Données Employés'!$B$5:$H$18,5,FALSE)) | F5: 45730 | G5: 4 | H5: 5 | I5: 3 | J5: 4 | K5: Tres satisfaisant
B6: EC-002 | C6: PAF-001 | D6: EMP-001 | E6: =IF(D6="","",VLOOKUP(D6,'_Données Employés'!$B$5:$H$18,4,FALSE)&" "&VLOOKUP(D6,'_Données Employés'!$B$5:$H$18,5,FALSE)) | F6: 45730 | G6: 5 | H6: 4 | I6: 4 | J6: 4.3 | K6: Excellent
B7: EC-003 | C7: PAF-002 | D7: EMP-004 | E7: =IF(D7="","",VLOOKUP(D7,'_Données Employés'!$B$5:$H$18,4,FALSE)&" "&VLOOKUP(D7,'_Données Employés'!$B$5:$H$18,5,FALSE)) | F7: 45772 | G7: 3 | H7: 4 | I7: 5 | J7: 4 | K7: Satisfaisant
B8: EC-004 | C8: PAF-002 | D8: EMP-012 | E8: =IF(D8="","",VLOOKUP(D8,'_Données Employés'!$B$5:$H$18,4,FALSE)&" "&VLOOKUP(D8,'_Données Employés'!$B$5:$H$18,5,FALSE)) | F8: 45772 | G8: 4 | H8: 3 | I8: 4 | J8: 3.7 | K8: Satisfaisant
B9: EC-005 | C9: PAF-003 | D9: EMP-006 | E9: =IF(D9="","",VLOOKUP(D9,'_Données Employés'!$B$5:$H$18,4,FALSE)&" "&VLOOKUP(D9,'_Données Employés'!$B$5:$H$18,5,FALSE)) | F9: 45812 | G9: 5 | H9: 5 | I9: 4 | J9: 4.7 | K9: Excellent
B10: =IF(C10="","EC-"&TEXT(COUNTA($C$5:C10),"000")) | J10: =IF(G10="","",IF((G10+H10+I10)=0,"",ROUND((G10+H10+I10)/3,1)))
B11: =IF(C11="","EC-"&TEXT(COUNTA($C$5:C11),"000")) | J11: =IF(G11="","",IF((G11+H11+I11)=0,"",ROUND((G11+H11+I11)/3,1)))
B12: =IF(C12="","EC-"&TEXT(COUNTA($C$5:C12),"000")) | J12: =IF(G12="","",IF((G12+H12+I12)=0,"",ROUND((G12+H12+I12)/3,1)))
B13: =IF(C13="","EC-"&TEXT(COUNTA($C$5:C13),"000")) | J13: =IF(G13="","",IF((G13+H13+I13)=0,"",ROUND((G13+H13+I13)/3,1)))
B14: =IF(C14="","EC-"&TEXT(COUNTA($C$5:C14),"000")) | J14: =IF(G14="","",IF((G14+H14+I14)=0,"",ROUND((G14+H14+I14)/3,1)))
B15: =IF(C15="","EC-"&TEXT(COUNTA($C$5:C15),"000")) | J15: =IF(G15="","",IF((G15+H15+I15)=0,"",ROUND((G15+H15+I15)/3,1)))
B16: =IF(C16="","EC-"&TEXT(COUNTA($C$5:C16),"000")) | J16: =IF(G16="","",IF((G16+H16+I16)=0,"",ROUND((G16+H16+I16)/3,1)))
B17: =IF(C17="","EC-"&TEXT(COUNTA($C$5:C17),"000")) | J17: =IF(G17="","",IF((G17+H17+I17)=0,"",ROUND((G17+H17+I17)/3,1)))
B18: =IF(C18="","EC-"&TEXT(COUNTA($C$5:C18),"000")) | J18: =IF(G18="","",IF((G18+H18+I18)=0,"",ROUND((G18+H18+I18)/3,1)))
B19: =IF(C19="","EC-"&TEXT(COUNTA($C$5:C19),"000")) | J19: =IF(G19="","",IF((G19+H19+I19)=0,"",ROUND((G19+H19+I19)/3,1)))
B20: =IF(C20="","EC-"&TEXT(COUNTA($C$5:C20),"000")) | J20: =IF(G20="","",IF((G20+H20+I20)=0,"",ROUND((G20+H20+I20)/3,1)))
B21: =IF(C21="","EC-"&TEXT(COUNTA($C$5:C21),"000")) | J21: =IF(G21="","",IF((G21+H21+I21)=0,"",ROUND((G21+H21+I21)/3,1)))
... B109: =IF(C109="","EC-"&TEXT(COUNTA($C$5:C109),"000")) | J109: =IF(G109="","",IF((G109+H109+I109)=0,"",ROUND((G109+H109+I109)/3,1)))
B111: INDICATEURS (mis a jour automatiquement)
B112: Evaluations | D112: Score moyen general | F112: Score max | H112: Score min
B113: =COUNTIF(B5:B104,"<>") | D113: =IFERROR(AVERAGE(J5:J104),0) | F113: =IFERROR(MAX(J5:J104),0) | H113: =IFERROR(MIN(J5:J104),0)

Sheet 7-Evaluation a Froid
B2: EVALUATION A FROID (3-6 MOIS APRES FORMATION) (#69)
B3: TABLEAU DYNAMIQUE — Saisissez dans la prochaine ligne jaune. Les calculs se mettent a jour automatiquement.
B4: N° Eval | C4: Action Formation | D4: Matricule | E4: Nom Employe | F4: Date Formation | G4: Date Eval Froid | H4: Delai (mois) | I4: Application (/5) | J4: Impact Mesurable
B5: EF-001 | C5: PAF-001 | D5: EMP-010 | E5: =IF(D5="","",VLOOKUP(D5,'_Données Employés'!$B$5:$H$18,4,FALSE)&" "&VLOOKUP(D5,'_Données Employés'!$B$5:$H$18,5,FALSE)) | F5: 45730 | G5: 45822 | H5: 3 | I5: 4 | J5: Reduction pertes alimentaires -15%
B6: EF-002 | C6: PAF-001 | D6: EMP-001 | E6: =IF(D6="","",VLOOKUP(D6,'_Données Employés'!$B$5:$H$18,4,FALSE)&" "&VLOOKUP(D6,'_Données Employés'!$B$5:$H$18,5,FALSE)) | F6: 45730 | G6: 45822 | H6: 3 | I6: 5 | J6: 0 non conformite HACCP depuis formation
B7: EF-003 | C7: PAF-002 | D7: EMP-004 | E7: =IF(D7="","",VLOOKUP(D7,'_Données Employés'!$B$5:$H$18,4,FALSE)&" "&VLOOKUP(D7,'_Données Employés'!$B$5:$H$18,5,FALSE)) | F7: 45772 | G7: 45863 | H7: 3 | I7: 3 | J7: Meilleure gestion reservations en anglais
B8: =IF(C8="","EF-"&TEXT(COUNTA($C$5:C8),"000")) | H8: =IF(F8="","",ROUND((G8-F8)/30.44,0))
B9: =IF(C9="","EF-"&TEXT(COUNTA($C$5:C9),"000")) | H9: =IF(F9="","",ROUND((G9-F9)/30.44,0))
B10: =IF(C10="","EF-"&TEXT(COUNTA($C$5:C10),"000")) | H10: =IF(F10="","",ROUND((G10-F10)/30.44,0))
B11: =IF(C11="","EF-"&TEXT(COUNTA($C$5:C11),"000")) | H11: =IF(F11="","",ROUND((G11-F11)/30.44,0))
B12: =IF(C12="","EF-"&TEXT(COUNTA($C$5:C12),"000")) | H12: =IF(F12="","",ROUND((G12-F12)/30.44,0))
B13: =IF(C13="","EF-"&TEXT(COUNTA($C$5:C13),"000")) | H13: =IF(F13="","",ROUND((G13-F13)/30.44,0))
B14: =IF(C14="","EF-"&TEXT(COUNTA($C$5:C14),"000")) | H14: =IF(F14="","",ROUND((G14-F14)/30.44,0))
B15: =IF(C15="","EF-"&TEXT(COUNTA($C$5:C15),"000")) | H15: =IF(F15="","",ROUND((G15-F15)/30.44,0))
B16: =IF(C16="","EF-"&TEXT(COUNTA($C$5:C16),"000")) | H16: =IF(F16="","",ROUND((G16-F16)/30.44,0))
B17: =IF(C17="","EF-"&TEXT(COUNTA($C$5:C17),"000")) | H17: =IF(F17="","",ROUND((G17-F17)/30.44,0))
B18: =IF(C18="","EF-"&TEXT(COUNTA($C$5:C18),"000")) | H18: =IF(F18="","",ROUND((G18-F18)/30.44,0))
B19: =IF(C19="","EF-"&TEXT(COUNTA($C$5:C19),"000")) | H19: =IF(F19="","",ROUND((G19-F19)/30.44,0))
... B107: =IF(C107="","EF-"&TEXT(COUNTA($C$5:C107),"000")) | H107: =IF(F107="","",ROUND((G107-F107)/30.44,0))
B109: INDICATEURS (mis a jour automatiquement)
B110: Evaluations froid | D110: Application moyenne (/5) | F110: Delai moyen (mois) | H110: Impact positif
B111: =COUNTIF(B5:B104,"<>") | D111: =IFERROR(AVERAGE(I5:I104),0) | F111: =IFERROR(AVERAGE(H5:H104),0) | H111: =COUNTIF(I5:I104,">=4")

Sheet 8-Budget Formation
B2: SUIVI BUDGET FORMATION (#70)
B3: TABLEAU DYNAMIQUE — Saisissez dans la prochaine ligne jaune. Les calculs se mettent a jour automatiquement.
B4: N° | C4: Poste Budgetaire | D4: Departement | E4: Annee | F4: Budget Alloue (FCFA) | G4: Cout Reel (FCFA) | H4: Ecart (FCFA) | I4: Taux Consommation (%) | J4: Statut
B5: BUD-001 | C5: Formations techniques | D5: Cuisine & Restauration | E5: 2025 | F5: 500000 | G5: =IFERROR(SUMIF('4-Inscriptions Formation'!E:E,D5,'4-Inscriptions Formation'!I:I),0) | H5: =F5-G5 | I5: =IFERROR(ROUND(G5/F5*100,1),0) | J5: Consomme partiel
B6: BUD-002 | C6: Formations langues | D6: Réception & Front Office | E6: 2025 | F6: 300000 | G6: =IFERROR(SUMIF('4-Inscriptions Formation'!E:E,D6,'4-Inscriptions Formation'!I:I),0) | H6: =F6-G6 | I6: =IFERROR(ROUND(G6/F6*100,1),0) | J6: Consomme partiel
B7: BUD-003 | C7: Formations securite | D7: Tous | E7: 2025 | F7: 400000 | G7: =IFERROR(SUMIF('4-Inscriptions Formation'!E:E,D7,'4-Inscriptions Formation'!I:I),0) | H7: =F7-G7 | I7: =IFERROR(ROUND(G7/F7*100,1),0) | J7: Provisionne
B8: BUD-004 | C8: Formations informatique | D8: Finance & Comptabilité | E8: 2025 | F8: 100000 | G8: =IFERROR(SUMIF('4-Inscriptions Formation'!E:E,D8,'4-Inscriptions Formation'!I:I),0) | H8: =F8-G8 | I8: =IFERROR(ROUND(G8/F8*100,1),0) | J8: Provisionne
B9: BUD-005 | C9: Formations management | D9: Direction Generale | E9: 2025 | F9: 200000 | G9: =IFERROR(SUMIF('4-Inscriptions Formation'!E:E,D9,'4-Inscriptions Formation'!I:I),0) | H9: =F9-G9 | I9: =IFERROR(ROUND(G9/F9*100,1),0) | J9: Non utilise
B10: =IF(C10="","BUD-"&TEXT(COUNTA($C$5:C10),"000")) | H10: =IF(F10="","",F10-G10) | I10: =IF(F10="","",IF(F10=0,"",G10/F10))
B11: =IF(C11="","BUD-"&TEXT(COUNTA($C$5:C11),"000")) | H11: =IF(F11="","",F11-G11) | I11: =IF(F11="","",IF(F11=0,"",G11/F11))
B12: =IF(C12="","BUD-"&TEXT(COUNTA($C$5:C12),"000")) | H12: =IF(F12="","",F12-G12) | I12: =IF(F12="","",IF(F12=0,"",G12/F12))
B13: =IF(C13="","BUD-"&TEXT(COUNTA($C$5:C13),"000")) | H13: =IF(F13="","",F13-G13) | I13: =IF(F13="","",IF(F13=0,"",G13/F13))
B14: =IF(C14="","BUD-"&TEXT(COUNTA($C$5:C14),"000")) | H14: =IF(F14="","",F14-G14) | I14: =IF(F14="","",IF(F14=0,"",G14/F14))
B15: =IF(C15="","BUD-"&TEXT(COUNTA($C$5:C15),"000")) | H15: =IF(F15="","",F15-G15) | I15: =IF(F15="","",IF(F15=0,"",G15/F15))
B16: =IF(C16="","BUD-"&TEXT(COUNTA($C$5:C16),"000")) | H16: =IF(F16="","",F16-G16) | I16: =IF(F16="","",IF(F16=0,"",G16/F16))
B17: =IF(C17="","BUD-"&TEXT(COUNTA($C$5:C17),"000")) | H17: =IF(F17="","",F17-G17) | I17: =IF(F17="","",IF(F17=0,"",G17/F17))
B18: =IF(C18="","BUD-"&TEXT(COUNTA($C$5:C18),"000")) | H18: =IF(F18="","",F18-G18) | I18: =IF(F18="","",IF(F18=0,"",G18/F18))
B19: =IF(C19="","BUD-"&TEXT(COUNTA($C$5:C19),"000")) | H19: =IF(F19="","",F19-G19) | I19: =IF(F19="","",IF(F19=0,"",G19/F19))
B20: =IF(C20="","BUD-"&TEXT(COUNTA($C$5:C20),"000")) | H20: =IF(F20="","",F20-G20) | I20: =IF(F20="","",IF(F20=0,"",G20/F20))
B21: =IF(C21="","BUD-"&TEXT(COUNTA($C$5:C21),"000")) | H21: =IF(F21="","",F21-G21) | I21: =IF(F21="","",IF(F21=0,"",G21/F21))
... B109: =IF(C109="","BUD-"&TEXT(COUNTA($C$5:C109),"000")) | H109: =IF(F109="","",F109-G109) | I109: =IF(F109="","",IF(F109=0,"",G109/F109))
B111: TOTAL | F111: =SUM(F5:F104) | G111: =SUM(G5:G104) | H111: =SUM(H5:H104)
B113: INDICATEURS (mis a jour automatiquement)
B114: Postes budgetaires | D114: Budget total alloue (FCFA) | F114: Cout total reel (FCFA) | G114: =IFERROR(SUMIF('4-Inscriptions Formation'!E:E,D114,'4-Inscriptions Formation'!I:I),0) | H114: =F114-G114 | I114: =IFERROR(ROUND(G114/F114*100,1),0)
B115: =COUNTIF(B5:B104,"<>") | D115: =SUM(F5:F104) | F115: =SUM(G5:G104) | G115: =IFERROR(SUMIF('4-Inscriptions Formation'!E:E,D115,'4-Inscriptions Formation'!I:I),0) | H115: =F115-G115 | I115: =IFERROR(ROUND(G115/F115*100,1),0)

Sheet 9-Catalogue Formations
B2: CATALOGUE DES FORMATIONS DISPONIBLES (#71)
B3: TABLEAU DYNAMIQUE — Saisissez dans la prochaine ligne jaune. Les calculs se mettent a jour automatiquement.
B4: N° | C4: Intitule Formation | D4: Type Formation | E4: Objectifs | F4: Public Cible | G4: Duree Standard (h) | H4: Cout Unitaire (FCFA) | I4: Prestataire | J4: Frequence
B5: CAT-001 | C5: HACCP Niveau 1 | D5: Formation securite & HACCP | E5: Maitriser regles hygiene alimentaire | F5: Cuisiniers, Plongeurs | G5: 20 | H5: 31250 | I5: Dr. Ngassa (CNPS) | J5: Annuelle
B6: CAT-002 | C6: Anglais hotellerie | D6: Formation langue etrangere | E6: Communiquer en anglais avec clientele | F6: Receptionnistes, Concierges | G6: 30 | H6: 30000 | I6: British Council | J6: Semestrielle
B7: CAT-003 | C7: Gestion conflits clients | D7: Formation accueil & service client | E7: Gerer situations tendues avec clientele | F7: Service client, Reception | G7: 12 | H7: 19200 | I7: Coach Kamga | J7: Trimestrielle
B8: CAT-004 | C8: Excel avance | D8: Formation informatique & bureautique | E8: Maitriser tableaux croises, macros | F8: Comptables, DAF | G8: 15 | H8: 11250 | I8: Formateur interne IT | J8: Annuelle
B9: CAT-005 | C9: Securite incendie | D9: Formation hygiene & securite | E9: Evacuation, extincteurs, premiers secours | F9: Tout personnel | G9: 4 | H9: 5000 | I9: Sapeurs-pompiers Douala | J9: Annuelle
B10: =IF(C10="","CAT-"&TEXT(COUNTA($C$5:C10),"000"))
B11: =IF(C11="","CAT-"&TEXT(COUNTA($C$5:C11),"000"))
B12: =IF(C12="","CAT-"&TEXT(COUNTA($C$5:C12),"000"))
B13: =IF(C13="","CAT-"&TEXT(COUNTA($C$5:C13),"000"))
B14: =IF(C14="","CAT-"&TEXT(COUNTA($C$5:C14),"000"))
B15: =IF(C15="","CAT-"&TEXT(COUNTA($C$5:C15),"000"))
B16: =IF(C16="","CAT-"&TEXT(COUNTA($C$5:C16),"000"))
B17: =IF(C17="","CAT-"&TEXT(COUNTA($C$5:C17),"000"))
B18: =IF(C18="","CAT-"&TEXT(COUNTA($C$5:C18),"000"))
B19: =IF(C19="","CAT-"&TEXT(COUNTA($C$5:C19),"000"))
B20: =IF(C20="","CAT-"&TEXT(COUNTA($C$5:C20),"000"))
B21: =IF(C21="","CAT-"&TEXT(COUNTA($C$5:C21),"000"))
... B109: =IF(C109="","CAT-"&TEXT(COUNTA($C$5:C109),"000"))
B111: TOTAL | G111: =SUM(G5:G104) | H111: =SUM(H5:H104)
B113: INDICATEURS (mis a jour automatiquement)
B114: Formations au catalogue | D114: Duree moyenne (h) | F114: Cout moyen (FCFA) | H114: Prestataires
B115: =COUNTIF(B5:B104,"<>") | D115: =IFERROR(AVERAGE(G5:G104),0) | F115: =IFERROR(AVERAGE(H5:H104),0) | H115: =COUNTIF(I5:I104,"<>")

Sheet 10-Gestion Formateurs
B2: GESTION DES FORMATEURS INTERNES & EXTERNES (#72)
B3: TABLEAU DYNAMIQUE — Saisissez dans la prochaine ligne jaune. Les calculs se mettent a jour automatiquement.
B4: N° | C4: Nom Formateur | D4: Type Formateur | E4: Specialite | F4: Organisme | G4: Contact | H4: Nb Formations Donnees | I4: Satisfaction Moy. (/5) | J4: Cout Journalier (FCFA) | K4: Disponibilite
B5: FOR-001 | C5: Dr. Ngassa | D5: Formateur externe | E5: HACCP & Hygiene | F5: CNPS | G5: 699 000 111 | H5: 3 | I5: 4.5 | J5: 50000 | K5: Disponible
B6: FOR-002 | C6: Mme. Johnson | D6: Formateur externe | E6: Anglais hotellerie | F6: British Council | G6: 233 000 222 | H6: 2 | I6: 4 | J6: 60000 | K6: Disponible
B7: FOR-003 | C7: Coach Kamga | D7: Coach interne | E7: Service client | F7: Interne | G7: 677 000 333 | H7: 5 | I7: 4.8 | J7: 0 | K7: Disponible
B8: FOR-004 | C8: Tchinda Armand | D8: Formateur interne | E8: Informatique | F8: Interne - IT | G8: 690 000 444 | H8: 4 | I8: 4.2 | J8: 0 | K8: Sur planning
B9: FOR-005 | C9: Cpt. Fotso | D9: Consultant | E9: Securite incendie | F9: Sapeurs-pompiers | G9: 233 000 555 | H9: 2 | I9: 4.6 | J9: 75000 | K9: Sur rendez-vous
B10: =IF(C10="","FOR-"&TEXT(COUNTA($C$5:C10),"000"))
B11: =IF(C11="","FOR-"&TEXT(COUNTA($C$5:C11),"000"))
B12: =IF(C12="","FOR-"&TEXT(COUNTA($C$5:C12),"000"))
B13: =IF(C13="","FOR-"&TEXT(COUNTA($C$5:C13),"000"))
B14: =IF(C14="","FOR-"&TEXT(COUNTA($C$5:C14),"000"))
B15: =IF(C15="","FOR-"&TEXT(COUNTA($C$5:C15),"000"))
B16: =IF(C16="","FOR-"&TEXT(COUNTA($C$5:C16),"000"))
B17: =IF(C17="","FOR-"&TEXT(COUNTA($C$5:C17),"000"))
B18: =IF(C18="","FOR-"&TEXT(COUNTA($C$5:C18),"000"))
B19: =IF(C19="","FOR-"&TEXT(COUNTA($C$5:C19),"000"))
B20: =IF(C20="","FOR-"&TEXT(COUNTA($C$5:C20),"000"))
B21: =IF(C21="","FOR-"&TEXT(COUNTA($C$5:C21),"000"))
... B109: =IF(C109="","FOR-"&TEXT(COUNTA($C$5:C109),"000"))
B111: TOTAL | H111: =SUM(H5:H104)
B113: INDICATEURS (mis a jour automatiquement)
B114: Formateurs | D114: Formations totales | F114: Satisfaction moyenne | H114: Internes
B115: =COUNTIF(B5:B104,"<>") | D115: =SUM(H5:H104) | F115: =IFERROR(AVERAGE(I5:I104),0) | H115: =COUNTIF(D5:D104,"Formateur interne")

Sheet 11-Conventions Formation
B2: CONVENTIONS & CONTRATS DE FORMATION (#73)
B3: TABLEAU DYNAMIQUE — Saisissez dans la prochaine ligne jaune. Les calculs se mettent a jour automatiquement.
B4: N° Convention | C4: Organisme Partenaire | D4: Objet Formation | E4: Departements Beneficiaires | F4: Nb Stagiaires Max | G4: Date Signature | H4: Date Expiration | I4: Montant (FCFA) | J4: Nb Sessions Realisees | K4: Nb Sessions Restantes | L4: Statut
B5: CONV-001 | C5: British Council | D5: Formation anglais hotellerie | E5: Réception & Front Office | F5: 10 | G5: 45672 | H5: 46037 | I5: 600000 | J5: 2 | K5: 3 | L5: En vigueur
B6: CONV-002 | C6: CNPS | D6: Formation HACCP | E6: Cuisine & Restauration | F6: 15 | G6: 45689 | H6: 46054 | I6: 450000 | J6: 1 | K6: 2 | L6: En vigueur
B7: CONV-003 | C7: Sapeurs-pompiers Douala | D7: Securite incendie | E7: Tous | F7: 50 | G7: 45717 | H7: 46022 | I7: 150000 | J7: 0 | K7: 2 | L7: En vigueur
B8: =IF(C8="","CONV-"&TEXT(COUNTA($C$5:C8),"000")) | K8: =IF(J8="","",F8-J8)
B9: =IF(C9="","CONV-"&TEXT(COUNTA($C$5:C9),"000")) | K9: =IF(J9="","",F9-J9)
B10: =IF(C10="","CONV-"&TEXT(COUNTA($C$5:C10),"000")) | K10: =IF(J10="","",F10-J10)
B11: =IF(C11="","CONV-"&TEXT(COUNTA($C$5:C11),"000")) | K11: =IF(J11="","",F11-J11)
B12: =IF(C12="","CONV-"&TEXT(COUNTA($C$5:C12),"000")) | K12: =IF(J12="","",F12-J12)
B13: =IF(C13="","CONV-"&TEXT(COUNTA($C$5:C13),"000")) | K13: =IF(J13="","",F13-J13)
B14: =IF(C14="","CONV-"&TEXT(COUNTA($C$5:C14),"000")) | K14: =IF(J14="","",F14-J14)
B15: =IF(C15="","CONV-"&TEXT(COUNTA($C$5:C15),"000")) | K15: =IF(J15="","",F15-J15)
B16: =IF(C16="","CONV-"&TEXT(COUNTA($C$5:C16),"000")) | K16: =IF(J16="","",F16-J16)
B17: =IF(C17="","CONV-"&TEXT(COUNTA($C$5:C17),"000")) | K17: =IF(J17="","",F17-J17)
B18: =IF(C18="","CONV-"&TEXT(COUNTA($C$5:C18),"000")) | K18: =IF(J18="","",F18-J18)
B19: =IF(C19="","CONV-"&TEXT(COUNTA($C$5:C19),"000")) | K19: =IF(J19="","",F19-J19)
... B107: =IF(C107="","CONV-"&TEXT(COUNTA($C$5:C107),"000")) | K107: =IF(J107="","",F107-J107)
B109: TOTAL | I109: =SUM(I5:I104) | J109: =SUM(J5:J104) | K109: =SUM(K5:K104)
B111: INDICATEURS (mis a jour automatiquement)
B112: Conventions actives | D112: Montant total (FCFA) | F112: Sessions realisees | H112: Sessions restantes
B113: =COUNTIF(B5:B104,"<>") | D113: =SUM(I5:I104) | F113: =SUM(J5:J104) | H113: =SUM(K5:K104)

Sheet 12-Plan Individuel Dev.
B2: PLAN INDIVIDUEL DE DEVELOPPEMENT - PID (#74)
B3: TABLEAU DYNAMIQUE — Saisissez dans la prochaine ligne jaune. Les calculs se mettent a jour automatiquement.
B4: N° PID | C4: Matricule | D4: Nom Employe | E4: Departement | F4: Poste Actuel | G4: Competence a Developper | H4: Objectif Mesurable | I4: Action Formation Liee | J4: Echeance | K4: Avancement (%) | L4: Statut
B5: PID-001 | C5: EMP-010 | D5: =IF(C5="","",VLOOKUP(C5,'_Données Employés'!$B$5:$H$18,4,FALSE)&" "&VLOOKUP(C5,'_Données Employés'!$B$5:$H$18,5,FALSE)) | E5: =IF(C5="","",VLOOKUP(C5,'_Données Employés'!$B$5:$H$18,6,FALSE)) | F5: =IF(C5="","",VLOOKUP(C5,'_Données Employés'!$B$5:$H$18,7,FALSE)) | G5: Techniques cuisson avancees | H5: Obtenir certification cuisson niveau 2 | I5: PAF-006 | J5: 46022 | K5: 40 | L5: En cours de realisation
B6: PID-002 | C6: EMP-004 | D6: =IF(C6="","",VLOOKUP(C6,'_Données Employés'!$B$5:$H$18,4,FALSE)&" "&VLOOKUP(C6,'_Données Employés'!$B$5:$H$18,5,FALSE)) | E6: =IF(C6="","",VLOOKUP(C6,'_Données Employés'!$B$5:$H$18,6,FALSE)) | F6: =IF(C6="","",VLOOKUP(C6,'_Données Employés'!$B$5:$H$18,7,FALSE)) | G6: Maitrise PMS Opera | H6: Gerer 100% des reservations sur Opera | I6: PAF-004 | J6: 45930 | K6: 0 | L6: Valide par N+1
B7: PID-003 | C7: EMP-001 | D7: =IF(C7="","",VLOOKUP(C7,'_Données Employés'!$B$5:$H$18,4,FALSE)&" "&VLOOKUP(C7,'_Données Employés'!$B$5:$H$18,5,FALSE)) | E7: =IF(C7="","",VLOOKUP(C7,'_Données Employés'!$B$5:$H$18,6,FALSE)) | F7: =IF(C7="","",VLOOKUP(C7,'_Données Employés'!$B$5:$H$18,7,FALSE)) | G7: Management d'equipe | H7: Certifier management niveau 1 | J7: 46022 | K7: 20 | L7: En cours de realisation
B8: PID-004 | C8: EMP-006 | D8: =IF(C8="","",VLOOKUP(C8,'_Données Employés'!$B$5:$H$18,4,FALSE)&" "&VLOOKUP(C8,'_Données Employés'!$B$5:$H$18,5,FALSE)) | E8: =IF(C8="","",VLOOKUP(C8,'_Données Employés'!$B$5:$H$18,6,FALSE)) | F8: =IF(C8="","",VLOOKUP(C8,'_Données Employés'!$B$5:$H$18,7,FALSE)) | G8: Techniques de vente | H8: Augmenter ventes croisees de 20% | I8: PAF-007 | J8: 45961 | K8: 60 | L8: En cours de realisation
B9: PID-005 | C9: EMP-011 | D9: =IF(C9="","",VLOOKUP(C9,'_Données Employés'!$B$5:$H$18,4,FALSE)&" "&VLOOKUP(C9,'_Données Employés'!$B$5:$H$18,5,FALSE)) | E9: =IF(C9="","",VLOOKUP(C9,'_Données Employés'!$B$5:$H$18,6,FALSE)) | F9: =IF(C9="","",VLOOKUP(C9,'_Données Employés'!$B$5:$H$18,7,FALSE)) | G9: Gestion CCTV | H9: Maitriser systeme surveillance | I9: PAF-008 | J9: 45869 | K9: 80 | L9: En cours de realisation
B10: =IF(C10="","PID-"&TEXT(COUNTA($C$5:C10),"000"))
B11: =IF(C11="","PID-"&TEXT(COUNTA($C$5:C11),"000"))
B12: =IF(C12="","PID-"&TEXT(COUNTA($C$5:C12),"000"))
B13: =IF(C13="","PID-"&TEXT(COUNTA($C$5:C13),"000"))
B14: =IF(C14="","PID-"&TEXT(COUNTA($C$5:C14),"000"))
B15: =IF(C15="","PID-"&TEXT(COUNTA($C$5:C15),"000"))
B16: =IF(C16="","PID-"&TEXT(COUNTA($C$5:C16),"000"))
B17: =IF(C17="","PID-"&TEXT(COUNTA($C$5:C17),"000"))
B18: =IF(C18="","PID-"&TEXT(COUNTA($C$5:C18),"000"))
B19: =IF(C19="","PID-"&TEXT(COUNTA($C$5:C19),"000"))
B20: =IF(C20="","PID-"&TEXT(COUNTA($C$5:C20),"000"))
B21: =IF(C21="","PID-"&TEXT(COUNTA($C$5:C21),"000"))
... B109: =IF(C109="","PID-"&TEXT(COUNTA($C$5:C109),"000"))
B111: INDICATEURS (mis a jour automatiquement)
B112: PID suivis | D112: Avancement moyen | F112: En cours | H112: Valides
B113: =COUNTIF(B5:B104,"<>") | D113: =IFERROR(AVERAGE(K5:K104),0) | F113: =COUNTIF(L5:L104,"En cours de realisation") | H113: =COUNTIF(L5:L104,"Valide par N+1")

Sheet 13-Matrice Competences
B2: MATRICE DE COMPETENCES & POLYVALENCE (#75)
B3: TABLEAU DYNAMIQUE — Saisissez dans la prochaine ligne jaune. Les calculs se mettent a jour automatiquement.
B4: N° | C4: Matricule | D4: Nom Employe | E4: Departement | F4: Poste Principal | G4: Competence 1 (Niveau) | H4: Competence 2 (Niveau) | I4: Competence 3 (Niveau) | J4: Score Polyvalence
B5: MAT-001 | C5: EMP-010 | D5: =IF(C5="","",VLOOKUP(C5,'_Données Employés'!$B$5:$H$18,4,FALSE)&" "&VLOOKUP(C5,'_Données Employés'!$B$5:$H$18,5,FALSE)) | E5: =IF(C5="","",VLOOKUP(C5,'_Données Employés'!$B$5:$H$18,6,FALSE)) | F5: =IF(C5="","",VLOOKUP(C5,'_Données Employés'!$B$5:$H$18,7,FALSE)) | G5: Cuisson (Avance) | H5: Patisserie (Intermediaire) | I5: HACCP (Expert) | J5: 3
B6: MAT-002 | C6: EMP-004 | D6: =IF(C6="","",VLOOKUP(C6,'_Données Employés'!$B$5:$H$18,4,FALSE)&" "&VLOOKUP(C6,'_Données Employés'!$B$5:$H$18,5,FALSE)) | E6: =IF(C6="","",VLOOKUP(C6,'_Données Employés'!$B$5:$H$18,6,FALSE)) | F6: =IF(C6="","",VLOOKUP(C6,'_Données Employés'!$B$5:$H$18,7,FALSE)) | G6: Accueil (Avance) | H6: PMS Opera (Intermediaire) | I6: Anglais (Intermediaire) | J6: 3
B7: MAT-003 | C7: EMP-006 | D7: =IF(C7="","",VLOOKUP(C7,'_Données Employés'!$B$5:$H$18,4,FALSE)&" "&VLOOKUP(C7,'_Données Employés'!$B$5:$H$18,5,FALSE)) | E7: =IF(C7="","",VLOOKUP(C7,'_Données Employés'!$B$5:$H$18,6,FALSE)) | F7: =IF(C7="","",VLOOKUP(C7,'_Données Employés'!$B$5:$H$18,7,FALSE)) | G7: Vente (Intermediaire) | H7: Gestion conflits (Intermediaire) | I7: CRM (Debutant) | J7: 2
B8: MAT-004 | C8: EMP-011 | D8: =IF(C8="","",VLOOKUP(C8,'_Données Employés'!$B$5:$H$18,4,FALSE)&" "&VLOOKUP(C8,'_Données Employés'!$B$5:$H$18,5,FALSE)) | E8: =IF(C8="","",VLOOKUP(C8,'_Données Employés'!$B$5:$H$18,6,FALSE)) | F8: =IF(C8="","",VLOOKUP(C8,'_Données Employés'!$B$5:$H$18,7,FALSE)) | G8: Surveillance (Avance) | H8: CCTV (Intermediaire) | I8: Incendie (Avance) | J8: 3
B9: MAT-005 | C9: EMP-009 | D9: =IF(C9="","",VLOOKUP(C9,'_Données Employés'!$B$5:$H$18,4,FALSE)&" "&VLOOKUP(C9,'_Données Employés'!$B$5:$H$18,5,FALSE)) | E9: =IF(C9="","",VLOOKUP(C9,'_Données Employés'!$B$5:$H$18,6,FALSE)) | F9: =IF(C9="","",VLOOKUP(C9,'_Données Employés'!$B$5:$H$18,7,FALSE)) | G9: Plomberie (Expert) | H9: Electricite (Avance) | I9: CVC (Intermediaire) | J9: 3
B10: MAT-007 | C10: EMP-002 | D10: =IF(C10="","",VLOOKUP(C10,'_Données Employés'!$B$5:$H$18,4,FALSE)&" "&VLOOKUP(C10,'_Données Employés'!$B$5:$H$18,5,FALSE)) | E10: =IF(C10="","",VLOOKUP(C10,'_Données Employés'!$B$5:$H$18,6,FALSE)) | F10: =IF(C10="","",VLOOKUP(C10,'_Données Employés'!$B$5:$H$18,7,FALSE)) | G10: Accueil (Avance) | H10: Anglais (Debutant) | I10: PMS Opera (Debutant) | J10: 2
B11: MAT-008 | C11: EMP-005 | D11: =IF(C11="","",VLOOKUP(C11,'_Données Employés'!$B$5:$H$18,4,FALSE)&" "&VLOOKUP(C11,'_Données Employés'!$B$5:$H$18,5,FALSE)) | E11: =IF(C11="","",VLOOKUP(C11,'_Données Employés'!$B$5:$H$18,6,FALSE)) | F11: =IF(C11="","",VLOOKUP(C11,'_Données Employés'!$B$5:$H$18,7,FALSE)) | G11: Plomberie (Intermediaire) | H11: Electricite (Intermediaire) | I11: CVC (Debutant) | J11: 2
B12: MAT-009 | C12: EMP-007 | D12: =IF(C12="","",VLOOKUP(C12,'_Données Employés'!$B$5:$H$18,4,FALSE)&" "&VLOOKUP(C12,'_Données Employés'!$B$5:$H$18,5,FALSE)) | E12: =IF(C12="","",VLOOKUP(C12,'_Données Employés'!$B$5:$H$18,6,FALSE)) | F12: =IF(C12="","",VLOOKUP(C12,'_Données Employés'!$B$5:$H$18,7,FALSE)) | G12: Plomberie (Debutant) | H12: Electricite (Debutant) | I12: Nettoyage industriel (Debutant) | J12: 2
B13: MAT-010 | C13: EMP-008 | D13: =IF(C13="","",VLOOKUP(C13,'_Données Employés'!$B$5:$H$18,4,FALSE)&" "&VLOOKUP(C13,'_Données Employés'!$B$5:$H$18,5,FALSE)) | E13: =IF(C13="","",VLOOKUP(C13,'_Données Employés'!$B$5:$H$18,6,FALSE)) | F13: =IF(C13="","",VLOOKUP(C13,'_Données Employés'!$B$5:$H$18,7,FALSE)) | G13: Vente (Intermediaire) | H13: Négociation (Debutant) | I13: CRM (Debutant) | J13: 2
B14: MAT-011 | C14: EMP-028 | D14: =IF(C14="","",VLOOKUP(C14,'_Données Employés'!$B$5:$H$18,4,FALSE)&" "&VLOOKUP(C14,'_Données Employés'!$B$5:$H$18,5,FALSE)) | E14: =IF(C14="","",VLOOKUP(C14,'_Données Employés'!$B$5:$H$18,6,FALSE)) | F14: =IF(C14="","",VLOOKUP(C14,'_Données Employés'!$B$5:$H$18,7,FALSE)) | G14: Surveillance (Intermediaire) | H14: CCTV (Debutant) | I14: Incendie (Intermediaire) | J14: 2
B15: MAT-012 | C15: EMP-029 | D15: =IF(C15="","",VLOOKUP(C15,'_Données Employés'!$B$5:$H$18,4,FALSE)&" "&VLOOKUP(C15,'_Données Employés'!$B$5:$H$18,5,FALSE)) | E15: =IF(C15="","",VLOOKUP(C15,'_Données Employés'!$B$5:$H$18,6,FALSE)) | F15: =IF(C15="","",VLOOKUP(C15,'_Données Employés'!$B$5:$H$18,7,FALSE)) | G15: Surveillance (Expert) | H15: CCTV (Avance) | I15: Incendie (Expert) | J15: 2
B16: MAT-013 | C16: EMP-001 | D16: =IF(C16="","",VLOOKUP(C16,'_Données Employés'!$B$5:$H$18,4,FALSE)&" "&VLOOKUP(C16,'_Données Employés'!$B$5:$H$18,5,FALSE)) | E16: =IF(C16="","",VLOOKUP(C16,'_Données Employés'!$B$5:$H$18,6,FALSE)) | F16: =IF(C16="","",VLOOKUP(C16,'_Données Employés'!$B$5:$H$18,7,FALSE)) | G16: Management (Avance) | H16: RH (Expert) | I16: Formation (Intermediaire) | J16: 3
... B18: MAT-015 | C18: EMP-012 | D18: =IF(C18="","",VLOOKUP(C18,'_Données Employés'!$B$5:$H$18,4,FALSE)&" "&VLOOKUP(C18,'_Données Employés'!$B$5:$H$18,5,FALSE)) | E18: =IF(C18="","",VLOOKUP(C18,'_Données Employés'!$B$5:$H$18,6,FALSE)) | F18: =IF(C18="","",VLOOKUP(C18,'_Données Employés'!$B$5:$H$18,7,FALSE)) | G18: Accueil (Debutant) | H18: Telephone (Intermediaire) | I18: Anglais (Debutant) | J18: 3
B19: =IF(C19="","MAT-"&TEXT(COUNTA($C$5:C19),"000"))
B20: =IF(C20="","MAT-"&TEXT(COUNTA($C$5:C20),"000"))
B21: =IF(C21="","MAT-"&TEXT(COUNTA($C$5:C21),"000"))
B22: =IF(C22="","MAT-"&TEXT(COUNTA($C$5:C22),"000"))
B23: =IF(C23="","MAT-"&TEXT(COUNTA($C$5:C23),"000"))
B24: =IF(C24="","MAT-"&TEXT(COUNTA($C$5:C24),"000"))
B25: =IF(C25="","MAT-"&TEXT(COUNTA($C$5:C25),"000"))
B26: =IF(C26="","MAT-"&TEXT(COUNTA($C$5:C26),"000"))
B27: =IF(C27="","MAT-"&TEXT(COUNTA($C$5:C27),"000"))
B28: =IF(C28="","MAT-"&TEXT(COUNTA($C$5:C28),"000"))
B29: =IF(C29="","MAT-"&TEXT(COUNTA($C$5:C29),"000"))
B30: =IF(C30="","MAT-"&TEXT(COUNTA($C$5:C30),"000"))
... B109: =IF(C109="","MAT-"&TEXT(COUNTA($C$5:C109),"000"))
B111: TOTAL | J111: =SUM(J5:J104)
B113: INDICATEURS (mis a jour automatiquement)
B114: Employes evalues | D114: Polyvalence moyenne | F114: Score max | H114: Score min
B115: =COUNTIF(B5:B104,"<>") | D115: =IFERROR(AVERAGE(J5:J104),0) | F115: =IFERROR(MAX(J5:J104),0) | H115: =IFERROR(MIN(J5:J104),0)

Sheet 14-Bilan Competences par Dept
B2: BILAN DE COMPETENCES PAR DEPARTEMENT
B3: TABLEAU DYNAMIQUE — Saisissez dans la prochaine ligne jaune. Les calculs se mettent a jour automatiquement.
B4: N° | C4: Departement | D4: Annee | E4: Effectif | F4: Nb Formations Suivies | G4: Heures Formation (h) | H4: Cout Total (FCFA) | I4: Nb Comp. Developpees | J4: Score Polyvalence Moy.
B5: BCD-001 | C5: Cuisine & Restauration | D5: 2025 | E5: =COUNTIF('13-Matrice Competences'!E:E,C5) | F5: =COUNTIF('4-Inscriptions Formation'!E:E,C5) | G5: 60 | H5: =IFERROR(SUMIF('4-Inscriptions Formation'!E:E,C5,'4-Inscriptions Formation'!I:I),0) | I5: 8 | J5: =IFERROR(ROUND(AVERAGEIF('13-Matrice Competences'!E:E,C5,'13-Matrice Competences'!J:J),1),0)
B6: BCD-002 | C6: Réception & Front Office | D6: 2025 | E6: =COUNTIF('13-Matrice Competences'!E:E,C6) | F6: =COUNTIF('4-Inscriptions Formation'!E:E,C6) | G6: 42 | H6: =IFERROR(SUMIF('4-Inscriptions Formation'!E:E,C6,'4-Inscriptions Formation'!I:I),0) | I6: 6 | J6: =IFERROR(ROUND(AVERAGEIF('13-Matrice Competences'!E:E,C6,'13-Matrice Competences'!J:J),1),0)
B7: BCD-003 | C7: Service Client | D7: 2025 | E7: =COUNTIF('13-Matrice Competences'!E:E,C7) | F7: =COUNTIF('4-Inscriptions Formation'!E:E,C7) | G7: 30 | H7: =IFERROR(SUMIF('4-Inscriptions Formation'!E:E,C7,'4-Inscriptions Formation'!I:I),0) | I7: 5 | J7: =IFERROR(ROUND(AVERAGEIF('13-Matrice Competences'!E:E,C7,'13-Matrice Competences'!J:J),1),0)
B8: BCD-004 | C8: Finance & Comptabilité | D8: 2025 | E8: =COUNTIF('13-Matrice Competences'!E:E,C8) | F8: =COUNTIF('4-Inscriptions Formation'!E:E,C8) | G8: 15 | H8: =IFERROR(SUMIF('4-Inscriptions Formation'!E:E,C8,'4-Inscriptions Formation'!I:I),0) | I8: 3 | J8: =IFERROR(ROUND(AVERAGEIF('13-Matrice Competences'!E:E,C8,'13-Matrice Competences'!J:J),1),0)
B9: BCD-005 | C9: Sécurité | D9: 2025 | E9: =COUNTIF('13-Matrice Competences'!E:E,C9) | F9: =COUNTIF('4-Inscriptions Formation'!E:E,C9) | G9: 20 | H9: =IFERROR(SUMIF('4-Inscriptions Formation'!E:E,C9,'4-Inscriptions Formation'!I:I),0) | I9: 4 | J9: =IFERROR(ROUND(AVERAGEIF('13-Matrice Competences'!E:E,C9,'13-Matrice Competences'!J:J),1),0)
B10: BCD-006 | C10: Maintenance | D10: 2025 | E10: =COUNTIF('13-Matrice Competences'!E:E,C10) | F10: =COUNTIF('4-Inscriptions Formation'!E:E,C10) | G10: 20 | H10: =IFERROR(SUMIF('4-Inscriptions Formation'!E:E,C10,'4-Inscriptions Formation'!I:I),0) | I10: 4 | J10: =IFERROR(ROUND(AVERAGEIF('13-Matrice Competences'!E:E,C10,'13-Matrice Competences'!J:J),1),0)
B11: BCD-007 | C11: Service Client | D11: 2025 | E11: =COUNTIF('13-Matrice Competences'!E:E,C11) | F11: =COUNTIF('4-Inscriptions Formation'!E:E,C11) | G11: 28 | H11: =IFERROR(SUMIF('4-Inscriptions Formation'!E:E,C11,'4-Inscriptions Formation'!I:I),0) | I11: 5 | J11: =IFERROR(ROUND(AVERAGEIF('13-Matrice Competences'!E:E,C11,'13-Matrice Competences'!J:J),1),0)
B12: =IF(C12="","BCD-"&TEXT(COUNTA($C$5:C12),"000"))
B13: =IF(C13="","BCD-"&TEXT(COUNTA($C$5:C13),"000"))
B14: =IF(C14="","BCD-"&TEXT(COUNTA($C$5:C14),"000"))
B15: =IF(C15="","BCD-"&TEXT(COUNTA($C$5:C15),"000"))
B16: =IF(C16="","BCD-"&TEXT(COUNTA($C$5:C16),"000"))
B17: =IF(C17="","BCD-"&TEXT(COUNTA($C$5:C17),"000"))
B18: =IF(C18="","BCD-"&TEXT(COUNTA($C$5:C18),"000"))
B19: =IF(C19="","BCD-"&TEXT(COUNTA($C$5:C19),"000"))
B20: =IF(C20="","BCD-"&TEXT(COUNTA($C$5:C20),"000"))
B21: =IF(C21="","BCD-"&TEXT(COUNTA($C$5:C21),"000"))
B22: =IF(C22="","BCD-"&TEXT(COUNTA($C$5:C22),"000"))
B23: =IF(C23="","BCD-"&TEXT(COUNTA($C$5:C23),"000"))
... B111: =IF(C111="","BCD-"&TEXT(COUNTA($C$5:C111),"000"))
B113: TOTAL | E113: =SUM(E5:E104) | F113: =SUM(F5:F104) | G113: =SUM(G5:G104) | H113: =SUM(H5:H104) | I113: =SUM(I5:I104)
B115: INDICATEURS (mis a jour automatiquement)
B116: Departements suivis | D116: Total formations | F116: Total heures (h) | H116: Cout global (FCFA)
B117: =COUNTIF(B5:B104,"<>") | D117: =SUM(F5:F104) | F117: =SUM(G5:G104) | H117: =SUM(H5:H104)

Sheet 15-Certifications & Qualif.
B2: SUIVI DES CERTIFICATIONS & QUALIFICATIONS
B3: TABLEAU DYNAMIQUE — Saisissez dans la prochaine ligne jaune. Les calculs se mettent a jour automatiquement.
B4: N° | C4: Matricule | D4: Nom Employe | E4: Departement | F4: Certification | G4: Organisme Delivrant | H4: Date Obtention | I4: Date Expiration | J4: Statut Certificat
B5: CERT-001 | C5: EMP-010 | D5: =IF(C5="","",VLOOKUP(C5,'_Données Employés'!$B$5:$H$18,4,FALSE)&" "&VLOOKUP(C5,'_Données Employés'!$B$5:$H$18,5,FALSE)) | E5: =IF(C5="","",VLOOKUP(C5,'_Données Employés'!$B$5:$H$18,6,FALSE)) | F5: HACCP Niveau 1 | G5: CNPS | H5: 45730 | I5: 46826 | J5: Valide
B6: CERT-002 | C6: EMP-001 | D6: =IF(C6="","",VLOOKUP(C6,'_Données Employés'!$B$5:$H$18,4,FALSE)&" "&VLOOKUP(C6,'_Données Employés'!$B$5:$H$18,5,FALSE)) | E6: =IF(C6="","",VLOOKUP(C6,'_Données Employés'!$B$5:$H$18,6,FALSE)) | F6: HACCP Niveau 1 | G6: CNPS | H6: 45730 | I6: 46826 | J6: Valide
B7: CERT-003 | C7: EMP-009 | D7: =IF(C7="","",VLOOKUP(C7,'_Données Employés'!$B$5:$H$18,4,FALSE)&" "&VLOOKUP(C7,'_Données Employés'!$B$5:$H$18,5,FALSE)) | E7: =IF(C7="","",VLOOKUP(C7,'_Données Employés'!$B$5:$H$18,6,FALSE)) | F7: CVC Certifie | G7: GEFCO | H7: 45458 | I7: 45823 | J7: A renouveler
B8: CERT-004 | C8: EMP-011 | D8: =IF(C8="","",VLOOKUP(C8,'_Données Employés'!$B$5:$H$18,4,FALSE)&" "&VLOOKUP(C8,'_Données Employés'!$B$5:$H$18,5,FALSE)) | E8: =IF(C8="","",VLOOKUP(C8,'_Données Employés'!$B$5:$H$18,6,FALSE)) | F8: Agent securite certifie | G8: Ministere Interieur | H8: 45170 | I8: 45901 | J8: Valide
B9: CERT-005 | C9: EMP-001 | D9: =IF(C9="","",VLOOKUP(C9,'_Données Employés'!$B$5:$H$18,4,FALSE)&" "&VLOOKUP(C9,'_Données Employés'!$B$5:$H$18,5,FALSE)) | E9: =IF(C9="","",VLOOKUP(C9,'_Données Employés'!$B$5:$H$18,6,FALSE)) | F9: Master RH | G9: Unite de Douala | H9: 44012 | I9: 73050 | J9: Valide
B10: =IF(C10="","CERT-"&TEXT(COUNTA($C$5:C10),"000"))
B11: =IF(C11="","CERT-"&TEXT(COUNTA($C$5:C11),"000"))
B12: =IF(C12="","CERT-"&TEXT(COUNTA($C$5:C12),"000"))
B13: =IF(C13="","CERT-"&TEXT(COUNTA($C$5:C13),"000"))
B14: =IF(C14="","CERT-"&TEXT(COUNTA($C$5:C14),"000"))
B15: =IF(C15="","CERT-"&TEXT(COUNTA($C$5:C15),"000"))
B16: =IF(C16="","CERT-"&TEXT(COUNTA($C$5:C16),"000"))
B17: =IF(C17="","CERT-"&TEXT(COUNTA($C$5:C17),"000"))
B18: =IF(C18="","CERT-"&TEXT(COUNTA($C$5:C18),"000"))
B19: =IF(C19="","CERT-"&TEXT(COUNTA($C$5:C19),"000"))
B20: =IF(C20="","CERT-"&TEXT(COUNTA($C$5:C20),"000"))
B21: =IF(C21="","CERT-"&TEXT(COUNTA($C$5:C21),"000"))
... B109: =IF(C109="","CERT-"&TEXT(COUNTA($C$5:C109),"000"))
B111: INDICATEURS (mis a jour automatiquement)
B112: Certifications | D112: Valides | F112: A renouveler | H112: Expirees
B113: =COUNTIF(B5:B104,"<>") | D113: =COUNTIF(J5:J104,"Valide") | F113: =COUNTIF(J5:J104,"A renouveler") | H113: =COUNTIF(J5:J104,"Expire")

Sheet 16-Historique Form. Employé
B2: HISTORIQUE FORMATIONS PAR EMPLOYE
B3: TABLEAU DYNAMIQUE — Saisissez dans la prochaine ligne jaune. Les calculs se mettent a jour automatiquement.
B4: N° | C4: Matricule | D4: Nom Employe | E4: Departement | F4: Annee | G4: Nb Formations | H4: Heures Totales (h) | I4: Cout Total (FCFA) | J4: Score Eval Chaud Moy. | K4: Score Eval Froid Moy.
B5: HF-001 | C5: EMP-010 | D5: =IF(C5="","",VLOOKUP(C5,'_Données Employés'!$B$5:$H$18,4,FALSE)&" "&VLOOKUP(C5,'_Données Employés'!$B$5:$H$18,5,FALSE)) | E5: =IF(C5="","",VLOOKUP(C5,'_Données Employés'!$B$5:$H$18,6,FALSE)) | F5: 2025 | G5: =COUNTIF('4-Inscriptions Formation'!C:C,C5) | H5: 24 | I5: =IFERROR(SUMIF('4-Inscriptions Formation'!C:C,C5,'4-Inscriptions Formation'!I:I),0) | J5: =IFERROR(ROUND(AVERAGEIF('6-Evaluation a Chaud'!D:D,C5,'6-Evaluation a Chaud'!J:J),1),0) | K5: =IFERROR(ROUND(AVERAGEIF('7-Evaluation a Froid'!D:D,C5,'7-Evaluation a Froid'!I:I),1),0)
B6: HF-002 | C6: EMP-004 | D6: =IF(C6="","",VLOOKUP(C6,'_Données Employés'!$B$5:$H$18,4,FALSE)&" "&VLOOKUP(C6,'_Données Employés'!$B$5:$H$18,5,FALSE)) | E6: =IF(C6="","",VLOOKUP(C6,'_Données Employés'!$B$5:$H$18,6,FALSE)) | F6: 2025 | G6: =COUNTIF('4-Inscriptions Formation'!C:C,C6) | H6: 45 | I6: =IFERROR(SUMIF('4-Inscriptions Formation'!C:C,C6,'4-Inscriptions Formation'!I:I),0) | J6: =IFERROR(ROUND(AVERAGEIF('6-Evaluation a Chaud'!D:D,C6,'6-Evaluation a Chaud'!J:J),1),0) | K6: =IFERROR(ROUND(AVERAGEIF('7-Evaluation a Froid'!D:D,C6,'7-Evaluation a Froid'!I:I),1),0)
B7: HF-002 | C7: EMP-004 | D7: =IF(C7="","",VLOOKUP(C7,'_Données Employés'!$B$5:$H$18,4,FALSE)&" "&VLOOKUP(C7,'_Données Employés'!$B$5:$H$18,5,FALSE)) | E7: =IF(C7="","",VLOOKUP(C7,'_Données Employés'!$B$5:$H$18,6,FALSE)) | F7: 2024 | G7: =COUNTIF('4-Inscriptions Formation'!C:C,C7) | H7: 20 | I7: =IFERROR(SUMIF('4-Inscriptions Formation'!C:C,C7,'4-Inscriptions Formation'!I:I),0) | J7: =IFERROR(ROUND(AVERAGEIF('6-Evaluation a Chaud'!D:D,C7,'6-Evaluation a Chaud'!J:J),1),0) | K7: =IFERROR(ROUND(AVERAGEIF('7-Evaluation a Froid'!D:D,C7,'7-Evaluation a Froid'!I:I),1),0)
B8: HF-003 | C8: EMP-006 | D8: =IF(C8="","",VLOOKUP(C8,'_Données Employés'!$B$5:$H$18,4,FALSE)&" "&VLOOKUP(C8,'_Données Employés'!$B$5:$H$18,5,FALSE)) | E8: =IF(C8="","",VLOOKUP(C8,'_Données Employés'!$B$5:$H$18,6,FALSE)) | F8: 2025 | G8: =COUNTIF('4-Inscriptions Formation'!C:C,C8) | H8: 12 | I8: =IFERROR(SUMIF('4-Inscriptions Formation'!C:C,C8,'4-Inscriptions Formation'!I:I),0) | J8: =IFERROR(ROUND(AVERAGEIF('6-Evaluation a Chaud'!D:D,C8,'6-Evaluation a Chaud'!J:J),1),0) | K8: =IFERROR(ROUND(AVERAGEIF('7-Evaluation a Froid'!D:D,C8,'7-Evaluation a Froid'!I:I),1),0)
B9: HF-004 | C9: EMP-001 | D9: =IF(C9="","",VLOOKUP(C9,'_Données Employés'!$B$5:$H$18,4,FALSE)&" "&VLOOKUP(C9,'_Données Employés'!$B$5:$H$18,5,FALSE)) | E9: =IF(C9="","",VLOOKUP(C9,'_Données Employés'!$B$5:$H$18,6,FALSE)) | F9: 2025 | G9: =COUNTIF('4-Inscriptions Formation'!C:C,C9) | H9: 4 | I9: =IFERROR(SUMIF('4-Inscriptions Formation'!C:C,C9,'4-Inscriptions Formation'!I:I),0) | J9: =IFERROR(ROUND(AVERAGEIF('6-Evaluation a Chaud'!D:D,C9,'6-Evaluation a Chaud'!J:J),1),0) | K9: =IFERROR(ROUND(AVERAGEIF('7-Evaluation a Froid'!D:D,C9,'7-Evaluation a Froid'!I:I),1),0)
B10: HF-007 | C10: EMP-002 | D10: =IF(C10="","",VLOOKUP(C10,'_Données Employés'!$B$5:$H$18,4,FALSE)&" "&VLOOKUP(C10,'_Données Employés'!$B$5:$H$18,5,FALSE)) | E10: =IF(C10="","",VLOOKUP(C10,'_Données Employés'!$B$5:$H$18,6,FALSE)) | F10: 2025
B11: HF-008 | C11: EMP-005 | D11: =IF(C11="","",VLOOKUP(C11,'_Données Employés'!$B$5:$H$18,4,FALSE)&" "&VLOOKUP(C11,'_Données Employés'!$B$5:$H$18,5,FALSE)) | E11: =IF(C11="","",VLOOKUP(C11,'_Données Employés'!$B$5:$H$18,6,FALSE)) | F11: 2025
B12: HF-009 | C12: EMP-007 | D12: =IF(C12="","",VLOOKUP(C12,'_Données Employés'!$B$5:$H$18,4,FALSE)&" "&VLOOKUP(C12,'_Données Employés'!$B$5:$H$18,5,FALSE)) | E12: =IF(C12="","",VLOOKUP(C12,'_Données Employés'!$B$5:$H$18,6,FALSE)) | F12: 2025
B13: HF-010 | C13: EMP-008 | D13: =IF(C13="","",VLOOKUP(C13,'_Données Employés'!$B$5:$H$18,4,FALSE)&" "&VLOOKUP(C13,'_Données Employés'!$B$5:$H$18,5,FALSE)) | E13: =IF(C13="","",VLOOKUP(C13,'_Données Employés'!$B$5:$H$18,6,FALSE)) | F13: 2025
B14: HF-011 | C14: EMP-028 | D14: =IF(C14="","",VLOOKUP(C14,'_Données Employés'!$B$5:$H$18,4,FALSE)&" "&VLOOKUP(C14,'_Données Employés'!$B$5:$H$18,5,FALSE)) | E14: =IF(C14="","",VLOOKUP(C14,'_Données Employés'!$B$5:$H$18,6,FALSE)) | F14: 2025
B15: HF-012 | C15: EMP-029 | D15: =IF(C15="","",VLOOKUP(C15,'_Données Employés'!$B$5:$H$18,4,FALSE)&" "&VLOOKUP(C15,'_Données Employés'!$B$5:$H$18,5,FALSE)) | E15: =IF(C15="","",VLOOKUP(C15,'_Données Employés'!$B$5:$H$18,6,FALSE)) | F15: 2025
B16: =IF(C16="","HF-"&TEXT(COUNTA($C$5:C16),"000"))
B17: =IF(C17="","HF-"&TEXT(COUNTA($C$5:C17),"000"))
B18: =IF(C18="","HF-"&TEXT(COUNTA($C$5:C18),"000"))
B19: =IF(C19="","HF-"&TEXT(COUNTA($C$5:C19),"000"))
B20: =IF(C20="","HF-"&TEXT(COUNTA($C$5:C20),"000"))
B21: =IF(C21="","HF-"&TEXT(COUNTA($C$5:C21),"000"))
B22: =IF(C22="","HF-"&TEXT(COUNTA($C$5:C22),"000"))
B23: =IF(C23="","HF-"&TEXT(COUNTA($C$5:C23),"000"))
B24: =IF(C24="","HF-"&TEXT(COUNTA($C$5:C24),"000"))
B25: =IF(C25="","HF-"&TEXT(COUNTA($C$5:C25),"000"))
B26: =IF(C26="","HF-"&TEXT(COUNTA($C$5:C26),"000"))
B27: =IF(C27="","HF-"&TEXT(COUNTA($C$5:C27),"000"))
... B109: =IF(C109="","HF-"&TEXT(COUNTA($C$5:C109),"000"))
B111: TOTAL | G111: =SUM(G5:G104) | H111: =SUM(H5:H104) | I111: =SUM(I5:I104)
B113: INDICATEURS (mis a jour automatiquement)
B114: Lignes historique | D114: Total heures (h) | F114: Cout total (FCFA) | H114: Score chaud moyen
B115: =COUNTIF(B5:B104,"<>") | D115: =SUM(H5:H104) | F115: =SUM(I5:I104) | H115: =IFERROR(AVERAGE(J5:J104),0)

Sheet 17-Suivi Mensuel Formations
B2: SUIVI MENSUEL DES FORMATIONS
B3: TABLEAU DYNAMIQUE — Saisissez dans la prochaine ligne jaune. Les calculs se mettent a jour automatiquement.
B4: N° | C4: Mois | D4: Annee | E4: Nb Actions Realisees | F4: Nb Participants | G4: Heures Formation | H4: Cout (FCFA) | I4: Taux Realisation PAF (%)
B5: SM-001 | C5: Janvier | D5: 2025 | E5: 0 | F5: 0 | G5: 0 | H5: 0 | I5: 0
B6: SM-002 | C6: Fevrier | D6: 2025 | E6: 1 | F6: 15 | G6: 4 | H6: 7500 | I6: 10
B7: SM-003 | C7: Mars | D7: 2025 | E7: 1 | F7: 8 | G7: 20 | H7: 250000 | I7: 10
B8: SM-004 | C8: Avril | D8: 2025 | E8: 1 | F8: 6 | G8: 30 | H8: 180000 | I8: 10
B9: SM-005 | C9: Mai | D9: 2025 | E9: 0 | F9: 0 | G9: 0 | H9: 0 | I9: 0
B10: SM-006 | C10: Juin | D10: 2025 | E10: 1 | F10: 5 | G10: 12 | H10: 96000 | I10: 10
B11: =IF(C11="","SM-"&TEXT(COUNTA($C$5:C11),"000"))
B12: =IF(C12="","SM-"&TEXT(COUNTA($C$5:C12),"000"))
B13: =IF(C13="","SM-"&TEXT(COUNTA($C$5:C13),"000"))
B14: =IF(C14="","SM-"&TEXT(COUNTA($C$5:C14),"000"))
B15: =IF(C15="","SM-"&TEXT(COUNTA($C$5:C15),"000"))
B16: =IF(C16="","SM-"&TEXT(COUNTA($C$5:C16),"000"))
B17: =IF(C17="","SM-"&TEXT(COUNTA($C$5:C17),"000"))
B18: =IF(C18="","SM-"&TEXT(COUNTA($C$5:C18),"000"))
B19: =IF(C19="","SM-"&TEXT(COUNTA($C$5:C19),"000"))
B20: =IF(C20="","SM-"&TEXT(COUNTA($C$5:C20),"000"))
B21: =IF(C21="","SM-"&TEXT(COUNTA($C$5:C21),"000"))
B22: =IF(C22="","SM-"&TEXT(COUNTA($C$5:C22),"000"))
... B110: =IF(C110="","SM-"&TEXT(COUNTA($C$5:C110),"000"))
B112: TOTAL | E112: =SUM(E5:E104) | F112: =SUM(F5:F104) | G112: =SUM(G5:G104) | H112: =SUM(H5:H104)
B114: INDICATEURS (mis a jour automatiquement)
