Workbook

Sheet _Données Employés
A1: Matricule | B1: Nom | C1: Prénom | D1: Département | E1: Poste | F1: Salaire Brut | G1: Genre | H1: Date Embauche
A2: EMP-001 | B2: Nganou | C2: Clarisse | D2: Cuisine & Restauration | E2: Chef | F2: 450000 | G2: F | H2: 2020-01-15
A3: EMP-002 | B3: Tagne | C3: René | D3: Réception & Front Office | E3: Réceptionniste | F3: 165000 | G3: H | H3: 2019-06-01
A4: EMP-003 | B4: Fotso | C4: Camille | D4: Cuisine & Restauration | E4: Cuisinier | F4: 180000 | G4: H | H4: 2021-03-10
A5: EMP-004 | B5: Tchinda | C5: Arlette | D5: Service Client | E5: Assistante RH | F5: 200000 | G5: F | H5: 2022-09-01
A6: EMP-005 | B6: Ngansop | C6: Sylvie | D6: Finance & Comptabilité | E6: Comptable senior | F6: 250000 | G6: F | H6: 2018-02-20
A7: EMP-006 | B7: Fokam | C7: Eric | D7: Réception & Front Office | E7: Chef Réception | F7: 280000 | G7: H | H7: 2017-08-15
A8: EMP-007 | B8: Tchouankou | C8: Paul | D8: Étage & Housekeeping | E8: Chef Étage | F8: 230000 | G8: H | H8: 2020-11-01
A9: EMP-008 | B9: Awa | C9: Fatou | D9: Commercial | E9: Agent Commercial | F9: 155000 | G9: F | H9: 2023-01-15
A10: EMP-009 | B10: Bouba | C10: Ahmed | D10: Cuisine & Restauration | E10: Sous-Chef | F10: 210000 | G10: H | H10: 2019-04-01
A11: EMP-010 | B11: Kamga | C11: Patrice | D11: Sécurité | E11: Chef Sécurité | F11: 210000 | G11: H | H11: 2021-07-01
A12: EMP-011 | B12: Ngo | C12: Delphine | D12: Marketing & Communication | E12: Chef Marketing | F12: 300000 | G12: F | H12: 2018-05-15
A13: EMP-012 | B13: Tamo | C13: Elvis | D13: Logistique & Approvisionnement | E13: Chef Logistique | F13: 240000 | G13: H | H13: 2022-03-01
... A15: EMP-014 | B15: Kane | C15: Adama | D15: Direction Générale | E15: DAF | F15: 350000 | G15: H | H15: 2016-01-10

Sheet 1-Tableau de Bord
B2: DOMAINE 16 — DIVERSITE, EQUITE & INCLUSION
B3: TABLEAU DE BORD — Vue synthetique de tous les indicateurs du domaine (mis a jour automatiquement)
B5: % femmes global | E5: Services conformes parite | H5: Pers. handicapees | K5: Actions diversite
B6: =IFERROR(SUM('2-Parite Homme Femme'!F5:F104)/SUM('2-Parite Homme Femme'!G5:G104),0) | E6: =COUNTIF('2-Parite Homme Femme'!K5:K104,"Conforme") | H6: =COUNTIF('3-Emploi Pers. Handicapees'!B5:B104,"<>") | K6: =COUNTIF('5-Plan Action Diversite'!B5:B104,"<>")
B9: Effectif total suivi | E9: Categories diversite | H9: Budget plan action | K9: Services non conformes
B10: =SUM('4-Suivi Diversite'!E5:E104) | E10: =COUNTIF('4-Suivi Diversite'!B5:B104,"<>") | H10: =SUM('5-Plan Action Diversite'!H5:H104) | K10: =COUNTIF('2-Parite Homme Femme'!K5:K104,"Non conforme")
B14: REPARTITION PAR SERVICE & DIVERSITE PAR CRITERE
B15: Service | C15: Hommes | D15: Femmes
B16: Direction Générale | C16: =IFERROR(INDEX('2-Parite Homme Femme'!E:E,MATCH("Direction Générale",'2-Parite Homme Femme'!C:C,0)),0) | D16: =IFERROR(INDEX('2-Parite Homme Femme'!F:F,MATCH("Direction Générale",'2-Parite Homme Femme'!C:C,0)),0)
B17: Service Client | C17: =IFERROR(INDEX('2-Parite Homme Femme'!E:E,MATCH("Service Client",'2-Parite Homme Femme'!C:C,0)),0) | D17: =IFERROR(INDEX('2-Parite Homme Femme'!F:F,MATCH("Service Client",'2-Parite Homme Femme'!C:C,0)),0)
B18: Réception & Front Office | C18: =IFERROR(INDEX('2-Parite Homme Femme'!E:E,MATCH("Réception & Front Office",'2-Parite Homme Femme'!C:C,0)),0) | D18: =IFERROR(INDEX('2-Parite Homme Femme'!F:F,MATCH("Réception & Front Office",'2-Parite Homme Femme'!C:C,0)),0)
B19: Cuisine & Restauration | C19: =IFERROR(INDEX('2-Parite Homme Femme'!E:E,MATCH("Cuisine & Restauration",'2-Parite Homme Femme'!C:C,0)),0) | D19: =IFERROR(INDEX('2-Parite Homme Femme'!F:F,MATCH("Cuisine & Restauration",'2-Parite Homme Femme'!C:C,0)),0)
B20: Maintenance | C20: =IFERROR(INDEX('2-Parite Homme Femme'!E:E,MATCH("Maintenance",'2-Parite Homme Femme'!C:C,0)),0) | D20: =IFERROR(INDEX('2-Parite Homme Femme'!F:F,MATCH("Maintenance",'2-Parite Homme Femme'!C:C,0)),0)
B21: Sécurité | C21: =IFERROR(INDEX('2-Parite Homme Femme'!E:E,MATCH("Sécurité",'2-Parite Homme Femme'!C:C,0)),0) | D21: =IFERROR(INDEX('2-Parite Homme Femme'!F:F,MATCH("Sécurité",'2-Parite Homme Femme'!C:C,0)),0)
H23: Tranche Age | I23: Effectif
H24: 18-25 ans | I24: =IFERROR(INDEX('4-Suivi Diversite'!E:E,MATCH("18-25 ans",'4-Suivi Diversite'!D:D,0)),0)
H25: 26-35 ans | I25: =IFERROR(INDEX('4-Suivi Diversite'!E:E,MATCH("26-35 ans",'4-Suivi Diversite'!D:D,0)),0)
H26: 36-45 ans | I26: =IFERROR(INDEX('4-Suivi Diversite'!E:E,MATCH("36-45 ans",'4-Suivi Diversite'!D:D,0)),0)
H27: 46-55 ans | I27: =IFERROR(INDEX('4-Suivi Diversite'!E:E,MATCH("46-55 ans",'4-Suivi Diversite'!D:D,0)),0)
H28: 56 ans et + | I28: =IFERROR(INDEX('4-Suivi Diversite'!E:E,MATCH("56 ans et +",'4-Suivi Diversite'!D:D,0)),0)

Sheet _Lists
B1: genre | C1: departement | D1: poste_hotel | E1: categorie_pro | F1: tranche_age | G1: type_handicap | H1: niveau_amenagement | I1: statut_emploi_handicap | J1: origine_region | K1: nationalite | L1: statut_diversite | M1: statut_action | N1: criteres_diversite
B2: Homme | C2: Direction Générale | D2: DG | E2: Cadre dirigeant | F2: 18-25 ans | G2: Moteur | H2: Aucun necessaire | I2: En poste | J2: Centre | K2: Camerounaise | L2: Conforme | M2: Planifiee | N2: Age
B3: Femme | C3: Service Client | D3: DRH | E3: Cadre | F3: 26-35 ans | G3: Visuel | H3: Amenagement leger (materiel) | I3: En cours de recrutement | J3: Littoral | K3: Nigeriane | L3: En cours d'amelioration | M3: En cours | N3: Origine
C4: Finance & Comptabilité | D4: Assistante RH | E4: Agent de maitrise | F4: 36-45 ans | G4: Auditif | H4: Amenagement modere (poste adapte) | I4: Entretien realise | J4: Ouest | K4: Ghanaeenne | L4: Non conforme | M4: Terminee | N4: Nationalite
C5: Marketing & Communication | D5: DAF | E5: Employe | F5: 46-55 ans | G5: Mental | H5: Amenagement lourd (infrastructure) | I5: Candidature en attente | J5: Nord-Ouest | K5: Ivoirienne | L5: En attente de donnees | M5: Reportee | N5: Genre
C6: Maintenance | D6: Comptable senior | E6: Stagiaire | F6: 56 ans et + | G6: Maladie chronique | H6: Accompagnement specialise | I6: Non retenu | J6: Sud-Ouest | K6: Senegalaise | L6: Objectif atteint | M6: Annulee | N6: Handicap
C7: Commercial | D7: Chef Comptable | G7: Autre | I7: Formation en cours | J7: Sud | K7: Tchadienne | N7: Formation
C8: Logistique & Approvisionnement | D8: Chef Marketing | J8: Est | K8: Gabonaise | N8: Anciennete
C9: Cuisine & Restauration | D9: Chef de service IT | J9: Adamawa | K9: Autre
C10: Réception & Front Office | D10: Technicien IT | J10: Nord
C11: Sécurité | D11: Chef Commercial | J11: Extreme-Nord
C12: Étage & Housekeeping | D12: Agent Commercial
D13: Chef Logistique
D14: Magasinier
D15: Chef Reception
D16: Receptionniste
D17: Concierge
D18: Chef Cuisine
D19: Sous-Chef
D20: Cuisinier
D21: Plongeur
D22: Chef Entretien
D23: Agent Entretien
D24: Chef Sécurité
D25: Agent Sécurité

Sheet 2-Parite Homme Femme
B2: SUIVI DE LA PARITE HOMME/FEMME (#155)
B3: TABLEAU DYNAMIQUE — Saisissez dans la prochaine ligne jaune. Les calculs se mettent a jour automatiquement.
B4: N° | C4: Service | D4: Categorie Pro. | E4: Hommes | F4: Femmes | G4: Total | H4: % Femmes | I4: Ecart Parite | J4: Objectif % Femmes | K4: Statut
B5: PAR-001 | C5: Direction Générale | D5: Cadre dirigeant | E5: 3 | F5: 1 | J5: 0.4 | K5: En cours d'amelioration
B6: PAR-002 | C6: Service Client | D6: Cadre | E6: 1 | F6: 2 | J6: 0.5 | K6: Conforme
B7: PAR-003 | C7: Réception & Front Office | D7: Employe | E7: 6 | F7: 8 | J7: 0.5 | K7: Conforme
B8: PAR-004 | C8: Cuisine & Restauration | D8: Employe | E8: 15 | F8: 7 | J8: 0.35 | K8: En cours d'amelioration
B9: PAR-005 | C9: Maintenance | D9: Employe | E9: 8 | F9: 2 | J9: 0.3 | K9: Non conforme
B10: PAR-006 | C10: Sécurité | D10: Employe | E10: 10 | F10: 0 | J10: 0.25 | K10: Non conforme
B11: PAR-007 | C11: Finance & Comptabilité | D11: Cadre | E11: 2 | F11: 2 | J11: 0.45 | K11: Conforme
B12: PAR-008 | C12: Informatique | D12: Cadre | E12: 2 | F12: 0 | J12: 0.3 | K12: Non conforme
B13: =IF(C13="","PAR-"&TEXT(COUNTA($C$5:C13),"000")) | G13: =E13+F13 | H13: =IF(G13="","",F13/G13) | I13: =IF(G13="","",E13-F13)
B14: =IF(C14="","PAR-"&TEXT(COUNTA($C$5:C14),"000")) | G14: =E14+F14 | H14: =IF(G14="","",F14/G14) | I14: =IF(G14="","",E14-F14)
B15: =IF(C15="","PAR-"&TEXT(COUNTA($C$5:C15),"000")) | G15: =E15+F15 | H15: =IF(G15="","",F15/G15) | I15: =IF(G15="","",E15-F15)
B16: =IF(C16="","PAR-"&TEXT(COUNTA($C$5:C16),"000")) | G16: =E16+F16 | H16: =IF(G16="","",F16/G16) | I16: =IF(G16="","",E16-F16)
B17: =IF(C17="","PAR-"&TEXT(COUNTA($C$5:C17),"000")) | G17: =E17+F17 | H17: =IF(G17="","",F17/G17) | I17: =IF(G17="","",E17-F17)
B18: =IF(C18="","PAR-"&TEXT(COUNTA($C$5:C18),"000")) | G18: =E18+F18 | H18: =IF(G18="","",F18/G18) | I18: =IF(G18="","",E18-F18)
B19: =IF(C19="","PAR-"&TEXT(COUNTA($C$5:C19),"000")) | G19: =E19+F19 | H19: =IF(G19="","",F19/G19) | I19: =IF(G19="","",E19-F19)
B20: =IF(C20="","PAR-"&TEXT(COUNTA($C$5:C20),"000")) | G20: =E20+F20 | H20: =IF(G20="","",F20/G20) | I20: =IF(G20="","",E20-F20)
B21: =IF(C21="","PAR-"&TEXT(COUNTA($C$5:C21),"000")) | G21: =E21+F21 | H21: =IF(G21="","",F21/G21) | I21: =IF(G21="","",E21-F21)
B22: =IF(C22="","PAR-"&TEXT(COUNTA($C$5:C22),"000")) | G22: =E22+F22 | H22: =IF(G22="","",F22/G22) | I22: =IF(G22="","",E22-F22)
B23: =IF(C23="","PAR-"&TEXT(COUNTA($C$5:C23),"000")) | G23: =E23+F23 | H23: =IF(G23="","",F23/G23) | I23: =IF(G23="","",E23-F23)
B24: =IF(C24="","PAR-"&TEXT(COUNTA($C$5:C24),"000")) | G24: =E24+F24 | H24: =IF(G24="","",F24/G24) | I24: =IF(G24="","",E24-F24)
... B112: =IF(C112="","PAR-"&TEXT(COUNTA($C$5:C112),"000")) | G112: =E112+F112 | H112: =IF(G112="","",F112/G112) | I112: =IF(G112="","",E112-F112)
B114: TOTAL | E114: =SUM(E5:E104) | F114: =SUM(F5:F104) | G114: =SUM(G5:G104)
B116: INDICATEURS (mis a jour automatiquement)
B117: Services analyses | D117: % femmes global | F117: Services conformes
B118: =COUNTIF(B5:B104,"<>") | D118: =IFERROR(SUM(F5:F104)/SUM(G5:G104),0) | F118: =COUNTIF(K5:K104,"Conforme")

Sheet 3-Emploi Pers. Handicapees
B2: GESTION EMPLOI PERSONNES HANDICAPEES (#156)
B3: TABLEAU DYNAMIQUE — Saisissez dans la prochaine ligne jaune. Les calculs se mettent a jour automatiquement.
B4: N° | C4: Employe | D4: Poste | E4: Service | F4: Type Handicap | G4: Niveau Amenagement | H4: Date Embauche | I4: Salaire Brut (FCFA) | J4: Amenagement Realise | K4: Date Revision Med. | L4: Statut
B5: EMP-001 | C5: Nga A. | D5: Standardiste | E5: Réception & Front Office | F5: Auditif | G5: Amenagement leger (materiel) | H5: 44635 | I5: 165000 | J5: Telephone amplifie, eclairage special | K5: 45915 | L5: En poste
B6: EMP-002 | C6: Tagne M. | D6: Plongeur | E6: Cuisine & Restauration | F6: Moteur | G6: Amenagement modere (poste adapte) | H6: 45078 | I6: 145000 | J6: Tapis anti-glissade, siege adapte | K6: 45992 | L6: En poste
B7: EMP-003 | C7: Foumane P. | D7: Gardien jour | E7: Sécurité | F7: Visuel | G7: Amenagement leger (materiel) | H7: 45301 | I7: 150000 | J7: Eclairage renforce, lunettes speciales | K7: 45848 | L7: En poste
B8: =IF(C8="","EMP-"&TEXT(COUNTA($C$5:C8),"000"))
B9: =IF(C9="","EMP-"&TEXT(COUNTA($C$5:C9),"000"))
B10: =IF(C10="","EMP-"&TEXT(COUNTA($C$5:C10),"000"))
B11: =IF(C11="","EMP-"&TEXT(COUNTA($C$5:C11),"000"))
B12: =IF(C12="","EMP-"&TEXT(COUNTA($C$5:C12),"000"))
B13: =IF(C13="","EMP-"&TEXT(COUNTA($C$5:C13),"000"))
B14: =IF(C14="","EMP-"&TEXT(COUNTA($C$5:C14),"000"))
B15: =IF(C15="","EMP-"&TEXT(COUNTA($C$5:C15),"000"))
B16: =IF(C16="","EMP-"&TEXT(COUNTA($C$5:C16),"000"))
B17: =IF(C17="","EMP-"&TEXT(COUNTA($C$5:C17),"000"))
B18: =IF(C18="","EMP-"&TEXT(COUNTA($C$5:C18),"000"))
B19: =IF(C19="","EMP-"&TEXT(COUNTA($C$5:C19),"000"))
... B107: =IF(C107="","EMP-"&TEXT(COUNTA($C$5:C107),"000"))
B109: INDICATEURS (mis a jour automatiquement)
B110: Pers. handicapees | D110: En poste
B111: =COUNTIF(B5:B104,"<>") | D111: =COUNTIF(L5:L104,"En poste")

Sheet 4-Suivi Diversite
B2: SUIVI DE LA DIVERSITE (Age, Origine, Nationalite) (#157)
B3: TABLEAU DYNAMIQUE — Saisissez dans la prochaine ligne jaune. Les calculs se mettent a jour automatiquement.
B4: N° | C4: Criteres Diversite | D4: Categorie | E4: Effectif | F4: % Total | G4: Cadres | H4: % Cadres | I4: Observations
B5: DIV-001 | C5: Age | D5: 18-25 ans | E5: 18 | G5: 1 | I5: Majorite stagiaires et nouveaux
B6: DIV-002 | C6: Age | D6: 26-35 ans | E6: 40 | G6: 8 | I6: Noyau dur de l'effectif
B7: DIV-003 | C7: Age | D7: 36-45 ans | E7: 18 | G7: 5 | I7: Equilibre correct
B8: DIV-004 | C8: Age | D8: 46-55 ans | E8: 8 | G8: 2 | I8: Experience valorisee
B9: DIV-005 | C9: Age | D9: 56 ans et + | E9: 5 | G9: 1 | I9: Seniors a valoriser
B10: DIV-006 | C10: Origine | D10: Centre | E10: 20 | G10: 5 | I10: Region majoritaire
B11: DIV-007 | C11: Origine | D11: Littoral | E11: 30 | G11: 7 | I11: Douala et environs
B12: DIV-008 | C12: Origine | D12: Ouest | E12: 15 | G12: 3 | I12: Bamileke representes
B13: DIV-009 | C13: Origine | D13: Nord-Ouest | E13: 10 | G13: 1 | I13: Sous-representation cadres
B14: DIV-010 | C14: Origine | D14: Autres regions | E14: 14 | G14: 1 | I14: Diversite acceptable
B15: DIV-011 | C15: Nationalite | D15: Camerounaise | E15: 85 | G15: 17 | I15: Majorite ecrasante
B16: DIV-012 | C16: Nationalite | D16: Etrangere | E16: 4 | G16: 0 | I16: Manque cadres etrangers
B17: =IF(C17="","DIV-"&TEXT(COUNTA($C$5:C17),"000")) | F17: =IF(E17="","",IF(SUM(E5:E104)=0,"",E17/SUM(E5:E104))) | H17: =IF(OR(G17="",G17=0),"",G17/SUM(G5:G104))
B18: =IF(C18="","DIV-"&TEXT(COUNTA($C$5:C18),"000")) | F18: =IF(E18="","",IF(SUM(E5:E104)=0,"",E18/SUM(E5:E104))) | H18: =IF(OR(G18="",G18=0),"",G18/SUM(G5:G104))
B19: =IF(C19="","DIV-"&TEXT(COUNTA($C$5:C19),"000")) | F19: =IF(E19="","",IF(SUM(E5:E104)=0,"",E19/SUM(E5:E104))) | H19: =IF(OR(G19="",G19=0),"",G19/SUM(G5:G104))
B20: =IF(C20="","DIV-"&TEXT(COUNTA($C$5:C20),"000")) | F20: =IF(E20="","",IF(SUM(E5:E104)=0,"",E20/SUM(E5:E104))) | H20: =IF(OR(G20="",G20=0),"",G20/SUM(G5:G104))
B21: =IF(C21="","DIV-"&TEXT(COUNTA($C$5:C21),"000")) | F21: =IF(E21="","",IF(SUM(E5:E104)=0,"",E21/SUM(E5:E104))) | H21: =IF(OR(G21="",G21=0),"",G21/SUM(G5:G104))
B22: =IF(C22="","DIV-"&TEXT(COUNTA($C$5:C22),"000")) | F22: =IF(E22="","",IF(SUM(E5:E104)=0,"",E22/SUM(E5:E104))) | H22: =IF(OR(G22="",G22=0),"",G22/SUM(G5:G104))
B23: =IF(C23="","DIV-"&TEXT(COUNTA($C$5:C23),"000")) | F23: =IF(E23="","",IF(SUM(E5:E104)=0,"",E23/SUM(E5:E104))) | H23: =IF(OR(G23="",G23=0),"",G23/SUM(G5:G104))
B24: =IF(C24="","DIV-"&TEXT(COUNTA($C$5:C24),"000")) | F24: =IF(E24="","",IF(SUM(E5:E104)=0,"",E24/SUM(E5:E104))) | H24: =IF(OR(G24="",G24=0),"",G24/SUM(G5:G104))
B25: =IF(C25="","DIV-"&TEXT(COUNTA($C$5:C25),"000")) | F25: =IF(E25="","",IF(SUM(E5:E104)=0,"",E25/SUM(E5:E104))) | H25: =IF(OR(G25="",G25=0),"",G25/SUM(G5:G104))
B26: =IF(C26="","DIV-"&TEXT(COUNTA($C$5:C26),"000")) | F26: =IF(E26="","",IF(SUM(E5:E104)=0,"",E26/SUM(E5:E104))) | H26: =IF(OR(G26="",G26=0),"",G26/SUM(G5:G104))
B27: =IF(C27="","DIV-"&TEXT(COUNTA($C$5:C27),"000")) | F27: =IF(E27="","",IF(SUM(E5:E104)=0,"",E27/SUM(E5:E104))) | H27: =IF(OR(G27="",G27=0),"",G27/SUM(G5:G104))
B28: =IF(C28="","DIV-"&TEXT(COUNTA($C$5:C28),"000")) | F28: =IF(E28="","",IF(SUM(E5:E104)=0,"",E28/SUM(E5:E104))) | H28: =IF(OR(G28="",G28=0),"",G28/SUM(G5:G104))
B29: =IF(C29="","DIV-"&TEXT(COUNTA($C$5:C29),"000")) | F29: =IF(E29="","",IF(SUM(E5:E104)=0,"",E29/SUM(E5:E104))) | H29: =IF(OR(G29="",G29=0),"",G29/SUM(G5:G104))
B30: =IF(C30="","DIV-"&TEXT(COUNTA($C$5:C30),"000")) | F30: =IF(E30="","",IF(SUM(E5:E104)=0,"",E30/SUM(E5:E104))) | H30: =IF(OR(G30="",G30=0),"",G30/SUM(G5:G104))
B31: =IF(C31="","DIV-"&TEXT(COUNTA($C$5:C31),"000")) | F31: =IF(E31="","",IF(SUM(E5:E104)=0,"",E31/SUM(E5:E104))) | H31: =IF(OR(G31="",G31=0),"",G31/SUM(G5:G104))
B32: =IF(C32="","DIV-"&TEXT(COUNTA($C$5:C32),"000")) | F32: =IF(E32="","",IF(SUM(E5:E104)=0,"",E32/SUM(E5:E104))) | H32: =IF(OR(G32="",G32=0),"",G32/SUM(G5:G104))
B33: =IF(C33="","DIV-"&TEXT(COUNTA($C$5:C33),"000")) | F33: =IF(E33="","",IF(SUM(E5:E104)=0,"",E33/SUM(E5:E104))) | H33: =IF(OR(G33="",G33=0),"",G33/SUM(G5:G104))
B34: =IF(C34="","DIV-"&TEXT(COUNTA($C$5:C34),"000")) | F34: =IF(E34="","",IF(SUM(E5:E104)=0,"",E34/SUM(E5:E104))) | H34: =IF(OR(G34="",G34=0),"",G34/SUM(G5:G104))
B35: =IF(C35="","DIV-"&TEXT(COUNTA($C$5:C35),"000")) | F35: =IF(E35="","",IF(SUM(E5:E104)=0,"",E35/SUM(E5:E104))) | H35: =IF(OR(G35="",G35=0),"",G35/SUM(G5:G104))
B36: =IF(C36="","DIV-"&TEXT(COUNTA($C$5:C36),"000")) | F36: =IF(E36="","",IF(SUM(E5:E104)=0,"",E36/SUM(E5:E104))) | H36: =IF(OR(G36="",G36=0),"",G36/SUM(G5:G104))
B37: =IF(C37="","DIV-"&TEXT(COUNTA($C$5:C37),"000")) | F37: =IF(E37="","",IF(SUM(E5:E104)=0,"",E37/SUM(E5:E104))) | H37: =IF(OR(G37="",G37=0),"",G37/SUM(G5:G104))
B38: =IF(C38="","DIV-"&TEXT(COUNTA($C$5:C38),"000")) | F38: =IF(E38="","",IF(SUM(E5:E104)=0,"",E38/SUM(E5:E104))) | H38: =IF(OR(G38="",G38=0),"",G38/SUM(G5:G104))
B39: =IF(C39="","DIV-"&TEXT(COUNTA($C$5:C39),"000")) | F39: =IF(E39="","",IF(SUM(E5:E104)=0,"",E39/SUM(E5:E104))) | H39: =IF(OR(G39="",G39=0),"",G39/SUM(G5:G104))
B40: =IF(C40="","DIV-"&TEXT(COUNTA($C$5:C40),"000")) | F40: =IF(E40="","",IF(SUM(E5:E104)=0,"",E40/SUM(E5:E104))) | H40: =IF(OR(G40="",G40=0),"",G40/SUM(G5:G104))
B41: =IF(C41="","DIV-"&TEXT(COUNTA($C$5:C41),"000")) | F41: =IF(E41="","",IF(SUM(E5:E104)=0,"",E41/SUM(E5:E104))) | H41: =IF(OR(G41="",G41=0),"",G41/SUM(G5:G104))
...

Sheet 5-Plan Action Diversite
B2: PLAN D'ACTION DIVERSITE & INCLUSION (#158)
B3: TABLEAU DYNAMIQUE — Saisissez dans la prochaine ligne jaune. Les calculs se mettent a jour automatiquement.
B4: N° | C4: Action | D4: Objectif Diversite | E4: Cible | F4: Indicateur de Succes | G4: Valeur Initiale | H4: Objectif | I4: Budget (FCFA) | J4: Responsable | K4: Echeance | L4: Statut
B5: PAD-001 | C5: Recrutement femmes securite | D5: Parite H/F | E5: Service Sécurité | F5: % femmes securite | G5: 0 | H5: 0.25 | I5: 50000 | J5: DRH + Chef Sécurité | K5: 46022 | L5: En cours
B6: PAD-002 | C6: Amenagement postes handicapes | D6: Inclusion handicap | E6: Tous services | F6: Nb postes amenages | G6: 3 | H6: 6 | I6: 300000 | J6: DRH + Chef Entretien | K6: 46203 | L6: En cours
B7: PAD-003 | C7: Formation sensibilisation diversite | D7: Diversite culturelle | E7: Cadres et managers | F7: Nb personnes formees | G7: 0 | H7: 30 | I7: 200000 | J7: DRH | K7: 45930 | L7: Planifiee
B8: PAD-004 | C8: Audit salarial par genre | D8: Equite salariale | E8: Tous services | F8: Ecart salarial H/F (%) | G8: 0.15 | H8: 0.05 | I8: 150000 | J8: DRH + DAF | K8: 45961 | L8: Planifiee
B9: PAD-005 | C9: Programme tutorat jeunes | D9: Diversite d'age | E9: 18-25 ans | F9: Nb jeunes encadres | G9: 0 | H9: 10 | I9: 100000 | J9: DRH | K9: 46112 | L9: En cours
B10: =IF(C10="","PAD-"&TEXT(COUNTA($C$5:C10),"000"))
B11: =IF(C11="","PAD-"&TEXT(COUNTA($C$5:C11),"000"))
B12: =IF(C12="","PAD-"&TEXT(COUNTA($C$5:C12),"000"))
B13: =IF(C13="","PAD-"&TEXT(COUNTA($C$5:C13),"000"))
B14: =IF(C14="","PAD-"&TEXT(COUNTA($C$5:C14),"000"))
B15: =IF(C15="","PAD-"&TEXT(COUNTA($C$5:C15),"000"))
B16: =IF(C16="","PAD-"&TEXT(COUNTA($C$5:C16),"000"))
B17: =IF(C17="","PAD-"&TEXT(COUNTA($C$5:C17),"000"))
B18: =IF(C18="","PAD-"&TEXT(COUNTA($C$5:C18),"000"))
B19: =IF(C19="","PAD-"&TEXT(COUNTA($C$5:C19),"000"))
B20: =IF(C20="","PAD-"&TEXT(COUNTA($C$5:C20),"000"))
B21: =IF(C21="","PAD-"&TEXT(COUNTA($C$5:C21),"000"))
... B109: =IF(C109="","PAD-"&TEXT(COUNTA($C$5:C109),"000"))
B111: TOTAL | I111: =SUM(I5:I104)
B113: INDICATEURS (mis a jour automatiquement)
B114: Actions planifiees | D114: Budget total | F114: En cours | H114: Planifiees
B115: =COUNTIF(B5:B104,"<>") | D115: =SUM(I5:I104) | F115: =COUNTIF(L5:L104,"En cours") | H115: =COUNTIF(L5:L104,"Planifiee")
