Workbook

Sheet F01 - _Données Retraite
A2: DONNÉES PERSONNEL RETRAITE — Base de référence gestion des départs
A3: TABLEAU DYNAMIQUE — Saisissez dans la zone prévue ci-dessous
A5: Matricule | B5: Nom | C5: Prénom | D5: Nationalité | E5: Département | F5: Poste | G5: Catégorie | H5: Âge | I5: Genre | J5: Situation Fam. | K5: Nb Enfants
A6: RET-001 | B6: Konan | C6: Yao | D6: Ivoirienne | E6: Direction Générale | F6: Directeur Général Adjoint | G6: Cadre | H6: 58 | I6: M | J6: Marié(e) | K6: 3
A7: RET-002 | B7: Touré | C7: Aminata | D7: Ivoirienne | E7: Finance & Comptabilité | F7: Directrice Financière | G7: Cadre | H7: 57 | I7: F | J7: Marié(e) | K7: 2
A8: RET-003 | B8: Diop | C8: Moussa | D8: Sénégalaise | E8: Ressources Humaines | F8: DRH Senior | G8: Cadre | H8: 60 | I8: M | J8: Marié(e) | K8: 4
A9: RET-004 | B9: Bamba | C9: Fatou | D9: Ivoirienne | E9: Administration | F9: Resp. Administrative | G9: Agent de maîtrise | H9: 55 | I9: F | J9: Veuve(ve) | K9: 1
A10: RET-005 | B10: Nguyen | C10: Tien | D10: Vietnamienne | E10: Informatique | F10: DSI | G10: Cadre | H10: 59 | I10: M | J10: Marié(e) | K10: 2
A11: RET-006 | B11: Moreau | C11: Pierre | D11: Française | E11: Commercial | F11: Directeur Commercial | G11: Cadre | H11: 61 | I11: M | J11: Divorcé(e) | K11: 1
A12: RET-007 | B12: Osei | C12: Kwame | D12: Ghanéenne | E12: Logistique | F12: Chef Logistique | G12: Agent de maîtrise | H12: 54 | I12: M | J12: Marié(e) | K12: 3
A13: RET-008 | B13: Dubois | C13: Marie | D13: Française | E13: Ressources Humaines | F13: Resp. Paie | G13: Non-cadre | H13: 56 | I13: F | J13: Célibataire | K13: 0
A14: RET-009 | B14: Aka | C14: Jean | D14: Ivoirienne | E14: Entretien | F14: Chef d'Équipe | G14: Agent de maîtrise | H14: 58 | I14: M | J14: Marié(e) | K14: 5
A15: RET-010 | B15: Petrov | C15: Ivan | D15: Russe | E15: Sécurité | F15: Resp. Sécurité | G15: Cadre | H15: 52 | I15: M | J15: Marié(e) | K15: 2
A16: RET-011 | B16: Konaté | C16: Awa | D16: Ivoirienne | E16: Service Client | F16: Resp. Relation Client | G16: Non-cadre | H16: 53 | I16: F | J16: Marié(e) | K16: 2
A17: RET-012 | B17: Laurent | C17: Jacques | D17: Française | E17: Technique | F17: Ingénieur Principal | G17: Cadre | H17: 60 | I17: M | J17: Marié(e) | K17: 3
... A20: RET-015 | B20: Essis | C20: N'Guessan | D20: Ivoirienne | E20: Hébergement | F20: Gouvernante Générale | G20: Agent de maîtrise | H20: 56 | I20: F | J20: Marié(e) | K20: 2

Sheet F02 - _Lists
A2: LISTES DE RÉFÉRENCE — Valeurs pour listes déroulantes
A3: TABLEAU DYNAMIQUE — Saisissez dans la zone prévue ci-dessous
A5: nationalites | B5: departements | C5: postes | D5: categories_personnel | E5: regimes_retraite | F5: statuts_retraite | G5: causes_depart | H5: types_depart | I5: dispositifs_prevoyance | J5: modes_paiement | K5: statuts_dossier | L5: priorites | M5: conformites | N5: statuts_action | O5: frequences | P5: mois | Q5: trimestres | R5: validations | S5: situation_familiale | T5: genres | U5: niveaux_pension | V5: types_outplacement | W5: statuts_transition | X5: types_risque_financier | Y5: tendances
A6: Ivoirienne | B6: Direction Générale | C6: Directeur Général Adjoint | D6: Cadre | E6: Régime Général CNPS | F6: Actif - Pré-retraite | G6: Âge légal | H6: Retraite anticipée | I6: Retraite complémentaire | J6: Virement bancaire | K6: En cours | L6: Haute | M6: Conforme | N6: En attente | O6: Mensuelle | P6: Janvier 2025 | Q6: T1 2025 | R6: Validé | S6: Célibataire | T6: M | U6: Pleine | V6: Reclassement interne | W6: Non commencé | X6: Risque longévité | Y6: Hausse
A7: Sénégalaise | B7: Ressources Humaines | C7: Directrice Financière | D7: Non-cadre | E7: Régime Cadre IRC | F7: Actif - Senior | G7: Départ anticipé | H7: Retraite normale (60 ans) | I7: Épargne retraite PER | J7: Chèque | K7: Instruit | L7: Moyenne | M7: Partiellement conforme | N7: En cours | O7: Trimestrielle | P7: Février 2025 | Q7: T2 2025 | R7: En attente | S7: Marié(e) | T7: F | U7: Réduite | V7: Bilan de compétences | W7: En préparation | X7: Risque inflation | Y7: Baisse
A8: Française | B8: Finance & Comptabilité | C8: DRH Senior | D8: Agent de maîtrise | E8: Régime Complémentaire AGIRC | F8: Retraité | G8: Invalidité | H8: Retraite tardive (65+ ans) | I8: Assurance décès | J8: Espèces | K8: Validé | L8: Basse | M8: Non conforme | N8: Terminé | O8: Semestrielle | P8: Mars 2025 | Q8: T3 2025 | R8: Rejeté | S8: Concubin(e) | U8: Minimale | V8: Coaching individuel | W8: En cours | X8: Risque réglementaire | Y8: Stable
A9: Vietnamienne | B9: Commercial | C9: Resp. Administrative | D9: Direction | E9: Régime Prévoyance Entreprise | F9: Mise à la retraite | G9: Volontaire | H9: Pré-retraite progressive | I9: Rente invalidité | J9: Virement international | K9: Rejeté | M9: En attente | N9: Reporté | O9: Annuelle | P9: Avril 2025 | Q9: T4 2025 | R9: Non applicable | S9: Divorcé(e) | U9: Majorée | V9: Formation reconversion | W9: Terminé | X9: Risque de rendement
A10: Ghanéenne | B10: Informatique | C10: DSI | E10: Régime Spécial Fonction Publique | F10: Départ volontaire | G10: Mise à la retraite employeur | H10: Mise à la retraite | I10: Capital décès | J10: Prélèvement automatique | K10: En attente pièce | M10: Non applicable | N10: Annulé | O10: Ponctuelle | P10: Mai 2025 | S10: Veuf(ve) | U10: Proportionnelle | V10: Aide à la création d'entreprise | W10: Abandonné | X10: Risque de change
A11: Russe | B11: Logistique | C11: Directeur Commercial | E11: Régime International Cotonou | F11: Pré-retraite progressive | G11: Rupture conventionnelle | H11: Démission négociée | I11: Sécurité sociale | K11: Transmis CNPS | P11: Juin 2025 | V11: Réseautage | W11: En évaluation | X11: Risque de liquidité
A12: Malianne | B12: Administration | C12: Chef Logistique | E12: Régime Bilatéral France-CI | F12: Retraite anticipée | G12: Décès | H12: Fin de contrat | I12: Couverture santé senior | K12: Clôturé | P12: Juillet 2025 | V12: Mise en disponibilité
A13: Japonaise | B13: Entretien | C13: Resp. Paie | E13: PERCO | F13: Rachat de trimestres | G13: Convention de fin de carrière | I13: Plan d'épargne entreprise | P13: Août 2025
A14: Camerounaise | B14: Service Client | C14: Chef d'Équipe | E14: REER | P14: Septembre 2025
A15: Belge | B15: Sécurité | C15: Resp. Sécurité | P15: Octobre 2025
A16: Suisse | B16: Formation | C16: Resp. Relation Client | P16: Novembre 2025
A17: Américaine | B17: Technique | C17: Ingénieur Principal | P17: Décembre 2025
A18: Britannique | B18: Qualité | C18: Formatrice Senior
A19: Marocaine | B19: Hébergement | C19: Directeur Qualité
A20: Congolaise | B20: Restauration | C20: Gouvernante Générale
A21: Béninoise | B21: Juridique | C21: Comptable Senior
A22: Nigériane | B22: Communication | C22: Chef de Projet
A23: Togolaise | C23: Contrôleur de Gestion
A24: Guinéenne
A25: Burkinabè

Sheet F03 - 1-Tableau de Bord
A2: DOMAINE 31 — GESTION DES RETRAITES, PRÉVOYANCE ET TRANSITIONS DE CARRIÈRE RH
A3: Tableau de Bord Synthétique — Retraites, prévoyance, successions et transitions
A5: INDICATEURS CLÉS
A6: Nb Départs Prochains 3 ans | C6: Budget Retraites (M FCFA) | E6: Dossiers en Cours | G6: Taux Conformité (%) | I6: Transitions Planifiées | K6: Risque Financier
A7: 15 | C7: 124.6 | E7: 8 | G7: 91 | I7: 5 | K7: Modéré
A9: RÉPARTITION PAR RÉGIME DE RETRAITE | I9: DÉPARTS PLANIFIÉS 2025-2028
A10: Régime | B10: Effectif | C10: Pension Moy. (kFCFA) | D10: Âge Moy. | E10: Conformité (%) | I10: Année | J10: Nb Départs | K10: Budget Estimé (M) | L10: Succession OK | M10: Alerte
A11: Régime Général CNPS | B11: 5 | C11: 185 | D11: 57.2 | E11: 95 | I11: 2025 | J11: 3 | K11: 28.5 | L11: 2/3 | M11: 1 sans successeur
A12: Régime Cadre IRC | B12: 4 | C12: 320 | D12: 59.5 | E12: 92 | I12: 2026 | J12: 4 | K12: 35.2 | L12: 3/4 | M12: Formation en cours
A13: Régime Complémentaire | B13: 3 | C13: 410 | D13: 58 | E13: 88 | I13: 2027 | J13: 5 | K13: 42.8 | L13: 2/5 | M13: 2 à planifier
A14: Régime International | B14: 2 | C14: 550 | D14: 56.5 | E14: 85 | I14: 2028 | J14: 3 | K14: 18.1 | L14: 1/3 | M14: Priorité haute
A15: PERCO | B15: 1 | C15: 280 | D15: 53 | E15: 90
A18: ACTIONS PLANIFIÉES
A19: Action | B19: Responsable | C19: Échéance | D19: Priorité | E19: Statut
A20: Dossier retraite Konan Y. | B20: Resp. Retraites | C20: 45838 | D20: Haute | E20: En cours
A21: Audit régimes prévoyance | B21: Contrôle de gestion | C21: 45747 | D21: Moyenne | E21: En cours
A22: Plan succession Touré A. | B22: DRH | C22: 45901 | D22: Haute | E22: En attente
A23: Renégociation contrat prévoyance | B23: DRH / Juridique | C23: 46006 | D23: Moyenne | E23: Planifié

Sheet F04 - 2-Dossiers Retraites
A2: 2-DOSSIERS DE RETRAITE
A3: TABLEAU DYNAMIQUE — Saisissez dans la zone prévue ci-dessous
A5: Code Dossier | B5: Matricule | C5: Régime Retraite | D5: Statut Retraite | E5: Date Demande | F5: Date Départ Prévu | G5: Âge Départ | H5: Trimestres Validés | I5: Pension Estimée (FCFA) | J5: Niveau Pension | K5: Conformité | L5: Observations
A6: DOS-001 | B6: RET-001 | C6: Régime Cadre IRC | D6: Actif - Pré-retraite | E6: 45672 | F6: 45838 | G6: =IF(A6="","",IFERROR(VLOOKUP(B6,'F01 - _Données Retraite'!$A$6:$K$20,8,FALSE),"")) | H6: 168 | I6: 480000 | K6: Conforme | L6: Proced. normal | M6: =IF(B6="","",IFERROR(VLOOKUP(B6,'F01 - _Données Retraite'!$A$6:$K$20,2,FALSE)&" "&VLOOKUP(B6,'F01 - _Données Retraite'!$A$6:$K$20,3,FALSE),"")) | N6: =IF(C6="","",IFERROR(COUNTIF($C$6:$C$115,C6),0))
A7: DOS-002 | B7: RET-002 | C7: Régime Cadre IRC | D7: Actif - Senior | E7: 45717 | F7: 46037 | G7: =IF(A7="","",IFERROR(VLOOKUP(B7,'F01 - _Données Retraite'!$A$6:$K$20,8,FALSE),"")) | H7: 162 | I7: 520000 | K7: Conforme | M7: =IF(B7="","",IFERROR(VLOOKUP(B7,'F01 - _Données Retraite'!$A$6:$K$20,2,FALSE)&" "&VLOOKUP(B7,'F01 - _Données Retraite'!$A$6:$K$20,3,FALSE),"")) | N7: =IF(C7="","",IFERROR(COUNTIF($C$6:$C$115,C7),0))
A8: DOS-003 | B8: RET-003 | C8: Régime Général CNPS | D8: Retraité | E8: 45444 | F8: 45657 | G8: =IF(A8="","",IFERROR(VLOOKUP(B8,'F01 - _Données Retraite'!$A$6:$K$20,8,FALSE),"")) | H8: 180 | I8: 350000 | K8: Conforme | L8: Déjà parti | M8: =IF(B8="","",IFERROR(VLOOKUP(B8,'F01 - _Données Retraite'!$A$6:$K$20,2,FALSE)&" "&VLOOKUP(B8,'F01 - _Données Retraite'!$A$6:$K$20,3,FALSE),"")) | N8: =IF(C8="","",IFERROR(COUNTIF($C$6:$C$115,C8),0))
A9: DOS-004 | B9: RET-005 | C9: Régime International | D9: Actif - Pré-retraite | E9: 45689 | F9: 46022 | G9: =IF(A9="","",IFERROR(VLOOKUP(B9,'F01 - _Données Retraite'!$A$6:$K$20,8,FALSE),"")) | H9: 155 | I9: 620000 | K9: En attente | L9: Convention bilatérale | M9: =IF(B9="","",IFERROR(VLOOKUP(B9,'F01 - _Données Retraite'!$A$6:$K$20,2,FALSE)&" "&VLOOKUP(B9,'F01 - _Données Retraite'!$A$6:$K$20,3,FALSE),"")) | N9: =IF(C9="","",IFERROR(COUNTIF($C$6:$C$115,C9),0))
A10: DOS-005 | B10: RET-006 | C10: Régime Complémentaire | D10: Retraité | E10: 45536 | F10: 45717 | G10: =IF(A10="","",IFERROR(VLOOKUP(B10,'F01 - _Données Retraite'!$A$6:$K$20,8,FALSE),"")) | H10: 172 | I10: 440000 | K10: Partiellement conforme | L10: Rachat en cours | M10: =IF(B10="","",IFERROR(VLOOKUP(B10,'F01 - _Données Retraite'!$A$6:$K$20,2,FALSE)&" "&VLOOKUP(B10,'F01 - _Données Retraite'!$A$6:$K$20,3,FALSE),"")) | N10: =IF(C10="","",IFERROR(COUNTIF($C$6:$C$115,C10),0))
G11: =IF(A11="","",IFERROR(VLOOKUP(B11,'F01 - _Données Retraite'!$A$6:$K$20,8,FALSE),"")) | M11: =IF(B11="","",IFERROR(VLOOKUP(B11,'F01 - _Données Retraite'!$A$6:$K$20,2,FALSE)&" "&VLOOKUP(B11,'F01 - _Données Retraite'!$A$6:$K$20,3,FALSE),"")) | N11: =IF(C11="","",IFERROR(COUNTIF($C$6:$C$115,C11),0))
G12: =IF(A12="","",IFERROR(VLOOKUP(B12,'F01 - _Données Retraite'!$A$6:$K$20,8,FALSE),"")) | M12: =IF(B12="","",IFERROR(VLOOKUP(B12,'F01 - _Données Retraite'!$A$6:$K$20,2,FALSE)&" "&VLOOKUP(B12,'F01 - _Données Retraite'!$A$6:$K$20,3,FALSE),"")) | N12: =IF(C12="","",IFERROR(COUNTIF($C$6:$C$115,C12),0))
G13: =IF(A13="","",IFERROR(VLOOKUP(B13,'F01 - _Données Retraite'!$A$6:$K$20,8,FALSE),"")) | M13: =IF(B13="","",IFERROR(VLOOKUP(B13,'F01 - _Données Retraite'!$A$6:$K$20,2,FALSE)&" "&VLOOKUP(B13,'F01 - _Données Retraite'!$A$6:$K$20,3,FALSE),"")) | N13: =IF(C13="","",IFERROR(COUNTIF($C$6:$C$115,C13),0))
G14: =IF(A14="","",IFERROR(VLOOKUP(B14,'F01 - _Données Retraite'!$A$6:$K$20,8,FALSE),"")) | M14: =IF(B14="","",IFERROR(VLOOKUP(B14,'F01 - _Données Retraite'!$A$6:$K$20,2,FALSE)&" "&VLOOKUP(B14,'F01 - _Données Retraite'!$A$6:$K$20,3,FALSE),"")) | N14: =IF(C14="","",IFERROR(COUNTIF($C$6:$C$115,C14),0))
G15: =IF(A15="","",IFERROR(VLOOKUP(B15,'F01 - _Données Retraite'!$A$6:$K$20,8,FALSE),"")) | M15: =IF(B15="","",IFERROR(VLOOKUP(B15,'F01 - _Données Retraite'!$A$6:$K$20,2,FALSE)&" "&VLOOKUP(B15,'F01 - _Données Retraite'!$A$6:$K$20,3,FALSE),"")) | N15: =IF(C15="","",IFERROR(COUNTIF($C$6:$C$115,C15),0))
G16: =IF(A16="","",IFERROR(VLOOKUP(B16,'F01 - _Données Retraite'!$A$6:$K$20,8,FALSE),"")) | M16: =IF(B16="","",IFERROR(VLOOKUP(B16,'F01 - _Données Retraite'!$A$6:$K$20,2,FALSE)&" "&VLOOKUP(B16,'F01 - _Données Retraite'!$A$6:$K$20,3,FALSE),"")) | N16: =IF(C16="","",IFERROR(COUNTIF($C$6:$C$115,C16),0))
G17: =IF(A17="","",IFERROR(VLOOKUP(B17,'F01 - _Données Retraite'!$A$6:$K$20,8,FALSE),"")) | M17: =IF(B17="","",IFERROR(VLOOKUP(B17,'F01 - _Données Retraite'!$A$6:$K$20,2,FALSE)&" "&VLOOKUP(B17,'F01 - _Données Retraite'!$A$6:$K$20,3,FALSE),"")) | N17: =IF(C17="","",IFERROR(COUNTIF($C$6:$C$115,C17),0))
G18: =IF(A18="","",IFERROR(VLOOKUP(B18,'F01 - _Données Retraite'!$A$6:$K$20,8,FALSE),"")) | M18: =IF(B18="","",IFERROR(VLOOKUP(B18,'F01 - _Données Retraite'!$A$6:$K$20,2,FALSE)&" "&VLOOKUP(B18,'F01 - _Données Retraite'!$A$6:$K$20,3,FALSE),"")) | N18: =IF(C18="","",IFERROR(COUNTIF($C$6:$C$115,C18),0))
G19: =IF(A19="","",IFERROR(VLOOKUP(B19,'F01 - _Données Retraite'!$A$6:$K$20,8,FALSE),"")) | M19: =IF(B19="","",IFERROR(VLOOKUP(B19,'F01 - _Données Retraite'!$A$6:$K$20,2,FALSE)&" "&VLOOKUP(B19,'F01 - _Données Retraite'!$A$6:$K$20,3,FALSE),"")) | N19: =IF(C19="","",IFERROR(COUNTIF($C$6:$C$115,C19),0))
G20: =IF(A20="","",IFERROR(VLOOKUP(B20,'F01 - _Données Retraite'!$A$6:$K$20,8,FALSE),"")) | M20: =IF(B20="","",IFERROR(VLOOKUP(B20,'F01 - _Données Retraite'!$A$6:$K$20,2,FALSE)&" "&VLOOKUP(B20,'F01 - _Données Retraite'!$A$6:$K$20,3,FALSE),"")) | N20: =IF(C20="","",IFERROR(COUNTIF($C$6:$C$115,C20),0))
G21: =IF(A21="","",IFERROR(VLOOKUP(B21,'F01 - _Données Retraite'!$A$6:$K$20,8,FALSE),"")) | M21: =IF(B21="","",IFERROR(VLOOKUP(B21,'F01 - _Données Retraite'!$A$6:$K$20,2,FALSE)&" "&VLOOKUP(B21,'F01 - _Données Retraite'!$A$6:$K$20,3,FALSE),"")) | N21: =IF(C21="","",IFERROR(COUNTIF($C$6:$C$115,C21),0))
G22: =IF(A22="","",IFERROR(VLOOKUP(B22,'F01 - _Données Retraite'!$A$6:$K$20,8,FALSE),"")) | M22: =IF(B22="","",IFERROR(VLOOKUP(B22,'F01 - _Données Retraite'!$A$6:$K$20,2,FALSE)&" "&VLOOKUP(B22,'F01 - _Données Retraite'!$A$6:$K$20,3,FALSE),"")) | N22: =IF(C22="","",IFERROR(COUNTIF($C$6:$C$115,C22),0))
... G115: =IF(A115="","",IFERROR(VLOOKUP(B115,'F01 - _Données Retraite'!$A$6:$K$20,8,FALSE),"")) | M115: =IF(B115="","",IFERROR(VLOOKUP(B115,'F01 - _Données Retraite'!$A$6:$K$20,2,FALSE)&" "&VLOOKUP(B115,'F01 - _Données Retraite'!$A$6:$K$20,3,FALSE),"")) | N115: =IF(C115="","",IFERROR(COUNTIF($C$6:$C$115,C115),0))

Sheet F05 - 3-Gestion Prévoyance
A2: 3-GESTION PRÉVOYANCE
A3: TABLEAU DYNAMIQUE — Saisissez dans la zone prévue ci-dessous
A5: Code Prév. | B5: Matricule | C5: Dispositif | D5: Montant Cotisation (FCFA) | E5: Part Employeur (FCFA) | F5: Part Salarié (FCFA) | G5: Total Mensuel (FCFA) | H5: Fréquence | I5: Mode Paiement | J5: Date Adhésion | K5: Statut | L5: Observations
A6: PREV-001 | B6: RET-001 | C6: Retraite complémentaire | D6: 180000 | E6: 120000 | F6: 60000 | G6: =IF(OR(D6="",E6=""),"",D6+E6) | H6: Mensuelle | I6: Virement bancaire | J6: 40179 | K6: Validé | M6: =IF(B6="","",IFERROR(VLOOKUP(B6,'F01 - _Données Retraite'!$A$6:$K$20,2,FALSE)&" "&VLOOKUP(B6,'F01 - _Données Retraite'!$A$6:$K$20,3,FALSE),"")) | N6: =IF(B6="","",IFERROR(SUMIF($B$6:$B$115,B6,$G$6:$G$115),0))
A7: PREV-002 | B7: RET-002 | C7: Épargne retraite PER | D7: 250000 | E7: 175000 | F7: 75000 | G7: =IF(OR(D7="",E7=""),"",D7+E7) | H7: Mensuelle | I7: Prélèvement auto. | J7: 39522 | K7: Validé | M7: =IF(B7="","",IFERROR(VLOOKUP(B7,'F01 - _Données Retraite'!$A$6:$K$20,2,FALSE)&" "&VLOOKUP(B7,'F01 - _Données Retraite'!$A$6:$K$20,3,FALSE),"")) | N7: =IF(B7="","",IFERROR(SUMIF($B$6:$B$115,B7,$G$6:$G$115),0))
A8: PREV-003 | B8: RET-003 | C8: Assurance décès | D8: 45000 | E8: 30000 | F8: 15000 | G8: =IF(OR(D8="",E8=""),"",D8+E8) | H8: Mensuelle | I8: Virement bancaire | J8: 38504 | K8: Validé | L8: Capital garanti 15M | M8: =IF(B8="","",IFERROR(VLOOKUP(B8,'F01 - _Données Retraite'!$A$6:$K$20,2,FALSE)&" "&VLOOKUP(B8,'F01 - _Données Retraite'!$A$6:$K$20,3,FALSE),"")) | N8: =IF(B8="","",IFERROR(SUMIF($B$6:$B$115,B8,$G$6:$G$115),0))
A9: PREV-004 | B9: RET-005 | C9: Couverture santé senior | D9: 95000 | E9: 63000 | F9: 32000 | G9: =IF(OR(D9="",E9=""),"",D9+E9) | H9: Mensuelle | I9: Virement bancaire | J9: 40909 | K9: En attente | M9: =IF(B9="","",IFERROR(VLOOKUP(B9,'F01 - _Données Retraite'!$A$6:$K$20,2,FALSE)&" "&VLOOKUP(B9,'F01 - _Données Retraite'!$A$6:$K$20,3,FALSE),"")) | N9: =IF(B9="","",IFERROR(SUMIF($B$6:$B$115,B9,$G$6:$G$115),0))
A10: PREV-005 | B10: RET-007 | C10: Rente invalidité | D10: 35000 | E10: 23000 | F10: 12000 | G10: =IF(OR(D10="",E10=""),"",D10+E10) | H10: Mensuelle | I10: Virement bancaire | J10: 42248 | K10: Validé | M10: =IF(B10="","",IFERROR(VLOOKUP(B10,'F01 - _Données Retraite'!$A$6:$K$20,2,FALSE)&" "&VLOOKUP(B10,'F01 - _Données Retraite'!$A$6:$K$20,3,FALSE),"")) | N10: =IF(B10="","",IFERROR(SUMIF($B$6:$B$115,B10,$G$6:$G$115),0))
G11: =IF(OR(D11="",E11=""),"",D11+E11) | M11: =IF(B11="","",IFERROR(VLOOKUP(B11,'F01 - _Données Retraite'!$A$6:$K$20,2,FALSE)&" "&VLOOKUP(B11,'F01 - _Données Retraite'!$A$6:$K$20,3,FALSE),"")) | N11: =IF(B11="","",IFERROR(SUMIF($B$6:$B$115,B11,$G$6:$G$115),0))
G12: =IF(OR(D12="",E12=""),"",D12+E12) | M12: =IF(B12="","",IFERROR(VLOOKUP(B12,'F01 - _Données Retraite'!$A$6:$K$20,2,FALSE)&" "&VLOOKUP(B12,'F01 - _Données Retraite'!$A$6:$K$20,3,FALSE),"")) | N12: =IF(B12="","",IFERROR(SUMIF($B$6:$B$115,B12,$G$6:$G$115),0))
G13: =IF(OR(D13="",E13=""),"",D13+E13) | M13: =IF(B13="","",IFERROR(VLOOKUP(B13,'F01 - _Données Retraite'!$A$6:$K$20,2,FALSE)&" "&VLOOKUP(B13,'F01 - _Données Retraite'!$A$6:$K$20,3,FALSE),"")) | N13: =IF(B13="","",IFERROR(SUMIF($B$6:$B$115,B13,$G$6:$G$115),0))
G14: =IF(OR(D14="",E14=""),"",D14+E14) | M14: =IF(B14="","",IFERROR(VLOOKUP(B14,'F01 - _Données Retraite'!$A$6:$K$20,2,FALSE)&" "&VLOOKUP(B14,'F01 - _Données Retraite'!$A$6:$K$20,3,FALSE),"")) | N14: =IF(B14="","",IFERROR(SUMIF($B$6:$B$115,B14,$G$6:$G$115),0))
G15: =IF(OR(D15="",E15=""),"",D15+E15) | M15: =IF(B15="","",IFERROR(VLOOKUP(B15,'F01 - _Données Retraite'!$A$6:$K$20,2,FALSE)&" "&VLOOKUP(B15,'F01 - _Données Retraite'!$A$6:$K$20,3,FALSE),"")) | N15: =IF(B15="","",IFERROR(SUMIF($B$6:$B$115,B15,$G$6:$G$115),0))
G16: =IF(OR(D16="",E16=""),"",D16+E16) | M16: =IF(B16="","",IFERROR(VLOOKUP(B16,'F01 - _Données Retraite'!$A$6:$K$20,2,FALSE)&" "&VLOOKUP(B16,'F01 - _Données Retraite'!$A$6:$K$20,3,FALSE),"")) | N16: =IF(B16="","",IFERROR(SUMIF($B$6:$B$115,B16,$G$6:$G$115),0))
G17: =IF(OR(D17="",E17=""),"",D17+E17) | M17: =IF(B17="","",IFERROR(VLOOKUP(B17,'F01 - _Données Retraite'!$A$6:$K$20,2,FALSE)&" "&VLOOKUP(B17,'F01 - _Données Retraite'!$A$6:$K$20,3,FALSE),"")) | N17: =IF(B17="","",IFERROR(SUMIF($B$6:$B$115,B17,$G$6:$G$115),0))
G18: =IF(OR(D18="",E18=""),"",D18+E18) | M18: =IF(B18="","",IFERROR(VLOOKUP(B18,'F01 - _Données Retraite'!$A$6:$K$20,2,FALSE)&" "&VLOOKUP(B18,'F01 - _Données Retraite'!$A$6:$K$20,3,FALSE),"")) | N18: =IF(B18="","",IFERROR(SUMIF($B$6:$B$115,B18,$G$6:$G$115),0))
G19: =IF(OR(D19="",E19=""),"",D19+E19) | M19: =IF(B19="","",IFERROR(VLOOKUP(B19,'F01 - _Données Retraite'!$A$6:$K$20,2,FALSE)&" "&VLOOKUP(B19,'F01 - _Données Retraite'!$A$6:$K$20,3,FALSE),"")) | N19: =IF(B19="","",IFERROR(SUMIF($B$6:$B$115,B19,$G$6:$G$115),0))
G20: =IF(OR(D20="",E20=""),"",D20+E20) | M20: =IF(B20="","",IFERROR(VLOOKUP(B20,'F01 - _Données Retraite'!$A$6:$K$20,2,FALSE)&" "&VLOOKUP(B20,'F01 - _Données Retraite'!$A$6:$K$20,3,FALSE),"")) | N20: =IF(B20="","",IFERROR(SUMIF($B$6:$B$115,B20,$G$6:$G$115),0))
G21: =IF(OR(D21="",E21=""),"",D21+E21) | M21: =IF(B21="","",IFERROR(VLOOKUP(B21,'F01 - _Données Retraite'!$A$6:$K$20,2,FALSE)&" "&VLOOKUP(B21,'F01 - _Données Retraite'!$A$6:$K$20,3,FALSE),"")) | N21: =IF(B21="","",IFERROR(SUMIF($B$6:$B$115,B21,$G$6:$G$115),0))
G22: =IF(OR(D22="",E22=""),"",D22+E22) | M22: =IF(B22="","",IFERROR(VLOOKUP(B22,'F01 - _Données Retraite'!$A$6:$K$20,2,FALSE)&" "&VLOOKUP(B22,'F01 - _Données Retraite'!$A$6:$K$20,3,FALSE),"")) | N22: =IF(B22="","",IFERROR(SUMIF($B$6:$B$115,B22,$G$6:$G$115),0))
... G115: =IF(OR(D115="",E115=""),"",D115+E115) | M115: =IF(B115="","",IFERROR(VLOOKUP(B115,'F01 - _Données Retraite'!$A$6:$K$20,2,FALSE)&" "&VLOOKUP(B115,'F01 - _Données Retraite'!$A$6:$K$20,3,FALSE),"")) | N115: =IF(B115="","",IFERROR(SUMIF($B$6:$B$115,B115,$G$6:$G$115),0))

Sheet F06 - 4-Simulateurs Pension
A2: 4-SIMULATEURS DE PENSION
A3: TABLEAU DYNAMIQUE — Saisissez dans la zone prévue ci-dessous
A5: Code Simul. | B5: Matricule | C5: Régime | D5: Salaire Référence (FCFA) | E5: Nb Trimestres | F5: Taux de Liquidation (%) | G5: Pension Brute (FCFA) | H5: CSG/CRDS (FCFA) | I5: Pension Nette (FCFA) | J5: Scénario | K5: Date Simulation | L5: Écart vs Objectif (%) | M5: Observations
A6: SIM-001 | B6: RET-001 | C6: Régime Cadre IRC | D6: 1800000 | E6: 168 | F6: =IF(OR(D6="",E6=""),"",IFERROR(MIN(E6/160*100,80),0)) | G6: =IF(OR(D6="",F6=""),"",IFERROR(D6*F6/100,0)) | H6: =IF(G6="","",IFERROR(G6*0.097,0)) | I6: =IF(G6="","",IFERROR(G6-H6,0)) | J6: Normal | K6: 45672 | L6: =IF(B6="","",IFERROR(AVERAGEIF($B$6:$B$115,B6,$I$6:$I$115),0))
A7: SIM-002 | B7: RET-001 | C7: Régime Cadre IRC | D7: 1800000 | E7: 172 | F7: =IF(OR(D7="",E7=""),"",IFERROR(MIN(E7/160*100,80),0)) | G7: =IF(OR(D7="",F7=""),"",IFERROR(D7*F7/100,0)) | H7: =IF(G7="","",IFERROR(G7*0.097,0)) | I7: =IF(G7="","",IFERROR(G7-H7,0)) | J7: Rachat 4 trim. | K7: 45677 | L7: =IF(B7="","",IFERROR(AVERAGEIF($B$6:$B$115,B7,$I$6:$I$115),0))
A8: SIM-003 | B8: RET-002 | C8: Régime Cadre IRC | D8: 2200000 | E8: 162 | F8: =IF(OR(D8="",E8=""),"",IFERROR(MIN(E8/160*100,80),0)) | G8: =IF(OR(D8="",F8=""),"",IFERROR(D8*F8/100,0)) | H8: =IF(G8="","",IFERROR(G8*0.097,0)) | I8: =IF(G8="","",IFERROR(G8-H8,0)) | J8: Normal | K8: 45717 | L8: =IF(B8="","",IFERROR(AVERAGEIF($B$6:$B$115,B8,$I$6:$I$115),0))
A9: SIM-004 | B9: RET-006 | C9: Régime Complémentaire | D9: 1600000 | E9: 172 | F9: =IF(OR(D9="",E9=""),"",IFERROR(MIN(E9/160*100,80),0)) | G9: =IF(OR(D9="",F9=""),"",IFERROR(D9*F9/100,0)) | H9: =IF(G9="","",IFERROR(G9*0.097,0)) | I9: =IF(G9="","",IFERROR(G9-H9,0)) | J9: Surcote 5 ans | K9: 45566 | L9: =IF(B9="","",IFERROR(AVERAGEIF($B$6:$B$115,B9,$I$6:$I$115),0))
A10: SIM-005 | B10: RET-005 | C10: Régime International | D10: 3500000 | E10: 155 | F10: =IF(OR(D10="",E10=""),"",IFERROR(MIN(E10/160*100,80),0)) | G10: =IF(OR(D10="",F10=""),"",IFERROR(D10*F10/100,0)) | H10: =IF(G10="","",IFERROR(G10*0.097,0)) | I10: =IF(G10="","",IFERROR(G10-H10,0)) | J10: Convention intl. | K10: 45689 | L10: =IF(B10="","",IFERROR(AVERAGEIF($B$6:$B$115,B10,$I$6:$I$115),0))
F11: =IF(OR(D11="",E11=""),"",IFERROR(MIN(E11/160*100,80),0)) | G11: =IF(OR(D11="",F11=""),"",IFERROR(D11*F11/100,0)) | H11: =IF(G11="","",IFERROR(G11*0.097,0)) | I11: =IF(G11="","",IFERROR(G11-H11,0)) | L11: =IF(B11="","",IFERROR(AVERAGEIF($B$6:$B$115,B11,$I$6:$I$115),0))
F12: =IF(OR(D12="",E12=""),"",IFERROR(MIN(E12/160*100,80),0)) | G12: =IF(OR(D12="",F12=""),"",IFERROR(D12*F12/100,0)) | H12: =IF(G12="","",IFERROR(G12*0.097,0)) | I12: =IF(G12="","",IFERROR(G12-H12,0)) | L12: =IF(B12="","",IFERROR(AVERAGEIF($B$6:$B$115,B12,$I$6:$I$115),0))
F13: =IF(OR(D13="",E13=""),"",IFERROR(MIN(E13/160*100,80),0)) | G13: =IF(OR(D13="",F13=""),"",IFERROR(D13*F13/100,0)) | H13: =IF(G13="","",IFERROR(G13*0.097,0)) | I13: =IF(G13="","",IFERROR(G13-H13,0)) | L13: =IF(B13="","",IFERROR(AVERAGEIF($B$6:$B$115,B13,$I$6:$I$115),0))
F14: =IF(OR(D14="",E14=""),"",IFERROR(MIN(E14/160*100,80),0)) | G14: =IF(OR(D14="",F14=""),"",IFERROR(D14*F14/100,0)) | H14: =IF(G14="","",IFERROR(G14*0.097,0)) | I14: =IF(G14="","",IFERROR(G14-H14,0)) | L14: =IF(B14="","",IFERROR(AVERAGEIF($B$6:$B$115,B14,$I$6:$I$115),0))
F15: =IF(OR(D15="",E15=""),"",IFERROR(MIN(E15/160*100,80),0)) | G15: =IF(OR(D15="",F15=""),"",IFERROR(D15*F15/100,0)) | H15: =IF(G15="","",IFERROR(G15*0.097,0)) | I15: =IF(G15="","",IFERROR(G15-H15,0)) | L15: =IF(B15="","",IFERROR(AVERAGEIF($B$6:$B$115,B15,$I$6:$I$115),0))
F16: =IF(OR(D16="",E16=""),"",IFERROR(MIN(E16/160*100,80),0)) | G16: =IF(OR(D16="",F16=""),"",IFERROR(D16*F16/100,0)) | H16: =IF(G16="","",IFERROR(G16*0.097,0)) | I16: =IF(G16="","",IFERROR(G16-H16,0)) | L16: =IF(B16="","",IFERROR(AVERAGEIF($B$6:$B$115,B16,$I$6:$I$115),0))
F17: =IF(OR(D17="",E17=""),"",IFERROR(MIN(E17/160*100,80),0)) | G17: =IF(OR(D17="",F17=""),"",IFERROR(D17*F17/100,0)) | H17: =IF(G17="","",IFERROR(G17*0.097,0)) | I17: =IF(G17="","",IFERROR(G17-H17,0)) | L17: =IF(B17="","",IFERROR(AVERAGEIF($B$6:$B$115,B17,$I$6:$I$115),0))
F18: =IF(OR(D18="",E18=""),"",IFERROR(MIN(E18/160*100,80),0)) | G18: =IF(OR(D18="",F18=""),"",IFERROR(D18*F18/100,0)) | H18: =IF(G18="","",IFERROR(G18*0.097,0)) | I18: =IF(G18="","",IFERROR(G18-H18,0)) | L18: =IF(B18="","",IFERROR(AVERAGEIF($B$6:$B$115,B18,$I$6:$I$115),0))
F19: =IF(OR(D19="",E19=""),"",IFERROR(MIN(E19/160*100,80),0)) | G19: =IF(OR(D19="",F19=""),"",IFERROR(D19*F19/100,0)) | H19: =IF(G19="","",IFERROR(G19*0.097,0)) | I19: =IF(G19="","",IFERROR(G19-H19,0)) | L19: =IF(B19="","",IFERROR(AVERAGEIF($B$6:$B$115,B19,$I$6:$I$115),0))
F20: =IF(OR(D20="",E20=""),"",IFERROR(MIN(E20/160*100,80),0)) | G20: =IF(OR(D20="",F20=""),"",IFERROR(D20*F20/100,0)) | H20: =IF(G20="","",IFERROR(G20*0.097,0)) | I20: =IF(G20="","",IFERROR(G20-H20,0)) | L20: =IF(B20="","",IFERROR(AVERAGEIF($B$6:$B$115,B20,$I$6:$I$115),0))
F21: =IF(OR(D21="",E21=""),"",IFERROR(MIN(E21/160*100,80),0)) | G21: =IF(OR(D21="",F21=""),"",IFERROR(D21*F21/100,0)) | H21: =IF(G21="","",IFERROR(G21*0.097,0)) | I21: =IF(G21="","",IFERROR(G21-H21,0)) | L21: =IF(B21="","",IFERROR(AVERAGEIF($B$6:$B$115,B21,$I$6:$I$115),0))
F22: =IF(OR(D22="",E22=""),"",IFERROR(MIN(E22/160*100,80),0)) | G22: =IF(OR(D22="",F22=""),"",IFERROR(D22*F22/100,0)) | H22: =IF(G22="","",IFERROR(G22*0.097,0)) | I22: =IF(G22="","",IFERROR(G22-H22,0)) | L22: =IF(B22="","",IFERROR(AVERAGEIF($B$6:$B$115,B22,$I$6:$I$115),0))
... F115: =IF(OR(D115="",E115=""),"",IFERROR(MIN(E115/160*100,80),0)) | G115: =IF(OR(D115="",F115=""),"",IFERROR(D115*F115/100,0)) | H115: =IF(G115="","",IFERROR(G115*0.097,0)) | I115: =IF(G115="","",IFERROR(G115-H115,0)) | L115: =IF(B115="","",IFERROR(AVERAGEIF($B$6:$B$115,B115,$I$6:$I$115),0))

Sheet F07 - 5-Plans de Départ
A2: 5-PLANS DE DÉPART EN RETRAITE
A3: TABLEAU DYNAMIQUE — Saisissez dans la zone prévue ci-dessous
A5: Code Plan | B5: Matricule | C5: Type Départ | D5: Cause Départ | E5: Date Départ Prévu | F5: Date Préavis | G5: Date Transmission CNPS | H5: Entretien Final | I5: Passation Effectuée | J5: Solde Tout Compte | K5: Statut | L5: Observations
A6: PLAN-001 | B6: RET-001 | C6: Retraite normale (60 ans) | D6: Âge légal | E6: 45838 | F6: 45747 | H6: Oui | I6: En cours | J6: En cours | K6: En cours | M6: =IF(B6="","",IFERROR(VLOOKUP(B6,'F01 - _Données Retraite'!$A$6:$K$20,2,FALSE)&" "&VLOOKUP(B6,'F01 - _Données Retraite'!$A$6:$K$20,3,FALSE),"")) | N6: =IF(A6="","",IF(AND(H6="Oui",I6="Oui"),"COMPLET","INCOMPLET"))
A7: PLAN-002 | B7: RET-002 | C7: Retraite anticipée | D7: Volontaire | E7: 46037 | F7: 45945 | H7: Non | I7: Non | J7: Non | K7: En préparation | M7: =IF(B7="","",IFERROR(VLOOKUP(B7,'F01 - _Données Retraite'!$A$6:$K$20,2,FALSE)&" "&VLOOKUP(B7,'F01 - _Données Retraite'!$A$6:$K$20,3,FALSE),"")) | N7: =IF(A7="","",IF(AND(H7="Oui",I7="Oui"),"COMPLET","INCOMPLET"))
A8: PLAN-003 | B8: RET-003 | C8: Retraite normale (60 ans) | D8: Âge légal | E8: 45657 | F8: 45565 | G8: 45580 | H8: Oui | I8: Oui | J8: Oui | K8: Clôturé | M8: =IF(B8="","",IFERROR(VLOOKUP(B8,'F01 - _Données Retraite'!$A$6:$K$20,2,FALSE)&" "&VLOOKUP(B8,'F01 - _Données Retraite'!$A$6:$K$20,3,FALSE),"")) | N8: =IF(A8="","",IF(AND(H8="Oui",I8="Oui"),"COMPLET","INCOMPLET"))
A9: PLAN-004 | B9: RET-006 | C9: Retraite tardive (65+ ans) | D9: Départ anticipé | E9: 45717 | F9: 45627 | G9: 45667 | H9: Oui | I9: Oui | J9: Oui | K9: Clôturé | M9: =IF(B9="","",IFERROR(VLOOKUP(B9,'F01 - _Données Retraite'!$A$6:$K$20,2,FALSE)&" "&VLOOKUP(B9,'F01 - _Données Retraite'!$A$6:$K$20,3,FALSE),"")) | N9: =IF(A9="","",IF(AND(H9="Oui",I9="Oui"),"COMPLET","INCOMPLET"))
A10: PLAN-005 | B10: RET-005 | C10: Retraite normale (60 ans) | D10: Âge légal | E10: 46022 | F10: 45930 | H10: Non | I10: Non | J10: Non | K10: En préparation | M10: =IF(B10="","",IFERROR(VLOOKUP(B10,'F01 - _Données Retraite'!$A$6:$K$20,2,FALSE)&" "&VLOOKUP(B10,'F01 - _Données Retraite'!$A$6:$K$20,3,FALSE),"")) | N10: =IF(A10="","",IF(AND(H10="Oui",I10="Oui"),"COMPLET","INCOMPLET"))
M11: =IF(B11="","",IFERROR(VLOOKUP(B11,'F01 - _Données Retraite'!$A$6:$K$20,2,FALSE)&" "&VLOOKUP(B11,'F01 - _Données Retraite'!$A$6:$K$20,3,FALSE),"")) | N11: =IF(A11="","",IF(AND(H11="Oui",I11="Oui"),"COMPLET","INCOMPLET"))
M12: =IF(B12="","",IFERROR(VLOOKUP(B12,'F01 - _Données Retraite'!$A$6:$K$20,2,FALSE)&" "&VLOOKUP(B12,'F01 - _Données Retraite'!$A$6:$K$20,3,FALSE),"")) | N12: =IF(A12="","",IF(AND(H12="Oui",I12="Oui"),"COMPLET","INCOMPLET"))
M13: =IF(B13="","",IFERROR(VLOOKUP(B13,'F01 - _Données Retraite'!$A$6:$K$20,2,FALSE)&" "&VLOOKUP(B13,'F01 - _Données Retraite'!$A$6:$K$20,3,FALSE),"")) | N13: =IF(A13="","",IF(AND(H13="Oui",I13="Oui"),"COMPLET","INCOMPLET"))
M14: =IF(B14="","",IFERROR(VLOOKUP(B14,'F01 - _Données Retraite'!$A$6:$K$20,2,FALSE)&" "&VLOOKUP(B14,'F01 - _Données Retraite'!$A$6:$K$20,3,FALSE),"")) | N14: =IF(A14="","",IF(AND(H14="Oui",I14="Oui"),"COMPLET","INCOMPLET"))
M15: =IF(B15="","",IFERROR(VLOOKUP(B15,'F01 - _Données Retraite'!$A$6:$K$20,2,FALSE)&" "&VLOOKUP(B15,'F01 - _Données Retraite'!$A$6:$K$20,3,FALSE),"")) | N15: =IF(A15="","",IF(AND(H15="Oui",I15="Oui"),"COMPLET","INCOMPLET"))
M16: =IF(B16="","",IFERROR(VLOOKUP(B16,'F01 - _Données Retraite'!$A$6:$K$20,2,FALSE)&" "&VLOOKUP(B16,'F01 - _Données Retraite'!$A$6:$K$20,3,FALSE),"")) | N16: =IF(A16="","",IF(AND(H16="Oui",I16="Oui"),"COMPLET","INCOMPLET"))
M17: =IF(B17="","",IFERROR(VLOOKUP(B17,'F01 - _Données Retraite'!$A$6:$K$20,2,FALSE)&" "&VLOOKUP(B17,'F01 - _Données Retraite'!$A$6:$K$20,3,FALSE),"")) | N17: =IF(A17="","",IF(AND(H17="Oui",I17="Oui"),"COMPLET","INCOMPLET"))
M18: =IF(B18="","",IFERROR(VLOOKUP(B18,'F01 - _Données Retraite'!$A$6:$K$20,2,FALSE)&" "&VLOOKUP(B18,'F01 - _Données Retraite'!$A$6:$K$20,3,FALSE),"")) | N18: =IF(A18="","",IF(AND(H18="Oui",I18="Oui"),"COMPLET","INCOMPLET"))
M19: =IF(B19="","",IFERROR(VLOOKUP(B19,'F01 - _Données Retraite'!$A$6:$K$20,2,FALSE)&" "&VLOOKUP(B19,'F01 - _Données Retraite'!$A$6:$K$20,3,FALSE),"")) | N19: =IF(A19="","",IF(AND(H19="Oui",I19="Oui"),"COMPLET","INCOMPLET"))
M20: =IF(B20="","",IFERROR(VLOOKUP(B20,'F01 - _Données Retraite'!$A$6:$K$20,2,FALSE)&" "&VLOOKUP(B20,'F01 - _Données Retraite'!$A$6:$K$20,3,FALSE),"")) | N20: =IF(A20="","",IF(AND(H20="Oui",I20="Oui"),"COMPLET","INCOMPLET"))
M21: =IF(B21="","",IFERROR(VLOOKUP(B21,'F01 - _Données Retraite'!$A$6:$K$20,2,FALSE)&" "&VLOOKUP(B21,'F01 - _Données Retraite'!$A$6:$K$20,3,FALSE),"")) | N21: =IF(A21="","",IF(AND(H21="Oui",I21="Oui"),"COMPLET","INCOMPLET"))
M22: =IF(B22="","",IFERROR(VLOOKUP(B22,'F01 - _Données Retraite'!$A$6:$K$20,2,FALSE)&" "&VLOOKUP(B22,'F01 - _Données Retraite'!$A$6:$K$20,3,FALSE),"")) | N22: =IF(A22="","",IF(AND(H22="Oui",I22="Oui"),"COMPLET","INCOMPLET"))
... M115: =IF(B115="","",IFERROR(VLOOKUP(B115,'F01 - _Données Retraite'!$A$6:$K$20,2,FALSE)&" "&VLOOKUP(B115,'F01 - _Données Retraite'!$A$6:$K$20,3,FALSE),"")) | N115: =IF(A115="","",IF(AND(H115="Oui",I115="Oui"),"COMPLET","INCOMPLET"))

Sheet F08 - 6-Outplacement
A2: 6-OUTPLACEMENT ET RECONVERSION
A3: TABLEAU DYNAMIQUE — Saisissez dans la zone prévue ci-dessous
A5: Code Outpl. | B5: Matricule | C5: Type Outplacement | D5: Date Début | E5: Date Fin | F5: Coût Total (FCFA) | G5: Bilan Réalisé | H5: Reconversion Réussie | I5: Nouvel Employeur | J5: Poste Obtenu | K5: Statut | L5: Observations
A6: OUT-001 | B6: RET-003 | C6: Reclassement interne | D6: 45536 | E6: 45716 | F6: 350000 | G6: Oui | H6: En cours | I6: Interne | J6: Consultant Senior | K6: En cours | M6: =IF(B6="","",IFERROR(VLOOKUP(B6,'F01 - _Données Retraite'!$A$6:$K$20,2,FALSE)&" "&VLOOKUP(B6,'F01 - _Données Retraite'!$A$6:$K$20,3,FALSE),"")) | N6: =IF(B6="","",IFERROR(SUMIF($B$6:$B$115,B6,$F$6:$F$115),0))
A7: OUT-002 | B7: RET-006 | C7: Coaching individuel | D7: 45658 | E7: 45838 | F7: 500000 | G7: Non | H7: Non | K7: En cours | M7: =IF(B7="","",IFERROR(VLOOKUP(B7,'F01 - _Données Retraite'!$A$6:$K$20,2,FALSE)&" "&VLOOKUP(B7,'F01 - _Données Retraite'!$A$6:$K$20,3,FALSE),"")) | N7: =IF(B7="","",IFERROR(SUMIF($B$6:$B$115,B7,$F$6:$F$115),0))
A8: OUT-003 | B8: RET-009 | C8: Formation reconversion | D8: 45717 | E8: 45900 | F8: 420000 | G8: Non | H8: Non | K8: En attente | M8: =IF(B8="","",IFERROR(VLOOKUP(B8,'F01 - _Données Retraite'!$A$6:$K$20,2,FALSE)&" "&VLOOKUP(B8,'F01 - _Données Retraite'!$A$6:$K$20,3,FALSE),"")) | N8: =IF(B8="","",IFERROR(SUMIF($B$6:$B$115,B8,$F$6:$F$115),0))
M9: =IF(B9="","",IFERROR(VLOOKUP(B9,'F01 - _Données Retraite'!$A$6:$K$20,2,FALSE)&" "&VLOOKUP(B9,'F01 - _Données Retraite'!$A$6:$K$20,3,FALSE),"")) | N9: =IF(B9="","",IFERROR(SUMIF($B$6:$B$115,B9,$F$6:$F$115),0))
M10: =IF(B10="","",IFERROR(VLOOKUP(B10,'F01 - _Données Retraite'!$A$6:$K$20,2,FALSE)&" "&VLOOKUP(B10,'F01 - _Données Retraite'!$A$6:$K$20,3,FALSE),"")) | N10: =IF(B10="","",IFERROR(SUMIF($B$6:$B$115,B10,$F$6:$F$115),0))
M11: =IF(B11="","",IFERROR(VLOOKUP(B11,'F01 - _Données Retraite'!$A$6:$K$20,2,FALSE)&" "&VLOOKUP(B11,'F01 - _Données Retraite'!$A$6:$K$20,3,FALSE),"")) | N11: =IF(B11="","",IFERROR(SUMIF($B$6:$B$115,B11,$F$6:$F$115),0))
M12: =IF(B12="","",IFERROR(VLOOKUP(B12,'F01 - _Données Retraite'!$A$6:$K$20,2,FALSE)&" "&VLOOKUP(B12,'F01 - _Données Retraite'!$A$6:$K$20,3,FALSE),"")) | N12: =IF(B12="","",IFERROR(SUMIF($B$6:$B$115,B12,$F$6:$F$115),0))
M13: =IF(B13="","",IFERROR(VLOOKUP(B13,'F01 - _Données Retraite'!$A$6:$K$20,2,FALSE)&" "&VLOOKUP(B13,'F01 - _Données Retraite'!$A$6:$K$20,3,FALSE),"")) | N13: =IF(B13="","",IFERROR(SUMIF($B$6:$B$115,B13,$F$6:$F$115),0))
M14: =IF(B14="","",IFERROR(VLOOKUP(B14,'F01 - _Données Retraite'!$A$6:$K$20,2,FALSE)&" "&VLOOKUP(B14,'F01 - _Données Retraite'!$A$6:$K$20,3,FALSE),"")) | N14: =IF(B14="","",IFERROR(SUMIF($B$6:$B$115,B14,$F$6:$F$115),0))
M15: =IF(B15="","",IFERROR(VLOOKUP(B15,'F01 - _Données Retraite'!$A$6:$K$20,2,FALSE)&" "&VLOOKUP(B15,'F01 - _Données Retraite'!$A$6:$K$20,3,FALSE),"")) | N15: =IF(B15="","",IFERROR(SUMIF($B$6:$B$115,B15,$F$6:$F$115),0))
M16: =IF(B16="","",IFERROR(VLOOKUP(B16,'F01 - _Données Retraite'!$A$6:$K$20,2,FALSE)&" "&VLOOKUP(B16,'F01 - _Données Retraite'!$A$6:$K$20,3,FALSE),"")) | N16: =IF(B16="","",IFERROR(SUMIF($B$6:$B$115,B16,$F$6:$F$115),0))
M17: =IF(B17="","",IFERROR(VLOOKUP(B17,'F01 - _Données Retraite'!$A$6:$K$20,2,FALSE)&" "&VLOOKUP(B17,'F01 - _Données Retraite'!$A$6:$K$20,3,FALSE),"")) | N17: =IF(B17="","",IFERROR(SUMIF($B$6:$B$115,B17,$F$6:$F$115),0))
M18: =IF(B18="","",IFERROR(VLOOKUP(B18,'F01 - _Données Retraite'!$A$6:$K$20,2,FALSE)&" "&VLOOKUP(B18,'F01 - _Données Retraite'!$A$6:$K$20,3,FALSE),"")) | N18: =IF(B18="","",IFERROR(SUMIF($B$6:$B$115,B18,$F$6:$F$115),0))
M19: =IF(B19="","",IFERROR(VLOOKUP(B19,'F01 - _Données Retraite'!$A$6:$K$20,2,FALSE)&" "&VLOOKUP(B19,'F01 - _Données Retraite'!$A$6:$K$20,3,FALSE),"")) | N19: =IF(B19="","",IFERROR(SUMIF($B$6:$B$115,B19,$F$6:$F$115),0))
M20: =IF(B20="","",IFERROR(VLOOKUP(B20,'F01 - _Données Retraite'!$A$6:$K$20,2,FALSE)&" "&VLOOKUP(B20,'F01 - _Données Retraite'!$A$6:$K$20,3,FALSE),"")) | N20: =IF(B20="","",IFERROR(SUMIF($B$6:$B$115,B20,$F$6:$F$115),0))
... M115: =IF(B115="","",IFERROR(VLOOKUP(B115,'F01 - _Données Retraite'!$A$6:$K$20,2,FALSE)&" "&VLOOKUP(B115,'F01 - _Données Retraite'!$A$6:$K$20,3,FALSE),"")) | N115: =IF(B115="","",IFERROR(SUMIF($B$6:$B$115,B115,$F$6:$F$115),0))

Sheet F09 - 7-Transitions Carrière
A2: 7-TRANSITIONS DE CARRIÈRE FIN DE CARRIÈRE
A3: TABLEAU DYNAMIQUE — Saisissez dans la zone prévue ci-dessous
A5: Code Trans. | B5: Matricule | C5: Type Transition | D5: Poste Actuel | E5: Poste Cible | F5: Date Début | G5: Date Fin | H5: Durée (mois) | I5: Tuteur | J5: Évaluation Mi-Parcours | K5: Évaluation Finale | L5: Statut | M5: Observations
A6: TRA-001 | B6: RET-001 | C6: Progressive | D6: DG Adjoint | E6: Conseiller Stratégique | F6: 45658 | G6: 45838 | H6: =IF(OR(F6="",G6=""),"",IFERROR((G6-F6)/30.44,0)) | I6: DG Général | J6: Favorable | K6: En attente | L6: En cours | M6: =IF(B6="","",IFERROR(VLOOKUP(B6,'F01 - _Données Retraite'!$A$6:$K$20,2,FALSE)&" "&VLOOKUP(B6,'F01 - _Données Retraite'!$A$6:$K$20,3,FALSE),"")) | N6: =IF(A6="","",IF(AND(J6="Favorable",K6="Favorable"),"RÉUSSI","EN COURS"))
A7: TRA-002 | B7: RET-002 | C7: Partage d'expérience | D7: Dir. Financière | E7: Mentor Financier | F7: 45809 | G7: 46037 | H7: =IF(OR(F7="",G7=""),"",IFERROR((G7-F7)/30.44,0)) | I7: DAF | J7: Non | K7: Non | L7: En préparation | M7: =IF(B7="","",IFERROR(VLOOKUP(B7,'F01 - _Données Retraite'!$A$6:$K$20,2,FALSE)&" "&VLOOKUP(B7,'F01 - _Données Retraite'!$A$6:$K$20,3,FALSE),"")) | N7: =IF(A7="","",IF(AND(J7="Favorable",K7="Favorable"),"RÉUSSI","EN COURS"))
A8: TRA-003 | B8: RET-004 | C8: Réduction temps | D8: Resp. Administrative | E8: Resp. Administrative 80% | F8: 45717 | G8: 46447 | H8: =IF(OR(F8="",G8=""),"",IFERROR((G8-F8)/30.44,0)) | I8: DRH | J8: Non | K8: Non | L8: Non commencé | M8: =IF(B8="","",IFERROR(VLOOKUP(B8,'F01 - _Données Retraite'!$A$6:$K$20,2,FALSE)&" "&VLOOKUP(B8,'F01 - _Données Retraite'!$A$6:$K$20,3,FALSE),"")) | N8: =IF(A8="","",IF(AND(J8="Favorable",K8="Favorable"),"RÉUSSI","EN COURS"))
H9: =IF(OR(F9="",G9=""),"",IFERROR((G9-F9)/30.44,0)) | M9: =IF(B9="","",IFERROR(VLOOKUP(B9,'F01 - _Données Retraite'!$A$6:$K$20,2,FALSE)&" "&VLOOKUP(B9,'F01 - _Données Retraite'!$A$6:$K$20,3,FALSE),"")) | N9: =IF(A9="","",IF(AND(J9="Favorable",K9="Favorable"),"RÉUSSI","EN COURS"))
H10: =IF(OR(F10="",G10=""),"",IFERROR((G10-F10)/30.44,0)) | M10: =IF(B10="","",IFERROR(VLOOKUP(B10,'F01 - _Données Retraite'!$A$6:$K$20,2,FALSE)&" "&VLOOKUP(B10,'F01 - _Données Retraite'!$A$6:$K$20,3,FALSE),"")) | N10: =IF(A10="","",IF(AND(J10="Favorable",K10="Favorable"),"RÉUSSI","EN COURS"))
H11: =IF(OR(F11="",G11=""),"",IFERROR((G11-F11)/30.44,0)) | M11: =IF(B11="","",IFERROR(VLOOKUP(B11,'F01 - _Données Retraite'!$A$6:$K$20,2,FALSE)&" "&VLOOKUP(B11,'F01 - _Données Retraite'!$A$6:$K$20,3,FALSE),"")) | N11: =IF(A11="","",IF(AND(J11="Favorable",K11="Favorable"),"RÉUSSI","EN COURS"))
H12: =IF(OR(F12="",G12=""),"",IFERROR((G12-F12)/30.44,0)) | M12: =IF(B12="","",IFERROR(VLOOKUP(B12,'F01 - _Données Retraite'!$A$6:$K$20,2,FALSE)&" "&VLOOKUP(B12,'F01 - _Données Retraite'!$A$6:$K$20,3,FALSE),"")) | N12: =IF(A12="","",IF(AND(J12="Favorable",K12="Favorable"),"RÉUSSI","EN COURS"))
H13: =IF(OR(F13="",G13=""),"",IFERROR((G13-F13)/30.44,0)) | M13: =IF(B13="","",IFERROR(VLOOKUP(B13,'F01 - _Données Retraite'!$A$6:$K$20,2,FALSE)&" "&VLOOKUP(B13,'F01 - _Données Retraite'!$A$6:$K$20,3,FALSE),"")) | N13: =IF(A13="","",IF(AND(J13="Favorable",K13="Favorable"),"RÉUSSI","EN COURS"))
H14: =IF(OR(F14="",G14=""),"",IFERROR((G14-F14)/30.44,0)) | M14: =IF(B14="","",IFERROR(VLOOKUP(B14,'F01 - _Données Retraite'!$A$6:$K$20,2,FALSE)&" "&VLOOKUP(B14,'F01 - _Données Retraite'!$A$6:$K$20,3,FALSE),"")) | N14: =IF(A14="","",IF(AND(J14="Favorable",K14="Favorable"),"RÉUSSI","EN COURS"))
H15: =IF(OR(F15="",G15=""),"",IFERROR((G15-F15)/30.44,0)) | M15: =IF(B15="","",IFERROR(VLOOKUP(B15,'F01 - _Données Retraite'!$A$6:$K$20,2,FALSE)&" "&VLOOKUP(B15,'F01 - _Données Retraite'!$A$6:$K$20,3,FALSE),"")) | N15: =IF(A15="","",IF(AND(J15="Favorable",K15="Favorable"),"RÉUSSI","EN COURS"))
H16: =IF(OR(F16="",G16=""),"",IFERROR((G16-F16)/30.44,0)) | M16: =IF(B16="","",IFERROR(VLOOKUP(B16,'F01 - _Données Retraite'!$A$6:$K$20,2,FALSE)&" "&VLOOKUP(B16,'F01 - _Données Retraite'!$A$6:$K$20,3,FALSE),"")) | N16: =IF(A16="","",IF(AND(J16="Favorable",K16="Favorable"),"RÉUSSI","EN COURS"))
H17: =IF(OR(F17="",G17=""),"",IFERROR((G17-F17)/30.44,0)) | M17: =IF(B17="","",IFERROR(VLOOKUP(B17,'F01 - _Données Retraite'!$A$6:$K$20,2,FALSE)&" "&VLOOKUP(B17,'F01 - _Données Retraite'!$A$6:$K$20,3,FALSE),"")) | N17: =IF(A17="","",IF(AND(J17="Favorable",K17="Favorable"),"RÉUSSI","EN COURS"))
H18: =IF(OR(F18="",G18=""),"",IFERROR((G18-F18)/30.44,0)) | M18: =IF(B18="","",IFERROR(VLOOKUP(B18,'F01 - _Données Retraite'!$A$6:$K$20,2,FALSE)&" "&VLOOKUP(B18,'F01 - _Données Retraite'!$A$6:$K$20,3,FALSE),"")) | N18: =IF(A18="","",IF(AND(J18="Favorable",K18="Favorable"),"RÉUSSI","EN COURS"))
H19: =IF(OR(F19="",G19=""),"",IFERROR((G19-F19)/30.44,0)) | M19: =IF(B19="","",IFERROR(VLOOKUP(B19,'F01 - _Données Retraite'!$A$6:$K$20,2,FALSE)&" "&VLOOKUP(B19,'F01 - _Données Retraite'!$A$6:$K$20,3,FALSE),"")) | N19: =IF(A19="","",IF(AND(J19="Favorable",K19="Favorable"),"RÉUSSI","EN COURS"))
H20: =IF(OR(F20="",G20=""),"",IFERROR((G20-F20)/30.44,0)) | M20: =IF(B20="","",IFERROR(VLOOKUP(B20,'F01 - _Données Retraite'!$A$6:$K$20,2,FALSE)&" "&VLOOKUP(B20,'F01 - _Données Retraite'!$A$6:$K$20,3,FALSE),"")) | N20: =IF(A20="","",IF(AND(J20="Favorable",K20="Favorable"),"RÉUSSI","EN COURS"))
... H115: =IF(OR(F115="",G115=""),"",IFERROR((G115-F115)/30.44,0)) | M115: =IF(B115="","",IFERROR(VLOOKUP(B115,'F01 - _Données Retraite'!$A$6:$K$20,2,FALSE)&" "&VLOOKUP(B115,'F01 - _Données Retraite'!$A$6:$K$20,3,FALSE),"")) | N115: =IF(A115="","",IF(AND(J115="Favorable",K115="Favorable"),"RÉUSSI","EN COURS"))

Sheet F10 - 8-Bien-être Fin Carrière
A2: 8-BIEN-ÊTRE ET ACCOMPAGNEMENT FIN DE CARRIÈRE
A3: TABLEAU DYNAMIQUE — Saisissez dans la zone prévue ci-dessous
A5: Code Bien-Être | B5: Matricule | C5: Type Accompagnement | D5: Date Début | E5: Fréquence Suivi | F5: Score Bien-Être (/100) | G5: Score Évolution | H5: Risque Burnout | I5: Risque Isolement | J5: Action Corrective | K5: Responsable | L5: Observations
A6: BE-001 | B6: RET-001 | C6: Coaching fin de carrière | D6: 45658 | E6: Mensuelle | F6: 78 | G6: =IF(F6="","",IFERROR(F6-70,"")) | H6: Modéré | I6: Faible | J6: Atelier partage | K6: Psychologue | M6: =IF(B6="","",IFERROR(VLOOKUP(B6,'F01 - _Données Retraite'!$A$6:$K$20,2,FALSE)&" "&VLOOKUP(B6,'F01 - _Données Retraite'!$A$6:$K$20,3,FALSE),"")) | N6: =IF(B6="","",IFERROR(AVERAGEIF($B$6:$B$115,B6,$F$6:$F$115),0))
A7: BE-002 | B7: RET-002 | C7: Accompagnement transition | D7: 45717 | E7: Trimestrielle | F7: 72 | G7: =IF(F7="","",IFERROR(F7-70,"")) | H7: Élevé | I7: Modéré | J7: Groupe de parole | K7: DRH | M7: =IF(B7="","",IFERROR(VLOOKUP(B7,'F01 - _Données Retraite'!$A$6:$K$20,2,FALSE)&" "&VLOOKUP(B7,'F01 - _Données Retraite'!$A$6:$K$20,3,FALSE),"")) | N7: =IF(B7="","",IFERROR(AVERAGEIF($B$6:$B$115,B7,$F$6:$F$115),0))
A8: BE-003 | B8: RET-003 | C8: Suivi post-retraite | D8: 45672 | E8: Semestrielle | F8: 85 | G8: =IF(F8="","",IFERROR(F8-70,"")) | H8: Faible | I8: Faible | J8: Aucune | K8: Resp. Retraites | M8: =IF(B8="","",IFERROR(VLOOKUP(B8,'F01 - _Données Retraite'!$A$6:$K$20,2,FALSE)&" "&VLOOKUP(B8,'F01 - _Données Retraite'!$A$6:$K$20,3,FALSE),"")) | N8: =IF(B8="","",IFERROR(AVERAGEIF($B$6:$B$115,B8,$F$6:$F$115),0))
G9: =IF(F9="","",IFERROR(F9-70,"")) | M9: =IF(B9="","",IFERROR(VLOOKUP(B9,'F01 - _Données Retraite'!$A$6:$K$20,2,FALSE)&" "&VLOOKUP(B9,'F01 - _Données Retraite'!$A$6:$K$20,3,FALSE),"")) | N9: =IF(B9="","",IFERROR(AVERAGEIF($B$6:$B$115,B9,$F$6:$F$115),0))
G10: =IF(F10="","",IFERROR(F10-70,"")) | M10: =IF(B10="","",IFERROR(VLOOKUP(B10,'F01 - _Données Retraite'!$A$6:$K$20,2,FALSE)&" "&VLOOKUP(B10,'F01 - _Données Retraite'!$A$6:$K$20,3,FALSE),"")) | N10: =IF(B10="","",IFERROR(AVERAGEIF($B$6:$B$115,B10,$F$6:$F$115),0))
G11: =IF(F11="","",IFERROR(F11-70,"")) | M11: =IF(B11="","",IFERROR(VLOOKUP(B11,'F01 - _Données Retraite'!$A$6:$K$20,2,FALSE)&" "&VLOOKUP(B11,'F01 - _Données Retraite'!$A$6:$K$20,3,FALSE),"")) | N11: =IF(B11="","",IFERROR(AVERAGEIF($B$6:$B$115,B11,$F$6:$F$115),0))
G12: =IF(F12="","",IFERROR(F12-70,"")) | M12: =IF(B12="","",IFERROR(VLOOKUP(B12,'F01 - _Données Retraite'!$A$6:$K$20,2,FALSE)&" "&VLOOKUP(B12,'F01 - _Données Retraite'!$A$6:$K$20,3,FALSE),"")) | N12: =IF(B12="","",IFERROR(AVERAGEIF($B$6:$B$115,B12,$F$6:$F$115),0))
G13: =IF(F13="","",IFERROR(F13-70,"")) | M13: =IF(B13="","",IFERROR(VLOOKUP(B13,'F01 - _Données Retraite'!$A$6:$K$20,2,FALSE)&" "&VLOOKUP(B13,'F01 - _Données Retraite'!$A$6:$K$20,3,FALSE),"")) | N13: =IF(B13="","",IFERROR(AVERAGEIF($B$6:$B$115,B13,$F$6:$F$115),0))
G14: =IF(F14="","",IFERROR(F14-70,"")) | M14: =IF(B14="","",IFERROR(VLOOKUP(B14,'F01 - _Données Retraite'!$A$6:$K$20,2,FALSE)&" "&VLOOKUP(B14,'F01 - _Données Retraite'!$A$6:$K$20,3,FALSE),"")) | N14: =IF(B14="","",IFERROR(AVERAGEIF($B$6:$B$115,B14,$F$6:$F$115),0))
G15: =IF(F15="","",IFERROR(F15-70,"")) | M15: =IF(B15="","",IFERROR(VLOOKUP(B15,'F01 - _Données Retraite'!$A$6:$K$20,2,FALSE)&" "&VLOOKUP(B15,'F01 - _Données Retraite'!$A$6:$K$20,3,FALSE),"")) | N15: =IF(B15="","",IFERROR(AVERAGEIF($B$6:$B$115,B15,$F$6:$F$115),0))
G16: =IF(F16="","",IFERROR(F16-70,"")) | M16: =IF(B16="","",IFERROR(VLOOKUP(B16,'F01 - _Données Retraite'!$A$6:$K$20,2,FALSE)&" "&VLOOKUP(B16,'F01 - _Données Retraite'!$A$6:$K$20,3,FALSE),"")) | N16: =IF(B16="","",IFERROR(AVERAGEIF($B$6:$B$115,B16,$F$6:$F$115),0))
G17: =IF(F17="","",IFERROR(F17-70,"")) | M17: =IF(B17="","",IFERROR(VLOOKUP(B17,'F01 - _Données Retraite'!$A$6:$K$20,2,FALSE)&" "&VLOOKUP(B17,'F01 - _Données Retraite'!$A$6:$K$20,3,FALSE),"")) | N17: =IF(B17="","",IFERROR(AVERAGEIF($B$6:$B$115,B17,$F$6:$F$115),0))
G18: =IF(F18="","",IFERROR(F18-70,"")) | M18: =IF(B18="","",IFERROR(VLOOKUP(B18,'F01 - _Données Retraite'!$A$6:$K$20,2,FALSE)&" "&VLOOKUP(B18,'F01 - _Données Retraite'!$A$6:$K$20,3,FALSE),"")) | N18: =IF(B18="","",IFERROR(AVERAGEIF($B$6:$B$115,B18,$F$6:$F$115),0))
G19: =IF(F19="","",IFERROR(F19-70,"")) | M19: =IF(B19="","",IFERROR(VLOOKUP(B19,'F01 - _Données Retraite'!$A$6:$K$20,2,FALSE)&" "&VLOOKUP(B19,'F01 - _Données Retraite'!$A$6:$K$20,3,FALSE),"")) | N19: =IF(B19="","",IFERROR(AVERAGEIF($B$6:$B$115,B19,$F$6:$F$115),0))
G20: =IF(F20="","",IFERROR(F20-70,"")) | M20: =IF(B20="","",IFERROR(VLOOKUP(B20,'F01 - _Données Retraite'!$A$6:$K$20,2,FALSE)&" "&VLOOKUP(B20,'F01 - _Données Retraite'!$A$6:$K$20,3,FALSE),"")) | N20: =IF(B20="","",IFERROR(AVERAGEIF($B$6:$B$115,B20,$F$6:$F$115),0))
... G115: =IF(F115="","",IFERROR(F115-70,"")) | M115: =IF(B115="","",IFERROR(VLOOKUP(B115,'F01 - _Données Retraite'!$A$6:$K$20,2,FALSE)&" "&VLOOKUP(B115,'F01 - _Données Retraite'!$A$6:$K$20,3,FALSE),"")) | N115: =IF(B115="","",IFERROR(AVERAGEIF($B$6:$B$115,B115,$F$6:$F$115),0))

Sheet F11 - 9-Suivi Médical Retraités
A2: 9-SUIVI MÉDICAL DES RETRAITÉS ET PRÉ-RETRAITÉS
A3: TABLEAU DYNAMIQUE — Saisissez dans la zone prévue ci-dessous
A5: Code Médical | B5: Matricule | C5: Type Examen | D5: Date Examen | E5: Médecin | F5: Résultat | G5: Aptitude | H5: Date Prochain Examen | I5: Suivi Pathologie | J5: Traitement en Cours | K5: Cout Examen (FCFA) | L5: Statut | M5: Observations
A6: MED-001 | B6: RET-001 | C6: Bilan complet | D6: 45667 | E6: Dr. Koné | F6: Normal | G6: Apte | H6: 46032 | I6: Hypertension légère | J6: Oui | K6: 85000 | L6: Validé | M6: =IF(B6="","",IFERROR(VLOOKUP(B6,'F01 - _Données Retraite'!$A$6:$K$20,2,FALSE)&" "&VLOOKUP(B6,'F01 - _Données Retraite'!$A$6:$K$20,3,FALSE),"")) | N6: =IF(B6="","",IFERROR(SUMIF($B$6:$B$115,B6,$K$6:$K$115),0))
A7: MED-002 | B7: RET-002 | C7: Bilan cardiovasculaire | D7: 45703 | E7: Dr. Traoré | F7: Anomalie mineure | G7: Apte avec restrictions | H7: 45884 | I7: Cholestérol élevé | J7: Oui | K7: 120000 | L7: Validé | M7: =IF(B7="","",IFERROR(VLOOKUP(B7,'F01 - _Données Retraite'!$A$6:$K$20,2,FALSE)&" "&VLOOKUP(B7,'F01 - _Données Retraite'!$A$6:$K$20,3,FALSE),"")) | N7: =IF(B7="","",IFERROR(SUMIF($B$6:$B$115,B7,$K$6:$K$115),0))
A8: MED-003 | B8: RET-003 | C8: Suivi post-retraite | D8: 45677 | E8: Dr. Bamba | F8: Normal | G8: Apte | H8: 46042 | I8: Aucune | J8: Non | K8: 45000 | L8: Validé | M8: =IF(B8="","",IFERROR(VLOOKUP(B8,'F01 - _Données Retraite'!$A$6:$K$20,2,FALSE)&" "&VLOOKUP(B8,'F01 - _Données Retraite'!$A$6:$K$20,3,FALSE),"")) | N8: =IF(B8="","",IFERROR(SUMIF($B$6:$B$115,B8,$K$6:$K$115),0))
M9: =IF(B9="","",IFERROR(VLOOKUP(B9,'F01 - _Données Retraite'!$A$6:$K$20,2,FALSE)&" "&VLOOKUP(B9,'F01 - _Données Retraite'!$A$6:$K$20,3,FALSE),"")) | N9: =IF(B9="","",IFERROR(SUMIF($B$6:$B$115,B9,$K$6:$K$115),0))
M10: =IF(B10="","",IFERROR(VLOOKUP(B10,'F01 - _Données Retraite'!$A$6:$K$20,2,FALSE)&" "&VLOOKUP(B10,'F01 - _Données Retraite'!$A$6:$K$20,3,FALSE),"")) | N10: =IF(B10="","",IFERROR(SUMIF($B$6:$B$115,B10,$K$6:$K$115),0))
M11: =IF(B11="","",IFERROR(VLOOKUP(B11,'F01 - _Données Retraite'!$A$6:$K$20,2,FALSE)&" "&VLOOKUP(B11,'F01 - _Données Retraite'!$A$6:$K$20,3,FALSE),"")) | N11: =IF(B11="","",IFERROR(SUMIF($B$6:$B$115,B11,$K$6:$K$115),0))
M12: =IF(B12="","",IFERROR(VLOOKUP(B12,'F01 - _Données Retraite'!$A$6:$K$20,2,FALSE)&" "&VLOOKUP(B12,'F01 - _Données Retraite'!$A$6:$K$20,3,FALSE),"")) | N12: =IF(B12="","",IFERROR(SUMIF($B$6:$B$115,B12,$K$6:$K$115),0))
M13: =IF(B13="","",IFERROR(VLOOKUP(B13,'F01 - _Données Retraite'!$A$6:$K$20,2,FALSE)&" "&VLOOKUP(B13,'F01 - _Données Retraite'!$A$6:$K$20,3,FALSE),"")) | N13: =IF(B13="","",IFERROR(SUMIF($B$6:$B$115,B13,$K$6:$K$115),0))
M14: =IF(B14="","",IFERROR(VLOOKUP(B14,'F01 - _Données Retraite'!$A$6:$K$20,2,FALSE)&" "&VLOOKUP(B14,'F01 - _Données Retraite'!$A$6:$K$20,3,FALSE),"")) | N14: =IF(B14="","",IFERROR(SUMIF($B$6:$B$115,B14,$K$6:$K$115),0))
M15: =IF(B15="","",IFERROR(VLOOKUP(B15,'F01 - _Données Retraite'!$A$6:$K$20,2,FALSE)&" "&VLOOKUP(B15,'F01 - _Données Retraite'!$A$6:$K$20,3,FALSE),"")) | N15: =IF(B15="","",IFERROR(SUMIF($B$6:$B$115,B15,$K$6:$K$115),0))
M16: =IF(B16="","",IFERROR(VLOOKUP(B16,'F01 - _Données Retraite'!$A$6:$K$20,2,FALSE)&" "&VLOOKUP(B16,'F01 - _Données Retraite'!$A$6:$K$20,3,FALSE),"")) | N16: =IF(B16="","",IFERROR(SUMIF($B$6:$B$115,B16,$K$6:$K$115),0))
M17: =IF(B17="","",IFERROR(VLOOKUP(B17,'F01 - _Données Retraite'!$A$6:$K$20,2,FALSE)&" "&VLOOKUP(B17,'F01 - _Données Retraite'!$A$6:$K$20,3,FALSE),"")) | N17: =IF(B17="","",IFERROR(SUMIF($B$6:$B$115,B17,$K$6:$K$115),0))
M18: =IF(B18="","",IFERROR(VLOOKUP(B18,'F01 - _Données Retraite'!$A$6:$K$20,2,FALSE)&" "&VLOOKUP(B18,'F01 - _Données Retraite'!$A$6:$K$20,3,FALSE),"")) | N18: =IF(B18="","",IFERROR(SUMIF($B$6:$B$115,B18,$K$6:$K$115),0))
M19: =IF(B19="","",IFERROR(VLOOKUP(B19,'F01 - _Données Retraite'!$A$6:$K$20,2,FALSE)&" "&VLOOKUP(B19,'F01 - _Données Retraite'!$A$6:$K$20,3,FALSE),"")) | N19: =IF(B19="","",IFERROR(SUMIF($B$6:$B$115,B19,$K$6:$K$115),0))
M20: =IF(B20="","",IFERROR(VLOOKUP(B20,'F01 - _Données Retraite'!$A$6:$K$20,2,FALSE)&" "&VLOOKUP(B20,'F01 - _Données Retraite'!$A$6:$K$20,3,FALSE),"")) | N20: =IF(B20="","",IFERROR(SUMIF($B$6:$B$115,B20,$K$6:$K$115),0))
... M115: =IF(B115="","",IFERROR(VLOOKUP(B115,'F01 - _Données Retraite'!$A$6:$K$20,2,FALSE)&" "&VLOOKUP(B115,'F01 - _Données Retraite'!$A$6:$K$20,3,FALSE),"")) | N115: =IF(B115="","",IFERROR(SUMIF($B$6:$B$115,B115,$K$6:$K$115),0))

Sheet F12 - 10-Gestion Succession
A2: 10-GESTION DE LA SUCCESSION
A3: TABLEAU DYNAMIQUE — Saisissez dans la zone prévue ci-dessous
A5: Code Succ. | B5: Matricule Sortant | C5: Poste Libéré | D5: Département | E5: Matricule Successeur | F5: Nom Successeur | G5: Date Prise de Fonction | H5: Type Succession | I5: Formation Requise | J5: Durée Transition (mois) | K5: Évaluation | L5: Statut | M5: Observations
A6: SUCC-001 | B6: RET-001 | C6: DG Adjoint | D6: Direction Générale | E6: SUC-001 | F6: Koné Ibrahim | G6: 45839 | H6: Interne | I6: Leadership stratégique | J6: 6 | K6: En attente | L6: Planifiée | M6: =IF(B6="","",IFERROR(VLOOKUP(B6,'F01 - _Données Retraite'!$A$6:$K$20,2,FALSE)&" "&VLOOKUP(B6,'F01 - _Données Retraite'!$A$6:$K$20,3,FALSE),"")) | N6: =IF(A6="","",IF(AND(D6<>"",E6<>""),"SUCCESSEUR IDENTIFIÉ","SANS SUCCESSEUR"))
A7: SUCC-002 | B7: RET-002 | C7: Dir. Financière | D7: Finance & Comptabilité | E7: SUC-002 | F7: Diallo Aminata | G7: 46054 | H7: Interne | I7: Contrôle de gestion avancé | J7: 3 | K7: Non | L7: En préparation | M7: =IF(B7="","",IFERROR(VLOOKUP(B7,'F01 - _Données Retraite'!$A$6:$K$20,2,FALSE)&" "&VLOOKUP(B7,'F01 - _Données Retraite'!$A$6:$K$20,3,FALSE),"")) | N7: =IF(A7="","",IF(AND(D7<>"",E7<>""),"SUCCESSEUR IDENTIFIÉ","SANS SUCCESSEUR"))
A8: SUCC-003 | B8: RET-003 | C8: DRH Senior | D8: Ressources Humaines | H8: Externe | I8: Management RH complet | J8: 0 | K8: Non | L8: Non commencé | M8: =IF(B8="","",IFERROR(VLOOKUP(B8,'F01 - _Données Retraite'!$A$6:$K$20,2,FALSE)&" "&VLOOKUP(B8,'F01 - _Données Retraite'!$A$6:$K$20,3,FALSE),"")) | N8: =IF(A8="","",IF(AND(D8<>"",E8<>""),"SUCCESSEUR IDENTIFIÉ","SANS SUCCESSEUR"))
M9: =IF(B9="","",IFERROR(VLOOKUP(B9,'F01 - _Données Retraite'!$A$6:$K$20,2,FALSE)&" "&VLOOKUP(B9,'F01 - _Données Retraite'!$A$6:$K$20,3,FALSE),"")) | N9: =IF(A9="","",IF(AND(D9<>"",E9<>""),"SUCCESSEUR IDENTIFIÉ","SANS SUCCESSEUR"))
M10: =IF(B10="","",IFERROR(VLOOKUP(B10,'F01 - _Données Retraite'!$A$6:$K$20,2,FALSE)&" "&VLOOKUP(B10,'F01 - _Données Retraite'!$A$6:$K$20,3,FALSE),"")) | N10: =IF(A10="","",IF(AND(D10<>"",E10<>""),"SUCCESSEUR IDENTIFIÉ","SANS SUCCESSEUR"))
M11: =IF(B11="","",IFERROR(VLOOKUP(B11,'F01 - _Données Retraite'!$A$6:$K$20,2,FALSE)&" "&VLOOKUP(B11,'F01 - _Données Retraite'!$A$6:$K$20,3,FALSE),"")) | N11: =IF(A11="","",IF(AND(D11<>"",E11<>""),"SUCCESSEUR IDENTIFIÉ","SANS SUCCESSEUR"))
M12: =IF(B12="","",IFERROR(VLOOKUP(B12,'F01 - _Données Retraite'!$A$6:$K$20,2,FALSE)&" "&VLOOKUP(B12,'F01 - _Données Retraite'!$A$6:$K$20,3,FALSE),"")) | N12: =IF(A12="","",IF(AND(D12<>"",E12<>""),"SUCCESSEUR IDENTIFIÉ","SANS SUCCESSEUR"))
M13: =IF(B13="","",IFERROR(VLOOKUP(B13,'F01 - _Données Retraite'!$A$6:$K$20,2,FALSE)&" "&VLOOKUP(B13,'F01 - _Données Retraite'!$A$6:$K$20,3,FALSE),"")) | N13: =IF(A13="","",IF(AND(D13<>"",E13<>""),"SUCCESSEUR IDENTIFIÉ","SANS SUCCESSEUR"))
M14: =IF(B14="","",IFERROR(VLOOKUP(B14,'F01 - _Données Retraite'!$A$6:$K$20,2,FALSE)&" "&VLOOKUP(B14,'F01 - _Données Retraite'!$A$6:$K$20,3,FALSE),"")) | N14: =IF(A14="","",IF(AND(D14<>"",E14<>""),"SUCCESSEUR IDENTIFIÉ","SANS SUCCESSEUR"))
M15: =IF(B15="","",IFERROR(VLOOKUP(B15,'F01 - _Données Retraite'!$A$6:$K$20,2,FALSE)&" "&VLOOKUP(B15,'F01 - _Données Retraite'!$A$6:$K$20,3,FALSE),"")) | N15: =IF(A15="","",IF(AND(D15<>"",E15<>""),"SUCCESSEUR IDENTIFIÉ","SANS SUCCESSEUR"))
M16: =IF(B16="","",IFERROR(VLOOKUP(B16,'F01 - _Données Retraite'!$A$6:$K$20,2,FALSE)&" "&VLOOKUP(B16,'F01 - _Données Retraite'!$A$6:$K$20,3,FALSE),"")) | N16: =IF(A16="","",IF(AND(D16<>"",E16<>""),"SUCCESSEUR IDENTIFIÉ","SANS SUCCESSEUR"))
M17: =IF(B17="","",IFERROR(VLOOKUP(B17,'F01 - _Données Retraite'!$A$6:$K$20,2,FALSE)&" "&VLOOKUP(B17,'F01 - _Données Retraite'!$A$6:$K$20,3,FALSE),"")) | N17: =IF(A17="","",IF(AND(D17<>"",E17<>""),"SUCCESSEUR IDENTIFIÉ","SANS SUCCESSEUR"))
M18: =IF(B18="","",IFERROR(VLOOKUP(B18,'F01 - _Données Retraite'!$A$6:$K$20,2,FALSE)&" "&VLOOKUP(B18,'F01 - _Données Retraite'!$A$6:$K$20,3,FALSE),"")) | N18: =IF(A18="","",IF(AND(D18<>"",E18<>""),"SUCCESSEUR IDENTIFIÉ","SANS SUCCESSEUR"))
M19: =IF(B19="","",IFERROR(VLOOKUP(B19,'F01 - _Données Retraite'!$A$6:$K$20,2,FALSE)&" "&VLOOKUP(B19,'F01 - _Données Retraite'!$A$6:$K$20,3,FALSE),"")) | N19: =IF(A19="","",IF(AND(D19<>"",E19<>""),"SUCCESSEUR IDENTIFIÉ","SANS SUCCESSEUR"))
M20: =IF(B20="","",IFERROR(VLOOKUP(B20,'F01 - _Données Retraite'!$A$6:$K$20,2,FALSE)&" "&VLOOKUP(B20,'F01 - _Données Retraite'!$A$6:$K$20,3,FALSE),"")) | N20: =IF(A20="","",IF(AND(D20<>"",E20<>""),"SUCCESSEUR IDENTIFIÉ","SANS SUCCESSEUR"))
... M115: =IF(B115="","",IFERROR(VLOOKUP(B115,'F01 - _Données Retraite'!$A$6:$K$20,2,FALSE)&" "&VLOOKUP(B115,'F01 - _Données Retraite'!$A$6:$K$20,3,FALSE),"")) | N115: =IF(A115="","",IF(AND(D115<>"",E115<>""),"SUCCESSEUR IDENTIFIÉ","SANS SUCCESSEUR"))

Sheet F13 - 11-Budget Retraites
A2: 11-BUDGET RETRAITES ET PRÉVOYANCE
A3: TABLEAU DYNAMIQUE — Saisissez dans la zone prévue ci-dessous
A5: Code Budget | B5: Poste Budget | C5: Montant Prévu (FCFA) | D5: Montant Réalisé (FCFA) | E5: Écart (FCFA) | F5: Taux Réalisation (%) | G5: Trimestre | H5: Catégorie | I5: Mode Paiement | J5: Validé Par | K5: Date Validation | L5: Observations
A6: BUD-001 | B6: Pensions - Régime Général | C6: 45000000 | D6: 42500000 | E6: =IF(OR(C6="",D6=""),"",C6-D6) | F6: =IF(OR(C6="",D6=""),"",IFERROR(D6/C6*100,0)) | G6: T1 2025 | H6: Pension | I6: Virement bancaire | J6: DAF | K6: 45762 | M6: =IF(G6="","",IFERROR(SUMIF($G$6:$G$115,G6,$D$6:$D$115),0)) | N6: =IF(G6="","",IFERROR(AVERAGEIF($G$6:$G$115,G6,$F$6:$F$115),0))
A7: BUD-002 | B7: Pensions - Régime Cadre | C7: 58000000 | D7: 56200000 | E7: =IF(OR(C7="",D7=""),"",C7-D7) | F7: =IF(OR(C7="",D7=""),"",IFERROR(D7/C7*100,0)) | G7: T1 2025 | H7: Pension | I7: Virement bancaire | J7: DAF | K7: 45762 | M7: =IF(G7="","",IFERROR(SUMIF($G$6:$G$115,G7,$D$6:$D$115),0)) | N7: =IF(G7="","",IFERROR(AVERAGEIF($G$6:$G$115,G7,$F$6:$F$115),0))
A8: BUD-003 | B8: Cotisations Prévoyance | C8: 18000000 | D8: 17850000 | E8: =IF(OR(C8="",D8=""),"",C8-D8) | F8: =IF(OR(C8="",D8=""),"",IFERROR(D8/C8*100,0)) | G8: T1 2025 | H8: Prévoyance | I8: Prélèvement auto. | J8: DRH | K8: 45757 | M8: =IF(G8="","",IFERROR(SUMIF($G$6:$G$115,G8,$D$6:$D$115),0)) | N8: =IF(G8="","",IFERROR(AVERAGEIF($G$6:$G$115,G8,$F$6:$F$115),0))
A9: BUD-004 | B9: Outplacement | C9: 2500000 | D9: 1800000 | E9: =IF(OR(C9="",D9=""),"",C9-D9) | F9: =IF(OR(C9="",D9=""),"",IFERROR(D9/C9*100,0)) | G9: T1 2025 | H9: Transition | I9: Virement bancaire | J9: DRH | K9: 45767 | M9: =IF(G9="","",IFERROR(SUMIF($G$6:$G$115,G9,$D$6:$D$115),0)) | N9: =IF(G9="","",IFERROR(AVERAGEIF($G$6:$G$115,G9,$F$6:$F$115),0))
A10: BUD-005 | B10: Formation Fin de Carrière | C10: 1200000 | D10: 950000 | E10: =IF(OR(C10="",D10=""),"",C10-D10) | F10: =IF(OR(C10="",D10=""),"",IFERROR(D10/C10*100,0)) | G10: T1 2025 | H10: Formation | I10: Virement bancaire | J10: DRH | K10: 45757 | M10: =IF(G10="","",IFERROR(SUMIF($G$6:$G$115,G10,$D$6:$D$115),0)) | N10: =IF(G10="","",IFERROR(AVERAGEIF($G$6:$G$115,G10,$F$6:$F$115),0))
E11: =IF(OR(C11="",D11=""),"",C11-D11) | F11: =IF(OR(C11="",D11=""),"",IFERROR(D11/C11*100,0)) | M11: =IF(G11="","",IFERROR(SUMIF($G$6:$G$115,G11,$D$6:$D$115),0)) | N11: =IF(G11="","",IFERROR(AVERAGEIF($G$6:$G$115,G11,$F$6:$F$115),0))
E12: =IF(OR(C12="",D12=""),"",C12-D12) | F12: =IF(OR(C12="",D12=""),"",IFERROR(D12/C12*100,0)) | M12: =IF(G12="","",IFERROR(SUMIF($G$6:$G$115,G12,$D$6:$D$115),0)) | N12: =IF(G12="","",IFERROR(AVERAGEIF($G$6:$G$115,G12,$F$6:$F$115),0))
E13: =IF(OR(C13="",D13=""),"",C13-D13) | F13: =IF(OR(C13="",D13=""),"",IFERROR(D13/C13*100,0)) | M13: =IF(G13="","",IFERROR(SUMIF($G$6:$G$115,G13,$D$6:$D$115),0)) | N13: =IF(G13="","",IFERROR(AVERAGEIF($G$6:$G$115,G13,$F$6:$F$115),0))
E14: =IF(OR(C14="",D14=""),"",C14-D14) | F14: =IF(OR(C14="",D14=""),"",IFERROR(D14/C14*100,0)) | M14: =IF(G14="","",IFERROR(SUMIF($G$6:$G$115,G14,$D$6:$D$115),0)) | N14: =IF(G14="","",IFERROR(AVERAGEIF($G$6:$G$115,G14,$F$6:$F$115),0))
E15: =IF(OR(C15="",D15=""),"",C15-D15) | F15: =IF(OR(C15="",D15=""),"",IFERROR(D15/C15*100,0)) | M15: =IF(G15="","",IFERROR(SUMIF($G$6:$G$115,G15,$D$6:$D$115),0)) | N15: =IF(G15="","",IFERROR(AVERAGEIF($G$6:$G$115,G15,$F$6:$F$115),0))
E16: =IF(OR(C16="",D16=""),"",C16-D16) | F16: =IF(OR(C16="",D16=""),"",IFERROR(D16/C16*100,0)) | M16: =IF(G16="","",IFERROR(SUMIF($G$6:$G$115,G16,$D$6:$D$115),0)) | N16: =IF(G16="","",IFERROR(AVERAGEIF($G$6:$G$115,G16,$F$6:$F$115),0))
