Workbook

Sheet F01 - _Données Employés
A2: DONNÉES EMPLOYÉS — Base de référence Avantages Sociaux
A3: TABLEAU DYNAMIQUE — Saisissez dans la zone prévue ci-dessous
A5: Matricule | B5: Nom | C5: Prénom | D5: Département | E5: Poste | F5: Date Embauche | G5: Statut | H5: Classification | I5: Salaire de base (FCFA) | J5: Ancienneté (années)
A6: EMP-001 | B6: Nkoulou | C6: Patrice | D6: Direction Générale | E6: Réceptionniste chef | F6: 43174 | G6: CDI | H6: E4 | I6: 350000 | J6: =IF(F6="","",DATEDIF(F6,TODAY(),"Y")&" ans "&DATEDIF(F6,TODAY(),"YM")&" mois")
A7: EMP-002 | B7: Mbarga | C7: Sylvie | D7: Cuisine & Restauration | E7: Chef Cuisinier | F7: 42552 | G7: CDI | H7: E5 | I7: 420000 | J7: =IF(F7="","",DATEDIF(F7,TODAY(),"Y")&" ans "&DATEDIF(F7,TODAY(),"YM")&" mois")
A8: EMP-003 | B8: Nganou | C8: Clémentine | D8: Hébergement | E8: Gouvernante | F8: 43475 | G8: CDI | H8: E4 | I8: 320000 | J8: =IF(F8="","",DATEDIF(F8,TODAY(),"Y")&" ans "&DATEDIF(F8,TODAY(),"YM")&" mois")
A9: EMP-004 | B9: Tchinda | C9: Albert | D9: Cuisine & Restauration | E9: Serveur | F9: 44805 | G9: CDD | H9: E2 | I9: 180000 | J9: =IF(F9="","",DATEDIF(F9,TODAY(),"Y")&" ans "&DATEDIF(F9,TODAY(),"YM")&" mois")
A10: EMP-005 | B10: Bessa | C10: Jean-Pierre | D10: Sécurité | E10: Chef Sécurité | F10: 43059 | G10: CDI | H10: E4 | I10: 300000 | J10: =IF(F10="","",DATEDIF(F10,TODAY(),"Y")&" ans "&DATEDIF(F10,TODAY(),"YM")&" mois")
A11: EMP-006 | B11: Fotso | C11: Marie | D11: Finance & Comptabilité | E11: Comptable | F11: 43997 | G11: CDI | H11: E4 | I11: 340000 | J11: =IF(F11="","",DATEDIF(F11,TODAY(),"Y")&" ans "&DATEDIF(F11,TODAY(),"YM")&" mois")
A12: EMP-007 | B12: Kamga | C12: Samuel | D12: Entretien & Maintenance | E12: Technicien | F12: 44958 | G12: CDI | H12: E2 | I12: 195000 | J12: =IF(F12="","",DATEDIF(F12,TODAY(),"Y")&" ans "&DATEDIF(F12,TODAY(),"YM")&" mois")
A13: EMP-008 | B13: Djomga | C13: Thérèse | D13: Réception & Front Office | E13: Concierge | F13: 42095 | G13: CDI | H13: E4 | I13: 310000 | J13: =IF(F13="","",DATEDIF(F13,TODAY(),"Y")&" ans "&DATEDIF(F13,TODAY(),"YM")&" mois")
A14: EMP-009 | B14: Tabi | C14: Emmanuel | D14: Cuisine & Restauration | E14: Plongeur | F14: 45153 | G14: CDD | H14: E1 | I14: 150000 | J14: =IF(F14="","",DATEDIF(F14,TODAY(),"Y")&" ans "&DATEDIF(F14,TODAY(),"YM")&" mois")
A15: EMP-010 | B15: Ngo | C15: Anatole | D15: Cuisine & Restauration | E15: Barman | F15: 44256 | G15: CDI | H15: E3 | I15: 250000 | J15: =IF(F15="","",DATEDIF(F15,TODAY(),"Y")&" ans "&DATEDIF(F15,TODAY(),"YM")&" mois")
A16: EMP-011 | B16: Aka | C16: Béatrice | D16: Ressources Humaines | E16: Assistante RH | F16: 44075 | G16: CDI | H16: E3 | I16: 260000 | J16: =IF(F16="","",DATEDIF(F16,TODAY(),"Y")&" ans "&DATEDIF(F16,TODAY(),"YM")&" mois")
A17: EMP-012 | B17: Yao | C17: Serge | D17: Commercial & Marketing | E17: Responsable commercial | F17: 42870 | G17: CDI | H17: E5 | I17: 380000 | J17: =IF(F17="","",DATEDIF(F17,TODAY(),"Y")&" ans "&DATEDIF(F17,TODAY(),"YM")&" mois")

Sheet F02 - _Lists
A2: LISTES DE RÉFÉRENCE — Valeurs pour listes déroulantes
A3: TABLEAU DYNAMIQUE — Saisissez dans la zone prévue ci-dessous
A5: Departements | B5: Categories Avantages | C5: Types Avantages | D5: Frequences | E5: Statuts Avantages | F5: Fournisseurs | G5: Niveaux Couverture | H5: Plafonds | I5: Oui Non | J5: Modes Paiement | K5: Mois | L5: Etats Logement | M5: Types Reclamation | N5: Priorites | O5: Statuts Reclamation | P5: Types Pret | Q5: Types Alimentation | R5: Types Transport | S5: Plans Retraite | T5: Classifications | U5: Statuts Emploi
A6: Direction Générale | B6: Santé | C6: Obligatoire | D6: Mensuel | E6: Actif | F6: CNPS | G6: Basique | H6: 50 000 FCFA | I6: Oui | J6: Virement | K6: Janvier | L6: Bon | M6: Retard remboursement | N6: Basse | O6: Ouverte | P6: Prêt social | Q6: Tickets restaurant | R6: Abonnement transport | S6: PER | T6: E1 | U6: CDI
A7: Ressources Humaines | B7: Retraite | C7: Conventionné | D7: Trimestriel | E7: Suspendu | F7: AXA Assurance | G7: Standard | H7: 75 000 FCFA | I7: Non | J7: Chèque | K7: Février | L7: Moyen | M7: Couverture refusée | N7: Moyenne | O7: En cours | P7: Avance sur salaire | Q7: Panier repas | R7: Indemnité km | S7: REER | T7: E2 | U7: CDD
A8: Finance & Comptabilité | B8: Prévoyance | C8: Facultatif | D8: Annuel | E8: En attente | F8: NSIA Vie | G8: Premium | H8: 100 000 FCFA | J8: Espèces | K8: Mars | L8: Réparation | M8: Montant erroné | N8: Haute | O8: Résolue | P8: Aide financière | Q8: Prime alimentaire | R8: Véhicule fonction | S8: CARPA | T8: E3 | U8: Stage
A9: Réception & Front Office | B9: Alimentation | D9: Ponctuel | E9: Résilié | F9: Allianz | H9: 150 000 FCFA | J9: Prélèvement automatique | K9: Avril | M9: Information manquante | O9: Rejetée | S9: CNPS complémentaire | T9: E4 | U9: Intérim
A10: Hébergement | B10: Transport | F10: Mutuelle Hôteliers CI | H10: 200 000 FCFA | K10: Mai | T10: E5
A11: Cuisine & Restauration | B11: Logement | F11: SNC Lavie | H11: 300 000 FCFA | K11: Juin | T11: E6
A12: Entretien & Maintenance | B12: Formation | F12: Cie Ivoirienne d'Assurance | H12: 500 000 FCFA | K12: Juillet
A13: Sécurité | B13: Loisirs | F13: SATRAM | K13: Août
A14: Commercial & Marketing | B14: Autre | F14: CFAO Assurances | K14: Septembre
A15: Achats & Logistique | F15: Coris Assurances | K15: Octobre
A16: Sport & Loisirs | K16: Novembre
A17: Animation | K17: Décembre

Sheet F03 - 1-Tableau de Bord
A2: DOMAINE 22 — AVANTAGES SOCIAUX ET PRÉVOYANCE
A3: Tableau de Bord Synthétique — Suivi en temps réel des avantages sociaux et prévoyance
A5: INDICATEURS CLÉS DE PERFORMANCE
A6: Total employés bénéficiant | C6: Coût total avantages/mois (FCFA) | E6: Taux de couverture santé (%) | G6: Budget annuel avantages (FCFA) | I6: Fournisseurs actifs | K6: Avantages en attente
A7: =COUNTA('F05 - 3-Inscription Avant.'!A6:A25)-COUNTBLANK('F05 - 3-Inscription Avant.'!A6:A25) | C7: =SUMIF('F05 - 3-Inscription Avant.'!D6:D115,"Actif",'F05 - 3-Inscription Avant.'!H6:H115) | E7: =IF(COUNTA('F01 - _Données Employés'!A6:A20)=0,0,COUNTIF('F05 - 3-Inscription Avant.'!F6:F115,"AV-001")/COUNTA('F01 - _Données Employés'!A6:A20)) | G7: =SUMIF('F05 - 3-Inscription Avant.'!D6:D115,"Actif",'F05 - 3-Inscription Avant.'!H6:H115)*12 | I7: =COUNTIF('F07 - 5-Gest. Fournisseurs'!H6:H35,"Oui") | K7: =COUNTIF('F05 - 3-Inscription Avant.'!D6:D115,"En attente")
A9: ANALYSE PAR CATÉGORIE D'AVANTAGE | I9: DISTRIBUTION PAR STATUT
A10: Catégorie d'avantage | B10: Nb bénéficiaires | C10: Coût mensuel (FCFA) | D10: % du total | E10: Budget annuel | F10: Coût moyen/bénéf. | G10: Statut | I10: Statut | J10: Nombre | K10: Pourcentage
A11: Santé | B11: =COUNTIF('F05 - 3-Inscription Avant.'!F6:F115,'F04 - 2-Référentiel Avant.'!B6:B20) | C11: =SUMIF('F04 - 2-Référentiel Avant.'!B6:B20,A11,'F05 - 3-Inscription Avant.'!H6:H115) | D11: =IF(SUM(C11:C19)=0,0,C11/SUM(C11:C19)) | E11: =C11*12 | F11: =IF(B11=0,0,C11/B11) | G11: =IF(B11>0,"Actif","Inactif") | I11: Actif | J11: =COUNTIF('F05 - 3-Inscription Avant.'!D6:D115,I11) | K11: =IF(SUM(J11:J14)=0,0,J11/SUM(J11:J14))
A12: Retraite | B12: =COUNTIF('F05 - 3-Inscription Avant.'!F6:F115,'F04 - 2-Référentiel Avant.'!B6:B20) | C12: =SUMIF('F04 - 2-Référentiel Avant.'!B6:B20,A12,'F05 - 3-Inscription Avant.'!H6:H115) | D12: =IF(SUM(C11:C19)=0,0,C12/SUM(C11:C19)) | E12: =C12*12 | F12: =IF(B12=0,0,C12/B12) | G12: =IF(B12>0,"Actif","Inactif") | I12: Suspendu | J12: =COUNTIF('F05 - 3-Inscription Avant.'!D6:D115,I12) | K12: =IF(SUM(J11:J14)=0,0,J12/SUM(J11:J14))
A13: Prévoyance | B13: =COUNTIF('F05 - 3-Inscription Avant.'!F6:F115,'F04 - 2-Référentiel Avant.'!B6:B20) | C13: =SUMIF('F04 - 2-Référentiel Avant.'!B6:B20,A13,'F05 - 3-Inscription Avant.'!H6:H115) | D13: =IF(SUM(C11:C19)=0,0,C13/SUM(C11:C19)) | E13: =C13*12 | F13: =IF(B13=0,0,C13/B13) | G13: =IF(B13>0,"Actif","Inactif") | I13: En attente | J13: =COUNTIF('F05 - 3-Inscription Avant.'!D6:D115,I13) | K13: =IF(SUM(J11:J14)=0,0,J13/SUM(J11:J14))
A14: Alimentation | B14: =COUNTIF('F05 - 3-Inscription Avant.'!F6:F115,'F04 - 2-Référentiel Avant.'!B6:B20) | C14: =SUMIF('F04 - 2-Référentiel Avant.'!B6:B20,A14,'F05 - 3-Inscription Avant.'!H6:H115) | D14: =IF(SUM(C11:C19)=0,0,C14/SUM(C11:C19)) | E14: =C14*12 | F14: =IF(B14=0,0,C14/B14) | G14: =IF(B14>0,"Actif","Inactif") | I14: Résilié | J14: =COUNTIF('F05 - 3-Inscription Avant.'!D6:D115,I14) | K14: =IF(SUM(J11:J14)=0,0,J14/SUM(J11:J14))
A15: Transport | B15: =COUNTIF('F05 - 3-Inscription Avant.'!F6:F115,'F04 - 2-Référentiel Avant.'!B6:B20) | C15: =SUMIF('F04 - 2-Référentiel Avant.'!B6:B20,A15,'F05 - 3-Inscription Avant.'!H6:H115) | D15: =IF(SUM(C11:C19)=0,0,C15/SUM(C11:C19)) | E15: =C15*12 | F15: =IF(B15=0,0,C15/B15) | G15: =IF(B15>0,"Actif","Inactif")
A16: Logement | B16: =COUNTIF('F05 - 3-Inscription Avant.'!F6:F115,'F04 - 2-Référentiel Avant.'!B6:B20) | C16: =SUMIF('F04 - 2-Référentiel Avant.'!B6:B20,A16,'F05 - 3-Inscription Avant.'!H6:H115) | D16: =IF(SUM(C11:C19)=0,0,C16/SUM(C11:C19)) | E16: =C16*12 | F16: =IF(B16=0,0,C16/B16) | G16: =IF(B16>0,"Actif","Inactif")
A17: Formation | B17: =COUNTIF('F05 - 3-Inscription Avant.'!F6:F115,'F04 - 2-Référentiel Avant.'!B6:B20) | C17: =SUMIF('F04 - 2-Référentiel Avant.'!B6:B20,A17,'F05 - 3-Inscription Avant.'!H6:H115) | D17: =IF(SUM(C11:C19)=0,0,C17/SUM(C11:C19)) | E17: =C17*12 | F17: =IF(B17=0,0,C17/B17) | G17: =IF(B17>0,"Actif","Inactif")
A18: Loisirs | B18: =COUNTIF('F05 - 3-Inscription Avant.'!F6:F115,'F04 - 2-Référentiel Avant.'!B6:B20) | C18: =SUMIF('F04 - 2-Référentiel Avant.'!B6:B20,A18,'F05 - 3-Inscription Avant.'!H6:H115) | D18: =IF(SUM(C11:C19)=0,0,C18/SUM(C11:C19)) | E18: =C18*12 | F18: =IF(B18=0,0,C18/B18) | G18: =IF(B18>0,"Actif","Inactif")
A19: Autre | B19: =COUNTIF('F05 - 3-Inscription Avant.'!F6:F115,'F04 - 2-Référentiel Avant.'!B6:B20) | C19: =SUMIF('F04 - 2-Référentiel Avant.'!B6:B20,A19,'F05 - 3-Inscription Avant.'!H6:H115) | D19: =IF(SUM(C11:C19)=0,0,C19/SUM(C11:C19)) | E19: =C19*12 | F19: =IF(B19=0,0,C19/B19) | G19: =IF(B19>0,"Actif","Inactif")
A20: TOTAL | B20: =SUM(B11:B19) | C20: =SUM(C11:C19) | D20: =SUM(D11:D19) | E20: =SUM(E11:E19)
A22: TOP 5 AVANTAGES LES PLUS COÛTEUX
A23: Rang | B23: Code Avantage | C23: Intitulé | D23: Catégorie | E23: Coût unitaire (FCFA) | F23: Bénéficiaires | G23: Coût total/mois
A24: 1 | B24: =INDEX('F04 - 2-Référentiel Avant.'!A6:A20,MATCH(LARGE('F04 - 2-Référentiel Avant.'!H6:H20*COUNTIF('F05 - 3-Inscription Avant.'!F6:F115,'F04 - 2-Référentiel Avant.'!A6:A20),1),'F04 - 2-Référentiel Avant.'!H6:H20*COUNTIF('F05 - 3-Inscription Avant.'!F6:F115,'F04 - 2-Référentiel Avant.'!A6:A20),0)) | C24: =IFERROR(VLOOKUP(B24,'F04 - 2-Référentiel Avant.'!$A$6:$C$20,2,FALSE),"") | D24: =IFERROR(VLOOKUP(B24,'F04 - 2-Référentiel Avant.'!$A$6:$C$20,3,FALSE),"") | E24: =IFERROR(VLOOKUP(B24,'F04 - 2-Référentiel Avant.'!$A$6:$H$20,8,FALSE),0) | F24: =COUNTIF('F05 - 3-Inscription Avant.'!F6:F115,B24) | G24: =E24*F24
A25: 2 | B25: =INDEX('F04 - 2-Référentiel Avant.'!A6:A20,MATCH(LARGE('F04 - 2-Référentiel Avant.'!H6:H20*COUNTIF('F05 - 3-Inscription Avant.'!F6:F115,'F04 - 2-Référentiel Avant.'!A6:A20),2),'F04 - 2-Référentiel Avant.'!H6:H20*COUNTIF('F05 - 3-Inscription Avant.'!F6:F115,'F04 - 2-Référentiel Avant.'!A6:A20),0)) | C25: =IFERROR(VLOOKUP(B25,'F04 - 2-Référentiel Avant.'!$A$6:$C$20,2,FALSE),"") | D25: =IFERROR(VLOOKUP(B25,'F04 - 2-Référentiel Avant.'!$A$6:$C$20,3,FALSE),"") | E25: =IFERROR(VLOOKUP(B25,'F04 - 2-Référentiel Avant.'!$A$6:$H$20,8,FALSE),0) | F25: =COUNTIF('F05 - 3-Inscription Avant.'!F6:F115,B25) | G25: =E25*F25
A26: 3 | B26: =INDEX('F04 - 2-Référentiel Avant.'!A6:A20,MATCH(LARGE('F04 - 2-Référentiel Avant.'!H6:H20*COUNTIF('F05 - 3-Inscription Avant.'!F6:F115,'F04 - 2-Référentiel Avant.'!A6:A20),3),'F04 - 2-Référentiel Avant.'!H6:H20*COUNTIF('F05 - 3-Inscription Avant.'!F6:F115,'F04 - 2-Référentiel Avant.'!A6:A20),0)) | C26: =IFERROR(VLOOKUP(B26,'F04 - 2-Référentiel Avant.'!$A$6:$C$20,2,FALSE),"") | D26: =IFERROR(VLOOKUP(B26,'F04 - 2-Référentiel Avant.'!$A$6:$C$20,3,FALSE),"") | E26: =IFERROR(VLOOKUP(B26,'F04 - 2-Référentiel Avant.'!$A$6:$H$20,8,FALSE),0) | F26: =COUNTIF('F05 - 3-Inscription Avant.'!F6:F115,B26) | G26: =E26*F26
A27: 4 | B27: =INDEX('F04 - 2-Référentiel Avant.'!A6:A20,MATCH(LARGE('F04 - 2-Référentiel Avant.'!H6:H20*COUNTIF('F05 - 3-Inscription Avant.'!F6:F115,'F04 - 2-Référentiel Avant.'!A6:A20),4),'F04 - 2-Référentiel Avant.'!H6:H20*COUNTIF('F05 - 3-Inscription Avant.'!F6:F115,'F04 - 2-Référentiel Avant.'!A6:A20),0)) | C27: =IFERROR(VLOOKUP(B27,'F04 - 2-Référentiel Avant.'!$A$6:$C$20,2,FALSE),"") | D27: =IFERROR(VLOOKUP(B27,'F04 - 2-Référentiel Avant.'!$A$6:$C$20,3,FALSE),"") | E27: =IFERROR(VLOOKUP(B27,'F04 - 2-Référentiel Avant.'!$A$6:$H$20,8,FALSE),0) | F27: =COUNTIF('F05 - 3-Inscription Avant.'!F6:F115,B27) | G27: =E27*F27
A28: 5 | B28: =INDEX('F04 - 2-Référentiel Avant.'!A6:A20,MATCH(LARGE('F04 - 2-Référentiel Avant.'!H6:H20*COUNTIF('F05 - 3-Inscription Avant.'!F6:F115,'F04 - 2-Référentiel Avant.'!A6:A20),5),'F04 - 2-Référentiel Avant.'!H6:H20*COUNTIF('F05 - 3-Inscription Avant.'!F6:F115,'F04 - 2-Référentiel Avant.'!A6:A20),0)) | C28: =IFERROR(VLOOKUP(B28,'F04 - 2-Référentiel Avant.'!$A$6:$C$20,2,FALSE),"") | D28: =IFERROR(VLOOKUP(B28,'F04 - 2-Référentiel Avant.'!$A$6:$C$20,3,FALSE),"") | E28: =IFERROR(VLOOKUP(B28,'F04 - 2-Référentiel Avant.'!$A$6:$H$20,8,FALSE),0) | F28: =COUNTIF('F05 - 3-Inscription Avant.'!F6:F115,B28) | G28: =E28*F28

Sheet F04 - 2-Référentiel Avant.
A2: RÉFÉRENTIEL DES AVANTAGES SOCIAUX ET PRÉVOYANCE
A3: TABLEAU DYNAMIQUE — Saisissez dans la zone prévue ci-dessous
A5: Code avantage | B5: Catégorie | C5: Intitulé | D5: Description | E5: Type | F5: Fréquence | G5: Fournisseur | H5: Coût unitaire (FCFA) | I5: Plafond (FCFA) | J5: Base de calcul | K5: Bénéficiaires éligibles | L5: Conformité légale | M5: Date MAJ
A6: AV-001 | B6: Santé | C6: CNPS - Prestations familiales | D6: Couverture sociale de base obligatoire | E6: Obligatoire | F6: Mensuel | G6: CNPS | H6: 14000 | I6: 200000 | J6: Salaire de base × 2,8% | K6: Tous employés | L6: Conforme - Art. 21 Code Travail CI | M6: 45292
A7: AV-002 | B7: Santé | C7: Mutuelle santé hôtellerie | D7: Complémentaire santé collective | E7: Conventionné | F7: Mensuel | G7: Mutuelle Hôteliers CI | H7: 18500 | I7: 500000 | J7: Forfait par catégorie | K7: Tous CDI | L7: Conforme - Accord collectif | M7: 45292
A8: AV-003 | B8: Prévoyance | C8: Assurance décès-invalidité | D8: Capital décès + invalidité permanente | E8: Obligatoire | F8: Mensuel | G8: AXA Assurance | H8: 8500 | I8: 10000000 | J8: Salaire × 1,7% | K8: Tous employés | L8: Conforme - CNPS | M8: 45292
A9: AV-004 | B9: Alimentation | C9: Tickets restaurant | D9: Aide alimentaire journalière | E9: Conventionné | F9: Mensuel | G9: SNC Lavie | H9: 22000 | I9: 50000 | J9: Nb jours × valeur faciale | K9: Tous employés | L9: Conforme - Convention collective | M9: 45292
A10: AV-005 | B10: Transport | C10: Prime de transport | D10: Indemnité trajet domicile-travail | E10: Conventionné | F10: Mensuel | H10: 25000 | I10: 30000 | J10: Forfait mensuel | K10: Tous employés | L10: Conforme - Art. 30 | M10: 45292
A11: AV-006 | B11: Logement | C11: Prêt logement social | D11: Aide à l'accession au logement | E11: Facultatif | F11: Ponctuel | G11: NSIA Vie | H11: 0 | I11: 5000000 | J11: Salaire × 36 max | K11: CDI > 2 ans | L11: Conforme | M11: 45292
A12: AV-007 | B12: Prévoyance | C12: Assurance chômage | D12: Indemnisation perte d'emploi | E12: Obligatoire | F12: Mensuel | G12: CNPS | H12: 5200 | I12: 200000 | J12: Salaire × 1,04% | K12: Tous employés | L12: Conforme - Décret 96-200 | M12: 45292
A13: AV-008 | B13: Retraite | C13: Retraite complémentaire | D13: Épargne retraite volontaire | E13: Facultatif | F13: Mensuel | G13: Allianz | H13: 15000 | I13: 150000 | J13: Forfait + % salaire | K13: CDI volontaires | L13: Conforme - Art. 50 Code Travail | M13: 45292
A14: AV-009 | B14: Santé | C14: Médecine du travail | D14: Visites médicales obligatoires | E14: Obligatoire | F14: Annuel | G14: SATRAM | H14: 5000 | I14: 10000 | J14: Forfait annuel / employé | K14: Tous employés | L14: Conforme - Art. 65 Code Travail | M14: 45292
A15: AV-010 | B15: Alimentation | C15: Prime panier | D15: Prime alimentaire complémentaire | E15: Conventionné | F15: Mensuel | H15: 15000 | I15: 20000 | J15: Forfait mensuel | K15: Tous employés | L15: Conforme - Accord entreprise | M15: 45292
A16: AV-011 | B16: Prévoyance | C16: Allocation familiale | D16: Prestations familiales CNPS | E16: Obligatoire | F16: Mensuel | G16: CNPS | H16: 5000 | I16: 50000 | J16: Par enfant à charge | K16: Employés avec enfants | L16: Conforme - Art. 35 | M16: 45292
A17: AV-012 | B17: Prévoyance | C17: Indemnité de licenciement | D17: Indemnité départ forcé | E17: Obligatoire | F17: Ponctuel | H17: 0 | I17: 0 | J17: Ancienneté × salaire | K17: Selon conditions | L17: Conforme - Art. 20-21 | M17: 45292
A18: AV-013 | B18: Formation | C18: Formation continue | D18: Droit à la formation professionnelle | E18: Obligatoire | F18: Annuel | H18: 40000 | I18: 80000 | J18: 1,2% masse salariale | K18: Tous employés | L18: Conforme - Art. 22-24 | M18: 45292
A19: AV-014 | B19: Autre | C19: Vêtements de travail | D19: Tenue professionnelle fournie | E19: Conventionné | F19: Annuel | H19: 25000 | I19: 35000 | J19: Forfait annuel | K19: Tous employés | L19: Conforme | M19: 45292
A20: AV-015 | B20: Autre | C20: Prime d'ancienneté | D20: Prime fidélisation selon ancienneté | E20: Conventionné | F20: Annuel | H20: 0 | I20: 50000 | J20: 2% × salaire × années | K20: CDI > 1 an | L20: Conforme - Convention collective | M20: 45292

Sheet F05 - 3-Inscription Avant.
A2: INSCRIPTION AUX AVANTAGES SOCIAUX
A3: TABLEAU DYNAMIQUE — Saisissez dans la zone prévue ci-dessous
A5: Matricule | B5: Nom (VLOOKUP) | C5: Prénom (VLOOKUP) | D5: Code avantage | E5: Intitulé (VLOOKUP) | F5: Catégorie (VLOOKUP) | G5: Date inscription | H5: Statut | I5: Cotisation employé (FCFA) | J5: Cotisation employeur (FCFA) | K5: Coût total (FCFA) | L5: Date début | M5: Date fin | N5: Date MAJ
A6: EMP-001 | B6: =IFERROR(VLOOKUP(A6,'F01 - _Données Employés'!$A$6:$C$20,2,FALSE),"") | C6: =IFERROR(VLOOKUP(A6,'F01 - _Données Employés'!$A$6:$C$20,3,FALSE),"") | D6: AV-001 | E6: =IFERROR(VLOOKUP(D6,'F04 - 2-Référentiel Avant.'!$A$6:$C$20,3,FALSE),"") | F6: =IFERROR(VLOOKUP(D6,'F04 - 2-Référentiel Avant.'!$A$6:$B$20,2,FALSE),"") | G6: 43174 | H6: Actif | I6: 9800 | J6: 14000 | K6: =IF(I6="",0,I6+J6) | L6: 43174 | N6: 45444
A7: EMP-001 | B7: =IFERROR(VLOOKUP(A7,'F01 - _Données Employés'!$A$6:$C$20,2,FALSE),"") | C7: =IFERROR(VLOOKUP(A7,'F01 - _Données Employés'!$A$6:$C$20,3,FALSE),"") | D7: AV-002 | E7: =IFERROR(VLOOKUP(D7,'F04 - 2-Référentiel Avant.'!$A$6:$C$20,3,FALSE),"") | F7: =IFERROR(VLOOKUP(D7,'F04 - 2-Référentiel Avant.'!$A$6:$B$20,2,FALSE),"") | G7: 43174 | H7: Actif | I7: 7400 | J7: 11100 | K7: =IF(I7="",0,I7+J7) | L7: 43174 | N7: 45444
A8: EMP-001 | B8: =IFERROR(VLOOKUP(A8,'F01 - _Données Employés'!$A$6:$C$20,2,FALSE),"") | C8: =IFERROR(VLOOKUP(A8,'F01 - _Données Employés'!$A$6:$C$20,3,FALSE),"") | D8: AV-003 | E8: =IFERROR(VLOOKUP(D8,'F04 - 2-Référentiel Avant.'!$A$6:$C$20,3,FALSE),"") | F8: =IFERROR(VLOOKUP(D8,'F04 - 2-Référentiel Avant.'!$A$6:$B$20,2,FALSE),"") | G8: 43174 | H8: Actif | I8: 5950 | J8: 8500 | K8: =IF(I8="",0,I8+J8) | L8: 43174 | N8: 45444
A9: EMP-001 | B9: =IFERROR(VLOOKUP(A9,'F01 - _Données Employés'!$A$6:$C$20,2,FALSE),"") | C9: =IFERROR(VLOOKUP(A9,'F01 - _Données Employés'!$A$6:$C$20,3,FALSE),"") | D9: AV-004 | E9: =IFERROR(VLOOKUP(D9,'F04 - 2-Référentiel Avant.'!$A$6:$C$20,3,FALSE),"") | F9: =IFERROR(VLOOKUP(D9,'F04 - 2-Référentiel Avant.'!$A$6:$B$20,2,FALSE),"") | G9: 43174 | H9: Actif | I9: 8800 | J9: 13200 | K9: =IF(I9="",0,I9+J9) | L9: 43174 | N9: 45444
A10: EMP-001 | B10: =IFERROR(VLOOKUP(A10,'F01 - _Données Employés'!$A$6:$C$20,2,FALSE),"") | C10: =IFERROR(VLOOKUP(A10,'F01 - _Données Employés'!$A$6:$C$20,3,FALSE),"") | D10: AV-005 | E10: =IFERROR(VLOOKUP(D10,'F04 - 2-Référentiel Avant.'!$A$6:$C$20,3,FALSE),"") | F10: =IFERROR(VLOOKUP(D10,'F04 - 2-Référentiel Avant.'!$A$6:$B$20,2,FALSE),"") | G10: 43174 | H10: Actif | I10: 10000 | J10: 15000 | K10: =IF(I10="",0,I10+J10) | L10: 43174 | N10: 45444
A11: EMP-002 | B11: =IFERROR(VLOOKUP(A11,'F01 - _Données Employés'!$A$6:$C$20,2,FALSE),"") | C11: =IFERROR(VLOOKUP(A11,'F01 - _Données Employés'!$A$6:$C$20,3,FALSE),"") | D11: AV-001 | E11: =IFERROR(VLOOKUP(D11,'F04 - 2-Référentiel Avant.'!$A$6:$C$20,3,FALSE),"") | F11: =IFERROR(VLOOKUP(D11,'F04 - 2-Référentiel Avant.'!$A$6:$B$20,2,FALSE),"") | G11: 42552 | H11: Actif | I11: 11760 | J11: 16800 | K11: =IF(I11="",0,I11+J11) | L11: 42552 | N11: 45444
A12: EMP-002 | B12: =IFERROR(VLOOKUP(A12,'F01 - _Données Employés'!$A$6:$C$20,2,FALSE),"") | C12: =IFERROR(VLOOKUP(A12,'F01 - _Données Employés'!$A$6:$C$20,3,FALSE),"") | D12: AV-002 | E12: =IFERROR(VLOOKUP(D12,'F04 - 2-Référentiel Avant.'!$A$6:$C$20,3,FALSE),"") | F12: =IFERROR(VLOOKUP(D12,'F04 - 2-Référentiel Avant.'!$A$6:$B$20,2,FALSE),"") | G12: 42552 | H12: Actif | I12: 7400 | J12: 11100 | K12: =IF(I12="",0,I12+J12) | L12: 42552 | N12: 45444
A13: EMP-002 | B13: =IFERROR(VLOOKUP(A13,'F01 - _Données Employés'!$A$6:$C$20,2,FALSE),"") | C13: =IFERROR(VLOOKUP(A13,'F01 - _Données Employés'!$A$6:$C$20,3,FALSE),"") | D13: AV-003 | E13: =IFERROR(VLOOKUP(D13,'F04 - 2-Référentiel Avant.'!$A$6:$C$20,3,FALSE),"") | F13: =IFERROR(VLOOKUP(D13,'F04 - 2-Référentiel Avant.'!$A$6:$B$20,2,FALSE),"") | G13: 42552 | H13: Actif | I13: 7140 | J13: 10200 | K13: =IF(I13="",0,I13+J13) | L13: 42552 | N13: 45444
A14: EMP-002 | B14: =IFERROR(VLOOKUP(A14,'F01 - _Données Employés'!$A$6:$C$20,2,FALSE),"") | C14: =IFERROR(VLOOKUP(A14,'F01 - _Données Employés'!$A$6:$C$20,3,FALSE),"") | D14: AV-008 | E14: =IFERROR(VLOOKUP(D14,'F04 - 2-Référentiel Avant.'!$A$6:$C$20,3,FALSE),"") | F14: =IFERROR(VLOOKUP(D14,'F04 - 2-Référentiel Avant.'!$A$6:$B$20,2,FALSE),"") | G14: 43466 | H14: Actif | I14: 5000 | J14: 10000 | K14: =IF(I14="",0,I14+J14) | L14: 43466 | N14: 45444
A15: EMP-003 | B15: =IFERROR(VLOOKUP(A15,'F01 - _Données Employés'!$A$6:$C$20,2,FALSE),"") | C15: =IFERROR(VLOOKUP(A15,'F01 - _Données Employés'!$A$6:$C$20,3,FALSE),"") | D15: AV-001 | E15: =IFERROR(VLOOKUP(D15,'F04 - 2-Référentiel Avant.'!$A$6:$C$20,3,FALSE),"") | F15: =IFERROR(VLOOKUP(D15,'F04 - 2-Référentiel Avant.'!$A$6:$B$20,2,FALSE),"") | G15: 43475 | H15: Actif | I15: 8960 | J15: 12800 | K15: =IF(I15="",0,I15+J15) | L15: 43475 | N15: 45444
A16: EMP-003 | B16: =IFERROR(VLOOKUP(A16,'F01 - _Données Employés'!$A$6:$C$20,2,FALSE),"") | C16: =IFERROR(VLOOKUP(A16,'F01 - _Données Employés'!$A$6:$C$20,3,FALSE),"") | D16: AV-002 | E16: =IFERROR(VLOOKUP(D16,'F04 - 2-Référentiel Avant.'!$A$6:$C$20,3,FALSE),"") | F16: =IFERROR(VLOOKUP(D16,'F04 - 2-Référentiel Avant.'!$A$6:$B$20,2,FALSE),"") | G16: 43475 | H16: Actif | I16: 7400 | J16: 11100 | K16: =IF(I16="",0,I16+J16) | L16: 43475 | N16: 45444
A17: EMP-003 | B17: =IFERROR(VLOOKUP(A17,'F01 - _Données Employés'!$A$6:$C$20,2,FALSE),"") | C17: =IFERROR(VLOOKUP(A17,'F01 - _Données Employés'!$A$6:$C$20,3,FALSE),"") | D17: AV-004 | E17: =IFERROR(VLOOKUP(D17,'F04 - 2-Référentiel Avant.'!$A$6:$C$20,3,FALSE),"") | F17: =IFERROR(VLOOKUP(D17,'F04 - 2-Référentiel Avant.'!$A$6:$B$20,2,FALSE),"") | G17: 43475 | H17: Actif | I17: 8800 | J17: 13200 | K17: =IF(I17="",0,I17+J17) | L17: 43475 | N17: 45444
... A25: EMP-006 | B25: =IFERROR(VLOOKUP(A25,'F01 - _Données Employés'!$A$6:$C$20,2,FALSE),"") | C25: =IFERROR(VLOOKUP(A25,'F01 - _Données Employés'!$A$6:$C$20,3,FALSE),"") | D25: AV-008 | E25: =IFERROR(VLOOKUP(D25,'F04 - 2-Référentiel Avant.'!$A$6:$C$20,3,FALSE),"") | F25: =IFERROR(VLOOKUP(D25,'F04 - 2-Référentiel Avant.'!$A$6:$B$20,2,FALSE),"") | G25: 44197 | H25: Actif | I25: 5000 | J25: 10000 | K25: =IF(I25="",0,I25+J25) | L25: 44197 | N25: 45444

Sheet F06 - 4-Suivi Cotisations
A2: SUIVI DES COTISATIONS AUX AVANTAGES SOCIAUX
A3: TABLEAU DYNAMIQUE — Saisissez dans la zone prévue ci-dessous
A5: Matricule | B5: Nom (VLOOKUP) | C5: Prénom (VLOOKUP) | D5: Avantage (VLOOKUP) | E5: Montant total (FCFA) | F5: Mois | G5: Paiement effectué | H5: Date paiement | I5: Mode paiement | J5: Référence | K5: Retard | L5: Pénalité (FCFA) | M5: Montant TTC (FCFA) | N5: Date MAJ
A6: EMP-001 | B6: =IFERROR(VLOOKUP(A6,'F01 - _Données Employés'!$A$6:$C$20,2,FALSE),"") | C6: =IFERROR(VLOOKUP(A6,'F01 - _Données Employés'!$A$6:$C$20,3,FALSE),"") | D6: =IFERROR(VLOOKUP(D6,'F04 - 2-Référentiel Avant.'!$A$6:$C$20,3,FALSE),"") | E6: 23800 | F6: Janvier | G6: Oui | H6: 45306 | I6: Virement | J6: REF-2024-0001 | K6: =IF(AND(G6="Non",TODAY()>DATE(2025,2,15)),"EN RETARD","") | L6: =IF(K6="EN RETARD",E6*0.05,0) | M6: =E6+L6 | N6: 45319
A7: EMP-002 | B7: =IFERROR(VLOOKUP(A7,'F01 - _Données Employés'!$A$6:$C$20,2,FALSE),"") | C7: =IFERROR(VLOOKUP(A7,'F01 - _Données Employés'!$A$6:$C$20,3,FALSE),"") | D7: =IFERROR(VLOOKUP(D7,'F04 - 2-Référentiel Avant.'!$A$6:$C$20,3,FALSE),"") | E7: 18500 | F7: Février | G7: Oui | H7: 45337 | I7: Prélèvement automatique | J7: REF-2024-0002 | K7: =IF(AND(G7="Non",TODAY()>DATE(2025,3,15)),"EN RETARD","") | L7: =IF(K7="EN RETARD",E7*0.05,0) | M7: =E7+L7 | N7: 45350
A8: EMP-003 | B8: =IFERROR(VLOOKUP(A8,'F01 - _Données Employés'!$A$6:$C$20,2,FALSE),"") | C8: =IFERROR(VLOOKUP(A8,'F01 - _Données Employés'!$A$6:$C$20,3,FALSE),"") | D8: =IFERROR(VLOOKUP(D8,'F04 - 2-Référentiel Avant.'!$A$6:$C$20,3,FALSE),"") | E8: 14440 | F8: Mars | G8: Oui | H8: 45366 | I8: Virement | J8: REF-2024-0003 | K8: =IF(AND(G8="Non",TODAY()>DATE(2025,4,15)),"EN RETARD","") | L8: =IF(K8="EN RETARD",E8*0.05,0) | M8: =E8+L8 | N8: 45379
A9: EMP-001 | B9: =IFERROR(VLOOKUP(A9,'F01 - _Données Employés'!$A$6:$C$20,2,FALSE),"") | C9: =IFERROR(VLOOKUP(A9,'F01 - _Données Employés'!$A$6:$C$20,3,FALSE),"") | D9: =IFERROR(VLOOKUP(D9,'F04 - 2-Référentiel Avant.'!$A$6:$C$20,3,FALSE),"") | E9: 22000 | F9: Avril | G9: Non | I9: Chèque | J9: REF-2024-0004 | K9: =IF(AND(G9="Non",TODAY()>DATE(2025,5,15)),"EN RETARD","") | L9: =IF(K9="EN RETARD",E9*0.05,0) | M9: =E9+L9 | N9: 45410
A10: EMP-005 | B10: =IFERROR(VLOOKUP(A10,'F01 - _Données Employés'!$A$6:$C$20,2,FALSE),"") | C10: =IFERROR(VLOOKUP(A10,'F01 - _Données Employés'!$A$6:$C$20,3,FALSE),"") | D10: =IFERROR(VLOOKUP(D10,'F04 - 2-Référentiel Avant.'!$A$6:$C$20,3,FALSE),"") | E10: 20400 | F10: Mai | G10: Oui | H10: 45427 | I10: Virement | J10: REF-2024-0005 | K10: =IF(AND(G10="Non",TODAY()>DATE(2025,6,15)),"EN RETARD","") | L10: =IF(K10="EN RETARD",E10*0.05,0) | M10: =E10+L10 | N10: 45440
A11: EMP-006 | B11: =IFERROR(VLOOKUP(A11,'F01 - _Données Employés'!$A$6:$C$20,2,FALSE),"") | C11: =IFERROR(VLOOKUP(A11,'F01 - _Données Employés'!$A$6:$C$20,3,FALSE),"") | D11: =IFERROR(VLOOKUP(D11,'F04 - 2-Référentiel Avant.'!$A$6:$C$20,3,FALSE),"") | E11: 15800 | F11: Juin | G11: Oui | H11: 45458 | I11: Prélèvement automatique | J11: REF-2024-0006 | K11: =IF(AND(G11="Non",TODAY()>DATE(2025,7,15)),"EN RETARD","") | L11: =IF(K11="EN RETARD",E11*0.05,0) | M11: =E11+L11 | N11: 45471
A12: EMP-002 | B12: =IFERROR(VLOOKUP(A12,'F01 - _Données Employés'!$A$6:$C$20,2,FALSE),"") | C12: =IFERROR(VLOOKUP(A12,'F01 - _Données Employés'!$A$6:$C$20,3,FALSE),"") | D12: =IFERROR(VLOOKUP(D12,'F04 - 2-Référentiel Avant.'!$A$6:$C$20,3,FALSE),"") | E12: 25000 | F12: Juillet | G12: Non | I12: Virement | J12: REF-2024-0007 | K12: =IF(AND(G12="Non",TODAY()>DATE(2025,8,15)),"EN RETARD","") | L12: =IF(K12="EN RETARD",E12*0.05,0) | M12: =E12+L12 | N12: 45501
A13: EMP-003 | B13: =IFERROR(VLOOKUP(A13,'F01 - _Données Employés'!$A$6:$C$20,2,FALSE),"") | C13: =IFERROR(VLOOKUP(A13,'F01 - _Données Employés'!$A$6:$C$20,3,FALSE),"") | D13: =IFERROR(VLOOKUP(D13,'F04 - 2-Référentiel Avant.'!$A$6:$C$20,3,FALSE),"") | E13: 19200 | F13: Août | G13: Oui | H13: 45519 | I13: Chèque | J13: REF-2024-0008 | K13: =IF(AND(G13="Non",TODAY()>DATE(2025,9,15)),"EN RETARD","") | L13: =IF(K13="EN RETARD",E13*0.05,0) | M13: =E13+L13 | N13: 45532
A14: EMP-001 | B14: =IFERROR(VLOOKUP(A14,'F01 - _Données Employés'!$A$6:$C$20,2,FALSE),"") | C14: =IFERROR(VLOOKUP(A14,'F01 - _Données Employés'!$A$6:$C$20,3,FALSE),"") | D14: =IFERROR(VLOOKUP(D14,'F04 - 2-Référentiel Avant.'!$A$6:$C$20,3,FALSE),"") | E14: 17600 | F14: Septembre | G14: Oui | H14: 45550 | I14: Virement | J14: REF-2024-0009 | K14: =IF(AND(G14="Non",TODAY()>DATE(2025,10,15)),"EN RETARD","") | L14: =IF(K14="EN RETARD",E14*0.05,0) | M14: =E14+L14 | N14: 45563
A15: EMP-004 | B15: =IFERROR(VLOOKUP(A15,'F01 - _Données Employés'!$A$6:$C$20,2,FALSE),"") | C15: =IFERROR(VLOOKUP(A15,'F01 - _Données Employés'!$A$6:$C$20,3,FALSE),"") | D15: =IFERROR(VLOOKUP(D15,'F04 - 2-Référentiel Avant.'!$A$6:$C$20,3,FALSE),"") | E15: 22000 | F15: Octobre | G15: Oui | H15: 45580 | I15: Prélèvement automatique | J15: REF-2024-0010 | K15: =IF(AND(G15="Non",TODAY()>DATE(2025,11,15)),"EN RETARD","") | L15: =IF(K15="EN RETARD",E15*0.05,0) | M15: =E15+L15 | N15: 45593
A16: EMP-003 | B16: =IFERROR(VLOOKUP(A16,'F01 - _Données Employés'!$A$6:$C$20,2,FALSE),"") | C16: =IFERROR(VLOOKUP(A16,'F01 - _Données Employés'!$A$6:$C$20,3,FALSE),"") | D16: =IFERROR(VLOOKUP(D16,'F04 - 2-Référentiel Avant.'!$A$6:$C$20,3,FALSE),"") | E16: 25000 | F16: Novembre | G16: Non | I16: Virement | J16: REF-2024-0011 | K16: =IF(AND(G16="Non",TODAY()>DATE(2025,12,15)),"EN RETARD","") | L16: =IF(K16="EN RETARD",E16*0.05,0) | M16: =E16+L16 | N16: 45624
A17: EMP-006 | B17: =IFERROR(VLOOKUP(A17,'F01 - _Données Employés'!$A$6:$C$20,2,FALSE),"") | C17: =IFERROR(VLOOKUP(A17,'F01 - _Données Employés'!$A$6:$C$20,3,FALSE),"") | D17: =IFERROR(VLOOKUP(D17,'F04 - 2-Référentiel Avant.'!$A$6:$C$20,3,FALSE),"") | E17: 19520 | F17: Décembre | G17: Oui | H17: 45641 | I17: Chèque | J17: REF-2024-0012 | K17: =IF(AND(G17="Non",TODAY()>DATE(2026,1,15)),"EN RETARD","") | L17: =IF(K17="EN RETARD",E17*0.05,0) | M17: =E17+L17 | N17: 45654
A18: EMP-008 | B18: =IFERROR(VLOOKUP(A18,'F01 - _Données Employés'!$A$6:$C$20,2,FALSE),"") | C18: =IFERROR(VLOOKUP(A18,'F01 - _Données Employés'!$A$6:$C$20,3,FALSE),"") | D18: =IFERROR(VLOOKUP(D18,'F04 - 2-Référentiel Avant.'!$A$6:$C$20,3,FALSE),"") | E18: 15000 | F18: Janvier | G18: Oui | H18: 45306 | I18: Virement | J18: REF-2024-0013 | K18: =IF(AND(G18="Non",TODAY()>DATE(2025,2,15)),"EN RETARD","") | L18: =IF(K18="EN RETARD",E18*0.05,0) | M18: =E18+L18 | N18: 45319
A19: EMP-001 | B19: =IFERROR(VLOOKUP(A19,'F01 - _Données Employés'!$A$6:$C$20,2,FALSE),"") | C19: =IFERROR(VLOOKUP(A19,'F01 - _Données Employés'!$A$6:$C$20,3,FALSE),"") | D19: =IFERROR(VLOOKUP(D19,'F04 - 2-Référentiel Avant.'!$A$6:$C$20,3,FALSE),"") | E19: 22800 | F19: Février | G19: Oui | H19: 45337 | I19: Prélèvement automatique | J19: REF-2024-0014 | K19: =IF(AND(G19="Non",TODAY()>DATE(2025,3,15)),"EN RETARD","") | L19: =IF(K19="EN RETARD",E19*0.05,0) | M19: =E19+L19 | N19: 45350
A20: EMP-004 | B20: =IFERROR(VLOOKUP(A20,'F01 - _Données Employés'!$A$6:$C$20,2,FALSE),"") | C20: =IFERROR(VLOOKUP(A20,'F01 - _Données Employés'!$A$6:$C$20,3,FALSE),"") | D20: =IFERROR(VLOOKUP(D20,'F04 - 2-Référentiel Avant.'!$A$6:$C$20,3,FALSE),"") | E20: 13200 | F20: Mars | G20: Non | I20: Virement | J20: REF-2024-0015 | K20: =IF(AND(G20="Non",TODAY()>DATE(2025,4,15)),"EN RETARD","") | L20: =IF(K20="EN RETARD",E20*0.05,0) | M20: =E20+L20 | N20: 45379

Sheet F07 - 5-Gest. Fournisseurs
A2: GESTION DES FOURNISSEURS D'AVANTAGES SOCIAUX
A3: TABLEAU DYNAMIQUE — Saisissez dans la zone prévue ci-dessous
A5: Code fournisseur | B5: Nom | C5: Catégorie avantages | D5: Contact | E5: Téléphone | F5: Email | G5: Contrat actif | H5: Date début contrat | I5: Date fin contrat | J5: Nb bénéficiaires | K5: Coût mensuel total (FCFA) | L5: Qualité service (1-5) | M5: Statut | N5: Date MAJ
A6: FOU-001 | B6: CNPS | C6: Santé, Retraite, Prévoyance | D6: M. Koné Ibrahim | E6: +225 20 30 40 50 | F6: contact@cnps.ci | G6: Oui | H6: 44927 | I6: 46022 | J6: =COUNTIF('F04 - 2-Référentiel Avant.'!G6:G20,"*"&B6&"*") | K6: =SUMIF('F06 - 4-Suivi Cotisations'!E6:E115,">"&0) | L6: 4 | M6: Actif | N6: 45444
A7: FOU-002 | B7: AXA Assurance | C7: Prévoyance | D7: Mme Touré Awa | E7: +225 27 20 30 40 | F7: awa.toure@axa.ci | G7: Oui | H7: 44927 | I7: 45838 | J7: =COUNTIF('F04 - 2-Référentiel Avant.'!G6:G20,"*"&B7&"*") | K7: =SUMIF('F06 - 4-Suivi Cotisations'!E6:E115,">"&0) | L7: 4 | M7: Actif | N7: 45444
A8: FOU-003 | B8: NSIA Vie | C8: Logement | D8: M. Bamba Moussa | E8: +225 27 21 22 23 | F8: m.bamba@nsia.ci | G8: Oui | H8: 45292 | I8: 46022 | J8: =COUNTIF('F04 - 2-Référentiel Avant.'!G6:G20,"*"&B8&"*") | K8: =SUMIF('F06 - 4-Suivi Cotisations'!E6:E115,">"&0) | L8: 4 | M8: Actif | N8: 45444
A9: FOU-004 | B9: Allianz | C9: Retraite | D9: Mme Diabaté Mariam | E9: +225 27 30 31 32 | F9: m.diabate@allianz.ci | G9: Oui | H9: 45078 | I9: 45808 | J9: =COUNTIF('F04 - 2-Référentiel Avant.'!G6:G20,"*"&B9&"*") | K9: =SUMIF('F06 - 4-Suivi Cotisations'!E6:E115,">"&0) | L9: 4 | M9: Actif | N9: 45444
A10: FOU-005 | B10: Mutuelle Hôteliers CI | C10: Santé | D10: M. Aka Georges | E10: +225 27 40 41 42 | F10: g.aka@mutuelle-hotel.ci | G10: Oui | H10: 44562 | I10: 46022 | J10: =COUNTIF('F04 - 2-Référentiel Avant.'!G6:G20,"*"&B10&"*") | K10: =SUMIF('F06 - 4-Suivi Cotisations'!E6:E115,">"&0) | L10: 4 | M10: Actif | N10: 45444

Sheet F08 - 6-Prévoyance Santé
A2: PRÉVOYANCE SANTÉ — Détail couverture et cotisations
A3: TABLEAU DYNAMIQUE — Saisissez dans la zone prévue ci-dessous
A5: Matricule | B5: Nom (VLOOKUP) | C5: Prénom (VLOOKUP) | D5: Niveau couverture | E5: Couverture conjoint | F5: Couverture enfants | G5: Nb enfants à charge | H5: Cotisation mensuelle (FCFA) | I5: Remboursements mensuels (FCFA) | J5: Solde disponible (FCFA) | K5: Plafond annuel (FCFA) | L5: Utilisation (%) | N5: Date MAJ
A6: EMP-001 | B6: =IFERROR(VLOOKUP(A6,'F01 - _Données Employés'!$A$6:$C$20,2,FALSE),"") | C6: =IFERROR(VLOOKUP(A6,'F01 - _Données Employés'!$A$6:$C$20,3,FALSE),"") | D6: Premium | E6: Oui | F6: Oui | G6: 3 | H6: =IF(D6="Basique",10000,IF(D6="Standard",18500,28000))+IF(E6="Oui",8000,0)+F6*3000 | I6: 15000 | J6: =I6*12-H6*12 | K6: =IF(D6="Basique",200000,IF(D6="Standard",500000,1000000)) | L6: =IF(K6=0,0,(H6*12)/K6) | N6: 45444
A7: EMP-002 | B7: =IFERROR(VLOOKUP(A7,'F01 - _Données Employés'!$A$6:$C$20,2,FALSE),"") | C7: =IFERROR(VLOOKUP(A7,'F01 - _Données Employés'!$A$6:$C$20,3,FALSE),"") | D7: Standard | E7: Oui | F7: Oui | G7: 2 | H7: =IF(D7="Basique",10000,IF(D7="Standard",18500,28000))+IF(E7="Oui",8000,0)+F7*3000 | I7: 25000 | J7: =I7*12-H7*12 | K7: =IF(D7="Basique",200000,IF(D7="Standard",500000,1000000)) | L7: =IF(K7=0,0,(H7*12)/K7) | N7: 45444
A8: EMP-003 | B8: =IFERROR(VLOOKUP(A8,'F01 - _Données Employés'!$A$6:$C$20,2,FALSE),"") | C8: =IFERROR(VLOOKUP(A8,'F01 - _Données Employés'!$A$6:$C$20,3,FALSE),"") | D8: Standard | E8: Non | F8: Oui | G8: 1 | H8: =IF(D8="Basique",10000,IF(D8="Standard",18500,28000))+IF(E8="Oui",8000,0)+F8*3000 | I8: 8000 | J8: =I8*12-H8*12 | K8: =IF(D8="Basique",200000,IF(D8="Standard",500000,1000000)) | L8: =IF(K8=0,0,(H8*12)/K8) | N8: 45444
A9: EMP-005 | B9: =IFERROR(VLOOKUP(A9,'F01 - _Données Employés'!$A$6:$C$20,2,FALSE),"") | C9: =IFERROR(VLOOKUP(A9,'F01 - _Données Employés'!$A$6:$C$20,3,FALSE),"") | D9: Premium | E9: Oui | F9: Non | G9: 0 | H9: =IF(D9="Basique",10000,IF(D9="Standard",18500,28000))+IF(E9="Oui",8000,0)+F9*3000 | I9: 12000 | J9: =I9*12-H9*12 | K9: =IF(D9="Basique",200000,IF(D9="Standard",500000,1000000)) | L9: =IF(K9=0,0,(H9*12)/K9) | N9: 45444
A10: EMP-006 | B10: =IFERROR(VLOOKUP(A10,'F01 - _Données Employés'!$A$6:$C$20,2,FALSE),"") | C10: =IFERROR(VLOOKUP(A10,'F01 - _Données Employés'!$A$6:$C$20,3,FALSE),"") | D10: Standard | E10: Non | F10: Oui | G10: 2 | H10: =IF(D10="Basique",10000,IF(D10="Standard",18500,28000))+IF(E10="Oui",8000,0)+F10*3000 | I10: 5000 | J10: =I10*12-H10*12 | K10: =IF(D10="Basique",200000,IF(D10="Standard",500000,1000000)) | L10: =IF(K10=0,0,(H10*12)/K10) | N10: 45444
A11: EMP-008 | B11: =IFERROR(VLOOKUP(A11,'F01 - _Données Employés'!$A$6:$C$20,2,FALSE),"") | C11: =IFERROR(VLOOKUP(A11,'F01 - _Données Employés'!$A$6:$C$20,3,FALSE),"") | D11: Premium | E11: Oui | F11: Oui | G11: 2 | H11: =IF(D11="Basique",10000,IF(D11="Standard",18500,28000))+IF(E11="Oui",8000,0)+F11*3000 | I11: 20000 | J11: =I11*12-H11*12 | K11: =IF(D11="Basique",200000,IF(D11="Standard",500000,1000000)) | L11: =IF(K11=0,0,(H11*12)/K11) | N11: 45444
A12: EMP-010 | B12: =IFERROR(VLOOKUP(A12,'F01 - _Données Employés'!$A$6:$C$20,2,FALSE),"") | C12: =IFERROR(VLOOKUP(A12,'F01 - _Données Employés'!$A$6:$C$20,3,FALSE),"") | D12: Basique | E12: Non | F12: Non | G12: 0 | H12: =IF(D12="Basique",10000,IF(D12="Standard",18500,28000))+IF(E12="Oui",8000,0)+F12*3000 | I12: 3000 | J12: =I12*12-H12*12 | K12: =IF(D12="Basique",200000,IF(D12="Standard",500000,1000000)) | L12: =IF(K12=0,0,(H12*12)/K12) | N12: 45444
A13: EMP-011 | B13: =IFERROR(VLOOKUP(A13,'F01 - _Données Employés'!$A$6:$C$20,2,FALSE),"") | C13: =IFERROR(VLOOKUP(A13,'F01 - _Données Employés'!$A$6:$C$20,3,FALSE),"") | D13: Standard | E13: Non | F13: Oui | G13: 1 | H13: =IF(D13="Basique",10000,IF(D13="Standard",18500,28000))+IF(E13="Oui",8000,0)+F13*3000 | I13: 6000 | J13: =I13*12-H13*12 | K13: =IF(D13="Basique",200000,IF(D13="Standard",500000,1000000)) | L13: =IF(K13=0,0,(H13*12)/K13) | N13: 45444
A14: EMP-012 | B14: =IFERROR(VLOOKUP(A14,'F01 - _Données Employés'!$A$6:$C$20,2,FALSE),"") | C14: =IFERROR(VLOOKUP(A14,'F01 - _Données Employés'!$A$6:$C$20,3,FALSE),"") | D14: Premium | E14: Oui | F14: Oui | G14: 3 | H14: =IF(D14="Basique",10000,IF(D14="Standard",18500,28000))+IF(E14="Oui",8000,0)+F14*3000 | I14: 18000 | J14: =I14*12-H14*12 | K14: =IF(D14="Basique",200000,IF(D14="Standard",500000,1000000)) | L14: =IF(K14=0,0,(H14*12)/K14) | N14: 45444

Sheet F09 - 7-Retraite Complém.
A2: RETRAITE COMPLÉMENTAIRE — Plans et projections
A3: TABLEAU DYNAMIQUE — Saisissez dans la zone prévue ci-dessous
A5: Matricule | B5: Nom (VLOOKUP) | C5: Plan retraite | D5: Points acquis | E5: Valeur point (FCFA) | F5: Montant épargné (FCFA) | G5: Cotisation mensuelle (FCFA) | H5: Taux employeur (%) | I5: Taux employé (%) | J5: Projection retraite (FCFA) | N5: Date MAJ
A6: EMP-001 | B6: =IFERROR(VLOOKUP(A6,'F01 - _Données Employés'!$A$6:$C$20,2,FALSE),"") | C6: PER | D6: 150 | E6: 450 | F6: =D6*E6 | G6: 15000 | H6: 0.6 | I6: 0.4 | J6: =F6+G6*(DATEDIF(IFERROR(VLOOKUP(A6,'F01 - _Données Employés'!$A$6:$F$20,6,FALSE),TODAY()),TODAY(),"Y")*12) | N6: 45444
A7: EMP-002 | B7: =IFERROR(VLOOKUP(A7,'F01 - _Données Employés'!$A$6:$C$20,2,FALSE),"") | C7: REER | D7: 220 | E7: 520 | F7: =D7*E7 | G7: 20000 | H7: 0.5 | I7: 0.5 | J7: =F7+G7*(DATEDIF(IFERROR(VLOOKUP(A7,'F01 - _Données Employés'!$A$6:$F$20,6,FALSE),TODAY()),TODAY(),"Y")*12) | N7: 45444
A8: EMP-005 | B8: =IFERROR(VLOOKUP(A8,'F01 - _Données Employés'!$A$6:$C$20,2,FALSE),"") | C8: CNPS complémentaire | D8: 80 | E8: 380 | F8: =D8*E8 | G8: 10000 | H8: 0.4 | I8: 0.6 | J8: =F8+G8*(DATEDIF(IFERROR(VLOOKUP(A8,'F01 - _Données Employés'!$A$6:$F$20,6,FALSE),TODAY()),TODAY(),"Y")*12) | N8: 45444
A9: EMP-006 | B9: =IFERROR(VLOOKUP(A9,'F01 - _Données Employés'!$A$6:$C$20,2,FALSE),"") | C9: PER | D9: 130 | E9: 450 | F9: =D9*E9 | G9: 15000 | H9: 0.6 | I9: 0.4 | J9: =F9+G9*(DATEDIF(IFERROR(VLOOKUP(A9,'F01 - _Données Employés'!$A$6:$F$20,6,FALSE),TODAY()),TODAY(),"Y")*12) | N9: 45444
A10: EMP-008 | B10: =IFERROR(VLOOKUP(A10,'F01 - _Données Employés'!$A$6:$C$20,2,FALSE),"") | C10: CARPA | D10: 190 | E10: 500 | F10: =D10*E10 | G10: 18000 | H10: 0.55 | I10: 0.45 | J10: =F10+G10*(DATEDIF(IFERROR(VLOOKUP(A10,'F01 - _Données Employés'!$A$6:$F$20,6,FALSE),TODAY()),TODAY(),"Y")*12) | N10: 45444

Sheet F10 - 8-Avant. Alimentation
A2: AVANTAGES ALIMENTATION — Tickets, paniers et primes
A3: TABLEAU DYNAMIQUE — Saisissez dans la zone prévue ci-dessous
A5: Matricule | B5: Nom (VLOOKUP) | C5: Type avantage | D5: Nb jours ouvrés/mois | E5: Valeur unitaire (FCFA) | F5: Montant mensuel (FCFA) | G5: Participation employeur (%) | H5: Part employé (FCFA) | I5: Plafond exonération (FCFA) | J5: Exonéré | N5: Date MAJ
A6: EMP-001 | B6: =IFERROR(VLOOKUP(A6,'F01 - _Données Employés'!$A$6:$C$20,2,FALSE),"") | C6: Tickets restaurant | D6: 22 | E6: 1000 | F6: =D6*E6 | G6: 0.6 | H6: =F6*(1-G6) | I6: 50000 | J6: =IF(F6<=I6,"Oui","Non") | N6: 45444
A7: EMP-002 | B7: =IFERROR(VLOOKUP(A7,'F01 - _Données Employés'!$A$6:$C$20,2,FALSE),"") | C7: Tickets restaurant | D7: 22 | E7: 1000 | F7: =D7*E7 | G7: 0.6 | H7: =F7*(1-G7) | I7: 50000 | J7: =IF(F7<=I7,"Oui","Non") | N7: 45444
A8: EMP-003 | B8: =IFERROR(VLOOKUP(A8,'F01 - _Données Employés'!$A$6:$C$20,2,FALSE),"") | C8: Panier repas | D8: 22 | E8: 800 | F8: =D8*E8 | G8: 0.5 | H8: =F8*(1-G8) | I8: 50000 | J8: =IF(F8<=I8,"Oui","Non") | N8: 45444
A9: EMP-004 | B9: =IFERROR(VLOOKUP(A9,'F01 - _Données Employés'!$A$6:$C$20,2,FALSE),"") | C9: Tickets restaurant | D9: 22 | E9: 1000 | F9: =D9*E9 | G9: 0.6 | H9: =F9*(1-G9) | I9: 50000 | J9: =IF(F9<=I9,"Oui","Non") | N9: 45444
A10: EMP-005 | B10: =IFERROR(VLOOKUP(A10,'F01 - _Données Employés'!$A$6:$C$20,2,FALSE),"") | C10: Prime alimentaire | D10: 22 | E10: 15000 | F10: =D10*E10 | G10: 1 | H10: =F10*(1-G10) | I10: 50000 | J10: =IF(F10<=I10,"Oui","Non") | N10: 45444
A11: EMP-006 | B11: =IFERROR(VLOOKUP(A11,'F01 - _Données Employés'!$A$6:$C$20,2,FALSE),"") | C11: Tickets restaurant | D11: 22 | E11: 1000 | F11: =D11*E11 | G11: 0.6 | H11: =F11*(1-G11) | I11: 50000 | J11: =IF(F11<=I11,"Oui","Non") | N11: 45444
A12: EMP-008 | B12: =IFERROR(VLOOKUP(A12,'F01 - _Données Employés'!$A$6:$C$20,2,FALSE),"") | C12: Tickets restaurant | D12: 22 | E12: 1000 | F12: =D12*E12 | G12: 0.6 | H12: =F12*(1-G12) | I12: 50000 | J12: =IF(F12<=I12,"Oui","Non") | N12: 45444
A13: EMP-009 | B13: =IFERROR(VLOOKUP(A13,'F01 - _Données Employés'!$A$6:$C$20,2,FALSE),"") | C13: Panier repas | D13: 22 | E13: 800 | F13: =D13*E13 | G13: 0.5 | H13: =F13*(1-G13) | I13: 50000 | J13: =IF(F13<=I13,"Oui","Non") | N13: 45444
A14: EMP-010 | B14: =IFERROR(VLOOKUP(A14,'F01 - _Données Employés'!$A$6:$C$20,2,FALSE),"") | C14: Prime alimentaire | D14: 22 | E14: 15000 | F14: =D14*E14 | G14: 1 | H14: =F14*(1-G14) | I14: 50000 | J14: =IF(F14<=I14,"Oui","Non") | N14: 45444

Sheet F11 - 9-Avantages Transport
A2: AVANTAGES TRANSPORT — Indemnités et véhicules
A3: TABLEAU DYNAMIQUE — Saisissez dans la zone prévue ci-dessous
A5: Matricule | B5: Nom (VLOOKUP) | C5: Type transport | D5: Distance trajet (km) | E5: Tarif/km (FCFA) | F5: Montant mensuel (FCFA) | G5: Plafond légal (FCFA) | H5: Dépassement | I5: Prise en charge employeur (%) | J5: Part employé (FCFA) | N5: Date MAJ
A6: EMP-001 | B6: =IFERROR(VLOOKUP(A6,'F01 - _Données Employés'!$A$6:$C$20,2,FALSE),"") | C6: Indemnité km | D6: 15 | E6: 150 | F6: =IF(C6="Véhicule fonction",50000,IF(C6="Abonnement transport",25000,D6*E6*22)) | G6: 30000 | H6: =IF(F6>G6,"DÉPASSÉ","") | I6: 0.8 | J6: =F6*(1-I6) | N6: 45444
A7: EMP-002 | B7: =IFERROR(VLOOKUP(A7,'F01 - _Données Employés'!$A$6:$C$20,2,FALSE),"") | C7: Indemnité km | D7: 22 | E7: 150 | F7: =IF(C7="Véhicule fonction",50000,IF(C7="Abonnement transport",25000,D7*E7*22)) | G7: 30000 | H7: =IF(F7>G7,"DÉPASSÉ","") | I7: 0.8 | J7: =F7*(1-I7) | N7: 45444
A8: EMP-003 | B8: =IFERROR(VLOOKUP(A8,'F01 - _Données Employés'!$A$6:$C$20,2,FALSE),"") | C8: Abonnement transport | D8: 10 | E8: 0 | F8: =IF(C8="Véhicule fonction",50000,IF(C8="Abonnement transport",25000,D8*E8*22)) | G8: 25000 | H8: =IF(F8>G8,"DÉPASSÉ","") | I8: 1 | J8: =F8*(1-I8) | N8: 45444
A9: EMP-004 | B9: =IFERROR(VLOOKUP(A9,'F01 - _Données Employés'!$A$6:$C$20,2,FALSE),"") | C9: Indemnité km | D9: 18 | E9: 150 | F9: =IF(C9="Véhicule fonction",50000,IF(C9="Abonnement transport",25000,D9*E9*22)) | G9: 30000 | H9: =IF(F9>G9,"DÉPASSÉ","") | I9: 0.8 | J9: =F9*(1-I9) | N9: 45444
A10: EMP-005 | B10: =IFERROR(VLOOKUP(A10,'F01 - _Données Employés'!$A$6:$C$20,2,FALSE),"") | C10: Véhicule fonction | D10: 25 | E10: 0 | F10: =IF(C10="Véhicule fonction",50000,IF(C10="Abonnement transport",25000,D10*E10*22)) | G10: 50000 | H10: =IF(F10>G10,"DÉPASSÉ","") | I10: 1 | J10: =F10*(1-I10) | N10: 45444
A11: EMP-006 | B11: =IFERROR(VLOOKUP(A11,'F01 - _Données Employés'!$A$6:$C$20,2,FALSE),"") | C11: Indemnité km | D11: 12 | E11: 150 | F11: =IF(C11="Véhicule fonction",50000,IF(C11="Abonnement transport",25000,D11*E11*22)) | G11: 30000 | H11: =IF(F11>G11,"DÉPASSÉ","") | I11: 0.8 | J11: =F11*(1-I11) | N11: 45444
A12: EMP-008 | B12: =IFERROR(VLOOKUP(A12,'F01 - _Données Employés'!$A$6:$C$20,2,FALSE),"") | C12: Indemnité km | D12: 20 | E12: 150 | F12: =IF(C12="Véhicule fonction",50000,IF(C12="Abonnement transport",25000,D12*E12*22)) | G12: 30000 | H12: =IF(F12>G12,"DÉPASSÉ","") | I12: 0.8 | J12: =F12*(1-I12) | N12: 45444
A13: EMP-010 | B13: =IFERROR(VLOOKUP(A13,'F01 - _Données Employés'!$A$6:$C$20,2,FALSE),"") | C13: Abonnement transport | D13: 8 | E13: 0 | F13: =IF(C13="Véhicule fonction",50000,IF(C13="Abonnement transport",25000,D13*E13*22)) | G13: 25000 | H13: =IF(F13>G13,"DÉPASSÉ","") | I13: 1 | J13: =F13*(1-I13) | N13: 45444

Sheet F12 - 10-Prêts et Avances
A2: PRÊTS ET AVANCES SOCIALES
A3: TABLEAU DYNAMIQUE — Saisissez dans la zone prévue ci-dessous
A5: Matricule | B5: Nom (VLOOKUP) | C5: Type prêt | D5: Montant demandé (FCFA) | E5: Montant accordé (FCFA) | F5: Taux intérêt (%) | G5: Durée (mois) | H5: Mensualité (FCFA) | I5: Montant restant dû (FCFA) | J5: Prochaine échéance | K5: Statut | N5: Date MAJ
A6: EMP-005 | B6: =IFERROR(VLOOKUP(A6,'F01 - _Données Employés'!$A$6:$C$20,2,FALSE),"") | C6: Prêt social | D6: 3000000 | E6: 2500000 | F6: 0.035 | G6: 48 | H6: =E6*(1+F6*G6/12)/G6 | I6: =E6*(1+F6*G6/12)-H6*G6 | J6: 45474 | K6: En cours | N6: 45444
A7: EMP-001 | B7: =IFERROR(VLOOKUP(A7,'F01 - _Données Employés'!$A$6:$C$20,2,FALSE),"") | C7: Prêt social | D7: 5000000 | E7: 4000000 | F7: 0.03 | G7: 60 | H7: =E7*(1+F7*G7/12)/G7 | I7: =E7*(1+F7*G7/12)-H7*G7 | J7: 45505 | K7: En cours | N7: 45444
A8: EMP-008 | B8: =IFERROR(VLOOKUP(A8,'F01 - _Données Employés'!$A$6:$C$20,2,FALSE),"") | C8: Avance sur salaire | D8: 200000 | E8: 200000 | F8: 0 | G8: 3 | H8: =E8*(1+F8*G8/12)/G8 | I8: =E8*(1+F8*G8/12)-H8*G8 | J8: 45536 | K8: En cours | N8: 45444
A9: EMP-003 | B9: =IFERROR(VLOOKUP(A9,'F01 - _Données Employés'!$A$6:$C$20,2,FALSE),"") | C9: Aide financière | D9: 150000 | E9: 150000 | F9: 0 | G9: 6 | H9: =E9*(1+F9*G9/12)/G9 | I9: =E9*(1+F9*G9/12)-H9*G9 | J9: 45566 | K9: En cours | N9: 45444
A10: EMP-012 | B10: =IFERROR(VLOOKUP(A10,'F01 - _Données Employés'!$A$6:$C$20,2,FALSE),"") | C10: Prêt social | D10: 4000000 | E10: 3500000 | F10: 0.035 | G10: 48 | H10: =E10*(1+F10*G10/12)/G10 | I10: =E10*(1+F10*G10/12)-H10*G10 | J10: 45597 | K10: En cours | N10: 45444

Sheet F13 - 11-Gestion Logement
A2: GESTION LOGEMENT — Fonctionnel, indemnités et aides
A3: TABLEAU DYNAMIQUE — Saisissez dans la zone prévue ci-dessous
A5: Matricule | B5: Nom (VLOOKUP) | C5: Type logement | D5: Nombre pièces | E5: Loyer mensuel (FCFA) | F5: Prise en charge (%) | G5: Part employé (FCFA) | H5: État logement | I5: Date état des lieux | J5: Statut | N5: Date MAJ
A6: EMP-005 | B6: =IFERROR(VLOOKUP(A6,'F01 - _Données Employés'!$A$6:$C$20,2,FALSE),"") | C6: Logement fonctionnel | D6: 3 | E6: 0 | F6: 1 | G6: =E6*(1-F6) | H6: Bon | I6: 45306 | J6: Actif | N6: 45444
A7: EMP-001 | B7: =IFERROR(VLOOKUP(A7,'F01 - _Données Employés'!$A$6:$C$20,2,FALSE),"") | C7: Indemnité logement | D7: 2 | E7: 80000 | F7: 0.5 | G7: =E7*(1-F7) | I7: 45306 | J7: Actif | N7: 45444
A8: EMP-008 | B8: =IFERROR(VLOOKUP(A8,'F01 - _Données Employés'!$A$6:$C$20,2,FALSE),"") | C8: Indemnité logement | D8: 2 | E8: 75000 | F8: 0.4 | G8: =E8*(1-F8) | I8: 45306 | J8: Actif | N8: 45444
A9: EMP-002 | B9: =IFERROR(VLOOKUP(A9,'F01 - _Données Employés'!$A$6:$C$20,2,FALSE),"") | C9: Aide au logement | D9: 3 | E9: 120000 | F9: 0.3 | G9: =E9*(1-F9) | I9: 45306 | J9: Actif | N9: 45444

Sheet F14 - 12-Analyse Coûts Av.
A2: ANALYSE DES COÛTS DES AVANTAGES SOCIAUX
A3: TABLEAU DYNAMIQUE — Saisissez dans la zone prévue ci-dessous
A5: Catégorie avantage | B5: Coût total annuel (FCFA) | C5: Coût moyen/bénéf. (FCFA) | D5: % budget RH | E5: Variation vs année préc. | F5: Tendance | G5: Budget prévu (FCFA) | H5: Écart (FCFA) | I5: Commentaire | N5: Date MAJ
A6: Santé | B6: =SUMIF('F04 - 2-Référentiel Avant.'!B6:B20,A6,'F05 - 3-Inscription Avant.'!H6:H115)*12 | C6: =IF(B6=0,0,B6/MAX(COUNTIF('F05 - 3-Inscription Avant.'!F6:F115,'F04 - 2-Référentiel Avant.'!A6:A20),1)) | D6: =IF(SUM(B6:B14)=0,0,B6/SUM(B6:B14)) | E6: +5% | F6: =IF(ISNUMBER(SEARCH("+",E6)),"↗ Hausse",IF(ISNUMBER(SEARCH("-",E6)),"↘ Baisse","→ Stable")) | G6: 4800000 | H6: =G6-B6 | N6: 45444
A7: Retraite | B7: =SUMIF('F04 - 2-Référentiel Avant.'!B6:B20,A7,'F05 - 3-Inscription Avant.'!H6:H115)*12 | C7: =IF(B7=0,0,B7/MAX(COUNTIF('F05 - 3-Inscription Avant.'!F6:F115,'F04 - 2-Référentiel Avant.'!A6:A20),1)) | D7: =IF(SUM(B6:B14)=0,0,B7/SUM(B6:B14)) | E7: +8% | F7: =IF(ISNUMBER(SEARCH("+",E7)),"↗ Hausse",IF(ISNUMBER(SEARCH("-",E7)),"↘ Baisse","→ Stable")) | G7: 2400000 | H7: =G7-B7 | N7: 45444
A8: Prévoyance | B8: =SUMIF('F04 - 2-Référentiel Avant.'!B6:B20,A8,'F05 - 3-Inscription Avant.'!H6:H115)*12 | C8: =IF(B8=0,0,B8/MAX(COUNTIF('F05 - 3-Inscription Avant.'!F6:F115,'F04 - 2-Référentiel Avant.'!A6:A20),1)) | D8: =IF(SUM(B6:B14)=0,0,B8/SUM(B6:B14)) | E8: -2% | F8: =IF(ISNUMBER(SEARCH("+",E8)),"↗ Hausse",IF(ISNUMBER(SEARCH("-",E8)),"↘ Baisse","→ Stable")) | G8: 3600000 | H8: =G8-B8 | N8: 45444
A9: Alimentation | B9: =SUMIF('F04 - 2-Référentiel Avant.'!B6:B20,A9,'F05 - 3-Inscription Avant.'!H6:H115)*12 | C9: =IF(B9=0,0,B9/MAX(COUNTIF('F05 - 3-Inscription Avant.'!F6:F115,'F04 - 2-Référentiel Avant.'!A6:A20),1)) | D9: =IF(SUM(B6:B14)=0,0,B9/SUM(B6:B14)) | E9: +3% | F9: =IF(ISNUMBER(SEARCH("+",E9)),"↗ Hausse",IF(ISNUMBER(SEARCH("-",E9)),"↘ Baisse","→ Stable")) | G9: 4200000 | H9: =G9-B9 | N9: 45444
A10: Transport | B10: =SUMIF('F04 - 2-Référentiel Avant.'!B6:B20,A10,'F05 - 3-Inscription Avant.'!H6:H115)*12 | C10: =IF(B10=0,0,B10/MAX(COUNTIF('F05 - 3-Inscription Avant.'!F6:F115,'F04 - 2-Référentiel Avant.'!A6:A20),1)) | D10: =IF(SUM(B6:B14)=0,0,B10/SUM(B6:B14)) | E10: +1% | F10: =IF(ISNUMBER(SEARCH("+",E10)),"↗ Hausse",IF(ISNUMBER(SEARCH("-",E10)),"↘ Baisse","→ Stable")) | G10: 3000000 | H10: =G10-B10 | N10: 45444
A11: Logement | B11: =SUMIF('F04 - 2-Référentiel Avant.'!B6:B20,A11,'F05 - 3-Inscription Avant.'!H6:H115)*12 | C11: =IF(B11=0,0,B11/MAX(COUNTIF('F05 - 3-Inscription Avant.'!F6:F115,'F04 - 2-Référentiel Avant.'!A6:A20),1)) | D11: =IF(SUM(B6:B14)=0,0,B11/SUM(B6:B14)) | E11: +10% | F11: =IF(ISNUMBER(SEARCH("+",E11)),"↗ Hausse",IF(ISNUMBER(SEARCH("-",E11)),"↘ Baisse","→ Stable")) | G11: 1800000 | H11: =G11-B11 | N11: 45444
A12: Formation | B12: =SUMIF('F04 - 2-Référentiel Avant.'!B6:B20,A12,'F05 - 3-Inscription Avant.'!H6:H115)*12 | C12: =IF(B12=0,0,B12/MAX(COUNTIF('F05 - 3-Inscription Avant.'!F6:F115,'F04 - 2-Référentiel Avant.'!A6:A20),1)) | D12: =IF(SUM(B6:B14)=0,0,B12/SUM(B6:B14)) | E12: -5% | F12: =IF(ISNUMBER(SEARCH("+",E12)),"↗ Hausse",IF(ISNUMBER(SEARCH("-",E12)),"↘ Baisse","→ Stable")) | G12: 960000 | H12: =G12-B12 | N12: 45444
A13: Loisirs | B13: =SUMIF('F04 - 2-Référentiel Avant.'!B6:B20,A13,'F05 - 3-Inscription Avant.'!H6:H115)*12 | C13: =IF(B13=0,0,B13/MAX(COUNTIF('F05 - 3-Inscription Avant.'!F6:F115,'F04 - 2-Référentiel Avant.'!A6:A20),1)) | D13: =IF(SUM(B6:B14)=0,0,B13/SUM(B6:B14)) | E13: 0% | F13: =IF(ISNUMBER(SEARCH("+",E13)),"↗ Hausse",IF(ISNUMBER(SEARCH("-",E13)),"↘ Baisse","→ Stable")) | G13: 300000 | H13: =G13-B13 | N13: 45444
A14: Autre | B14: =SUMIF('F04 - 2-Référentiel Avant.'!B6:B20,A14,'F05 - 3-Inscription Avant.'!H6:H115)*12 | C14: =IF(B14=0,0,B14/MAX(COUNTIF('F05 - 3-Inscription Avant.'!F6:F115,'F04 - 2-Référentiel Avant.'!A6:A20),1)) | D14: =IF(SUM(B6:B14)=0,0,B14/SUM(B6:B14)) | E14: +2% | F14: =IF(ISNUMBER(SEARCH("+",E14)),"↗ Hausse",IF(ISNUMBER(SEARCH("-",E14)),"↘ Baisse","→ Stable")) | G14: 600000 | H14: =G14-B14 | N14: 45444

Sheet F15 - 13-Plafonds Exonér.
A2: PLAFONDS LÉGAUX ET EXONÉRATIONS FISCALES
A3: TABLEAU DYNAMIQUE — Saisissez dans la zone prévue ci-dessous
A5: Code avantage | B5: Type avantage | C5: Plafond légal annuel (FCFA) | D5: Plafond utilisé (FCFA) | E5: Taux utilisation (%) | F5: Dépassement | G5: Montant exonéré (FCFA) | H5: Montant imposable (FCFA) | I5: Impact fiscal (FCFA) | J5: Recommandation | N5: Date MAJ
A6: AV-001 | B6: Santé | C6: 600000 | D6: =SUMIF('F05 - 3-Inscription Avant.'!F6:F115,A6,'F05 - 3-Inscription Avant.'!H6:H115)*12 | E6: =IF(C6=0,0,D6/C6) | F6: =IF(D6>C6,"DÉPASSÉ DE "&TEXT((D6-C6),"#,##0")&" FCFA","") | G6: =MIN(D6,C6) | H6: =MAX(D6-C6,0) | I6: =MAX(D6-C6,0)*0.25 | J6: =IF(E6>0.9,"Veiller au plafond","OK")
A7: AV-002 | B7: Santé | C7: 500000 | D7: =SUMIF('F05 - 3-Inscription Avant.'!F6:F115,A7,'F05 - 3-Inscription Avant.'!H6:H115)*12 | E7: =IF(C7=0,0,D7/C7) | F7: =IF(D7>C7,"DÉPASSÉ DE "&TEXT((D7-C7),"#,##0")&" FCFA","") | G7: =MIN(D7,C7) | H7: =MAX(D7-C7,0) | I7: =MAX(D7-C7,0)*0.25 | J7: =IF(E7>0.9,"Veiller au plafond","OK")
A8: AV-003 | B8: Prévoyance | C8: 10000000 | D8: =SUMIF('F05 - 3-Inscription Avant.'!F6:F115,A8,'F05 - 3-Inscription Avant.'!H6:H115)*12 | E8: =IF(C8=0,0,D8/C8) | F8: =IF(D8>C8,"DÉPASSÉ DE "&TEXT((D8-C8),"#,##0")&" FCFA","") | G8: =MIN(D8,C8) | H8: =MAX(D8-C8,0) | I8: =MAX(D8-C8,0)*0.25 | J8: =IF(E8>0.9,"Veiller au plafond","OK")
A9: AV-004 | B9: Alimentation | C9: 600000 | D9: =SUMIF('F05 - 3-Inscription Avant.'!F6:F115,A9,'F05 - 3-Inscription Avant.'!H6:H115)*12 | E9: =IF(C9=0,0,D9/C9) | F9: =IF(D9>C9,"DÉPASSÉ DE "&TEXT((D9-C9),"#,##0")&" FCFA","") | G9: =MIN(D9,C9) | H9: =MAX(D9-C9,0) | I9: =MAX(D9-C9,0)*0.25 | J9: =IF(E9>0.9,"Veiller au plafond","OK")
A10: AV-005 | B10: Transport | C10: 360000 | D10: =SUMIF('F05 - 3-Inscription Avant.'!F6:F115,A10,'F05 - 3-Inscription Avant.'!H6:H115)*12 | E10: =IF(C10=0,0,D10/C10) | F10: =IF(D10>C10,"DÉPASSÉ DE "&TEXT((D10-C10),"#,##0")&" FCFA","") | G10: =MIN(D10,C10) | H10: =MAX(D10-C10,0) | I10: =MAX(D10-C10,0)*0.25 | J10: =IF(E10>0.9,"Veiller au plafond","OK")
A11: AV-008 | B11: Retraite | C11: 150000 | D11: =SUMIF('F05 - 3-Inscription Avant.'!F6:F115,A11,'F05 - 3-Inscription Avant.'!H6:H115)*12 | E11: =IF(C11=0,0,D11/C11) | F11: =IF(D11>C11,"DÉPASSÉ DE "&TEXT((D11-C11),"#,##0")&" FCFA","") | G11: =MIN(D11,C11) | H11: =MAX(D11-C11,0) | I11: =MAX(D11-C11,0)*0.25 | J11: =IF(E11>0.9,"Veiller au plafond","OK")
A12: AV-013 | B12: Formation | C12: 960000 | D12: =SUMIF('F05 - 3-Inscription Avant.'!F6:F115,A12,'F05 - 3-Inscription Avant.'!H6:H115)*12 | E12: =IF(C12=0,0,D12/C12) | F12: =IF(D12>C12,"DÉPASSÉ DE "&TEXT((D12-C12),"#,##0")&" FCFA","") | G12: =MIN(D12,C12) | H12: =MAX(D12-C12,0) | I12: =MAX(D12-C12,0)*0.25 | J12: =IF(E12>0.9,"Veiller au plafond","OK")

Sheet F16 - 14-Suivi Réclamations
A2: SUIVI DES RÉCLAMATIONS AVANTAGES SOCIAUX
A3: TABLEAU DYNAMIQUE — Saisissez dans la zone prévue ci-dessous
A5: Matricule | B5: Nom (VLOOKUP) | C5: Avantage concerné | D5: Type réclamation | E5: Date réclamation | F5: Description | G5: Priorité | H5: Statut | I5: Délai résolution (jours) | J5: Responsable | K5: Date résolution | N5: Date MAJ
A6: EMP-003 | B6: =IFERROR(VLOOKUP(A6,'F01 - _Données Employés'!$A$6:$C$20,2,FALSE),"") | C6: AV-002 | D6: Retard remboursement | E6: 45413 | F6: Remboursement soins non reçu depuis 2 mois | G6: Haute | H6: En cours | I6: =IF(H6="Résolue",IFERROR(L6-E6,30),IF(H6="Rejetée",IFERROR(L6-E6,0),TODAY()-E6)) | J6: Mme Koffi | N6: 45444
A7: EMP-001 | B7: =IFERROR(VLOOKUP(A7,'F01 - _Données Employés'!$A$6:$C$20,2,FALSE),"") | C7: AV-004 | D7: Montant erroné | E7: 45416 | F7: Ticket restaurant valeur incorrecte ce mois | G7: Moyenne | H7: Ouverte | I7: =IF(H7="Résolue",IFERROR(L7-E7,30),IF(H7="Rejetée",IFERROR(L7-E7,0),TODAY()-E7)) | J7: M. Diallo | N7: 45444
A8: EMP-005 | B8: =IFERROR(VLOOKUP(A8,'F01 - _Données Employés'!$A$6:$C$20,2,FALSE),"") | C8: AV-001 | D8: Information manquante | E8: 45419 | F8: Attestation CNPS non disponible | G8: Basse | H8: Résolue | I8: =IF(H8="Résolue",IFERROR(L8-E8,30),IF(H8="Rejetée",IFERROR(L8-E8,0),TODAY()-E8)) | J8: Mme Koffi | K8: 45437 | N8: 45444
A9: EMP-008 | B9: =IFERROR(VLOOKUP(A9,'F01 - _Données Employés'!$A$6:$C$20,2,FALSE),"") | C9: AV-002 | D9: Couverture refusée | E9: 45422 | F9: Soins dentaires non couverts | G9: Haute | H9: En cours | I9: =IF(H9="Résolue",IFERROR(L9-E9,30),IF(H9="Rejetée",IFERROR(L9-E9,0),TODAY()-E9)) | J9: M. Diallo | N9: 45444
A10: EMP-002 | B10: =IFERROR(VLOOKUP(A10,'F01 - _Données Employés'!$A$6:$C$20,2,FALSE),"") | C10: AV-003 | D10: Retard remboursement | E10: 45425 | F10: Capital décès dossier en attente | G10: Haute | H10: Ouverte | I10: =IF(H10="Résolue",IFERROR(L10-E10,30),IF(H10="Rejetée",IFERROR(L10-E10,0),TODAY()-E10)) | J10: Mme Koffi | N10: 45444

Sheet F17 - 15-Hist. Modif.
A2: HISTORIQUE DES MODIFICATIONS D'AVANTAGES
A3: TABLEAU DYNAMIQUE — Saisissez dans la zone prévue ci-dessous
A5: Avantage | B5: Ancien montant (FCFA) | C5: Nouveau montant (FCFA) | D5: Date modification | E5: Motif | F5: Validé par | G5: Impact budgétaire (FCFA) | N5: Date MAJ
A6: AV-002 | B6: 16000 | C6: 18500 | D6: Révision tarifaire mutuelle 2024 | E6: DRH | F6: 45306 | G6: =(C6-B6)*COUNTIF('F05 - 3-Inscription Avant.'!F6:F115,A6)*12 | N6: 45444
A7: AV-004 | B7: 20000 | C7: 22000 | D7: Ajustement inflation alimentaire | E7: DAF | F7: 45323 | G7: =(C7-B7)*COUNTIF('F05 - 3-Inscription Avant.'!F6:F115,A7)*12 | N7: 45444
A8: AV-005 | B8: 22000 | C8: 25000 | D8: Augmentation coût carburant | E8: DAF | F8: 45352 | G8: =(C8-B8)*COUNTIF('F05 - 3-Inscription Avant.'!F6:F115,A8)*12 | N8: 45444
A9: AV-008 | B9: 12000 | C9: 15000 | D9: Révision plan épargne retraite | E9: DRH | F9: 45292 | G9: =(C9-B9)*COUNTIF('F05 - 3-Inscription Avant.'!F6:F115,A9)*12 | N9: 45444
A10: AV-013 | B10: 35000 | C10: 40000 | D10: Augmentation budget formation | E10: DRH | F10: 45383 | G10: =(C10-B10)*COUNTIF('F05 - 3-Inscription Avant.'!F6:F115,A10)*12 | N10: 45444

Sheet F18 - 16-Cal. Renouvellements
A2: CALENDRIER DES RENOUVELLEMENTS DE CONTRATS
A3: TABLEAU DYNAMIQUE — Saisissez dans la zone prévue ci-dessous
A5: Fournisseur | B5: Avantage | C5: Date fin contrat | D5: Date alerte (-60j) | E5: Jours restants | F5: Statut | G5: Action requise | H5: Responsable | I5: Renouvellement effectué | J5: Date renouvellement | N5: Date MAJ
A6: AXA Assurance | B6: AV-003 | C6: 45838 | D6: =C6-60 | E6: =IF(C6="","",C6-TODAY()) | F6: =IF(E6="","",IF(E6<30,"URGENT",IF(E6<60,"ATTENTION","OK"))) | G6: Relancer négociation | H6: M. Koné | I6: Non | N6: 45444
A7: Mutuelle Hôteliers CI | B7: AV-002 | C7: 46022 | D7: =C7-60 | E7: =IF(C7="","",C7-TODAY()) | F7: =IF(E7="","",IF(E7<30,"URGENT",IF(E7<60,"ATTENTION","OK"))) | G7: Préparer appel d'offres | H7: Mme Touré | I7: Non | N7: 45444
A8: Allianz | B8: AV-008 | C8: 45808 | D8: =C8-60 | E8: =IF(C8="","",C8-TODAY()) | F8: =IF(E8="","",IF(E8<30,"URGENT",IF(E8<60,"ATTENTION","OK"))) | G8: Comparer offres | H8: M. Bamba | I8: Non | N8: 45444
A9: NSIA Vie | B9: AV-006 | C9: 46022 | D9: =C9-60 | E9: =IF(C9="","",C9-TODAY()) | F9: =IF(E9="","",IF(E9<30,"URGENT",IF(E9<60,"ATTENTION","OK"))) | G9: Évaluer conditions | H9: Mme Diabaté | I9: Non | N9: 45444
A10: SATRAM | B10: AV-009 | C10: 45657 | D10: =C10-60 | E10: =IF(C10="","",C10-TODAY()) | F10: =IF(E10="","",IF(E10<30,"URGENT",IF(E10<60,"ATTENTION","OK"))) | G10: Planifier visite annuelle | H10: M. Aka | I10: Oui | J10: 45611 | N10: 45444

Sheet F19 - 17-Matrice Emp-Avant
A2: MATRICE EMPLOYÉS VS AVANTAGES — Inscriptions par catégorie
A3: TABLEAU DYNAMIQUE — Saisissez dans la zone prévue ci-dessous
A5: Matricule | B5: Nom | C5: Santé | D5: Retraite | E5: Prévoyance | F5: Alimentation | G5: Transport | H5: Logement | I5: Formation | J5: Loisirs | K5: Autre | L5: Total
