Workbook

Sheet F01 - _Données Collabor.
A2: DONNÉES COLLABORATEURS — Base de référence engagement
A3: TABLEAU DYNAMIQUE — Saisissez dans la zone prévue ci-dessous
A5: Matricule | B5: Nom | C5: Prénom | D5: Département | E5: Poste | F5: Score Engagement (%) | G5: Note Engagement (/5) | H5: Catégorie Engagement | I5: Genre
A6: COL-001 | B6: Koné | C6: Aminata | D6: Cuisine & Restauration | E6: Chef Pâtissier | F6: 78 | G6: 4.2 | H6: Très engagé | I6: F
A7: COL-002 | B7: Traoré | C7: Ibrahim | D7: Informatique | E7: DSI | F7: 85 | G7: 4.5 | H7: Très engagé | I7: M
A8: COL-003 | B8: Diallo | C8: Fatou | D8: Marketing & Communication | E8: Resp. Marketing | F8: 72 | G8: 3.8 | H8: Engagé | I8: F
A9: COL-004 | B9: Ouattara | C9: Moussa | D9: Finance & Comptabilité | E9: Comptable Senior | F9: 68 | G9: 3.5 | H9: Engagé | I9: M
A10: COL-005 | B10: Bamba | C10: Mariam | D10: Réception & Front Office | E10: Chef Réception | F10: 90 | G10: 4.8 | H10: Ambassadeur | I10: F
A11: COL-006 | B11: Coulibaly | C11: Adama | D11: Entretien & Maintenance | E11: Chef Entretien | F11: 55 | G11: 2.8 | H11: À surveiller | I11: M
A12: COL-007 | B12: Konan | C12: Yao | D12: Ressources Humaines | E12: DRH | F12: 82 | G12: 4 | H12: Très engagé | I12: M
A13: COL-008 | B13: Sangaré | C13: Awa | D13: Commercial | E13: Resp. Commercial | F13: 75 | G13: 3.9 | H13: Engagé | I13: F
A14: COL-009 | B14: Djibril | C14: Oumar | D14: Sécurité | E14: Chef Sécurité | F14: 60 | G14: 3 | H14: Neutre | I14: M
A15: COL-010 | B15: Yao | C15: Akissi | D15: Hébergement | E15: Gouvernante | F15: 88 | G15: 4.6 | H15: Très engagé | I15: F
A16: COL-011 | B16: N'Guessan | C16: Koffi | D16: Cuisine & Restauration | E16: Chef Cuisinier | F16: 80 | G16: 4.1 | H16: Très engagé | I16: M
A17: COL-012 | B17: Koffi | C17: Marie | D17: Service Client | E17: Resp. Service Client | F17: 70 | G17: 3.6 | H17: Engagé | I17: F
... A20: COL-015 | B20: N'Dri | C20: Fatou | D20: Animation & Loisirs | E20: Animatrice | F20: 76 | G20: 3.9 | H20: Engagé | I20: F

Sheet F02 - _Lists
A2: LISTES DE RÉFÉRENCE — Valeurs pour listes déroulantes
A3: TABLEAU DYNAMIQUE — Saisissez dans la zone prévue ci-dessous
A5: departements | B5: postes | C5: canaux | D5: types_evenement | E5: statuts_evenement | F5: statuts_action | G5: frequences | H5: priorites | I5: cibles | J5: types_enquete | K5: niveaux_satisfaction | L5: categories_suggestion | M5: statuts_suggestion | N5: niveaux_alerte | O5: types_alerte | P5: mois | Q5: trimestres | R5: tendances | S5: modes_paiement | T5: validations | U5: conformites | V5: engagement_niveaux | W5: periodicites_newsletter | X5: statuts_newsletter | Y5: types_poste_cvs
A6: Direction Générale | B6: DG | C6: Intranet | D6: Team building | E6: Planifié | F6: En attente | G6: Hebdomadaire | H6: Haute | I6: Tous | J6: Engagement global | K6: Très insatisfait | L6: Conditions de travail | M6: En attente | N6: Faible | O6: Rumeur | P6: Janvier 2025 | Q6: T1 2025 | R6: Hausse | S6: Virement | T6: Validé | U6: Conforme | V6: Ambassadeur | W6: Hebdomadaire | X6: Brouillon | Y6: Titulaire
A7: Ressources Humaines | B7: DRH | C7: Email interne | D7: Célébration | E7: En cours | F7: En cours | G7: Mensuelle | H7: Moyenne | I7: Cadres | J7: Climat social | K7: Insatisfait | L7: Rémunération | M7: Étudiée | N7: Moyen | O7: Mécontentement | P7: Février 2025 | Q7: T2 2025 | R7: Baisse | S7: Chèque | T7: En attente | U7: Partiellement conforme | V7: Très engagé | W7: Bimensuelle | X7: En revue | Y7: Suppléant
A8: Finance & Comptabilité | B8: DAF | C8: Affichage | D8: Formation informelle | E8: Terminé | F8: Terminé | G8: Trimestrielle | H8: Basse | I8: Non-cadres | J8: Satisfaction poste | K8: Neutre | L8: Formation | M8: Acceptée | N8: Élevé | O8: Conflit latent | P8: Mars 2025 | Q8: T3 2025 | R8: Stable | S8: Espèces | T8: Rejeté | U8: Non conforme | V8: Engagé | W8: Mensuelle | X8: Validé | Y8: Invité permanent
A9: Marketing & Communication | B9: DSI | C9: Réunion d'équipe | D9: Sport interne | E9: Annulé | F9: Reporté | G9: Semestrielle | I9: Département | J9: Qualité de vie travail | K9: Satisfait | L9: Communication | M9: Rejetée | N9: Critique | O9: Risque départ | P9: Avril 2025 | Q9: T4 2025 | T9: Non applicable | U9: En attente | V9: Neutre | W9: Trimestrielle | X9: Diffusé
A10: Informatique | B10: Resp. Marketing | C10: Newsletter | D10: Repas partagé | E10: Reporté | F10: Annulé | G10: Annuelle | I10: Nouveaux arrivants | J10: Communication interne | K10: Très satisfait | L10: Environnement | M10: Mise en oeuvre | O10: Tension interne | P10: Mai 2025 | V10: À surveiller | X10: Archivé
A11: Commercial | B11: Resp. Commercial | C11: Tablette digitale | D11: Atelier créatif | J11: Management | L11: Équipements | O11: Risque psychosocial | P11: Juin 2025 | V11: Désengagé
A12: Logistique & Approvisionnement | B12: Chef Logistique | C12: Application mobile | D12: Journée portes ouvertes | J12: Rémunération | L12: Horaires | P12: Juillet 2025
A13: Réception & Front Office | B13: Chef Réception | C13: Panneau d'affichage | D13: Soirée thématique | J13: Formation | L13: Relations collègues | P13: Août 2025
A14: Cuisine & Restauration | B14: Chef Cuisinier | C14: Réunion générale | L14: Management | P14: Septembre 2025
A15: Hébergement | B15: Chef Pâtissier | C15: Whatsapp groupe | L15: Sécurité | P15: Octobre 2025
A16: Entretien & Maintenance | B16: Comptable Senior | L16: Autre | P16: Novembre 2025
A17: Sécurité | B17: Chef Entretien | P17: Décembre 2025
A18: Service Client | B18: Chef Sécurité
A19: Animation & Loisirs | B19: Gouvernante
A20: Spa & Bien-être | B20: Resp. Service Client
B21: Animatrice
B22: Resp. Spa
B23: Agent Réception
B24: Agent Service Client
B25: Technicien

Sheet F03 - 1-Tableau de Bord
A2: DOMAINE 29 — COMMUNICATION INTERNE ET ENGAGEMENT COLLABORATEURS
A3: Tableau de Bord Synthétique — Engagement, communication et satisfaction
A5: INDICATEURS CLÉS
A6: Score Engagement Moyen | C6: Nb Suggestions Reçues | E6: Taux Participation Enquêtes | G6: Événements Réalisés (Année) | I6: Budget Communication Consommé | K6: Nb Newsletters Diffusées
A7: 75.6% | C7: 42 | E7: 87% | G7: 18 | I7: 62% | K7: 11
A9: ENGAGEMENT PAR DÉPARTEMENT | I9: CANAUX LES PLUS UTILISÉS
A10: Département | B10: Effectif | C10: Score Moyen | D10: Catégorie Majoritaire | E10: Nb Suggestions | I10: Canal | J10: Nb Publications | K10: Portée | L10: Interaction
A11: Cuisine & Restauration | B11: 2 | C11: 79 | D11: Très engagé | E11: 8 | I11: Intranet | J11: 45 | K11: 100% | L11: 62%
A12: Informatique | B12: 1 | C12: 85 | D12: Très engagé | E12: 6 | I12: Email interne | J12: 120 | K12: 100% | L12: 38%
A13: Marketing & Communication | B13: 1 | C13: 72 | D13: Engagé | E13: 5 | I13: Affichage | J13: 30 | K13: 85% | L13: N/A
A14: Finance & Comptabilité | B14: 1 | C14: 68 | D14: Engagé | E14: 3 | I14: Newsletter | J14: 11 | K14: 92% | L14: 55%
A15: Réception & Front Office | B15: 1 | C15: 90 | D15: Ambassadeur | E15: 7 | I15: Réunion d'équipe | J15: 48 | K15: Par département | L15: 78%
A16: Hébergement | B16: 1 | C16: 88 | D16: Très engagé | E16: 4 | I16: Tablette digitale | J16: 24 | K16: 65% | L16: 45%
A17: Entretien & Maintenance | B17: 1 | C17: 55 | D17: À surveiller | E17: 2
A18: Ressources Humaines | B18: 1 | C18: 82 | D18: Très engagé | E18: 3
A19: Commercial | B19: 1 | C19: 75 | D19: Engagé | E19: 2
A20: ACTIONS PLANIFIÉES
A21: Action | B21: Responsable | C21: Échéance | D21: Priorité | E21: Statut
A22: Lancer enquête engagement Q2 | B22: DRH | C22: 45748 | D22: Haute | E22: En cours
A23: Organiser team building annuel | B23: DRH / DG | C23: 45823 | D23: Haute | E23: Planifié
A24: Refonte intranet collaborateurs | B24: DSI / DRH | C24: 45808 | D24: Moyenne | E24: En cours
A25: Programme reconnaissance mensuel | B25: DRH | C25: 45717 | D25: Haute | E25: En cours

Sheet F04 - 2-Enquêtes Engagement
A2: 2-ENQUÊTES D'ENGAGEMENT
A3: TABLEAU DYNAMIQUE — Saisissez dans la zone prévue ci-dessous
A5: Code Enquête | B5: Type Enquête | C5: Période | D5: Date Lancement | E5: Date Clôture | F5: Nb Invités | G5: Nb Réponses | H5: Taux Participation (%) | I5: Score Moyen (/5) | J5: Statut | K5: Observations
A6: ENG-2025-T1 | B6: Engagement global | C6: T1 2025 | D6: 45672 | E6: 45687 | F6: 65 | G6: 57 | H6: =IF(OR(F6="",G6=""),"",IFERROR(G6/F6*100,0)) | I6: 4.1 | J6: Terminé | K6: Très bonne participation
A7: SAT-2025-T1 | B7: Satisfaction poste | C7: T1 2025 | D7: 45689 | E7: 45703 | F7: 65 | G7: 52 | H7: =IF(OR(F7="",G7=""),"",IFERROR(G7/F7*100,0)) | I7: 3.8 | J7: Terminé | K7: Baisse dans entretien
A8: COM-2025-T1 | B8: Communication interne | C8: T1 2025 | D8: 45717 | E8: 45730 | F8: 65 | G8: 48 | H8: =IF(OR(F8="",G8=""),"",IFERROR(G8/F8*100,0)) | I8: 3.5 | J8: Terminé | K8: Points d'amélioration identifiés
A9: ENG-2025-T2 | B9: Engagement global | C9: T2 2025 | D9: 45762 | E9: 45777 | F9: 68 | H9: =IF(OR(F9="",G9=""),"",IFERROR(G9/F9*100,0)) | J9: Planifié
A10: CLIM-2025-T2 | B10: Climat social | C10: T2 2025 | D10: 45778 | E10: 45792 | F10: 68 | H10: =IF(OR(F10="",G10=""),"",IFERROR(G10/F10*100,0)) | J10: Planifié
H11: =IF(OR(F11="",G11=""),"",IFERROR(G11/F11*100,0))
H12: =IF(OR(F12="",G12=""),"",IFERROR(G12/F12*100,0))
H13: =IF(OR(F13="",G13=""),"",IFERROR(G13/F13*100,0))
H14: =IF(OR(F14="",G14=""),"",IFERROR(G14/F14*100,0))
H15: =IF(OR(F15="",G15=""),"",IFERROR(G15/F15*100,0))
H16: =IF(OR(F16="",G16=""),"",IFERROR(G16/F16*100,0))
H17: =IF(OR(F17="",G17=""),"",IFERROR(G17/F17*100,0))
H18: =IF(OR(F18="",G18=""),"",IFERROR(G18/F18*100,0))
H19: =IF(OR(F19="",G19=""),"",IFERROR(G19/F19*100,0))
H20: =IF(OR(F20="",G20=""),"",IFERROR(G20/F20*100,0))
H21: =IF(OR(F21="",G21=""),"",IFERROR(G21/F21*100,0))
H22: =IF(OR(F22="",G22=""),"",IFERROR(G22/F22*100,0))
... H115: =IF(OR(F115="",G115=""),"",IFERROR(G115/F115*100,0))

Sheet F05 - 3-Plan Communication
A2: 3-PLAN DE COMMUNICATION INTERNE
A3: TABLEAU DYNAMIQUE — Saisissez dans la zone prévue ci-dessous
A5: Code Action | B5: Objectif Communication | C5: Cible | D5: Canal | E5: Fréquence | F5: Responsable | G5: Date Début | H5: Date Fin | I5: Budget (FCFA) | J5: Statut | K5: Indicateur Succès | L5: Résultat | M5: Observations
A6: =IF(B6="","",IF(COUNTA($A$6:A6)=0,"COM-ACT-"&TEXT(COUNTA($B$6:B6),"000"),"COM-ACT-"&TEXT(ROW()-5,"000"))) | B6: Informer sur la stratégie 2025 | C6: Tous | D6: Réunion générale | E6: Trimestrielle | F6: DG / DRH | G6: 45672 | H6: 46022 | I6: 50000 | J6: En cours | K6: Taux présence ≥ 80% | L6: 85%
A7: =IF(B7="","",IF(COUNTA($A$6:A7)=0,"COM-ACT-"&TEXT(COUNTA($B$6:B7),"000"),"COM-ACT-"&TEXT(ROW()-5,"000"))) | B7: Partager les résultats financiers | C7: Cadres | D7: Email interne | E7: Trimestrielle | F7: DAF | G7: 45689 | H7: 46022 | I7: 0 | J7: En cours | K7: Ouverture email ≥ 70% | L7: 72%
A8: =IF(B8="","",IF(COUNTA($A$6:A8)=0,"COM-ACT-"&TEXT(COUNTA($B$6:B8),"000"),"COM-ACT-"&TEXT(ROW()-5,"000"))) | B8: Animer la vie sociale | C8: Tous | D8: Affichage + Intranet | E8: Mensuelle | F8: DRH | G8: 45658 | H8: 46022 | I8: 200000 | J8: En cours | K8: 1 événement/mois | L8: En cours
A9: =IF(B9="","",IF(COUNTA($A$6:A9)=0,"COM-ACT-"&TEXT(COUNTA($B$6:B9),"000"),"COM-ACT-"&TEXT(ROW()-5,"000"))) | B9: Diffuser newsletter interne | C9: Tous | D9: Email + Intranet | E9: Mensuelle | F9: Resp. Marketing | G9: 45667 | H9: 46022 | I9: 120000 | J9: En cours | K9: Taux lecture ≥ 55% | L9: 58%
A10: =IF(B10="","",IF(COUNTA($A$6:A10)=0,"COM-ACT-"&TEXT(COUNTA($B$6:B10),"000"),"COM-ACT-"&TEXT(ROW()-5,"000"))) | B10: Sensibiliser QVT | C10: Tous | D10: Tablette digitale | E10: Mensuelle | F10: DRH / CSSCT | G10: 45717 | H10: 45930 | I10: 80000 | J10: Planifié | K10: Score QVT hausse 5%
A11: =IF(B11="","",IF(COUNTA($A$6:A11)=0,"COM-ACT-"&TEXT(COUNTA($B$6:B11),"000"),"COM-ACT-"&TEXT(ROW()-5,"000")))
A12: =IF(B12="","",IF(COUNTA($A$6:A12)=0,"COM-ACT-"&TEXT(COUNTA($B$6:B12),"000"),"COM-ACT-"&TEXT(ROW()-5,"000")))
A13: =IF(B13="","",IF(COUNTA($A$6:A13)=0,"COM-ACT-"&TEXT(COUNTA($B$6:B13),"000"),"COM-ACT-"&TEXT(ROW()-5,"000")))
A14: =IF(B14="","",IF(COUNTA($A$6:A14)=0,"COM-ACT-"&TEXT(COUNTA($B$6:B14),"000"),"COM-ACT-"&TEXT(ROW()-5,"000")))
A15: =IF(B15="","",IF(COUNTA($A$6:A15)=0,"COM-ACT-"&TEXT(COUNTA($B$6:B15),"000"),"COM-ACT-"&TEXT(ROW()-5,"000")))
A16: =IF(B16="","",IF(COUNTA($A$6:A16)=0,"COM-ACT-"&TEXT(COUNTA($B$6:B16),"000"),"COM-ACT-"&TEXT(ROW()-5,"000")))
A17: =IF(B17="","",IF(COUNTA($A$6:A17)=0,"COM-ACT-"&TEXT(COUNTA($B$6:B17),"000"),"COM-ACT-"&TEXT(ROW()-5,"000")))
A18: =IF(B18="","",IF(COUNTA($A$6:A18)=0,"COM-ACT-"&TEXT(COUNTA($B$6:B18),"000"),"COM-ACT-"&TEXT(ROW()-5,"000")))
A19: =IF(B19="","",IF(COUNTA($A$6:A19)=0,"COM-ACT-"&TEXT(COUNTA($B$6:B19),"000"),"COM-ACT-"&TEXT(ROW()-5,"000")))
A20: =IF(B20="","",IF(COUNTA($A$6:A20)=0,"COM-ACT-"&TEXT(COUNTA($B$6:B20),"000"),"COM-ACT-"&TEXT(ROW()-5,"000")))
A21: =IF(B21="","",IF(COUNTA($A$6:A21)=0,"COM-ACT-"&TEXT(COUNTA($B$6:B21),"000"),"COM-ACT-"&TEXT(ROW()-5,"000")))
A22: =IF(B22="","",IF(COUNTA($A$6:A22)=0,"COM-ACT-"&TEXT(COUNTA($B$6:B22),"000"),"COM-ACT-"&TEXT(ROW()-5,"000")))
... A115: =IF(B115="","",IF(COUNTA($A$6:A115)=0,"COM-ACT-"&TEXT(COUNTA($B$6:B115),"000"),"COM-ACT-"&TEXT(ROW()-5,"000")))

Sheet F06 - 4-Événements Internes
A2: 4-ÉVÉNEMENTS ET ANIMATIONS INTERNES
A3: TABLEAU DYNAMIQUE — Saisissez dans la zone prévue ci-dessous
A5: Code Événement | B5: Nom Événement | C5: Type | D5: Date | E5: Lieu | F5: Nb Participants | G5: Budget (FCFA) | H5: Coût Réel (FCFA) | I5: Satisfaction Moy. | J5: Statut | K5: Commentaire | L5: Observations
A6: =IF(B6="","",IF(COUNTA($A$6:A6)=0,"EVT-"&TEXT(COUNTA($B$6:B6),"000"),"EVT-"&TEXT(ROW()-5,"000"))) | B6: Kick-off Année 2025 | C6: Célébration | D6: 45667 | E6: Restaurant principal | F6: 62 | G6: 500000 | H6: =IF(G6="","",IFERROR(G6-F6,0)) | I6: 4.3 | J6: Terminé | K6: Excellente ambiance, DG très impliqué
A7: =IF(B7="","",IF(COUNTA($A$6:A7)=0,"EVT-"&TEXT(COUNTA($B$6:B7),"000"),"EVT-"&TEXT(ROW()-5,"000"))) | B7: Tournoi inter-départements | C7: Sport interne | D7: 45710 | E7: Terrain sport | F7: 45 | G7: 150000 | H7: =IF(G7="","",IFERROR(G7-F7,0)) | I7: 4.7 | J7: Terminé | K7: Participation record, ambiance conviviale
A8: =IF(B8="","",IF(COUNTA($A$6:A8)=0,"EVT-"&TEXT(COUNTA($B$6:B8),"000"),"EVT-"&TEXT(ROW()-5,"000"))) | B8: Atelier cuisine partagée | C8: Atelier créatif | D8: 45731 | E8: Cuisine principale | F8: 20 | G8: 80000 | H8: =IF(G8="","",IFERROR(G8-F8,0)) | I8: 4.5 | J8: Terminé | K8: Moment d'échange entre départements
A9: =IF(B9="","",IF(COUNTA($A$6:A9)=0,"EVT-"&TEXT(COUNTA($B$6:B9),"000"),"EVT-"&TEXT(ROW()-5,"000"))) | B9: Journée bien-être | C9: Team building | D9: 45767 | E9: Spa + Jardin | F9: 50 | G9: 300000 | H9: =IF(G9="","",IFERROR(G9-F9,0)) | J9: Planifié | K9: Activités spa, yoga et relaxation prévues
A10: =IF(B10="","",IF(COUNTA($A$6:A10)=0,"EVT-"&TEXT(COUNTA($B$6:B10),"000"),"EVT-"&TEXT(ROW()-5,"000"))) | B10: Soirée iftar | C10: Repas partagé | D10: 45736 | E10: Salle événementielle | F10: 58 | G10: 200000 | H10: =IF(G10="","",IFERROR(G10-F10,0)) | I10: 4.6 | J10: Terminé | K10: Moment fort de cohésion pendant ramadan
A11: =IF(B11="","",IF(COUNTA($A$6:A11)=0,"EVT-"&TEXT(COUNTA($B$6:B11),"000"),"EVT-"&TEXT(ROW()-5,"000"))) | H11: =IF(G11="","",IFERROR(G11-F11,0))
A12: =IF(B12="","",IF(COUNTA($A$6:A12)=0,"EVT-"&TEXT(COUNTA($B$6:B12),"000"),"EVT-"&TEXT(ROW()-5,"000"))) | H12: =IF(G12="","",IFERROR(G12-F12,0))
A13: =IF(B13="","",IF(COUNTA($A$6:A13)=0,"EVT-"&TEXT(COUNTA($B$6:B13),"000"),"EVT-"&TEXT(ROW()-5,"000"))) | H13: =IF(G13="","",IFERROR(G13-F13,0))
A14: =IF(B14="","",IF(COUNTA($A$6:A14)=0,"EVT-"&TEXT(COUNTA($B$6:B14),"000"),"EVT-"&TEXT(ROW()-5,"000"))) | H14: =IF(G14="","",IFERROR(G14-F14,0))
A15: =IF(B15="","",IF(COUNTA($A$6:A15)=0,"EVT-"&TEXT(COUNTA($B$6:B15),"000"),"EVT-"&TEXT(ROW()-5,"000"))) | H15: =IF(G15="","",IFERROR(G15-F15,0))
A16: =IF(B16="","",IF(COUNTA($A$6:A16)=0,"EVT-"&TEXT(COUNTA($B$6:B16),"000"),"EVT-"&TEXT(ROW()-5,"000"))) | H16: =IF(G16="","",IFERROR(G16-F16,0))
A17: =IF(B17="","",IF(COUNTA($A$6:A17)=0,"EVT-"&TEXT(COUNTA($B$6:B17),"000"),"EVT-"&TEXT(ROW()-5,"000"))) | H17: =IF(G17="","",IFERROR(G17-F17,0))
A18: =IF(B18="","",IF(COUNTA($A$6:A18)=0,"EVT-"&TEXT(COUNTA($B$6:B18),"000"),"EVT-"&TEXT(ROW()-5,"000"))) | H18: =IF(G18="","",IFERROR(G18-F18,0))
A19: =IF(B19="","",IF(COUNTA($A$6:A19)=0,"EVT-"&TEXT(COUNTA($B$6:B19),"000"),"EVT-"&TEXT(ROW()-5,"000"))) | H19: =IF(G19="","",IFERROR(G19-F19,0))
A20: =IF(B20="","",IF(COUNTA($A$6:A20)=0,"EVT-"&TEXT(COUNTA($B$6:B20),"000"),"EVT-"&TEXT(ROW()-5,"000"))) | H20: =IF(G20="","",IFERROR(G20-F20,0))
A21: =IF(B21="","",IF(COUNTA($A$6:A21)=0,"EVT-"&TEXT(COUNTA($B$6:B21),"000"),"EVT-"&TEXT(ROW()-5,"000"))) | H21: =IF(G21="","",IFERROR(G21-F21,0))
A22: =IF(B22="","",IF(COUNTA($A$6:A22)=0,"EVT-"&TEXT(COUNTA($B$6:B22),"000"),"EVT-"&TEXT(ROW()-5,"000"))) | H22: =IF(G22="","",IFERROR(G22-F22,0))
... A115: =IF(B115="","",IF(COUNTA($A$6:A115)=0,"EVT-"&TEXT(COUNTA($B$6:B115),"000"),"EVT-"&TEXT(ROW()-5,"000"))) | H115: =IF(G115="","",IFERROR(G115-F115,0))

Sheet F07 - 5-Canaux Communication
A2: 5-CANAUX DE COMMUNICATION
A3: TABLEAU DYNAMIQUE — Saisissez dans la zone prévue ci-dessous
A5: Canal | B5: Type Contenu | C5: Fréquence Diffusion | D5: Responsable | E5: Portée (nb personnes) | F5: Taux Interaction (%) | G5: Coût Mensuel (FCFA) | H5: Efficacité | I5: Dernière Mise à Jour | J5: Observations
A6: Intranet | B6: Informations générales | C6: Mensuelle | D6: DSI / DRH | E6: 65 | F6: 62 | G6: 50000 | H6: =IF(F6="","",IF(F6>=60,"Très efficace",IF(F6>=40,"Efficace",IF(F6>=20,"Modéré","Faible")))) | I6: 45716 | J6: =IF(G6="","",G6*12)
A7: Email interne | B7: Annonces officielles | C7: Hebdomadaire | D7: DRH | E7: 65 | F7: 38 | G7: 15000 | H7: =IF(F7="","",IF(F7>=60,"Très efficace",IF(F7>=40,"Efficace",IF(F7>=20,"Modéré","Faible")))) | I7: 45717 | J7: =IF(G7="","",G7*12)
A8: Affichage | B8: Informations légales, événements | C8: Mensuelle | D8: DRH | E8: 55 | G8: 10000 | H8: =IF(F8="","",IF(F8>=60,"Très efficace",IF(F8>=40,"Efficace",IF(F8>=20,"Modéré","Faible")))) | I8: 45703 | J8: =IF(G8="","",G8*12)
A9: Newsletter | B9: Actualités, succès, vie sociale | C9: Mensuelle | D9: Resp. Marketing | E9: 60 | F9: 55 | G9: 10000 | H9: =IF(F9="","",IF(F9>=60,"Très efficace",IF(F9>=40,"Efficace",IF(F9>=20,"Modéré","Faible")))) | I9: 45717 | J9: =IF(G9="","",G9*12)
A10: Tablette digitale | B10: Infographies, quiz, sondages | C10: Hebdomadaire | D10: DRH / DSI | E10: 42 | F10: 45 | G10: 25000 | H10: =IF(F10="","",IF(F10>=60,"Très efficace",IF(F10>=40,"Efficace",IF(F10>=20,"Modéré","Faible")))) | I10: 45721 | J10: =IF(G10="","",G10*12)
H11: =IF(F11="","",IF(F11>=60,"Très efficace",IF(F11>=40,"Efficace",IF(F11>=20,"Modéré","Faible")))) | J11: =IF(G11="","",G11*12)
H12: =IF(F12="","",IF(F12>=60,"Très efficace",IF(F12>=40,"Efficace",IF(F12>=20,"Modéré","Faible")))) | J12: =IF(G12="","",G12*12)
H13: =IF(F13="","",IF(F13>=60,"Très efficace",IF(F13>=40,"Efficace",IF(F13>=20,"Modéré","Faible")))) | J13: =IF(G13="","",G13*12)
H14: =IF(F14="","",IF(F14>=60,"Très efficace",IF(F14>=40,"Efficace",IF(F14>=20,"Modéré","Faible")))) | J14: =IF(G14="","",G14*12)
H15: =IF(F15="","",IF(F15>=60,"Très efficace",IF(F15>=40,"Efficace",IF(F15>=20,"Modéré","Faible")))) | J15: =IF(G15="","",G15*12)
H16: =IF(F16="","",IF(F16>=60,"Très efficace",IF(F16>=40,"Efficace",IF(F16>=20,"Modéré","Faible")))) | J16: =IF(G16="","",G16*12)
H17: =IF(F17="","",IF(F17>=60,"Très efficace",IF(F17>=40,"Efficace",IF(F17>=20,"Modéré","Faible")))) | J17: =IF(G17="","",G17*12)
H18: =IF(F18="","",IF(F18>=60,"Très efficace",IF(F18>=40,"Efficace",IF(F18>=20,"Modéré","Faible")))) | J18: =IF(G18="","",G18*12)
H19: =IF(F19="","",IF(F19>=60,"Très efficace",IF(F19>=40,"Efficace",IF(F19>=20,"Modéré","Faible")))) | J19: =IF(G19="","",G19*12)
H20: =IF(F20="","",IF(F20>=60,"Très efficace",IF(F20>=40,"Efficace",IF(F20>=20,"Modéré","Faible")))) | J20: =IF(G20="","",G20*12)
H21: =IF(F21="","",IF(F21>=60,"Très efficace",IF(F21>=40,"Efficace",IF(F21>=20,"Modéré","Faible")))) | J21: =IF(G21="","",G21*12)
H22: =IF(F22="","",IF(F22>=60,"Très efficace",IF(F22>=40,"Efficace",IF(F22>=20,"Modéré","Faible")))) | J22: =IF(G22="","",G22*12)
... H115: =IF(F115="","",IF(F115>=60,"Très efficace",IF(F115>=40,"Efficace",IF(F115>=20,"Modéré","Faible")))) | J115: =IF(G115="","",G115*12)

Sheet F08 - 6-Boîte à Idées
A2: 6-BOÎTE À IDÉES ET SUGGESTIONS
A3: TABLEAU DYNAMIQUE — Saisissez dans la zone prévue ci-dessous
A5: Code Suggestion | B5: Auteur | C5: Département | D5: Date Soumission | E5: Catégorie | F5: Description | G5: Statut | H5: Nb Soutiens | I5: Date Traitement | J5: Réponse RH | K5: Observations
A6: =IF(B6="","",IF(COUNTA($A$6:A6)=0,"SUG-"&TEXT(COUNTA($B$6:B6),"000"),"SUG-"&TEXT(ROW()-5,"000"))) | B6: Koné Aminata | C6: =IF(B6="","",VLOOKUP(B6,'F01 - _Données Collaborateurs'!$B$6:$F$20,5,FALSE)) | D6: 45677 | E6: Équipements | F6: Installer un four ventilé supplémentaire pour la pâtisserie | G6: Acceptée | H6: 8 | I6: 45703 | J6: Budget validé pour T2 2025 | K6: =IF(B6="","",IFERROR(VLOOKUP(B6,'F01 - _Données Collaborateurs'!$B$6:$H$20,6,FALSE),"")) | L6: =IF(I6="","",IF(I6-D6>15,"Traitement lent","Délai OK"))
A7: =IF(B7="","",IF(COUNTA($A$6:A7)=0,"SUG-"&TEXT(COUNTA($B$6:B7),"000"),"SUG-"&TEXT(ROW()-5,"000"))) | B7: Traoré Ibrahim | C7: =IF(B7="","",VLOOKUP(B7,'F01 - _Données Collaborateurs'!$B$6:$F$20,5,FALSE)) | D7: 45682 | E7: Communication | F7: Créer une application mobile pour les collaborateurs | G7: Étudiée | H7: 12 | J7: Étude de faisabilité en cours | K7: =IF(B7="","",IFERROR(VLOOKUP(B7,'F01 - _Données Collaborateurs'!$B$6:$H$20,6,FALSE),"")) | L7: =IF(I7="","",IF(I7-D7>15,"Traitement lent","Délai OK"))
A8: =IF(B8="","",IF(COUNTA($A$6:A8)=0,"SUG-"&TEXT(COUNTA($B$6:B8),"000"),"SUG-"&TEXT(ROW()-5,"000"))) | B8: Bamba Mariam | C8: =IF(B8="","",VLOOKUP(B8,'F01 - _Données Collaborateurs'!$B$6:$F$20,5,FALSE)) | D8: 45689 | E8: Conditions de travail | F8: Améliorer l'éclairage du comptoir réception nuit | G8: Mise en oeuvre | H8: 6 | I8: 45717 | J8: Intervention électricien programmée | K8: =IF(B8="","",IFERROR(VLOOKUP(B8,'F01 - _Données Collaborateurs'!$B$6:$H$20,6,FALSE),"")) | L8: =IF(I8="","",IF(I8-D8>15,"Traitement lent","Délai OK"))
A9: =IF(B9="","",IF(COUNTA($A$6:A9)=0,"SUG-"&TEXT(COUNTA($B$6:B9),"000"),"SUG-"&TEXT(ROW()-5,"000"))) | B9: Yao Akissi | C9: =IF(B9="","",VLOOKUP(B9,'F01 - _Données Collaborateurs'!$B$6:$F$20,5,FALSE)) | D9: 45698 | E9: Formation | F9: Formation gestion du stress pour les gouvernantes | G9: Acceptée | H9: 10 | I9: 45721 | J9: Session programmée avril 2025 | K9: =IF(B9="","",IFERROR(VLOOKUP(B9,'F01 - _Données Collaborateurs'!$B$6:$H$20,6,FALSE),"")) | L9: =IF(I9="","",IF(I9-D9>15,"Traitement lent","Délai OK"))
A10: =IF(B10="","",IF(COUNTA($A$6:A10)=0,"SUG-"&TEXT(COUNTA($B$6:B10),"000"),"SUG-"&TEXT(ROW()-5,"000"))) | B10: Coulibaly Adama | C10: =IF(B10="","",VLOOKUP(B10,'F01 - _Données Collaborateurs'!$B$6:$F$20,5,FALSE)) | D10: 45703 | E10: Sécurité | F10: Remplacer les extincteurs périmés étage 3 et 4 | G10: Acceptée | H10: 15 | I10: 45708 | J10: Commande urgente passée | K10: =IF(B10="","",IFERROR(VLOOKUP(B10,'F01 - _Données Collaborateurs'!$B$6:$H$20,6,FALSE),"")) | L10: =IF(I10="","",IF(I10-D10>15,"Traitement lent","Délai OK"))
A11: =IF(B11="","",IF(COUNTA($A$6:A11)=0,"SUG-"&TEXT(COUNTA($B$6:B11),"000"),"SUG-"&TEXT(ROW()-5,"000"))) | C11: =IF(B11="","",VLOOKUP(B11,'F01 - _Données Collaborateurs'!$B$6:$F$20,5,FALSE)) | K11: =IF(B11="","",IFERROR(VLOOKUP(B11,'F01 - _Données Collaborateurs'!$B$6:$H$20,6,FALSE),"")) | L11: =IF(I11="","",IF(I11-D11>15,"Traitement lent","Délai OK"))
A12: =IF(B12="","",IF(COUNTA($A$6:A12)=0,"SUG-"&TEXT(COUNTA($B$6:B12),"000"),"SUG-"&TEXT(ROW()-5,"000"))) | C12: =IF(B12="","",VLOOKUP(B12,'F01 - _Données Collaborateurs'!$B$6:$F$20,5,FALSE)) | K12: =IF(B12="","",IFERROR(VLOOKUP(B12,'F01 - _Données Collaborateurs'!$B$6:$H$20,6,FALSE),"")) | L12: =IF(I12="","",IF(I12-D12>15,"Traitement lent","Délai OK"))
A13: =IF(B13="","",IF(COUNTA($A$6:A13)=0,"SUG-"&TEXT(COUNTA($B$6:B13),"000"),"SUG-"&TEXT(ROW()-5,"000"))) | C13: =IF(B13="","",VLOOKUP(B13,'F01 - _Données Collaborateurs'!$B$6:$F$20,5,FALSE)) | K13: =IF(B13="","",IFERROR(VLOOKUP(B13,'F01 - _Données Collaborateurs'!$B$6:$H$20,6,FALSE),"")) | L13: =IF(I13="","",IF(I13-D13>15,"Traitement lent","Délai OK"))
A14: =IF(B14="","",IF(COUNTA($A$6:A14)=0,"SUG-"&TEXT(COUNTA($B$6:B14),"000"),"SUG-"&TEXT(ROW()-5,"000"))) | C14: =IF(B14="","",VLOOKUP(B14,'F01 - _Données Collaborateurs'!$B$6:$F$20,5,FALSE)) | K14: =IF(B14="","",IFERROR(VLOOKUP(B14,'F01 - _Données Collaborateurs'!$B$6:$H$20,6,FALSE),"")) | L14: =IF(I14="","",IF(I14-D14>15,"Traitement lent","Délai OK"))
A15: =IF(B15="","",IF(COUNTA($A$6:A15)=0,"SUG-"&TEXT(COUNTA($B$6:B15),"000"),"SUG-"&TEXT(ROW()-5,"000"))) | C15: =IF(B15="","",VLOOKUP(B15,'F01 - _Données Collaborateurs'!$B$6:$F$20,5,FALSE)) | K15: =IF(B15="","",IFERROR(VLOOKUP(B15,'F01 - _Données Collaborateurs'!$B$6:$H$20,6,FALSE),"")) | L15: =IF(I15="","",IF(I15-D15>15,"Traitement lent","Délai OK"))
A16: =IF(B16="","",IF(COUNTA($A$6:A16)=0,"SUG-"&TEXT(COUNTA($B$6:B16),"000"),"SUG-"&TEXT(ROW()-5,"000"))) | C16: =IF(B16="","",VLOOKUP(B16,'F01 - _Données Collaborateurs'!$B$6:$F$20,5,FALSE)) | K16: =IF(B16="","",IFERROR(VLOOKUP(B16,'F01 - _Données Collaborateurs'!$B$6:$H$20,6,FALSE),"")) | L16: =IF(I16="","",IF(I16-D16>15,"Traitement lent","Délai OK"))
A17: =IF(B17="","",IF(COUNTA($A$6:A17)=0,"SUG-"&TEXT(COUNTA($B$6:B17),"000"),"SUG-"&TEXT(ROW()-5,"000"))) | C17: =IF(B17="","",VLOOKUP(B17,'F01 - _Données Collaborateurs'!$B$6:$F$20,5,FALSE)) | K17: =IF(B17="","",IFERROR(VLOOKUP(B17,'F01 - _Données Collaborateurs'!$B$6:$H$20,6,FALSE),"")) | L17: =IF(I17="","",IF(I17-D17>15,"Traitement lent","Délai OK"))
A18: =IF(B18="","",IF(COUNTA($A$6:A18)=0,"SUG-"&TEXT(COUNTA($B$6:B18),"000"),"SUG-"&TEXT(ROW()-5,"000"))) | C18: =IF(B18="","",VLOOKUP(B18,'F01 - _Données Collaborateurs'!$B$6:$F$20,5,FALSE)) | K18: =IF(B18="","",IFERROR(VLOOKUP(B18,'F01 - _Données Collaborateurs'!$B$6:$H$20,6,FALSE),"")) | L18: =IF(I18="","",IF(I18-D18>15,"Traitement lent","Délai OK"))
A19: =IF(B19="","",IF(COUNTA($A$6:A19)=0,"SUG-"&TEXT(COUNTA($B$6:B19),"000"),"SUG-"&TEXT(ROW()-5,"000"))) | C19: =IF(B19="","",VLOOKUP(B19,'F01 - _Données Collaborateurs'!$B$6:$F$20,5,FALSE)) | K19: =IF(B19="","",IFERROR(VLOOKUP(B19,'F01 - _Données Collaborateurs'!$B$6:$H$20,6,FALSE),"")) | L19: =IF(I19="","",IF(I19-D19>15,"Traitement lent","Délai OK"))
A20: =IF(B20="","",IF(COUNTA($A$6:A20)=0,"SUG-"&TEXT(COUNTA($B$6:B20),"000"),"SUG-"&TEXT(ROW()-5,"000"))) | C20: =IF(B20="","",VLOOKUP(B20,'F01 - _Données Collaborateurs'!$B$6:$F$20,5,FALSE)) | K20: =IF(B20="","",IFERROR(VLOOKUP(B20,'F01 - _Données Collaborateurs'!$B$6:$H$20,6,FALSE),"")) | L20: =IF(I20="","",IF(I20-D20>15,"Traitement lent","Délai OK"))
A21: =IF(B21="","",IF(COUNTA($A$6:A21)=0,"SUG-"&TEXT(COUNTA($B$6:B21),"000"),"SUG-"&TEXT(ROW()-5,"000"))) | C21: =IF(B21="","",VLOOKUP(B21,'F01 - _Données Collaborateurs'!$B$6:$F$20,5,FALSE)) | K21: =IF(B21="","",IFERROR(VLOOKUP(B21,'F01 - _Données Collaborateurs'!$B$6:$H$20,6,FALSE),"")) | L21: =IF(I21="","",IF(I21-D21>15,"Traitement lent","Délai OK"))
A22: =IF(B22="","",IF(COUNTA($A$6:A22)=0,"SUG-"&TEXT(COUNTA($B$6:B22),"000"),"SUG-"&TEXT(ROW()-5,"000"))) | C22: =IF(B22="","",VLOOKUP(B22,'F01 - _Données Collaborateurs'!$B$6:$F$20,5,FALSE)) | K22: =IF(B22="","",IFERROR(VLOOKUP(B22,'F01 - _Données Collaborateurs'!$B$6:$H$20,6,FALSE),"")) | L22: =IF(I22="","",IF(I22-D22>15,"Traitement lent","Délai OK"))
... A115: =IF(B115="","",IF(COUNTA($A$6:A115)=0,"SUG-"&TEXT(COUNTA($B$6:B115),"000"),"SUG-"&TEXT(ROW()-5,"000"))) | C115: =IF(B115="","",VLOOKUP(B115,'F01 - _Données Collaborateurs'!$B$6:$F$20,5,FALSE)) | K115: =IF(B115="","",IFERROR(VLOOKUP(B115,'F01 - _Données Collaborateurs'!$B$6:$H$20,6,FALSE),"")) | L115: =IF(I115="","",IF(I115-D115>15,"Traitement lent","Délai OK"))

Sheet F09 - 7-Entretiens Individuels
A2: 7-ENTRETIENS INDIVIDUELS RÉGULIERS
A3: TABLEAU DYNAMIQUE — Saisissez dans la zone prévue ci-dessous
A5: Code Entretien | B5: Collaborateur | C5: Département | D5: Date Entretien | E5: Type | F5: Manager | G5: Score Satisfaction (/5) | H5: Points Forts | I5: Axes Amélioration | J5: Suivi | K5: Observations
A6: =IF(B6="","",IF(COUNTA($A$6:A6)=0,"ENT-"&TEXT(COUNTA($B$6:B6),"000"),"ENT-"&TEXT(ROW()-5,"000"))) | B6: Koné Aminata | C6: =IF(B6="","",VLOOKUP(B6,'F01 - _Données Collaborateurs'!$B$6:$F$20,5,FALSE)) | D6: 45677 | E6: Mensuel | F6: Chef Cuisinier | G6: 4 | H6: Créativité, leadership brigade | I6: Gestion du stress en période haute | J6: Formation gestion stress prévue | L6: =IF(B6="","",IFERROR(VLOOKUP(B6,'F01 - _Données Collaborateurs'!$B$6:$G$20,6,FALSE),"")) | M6: =IF(OR(G6="",L6=""),"",IFERROR(G6-L6/20*5,0))
A7: =IF(B7="","",IF(COUNTA($A$6:A7)=0,"ENT-"&TEXT(COUNTA($B$6:B7),"000"),"ENT-"&TEXT(ROW()-5,"000"))) | B7: Traoré Ibrahim | C7: =IF(B7="","",VLOOKUP(B7,'F01 - _Données Collaborateurs'!$B$6:$F$20,5,FALSE)) | D7: 45679 | E7: Mensuel | F7: DG | G7: 4.5 | H7: Expertise technique, disponibilité | I7: Délégation et accompagnement équipe | J7: Mentorat junior en place | L7: =IF(B7="","",IFERROR(VLOOKUP(B7,'F01 - _Données Collaborateurs'!$B$6:$G$20,6,FALSE),"")) | M7: =IF(OR(G7="",L7=""),"",IFERROR(G7-L7/20*5,0))
A8: =IF(B8="","",IF(COUNTA($A$6:A8)=0,"ENT-"&TEXT(COUNTA($B$6:B8),"000"),"ENT-"&TEXT(ROW()-5,"000"))) | B8: Bamba Mariam | C8: =IF(B8="","",VLOOKUP(B8,'F01 - _Données Collaborateurs'!$B$6:$F$20,5,FALSE)) | D8: 45682 | E8: Mensuel | F8: DRH | G8: 4.8 | H8: Excellente relation client, ponctualité | I8: Préparation concours interne | J8: Dossier en cours | L8: =IF(B8="","",IFERROR(VLOOKUP(B8,'F01 - _Données Collaborateurs'!$B$6:$G$20,6,FALSE),"")) | M8: =IF(OR(G8="",L8=""),"",IFERROR(G8-L8/20*5,0))
A9: =IF(B9="","",IF(COUNTA($A$6:A9)=0,"ENT-"&TEXT(COUNTA($B$6:B9),"000"),"ENT-"&TEXT(ROW()-5,"000"))) | B9: Coulibaly Adama | C9: =IF(B9="","",VLOOKUP(B9,'F01 - _Données Collaborateurs'!$B$6:$F$20,5,FALSE)) | D9: 45693 | E9: Mensuel | F9: Chef Entretien | G9: 3.2 | H9: Connaissance technique solide | I9: Motivation et communication | J9: Plan d'action en cours | L9: =IF(B9="","",IFERROR(VLOOKUP(B9,'F01 - _Données Collaborateurs'!$B$6:$G$20,6,FALSE),"")) | M9: =IF(OR(G9="",L9=""),"",IFERROR(G9-L9/20*5,0))
A10: =IF(B10="","",IF(COUNTA($A$6:A10)=0,"ENT-"&TEXT(COUNTA($B$6:B10),"000"),"ENT-"&TEXT(ROW()-5,"000"))) | B10: Djibril Oumar | C10: =IF(B10="","",VLOOKUP(B10,'F01 - _Données Collaborateurs'!$B$6:$F$20,5,FALSE)) | D10: 45698 | E10: Trimestriel | F10: DG | G10: 3 | H10: Rigueur, respect consignes | I10: Proactivité et initiative | J10: Objectif : 1 initiative/mois | L10: =IF(B10="","",IFERROR(VLOOKUP(B10,'F01 - _Données Collaborateurs'!$B$6:$G$20,6,FALSE),"")) | M10: =IF(OR(G10="",L10=""),"",IFERROR(G10-L10/20*5,0))
A11: =IF(B11="","",IF(COUNTA($A$6:A11)=0,"ENT-"&TEXT(COUNTA($B$6:B11),"000"),"ENT-"&TEXT(ROW()-5,"000"))) | C11: =IF(B11="","",VLOOKUP(B11,'F01 - _Données Collaborateurs'!$B$6:$F$20,5,FALSE)) | L11: =IF(B11="","",IFERROR(VLOOKUP(B11,'F01 - _Données Collaborateurs'!$B$6:$G$20,6,FALSE),"")) | M11: =IF(OR(G11="",L11=""),"",IFERROR(G11-L11/20*5,0))
A12: =IF(B12="","",IF(COUNTA($A$6:A12)=0,"ENT-"&TEXT(COUNTA($B$6:B12),"000"),"ENT-"&TEXT(ROW()-5,"000"))) | C12: =IF(B12="","",VLOOKUP(B12,'F01 - _Données Collaborateurs'!$B$6:$F$20,5,FALSE)) | L12: =IF(B12="","",IFERROR(VLOOKUP(B12,'F01 - _Données Collaborateurs'!$B$6:$G$20,6,FALSE),"")) | M12: =IF(OR(G12="",L12=""),"",IFERROR(G12-L12/20*5,0))
A13: =IF(B13="","",IF(COUNTA($A$6:A13)=0,"ENT-"&TEXT(COUNTA($B$6:B13),"000"),"ENT-"&TEXT(ROW()-5,"000"))) | C13: =IF(B13="","",VLOOKUP(B13,'F01 - _Données Collaborateurs'!$B$6:$F$20,5,FALSE)) | L13: =IF(B13="","",IFERROR(VLOOKUP(B13,'F01 - _Données Collaborateurs'!$B$6:$G$20,6,FALSE),"")) | M13: =IF(OR(G13="",L13=""),"",IFERROR(G13-L13/20*5,0))
A14: =IF(B14="","",IF(COUNTA($A$6:A14)=0,"ENT-"&TEXT(COUNTA($B$6:B14),"000"),"ENT-"&TEXT(ROW()-5,"000"))) | C14: =IF(B14="","",VLOOKUP(B14,'F01 - _Données Collaborateurs'!$B$6:$F$20,5,FALSE)) | L14: =IF(B14="","",IFERROR(VLOOKUP(B14,'F01 - _Données Collaborateurs'!$B$6:$G$20,6,FALSE),"")) | M14: =IF(OR(G14="",L14=""),"",IFERROR(G14-L14/20*5,0))
A15: =IF(B15="","",IF(COUNTA($A$6:A15)=0,"ENT-"&TEXT(COUNTA($B$6:B15),"000"),"ENT-"&TEXT(ROW()-5,"000"))) | C15: =IF(B15="","",VLOOKUP(B15,'F01 - _Données Collaborateurs'!$B$6:$F$20,5,FALSE)) | L15: =IF(B15="","",IFERROR(VLOOKUP(B15,'F01 - _Données Collaborateurs'!$B$6:$G$20,6,FALSE),"")) | M15: =IF(OR(G15="",L15=""),"",IFERROR(G15-L15/20*5,0))
A16: =IF(B16="","",IF(COUNTA($A$6:A16)=0,"ENT-"&TEXT(COUNTA($B$6:B16),"000"),"ENT-"&TEXT(ROW()-5,"000"))) | C16: =IF(B16="","",VLOOKUP(B16,'F01 - _Données Collaborateurs'!$B$6:$F$20,5,FALSE)) | L16: =IF(B16="","",IFERROR(VLOOKUP(B16,'F01 - _Données Collaborateurs'!$B$6:$G$20,6,FALSE),"")) | M16: =IF(OR(G16="",L16=""),"",IFERROR(G16-L16/20*5,0))
A17: =IF(B17="","",IF(COUNTA($A$6:A17)=0,"ENT-"&TEXT(COUNTA($B$6:B17),"000"),"ENT-"&TEXT(ROW()-5,"000"))) | C17: =IF(B17="","",VLOOKUP(B17,'F01 - _Données Collaborateurs'!$B$6:$F$20,5,FALSE)) | L17: =IF(B17="","",IFERROR(VLOOKUP(B17,'F01 - _Données Collaborateurs'!$B$6:$G$20,6,FALSE),"")) | M17: =IF(OR(G17="",L17=""),"",IFERROR(G17-L17/20*5,0))
A18: =IF(B18="","",IF(COUNTA($A$6:A18)=0,"ENT-"&TEXT(COUNTA($B$6:B18),"000"),"ENT-"&TEXT(ROW()-5,"000"))) | C18: =IF(B18="","",VLOOKUP(B18,'F01 - _Données Collaborateurs'!$B$6:$F$20,5,FALSE)) | L18: =IF(B18="","",IFERROR(VLOOKUP(B18,'F01 - _Données Collaborateurs'!$B$6:$G$20,6,FALSE),"")) | M18: =IF(OR(G18="",L18=""),"",IFERROR(G18-L18/20*5,0))
A19: =IF(B19="","",IF(COUNTA($A$6:A19)=0,"ENT-"&TEXT(COUNTA($B$6:B19),"000"),"ENT-"&TEXT(ROW()-5,"000"))) | C19: =IF(B19="","",VLOOKUP(B19,'F01 - _Données Collaborateurs'!$B$6:$F$20,5,FALSE)) | L19: =IF(B19="","",IFERROR(VLOOKUP(B19,'F01 - _Données Collaborateurs'!$B$6:$G$20,6,FALSE),"")) | M19: =IF(OR(G19="",L19=""),"",IFERROR(G19-L19/20*5,0))
A20: =IF(B20="","",IF(COUNTA($A$6:A20)=0,"ENT-"&TEXT(COUNTA($B$6:B20),"000"),"ENT-"&TEXT(ROW()-5,"000"))) | C20: =IF(B20="","",VLOOKUP(B20,'F01 - _Données Collaborateurs'!$B$6:$F$20,5,FALSE)) | L20: =IF(B20="","",IFERROR(VLOOKUP(B20,'F01 - _Données Collaborateurs'!$B$6:$G$20,6,FALSE),"")) | M20: =IF(OR(G20="",L20=""),"",IFERROR(G20-L20/20*5,0))
A21: =IF(B21="","",IF(COUNTA($A$6:A21)=0,"ENT-"&TEXT(COUNTA($B$6:B21),"000"),"ENT-"&TEXT(ROW()-5,"000"))) | C21: =IF(B21="","",VLOOKUP(B21,'F01 - _Données Collaborateurs'!$B$6:$F$20,5,FALSE)) | L21: =IF(B21="","",IFERROR(VLOOKUP(B21,'F01 - _Données Collaborateurs'!$B$6:$G$20,6,FALSE),"")) | M21: =IF(OR(G21="",L21=""),"",IFERROR(G21-L21/20*5,0))
A22: =IF(B22="","",IF(COUNTA($A$6:A22)=0,"ENT-"&TEXT(COUNTA($B$6:B22),"000"),"ENT-"&TEXT(ROW()-5,"000"))) | C22: =IF(B22="","",VLOOKUP(B22,'F01 - _Données Collaborateurs'!$B$6:$F$20,5,FALSE)) | L22: =IF(B22="","",IFERROR(VLOOKUP(B22,'F01 - _Données Collaborateurs'!$B$6:$G$20,6,FALSE),"")) | M22: =IF(OR(G22="",L22=""),"",IFERROR(G22-L22/20*5,0))
... A115: =IF(B115="","",IF(COUNTA($A$6:A115)=0,"ENT-"&TEXT(COUNTA($B$6:B115),"000"),"ENT-"&TEXT(ROW()-5,"000"))) | C115: =IF(B115="","",VLOOKUP(B115,'F01 - _Données Collaborateurs'!$B$6:$F$20,5,FALSE)) | L115: =IF(B115="","",IFERROR(VLOOKUP(B115,'F01 - _Données Collaborateurs'!$B$6:$G$20,6,FALSE),"")) | M115: =IF(OR(G115="",L115=""),"",IFERROR(G115-L115/20*5,0))

Sheet F10 - 8-Indic. Engage.Dépt
A2: 8-INDICATEURS D'ENGAGEMENT PAR DÉPARTEMENT
A3: TABLEAU DYNAMIQUE — Saisissez dans la zone prévue ci-dessous
A5: Département | B5: Effectif | C5: Score Engagement Moy. | D5: Nb Suggestions | E5: Taux Participation Enq. (%) | F5: Nb Départs Volontaires | G5: Taux Rotation (%) | H5: Nb Absences | I5: Score Climat Social (/5) | J5: Tendance | K5: Observations
A6: Cuisine & Restauration | B6: 2 | C6: =IF(A6="","",IFERROR(AVERAGEIF('F01 - _Données Collaborateurs'!$D$6:$D$20,A6,'F01 - _Données Collaborateurs'!$F$6:$F$20),0)) | D6: =IF(A6="","",IFERROR(COUNTIF('F08 - 6-Boîte à Idées'!$C$6:$C$115,A6),0)) | F6: =IF(A6="","",IFERROR(F6/B6*100,0)) | G6: =IF(A6="","",IFERROR(F6/B6*100,0)) | H6: 3 | K6: Bonne dynamique d'équipe
A7: Informatique | B7: 1 | C7: =IF(A7="","",IFERROR(AVERAGEIF('F01 - _Données Collaborateurs'!$D$6:$D$20,A7,'F01 - _Données Collaborateurs'!$F$6:$F$20),0)) | D7: =IF(A7="","",IFERROR(COUNTIF('F08 - 6-Boîte à Idées'!$C$6:$C$115,A7),0)) | F7: =IF(A7="","",IFERROR(F7/B7*100,0)) | G7: =IF(A7="","",IFERROR(F7/B7*100,0)) | H7: 1 | K7: Collaborateur très engagé
A8: Marketing & Communication | B8: 1 | C8: =IF(A8="","",IFERROR(AVERAGEIF('F01 - _Données Collaborateurs'!$D$6:$D$20,A8,'F01 - _Données Collaborateurs'!$F$6:$F$20),0)) | D8: =IF(A8="","",IFERROR(COUNTIF('F08 - 6-Boîte à Idées'!$C$6:$C$115,A8),0)) | F8: =IF(A8="","",IFERROR(F8/B8*100,0)) | G8: =IF(A8="","",IFERROR(F8/B8*100,0)) | H8: 2 | K8: Score communication attendu élevé
A9: Finance & Comptabilité | B9: 1 | C9: =IF(A9="","",IFERROR(AVERAGEIF('F01 - _Données Collaborateurs'!$D$6:$D$20,A9,'F01 - _Données Collaborateurs'!$F$6:$F$20),0)) | D9: =IF(A9="","",IFERROR(COUNTIF('F08 - 6-Boîte à Idées'!$C$6:$C$115,A9),0)) | F9: =IF(A9="","",IFERROR(F9/B9*100,0)) | G9: =IF(A9="","",IFERROR(F9/B9*100,0)) | H9: 4 | K9: Départ à analyser
A10: Réception & Front Office | B10: 1 | C10: =IF(A10="","",IFERROR(AVERAGEIF('F01 - _Données Collaborateurs'!$D$6:$D$20,A10,'F01 - _Données Collaborateurs'!$F$6:$F$20),0)) | D10: =IF(A10="","",IFERROR(COUNTIF('F08 - 6-Boîte à Idées'!$C$6:$C$115,A10),0)) | F10: =IF(A10="","",IFERROR(F10/B10*100,0)) | G10: =IF(A10="","",IFERROR(F10/B10*100,0)) | H10: 1 | K10: Ambassadrice de l'engagement
A11: Hébergement | B11: 1 | C11: =IF(A11="","",IFERROR(AVERAGEIF('F01 - _Données Collaborateurs'!$D$6:$D$20,A11,'F01 - _Données Collaborateurs'!$F$6:$F$20),0)) | D11: =IF(A11="","",IFERROR(COUNTIF('F08 - 6-Boîte à Idées'!$C$6:$C$115,A11),0)) | F11: =IF(A11="","",IFERROR(F11/B11*100,0)) | G11: =IF(A11="","",IFERROR(F11/B11*100,0)) | H11: 2 | K11: Excellente gouvernante
A12: Entretien & Maintenance | B12: 1 | C12: =IF(A12="","",IFERROR(AVERAGEIF('F01 - _Données Collaborateurs'!$D$6:$D$20,A12,'F01 - _Données Collaborateurs'!$F$6:$F$20),0)) | D12: =IF(A12="","",IFERROR(COUNTIF('F08 - 6-Boîte à Idées'!$C$6:$C$115,A12),0)) | F12: =IF(A12="","",IFERROR(F12/B12*100,0)) | G12: =IF(A12="","",IFERROR(F12/B12*100,0)) | H12: 6 | K12: Département à surveiller
A13: Ressources Humaines | B13: 1 | C13: =IF(A13="","",IFERROR(AVERAGEIF('F01 - _Données Collaborateurs'!$D$6:$D$20,A13,'F01 - _Données Collaborateurs'!$F$6:$F$20),0)) | D13: =IF(A13="","",IFERROR(COUNTIF('F08 - 6-Boîte à Idées'!$C$6:$C$115,A13),0)) | F13: =IF(A13="","",IFERROR(F13/B13*100,0)) | G13: =IF(A13="","",IFERROR(F13/B13*100,0)) | H13: 1 | K13: Référent engagement
A14: Commercial | B14: 1 | C14: =IF(A14="","",IFERROR(AVERAGEIF('F01 - _Données Collaborateurs'!$D$6:$D$20,A14,'F01 - _Données Collaborateurs'!$F$6:$F$20),0)) | D14: =IF(A14="","",IFERROR(COUNTIF('F08 - 6-Boîte à Idées'!$C$6:$C$115,A14),0)) | F14: =IF(A14="","",IFERROR(F14/B14*100,0)) | G14: =IF(A14="","",IFERROR(F14/B14*100,0)) | H14: 3 | K14: Stable
A15: Sécurité | B15: 1 | C15: =IF(A15="","",IFERROR(AVERAGEIF('F01 - _Données Collaborateurs'!$D$6:$D$20,A15,'F01 - _Données Collaborateurs'!$F$6:$F$20),0)) | D15: =IF(A15="","",IFERROR(COUNTIF('F08 - 6-Boîte à Idées'!$C$6:$C$115,A15),0)) | F15: =IF(A15="","",IFERROR(F15/B15*100,0)) | G15: =IF(A15="","",IFERROR(F15/B15*100,0)) | H15: 5 | K15: Rotation élevée à analyser
C16: =IF(A16="","",IFERROR(AVERAGEIF('F01 - _Données Collaborateurs'!$D$6:$D$20,A16,'F01 - _Données Collaborateurs'!$F$6:$F$20),0)) | D16: =IF(A16="","",IFERROR(COUNTIF('F08 - 6-Boîte à Idées'!$C$6:$C$115,A16),0)) | F16: =IF(A16="","",IFERROR(F16/B16*100,0)) | G16: =IF(A16="","",IFERROR(F16/B16*100,0))
C17: =IF(A17="","",IFERROR(AVERAGEIF('F01 - _Données Collaborateurs'!$D$6:$D$20,A17,'F01 - _Données Collaborateurs'!$F$6:$F$20),0)) | D17: =IF(A17="","",IFERROR(COUNTIF('F08 - 6-Boîte à Idées'!$C$6:$C$115,A17),0)) | F17: =IF(A17="","",IFERROR(F17/B17*100,0)) | G17: =IF(A17="","",IFERROR(F17/B17*100,0))
C18: =IF(A18="","",IFERROR(AVERAGEIF('F01 - _Données Collaborateurs'!$D$6:$D$20,A18,'F01 - _Données Collaborateurs'!$F$6:$F$20),0)) | D18: =IF(A18="","",IFERROR(COUNTIF('F08 - 6-Boîte à Idées'!$C$6:$C$115,A18),0)) | F18: =IF(A18="","",IFERROR(F18/B18*100,0)) | G18: =IF(A18="","",IFERROR(F18/B18*100,0))
C19: =IF(A19="","",IFERROR(AVERAGEIF('F01 - _Données Collaborateurs'!$D$6:$D$20,A19,'F01 - _Données Collaborateurs'!$F$6:$F$20),0)) | D19: =IF(A19="","",IFERROR(COUNTIF('F08 - 6-Boîte à Idées'!$C$6:$C$115,A19),0)) | F19: =IF(A19="","",IFERROR(F19/B19*100,0)) | G19: =IF(A19="","",IFERROR(F19/B19*100,0))
C20: =IF(A20="","",IFERROR(AVERAGEIF('F01 - _Données Collaborateurs'!$D$6:$D$20,A20,'F01 - _Données Collaborateurs'!$F$6:$F$20),0)) | D20: =IF(A20="","",IFERROR(COUNTIF('F08 - 6-Boîte à Idées'!$C$6:$C$115,A20),0)) | F20: =IF(A20="","",IFERROR(F20/B20*100,0)) | G20: =IF(A20="","",IFERROR(F20/B20*100,0))
C21: =IF(A21="","",IFERROR(AVERAGEIF('F01 - _Données Collaborateurs'!$D$6:$D$20,A21,'F01 - _Données Collaborateurs'!$F$6:$F$20),0)) | D21: =IF(A21="","",IFERROR(COUNTIF('F08 - 6-Boîte à Idées'!$C$6:$C$115,A21),0)) | F21: =IF(A21="","",IFERROR(F21/B21*100,0)) | G21: =IF(A21="","",IFERROR(F21/B21*100,0))
C22: =IF(A22="","",IFERROR(AVERAGEIF('F01 - _Données Collaborateurs'!$D$6:$D$20,A22,'F01 - _Données Collaborateurs'!$F$6:$F$20),0)) | D22: =IF(A22="","",IFERROR(COUNTIF('F08 - 6-Boîte à Idées'!$C$6:$C$115,A22),0)) | F22: =IF(A22="","",IFERROR(F22/B22*100,0)) | G22: =IF(A22="","",IFERROR(F22/B22*100,0))
C23: =IF(A23="","",IFERROR(AVERAGEIF('F01 - _Données Collaborateurs'!$D$6:$D$20,A23,'F01 - _Données Collaborateurs'!$F$6:$F$20),0)) | D23: =IF(A23="","",IFERROR(COUNTIF('F08 - 6-Boîte à Idées'!$C$6:$C$115,A23),0)) | F23: =IF(A23="","",IFERROR(F23/B23*100,0)) | G23: =IF(A23="","",IFERROR(F23/B23*100,0))
C24: =IF(A24="","",IFERROR(AVERAGEIF('F01 - _Données Collaborateurs'!$D$6:$D$20,A24,'F01 - _Données Collaborateurs'!$F$6:$F$20),0)) | D24: =IF(A24="","",IFERROR(COUNTIF('F08 - 6-Boîte à Idées'!$C$6:$C$115,A24),0)) | F24: =IF(A24="","",IFERROR(F24/B24*100,0)) | G24: =IF(A24="","",IFERROR(F24/B24*100,0))
C25: =IF(A25="","",IFERROR(AVERAGEIF('F01 - _Données Collaborateurs'!$D$6:$D$20,A25,'F01 - _Données Collaborateurs'!$F$6:$F$20),0)) | D25: =IF(A25="","",IFERROR(COUNTIF('F08 - 6-Boîte à Idées'!$C$6:$C$115,A25),0)) | F25: =IF(A25="","",IFERROR(F25/B25*100,0)) | G25: =IF(A25="","",IFERROR(F25/B25*100,0))
C26: =IF(A26="","",IFERROR(AVERAGEIF('F01 - _Données Collaborateurs'!$D$6:$D$20,A26,'F01 - _Données Collaborateurs'!$F$6:$F$20),0)) | D26: =IF(A26="","",IFERROR(COUNTIF('F08 - 6-Boîte à Idées'!$C$6:$C$115,A26),0)) | F26: =IF(A26="","",IFERROR(F26/B26*100,0)) | G26: =IF(A26="","",IFERROR(F26/B26*100,0))
C27: =IF(A27="","",IFERROR(AVERAGEIF('F01 - _Données Collaborateurs'!$D$6:$D$20,A27,'F01 - _Données Collaborateurs'!$F$6:$F$20),0)) | D27: =IF(A27="","",IFERROR(COUNTIF('F08 - 6-Boîte à Idées'!$C$6:$C$115,A27),0)) | F27: =IF(A27="","",IFERROR(F27/B27*100,0)) | G27: =IF(A27="","",IFERROR(F27/B27*100,0))
... C115: =IF(A115="","",IFERROR(AVERAGEIF('F01 - _Données Collaborateurs'!$D$6:$D$20,A115,'F01 - _Données Collaborateurs'!$F$6:$F$20),0)) | D115: =IF(A115="","",IFERROR(COUNTIF('F08 - 6-Boîte à Idées'!$C$6:$C$115,A115),0)) | F115: =IF(A115="","",IFERROR(F115/B115*100,0)) | G115: =IF(A115="","",IFERROR(F115/B115*100,0))

Sheet F11 - 9-Actions Amélior. QVT
A2: 9-ACTIONS D'AMÉLIORATION QVT
A3: TABLEAU DYNAMIQUE — Saisissez dans la zone prévue ci-dessous
A5: Code Action | B5: Action | C5: Département Concerné | D5: Origine | E5: Priorité | F5: Responsable | G5: Date Lancement | H5: Date Échéance | I5: Budget (FCFA) | J5: Statut | K5: Impact Mesuré | L5: Observations
A6: =IF(B6="","",IF(COUNTA($A$6:A6)=0,"QVT-"&TEXT(COUNTA($B$6:B6),"000"),"QVT-"&TEXT(ROW()-5,"000"))) | B6: Aménager espace de repos équipe cuisine | C6: Cuisine & Restauration | D6: Enquête engagement | E6: Haute | F6: DRH / Chef Cuisinier | G6: 45689 | H6: 45747 | I6: 500000 | J6: En cours | K6: Satisfaction +12% cuisine | L6: Travaux en cours
A7: =IF(B7="","",IF(COUNTA($A$6:A7)=0,"QVT-"&TEXT(COUNTA($B$6:B7),"000"),"QVT-"&TEXT(ROW()-5,"000"))) | B7: Programme reconnaissance mensuelle | C7: Tous | D7: Direction | E7: Haute | F7: DRH | G7: 45717 | H7: 46022 | I7: 600000 | J7: En cours | K7: Engagement +5% global | L7: 1er prix décerné mars
A8: =IF(B8="","",IF(COUNTA($A$6:A8)=0,"QVT-"&TEXT(COUNTA($B$6:B8),"000"),"QVT-"&TEXT(ROW()-5,"000"))) | B8: Formation gestion du stress | C8: Hébergement | D8: Entretien individuel | E8: Moyenne | F8: DRH | G8: 45762 | H8: 45777 | I8: 150000 | J8: Planifié | L8: Intervenant psychologue confirmé
A9: =IF(B9="","",IF(COUNTA($A$6:A9)=0,"QVT-"&TEXT(COUNTA($B$6:B9),"000"),"QVT-"&TEXT(ROW()-5,"000"))) | B9: Horaires flexibles vendredi entretien | C9: Entretien & Maintenance | D9: Suggestion collaborateur | E9: Moyenne | F9: DRH / Chef Entretien | G9: 45731 | H9: 45838 | I9: 0 | J9: En cours | K9: Absentéisme -20% | L9: Test sur 3 mois
A10: =IF(B10="","",IF(COUNTA($A$6:A10)=0,"QVT-"&TEXT(COUNTA($B$6:B10),"000"),"QVT-"&TEXT(ROW()-5,"000"))) | B10: Mise en place télétravail partiel DSI | C10: Informatique | D10: Enquête QVT | E10: Basse | F10: DSI / DRH | G10: 45778 | H10: 45900 | I10: 200000 | J10: Planifié | L10: Étude juridique en cours
A11: =IF(B11="","",IF(COUNTA($A$6:A11)=0,"QVT-"&TEXT(COUNTA($B$6:B11),"000"),"QVT-"&TEXT(ROW()-5,"000")))
A12: =IF(B12="","",IF(COUNTA($A$6:A12)=0,"QVT-"&TEXT(COUNTA($B$6:B12),"000"),"QVT-"&TEXT(ROW()-5,"000")))
A13: =IF(B13="","",IF(COUNTA($A$6:A13)=0,"QVT-"&TEXT(COUNTA($B$6:B13),"000"),"QVT-"&TEXT(ROW()-5,"000")))
A14: =IF(B14="","",IF(COUNTA($A$6:A14)=0,"QVT-"&TEXT(COUNTA($B$6:B14),"000"),"QVT-"&TEXT(ROW()-5,"000")))
A15: =IF(B15="","",IF(COUNTA($A$6:A15)=0,"QVT-"&TEXT(COUNTA($B$6:B15),"000"),"QVT-"&TEXT(ROW()-5,"000")))
A16: =IF(B16="","",IF(COUNTA($A$6:A16)=0,"QVT-"&TEXT(COUNTA($B$6:B16),"000"),"QVT-"&TEXT(ROW()-5,"000")))
A17: =IF(B17="","",IF(COUNTA($A$6:A17)=0,"QVT-"&TEXT(COUNTA($B$6:B17),"000"),"QVT-"&TEXT(ROW()-5,"000")))
A18: =IF(B18="","",IF(COUNTA($A$6:A18)=0,"QVT-"&TEXT(COUNTA($B$6:B18),"000"),"QVT-"&TEXT(ROW()-5,"000")))
A19: =IF(B19="","",IF(COUNTA($A$6:A19)=0,"QVT-"&TEXT(COUNTA($B$6:B19),"000"),"QVT-"&TEXT(ROW()-5,"000")))
A20: =IF(B20="","",IF(COUNTA($A$6:A20)=0,"QVT-"&TEXT(COUNTA($B$6:B20),"000"),"QVT-"&TEXT(ROW()-5,"000")))
A21: =IF(B21="","",IF(COUNTA($A$6:A21)=0,"QVT-"&TEXT(COUNTA($B$6:B21),"000"),"QVT-"&TEXT(ROW()-5,"000")))
A22: =IF(B22="","",IF(COUNTA($A$6:A22)=0,"QVT-"&TEXT(COUNTA($B$6:B22),"000"),"QVT-"&TEXT(ROW()-5,"000")))
... A115: =IF(B115="","",IF(COUNTA($A$6:A115)=0,"QVT-"&TEXT(COUNTA($B$6:B115),"000"),"QVT-"&TEXT(ROW()-5,"000")))

Sheet F12 - 10-Gest. Rumeurs Alertes
A2: 10-GESTION DES RUMEURS ET ALERTES
A3: TABLEAU DYNAMIQUE — Saisissez dans la zone prévue ci-dessous
A5: Code Alerte | B5: Type | C5: Niveau | D5: Source | E5: Date Détection | F5: Description | G5: Département Concerné | H5: Action Menee | I5: Date Résolution | J5: Statut | K5: Impact | L5: Observations
A6: =IF(B6="","",IF(COUNTA($A$6:A6)=0,"ALR-"&TEXT(COUNTA($B$6:B6),"000"),"ALR-"&TEXT(ROW()-5,"000"))) | B6: Rumeur | C6: Moyen | D6: Boîte à idées anonyme | E6: 45672 | F6: Rumeur de licenciements massifs en cuisine | G6: Cuisine & Restauration | H6: Communication officielle DG | I6: 45674 | J6: Résolu | K6: Faible | L6: Communiqué interne diffusé rapidement
A7: =IF(B7="","",IF(COUNTA($A$6:A7)=0,"ALR-"&TEXT(COUNTA($B$6:B7),"000"),"ALR-"&TEXT(ROW()-5,"000"))) | B7: Mécontentement | C7: Élevé | D7: Entretien manager | E7: 45689 | F7: Mécontentement équipe entretien sur les horaires | G7: Entretien & Maintenance | H7: Réunion d'équipe + révision planning | I7: 45703 | J7: Résolu | K7: Modéré | L7: Nouveau planning mis en place
A8: =IF(B8="","",IF(COUNTA($A$6:A8)=0,"ALR-"&TEXT(COUNTA($B$6:B8),"000"),"ALR-"&TEXT(ROW()-5,"000"))) | B8: Risque départ | C8: Élevé | D8: Entretien individuel | E8: 45698 | F8: Risque de départ gouvernante (opportunité concurrent) | G8: Hébergement | H8: Contre-proposition + reconnaissance | J8: En cours | K8: Élevé | L8: Suivi hebdomadaire mis en place
A9: =IF(B9="","",IF(COUNTA($A$6:A9)=0,"ALR-"&TEXT(COUNTA($B$6:B9),"000"),"ALR-"&TEXT(ROW()-5,"000"))) | B9: Tension interne | C9: Moyen | D9: Observation DRH | E9: 45708 | F9: Tension entre équipe sécurité et réception de nuit | G9: Sécurité | H9: Médiation DRH prévue | J9: En cours | K9: Modéré | L9: Réunion tripartite programmée
A10: =IF(B10="","",IF(COUNTA($A$6:A10)=0,"ALR-"&TEXT(COUNTA($B$6:B10),"000"),"ALR-"&TEXT(ROW()-5,"000")))
A11: =IF(B11="","",IF(COUNTA($A$6:A11)=0,"ALR-"&TEXT(COUNTA($B$6:B11),"000"),"ALR-"&TEXT(ROW()-5,"000")))
A12: =IF(B12="","",IF(COUNTA($A$6:A12)=0,"ALR-"&TEXT(COUNTA($B$6:B12),"000"),"ALR-"&TEXT(ROW()-5,"000")))
A13: =IF(B13="","",IF(COUNTA($A$6:A13)=0,"ALR-"&TEXT(COUNTA($B$6:B13),"000"),"ALR-"&TEXT(ROW()-5,"000")))
A14: =IF(B14="","",IF(COUNTA($A$6:A14)=0,"ALR-"&TEXT(COUNTA($B$6:B14),"000"),"ALR-"&TEXT(ROW()-5,"000")))
A15: =IF(B15="","",IF(COUNTA($A$6:A15)=0,"ALR-"&TEXT(COUNTA($B$6:B15),"000"),"ALR-"&TEXT(ROW()-5,"000")))
A16: =IF(B16="","",IF(COUNTA($A$6:A16)=0,"ALR-"&TEXT(COUNTA($B$6:B16),"000"),"ALR-"&TEXT(ROW()-5,"000")))
A17: =IF(B17="","",IF(COUNTA($A$6:A17)=0,"ALR-"&TEXT(COUNTA($B$6:B17),"000"),"ALR-"&TEXT(ROW()-5,"000")))
A18: =IF(B18="","",IF(COUNTA($A$6:A18)=0,"ALR-"&TEXT(COUNTA($B$6:B18),"000"),"ALR-"&TEXT(ROW()-5,"000")))
A19: =IF(B19="","",IF(COUNTA($A$6:A19)=0,"ALR-"&TEXT(COUNTA($B$6:B19),"000"),"ALR-"&TEXT(ROW()-5,"000")))
A20: =IF(B20="","",IF(COUNTA($A$6:A20)=0,"ALR-"&TEXT(COUNTA($B$6:B20),"000"),"ALR-"&TEXT(ROW()-5,"000")))
A21: =IF(B21="","",IF(COUNTA($A$6:A21)=0,"ALR-"&TEXT(COUNTA($B$6:B21),"000"),"ALR-"&TEXT(ROW()-5,"000")))
... A115: =IF(B115="","",IF(COUNTA($A$6:A115)=0,"ALR-"&TEXT(COUNTA($B$6:B115),"000"),"ALR-"&TEXT(ROW()-5,"000")))

Sheet F13 - 11-Newsletter Publicat.
A2: 11-NEWSLETTER ET PUBLICATIONS
A3: TABLEAU DYNAMIQUE — Saisissez dans la zone prévue ci-dessous
A5: Code Newsletter | B5: Titre | C5: Date Parution | D5: Périodicité | E5: Nb Pages | F5: Nb Destinataires | G5: Taux Ouverture (%) | H5: Taux Clic (%) | I5: Rédacteur | J5: Statut | K5: Thème Principal | L5: Observations
A6: =IF(B6="","",IF(COUNTA($A$6:A6)=0,"NWL-"&TEXT(COUNTA($B$6:B6),"000"),"NWL-"&TEXT(ROW()-5,"000"))) | B6: L'Essentiel - Janvier 2025 | C6: 45672 | D6: Mensuelle | E6: 4 | F6: 63 | G6: 68 | H6: 12 | I6: Resp. Marketing | J6: Diffusé | K6: Bilan 2024 et objectifs 2025 | L6: Record d'ouverture | M6: =IF(OR(G6="",H6=""),"",IFERROR(H6/G6*100,0)) | N6: =IF(G6="","",IF(G6>=65,"Excellente",IF(G6>=55,"Bonne",IF(G6>=45,"Correcte","Faible"))))
A7: =IF(B7="","",IF(COUNTA($A$6:A7)=0,"NWL-"&TEXT(COUNTA($B$6:B7),"000"),"NWL-"&TEXT(ROW()-5,"000"))) | B7: L'Essentiel - Février 2025 | C7: 45703 | D7: Mensuelle | E7: 3 | F7: 64 | G7: 62 | H7: 10 | I7: Resp. Marketing | J7: Diffusé | K7: Célébrations succès équipe | M7: =IF(OR(G7="",H7=""),"",IFERROR(H7/G7*100,0)) | N7: =IF(G7="","",IF(G7>=65,"Excellente",IF(G7>=55,"Bonne",IF(G7>=45,"Correcte","Faible"))))
A8: =IF(B8="","",IF(COUNTA($A$6:A8)=0,"NWL-"&TEXT(COUNTA($B$6:B8),"000"),"NWL-"&TEXT(ROW()-5,"000"))) | B8: L'Essentiel - Mars 2025 | C8: 45731 | D8: Mensuelle | E8: 4 | F8: 65 | I8: Resp. Marketing | J8: En revue | K8: Journée internationale de la femme | L8: Dossier spécial prévu | M8: =IF(OR(G8="",H8=""),"",IFERROR(H8/G8*100,0)) | N8: =IF(G8="","",IF(G8>=65,"Excellente",IF(G8>=55,"Bonne",IF(G8>=45,"Correcte","Faible"))))
A9: =IF(B9="","",IF(COUNTA($A$6:A9)=0,"NWL-"&TEXT(COUNTA($B$6:B9),"000"),"NWL-"&TEXT(ROW()-5,"000"))) | B9: L'Essentiel - Avril 2025 | D9: Mensuelle | I9: Resp. Marketing | J9: Brouillon | K9: QVT et bien-être au travail | M9: =IF(OR(G9="",H9=""),"",IFERROR(H9/G9*100,0)) | N9: =IF(G9="","",IF(G9>=65,"Excellente",IF(G9>=55,"Bonne",IF(G9>=45,"Correcte","Faible"))))
A10: =IF(B10="","",IF(COUNTA($A$6:A10)=0,"NWL-"&TEXT(COUNTA($B$6:B10),"000"),"NWL-"&TEXT(ROW()-5,"000"))) | M10: =IF(OR(G10="",H10=""),"",IFERROR(H10/G10*100,0)) | N10: =IF(G10="","",IF(G10>=65,"Excellente",IF(G10>=55,"Bonne",IF(G10>=45,"Correcte","Faible"))))
A11: =IF(B11="","",IF(COUNTA($A$6:A11)=0,"NWL-"&TEXT(COUNTA($B$6:B11),"000"),"NWL-"&TEXT(ROW()-5,"000"))) | M11: =IF(OR(G11="",H11=""),"",IFERROR(H11/G11*100,0)) | N11: =IF(G11="","",IF(G11>=65,"Excellente",IF(G11>=55,"Bonne",IF(G11>=45,"Correcte","Faible"))))
A12: =IF(B12="","",IF(COUNTA($A$6:A12)=0,"NWL-"&TEXT(COUNTA($B$6:B12),"000"),"NWL-"&TEXT(ROW()-5,"000"))) | M12: =IF(OR(G12="",H12=""),"",IFERROR(H12/G12*100,0)) | N12: =IF(G12="","",IF(G12>=65,"Excellente",IF(G12>=55,"Bonne",IF(G12>=45,"Correcte","Faible"))))
A13: =IF(B13="","",IF(COUNTA($A$6:A13)=0,"NWL-"&TEXT(COUNTA($B$6:B13),"000"),"NWL-"&TEXT(ROW()-5,"000"))) | M13: =IF(OR(G13="",H13=""),"",IFERROR(H13/G13*100,0)) | N13: =IF(G13="","",IF(G13>=65,"Excellente",IF(G13>=55,"Bonne",IF(G13>=45,"Correcte","Faible"))))
A14: =IF(B14="","",IF(COUNTA($A$6:A14)=0,"NWL-"&TEXT(COUNTA($B$6:B14),"000"),"NWL-"&TEXT(ROW()-5,"000"))) | M14: =IF(OR(G14="",H14=""),"",IFERROR(H14/G14*100,0)) | N14: =IF(G14="","",IF(G14>=65,"Excellente",IF(G14>=55,"Bonne",IF(G14>=45,"Correcte","Faible"))))
A15: =IF(B15="","",IF(COUNTA($A$6:A15)=0,"NWL-"&TEXT(COUNTA($B$6:B15),"000"),"NWL-"&TEXT(ROW()-5,"000"))) | M15: =IF(OR(G15="",H15=""),"",IFERROR(H15/G15*100,0)) | N15: =IF(G15="","",IF(G15>=65,"Excellente",IF(G15>=55,"Bonne",IF(G15>=45,"Correcte","Faible"))))
A16: =IF(B16="","",IF(COUNTA($A$6:A16)=0,"NWL-"&TEXT(COUNTA($B$6:B16),"000"),"NWL-"&TEXT(ROW()-5,"000"))) | M16: =IF(OR(G16="",H16=""),"",IFERROR(H16/G16*100,0)) | N16: =IF(G16="","",IF(G16>=65,"Excellente",IF(G16>=55,"Bonne",IF(G16>=45,"Correcte","Faible"))))
A17: =IF(B17="","",IF(COUNTA($A$6:A17)=0,"NWL-"&TEXT(COUNTA($B$6:B17),"000"),"NWL-"&TEXT(ROW()-5,"000"))) | M17: =IF(OR(G17="",H17=""),"",IFERROR(H17/G17*100,0)) | N17: =IF(G17="","",IF(G17>=65,"Excellente",IF(G17>=55,"Bonne",IF(G17>=45,"Correcte","Faible"))))
A18: =IF(B18="","",IF(COUNTA($A$6:A18)=0,"NWL-"&TEXT(COUNTA($B$6:B18),"000"),"NWL-"&TEXT(ROW()-5,"000"))) | M18: =IF(OR(G18="",H18=""),"",IFERROR(H18/G18*100,0)) | N18: =IF(G18="","",IF(G18>=65,"Excellente",IF(G18>=55,"Bonne",IF(G18>=45,"Correcte","Faible"))))
A19: =IF(B19="","",IF(COUNTA($A$6:A19)=0,"NWL-"&TEXT(COUNTA($B$6:B19),"000"),"NWL-"&TEXT(ROW()-5,"000"))) | M19: =IF(OR(G19="",H19=""),"",IFERROR(H19/G19*100,0)) | N19: =IF(G19="","",IF(G19>=65,"Excellente",IF(G19>=55,"Bonne",IF(G19>=45,"Correcte","Faible"))))
A20: =IF(B20="","",IF(COUNTA($A$6:A20)=0,"NWL-"&TEXT(COUNTA($B$6:B20),"000"),"NWL-"&TEXT(ROW()-5,"000"))) | M20: =IF(OR(G20="",H20=""),"",IFERROR(H20/G20*100,0)) | N20: =IF(G20="","",IF(G20>=65,"Excellente",IF(G20>=55,"Bonne",IF(G20>=45,"Correcte","Faible"))))
A21: =IF(B21="","",IF(COUNTA($A$6:A21)=0,"NWL-"&TEXT(COUNTA($B$6:B21),"000"),"NWL-"&TEXT(ROW()-5,"000"))) | M21: =IF(OR(G21="",H21=""),"",IFERROR(H21/G21*100,0)) | N21: =IF(G21="","",IF(G21>=65,"Excellente",IF(G21>=55,"Bonne",IF(G21>=45,"Correcte","Faible"))))
... A115: =IF(B115="","",IF(COUNTA($A$6:A115)=0,"NWL-"&TEXT(COUNTA($B$6:B115),"000"),"NWL-"&TEXT(ROW()-5,"000"))) | M115: =IF(OR(G115="",H115=""),"",IFERROR(H115/G115*100,0)) | N115: =IF(G115="","",IF(G115>=65,"Excellente",IF(G115>=55,"Bonne",IF(G115>=45,"Correcte","Faible"))))

Sheet F14 - 12-Comité Vie Sociale
A2: 12-COMITÉ DE VIE SOCIALE (CVS)
A3: TABLEAU DYNAMIQUE — Saisissez dans la zone prévue ci-dessous
A5: Code Réunion | B5: Date Réunion | C5: Type Réunion | D5: Nb Participants | E5: Ordre du Jour | F5: Décisions Prises | G5: Actions à Suivre | H5: Budget Discuté (FCFA) | I5: Prochaine Réunion | J5: Observations
A6: =IF(B6="","",IF(COUNTA($A$6:A6)=0,"CVS-"&TEXT(COUNTA($B$6:B6),"000"),"CVS-"&TEXT(ROW()-5,"000"))) | B6: 45677 | C6: Ordinaire | D6: 12 | E6: Bilan activités sociales Q4 2024, budget 2025 | F6: Validation budget 2M FCFA, 4 événements Q1 | G6: Programmer soirée iftar, préparer tournoi sport | H6: 500000 | I6: 45708 | J6: Quorum atteint, vote unanime | L6: =IF(B6="","",IFERROR(H6/1000000*100,0)) | M6: =IF(I6="","",IFERROR(I6-B6,0))
A7: =IF(B7="","",IF(COUNTA($A$6:A7)=0,"CVS-"&TEXT(COUNTA($B$6:B7),"000"),"CVS-"&TEXT(ROW()-5,"000"))) | B7: 45708 | C7: Extraordinaire | D7: 10 | E7: Aménagement espace repos, demande équipe cuisine | F7: Validation aménagement espace repos | G7: Demander devis travaux, prévoir inauguration mars | H7: 500000 | I7: 45736 | J7: Réunion urgente suite demande | L7: =IF(B7="","",IFERROR(H7/1000000*100,0)) | M7: =IF(I7="","",IFERROR(I7-B7,0))
A8: =IF(B8="","",IF(COUNTA($A$6:A8)=0,"CVS-"&TEXT(COUNTA($B$6:B8),"000"),"CVS-"&TEXT(ROW()-5,"000"))) | B8: 45736 | C8: Ordinaire | D8: 11 | E8: Bilan Q1, organisation fête fin d'année scolaire | F8: Validation fête scolaire, budget sorties famille | G8: Organiser sortie famille avril, réserver lieu | H8: 300000 | I8: 45767 | L8: =IF(B8="","",IFERROR(H8/1000000*100,0)) | M8: =IF(I8="","",IFERROR(I8-B8,0))
A9: =IF(B9="","",IF(COUNTA($A$6:A9)=0,"CVS-"&TEXT(COUNTA($B$6:B9),"000"),"CVS-"&TEXT(ROW()-5,"000"))) | L9: =IF(B9="","",IFERROR(H9/1000000*100,0)) | M9: =IF(I9="","",IFERROR(I9-B9,0))
A10: =IF(B10="","",IF(COUNTA($A$6:A10)=0,"CVS-"&TEXT(COUNTA($B$6:B10),"000"),"CVS-"&TEXT(ROW()-5,"000"))) | L10: =IF(B10="","",IFERROR(H10/1000000*100,0)) | M10: =IF(I10="","",IFERROR(I10-B10,0))
A11: =IF(B11="","",IF(COUNTA($A$6:A11)=0,"CVS-"&TEXT(COUNTA($B$6:B11),"000"),"CVS-"&TEXT(ROW()-5,"000"))) | L11: =IF(B11="","",IFERROR(H11/1000000*100,0)) | M11: =IF(I11="","",IFERROR(I11-B11,0))
A12: =IF(B12="","",IF(COUNTA($A$6:A12)=0,"CVS-"&TEXT(COUNTA($B$6:B12),"000"),"CVS-"&TEXT(ROW()-5,"000"))) | L12: =IF(B12="","",IFERROR(H12/1000000*100,0)) | M12: =IF(I12="","",IFERROR(I12-B12,0))
A13: =IF(B13="","",IF(COUNTA($A$6:A13)=0,"CVS-"&TEXT(COUNTA($B$6:B13),"000"),"CVS-"&TEXT(ROW()-5,"000"))) | L13: =IF(B13="","",IFERROR(H13/1000000*100,0)) | M13: =IF(I13="","",IFERROR(I13-B13,0))
A14: =IF(B14="","",IF(COUNTA($A$6:A14)=0,"CVS-"&TEXT(COUNTA($B$6:B14),"000"),"CVS-"&TEXT(ROW()-5,"000"))) | L14: =IF(B14="","",IFERROR(H14/1000000*100,0)) | M14: =IF(I14="","",IFERROR(I14-B14,0))
A15: =IF(B15="","",IF(COUNTA($A$6:A15)=0,"CVS-"&TEXT(COUNTA($B$6:B15),"000"),"CVS-"&TEXT(ROW()-5,"000"))) | L15: =IF(B15="","",IFERROR(H15/1000000*100,0)) | M15: =IF(I15="","",IFERROR(I15-B15,0))
A16: =IF(B16="","",IF(COUNTA($A$6:A16)=0,"CVS-"&TEXT(COUNTA($B$6:B16),"000"),"CVS-"&TEXT(ROW()-5,"000"))) | L16: =IF(B16="","",IFERROR(H16/1000000*100,0)) | M16: =IF(I16="","",IFERROR(I16-B16,0))
A17: =IF(B17="","",IF(COUNTA($A$6:A17)=0,"CVS-"&TEXT(COUNTA($B$6:B17),"000"),"CVS-"&TEXT(ROW()-5,"000"))) | L17: =IF(B17="","",IFERROR(H17/1000000*100,0)) | M17: =IF(I17="","",IFERROR(I17-B17,0))
A18: =IF(B18="","",IF(COUNTA($A$6:A18)=0,"CVS-"&TEXT(COUNTA($B$6:B18),"000"),"CVS-"&TEXT(ROW()-5,"000"))) | L18: =IF(B18="","",IFERROR(H18/1000000*100,0)) | M18: =IF(I18="","",IFERROR(I18-B18,0))
A19: =IF(B19="","",IF(COUNTA($A$6:A19)=0,"CVS-"&TEXT(COUNTA($B$6:B19),"000"),"CVS-"&TEXT(ROW()-5,"000"))) | L19: =IF(B19="","",IFERROR(H19/1000000*100,0)) | M19: =IF(I19="","",IFERROR(I19-B19,0))
A20: =IF(B20="","",IF(COUNTA($A$6:A20)=0,"CVS-"&TEXT(COUNTA($B$6:B20),"000"),"CVS-"&TEXT(ROW()-5,"000"))) | L20: =IF(B20="","",IFERROR(H20/1000000*100,0)) | M20: =IF(I20="","",IFERROR(I20-B20,0))
... A115: =IF(B115="","",IF(COUNTA($A$6:A115)=0,"CVS-"&TEXT(COUNTA($B$6:B115),"000"),"CVS-"&TEXT(ROW()-5,"000"))) | L115: =IF(B115="","",IFERROR(H115/1000000*100,0)) | M115: =IF(I115="","",IFERROR(I115-B115,0))

Sheet F15 - 13-Budget Communication
A2: 13-BUDGET COMMUNICATION INTERNE
A3: TABLEAU DYNAMIQUE — Saisissez dans la zone prévue ci-dessous
A5: Poste Budgétaire | B5: Trimestre | C5: Budget Prévu (FCFA) | D5: Dépenses Réalisées (FCFA) | E5: Engagé (FCFA) | F5: Reste à Engager (FCFA) | G5: Taux Consommation (%) | H5: Écart (FCFA) | I5: Observations
