Workbook

Sheet F01 - _Données Centrales
A2: DOMAINE 26 — GESTION BUDGÉTAIRE ET FISCALE DES RH
A3: DONNÉES CENTRALES — Base de référence (toutes les feuilles s'y réfèrent)
A5: Code Budget | B5: Centre de Coût | C5: Département | D5: Rubrique Budgétaire | E5: Nature Comptable | F5: Exercice | G5: Budget Alloué (FCFA) | H5: Budget Consommé (FCFA) | I5: Reste à Consommer (FCFA) | J5: Taux Consommation (%) | K5: Responsable | L5: Statut
A6: BUD-001 | B6: CC-100 | C6: Direction Générale | D6: Masse salariale DG | E6: Charges de personnel | F6: 2025 | G6: 85000000 | H6: 72500000 | I6: =G6-H6 | J6: =IFERROR(H6/G6,0) | K6: M. Nkoulou | L6: En cours
A7: BUD-002 | B7: CC-101 | C7: Ressources Humaines | D7: Masse salariale RH | E7: Charges de personnel | F7: 2025 | G7: 42000000 | H7: 35800000 | I7: =G7-H7 | J7: =IFERROR(H7/G7,0) | K7: Mme. Mbarga | L7: En cours
A8: BUD-003 | B8: CC-102 | C8: Finance & Comptabilité | D8: Masse salariale Fin | E8: Charges de personnel | F8: 2025 | G8: 38000000 | H8: 31200000 | I8: =G8-H8 | J8: =IFERROR(H8/G8,0) | K8: M. Eyenga | L8: En cours
A9: BUD-004 | B9: CC-103 | C9: Cuisine & Restauration | D9: Masse salariale Rest. | E9: Charges de personnel | F9: 2025 | G9: 120000000 | H9: 98500000 | I9: =G9-H9 | J9: =IFERROR(H9/G9,0) | K9: M. Tchinda | L9: En cours
A10: BUD-005 | B10: CC-104 | C10: Réception & Front Office | D10: Masse salariale Récept. | E10: Charges de personnel | F10: 2025 | G10: 65000000 | H10: 54200000 | I10: =G10-H10 | J10: =IFERROR(H10/G10,0) | K10: Mme. Ngassa | L10: En cours
A11: BUD-006 | B11: CC-105 | C11: Maintenance & Technique | D11: Masse salariale Maint. | E11: Charges de personnel | F11: 2025 | G11: 55000000 | H11: 46800000 | I11: =G11-H11 | J11: =IFERROR(H11/G11,0) | K11: M. Ondo | L11: En cours
A12: BUD-007 | B12: CC-200 | C12: Ressources Humaines | D12: Charges patronales | E12: Charges sociales | F12: 2025 | G12: 35000000 | H12: 28500000 | I12: =G12-H12 | J12: =IFERROR(H12/G12,0) | K12: Mme. Mbarga | L12: En cours
A13: BUD-008 | B13: CC-201 | C13: Ressources Humaines | D13: Formation & développement | E13: Charges de formation | F13: 2025 | G13: 15000000 | H13: 8700000 | I13: =G13-H13 | J13: =IFERROR(H13/G13,0) | K13: M. Fotso | L13: En cours
A14: BUD-009 | B14: CC-202 | C14: Ressources Humaines | D14: Recrutement & intégration | E14: Charges recrutement | F14: 2025 | G14: 8000000 | H14: 6200000 | I14: =G14-H14 | J14: =IFERROR(H14/G14,0) | K14: Mme. Essomba | L14: En cours
A15: BUD-010 | B15: CC-203 | C15: Ressources Humaines | D15: Avantages sociaux | E15: Avantages en nature | F15: 2025 | G15: 22000000 | H15: 16400000 | I15: =G15-H15 | J15: =IFERROR(H15/G15,0) | K15: Mme. Mbarga | L15: En cours
A16: BUD-011 | B16: CC-204 | C16: Ressources Humaines | D16: Épargne salariale | E16: Participation/Intéressement | F16: 2025 | G16: 18000000 | H16: 9500000 | I16: =G16-H16 | J16: =IFERROR(H16/G16,0) | K16: M. Eyenga | L16: En cours
A17: BUD-012 | B17: CC-205 | C17: Finance & Comptabilité | D17: Fiscalité salariale | E17: Impôts et taxes | F17: 2025 | G17: 25000000 | H17: 19800000 | I17: =G17-H17 | J17: =IFERROR(H17/G17,0) | K17: M. Eyenga | L17: En cours
... A20: BUD-015 | B20: CC-208 | C20: Tous départements | D20: Mobilité & relocalisation | E20: Charges de mobilité | F20: 2025 | G20: 10000000 | H20: 5400000 | I20: =G20-H20 | J20: =IFERROR(H20/G20,0) | K20: Mme. Essomba | L20: En cours

Sheet F02 - _Lists
A2: DOMAINE 26 — LISTES DE RÉFÉRENCE
A3: Valeurs pour listes déroulantes — Saisissez vos propres valeurs
A5: centres_cout | B5: departements | C5: rubriques_budget | D5: natures_comptables | E5: exercices | F5: statuts_budget | G5: types_charges | H5: regimes_fiscaux | I5: types_impots | J5: periodes | K5: trimestres | L5: mois | M5: priorites | N5: conformites | O5: types_declaration | P5: regimes_tva | Q5: statuts_paiement | R5: categories_rh | S5: tendances | T5: evaluations
A6: CC-100 | B6: Direction Générale | C6: Masse salariale | D6: Charges de personnel | E6: 2024 | F6: En cours | G6: Fixes | H6: Réel normal | I6: IR sur salaires | J6: Janvier | K6: T1 | L6: Janvier | M6: Haute | N6: Conforme | O6: DSF mensuelle | P6: TVA 19,25% | Q6: Payé | R6: Cadres | S6: Hausse | T6: Excellent
A7: CC-101 | B7: Ressources Humaines | C7: Charges patronales | D7: Charges sociales | E7: 2025 | F7: Clôturé | G7: Variables | H7: Réel simplifié | I7: Taxe sur les salaires | J7: Février | K7: T2 | L7: Février | M7: Moyenne | N7: Non conforme | O7: DSF annuelle | P7: TVA 0% | Q7: En attente | R7: Non cadres | S7: Baisse | T7: Très bon
A8: CC-102 | B8: Finance & Comptabilité | C8: Formation & développement | D8: Charges de formation | E8: 2026 | F8: Dépassé | G8: Exceptionnelles | H8: Synthèse | I8: CRDS | J8: Mars | K8: T3 | L8: Mars | M8: Basse | N8: En attente | O8: DSF rectificative | P8: TVA 5,5% | Q8: Partiellement payé | R8: Expatriés | S8: Stable | T8: Bon
A9: CC-103 | B9: Cuisine & Restauration | C9: Recrutement & intégration | D9: Charges recrutement | E9: 2027 | F9: En attente validation | G9: Récurrentes | H9: Régime des micro-entreprises | I9: CSG | J9: Avril | K9: T4 | L9: Avril | M9: Critique | N9: À régulariser | O9: DSN mensuelle | P9: TVA 10% | Q9: Impayé | R9: Stagiaires | S9: En attente | T9: Satisfaisant
A10: CC-104 | B10: Réception & Front Office | C10: Avantages sociaux | D10: Avantages en nature | F10: Reporté | G10: Non récurrentes | H10: Exonération totale | I10: Cotisations ASSEDIC | J10: Mai | L10: Mai | N10: En cours de vérification | O10: TVA mensuelle | P10: Exonéré | Q10: Litige | R10: Temporaires | T10: Insuffisant
A11: CC-105 | B11: Maintenance & Technique | C11: Épargne salariale | D11: Participation/Intéressement | F11: Annulé | H11: Convention fiscale | I11: Cotisations retraite | J11: Juin | L11: Juin | O11: TVA annuelle | P11: Non applicable | Q11: Reporté | R11: Consultants | T11: À améliorer
A12: CC-200 | B12: Marketing & Communication | C12: Fiscalité salariale | D12: Impôts et taxes | I12: Cotisations maladie | J12: Juillet | L12: Juillet | O12: Déclaration IS
A13: CC-201 | B13: Revenue Management | C13: Primes & indemnités | D13: Rémunération accessoire | I13: Cotisations AT/MP | J13: Août | L13: Août | O13: Déclaration TVA CA
A14: CC-202 | B14: Spa & Bien-être | C14: Santé & sécurité | D14: Charges SST | I14: Taxe d'apprentissage | J14: Septembre | L14: Septembre | O14: Liasse fiscale
A15: CC-203 | B15: Sécurité | C15: Mobilité & relocalisation | D15: Charges de mobilité | I15: Versement transport | J15: Octobre | L15: Octobre | O15: IBAN declaration
A16: CC-204 | B16: Commerce | C16: Audit fiscal | I16: Forfait social | J16: Novembre | L16: Novembre
A17: CC-205 | B17: Gouvernance | C17: Reporting budgétaire | I17: Contribution solidarité | J17: Décembre | L17: Décembre
A18: CC-206
A19: CC-207
A20: CC-208

Sheet F03 - 1-Tableau de Bord
A2: DOMAINE 26 — TABLEAU DE BORD SYNTHÉTIQUE
A3: Vue globale du budget RH, fiscalité et écarts
A6: Budget Total Alloué (FCFA) | B6: =SUM('F01 - _Données Centrales'!G6:G20) | C6: Budget Consommé (FCFA) | D6: =SUM('F01 - _Données Centrales'!H6:H20) | E6: Taux Consommation Global | F6: =IFERROR(SUM('F01 - _Données Centrales'!H6:H20)/SUM('F01 - _Données Centrales'!G6:G20),0) | G6: Écart Budgétaire (FCFA) | H6: =SUM('F01 - _Données Centrales'!G6:G20)-SUM('F01 - _Données Centrales'!H6:H20) | I6: Charges Patronales Totales | J6: =SUMIF('F01 - _Données Centrales'!E6:E20,"Charges sociales",'F01 - _Données Centrales'!H6:H20) | K6: Fiscalité Salariale Totale | L6: =SUMIF('F01 - _Données Centrales'!E6:E20,"Impôts et taxes",'F01 - _Données Centrales'!H6:H20)
A9: Nb Rubriques Budgétaires | B9: =COUNTA('F01 - _Données Centrales'!D6:D20) | C9: Rubriques Dépassées | D9: =COUNTIF('F01 - _Données Centrales'!L6:L20,"Dépassé") | E9: Coût Moyen/Département | F9: =IFERROR(SUM('F01 - _Données Centrales'!G6:G20)/COUNTIF('F01 - _Données Centrales'!C6:C20,"<>"&""),0) | G9: Taux Conformité Fiscale | H9: 92% | I9: Déclarations en Retard | J9: 0 | K9: Épargne Salariale Versée | L9: =SUMIF('F01 - _Données Centrales'!E6:E20,"Participation/Intéressement",'F01 - _Données Centrales'!H6:H20)

Sheet F04 - 2-Budget Prévis. Annuel
A2: DOMAINE 26 — 2-BUDGET PRÉVISIONNEL ANNUEL RH
A3: TABLEAU DYNAMIQUE — Saisissez dans la zone prévue ci-dessous
A5: Code Budget | B5: Centre de Coût | C5: Département | D5: Rubrique | E5: Janvier | F5: Février | G5: Mars | H5: T1 | I5: Avril | J5: Mai | K5: Juin | L5: T2 | M5: Juillet | N5: Août | O5: Septembre | P5: T3 | Q5: Octobre | R5: Novembre | S5: Décembre | T5: T4 | U5: Total Annuel | V5: Budget Alloué | W5: Écart
A6: BUD-001 | B6: CC-100 | C6: Direction Générale | D6: Masse salariale DG | E6: 7000000 | F6: 7000000 | G6: 7000000 | H6: =SUM(E6:G6) | I6: 7000000 | J6: 7000000 | K6: 7200000 | L6: =SUM(I6:K6) | M6: 7200000 | N6: 7200000 | O6: 7200000 | P6: =SUM(M6:O6) | Q6: 7200000 | R6: 7200000 | S6: 7200000 | T6: =SUM(Q6:S6) | U6: =H6+L6+P6+T6 | V6: =IFERROR(VLOOKUP(A6,'F01 - _Données Centrales'!$A$6:$L$20,7,FALSE),0) | W6: =V6-U6
A7: BUD-007 | B7: CC-200 | C7: Ressources Humaines | D7: Charges patronales | E7: 2800000 | F7: 2800000 | G7: 2800000 | H7: =SUM(E7:G7) | I7: 2800000 | J7: 2800000 | K7: 2800000 | L7: =SUM(I7:K7) | M7: 2800000 | N7: 2800000 | O7: 2800000 | P7: =SUM(M7:O7) | Q7: 2800000 | R7: 2800000 | S7: 2800000 | T7: =SUM(Q7:S7) | U7: =H7+L7+P7+T7 | V7: =IFERROR(VLOOKUP(A7,'F01 - _Données Centrales'!$A$6:$L$20,7,FALSE),0) | W7: =V7-U7
A8: BUD-012 | B8: CC-205 | C8: Finance & Comptabilité | D8: Fiscalité salariale | E8: 1800000 | F8: 1800000 | G8: 1800000 | H8: =SUM(E8:G8) | I8: 1800000 | J8: 1800000 | K8: 1800000 | L8: =SUM(I8:K8) | M8: 1800000 | N8: 1800000 | O8: 1800000 | P8: =SUM(M8:O8) | Q8: 1800000 | R8: 1800000 | S8: 1800000 | T8: =SUM(Q8:S8) | U8: =H8+L8+P8+T8 | V8: =IFERROR(VLOOKUP(A8,'F01 - _Données Centrales'!$A$6:$L$20,7,FALSE),0) | W8: =V8-U8
A9: BUD-010 | B9: CC-203 | C9: Ressources Humaines | D9: Avantages sociaux | E9: 1500000 | F9: 1500000 | G9: 1500000 | H9: =SUM(E9:G9) | I9: 1500000 | J9: 1500000 | K9: 1500000 | L9: =SUM(I9:K9) | M9: 1500000 | N9: 1500000 | O9: 1500000 | P9: =SUM(M9:O9) | Q9: 1500000 | R9: 1500000 | S9: 1500000 | T9: =SUM(Q9:S9) | U9: =H9+L9+P9+T9 | V9: =IFERROR(VLOOKUP(A9,'F01 - _Données Centrales'!$A$6:$L$20,7,FALSE),0) | W9: =V9-U9
A10: BUD-008 | B10: CC-201 | C10: Ressources Humaines | D10: Formation | E10: 800000 | F10: 800000 | G10: 1200000 | H10: =SUM(E10:G10) | I10: 1000000 | J10: 1000000 | K10: 800000 | L10: =SUM(I10:K10) | M10: 600000 | N10: 600000 | O10: 600000 | P10: =SUM(M10:O10) | Q10: 600000 | R10: 600000 | S10: 600000 | T10: =SUM(Q10:S10) | U10: =H10+L10+P10+T10 | V10: =IFERROR(VLOOKUP(A10,'F01 - _Données Centrales'!$A$6:$L$20,7,FALSE),0) | W10: =V10-U10
H11: =IF(A11="","",SUM(E11:G11)) | L11: =IF(A11="","",SUM(I11:K11)) | P11: =IF(A11="","",SUM(M11:O11)) | T11: =IF(A11="","",SUM(Q11:S11)) | U11: =IF(A11="","",H11+L11+P11+T11) | V11: =IF(A11="","",IFERROR(VLOOKUP(A11,'F01 - _Données Centrales'!$A$6:$L$20,7,FALSE),0)) | W11: =IF(A11="","",V11-U11)
H12: =IF(A12="","",SUM(E12:G12)) | L12: =IF(A12="","",SUM(I12:K12)) | P12: =IF(A12="","",SUM(M12:O12)) | T12: =IF(A12="","",SUM(Q12:S12)) | U12: =IF(A12="","",H12+L12+P12+T12) | V12: =IF(A12="","",IFERROR(VLOOKUP(A12,'F01 - _Données Centrales'!$A$6:$L$20,7,FALSE),0)) | W12: =IF(A12="","",V12-U12)
H13: =IF(A13="","",SUM(E13:G13)) | L13: =IF(A13="","",SUM(I13:K13)) | P13: =IF(A13="","",SUM(M13:O13)) | T13: =IF(A13="","",SUM(Q13:S13)) | U13: =IF(A13="","",H13+L13+P13+T13) | V13: =IF(A13="","",IFERROR(VLOOKUP(A13,'F01 - _Données Centrales'!$A$6:$L$20,7,FALSE),0)) | W13: =IF(A13="","",V13-U13)
H14: =IF(A14="","",SUM(E14:G14)) | L14: =IF(A14="","",SUM(I14:K14)) | P14: =IF(A14="","",SUM(M14:O14)) | T14: =IF(A14="","",SUM(Q14:S14)) | U14: =IF(A14="","",H14+L14+P14+T14) | V14: =IF(A14="","",IFERROR(VLOOKUP(A14,'F01 - _Données Centrales'!$A$6:$L$20,7,FALSE),0)) | W14: =IF(A14="","",V14-U14)
H15: =IF(A15="","",SUM(E15:G15)) | L15: =IF(A15="","",SUM(I15:K15)) | P15: =IF(A15="","",SUM(M15:O15)) | T15: =IF(A15="","",SUM(Q15:S15)) | U15: =IF(A15="","",H15+L15+P15+T15) | V15: =IF(A15="","",IFERROR(VLOOKUP(A15,'F01 - _Données Centrales'!$A$6:$L$20,7,FALSE),0)) | W15: =IF(A15="","",V15-U15)
H16: =IF(A16="","",SUM(E16:G16)) | L16: =IF(A16="","",SUM(I16:K16)) | P16: =IF(A16="","",SUM(M16:O16)) | T16: =IF(A16="","",SUM(Q16:S16)) | U16: =IF(A16="","",H16+L16+P16+T16) | V16: =IF(A16="","",IFERROR(VLOOKUP(A16,'F01 - _Données Centrales'!$A$6:$L$20,7,FALSE),0)) | W16: =IF(A16="","",V16-U16)
H17: =IF(A17="","",SUM(E17:G17)) | L17: =IF(A17="","",SUM(I17:K17)) | P17: =IF(A17="","",SUM(M17:O17)) | T17: =IF(A17="","",SUM(Q17:S17)) | U17: =IF(A17="","",H17+L17+P17+T17) | V17: =IF(A17="","",IFERROR(VLOOKUP(A17,'F01 - _Données Centrales'!$A$6:$L$20,7,FALSE),0)) | W17: =IF(A17="","",V17-U17)
H18: =IF(A18="","",SUM(E18:G18)) | L18: =IF(A18="","",SUM(I18:K18)) | P18: =IF(A18="","",SUM(M18:O18)) | T18: =IF(A18="","",SUM(Q18:S18)) | U18: =IF(A18="","",H18+L18+P18+T18) | V18: =IF(A18="","",IFERROR(VLOOKUP(A18,'F01 - _Données Centrales'!$A$6:$L$20,7,FALSE),0)) | W18: =IF(A18="","",V18-U18)
H19: =IF(A19="","",SUM(E19:G19)) | L19: =IF(A19="","",SUM(I19:K19)) | P19: =IF(A19="","",SUM(M19:O19)) | T19: =IF(A19="","",SUM(Q19:S19)) | U19: =IF(A19="","",H19+L19+P19+T19) | V19: =IF(A19="","",IFERROR(VLOOKUP(A19,'F01 - _Données Centrales'!$A$6:$L$20,7,FALSE),0)) | W19: =IF(A19="","",V19-U19)
H20: =IF(A20="","",SUM(E20:G20)) | L20: =IF(A20="","",SUM(I20:K20)) | P20: =IF(A20="","",SUM(M20:O20)) | T20: =IF(A20="","",SUM(Q20:S20)) | U20: =IF(A20="","",H20+L20+P20+T20) | V20: =IF(A20="","",IFERROR(VLOOKUP(A20,'F01 - _Données Centrales'!$A$6:$L$20,7,FALSE),0)) | W20: =IF(A20="","",V20-U20)
H21: =IF(A21="","",SUM(E21:G21)) | L21: =IF(A21="","",SUM(I21:K21)) | P21: =IF(A21="","",SUM(M21:O21)) | T21: =IF(A21="","",SUM(Q21:S21)) | U21: =IF(A21="","",H21+L21+P21+T21) | V21: =IF(A21="","",IFERROR(VLOOKUP(A21,'F01 - _Données Centrales'!$A$6:$L$20,7,FALSE),0)) | W21: =IF(A21="","",V21-U21)
H22: =IF(A22="","",SUM(E22:G22)) | L22: =IF(A22="","",SUM(I22:K22)) | P22: =IF(A22="","",SUM(M22:O22)) | T22: =IF(A22="","",SUM(Q22:S22)) | U22: =IF(A22="","",H22+L22+P22+T22) | V22: =IF(A22="","",IFERROR(VLOOKUP(A22,'F01 - _Données Centrales'!$A$6:$L$20,7,FALSE),0)) | W22: =IF(A22="","",V22-U22)
... H115: =IF(A115="","",SUM(E115:G115)) | L115: =IF(A115="","",SUM(I115:K115)) | P115: =IF(A115="","",SUM(M115:O115)) | T115: =IF(A115="","",SUM(Q115:S115)) | U115: =IF(A115="","",H115+L115+P115+T115) | V115: =IF(A115="","",IFERROR(VLOOKUP(A115,'F01 - _Données Centrales'!$A$6:$L$20,7,FALSE),0)) | W115: =IF(A115="","",V115-U115)

Sheet F05 - 3-Suivi Masse Salariale
A2: DOMAINE 26 — 3-SUIVI DE LA MASSE SALARIALE
A3: TABLEAU DYNAMIQUE — Suivi mensuel et cumul de la masse salariale par département
A5: Département | B5: Effectif | C5: Salaire Brut Total (FCFA) | D5: Charges Patronales (FCFA) | E5: Coût Total Employeur (FCFA) | F5: Salaire Moyen (FCFA) | G5: % du Total RH | H5: Mois
A6: Direction Générale | B6: 5 | C6: 42500000 | D6: 12750000 | E6: =C6+D6 | F6: =IFERROR(C6/B6,0) | G6: =IFERROR(C6/SUM($C$6:$C$15),0) | H6: Janvier 2025
A7: Ressources Humaines | B7: 12 | C7: 18000000 | D7: 5400000 | E7: =C7+D7 | F7: =IFERROR(C7/B7,0) | G7: =IFERROR(C7/SUM($C$6:$C$15),0) | H7: Janvier 2025
A8: Finance & Comptabilité | B8: 10 | C8: 15200000 | D8: 4560000 | E8: =C8+D8 | F8: =IFERROR(C8/B8,0) | G8: =IFERROR(C8/SUM($C$6:$C$15),0) | H8: Janvier 2025
A9: Cuisine & Restauration | B9: 45 | C9: 27000000 | D9: 8100000 | E9: =C9+D9 | F9: =IFERROR(C9/B9,0) | G9: =IFERROR(C9/SUM($C$6:$C$15),0) | H9: Janvier 2025
A10: Réception & Front Office | B10: 25 | C10: 17500000 | D10: 5250000 | E10: =C10+D10 | F10: =IFERROR(C10/B10,0) | G10: =IFERROR(C10/SUM($C$6:$C$15),0) | H10: Janvier 2025
A11: Maintenance & Technique | B11: 18 | C11: 14400000 | D11: 4320000 | E11: =C11+D11 | F11: =IFERROR(C11/B11,0) | G11: =IFERROR(C11/SUM($C$6:$C$15),0) | H11: Janvier 2025
A12: Marketing & Communication | B12: 8 | C12: 9600000 | D12: 2880000 | E12: =C12+D12 | F12: =IFERROR(C12/B12,0) | G12: =IFERROR(C12/SUM($C$6:$C$15),0) | H12: Janvier 2025
A13: Revenue Management | B13: 6 | C13: 7800000 | D13: 2340000 | E13: =C13+D13 | F13: =IFERROR(C13/B13,0) | G13: =IFERROR(C13/SUM($C$6:$C$15),0) | H13: Janvier 2025
A14: Sécurité | B14: 15 | C14: 7500000 | D14: 2250000 | E14: =C14+D14 | F14: =IFERROR(C14/B14,0) | G14: =IFERROR(C14/SUM($C$6:$C$15),0) | H14: Janvier 2025
A15: Commerce | B15: 10 | C15: 9000000 | D15: 2700000 | E15: =C15+D15 | F15: =IFERROR(C15/B15,0) | G15: =IFERROR(C15/SUM($C$6:$C$15),0) | H15: Janvier 2025
E16: =IF(A16="","",C16+D16) | F16: =IF(OR(A16="",B16=""),"",IFERROR(C16/B16,0)) | G16: =IF(A16="","",IFERROR(C16/SUM($C$6:$C$115),0))
E17: =IF(A17="","",C17+D17) | F17: =IF(OR(A17="",B17=""),"",IFERROR(C17/B17,0)) | G17: =IF(A17="","",IFERROR(C17/SUM($C$6:$C$115),0))
E18: =IF(A18="","",C18+D18) | F18: =IF(OR(A18="",B18=""),"",IFERROR(C18/B18,0)) | G18: =IF(A18="","",IFERROR(C18/SUM($C$6:$C$115),0))
E19: =IF(A19="","",C19+D19) | F19: =IF(OR(A19="",B19=""),"",IFERROR(C19/B19,0)) | G19: =IF(A19="","",IFERROR(C19/SUM($C$6:$C$115),0))
E20: =IF(A20="","",C20+D20) | F20: =IF(OR(A20="",B20=""),"",IFERROR(C20/B20,0)) | G20: =IF(A20="","",IFERROR(C20/SUM($C$6:$C$115),0))
E21: =IF(A21="","",C21+D21) | F21: =IF(OR(A21="",B21=""),"",IFERROR(C21/B21,0)) | G21: =IF(A21="","",IFERROR(C21/SUM($C$6:$C$115),0))
E22: =IF(A22="","",C22+D22) | F22: =IF(OR(A22="",B22=""),"",IFERROR(C22/B22,0)) | G22: =IF(A22="","",IFERROR(C22/SUM($C$6:$C$115),0))
E23: =IF(A23="","",C23+D23) | F23: =IF(OR(A23="",B23=""),"",IFERROR(C23/B23,0)) | G23: =IF(A23="","",IFERROR(C23/SUM($C$6:$C$115),0))
E24: =IF(A24="","",C24+D24) | F24: =IF(OR(A24="",B24=""),"",IFERROR(C24/B24,0)) | G24: =IF(A24="","",IFERROR(C24/SUM($C$6:$C$115),0))
E25: =IF(A25="","",C25+D25) | F25: =IF(OR(A25="",B25=""),"",IFERROR(C25/B25,0)) | G25: =IF(A25="","",IFERROR(C25/SUM($C$6:$C$115),0))
E26: =IF(A26="","",C26+D26) | F26: =IF(OR(A26="",B26=""),"",IFERROR(C26/B26,0)) | G26: =IF(A26="","",IFERROR(C26/SUM($C$6:$C$115),0))
E27: =IF(A27="","",C27+D27) | F27: =IF(OR(A27="",B27=""),"",IFERROR(C27/B27,0)) | G27: =IF(A27="","",IFERROR(C27/SUM($C$6:$C$115),0))
... E115: =IF(A115="","",C115+D115) | F115: =IF(OR(A115="",B115=""),"",IFERROR(C115/B115,0)) | G115: =IF(A115="","",IFERROR(C115/SUM($C$6:$C$115),0))

Sheet F06 - 4-Charges Patronales
A2: DOMAINE 26 — 4-CHARGES PATRONALES ET COTISATIONS SOCIALES
A3: TABLEAU DYNAMIQUE — Détail des cotisations par type et taux
A5: Type Cotisation | B5: Base de Calcul (FCFA) | C5: Taux Patronal (%) | D5: Montant Patronal (FCFA) | E5: Taux Salarial (%) | F5: Montant Salarial (FCFA) | G5: Total Part Patronale (FCFA) | H5: Déclaration | I5: Périodicité | J5: Statut
A6: Cotisation retraite CNPS | B6: 128500000 | C6: 8.4 | D6: =IFERROR(B6*C6/100,0) | E6: 4.8 | F6: =IFERROR(B6*E6/100,0) | G6: =D6+F6 | H6: DSN mensuelle | I6: Mensuelle | J6: Conforme
A7: Cotisation maladie CNPS | B7: 128500000 | C7: 4.2 | D7: =IFERROR(B7*C7/100,0) | E7: 1.75 | F7: =IFERROR(B7*E7/100,0) | G7: =D7+F7 | H7: DSN mensuelle | I7: Mensuelle | J7: Conforme
A8: Cotisation AT/MP | B8: 128500000 | C8: 3.5 | D8: =IFERROR(B8*C8/100,0) | E8: 0 | F8: =IFERROR(B8*E8/100,0) | G8: =D8+F8 | H8: DSN mensuelle | I8: Mensuelle | J8: Conforme
A9: Allocations familiales | B9: 128500000 | C9: 6.5 | D9: =IFERROR(B9*C9/100,0) | E9: 0 | F9: =IFERROR(B9*E9/100,0) | G9: =D9+F9 | H9: DSN mensuelle | I9: Mensuelle | J9: Conforme
A10: Taxe d'apprentissage | B10: 128500000 | C10: 0.68 | D10: =IFERROR(B10*C10/100,0) | E10: 0 | F10: =IFERROR(B10*E10/100,0) | G10: =D10+F10 | H10: DSF annuelle | I10: Annuelle | J10: En attente
A11: Formation professionnelle | B11: 128500000 | C11: 1.6 | D11: =IFERROR(B11*C11/100,0) | E11: 0 | F11: =IFERROR(B11*E11/100,0) | G11: =D11+F11 | H11: DSF annuelle | I11: Annuelle | J11: En attente
A12: Versement transport | B12: 128500000 | C12: 2 | D12: =IFERROR(B12*C12/100,0) | E12: 0 | F12: =IFERROR(B12*E12/100,0) | G12: =D12+F12 | H12: DSN mensuelle | I12: Mensuelle | J12: Conforme
A13: Forfait social (20%) | B13: 15000000 | C13: 20 | D13: =IFERROR(B13*C13/100,0) | E13: 0 | F13: =IFERROR(B13*E13/100,0) | G13: =D13+F13 | H13: DSN mensuelle | I13: Mensuelle | J13: Conforme
A14: Mutuelle entreprise | B14: 154 | C14: 50 | D14: =IFERROR(B14*C14/100,0) | E14: 50 | F14: =IFERROR(B14*E14/100,0) | G14: =D14+F14 | H14: Déclaration propre | I14: Mensuelle | J14: Conforme
A15: Prévoyance décès | B15: 128500000 | C15: 0.5 | D15: =IFERROR(B15*C15/100,0) | E15: 0 | F15: =IFERROR(B15*E15/100,0) | G15: =D15+F15 | H15: DSN mensuelle | I15: Mensuelle | J15: Conforme
D16: =IF(B16="","",IFERROR(B16*C16/100,0)) | F16: =IF(B16="","",IFERROR(B16*E16/100,0)) | G16: =IF(B16="","",D16+F16)
D17: =IF(B17="","",IFERROR(B17*C17/100,0)) | F17: =IF(B17="","",IFERROR(B17*E17/100,0)) | G17: =IF(B17="","",D17+F17)
D18: =IF(B18="","",IFERROR(B18*C18/100,0)) | F18: =IF(B18="","",IFERROR(B18*E18/100,0)) | G18: =IF(B18="","",D18+F18)
D19: =IF(B19="","",IFERROR(B19*C19/100,0)) | F19: =IF(B19="","",IFERROR(B19*E19/100,0)) | G19: =IF(B19="","",D19+F19)
D20: =IF(B20="","",IFERROR(B20*C20/100,0)) | F20: =IF(B20="","",IFERROR(B20*E20/100,0)) | G20: =IF(B20="","",D20+F20)
D21: =IF(B21="","",IFERROR(B21*C21/100,0)) | F21: =IF(B21="","",IFERROR(B21*E21/100,0)) | G21: =IF(B21="","",D21+F21)
D22: =IF(B22="","",IFERROR(B22*C22/100,0)) | F22: =IF(B22="","",IFERROR(B22*E22/100,0)) | G22: =IF(B22="","",D22+F22)
D23: =IF(B23="","",IFERROR(B23*C23/100,0)) | F23: =IF(B23="","",IFERROR(B23*E23/100,0)) | G23: =IF(B23="","",D23+F23)
D24: =IF(B24="","",IFERROR(B24*C24/100,0)) | F24: =IF(B24="","",IFERROR(B24*E24/100,0)) | G24: =IF(B24="","",D24+F24)
D25: =IF(B25="","",IFERROR(B25*C25/100,0)) | F25: =IF(B25="","",IFERROR(B25*E25/100,0)) | G25: =IF(B25="","",D25+F25)
D26: =IF(B26="","",IFERROR(B26*C26/100,0)) | F26: =IF(B26="","",IFERROR(B26*E26/100,0)) | G26: =IF(B26="","",D26+F26)
D27: =IF(B27="","",IFERROR(B27*C27/100,0)) | F27: =IF(B27="","",IFERROR(B27*E27/100,0)) | G27: =IF(B27="","",D27+F27)
... D115: =IF(B115="","",IFERROR(B115*C115/100,0)) | F115: =IF(B115="","",IFERROR(B115*E115/100,0)) | G115: =IF(B115="","",D115+F115)

Sheet F07 - 5-Fiscalité Rémunération
A2: DOMAINE 26 — 5-FISCALITÉ DE LA RÉMUNÉRATION
A3: TABLEAU DYNAMIQUE — IR, taxe sur salaires, CRDS/CSG
A5: Catégorie Employé | B5: Effectif | C5: Base Imposable (FCFA) | D5: Tranche IR (%) | E5: IR Calculé (FCFA) | F5: CRDS (FCFA) | G5: CSG (FCFA) | H5: Taxe Salaires (FCFA) | I5: Total Fiscalité (FCFA) | J5: Fiscalité Moy./Employé
A6: Cadres supérieurs | B6: 5 | C6: 42500000 | D6: 35 | E6: =IFERROR(C6*D6/100,0) | F6: =IFERROR(C6*0.5/100,0) | G6: =IFERROR(C6*0.98/100,0) | H6: =IFERROR(C6*2.5/100,0) | I6: =E6+F6+G6+H6 | J6: =IFERROR(I6/B6,0)
A7: Cadres | B7: 15 | C7: 54000000 | D7: 30 | E7: =IFERROR(C7*D7/100,0) | F7: =IFERROR(C7*0.5/100,0) | G7: =IFERROR(C7*0.98/100,0) | H7: =IFERROR(C7*2.5/100,0) | I7: =E7+F7+G7+H7 | J7: =IFERROR(I7/B7,0)
A8: Agents de maîtrise | B8: 30 | C8: 54000000 | D8: 20 | E8: =IFERROR(C8*D8/100,0) | F8: =IFERROR(C8*0.5/100,0) | G8: =IFERROR(C8*0.98/100,0) | H8: =IFERROR(C8*2.5/100,0) | I8: =E8+F8+G8+H8 | J8: =IFERROR(I8/B8,0)
A9: Employés | B9: 50 | C9: 45000000 | D9: 11 | E9: =IFERROR(C9*D9/100,0) | F9: =IFERROR(C9*0.5/100,0) | G9: =IFERROR(C9*0.98/100,0) | H9: =IFERROR(C9*2.5/100,0) | I9: =E9+F9+G9+H9 | J9: =IFERROR(I9/B9,0)
A10: Agents d'exécution | B10: 40 | C10: 24000000 | D10: 5 | E10: =IFERROR(C10*D10/100,0) | F10: =IFERROR(C10*0.5/100,0) | G10: =IFERROR(C10*0.98/100,0) | H10: =IFERROR(C10*2.5/100,0) | I10: =E10+F10+G10+H10 | J10: =IFERROR(I10/B10,0)
A11: Stagiaires | B11: 8 | C11: 1600000 | D11: 0 | E11: =IFERROR(C11*D11/100,0) | F11: =IFERROR(C11*0.5/100,0) | G11: =IFERROR(C11*0.98/100,0) | H11: =IFERROR(C11*2.5/100,0) | I11: =E11+F11+G11+H11 | J11: =IFERROR(I11/B11,0)
A12: Temporaires | B12: 10 | C12: 5000000 | D12: 15 | E12: =IFERROR(C12*D12/100,0) | F12: =IFERROR(C12*0.5/100,0) | G12: =IFERROR(C12*0.98/100,0) | H12: =IFERROR(C12*2.5/100,0) | I12: =E12+F12+G12+H12 | J12: =IFERROR(I12/B12,0)
A13: Expatriés | B13: 5 | C13: 20000000 | D13: 40 | E13: =IFERROR(C13*D13/100,0) | F13: =IFERROR(C13*0.5/100,0) | G13: =IFERROR(C13*0.98/100,0) | H13: =IFERROR(C13*2.5/100,0) | I13: =E13+F13+G13+H13 | J13: =IFERROR(I13/B13,0)
E14: =IF(C14="","",IFERROR(C14*D14/100,0)) | F14: =IF(C14="","",IFERROR(C14*0.5/100,0)) | G14: =IF(C14="","",IFERROR(C14*0.98/100,0)) | H14: =IF(C14="","",IFERROR(C14*2.5/100,0)) | I14: =IF(C14="","",E14+F14+G14+H14) | J14: =IF(OR(C14="",B14=""),"",IFERROR(I14/B14,0))
E15: =IF(C15="","",IFERROR(C15*D15/100,0)) | F15: =IF(C15="","",IFERROR(C15*0.5/100,0)) | G15: =IF(C15="","",IFERROR(C15*0.98/100,0)) | H15: =IF(C15="","",IFERROR(C15*2.5/100,0)) | I15: =IF(C15="","",E15+F15+G15+H15) | J15: =IF(OR(C15="",B15=""),"",IFERROR(I15/B15,0))
E16: =IF(C16="","",IFERROR(C16*D16/100,0)) | F16: =IF(C16="","",IFERROR(C16*0.5/100,0)) | G16: =IF(C16="","",IFERROR(C16*0.98/100,0)) | H16: =IF(C16="","",IFERROR(C16*2.5/100,0)) | I16: =IF(C16="","",E16+F16+G16+H16) | J16: =IF(OR(C16="",B16=""),"",IFERROR(I16/B16,0))
E17: =IF(C17="","",IFERROR(C17*D17/100,0)) | F17: =IF(C17="","",IFERROR(C17*0.5/100,0)) | G17: =IF(C17="","",IFERROR(C17*0.98/100,0)) | H17: =IF(C17="","",IFERROR(C17*2.5/100,0)) | I17: =IF(C17="","",E17+F17+G17+H17) | J17: =IF(OR(C17="",B17=""),"",IFERROR(I17/B17,0))
E18: =IF(C18="","",IFERROR(C18*D18/100,0)) | F18: =IF(C18="","",IFERROR(C18*0.5/100,0)) | G18: =IF(C18="","",IFERROR(C18*0.98/100,0)) | H18: =IF(C18="","",IFERROR(C18*2.5/100,0)) | I18: =IF(C18="","",E18+F18+G18+H18) | J18: =IF(OR(C18="",B18=""),"",IFERROR(I18/B18,0))
E19: =IF(C19="","",IFERROR(C19*D19/100,0)) | F19: =IF(C19="","",IFERROR(C19*0.5/100,0)) | G19: =IF(C19="","",IFERROR(C19*0.98/100,0)) | H19: =IF(C19="","",IFERROR(C19*2.5/100,0)) | I19: =IF(C19="","",E19+F19+G19+H19) | J19: =IF(OR(C19="",B19=""),"",IFERROR(I19/B19,0))
E20: =IF(C20="","",IFERROR(C20*D20/100,0)) | F20: =IF(C20="","",IFERROR(C20*0.5/100,0)) | G20: =IF(C20="","",IFERROR(C20*0.98/100,0)) | H20: =IF(C20="","",IFERROR(C20*2.5/100,0)) | I20: =IF(C20="","",E20+F20+G20+H20) | J20: =IF(OR(C20="",B20=""),"",IFERROR(I20/B20,0))
E21: =IF(C21="","",IFERROR(C21*D21/100,0)) | F21: =IF(C21="","",IFERROR(C21*0.5/100,0)) | G21: =IF(C21="","",IFERROR(C21*0.98/100,0)) | H21: =IF(C21="","",IFERROR(C21*2.5/100,0)) | I21: =IF(C21="","",E21+F21+G21+H21) | J21: =IF(OR(C21="",B21=""),"",IFERROR(I21/B21,0))
E22: =IF(C22="","",IFERROR(C22*D22/100,0)) | F22: =IF(C22="","",IFERROR(C22*0.5/100,0)) | G22: =IF(C22="","",IFERROR(C22*0.98/100,0)) | H22: =IF(C22="","",IFERROR(C22*2.5/100,0)) | I22: =IF(C22="","",E22+F22+G22+H22) | J22: =IF(OR(C22="",B22=""),"",IFERROR(I22/B22,0))
E23: =IF(C23="","",IFERROR(C23*D23/100,0)) | F23: =IF(C23="","",IFERROR(C23*0.5/100,0)) | G23: =IF(C23="","",IFERROR(C23*0.98/100,0)) | H23: =IF(C23="","",IFERROR(C23*2.5/100,0)) | I23: =IF(C23="","",E23+F23+G23+H23) | J23: =IF(OR(C23="",B23=""),"",IFERROR(I23/B23,0))
E24: =IF(C24="","",IFERROR(C24*D24/100,0)) | F24: =IF(C24="","",IFERROR(C24*0.5/100,0)) | G24: =IF(C24="","",IFERROR(C24*0.98/100,0)) | H24: =IF(C24="","",IFERROR(C24*2.5/100,0)) | I24: =IF(C24="","",E24+F24+G24+H24) | J24: =IF(OR(C24="",B24=""),"",IFERROR(I24/B24,0))
E25: =IF(C25="","",IFERROR(C25*D25/100,0)) | F25: =IF(C25="","",IFERROR(C25*0.5/100,0)) | G25: =IF(C25="","",IFERROR(C25*0.98/100,0)) | H25: =IF(C25="","",IFERROR(C25*2.5/100,0)) | I25: =IF(C25="","",E25+F25+G25+H25) | J25: =IF(OR(C25="",B25=""),"",IFERROR(I25/B25,0))
... E115: =IF(C115="","",IFERROR(C115*D115/100,0)) | F115: =IF(C115="","",IFERROR(C115*0.5/100,0)) | G115: =IF(C115="","",IFERROR(C115*0.98/100,0)) | H115: =IF(C115="","",IFERROR(C115*2.5/100,0)) | I115: =IF(C115="","",E115+F115+G115+H115) | J115: =IF(OR(C115="",B115=""),"",IFERROR(I115/B115,0))

Sheet F08 - 6-Épargne Salariale
A2: DOMAINE 26 — 6-ÉPARGNE SALARIALE (PEE/PEREI/Participation/Intéressement)
A3: TABLEAU DYNAMIQUE — Dispositifs d'épargne et impacts fiscaux
A5: Dispositif | B5: Nb Bénéficiaires | C5: Base de Calcul (FCFA) | D5: Taux (%) | E5: Montant Brut (FCFA) | F5: Cotisation Employeur (FCFA) | G5: Avantage Fiscal (FCFA) | H5: Coût Net (FCFA) | I5: Exercice | J5: Statut
A6: PEE (Plan Épargne Entreprise) | B6: 80 | C6: 128500000 | D6: 3 | E6: =IFERROR(C6*D6/100,0) | F6: =IFERROR(E6*0.6,0) | G6: =IFERROR(E6*0.25,0) | H6: =F6-G6 | I6: 2025 | J6: Actif
A7: PEREI | B7: 60 | C7: 96000000 | D7: 2 | E7: =IFERROR(C7*D7/100,0) | F7: =IFERROR(E7*0.6,0) | G7: =IFERROR(E7*0.25,0) | H7: =F7-G7 | I7: 2025 | J7: Actif
A8: Participation aux résultats | B8: 120 | C8: 256000000 | D8: 5 | E8: =IFERROR(C8*D8/100,0) | F8: =IFERROR(E8*0.6,0) | G8: =IFERROR(E8*0.25,0) | H8: =F8-G8 | I8: 2025 | J8: En cours
A9: Intéressement | B9: 100 | C9: 200000000 | D9: 4 | E9: =IFERROR(C9*D9/100,0) | F9: =IFERROR(E9*0.6,0) | G9: =IFERROR(E9*0.25,0) | H9: =F9-G9 | I9: 2025 | J9: Actif
A10: Abondement PEE | B10: 50 | C10: 40000000 | D10: 50 | E10: =IFERROR(C10*D10/100,0) | F10: =IFERROR(E10*0.6,0) | G10: =IFERROR(E10*0.25,0) | H10: =F10-G10 | I10: 2025 | J10: Actif
A11: Abondement PEREI | B11: 30 | C11: 24000000 | D11: 50 | E11: =IFERROR(C11*D11/100,0) | F11: =IFERROR(E11*0.6,0) | G11: =IFERROR(E11*0.25,0) | H11: =F11-G11 | I11: 2025 | J11: Actif
E12: =IF(C12="","",IFERROR(C12*D12/100,0)) | F12: =IF(C12="","",IFERROR(E12*0.6,0)) | G12: =IF(C12="","",IFERROR(E12*0.25,0)) | H12: =IF(C12="","",F12-G12)
E13: =IF(C13="","",IFERROR(C13*D13/100,0)) | F13: =IF(C13="","",IFERROR(E13*0.6,0)) | G13: =IF(C13="","",IFERROR(E13*0.25,0)) | H13: =IF(C13="","",F13-G13)
E14: =IF(C14="","",IFERROR(C14*D14/100,0)) | F14: =IF(C14="","",IFERROR(E14*0.6,0)) | G14: =IF(C14="","",IFERROR(E14*0.25,0)) | H14: =IF(C14="","",F14-G14)
E15: =IF(C15="","",IFERROR(C15*D15/100,0)) | F15: =IF(C15="","",IFERROR(E15*0.6,0)) | G15: =IF(C15="","",IFERROR(E15*0.25,0)) | H15: =IF(C15="","",F15-G15)
E16: =IF(C16="","",IFERROR(C16*D16/100,0)) | F16: =IF(C16="","",IFERROR(E16*0.6,0)) | G16: =IF(C16="","",IFERROR(E16*0.25,0)) | H16: =IF(C16="","",F16-G16)
E17: =IF(C17="","",IFERROR(C17*D17/100,0)) | F17: =IF(C17="","",IFERROR(E17*0.6,0)) | G17: =IF(C17="","",IFERROR(E17*0.25,0)) | H17: =IF(C17="","",F17-G17)
E18: =IF(C18="","",IFERROR(C18*D18/100,0)) | F18: =IF(C18="","",IFERROR(E18*0.6,0)) | G18: =IF(C18="","",IFERROR(E18*0.25,0)) | H18: =IF(C18="","",F18-G18)
E19: =IF(C19="","",IFERROR(C19*D19/100,0)) | F19: =IF(C19="","",IFERROR(E19*0.6,0)) | G19: =IF(C19="","",IFERROR(E19*0.25,0)) | H19: =IF(C19="","",F19-G19)
E20: =IF(C20="","",IFERROR(C20*D20/100,0)) | F20: =IF(C20="","",IFERROR(E20*0.6,0)) | G20: =IF(C20="","",IFERROR(E20*0.25,0)) | H20: =IF(C20="","",F20-G20)
E21: =IF(C21="","",IFERROR(C21*D21/100,0)) | F21: =IF(C21="","",IFERROR(E21*0.6,0)) | G21: =IF(C21="","",IFERROR(E21*0.25,0)) | H21: =IF(C21="","",F21-G21)
E22: =IF(C22="","",IFERROR(C22*D22/100,0)) | F22: =IF(C22="","",IFERROR(E22*0.6,0)) | G22: =IF(C22="","",IFERROR(E22*0.25,0)) | H22: =IF(C22="","",F22-G22)
E23: =IF(C23="","",IFERROR(C23*D23/100,0)) | F23: =IF(C23="","",IFERROR(E23*0.6,0)) | G23: =IF(C23="","",IFERROR(E23*0.25,0)) | H23: =IF(C23="","",F23-G23)
... E115: =IF(C115="","",IFERROR(C115*D115/100,0)) | F115: =IF(C115="","",IFERROR(E115*0.6,0)) | G115: =IF(C115="","",IFERROR(E115*0.25,0)) | H115: =IF(C115="","",F115-G115)

Sheet F09 - 7-Avantages Nature
A2: DOMAINE 26 — 7-AVANTAGES EN NATURE ET INDEMNITÉS
A3: TABLEAU DYNAMIQUE — Évaluation et traitement fiscal des avantages
A5: Type Avantage | B5: Nb Bénéficiaires | C5: Valeur Unitaire (FCFA) | D5: Valeur Totale (FCFA) | E5: TVA Associée (FCFA) | F5: Base Imposable (FCFA) | G5: Fiscalité Dues (FCFA) | H5: Taux Imposition (%) | I5: Coût Employeur Net (FCFA) | J5: Département
A6: Logement de fonction | B6: 8 | C6: 350000 | D6: =B6*C6 | E6: =IFERROR(D6*0.1925,0) | F6: =D6+E6 | G6: =IFERROR(F6*H6/100,0) | H6: 10 | I6: =D6+G6 | J6: Direction Générale
A7: Véhicule de fonction | B7: 12 | C7: 180000 | D7: =B7*C7 | E7: =IFERROR(D7*0.1925,0) | F7: =D7+E7 | G7: =IFERROR(F7*H7/100,0) | H7: 10 | I7: =D7+G7 | J7: Tous départements
A8: Téléphone professionnel | B8: 50 | C8: 25000 | D8: =B8*C8 | E8: =IFERROR(D8*0.1925,0) | F8: =D8+E8 | G8: =IFERROR(F8*H8/100,0) | H8: 0 | I8: =D8+G8 | J8: Tous départements
A9: Repas cantine | B9: 120 | C9: 45000 | D9: =B9*C9 | E9: =IFERROR(D9*0.1925,0) | F9: =D9+E9 | G9: =IFERROR(F9*H9/100,0) | H9: 0 | I9: =D9+G9 | J9: Tous départements
A10: Indemnité transport | B10: 120 | C10: 30000 | D10: =B10*C10 | E10: =IFERROR(D10*0.1925,0) | F10: =D10+E10 | G10: =IFERROR(F10*H10/100,0) | H10: 0 | I10: =D10+G10 | J10: Tous départements
A11: Indemnité logement | B11: 35 | C11: 150000 | D11: =B11*C11 | E11: =IFERROR(D11*0.1925,0) | F11: =D11+E11 | G11: =IFERROR(F11*H11/100,0) | H11: 15 | I11: =D11+G11 | J11: Cuisine & Restauration
A12: Abonnement mutuelle | B12: 154 | C12: 12000 | D12: =B12*C12 | E12: =IFERROR(D12*0.1925,0) | F12: =D12+E12 | G12: =IFERROR(F12*H12/100,0) | H12: 0 | I12: =D12+G12 | J12: Tous départements
A13: Indemnité scolarité | B13: 5 | C13: 200000 | D13: =B13*C13 | E13: =IFERROR(D13*0.1925,0) | F13: =D13+E13 | G13: =IFERROR(F13*H13/100,0) | H13: 0 | I13: =D13+G13 | J13: Direction Générale
A14: Frais médicaux | B14: 80 | C14: 20000 | D14: =B14*C14 | E14: =IFERROR(D14*0.1925,0) | F14: =D14+E14 | G14: =IFERROR(F14*H14/100,0) | H14: 0 | I14: =D14+G14 | J14: Tous départements
A15: Indemnité expatriation | B15: 5 | C15: 500000 | D15: =B15*C15 | E15: =IFERROR(D15*0.1925,0) | F15: =D15+E15 | G15: =IFERROR(F15*H15/100,0) | H15: 20 | I15: =D15+G15 | J15: Tous départements
D16: =IF(B16="","",B16*C16) | E16: =IF(D16="","",IFERROR(D16*0.1925,0)) | F16: =IF(D16="","",D16+E16) | G16: =IF(F16="","",IFERROR(F16*H16/100,0)) | I16: =IF(D16="","",D16+G16)
D17: =IF(B17="","",B17*C17) | E17: =IF(D17="","",IFERROR(D17*0.1925,0)) | F17: =IF(D17="","",D17+E17) | G17: =IF(F17="","",IFERROR(F17*H17/100,0)) | I17: =IF(D17="","",D17+G17)
D18: =IF(B18="","",B18*C18) | E18: =IF(D18="","",IFERROR(D18*0.1925,0)) | F18: =IF(D18="","",D18+E18) | G18: =IF(F18="","",IFERROR(F18*H18/100,0)) | I18: =IF(D18="","",D18+G18)
D19: =IF(B19="","",B19*C19) | E19: =IF(D19="","",IFERROR(D19*0.1925,0)) | F19: =IF(D19="","",D19+E19) | G19: =IF(F19="","",IFERROR(F19*H19/100,0)) | I19: =IF(D19="","",D19+G19)
D20: =IF(B20="","",B20*C20) | E20: =IF(D20="","",IFERROR(D20*0.1925,0)) | F20: =IF(D20="","",D20+E20) | G20: =IF(F20="","",IFERROR(F20*H20/100,0)) | I20: =IF(D20="","",D20+G20)
D21: =IF(B21="","",B21*C21) | E21: =IF(D21="","",IFERROR(D21*0.1925,0)) | F21: =IF(D21="","",D21+E21) | G21: =IF(F21="","",IFERROR(F21*H21/100,0)) | I21: =IF(D21="","",D21+G21)
D22: =IF(B22="","",B22*C22) | E22: =IF(D22="","",IFERROR(D22*0.1925,0)) | F22: =IF(D22="","",D22+E22) | G22: =IF(F22="","",IFERROR(F22*H22/100,0)) | I22: =IF(D22="","",D22+G22)
D23: =IF(B23="","",B23*C23) | E23: =IF(D23="","",IFERROR(D23*0.1925,0)) | F23: =IF(D23="","",D23+E23) | G23: =IF(F23="","",IFERROR(F23*H23/100,0)) | I23: =IF(D23="","",D23+G23)
D24: =IF(B24="","",B24*C24) | E24: =IF(D24="","",IFERROR(D24*0.1925,0)) | F24: =IF(D24="","",D24+E24) | G24: =IF(F24="","",IFERROR(F24*H24/100,0)) | I24: =IF(D24="","",D24+G24)
D25: =IF(B25="","",B25*C25) | E25: =IF(D25="","",IFERROR(D25*0.1925,0)) | F25: =IF(D25="","",D25+E25) | G25: =IF(F25="","",IFERROR(F25*H25/100,0)) | I25: =IF(D25="","",D25+G25)
D26: =IF(B26="","",B26*C26) | E26: =IF(D26="","",IFERROR(D26*0.1925,0)) | F26: =IF(D26="","",D26+E26) | G26: =IF(F26="","",IFERROR(F26*H26/100,0)) | I26: =IF(D26="","",D26+G26)
D27: =IF(B27="","",B27*C27) | E27: =IF(D27="","",IFERROR(D27*0.1925,0)) | F27: =IF(D27="","",D27+E27) | G27: =IF(F27="","",IFERROR(F27*H27/100,0)) | I27: =IF(D27="","",D27+G27)
... D115: =IF(B115="","",B115*C115) | E115: =IF(D115="","",IFERROR(D115*0.1925,0)) | F115: =IF(D115="","",D115+E115) | G115: =IF(F115="","",IFERROR(F115*H115/100,0)) | I115: =IF(D115="","",D115+G115)

Sheet F10 - 8-Fiscalité Internat.
A2: DOMAINE 26 — 8-FISCALITÉ INTERNATIONALE (IMPATRIATION/EXPATRIATION)
A3: TABLEAU DYNAMIQUE — Régimes fiscaux, conventions de non-double imposition
A5: Pays | B5: Convention Fiscale | C5: Régime Imposition | D5: Taux Effectif (%) | E5: Revenus Imposables Locaux (FCFA) | F5: Revenus Exonérés (FCFA) | G5: Crédit d'Impôt (FCFA) | H5: Impôt Étranger (FCFA) | I5: Impôt Local Dû (FCFA) | J5: Économie Réalisée (FCFA) | K5: Statut Conformité
A6: France | B6: Oui | C6: Régime de non-double imposition | D6: 30 | E6: 15000000 | F6: 8000000 | G6: =IFERROR(E6*D6/100,0) | H6: 2400000 | I6: =IFERROR((E6-F6)*D6/100,0) | J6: =IFERROR(G6-H6,0) | K6: Conforme
A7: Allemagne | B7: Oui | C7: Crédit d'impôt | D7: 28 | E7: 8000000 | F7: 4000000 | G7: =IFERROR(E7*D7/100,0) | H7: 1120000 | I7: =IFERROR((E7-F7)*D7/100,0) | J7: =IFERROR(G7-H7,0) | K7: Conforme
A8: Brésil | B8: Non | C8: Imposition complète | D8: 35 | E8: 6000000 | F8: 0 | G8: =IFERROR(E8*D8/100,0) | H8: 0 | I8: =IFERROR((E8-F8)*D8/100,0) | J8: =IFERROR(G8-H8,0) | K8: En attente
A9: Japon | B9: Oui | C9: Régime dérogatoire | D9: 33 | E9: 4000000 | F9: 2000000 | G9: =IFERROR(E9*D9/100,0) | H9: 660000 | I9: =IFERROR((E9-F9)*D9/100,0) | J9: =IFERROR(G9-H9,0) | K9: Conforme
A10: Royaume-Uni | B10: Oui | C10: Split payroll | D10: 32 | E10: 5000000 | F10: 2500000 | G10: =IFERROR(E10*D10/100,0) | H10: 800000 | I10: =IFERROR((E10-F10)*D10/100,0) | J10: =IFERROR(G10-H10,0) | K10: Conforme
A11: Chine | B11: Non | C11: Imposition source | D11: 25 | E11: 3500000 | F11: 0 | G11: =IFERROR(E11*D11/100,0) | H11: 0 | I11: =IFERROR((E11-F11)*D11/100,0) | J11: =IFERROR(G11-H11,0) | K11: En attente
A12: Maroc | B12: Oui | C12: Non-double imposition | D12: 30 | E12: 3000000 | F12: 1500000 | G12: =IFERROR(E12*D12/100,0) | H12: 450000 | I12: =IFERROR((E12-F12)*D12/100,0) | J12: =IFERROR(G12-H12,0) | K12: Conforme
A13: États-Unis | B13: Oui | C13: Régime FATCA | D13: 35 | E13: 4000000 | F13: 2000000 | G13: =IFERROR(E13*D13/100,0) | H13: 700000 | I13: =IFERROR((E13-F13)*D13/100,0) | J13: =IFERROR(G13-H13,0) | K13: À régulariser
G14: =IF(E14="","",IFERROR(E14*D14/100,0)) | I14: =IF(E14="","",IFERROR((E14-F14)*D14/100,0)) | J14: =IF(E14="","",IFERROR(G14-H14,0))
G15: =IF(E15="","",IFERROR(E15*D15/100,0)) | I15: =IF(E15="","",IFERROR((E15-F15)*D15/100,0)) | J15: =IF(E15="","",IFERROR(G15-H15,0))
G16: =IF(E16="","",IFERROR(E16*D16/100,0)) | I16: =IF(E16="","",IFERROR((E16-F16)*D16/100,0)) | J16: =IF(E16="","",IFERROR(G16-H16,0))
G17: =IF(E17="","",IFERROR(E17*D17/100,0)) | I17: =IF(E17="","",IFERROR((E17-F17)*D17/100,0)) | J17: =IF(E17="","",IFERROR(G17-H17,0))
G18: =IF(E18="","",IFERROR(E18*D18/100,0)) | I18: =IF(E18="","",IFERROR((E18-F18)*D18/100,0)) | J18: =IF(E18="","",IFERROR(G18-H18,0))
G19: =IF(E19="","",IFERROR(E19*D19/100,0)) | I19: =IF(E19="","",IFERROR((E19-F19)*D19/100,0)) | J19: =IF(E19="","",IFERROR(G19-H19,0))
G20: =IF(E20="","",IFERROR(E20*D20/100,0)) | I20: =IF(E20="","",IFERROR((E20-F20)*D20/100,0)) | J20: =IF(E20="","",IFERROR(G20-H20,0))
G21: =IF(E21="","",IFERROR(E21*D21/100,0)) | I21: =IF(E21="","",IFERROR((E21-F21)*D21/100,0)) | J21: =IF(E21="","",IFERROR(G21-H21,0))
G22: =IF(E22="","",IFERROR(E22*D22/100,0)) | I22: =IF(E22="","",IFERROR((E22-F22)*D22/100,0)) | J22: =IF(E22="","",IFERROR(G22-H22,0))
G23: =IF(E23="","",IFERROR(E23*D23/100,0)) | I23: =IF(E23="","",IFERROR((E23-F23)*D23/100,0)) | J23: =IF(E23="","",IFERROR(G23-H23,0))
G24: =IF(E24="","",IFERROR(E24*D24/100,0)) | I24: =IF(E24="","",IFERROR((E24-F24)*D24/100,0)) | J24: =IF(E24="","",IFERROR(G24-H24,0))
G25: =IF(E25="","",IFERROR(E25*D25/100,0)) | I25: =IF(E25="","",IFERROR((E25-F25)*D25/100,0)) | J25: =IF(E25="","",IFERROR(G25-H25,0))
... G115: =IF(E115="","",IFERROR(E115*D115/100,0)) | I115: =IF(E115="","",IFERROR((E115-F115)*D115/100,0)) | J115: =IF(E115="","",IFERROR(G115-H115,0))

Sheet F11 - 9-Déclarations Fiscales
A2: DOMAINE 26 — 9-DÉCLARATIONS FISCALES RH
A3: TABLEAU DYNAMIQUE — Calendrier, suivi et conformité des déclarations
A5: Code Décl. | B5: Type Déclaration | C5: Période | D5: Date Échéance | E5: Date Soumission | F5: Montant Déclaré (FCFA) | G5: Montant Versé (FCFA) | H5: Reste à Verser (FCFA) | I5: Pénalités (FCFA) | J5: Statut | K5: Responsable
A6: DF-2025-001 | B6: DSN mensuelle | C6: Janvier 2025 | D6: 45703 | E6: 45702 | F6: 18500000 | G6: 18500000 | H6: =F6-G6 | I6: 0 | J6: Payé | K6: M. Eyenga
A7: DF-2025-002 | B7: DSN mensuelle | C7: Février 2025 | D7: 45731 | E7: 45731 | F7: 18500000 | G7: 18500000 | H7: =F7-G7 | I7: 0 | J7: Payé | K7: M. Eyenga
A8: DF-2025-003 | B8: DSN mensuelle | C8: Mars 2025 | D8: 45762 | E8: 45762 | F8: 19200000 | G8: 19200000 | H8: =F8-G8 | I8: 0 | J8: Payé | K8: M. Eyenga
A9: DF-2025-004 | B9: DSN mensuelle | C9: Avril 2025 | D9: 45792 | E9: 45795 | F9: 19200000 | G9: 19200000 | H9: =F9-G9 | I9: 50000 | J9: Payé | K9: M. Eyenga
A10: DF-2025-005 | B10: DSN mensuelle | C10: Mai 2025 | D10: 45823 | E10: 45820 | F10: 18800000 | G10: 18800000 | H10: =F10-G10 | I10: 0 | J10: Payé | K10: M. Eyenga
A11: DF-2025-006 | B11: DSF annuelle | C11: Année 2024 | D11: 45777 | E11: 45775 | F11: 250000000 | G11: 250000000 | H11: =F11-G11 | I11: 0 | J11: Payé | K11: M. Eyenga
A12: DF-2025-007 | B12: TVA mensuelle | C12: Janvier 2025 | D12: 45703 | E12: 45702 | F12: 3200000 | G12: 3200000 | H12: =F12-G12 | I12: 0 | J12: Payé | K12: M. Fotso
A13: DF-2025-008 | B13: Déclaration IS | C13: Année 2024 | D13: 45747 | E13: 45746 | F13: 45000000 | G13: 45000000 | H13: =F13-G13 | I13: 0 | J13: Payé | K13: M. Eyenga
A14: DF-2025-009 | B14: DSN mensuelle | C14: Juin 2025 | D14: 45853 | E14: 45848 | F14: 19500000 | G14: 0 | H14: =F14-G14 | I14: 0 | J14: En attente | K14: M. Eyenga
A15: DF-2025-010 | B15: TVA mensuelle | C15: Juin 2025 | D15: 45853 | F15: 3400000 | G15: 0 | H15: =F15-G15 | I15: 0 | J15: En attente | K15: M. Fotso
H16: =IF(F16="","",F16-G16)
H17: =IF(F17="","",F17-G17)
H18: =IF(F18="","",F18-G18)
H19: =IF(F19="","",F19-G19)
H20: =IF(F20="","",F20-G20)
H21: =IF(F21="","",F21-G21)
H22: =IF(F22="","",F22-G22)
H23: =IF(F23="","",F23-G23)
H24: =IF(F24="","",F24-G24)
H25: =IF(F25="","",F25-G25)
H26: =IF(F26="","",F26-G26)
H27: =IF(F27="","",F27-G27)
... H115: =IF(F115="","",F115-G115)

Sheet F12 - 10-Suivi Écarts Budget.
A2: DOMAINE 26 — 10-SUIVI DES ÉCARTS BUDGÉTAIRES
A3: TABLEAU DYNAMIQUE — Analyse des décalages prévision/réalisation
A5: Code Budget | B5: Rubrique | C5: Budget Prévu (FCFA) | D5: Budget Réalisé (FCFA) | E5: Écart Absolu (FCFA) | F5: Écart Relatif (%) | G5: Sens Écart | H5: Niveau Alerte | I5: Analyse Causes | J5: Action Corrective | K5: Responsable
A6: BUD-001 | B6: Masse salariale DG | C6: 85000000 | D6: 72500000 | E6: =C6-D6 | F6: =IFERROR(E6/C6,0) | G6: =IF(E6>0,"Favorable",IF(E6<0,"Défavorable","Néant")) | H6: =IF(ABS(F6)>0.15,"Haute",IF(ABS(F6)>0.05,"Moyenne","Basse")) | I6: Poste DG vacant 3 mois | J6: Recrutement en cours | K6: M. Nkoulou
A7: BUD-002 | B7: Masse salariale RH | C7: 42000000 | D7: 35800000 | E7: =C7-D7 | F7: =IFERROR(E7/C7,0) | G7: =IF(E7>0,"Favorable",IF(E7<0,"Défavorable","Néant")) | H7: =IF(ABS(F7)>0.15,"Haute",IF(ABS(F7)>0.05,"Moyenne","Basse")) | I7: Turnover réduit | J7: Réaffectation prévue Q3 | K7: Mme. Mbarga
A8: BUD-004 | B8: Masse salariale Rest. | C8: 120000000 | D8: 98500000 | E8: =C8-D8 | F8: =IFERROR(E8/C8,0) | G8: =IF(E8>0,"Favorable",IF(E8<0,"Défavorable","Néant")) | H8: =IF(ABS(F8)>0.15,"Haute",IF(ABS(F8)>0.05,"Moyenne","Basse")) | I8: Heures supp. réduites | J8: Optimisation planning | K8: M. Tchinda
A9: BUD-007 | B9: Charges patronales | C9: 35000000 | D9: 28500000 | E9: =C9-D9 | F9: =IFERROR(E9/C9,0) | G9: =IF(E9>0,"Favorable",IF(E9<0,"Défavorable","Néant")) | H9: =IF(ABS(F9)>0.15,"Haute",IF(ABS(F9)>0.05,"Moyenne","Basse")) | I9: Baisse effectif cotisant | J9: Néant | K9: Mme. Mbarga
A10: BUD-008 | B10: Formation | C10: 15000000 | D10: 8700000 | E10: =C10-D10 | F10: =IFERROR(E10/C10,0) | G10: =IF(E10>0,"Favorable",IF(E10<0,"Défavorable","Néant")) | H10: =IF(ABS(F10)>0.15,"Haute",IF(ABS(F10)>0.05,"Moyenne","Basse")) | I10: Formations reportées Q2 | J10: Programme Q3 renforcé | K10: M. Fotso
A11: BUD-012 | B11: Fiscalité salariale | C11: 25000000 | D11: 19800000 | E11: =C11-D11 | F11: =IFERROR(E11/C11,0) | G11: =IF(E11>0,"Favorable",IF(E11<0,"Défavorable","Néant")) | H11: =IF(ABS(F11)>0.15,"Haute",IF(ABS(F11)>0.05,"Moyenne","Basse")) | I11: Réajustement base impos. | J11: Vérification en cours | K11: M. Eyenga
A12: BUD-013 | B12: Primes & indemnités | C12: 30000000 | D12: 22400000 | E12: =C12-D12 | F12: =IFERROR(E12/C12,0) | G12: =IF(E12>0,"Favorable",IF(E12<0,"Défavorable","Néant")) | H12: =IF(ABS(F12)>0.15,"Haute",IF(ABS(F12)>0.05,"Moyenne","Basse")) | I12: Prime performance reportée | J12: Versement prévu Q4 | K12: M. Nkoulou
A13: BUD-015 | B13: Mobilité | C13: 10000000 | D13: 5400000 | E13: =C13-D13 | F13: =IFERROR(E13/C13,0) | G13: =IF(E13>0,"Favorable",IF(E13<0,"Défavorable","Néant")) | H13: =IF(ABS(F13)>0.15,"Haute",IF(ABS(F13)>0.05,"Moyenne","Basse")) | I13: Relocalisations retardées | J13: Planification T3/T4 | K13: Mme. Essomba
E14: =IF(C14="","",C14-D14) | F14: =IF(C14="","",IFERROR(E14/C14,0)) | G14: =IF(E14="","",IF(E14>0,"Favorable",IF(E14<0,"Défavorable","Néant"))) | H14: =IF(F14="","",IF(ABS(F14)>0.15,"Haute",IF(ABS(F14)>0.05,"Moyenne","Basse")))
E15: =IF(C15="","",C15-D15) | F15: =IF(C15="","",IFERROR(E15/C15,0)) | G15: =IF(E15="","",IF(E15>0,"Favorable",IF(E15<0,"Défavorable","Néant"))) | H15: =IF(F15="","",IF(ABS(F15)>0.15,"Haute",IF(ABS(F15)>0.05,"Moyenne","Basse")))
E16: =IF(C16="","",C16-D16) | F16: =IF(C16="","",IFERROR(E16/C16,0)) | G16: =IF(E16="","",IF(E16>0,"Favorable",IF(E16<0,"Défavorable","Néant"))) | H16: =IF(F16="","",IF(ABS(F16)>0.15,"Haute",IF(ABS(F16)>0.05,"Moyenne","Basse")))
E17: =IF(C17="","",C17-D17) | F17: =IF(C17="","",IFERROR(E17/C17,0)) | G17: =IF(E17="","",IF(E17>0,"Favorable",IF(E17<0,"Défavorable","Néant"))) | H17: =IF(F17="","",IF(ABS(F17)>0.15,"Haute",IF(ABS(F17)>0.05,"Moyenne","Basse")))
E18: =IF(C18="","",C18-D18) | F18: =IF(C18="","",IFERROR(E18/C18,0)) | G18: =IF(E18="","",IF(E18>0,"Favorable",IF(E18<0,"Défavorable","Néant"))) | H18: =IF(F18="","",IF(ABS(F18)>0.15,"Haute",IF(ABS(F18)>0.05,"Moyenne","Basse")))
E19: =IF(C19="","",C19-D19) | F19: =IF(C19="","",IFERROR(E19/C19,0)) | G19: =IF(E19="","",IF(E19>0,"Favorable",IF(E19<0,"Défavorable","Néant"))) | H19: =IF(F19="","",IF(ABS(F19)>0.15,"Haute",IF(ABS(F19)>0.05,"Moyenne","Basse")))
E20: =IF(C20="","",C20-D20) | F20: =IF(C20="","",IFERROR(E20/C20,0)) | G20: =IF(E20="","",IF(E20>0,"Favorable",IF(E20<0,"Défavorable","Néant"))) | H20: =IF(F20="","",IF(ABS(F20)>0.15,"Haute",IF(ABS(F20)>0.05,"Moyenne","Basse")))
E21: =IF(C21="","",C21-D21) | F21: =IF(C21="","",IFERROR(E21/C21,0)) | G21: =IF(E21="","",IF(E21>0,"Favorable",IF(E21<0,"Défavorable","Néant"))) | H21: =IF(F21="","",IF(ABS(F21)>0.15,"Haute",IF(ABS(F21)>0.05,"Moyenne","Basse")))
E22: =IF(C22="","",C22-D22) | F22: =IF(C22="","",IFERROR(E22/C22,0)) | G22: =IF(E22="","",IF(E22>0,"Favorable",IF(E22<0,"Défavorable","Néant"))) | H22: =IF(F22="","",IF(ABS(F22)>0.15,"Haute",IF(ABS(F22)>0.05,"Moyenne","Basse")))
E23: =IF(C23="","",C23-D23) | F23: =IF(C23="","",IFERROR(E23/C23,0)) | G23: =IF(E23="","",IF(E23>0,"Favorable",IF(E23<0,"Défavorable","Néant"))) | H23: =IF(F23="","",IF(ABS(F23)>0.15,"Haute",IF(ABS(F23)>0.05,"Moyenne","Basse")))
E24: =IF(C24="","",C24-D24) | F24: =IF(C24="","",IFERROR(E24/C24,0)) | G24: =IF(E24="","",IF(E24>0,"Favorable",IF(E24<0,"Défavorable","Néant"))) | H24: =IF(F24="","",IF(ABS(F24)>0.15,"Haute",IF(ABS(F24)>0.05,"Moyenne","Basse")))
E25: =IF(C25="","",C25-D25) | F25: =IF(C25="","",IFERROR(E25/C25,0)) | G25: =IF(E25="","",IF(E25>0,"Favorable",IF(E25<0,"Défavorable","Néant"))) | H25: =IF(F25="","",IF(ABS(F25)>0.15,"Haute",IF(ABS(F25)>0.05,"Moyenne","Basse")))
... E115: =IF(C115="","",C115-D115) | F115: =IF(C115="","",IFERROR(E115/C115,0)) | G115: =IF(E115="","",IF(E115>0,"Favorable",IF(E115<0,"Défavorable","Néant"))) | H115: =IF(F115="","",IF(ABS(F115)>0.15,"Haute",IF(ABS(F115)>0.05,"Moyenne","Basse")))

Sheet F13 - 11-Optimisation Coûts
A2: DOMAINE 26 — 11-OPTIMISATION DES COÛTS RH
A3: TABLEAU DYNAMIQUE — Pistes d'économies et gains réalisés
A5: Code Action | B5: Département | C5: Poste Budgétaire | D5: Type d'Économie | E5: Économie Prévue (FCFA) | F5: Économie Réalisée (FCFA) | G5: Taux Réalisation (%) | H5: Date Mise en Œuvre | I5: Statut | J5: Commentaire
A6: OPT-001 | B6: Cuisine & Restauration | C6: Masse salariale | D6: Réduction heures supp. | E6: 5000000 | F6: 3200000 | G6: =IFERROR(F6/E6,0) | H6: 45689 | I6: En cours | J6: Planning optimisé
A7: OPT-002 | B7: Tous départements | C7: Charges patronales | D7: Réduction cotisations | E7: 3000000 | F7: 1800000 | G7: =IFERROR(F7/E7,0) | H7: 45672 | I7: En cours | J7: Dispositif réduction Fillon
A8: OPT-003 | B8: Direction Générale | C8: Primes & indemnités | D8: Révision grille primes | E8: 4000000 | F8: 2500000 | G8: =IFERROR(F8/E8,0) | H8: 45717 | I8: En cours | J8: Grille actualisée Q2
A9: OPT-004 | B9: Ressources Humaines | C9: Recrutement | D9: Internalisation recrutement | E9: 2000000 | F9: 1200000 | G9: =IFERROR(F9/E9,0) | H9: 45658 | I9: En cours | J9: Outil ATS interne déployé
A10: OPT-005 | B10: Tous départements | C10: Avantages sociaux | D10: Renégociation mutuelle | E10: 1500000 | F10: 900000 | G10: =IFERROR(F10/E10,0) | H10: 45748 | I10: Planifiée | J10: Appel d'offres en cours
A11: OPT-006 | B11: Ressources Humaines | C11: Formation | D11: E-learning | E11: 2500000 | F11: 1500000 | G11: =IFERROR(F11/E11,0) | H11: 45703 | I11: En cours | J11: Plateforme déployée
A12: OPT-007 | B12: Finance & Comptabilité | C12: Fiscalité salariale | D12: Crédit impôt apprentissage | E12: 800000 | F12: 600000 | G12: =IFERROR(F12/E12,0) | H12: 45658 | I12: En cours | J12: Déclaration en cours
A13: OPT-008 | B13: Maintenance & Technique | C13: Masse salariale | D13: Polyvalence agents | E13: 1800000 | F13: 700000 | G13: =IFERROR(F13/E13,0) | H13: 45731 | I13: En cours | J13: Formation croisée en cours
G14: =IF(E14="","",IFERROR(F14/E14,0))
G15: =IF(E15="","",IFERROR(F15/E15,0))
G16: =IF(E16="","",IFERROR(F16/E16,0))
G17: =IF(E17="","",IFERROR(F17/E17,0))
G18: =IF(E18="","",IFERROR(F18/E18,0))
G19: =IF(E19="","",IFERROR(F19/E19,0))
G20: =IF(E20="","",IFERROR(F20/E20,0))
G21: =IF(E21="","",IFERROR(F21/E21,0))
G22: =IF(E22="","",IFERROR(F22/E22,0))
G23: =IF(E23="","",IFERROR(F23/E23,0))
G24: =IF(E24="","",IFERROR(F24/E24,0))
G25: =IF(E25="","",IFERROR(F25/E25,0))
... G115: =IF(E115="","",IFERROR(F115/E115,0))

Sheet F14 - 12-Taxes CRDS CSG
A2: DOMAINE 26 — 12-TAXES SUR LES SALAIRES ET CRDS/CSG
A3: TABLEAU DYNAMIQUE — Détail des contributions assises sur les salaires
A5: Type Contribution | B5: Assiette (FCFA) | C5: Taux (%) | D5: Montant (FCFA) | E5: Part Employeur (FCFA) | F5: Part Salarié (FCFA) | G5: Répartition Employeur (%) | H5: Répartition Salarié (%) | I5: Exonération Possible | J5: Montant Exonéré (FCFA) | K5: Net Dû (FCFA)
A6: CSG déductible | B6: 128500000 | C6: 5.1 | D6: =IFERROR(B6*C6/100,0) | E6: =IFERROR(D6*G6/100,0) | F6: =IFERROR(D6*H6/100,0) | G6: 100 | H6: 0 | I6: Non | J6: 0 | K6: =D6-J6
A7: CSG non déductible | B7: 128500000 | C7: 2.4 | D7: =IFERROR(B7*C7/100,0) | E7: =IFERROR(D7*G7/100,0) | F7: =IFERROR(D7*H7/100,0) | G7: 100 | H7: 0 | I7: Non | J7: 0 | K7: =D7-J7
A8: CRDS | B8: 128500000 | C8: 0.5 | D8: =IFERROR(B8*C8/100,0) | E8: =IFERROR(D8*G8/100,0) | F8: =IFERROR(D8*H8/100,0) | G8: 100 | H8: 0 | I8: Non | J8: 0 | K8: =D8-J8
A9: Taxe sur les salaires tranche 1 | B9: 128500000 | C9: 4.25 | D9: =IFERROR(B9*C9/100,0) | E9: =IFERROR(D9*G9/100,0) | F9: =IFERROR(D9*H9/100,0) | G9: 100 | H9: 0 | I9: Non | J9: 0 | K9: =D9-J9
A10: Taxe sur les salaires tranche 2 | B10: 128500000 | C10: 8.5 | D10: =IFERROR(B10*C10/100,0) | E10: =IFERROR(D10*G10/100,0) | F10: =IFERROR(D10*H10/100,0) | G10: 100 | H10: 0 | I10: Association | J10: 300000 | K10: =D10-J10
A11: Forfait social 8% | B11: 15000000 | C11: 8 | D11: =IFERROR(B11*C11/100,0) | E11: =IFERROR(D11*G11/100,0) | F11: =IFERROR(D11*H11/100,0) | G11: 100 | H11: 0 | I11: Non | J11: 0 | K11: =D11-J11
A12: Forfait social 20% | B12: 15000000 | C12: 20 | D12: =IFERROR(B12*C12/100,0) | E12: =IFERROR(D12*G12/100,0) | F12: =IFERROR(D12*H12/100,0) | G12: 100 | H12: 0 | I12: Non | J12: 0 | K12: =D12-J12
A13: Contribution solidarité autonomie | B13: 128500000 | C13: 0.3 | D13: =IFERROR(B13*C13/100,0) | E13: =IFERROR(D13*G13/100,0) | F13: =IFERROR(D13*H13/100,0) | G13: 100 | H13: 0 | I13: Non | J13: 0 | K13: =D13-J13
D14: =IF(B14="","",IFERROR(B14*C14/100,0)) | E14: =IF(D14="","",IFERROR(D14*G14/100,0)) | F14: =IF(D14="","",IFERROR(D14*H14/100,0)) | K14: =IF(D14="","",D14-J14)
D15: =IF(B15="","",IFERROR(B15*C15/100,0)) | E15: =IF(D15="","",IFERROR(D15*G15/100,0)) | F15: =IF(D15="","",IFERROR(D15*H15/100,0)) | K15: =IF(D15="","",D15-J15)
D16: =IF(B16="","",IFERROR(B16*C16/100,0)) | E16: =IF(D16="","",IFERROR(D16*G16/100,0)) | F16: =IF(D16="","",IFERROR(D16*H16/100,0)) | K16: =IF(D16="","",D16-J16)
D17: =IF(B17="","",IFERROR(B17*C17/100,0)) | E17: =IF(D17="","",IFERROR(D17*G17/100,0)) | F17: =IF(D17="","",IFERROR(D17*H17/100,0)) | K17: =IF(D17="","",D17-J17)
D18: =IF(B18="","",IFERROR(B18*C18/100,0)) | E18: =IF(D18="","",IFERROR(D18*G18/100,0)) | F18: =IF(D18="","",IFERROR(D18*H18/100,0)) | K18: =IF(D18="","",D18-J18)
D19: =IF(B19="","",IFERROR(B19*C19/100,0)) | E19: =IF(D19="","",IFERROR(D19*G19/100,0)) | F19: =IF(D19="","",IFERROR(D19*H19/100,0)) | K19: =IF(D19="","",D19-J19)
D20: =IF(B20="","",IFERROR(B20*C20/100,0)) | E20: =IF(D20="","",IFERROR(D20*G20/100,0)) | F20: =IF(D20="","",IFERROR(D20*H20/100,0)) | K20: =IF(D20="","",D20-J20)
D21: =IF(B21="","",IFERROR(B21*C21/100,0)) | E21: =IF(D21="","",IFERROR(D21*G21/100,0)) | F21: =IF(D21="","",IFERROR(D21*H21/100,0)) | K21: =IF(D21="","",D21-J21)
D22: =IF(B22="","",IFERROR(B22*C22/100,0)) | E22: =IF(D22="","",IFERROR(D22*G22/100,0)) | F22: =IF(D22="","",IFERROR(D22*H22/100,0)) | K22: =IF(D22="","",D22-J22)
D23: =IF(B23="","",IFERROR(B23*C23/100,0)) | E23: =IF(D23="","",IFERROR(D23*G23/100,0)) | F23: =IF(D23="","",IFERROR(D23*H23/100,0)) | K23: =IF(D23="","",D23-J23)
D24: =IF(B24="","",IFERROR(B24*C24/100,0)) | E24: =IF(D24="","",IFERROR(D24*G24/100,0)) | F24: =IF(D24="","",IFERROR(D24*H24/100,0)) | K24: =IF(D24="","",D24-J24)
D25: =IF(B25="","",IFERROR(B25*C25/100,0)) | E25: =IF(D25="","",IFERROR(D25*G25/100,0)) | F25: =IF(D25="","",IFERROR(D25*H25/100,0)) | K25: =IF(D25="","",D25-J25)
... D115: =IF(B115="","",IFERROR(B115*C115/100,0)) | E115: =IF(D115="","",IFERROR(D115*G115/100,0)) | F115: =IF(D115="","",IFERROR(D115*H115/100,0)) | K115: =IF(D115="","",D115-J115)

Sheet F15 - 13-Charges Diverses RH
A2: DOMAINE 26 — 13-CHARGES DIVERSES RH (FORMATION/SÉCURITÉ/MOBILITÉ)
A3: TABLEAU DYNAMIQUE — Suivi des charges transversales RH
A5: Poste de Charge | B5: Département | C5: Nature | D5: Budget Annuel (FCFA) | E5: Q1 Consommé (FCFA) | F5: Q2 Consommé (FCFA) | G5: Q3 Consommé (FCFA) | H5: Q4 Consommé (FCFA) | I5: Total Consommé (FCFA) | J5: Reste (FCFA) | K5: Taux Consommation (%) | L5: Observation
A6: Formation continue | B6: RH | C6: Charges de formation | D6: 15000000 | E6: 3200000 | F6: 2800000 | G6: 1500000 | H6: 1200000 | I6: =SUM(E6:H6) | J6: =D6-I6 | K6: =IFERROR(I6/D6,0) | L6: Programme e-learning lancé
A7: Sécurité au travail | B7: Tous | C7: Charges SST | D7: 12000000 | E7: 2500000 | F7: 2100000 | G7: 1800000 | H7: 1400000 | I7: =SUM(E7:H7) | J7: =D7-I7 | K7: =IFERROR(I7/D7,0) | L7: EPI renouvelés Q2
A8: Recrutement externe | B8: RH | C8: Charges recrutement | D8: 8000000 | E8: 1800000 | F8: 2200000 | G8: 1200000 | H8: 1000000 | I8: =SUM(E8:H8) | J8: =D8-I8 | K8: =IFERROR(I8/D8,0) | L8: 3 recrutements clés Q2
A9: Mobilité interne | B9: RH | C9: Charges de mobilité | D9: 5000000 | E9: 800000 | F9: 1200000 | G9: 600000 | H9: 400000 | I9: =SUM(E9:H9) | J9: =D9-I9 | K9: =IFERROR(I9/D9,0) | L9: Mutations planifiées
A10: Cabinet conseil RH | B10: DG | C10: Honoraires | D10: 6000000 | E10: 1500000 | F10: 1500000 | G10: 1500000 | H10: 1500000 | I10: =SUM(E10:H10) | J10: =D10-I10 | K10: =IFERROR(I10/D10,0) | L10: Contrat annuel fixe
A11: Logiciels RH (SIRH) | B11: RH | C11: Investissement | D11: 4000000 | E11: 3000000 | F11: 500000 | G11: 200000 | H11: 300000 | I11: =SUM(E11:H11) | J11: =D11-I11 | K11: =IFERROR(I11/D11,0) | L11: Déploiement terminé Q1
A12: Audit social | B12: RH | C12: Honoraires | D12: 2000000 | E12: 0 | F12: 2000000 | G12: 0 | H12: 0 | I12: =SUM(E12:H12) | J12: =D12-I12 | K12: =IFERROR(I12/D12,0) | L12: Audit biennal planifié Q2
A13: Actions sociales | B13: RH | C13: Charges sociales | D13: 3500000 | E13: 800000 | F13: 900000 | G13: 700000 | H13: 600000 | I13: =SUM(E13:H13) | J13: =D13-I13 | K13: =IFERROR(I13/D13,0) | L13: CE et activités sociales
I14: =IF(D14="","",SUM(E14:H14)) | J14: =IF(D14="","",D14-I14) | K14: =IF(D14="","",IFERROR(I14/D14,0))
I15: =IF(D15="","",SUM(E15:H15)) | J15: =IF(D15="","",D15-I15) | K15: =IF(D15="","",IFERROR(I15/D15,0))
I16: =IF(D16="","",SUM(E16:H16)) | J16: =IF(D16="","",D16-I16) | K16: =IF(D16="","",IFERROR(I16/D16,0))
I17: =IF(D17="","",SUM(E17:H17)) | J17: =IF(D17="","",D17-I17) | K17: =IF(D17="","",IFERROR(I17/D17,0))
I18: =IF(D18="","",SUM(E18:H18)) | J18: =IF(D18="","",D18-I18) | K18: =IF(D18="","",IFERROR(I18/D18,0))
I19: =IF(D19="","",SUM(E19:H19)) | J19: =IF(D19="","",D19-I19) | K19: =IF(D19="","",IFERROR(I19/D19,0))
I20: =IF(D20="","",SUM(E20:H20)) | J20: =IF(D20="","",D20-I20) | K20: =IF(D20="","",IFERROR(I20/D20,0))
I21: =IF(D21="","",SUM(E21:H21)) | J21: =IF(D21="","",D21-I21) | K21: =IF(D21="","",IFERROR(I21/D21,0))
I22: =IF(D22="","",SUM(E22:H22)) | J22: =IF(D22="","",D22-I22) | K22: =IF(D22="","",IFERROR(I22/D22,0))
I23: =IF(D23="","",SUM(E23:H23)) | J23: =IF(D23="","",D23-I23) | K23: =IF(D23="","",IFERROR(I23/D23,0))
I24: =IF(D24="","",SUM(E24:H24)) | J24: =IF(D24="","",D24-I24) | K24: =IF(D24="","",IFERROR(I24/D24,0))
I25: =IF(D25="","",SUM(E25:H25)) | J25: =IF(D25="","",D25-I25) | K25: =IF(D25="","",IFERROR(I25/D25,0))
... I115: =IF(D115="","",SUM(E115:H115)) | J115: =IF(D115="","",D115-I115) | K115: =IF(D115="","",IFERROR(I115/D115,0))

Sheet F16 - 14-Reporting Mensuel
A2: DOMAINE 26 — 14-REPORTING BUDGÉTAIRE MENSUEL
A3: TABLEAU DYNAMIQUE — Synthèse mensuelle par grande catégorie
A5: Mois | B5: Masse Salariale (FCFA) | C5: Charges Sociales (FCFA) | D5: Fiscalité (FCFA) | E5: Formation (FCFA) | F5: Avantages (FCFA) | G5: Autres (FCFA) | H5: Total Mois (FCFA) | I5: Budget Mensuel (FCFA) | J5: Écart Mensuel (FCFA) | K5: Cumul Annuel (FCFA) | L5: Budget Annuel (FCFA) | M5: Écart Annuel (FCFA) | N5: Taux Réalisation (%)
A6: Janvier 2025 | B6: 18500000 | C6: 6500000 | D6: 5200000 | E6: 800000 | F6: 1500000 | G6: 1200000 | H6: =SUM(B6:G6) | I6: 35000000 | J6: =I6-H6 | K6: =H6 | L6: 572000000 | M6: =L6-K6 | N6: =IFERROR(K6/L6,0)
A7: Février 2025 | B7: 18700000 | C7: 6550000 | D7: 5250000 | E7: 700000 | F7: 1480000 | G7: 1150000 | H7: =SUM(B7:G7) | I7: 35000000 | J7: =I7-H7 | K7: =K6+H7 | L7: 572000000 | M7: =L7-K7 | N7: =IFERROR(K7/L7,0)
A8: Mars 2025 | B8: 19200000 | C8: 6700000 | D8: 5300000 | E8: 1200000 | F8: 1520000 | G8: 1800000 | H8: =SUM(B8:G8) | I8: 37000000 | J8: =I8-H8 | K8: =K7+H8 | L8: 572000000 | M8: =L8-K8 | N8: =IFERROR(K8/L8,0)
A9: Avril 2025 | B9: 19200000 | C9: 6720000 | D9: 5350000 | E9: 1000000 | F9: 1500000 | G9: 1600000 | H9: =SUM(B9:G9) | I9: 36500000 | J9: =I9-H9 | K9: =K8+H9 | L9: 572000000 | M9: =L9-K9 | N9: =IFERROR(K9/L9,0)
A10: Mai 2025 | B10: 18800000 | C10: 6580000 | D10: 5250000 | E10: 800000 | F10: 1490000 | G10: 1250000 | H10: =SUM(B10:G10) | I10: 35500000 | J10: =I10-H10 | K10: =K9+H10 | L10: 572000000 | M10: =L10-K10 | N10: =IFERROR(K10/L10,0)
A11: Juin 2025 | B11: 19500000 | C11: 6820000 | D11: 5400000 | E11: 600000 | F11: 1500000 | G11: 1500000 | H11: =SUM(B11:G11) | I11: 36000000 | J11: =I11-H11 | K11: =K10+H11 | L11: 572000000 | M11: =L11-K11 | N11: =IFERROR(K11/L11,0)
