Workbook

Sheet _Données Employés
B4: Matricule | C4: Civilité | D4: Nom | E4: Prénom | F4: Département | G4: Poste | H4: Salaire Base (FCFA)
B5: EMP-001 | C5: M. | D5: Nganou | E5: Clarisse | F5: Cuisine & Restauration | G5: Chef cuisinier | H5: 450000
B6: EMP-002 | C6: M. | D6: Tchinda | E6: Armand | F6: Réception & Front Office | G6: Réceptionniste | H6: 220000
B7: EMP-003 | C7: Mme | D7: Fotso | E7: Marguerite | F7: Finance & Comptabilité | G7: Comptable senior | H7: 380000
B8: EMP-004 | C8: M. | D8: Nkoulou | E8: Mbarga | F8: Étage & Housekeeping | G8: Gouvernant | H8: 195000
B9: EMP-005 | C9: M. | D9: Kamga | E9: Paul | F9: Maintenance | G9: Technicien maintenance | H9: 165000
B10: EMP-006 | C10: Mme | D10: Ngo | E10: Delphine | F10: Service Client | G10: Conseiller clientèle | H10: 160000
B11: EMP-007 | C11: M. | D11: Essomba | E11: Serge | F11: Maintenance | G11: Agent entretien | H11: 130000
B12: EMP-008 | C12: M. | D12: Tchouankou | E12: Paul | F12: Commercial | G12: Commercial | H12: 150000
B13: EMP-009 | C13: M. | D13: Fokam | E13: Eric | F13: Maintenance | G13: Technicien | H13: 140000
B14: EMP-010 | C14: M. | D14: Tagne | E14: René | F14: Cuisine & Restauration | G14: Plongeur | H14: 90000
B15: EMP-011 | C15: M. | D15: Bouba | E15: Ahmed | F15: Sécurité | G15: Agent Sécurité | H15: 120000
B16: EMP-012 | C16: Mme | D16: Awa | E16: Fatou | F16: Réception & Front Office | G16: Standardiste | H16: 155000
... B18: EMP-029 | C18: M. | D18: Kamga | E18: Patrice | F18: Sécurité | G18: Chef Sécurité | H18: 210000

Sheet 1-Tableau de Bord
B2: DOMAINE 5 — CONGES, ABSENCES & PRESENCE
B3: TABLEAU DE BORD — Vue synthetique de tous les indicateurs du domaine (mis a jour automatiquement)
B5: Droits acquis (j) | E5: Conges pris (j) | H5: Solde disponible (j) | K5: Depart en cours
B6: =SUM('2-Compteur Conges Payes'!G5:G104) | E6: =SUM('2-Compteur Conges Payes'!H5:H104) | H6: =SUM('2-Compteur Conges Payes'!J5:J104) | K6: =COUNTIF('3-Planning Departs Conge'!M5:M104,"En cours")
B9: Permissions accordées | E9: Absences NJ (total) | H9: Retards cumules (min) | K9: Arrets maladie (j)
B10: =COUNTIF('4-Permissions Speciales'!K5:K104,"<>") | E10: =SUM('6-Absences Non Justifiees'!I5:I104) | H10: =SUM('7-Retards & Departs Anticipes'!J5:J104) | K10: =SUM('8-Arrets Maladie'!I5:I104)
B13: Accidents travail | E13: Maternite en cours | H13: Taux absenteisme moy. | K13: Score presence moyen
B14: =COUNTIF('9-Arrets Accident Travail'!B5:B104,"<>") | E14: =COUNTIF('10-Conges Maternite Paternite'!M5:M104,"En cours") | H14: =IFERROR(AVERAGE('11-Taux Absenteisme'!K5:K104),0) | K14: =IFERROR(AVERAGE('17-Compteurs Absences Employe'!L5:L104),0)
B17: CS sans solde | E17: Conges forces (j) | H17: Pointages saisis | K17: Rapports d'absences
B18: =COUNTIF('5-Conges Sans Solde'!B5:B104,"<>") | E18: =SUM('13-Conge Force & Repos Impose'!G5:G104) | H18: =COUNTIF('12-Journal de Pointage'!B5:B104,"<>") | K18: =COUNTIF('18-Rapports & Stat Absences'!B5:B104,"<>")
B22: ABSENCES PAR MOTIF & PAR DEPARTEMENT
B23: Motif | C23: Nombre
B24: Conge annuel | C24: =SUM('2-Compteur Conges Payes'!H5:H104)
B25: Arret maladie | C25: =SUM('8-Arrets Maladie'!I5:I104)
B26: Absence injustifiee | C26: =SUM('6-Absences Non Justifiees'!I5:I104)
B27: Retard | C27: =COUNTIF('7-Retards & Departs Anticipes'!B5:B104,"<>")
B28: Permission speciale | C28: =COUNTIF('4-Permissions Speciales'!B5:B104,"<>")
B29: Accident travail | C29: =COUNTIF('9-Arrets Accident Travail'!B5:B104,"<>")
B30: Conge sans solde | C30: =COUNTIF('5-Conges Sans Solde'!B5:B104,"<>")
H32: Service | I32: Taux Abs.
H33: RH | I33: =IFERROR(AVERAGEIF('11-Taux Absenteisme'!C5:C104,"*"&H33&"*",'11-Taux Absenteisme'!K5:K104),0)
H34: Informatique | I34: =IFERROR(AVERAGEIF('11-Taux Absenteisme'!C5:C104,"*"&H34&"*",'11-Taux Absenteisme'!K5:K104),0)
H35: Finance | I35: =IFERROR(AVERAGEIF('11-Taux Absenteisme'!C5:C104,"*"&H35&"*",'11-Taux Absenteisme'!K5:K104),0)
H36: Reception | I36: =IFERROR(AVERAGEIF('11-Taux Absenteisme'!C5:C104,"*"&H36&"*",'11-Taux Absenteisme'!K5:K104),0)
H37: Cuisine | I37: =IFERROR(AVERAGEIF('11-Taux Absenteisme'!C5:C104,"*"&H37&"*",'11-Taux Absenteisme'!K5:K104),0)
H38: Entretien | I38: =IFERROR(AVERAGEIF('11-Taux Absenteisme'!C5:C104,"*"&H38&"*",'11-Taux Absenteisme'!K5:K104),0)
H39: Securite | I39: =IFERROR(AVERAGEIF('11-Taux Absenteisme'!C5:C104,"*"&H39&"*",'11-Taux Absenteisme'!K5:K104),0)

Sheet _Lists
B1: departement | C1: poste_hotel | D1: type_conge | E1: statut_conge | F1: motif_permission | G1: duree_legale | H1: type_absence | I1: sanction_absence | J1: statut_absence | K1: type_retard | L1: statut_retard | M1: type_arret | N1: statut_arret | O1: certificat | P1: cause_accident | Q1: type_suivi | R1: mois | S1: annee | T1: statut_rapport
B2: Direction Générale | C2: DG | D2: Conge annuel | E2: Planifie | F2: Mariage | G2: 1 jour | H2: Absence injustifiee | I2: Avertissement oral | J2: En cours | K2: Retard arrivee | L2: Justifie | M2: Arret maladie | N2: En cours | O2: Oui | P2: Chute | Q2: Reprise progressive | R2: Janvier | S2: 2024 | T2: Brouillon
B3: Ressources Humaines | C3: DRH | D3: Conge de maternite | E3: En cours | F3: Deces conjoint | G3: 2 jours | H3: Abandon de poste | I3: Avertissement ecrit | J3: Justifiee a posteriori | K3: Depart anticipe | L3: Non justifie | M3: Arret accident du travail | N3: Prolonge | O3: Non | P3: Coupure/brulure | Q3: Reprise pleine | R3: Fevrier | S3: 2025 | T3: Valide
B4: Finance & Comptabilité | C4: Assistante RH | D4: Conge de paternite | E4: Termine | F4: Deces enfant | G4: 3 jours | H4: Non presentation | I4: Blame | J4: Sanctionnee | K4: Pause allongee | L4: Tolere | M4: Arret maladie professionnelle | N4: Termine | O4: En attente | P4: Manutention | Q4: Visite de reprise | R4: Mars | S4: 2026 | T4: Approuve
B5: Marketing & Communication | C5: DAF | D5: Conge sans solde | E5: Annule | F5: Deces parent | G5: 4 jours | H5: Desertion | I5: Mise a pied 1 jour | J5: Cloturee | K5: Retour pause tardif | L5: Sanctionne | M5: Conge maternite | N5: Reprise | O5: Non requis | P5: Choc | Q5: Aptitude | R5: Avril | T5: Rejete
B6: Informatique | C6: Comptable senior | D6: Permission speciale | E6: Refuse | F6: Deces beau-parent | G6: 5 jours | H6: Absent sans autorisation | I6: Mise a pied 3 jours | J6: En attente | M6: Conge paternite | N6: En attente de justification | P6: Exposition chimique | Q6: Inaptitude | R6: Mai
B7: Commercial | C7: Chef Comptable | D7: Conge force | E7: En attente | F7: Naissance | G7: 7 jours | I7: Licenciement | M7: Hospitalisation | P7: Accident de trajet | R7: Juin
B8: Logistique & Approvisionnement | C8: Chef Marketing | D8: Repos compensatoire | F8: Bapteme | G8: 10 jours | P8: Autre | R8: Juillet
B9: Production | C9: Chef de service IT | D9: Conge sabbatique | F9: Demenagement | G9: 14 jours | R9: Aout
B10: Service Client | C10: Technicien IT | F10: Evenement familial | G10: 1 mois | R10: Septembre
B11: Reception & Front Office | C11: Chef Commercial | F11: Examen | G11: 3 mois | R11: Octobre
B12: Cuisine & Restauration | C12: Agent Commercial | G12: Variable | R12: Novembre
B13: Maintenance | C13: Chef Logistique | R13: Decembre
B14: Sécurité | C14: Magasinier
B15: Réception & Front Office | C15: Chef Reception
B16: Étage & Housekeeping | C16: Receptionniste
C17: Concierge
C18: Chef Cuisine
C19: Sous-Chef
C20: Cuisinier
C21: Plongeur
C22: Chef Entretien
C23: Agent Entretien
C24: Chef Securite
C25: Agent Securite

Sheet 2-Compteur Conges Payes
B2: COMPTEUR ANNUEL DE CONGES PAYES (#52)
B3: TABLEAU DYNAMIQUE — Saisissez dans la prochaine ligne jaune. Les calculs se mettent a jour automatiquement.
B4: N° Compteur | C4: Matricule | D4: Nom Employe | E4: Departement | F4: Annee | G4: Droits Acquis (j) | H4: Conges Pris (j) | I4: Conges Planifies (j) | J4: Solde Disponible (j) | K4: Report N-1 (j) | L4: Jours Perdus (j) | M4: Statut
B5: CC-001 | C5: EMP-001 | D5: =IF(C5="","",VLOOKUP(C5,'_Données Employés'!$B$5:$H$18,4,FALSE)&" "&VLOOKUP(C5,'_Données Employés'!$B$5:$H$18,5,FALSE)) | E5: =IF(C5="","",VLOOKUP(C5,'_Données Employés'!$B$5:$H$18,6,FALSE)) | F5: 2025 | G5: 30 | H5: 5 | I5: 10 | J5: 15 | K5: 0 | L5: 0 | M5: En cours
B6: CC-002 | C6: EMP-002 | D6: =IF(C6="","",VLOOKUP(C6,'_Données Employés'!$B$5:$H$18,4,FALSE)&" "&VLOOKUP(C6,'_Données Employés'!$B$5:$H$18,5,FALSE)) | E6: =IF(C6="","",VLOOKUP(C6,'_Données Employés'!$B$5:$H$18,6,FALSE)) | F6: 2025 | G6: 30 | H6: 0 | I6: 7 | J6: 23 | K6: 2 | L6: 0 | M6: En cours
B7: CC-003 | C7: EMP-003 | D7: =IF(C7="","",VLOOKUP(C7,'_Données Employés'!$B$5:$H$18,4,FALSE)&" "&VLOOKUP(C7,'_Données Employés'!$B$5:$H$18,5,FALSE)) | E7: =IF(C7="","",VLOOKUP(C7,'_Données Employés'!$B$5:$H$18,6,FALSE)) | F7: 2025 | G7: 30 | H7: 10 | I7: 5 | J7: 15 | K7: 0 | L7: 0 | M7: En cours
B8: CC-004 | C8: EMP-004 | D8: =IF(C8="","",VLOOKUP(C8,'_Données Employés'!$B$5:$H$18,4,FALSE)&" "&VLOOKUP(C8,'_Données Employés'!$B$5:$H$18,5,FALSE)) | E8: =IF(C8="","",VLOOKUP(C8,'_Données Employés'!$B$5:$H$18,6,FALSE)) | F8: 2025 | G8: 30 | H8: 8 | I8: 0 | J8: 22 | K8: 0 | L8: 0 | M8: En cours
B9: CC-005 | C9: EMP-005 | D9: =IF(C9="","",VLOOKUP(C9,'_Données Employés'!$B$5:$H$18,4,FALSE)&" "&VLOOKUP(C9,'_Données Employés'!$B$5:$H$18,5,FALSE)) | E9: =IF(C9="","",VLOOKUP(C9,'_Données Employés'!$B$5:$H$18,6,FALSE)) | F9: 2025 | G9: 30 | H9: 15 | I9: 5 | J9: 10 | K9: 0 | L9: 0 | M9: En cours
B10: CC-028 | C10: EMP-028 | D10: =IF(C10="","",VLOOKUP(C10,'_Données Employés'!$B$5:$H$18,4,FALSE)&" "&VLOOKUP(C10,'_Données Employés'!$B$5:$H$18,5,FALSE)) | E10: =IF(C10="","",VLOOKUP(C10,'_Données Employés'!$B$5:$H$18,6,FALSE)) | F10: 2025 | G10: 30 | H10: 0 | I10: 0 | J10: 30 | K10: 0 | L10: 0 | M10: En cours
B11: CC-029 | C11: EMP-029 | D11: =IF(C11="","",VLOOKUP(C11,'_Données Employés'!$B$5:$H$18,4,FALSE)&" "&VLOOKUP(C11,'_Données Employés'!$B$5:$H$18,5,FALSE)) | E11: =IF(C11="","",VLOOKUP(C11,'_Données Employés'!$B$5:$H$18,6,FALSE)) | F11: 2025 | G11: 30 | H11: 0 | I11: 0 | J11: 30 | K11: 0 | L11: 0 | M11: En cours
B12: =IF(C12="","CC-"&TEXT(COUNTA($C$5:C12),"000")) | J12: =IF(G12="","",G12-H12-I12)
B13: =IF(C13="","CC-"&TEXT(COUNTA($C$5:C13),"000")) | J13: =IF(G13="","",G13-H13-I13)
B14: =IF(C14="","CC-"&TEXT(COUNTA($C$5:C14),"000")) | J14: =IF(G14="","",G14-H14-I14)
B15: =IF(C15="","CC-"&TEXT(COUNTA($C$5:C15),"000")) | J15: =IF(G15="","",G15-H15-I15)
B16: =IF(C16="","CC-"&TEXT(COUNTA($C$5:C16),"000")) | J16: =IF(G16="","",G16-H16-I16)
B17: =IF(C17="","CC-"&TEXT(COUNTA($C$5:C17),"000")) | J17: =IF(G17="","",G17-H17-I17)
B18: =IF(C18="","CC-"&TEXT(COUNTA($C$5:C18),"000")) | J18: =IF(G18="","",G18-H18-I18)
B19: =IF(C19="","CC-"&TEXT(COUNTA($C$5:C19),"000")) | J19: =IF(G19="","",G19-H19-I19)
B20: =IF(C20="","CC-"&TEXT(COUNTA($C$5:C20),"000")) | J20: =IF(G20="","",G20-H20-I20)
B21: =IF(C21="","CC-"&TEXT(COUNTA($C$5:C21),"000")) | J21: =IF(G21="","",G21-H21-I21)
B22: =IF(C22="","CC-"&TEXT(COUNTA($C$5:C22),"000")) | J22: =IF(G22="","",G22-H22-I22)
B23: =IF(C23="","CC-"&TEXT(COUNTA($C$5:C23),"000")) | J23: =IF(G23="","",G23-H23-I23)
... B109: =IF(C109="","CC-"&TEXT(COUNTA($C$5:C109),"000")) | J109: =IF(G109="","",G109-H109-I109)
B111: TOTAL | G111: =SUM(G5:G104) | H111: =SUM(H5:H104) | I111: =SUM(I5:I104) | J111: =SUM(J5:J104)
B113: INDICATEURS (mis a jour automatiquement)
B114: Employes suivis | D114: Total droits acquis (j) | F114: Total conges pris (j) | H114: Solde moyen (j)
B115: =COUNTIF(B5:B104,"<>") | D115: =SUM(G5:G104) | F115: =SUM(H5:H104) | H115: =IFERROR(AVERAGE(J5:J104),0)

Sheet 3-Planning Departs Conge
B2: PLAN DE DEPART EN CONGE (#53)
B3: TABLEAU DYNAMIQUE — Saisissez dans la prochaine ligne jaune. Les calculs se mettent a jour automatiquement.
B4: N° Planning | C4: Matricule | D4: Nom Employe | E4: Departement | F4: Type Conge | G4: Date Debut | H4: Date Fin | I4: Nb Jours | J4: Remplacement | K4: Chevauchement | L4: Validation N+1 | M4: Statut
B5: PC-001 | C5: EMP-001 | D5: =IF(C5="","",VLOOKUP(C5,'_Données Employés'!$B$5:$H$18,4,FALSE)&" "&VLOOKUP(C5,'_Données Employés'!$B$5:$H$18,5,FALSE)) | E5: =IF(C5="","",VLOOKUP(C5,'_Données Employés'!$B$5:$H$18,6,FALSE)) | F5: Conge annuel | G5: 45852 | H5: 45863 | I5: 10 | J5: Assistante RH | K5: Non | L5: Oui | M5: Planifie
B6: PC-002 | C6: EMP-002 | D6: =IF(C6="","",VLOOKUP(C6,'_Données Employés'!$B$5:$H$18,4,FALSE)&" "&VLOOKUP(C6,'_Données Employés'!$B$5:$H$18,5,FALSE)) | E6: =IF(C6="","",VLOOKUP(C6,'_Données Employés'!$B$5:$H$18,6,FALSE)) | F6: Conge annuel | G6: 45873 | H6: 45884 | I6: 10 | J6: Technicien IT | K6: Non | L6: Oui | M6: Planifie
B7: PC-003 | C7: EMP-004 | D7: =IF(C7="","",VLOOKUP(C7,'_Données Employés'!$B$5:$H$18,4,FALSE)&" "&VLOOKUP(C7,'_Données Employés'!$B$5:$H$18,5,FALSE)) | E7: =IF(C7="","",VLOOKUP(C7,'_Données Employés'!$B$5:$H$18,6,FALSE)) | F7: Conge annuel | G7: 45845 | H7: 45856 | I7: 10 | J7: Receptionniste interim | K7: Oui | L7: Oui | M7: Planifie
B8: PC-004 | C8: EMP-005 | D8: =IF(C8="","",VLOOKUP(C8,'_Données Employés'!$B$5:$H$18,4,FALSE)&" "&VLOOKUP(C8,'_Données Employés'!$B$5:$H$18,5,FALSE)) | E8: =IF(C8="","",VLOOKUP(C8,'_Données Employés'!$B$5:$H$18,6,FALSE)) | F8: Conge annuel | G8: 45831 | H8: 45842 | I8: 8 | J8: Cuisinier stagiaire | K8: Non | L8: Oui | M8: En cours
B9: PC-005 | C9: EMP-003 | D9: =IF(C9="","",VLOOKUP(C9,'_Données Employés'!$B$5:$H$18,4,FALSE)&" "&VLOOKUP(C9,'_Données Employés'!$B$5:$H$18,5,FALSE)) | E9: =IF(C9="","",VLOOKUP(C9,'_Données Employés'!$B$5:$H$18,6,FALSE)) | F9: Conge annuel | G9: 45901 | H9: 45912 | I9: 10 | J9: Comptable junior | K9: Non | L9: En attente | M9: En attente
B10: =IF(C10="","PC-"&TEXT(COUNTA($C$5:C10),"000")) | I10: =IF(G10="","",H10-G10+1)
B11: =IF(C11="","PC-"&TEXT(COUNTA($C$5:C11),"000")) | I11: =IF(G11="","",H11-G11+1)
B12: =IF(C12="","PC-"&TEXT(COUNTA($C$5:C12),"000")) | I12: =IF(G12="","",H12-G12+1)
B13: =IF(C13="","PC-"&TEXT(COUNTA($C$5:C13),"000")) | I13: =IF(G13="","",H13-G13+1)
B14: =IF(C14="","PC-"&TEXT(COUNTA($C$5:C14),"000")) | I14: =IF(G14="","",H14-G14+1)
B15: =IF(C15="","PC-"&TEXT(COUNTA($C$5:C15),"000")) | I15: =IF(G15="","",H15-G15+1)
B16: =IF(C16="","PC-"&TEXT(COUNTA($C$5:C16),"000")) | I16: =IF(G16="","",H16-G16+1)
B17: =IF(C17="","PC-"&TEXT(COUNTA($C$5:C17),"000")) | I17: =IF(G17="","",H17-G17+1)
B18: =IF(C18="","PC-"&TEXT(COUNTA($C$5:C18),"000")) | I18: =IF(G18="","",H18-G18+1)
B19: =IF(C19="","PC-"&TEXT(COUNTA($C$5:C19),"000")) | I19: =IF(G19="","",H19-G19+1)
B20: =IF(C20="","PC-"&TEXT(COUNTA($C$5:C20),"000")) | I20: =IF(G20="","",H20-G20+1)
B21: =IF(C21="","PC-"&TEXT(COUNTA($C$5:C21),"000")) | I21: =IF(G21="","",H21-G21+1)
... B109: =IF(C109="","PC-"&TEXT(COUNTA($C$5:C109),"000")) | I109: =IF(G109="","",H109-G109+1)
B111: TOTAL | I111: =SUM(I5:I104)
B113: INDICATEURS (mis a jour automatiquement)
B114: Departs planifies | D114: Total jours conge (j) | F114: Chevauchements | H114: En cours
B115: =COUNTIF(B5:B104,"<>") | D115: =SUM(I5:I104) | F115: =COUNTIF(K5:K104,"Oui") | H115: =COUNTIF(M5:M104,"En cours")

Sheet 4-Permissions Speciales
B2: SUIVI DES PERMISSIONS SPECIALES (#54)
B3: TABLEAU DYNAMIQUE — Saisissez dans la prochaine ligne jaune. Les calculs se mettent a jour automatiquement.
B4: N° Permission | C4: Matricule | D4: Nom Employe | E4: Departement | F4: Evenement | G4: Duree Legale | H4: Date Debut | I4: Date Fin | J4: Nb Jours | K4: Statut
B5: PS-001 | C5: EMP-003 | D5: =IF(C5="","",VLOOKUP(C5,'_Données Employés'!$B$5:$H$18,4,FALSE)&" "&VLOOKUP(C5,'_Données Employés'!$B$5:$H$18,5,FALSE)) | E5: =IF(C5="","",VLOOKUP(C5,'_Données Employés'!$B$5:$H$18,6,FALSE)) | F5: Mariage | G5: 4 jours | H5: 45884 | I5: 45887 | J5: 4 | K5: Planifie
B6: PS-002 | C6: EMP-002 | D6: =IF(C6="","",VLOOKUP(C6,'_Données Employés'!$B$5:$H$18,4,FALSE)&" "&VLOOKUP(C6,'_Données Employés'!$B$5:$H$18,5,FALSE)) | E6: =IF(C6="","",VLOOKUP(C6,'_Données Employés'!$B$5:$H$18,6,FALSE)) | F6: Deces parent | G6: 3 jours | H6: 45787 | I6: 45789 | J6: 3 | K6: Termine
B7: PS-003 | C7: EMP-004 | D7: =IF(C7="","",VLOOKUP(C7,'_Données Employés'!$B$5:$H$18,4,FALSE)&" "&VLOOKUP(C7,'_Données Employés'!$B$5:$H$18,5,FALSE)) | E7: =IF(C7="","",VLOOKUP(C7,'_Données Employés'!$B$5:$H$18,6,FALSE)) | F7: Naissance | G7: 3 jours | H7: 45828 | I7: 45830 | J7: 3 | K7: Termine
B8: PS-004 | C8: EMP-001 | D8: =IF(C8="","",VLOOKUP(C8,'_Données Employés'!$B$5:$H$18,4,FALSE)&" "&VLOOKUP(C8,'_Données Employés'!$B$5:$H$18,5,FALSE)) | E8: =IF(C8="","",VLOOKUP(C8,'_Données Employés'!$B$5:$H$18,6,FALSE)) | F8: Demenagement | G8: 1 jour | H8: 45843 | I8: 45843 | J8: 1 | K8: Planifie
B9: PS-005 | C9: EMP-005 | D9: =IF(C9="","",VLOOKUP(C9,'_Données Employés'!$B$5:$H$18,4,FALSE)&" "&VLOOKUP(C9,'_Données Employés'!$B$5:$H$18,5,FALSE)) | E9: =IF(C9="","",VLOOKUP(C9,'_Données Employés'!$B$5:$H$18,6,FALSE)) | F9: Deces conjoint | G9: 5 jours | H9: 45749 | I9: 45753 | J9: 5 | K9: Termine
B10: =IF(C10="","PS-"&TEXT(COUNTA($C$5:C10),"000")) | J10: =IF(H10="","",I10-H10+1)
B11: =IF(C11="","PS-"&TEXT(COUNTA($C$5:C11),"000")) | J11: =IF(H11="","",I11-H11+1)
B12: =IF(C12="","PS-"&TEXT(COUNTA($C$5:C12),"000")) | J12: =IF(H12="","",I12-H12+1)
B13: =IF(C13="","PS-"&TEXT(COUNTA($C$5:C13),"000")) | J13: =IF(H13="","",I13-H13+1)
B14: =IF(C14="","PS-"&TEXT(COUNTA($C$5:C14),"000")) | J14: =IF(H14="","",I14-H14+1)
B15: =IF(C15="","PS-"&TEXT(COUNTA($C$5:C15),"000")) | J15: =IF(H15="","",I15-H15+1)
B16: =IF(C16="","PS-"&TEXT(COUNTA($C$5:C16),"000")) | J16: =IF(H16="","",I16-H16+1)
B17: =IF(C17="","PS-"&TEXT(COUNTA($C$5:C17),"000")) | J17: =IF(H17="","",I17-H17+1)
B18: =IF(C18="","PS-"&TEXT(COUNTA($C$5:C18),"000")) | J18: =IF(H18="","",I18-H18+1)
B19: =IF(C19="","PS-"&TEXT(COUNTA($C$5:C19),"000")) | J19: =IF(H19="","",I19-H19+1)
B20: =IF(C20="","PS-"&TEXT(COUNTA($C$5:C20),"000")) | J20: =IF(H20="","",I20-H20+1)
B21: =IF(C21="","PS-"&TEXT(COUNTA($C$5:C21),"000")) | J21: =IF(H21="","",I21-H21+1)
... B109: =IF(C109="","PS-"&TEXT(COUNTA($C$5:C109),"000")) | J109: =IF(H109="","",I109-H109+1)
B111: TOTAL | J111: =SUM(J5:J104)
B113: INDICATEURS (mis a jour automatiquement)
B114: Total permissions | D114: Total jours (j) | F114: Planifiees | H114: Terminees
B115: =COUNTIF(B5:B104,"<>") | D115: =SUM(J5:J104) | F115: =COUNTIF(K5:K104,"Planifie") | H115: =COUNTIF(K5:K104,"Termine")

Sheet 5-Conges Sans Solde
B2: GESTION DES CONGES SANS SOLDE (#55)
B3: TABLEAU DYNAMIQUE — Saisissez dans la prochaine ligne jaune. Les calculs se mettent a jour automatiquement.
B4: N° CSS | C4: Matricule | D4: Nom Employe | E4: Departement | F4: Motif Demande | G4: Date Debut | H4: Date Fin | I4: Nb Jours | J4: Impact Anciennete | K4: Validation DRH | L4: Statut
B5: CSS-001 | C5: EMP-008 | D5: =IF(C5="","",VLOOKUP(C5,'_Données Employés'!$B$5:$H$18,4,FALSE)&" "&VLOOKUP(C5,'_Données Employés'!$B$5:$H$18,5,FALSE)) | E5: =IF(C5="","",VLOOKUP(C5,'_Données Employés'!$B$5:$H$18,6,FALSE)) | F5: Voyage personnel | G5: 45839 | H5: 45853 | I5: 15 | J5: Oui - 15j retard | K5: Oui | L5: Approuve
B6: CSS-002 | C6: EMP-006 | D6: =IF(C6="","",VLOOKUP(C6,'_Données Employés'!$B$5:$H$18,4,FALSE)&" "&VLOOKUP(C6,'_Données Employés'!$B$5:$H$18,5,FALSE)) | E6: =IF(C6="","",VLOOKUP(C6,'_Données Employés'!$B$5:$H$18,6,FALSE)) | F6: Probleme familial | G6: 45818 | H6: 45828 | I6: 8 | J6: Non | K6: Oui | L6: Termine
B7: CSS-003 | C7: EMP-007 | D7: =IF(C7="","",VLOOKUP(C7,'_Données Employés'!$B$5:$H$18,4,FALSE)&" "&VLOOKUP(C7,'_Données Employés'!$B$5:$H$18,5,FALSE)) | E7: =IF(C7="","",VLOOKUP(C7,'_Données Employés'!$B$5:$H$18,6,FALSE)) | F7: Formation personnelle | G7: 45901 | H7: 45930 | I7: 22 | J7: Oui - 22j retard | K7: En attente | L7: En attente
B8: =IF(C8="","CSS-"&TEXT(COUNTA($C$5:C8),"000")) | I8: =IF(G8="","",H8-G8+1)
B9: =IF(C9="","CSS-"&TEXT(COUNTA($C$5:C9),"000")) | I9: =IF(G9="","",H9-G9+1)
B10: =IF(C10="","CSS-"&TEXT(COUNTA($C$5:C10),"000")) | I10: =IF(G10="","",H10-G10+1)
B11: =IF(C11="","CSS-"&TEXT(COUNTA($C$5:C11),"000")) | I11: =IF(G11="","",H11-G11+1)
B12: =IF(C12="","CSS-"&TEXT(COUNTA($C$5:C12),"000")) | I12: =IF(G12="","",H12-G12+1)
B13: =IF(C13="","CSS-"&TEXT(COUNTA($C$5:C13),"000")) | I13: =IF(G13="","",H13-G13+1)
B14: =IF(C14="","CSS-"&TEXT(COUNTA($C$5:C14),"000")) | I14: =IF(G14="","",H14-G14+1)
B15: =IF(C15="","CSS-"&TEXT(COUNTA($C$5:C15),"000")) | I15: =IF(G15="","",H15-G15+1)
B16: =IF(C16="","CSS-"&TEXT(COUNTA($C$5:C16),"000")) | I16: =IF(G16="","",H16-G16+1)
B17: =IF(C17="","CSS-"&TEXT(COUNTA($C$5:C17),"000")) | I17: =IF(G17="","",H17-G17+1)
B18: =IF(C18="","CSS-"&TEXT(COUNTA($C$5:C18),"000")) | I18: =IF(G18="","",H18-G18+1)
B19: =IF(C19="","CSS-"&TEXT(COUNTA($C$5:C19),"000")) | I19: =IF(G19="","",H19-G19+1)
... B107: =IF(C107="","CSS-"&TEXT(COUNTA($C$5:C107),"000")) | I107: =IF(G107="","",H107-G107+1)
B109: TOTAL | I109: =SUM(I5:I104)
B111: INDICATEURS (mis a jour automatiquement)
B112: Total CSS | D112: Total jours (j) | F112: En attente | H112: Impact anciennete
B113: =COUNTIF(B5:B104,"<>") | D113: =SUM(I5:I104) | F113: =COUNTIF(L5:L104,"En attente") | H113: =COUNTIF(J5:J104,"Oui*")

Sheet 6-Absences Non Justifiees
B2: REGISTRE DES ABSENCES NON JUSTIFIEES (#56)
B3: TABLEAU DYNAMIQUE — Saisissez dans la prochaine ligne jaune. Les calculs se mettent a jour automatiquement.
B4: N° Absence | C4: Matricule | D4: Nom Employe | E4: Departement | F4: Type Absence | G4: Date Debut | H4: Date Fin | I4: Nb Jours | J4: Motif (si fourni) | K4: Sanction Appliquee | L4: Statut
B5: ANJ-001 | C5: EMP-010 | D5: =IF(C5="","",VLOOKUP(C5,'_Données Employés'!$B$5:$H$18,4,FALSE)&" "&VLOOKUP(C5,'_Données Employés'!$B$5:$H$18,5,FALSE)) | E5: =IF(C5="","",VLOOKUP(C5,'_Données Employés'!$B$5:$H$18,6,FALSE)) | F5: Absence injustifiee | G5: 45813 | H5: 45814 | I5: 2 | J5: Aucun motif | K5: Avertissement ecrit | L5: Sanctionnee
B6: ANJ-002 | C6: EMP-009 | D6: =IF(C6="","",VLOOKUP(C6,'_Données Employés'!$B$5:$H$18,4,FALSE)&" "&VLOOKUP(C6,'_Données Employés'!$B$5:$H$18,5,FALSE)) | E6: =IF(C6="","",VLOOKUP(C6,'_Données Employés'!$B$5:$H$18,6,FALSE)) | F6: Non presentation | G6: 45789 | H6: 45789 | I6: 1 | J6: Oubli reprise conge | K6: Avertissement oral | L6: Cloturee
B7: ANJ-003 | C7: EMP-011 | D7: =IF(C7="","",VLOOKUP(C7,'_Données Employés'!$B$5:$H$18,4,FALSE)&" "&VLOOKUP(C7,'_Données Employés'!$B$5:$H$18,5,FALSE)) | E7: =IF(C7="","",VLOOKUP(C7,'_Données Employés'!$B$5:$H$18,6,FALSE)) | F7: Absent sans autorisation | G7: 45826 | H7: 45828 | I7: 3 | K7: Blame | L7: En cours
B8: ANJ-004 | C8: EMP-008 | D8: =IF(C8="","",VLOOKUP(C8,'_Données Employés'!$B$5:$H$18,4,FALSE)&" "&VLOOKUP(C8,'_Données Employés'!$B$5:$H$18,5,FALSE)) | E8: =IF(C8="","",VLOOKUP(C8,'_Données Employés'!$B$5:$H$18,6,FALSE)) | F8: Abandon de poste | G8: 45854 | I8: 1 | J8: Depart sans prevenir | K8: En attente decision | L8: En attente
B9: =IF(C9="","ANJ-"&TEXT(COUNTA($C$5:C9),"000")) | I9: =IF(G9="","",H9-G9+1)
B10: =IF(C10="","ANJ-"&TEXT(COUNTA($C$5:C10),"000")) | I10: =IF(G10="","",H10-G10+1)
B11: =IF(C11="","ANJ-"&TEXT(COUNTA($C$5:C11),"000")) | I11: =IF(G11="","",H11-G11+1)
B12: =IF(C12="","ANJ-"&TEXT(COUNTA($C$5:C12),"000")) | I12: =IF(G12="","",H12-G12+1)
B13: =IF(C13="","ANJ-"&TEXT(COUNTA($C$5:C13),"000")) | I13: =IF(G13="","",H13-G13+1)
B14: =IF(C14="","ANJ-"&TEXT(COUNTA($C$5:C14),"000")) | I14: =IF(G14="","",H14-G14+1)
B15: =IF(C15="","ANJ-"&TEXT(COUNTA($C$5:C15),"000")) | I15: =IF(G15="","",H15-G15+1)
B16: =IF(C16="","ANJ-"&TEXT(COUNTA($C$5:C16),"000")) | I16: =IF(G16="","",H16-G16+1)
B17: =IF(C17="","ANJ-"&TEXT(COUNTA($C$5:C17),"000")) | I17: =IF(G17="","",H17-G17+1)
B18: =IF(C18="","ANJ-"&TEXT(COUNTA($C$5:C18),"000")) | I18: =IF(G18="","",H18-G18+1)
B19: =IF(C19="","ANJ-"&TEXT(COUNTA($C$5:C19),"000")) | I19: =IF(G19="","",H19-G19+1)
B20: =IF(C20="","ANJ-"&TEXT(COUNTA($C$5:C20),"000")) | I20: =IF(G20="","",H20-G20+1)
... B108: =IF(C108="","ANJ-"&TEXT(COUNTA($C$5:C108),"000")) | I108: =IF(G108="","",H108-G108+1)
B110: TOTAL | I110: =SUM(I5:I104)
B112: INDICATEURS (mis a jour automatiquement)
B113: Total absences NJ | D113: Total jours (j) | F113: Sanctionnees | H113: En cours
B114: =COUNTIF(B5:B104,"<>") | D114: =SUM(I5:I104) | F114: =COUNTIF(L5:L104,"Sanctionnee") | H114: =COUNTIF(L5:L104,"En cours")

Sheet 7-Retards & Departs Anticipes
B2: SUIVI DES RETARDS & DEPARTS ANTICIPES (#57)
B3: TABLEAU DYNAMIQUE — Saisissez dans la prochaine ligne jaune. Les calculs se mettent a jour automatiquement.
B4: N° Retard | C4: Matricule | D4: Nom Employe | E4: Departement | F4: Type Retard | G4: Date | H4: Horaire Prevu | I4: Horaire Reel | J4: Retard (min) | K4: Motif | L4: Statut
B5: RET-001 | C5: EMP-002 | D5: =IF(C5="","",VLOOKUP(C5,'_Données Employés'!$B$5:$H$18,4,FALSE)&" "&VLOOKUP(C5,'_Données Employés'!$B$5:$H$18,5,FALSE)) | E5: =IF(C5="","",VLOOKUP(C5,'_Données Employés'!$B$5:$H$18,6,FALSE)) | F5: Retard arrivee | G5: 45810 | H5: 08h00 | I5: 08h15 | J5: 15 | K5: Transport en panne | L5: Justifie
B6: RET-002 | C6: EMP-005 | D6: =IF(C6="","",VLOOKUP(C6,'_Données Employés'!$B$5:$H$18,4,FALSE)&" "&VLOOKUP(C6,'_Données Employés'!$B$5:$H$18,5,FALSE)) | E6: =IF(C6="","",VLOOKUP(C6,'_Données Employés'!$B$5:$H$18,6,FALSE)) | F6: Retard arrivee | G6: 45813 | H6: 06h00 | I6: 06h25 | J6: 25 | K6: Pluie | L6: Non justifie
B7: RET-003 | C7: EMP-003 | D7: =IF(C7="","",VLOOKUP(C7,'_Données Employés'!$B$5:$H$18,4,FALSE)&" "&VLOOKUP(C7,'_Données Employés'!$B$5:$H$18,5,FALSE)) | E7: =IF(C7="","",VLOOKUP(C7,'_Données Employés'!$B$5:$H$18,6,FALSE)) | F7: Depart anticipe | G7: 45812 | H7: 17h00 | I7: 16h00 | J7: 60 | K7: Certificat medical | L7: Justifie
B8: RET-004 | C8: EMP-004 | D8: =IF(C8="","",VLOOKUP(C8,'_Données Employés'!$B$5:$H$18,4,FALSE)&" "&VLOOKUP(C8,'_Données Employés'!$B$5:$H$18,5,FALSE)) | E8: =IF(C8="","",VLOOKUP(C8,'_Données Employés'!$B$5:$H$18,6,FALSE)) | F8: Retard arrivee | G8: 45817 | H8: 06h00 | I8: 06h10 | J8: 10 | K8: Embouteillage | L8: Tolere
B9: RET-005 | C9: EMP-010 | D9: =IF(C9="","",VLOOKUP(C9,'_Données Employés'!$B$5:$H$18,4,FALSE)&" "&VLOOKUP(C9,'_Données Employés'!$B$5:$H$18,5,FALSE)) | E9: =IF(C9="","",VLOOKUP(C9,'_Données Employés'!$B$5:$H$18,6,FALSE)) | F9: Pause allongee | G9: 45819 | H9: 14h00 | I9: 14h30 | J9: 30 | L9: Non justifie
B10: =IF(C10="","RET-"&TEXT(COUNTA($C$5:C10),"000"))
B11: =IF(C11="","RET-"&TEXT(COUNTA($C$5:C11),"000"))
B12: =IF(C12="","RET-"&TEXT(COUNTA($C$5:C12),"000"))
B13: =IF(C13="","RET-"&TEXT(COUNTA($C$5:C13),"000"))
B14: =IF(C14="","RET-"&TEXT(COUNTA($C$5:C14),"000"))
B15: =IF(C15="","RET-"&TEXT(COUNTA($C$5:C15),"000"))
B16: =IF(C16="","RET-"&TEXT(COUNTA($C$5:C16),"000"))
B17: =IF(C17="","RET-"&TEXT(COUNTA($C$5:C17),"000"))
B18: =IF(C18="","RET-"&TEXT(COUNTA($C$5:C18),"000"))
B19: =IF(C19="","RET-"&TEXT(COUNTA($C$5:C19),"000"))
B20: =IF(C20="","RET-"&TEXT(COUNTA($C$5:C20),"000"))
B21: =IF(C21="","RET-"&TEXT(COUNTA($C$5:C21),"000"))
... B109: =IF(C109="","RET-"&TEXT(COUNTA($C$5:C109),"000"))
B111: TOTAL | J111: =SUM(J5:J104)
B113: INDICATEURS (mis a jour automatiquement)
B114: Total retards | D114: Minutes cumulees | F114: Non justifies | H114: Sanctionnes
B115: =COUNTIF(B5:B104,"<>") | D115: =SUM(J5:J104) | F115: =COUNTIF(L5:L104,"Non justifie") | H115: =COUNTIF(L5:L104,"Sanctionne")

Sheet 8-Arrets Maladie
B2: GESTION DES ARRETS MALADIE (#58)
B3: TABLEAU DYNAMIQUE — Saisissez dans la prochaine ligne jaune. Les calculs se mettent a jour automatiquement.
B4: N° Arret | C4: Matricule | D4: Nom Employe | E4: Departement | F4: Type Arret | G4: Date Debut | H4: Date Fin | I4: Nb Jours | J4: Certificat Medical | K4: IJSS Journalieres (FCFA) | L4: Maintien Salaire (FCFA) | M4: Statut
B5: AM-001 | C5: EMP-003 | D5: =IF(C5="","",VLOOKUP(C5,'_Données Employés'!$B$5:$H$18,4,FALSE)&" "&VLOOKUP(C5,'_Données Employés'!$B$5:$H$18,5,FALSE)) | E5: =IF(C5="","",VLOOKUP(C5,'_Données Employés'!$B$5:$H$18,6,FALSE)) | F5: Arret maladie | G5: 45811 | H5: 45814 | I5: 4 | J5: Oui | K5: 6000 | L5: 0 | M5: Termine
B6: AM-002 | C6: EMP-009 | D6: =IF(C6="","",VLOOKUP(C6,'_Données Employés'!$B$5:$H$18,4,FALSE)&" "&VLOOKUP(C6,'_Données Employés'!$B$5:$H$18,5,FALSE)) | E6: =IF(C6="","",VLOOKUP(C6,'_Données Employés'!$B$5:$H$18,6,FALSE)) | F6: Arret maladie | G6: 45797 | H6: 45807 | I6: 9 | J6: Oui | K6: 5400 | L6: 0 | M6: Termine
B7: AM-003 | C7: EMP-005 | D7: =IF(C7="","",VLOOKUP(C7,'_Données Employés'!$B$5:$H$18,4,FALSE)&" "&VLOOKUP(C7,'_Données Employés'!$B$5:$H$18,5,FALSE)) | E7: =IF(C7="","",VLOOKUP(C7,'_Données Employés'!$B$5:$H$18,6,FALSE)) | F7: Hospitalisation | G7: 45828 | H7: 45838 | I7: 10 | J7: Oui | K7: 6000 | L7: 120000 | M7: En cours
B8: AM-004 | C8: EMP-011 | D8: =IF(C8="","",VLOOKUP(C8,'_Données Employés'!$B$5:$H$18,4,FALSE)&" "&VLOOKUP(C8,'_Données Employés'!$B$5:$H$18,5,FALSE)) | E8: =IF(C8="","",VLOOKUP(C8,'_Données Employés'!$B$5:$H$18,6,FALSE)) | F8: Arret maladie | G8: 45833 | H8: 45843 | I8: 10 | J8: En attente | K8: 0 | L8: 0 | M8: En attente de justification
B9: =IF(C9="","AM-"&TEXT(COUNTA($C$5:C9),"000")) | I9: =IF(G9="","",H9-G9+1)
B10: =IF(C10="","AM-"&TEXT(COUNTA($C$5:C10),"000")) | I10: =IF(G10="","",H10-G10+1)
B11: =IF(C11="","AM-"&TEXT(COUNTA($C$5:C11),"000")) | I11: =IF(G11="","",H11-G11+1)
B12: =IF(C12="","AM-"&TEXT(COUNTA($C$5:C12),"000")) | I12: =IF(G12="","",H12-G12+1)
B13: =IF(C13="","AM-"&TEXT(COUNTA($C$5:C13),"000")) | I13: =IF(G13="","",H13-G13+1)
B14: =IF(C14="","AM-"&TEXT(COUNTA($C$5:C14),"000")) | I14: =IF(G14="","",H14-G14+1)
B15: =IF(C15="","AM-"&TEXT(COUNTA($C$5:C15),"000")) | I15: =IF(G15="","",H15-G15+1)
B16: =IF(C16="","AM-"&TEXT(COUNTA($C$5:C16),"000")) | I16: =IF(G16="","",H16-G16+1)
B17: =IF(C17="","AM-"&TEXT(COUNTA($C$5:C17),"000")) | I17: =IF(G17="","",H17-G17+1)
B18: =IF(C18="","AM-"&TEXT(COUNTA($C$5:C18),"000")) | I18: =IF(G18="","",H18-G18+1)
B19: =IF(C19="","AM-"&TEXT(COUNTA($C$5:C19),"000")) | I19: =IF(G19="","",H19-G19+1)
B20: =IF(C20="","AM-"&TEXT(COUNTA($C$5:C20),"000")) | I20: =IF(G20="","",H20-G20+1)
... B108: =IF(C108="","AM-"&TEXT(COUNTA($C$5:C108),"000")) | I108: =IF(G108="","",H108-G108+1)
B110: TOTAL | I110: =SUM(I5:I104) | K110: =SUM(K5:K104) | L110: =SUM(L5:L104)
B112: INDICATEURS (mis a jour automatiquement)
B113: Total arrets | D113: Total jours arret | F113: IJSS totales (FCFA) | H113: Sans certificat
B114: =COUNTIF(B5:B104,"<>") | D114: =SUM(I5:I104) | F114: =SUM(K5:K104) | H114: =COUNTIF(J5:J104,"Non")

Sheet 9-Arrets Accident Travail
B2: SUIVI DES ARRETS POUR ACCIDENT DU TRAVAIL (#59)
B3: TABLEAU DYNAMIQUE — Saisissez dans la prochaine ligne jaune. Les calculs se mettent a jour automatiquement.
B4: N° AT | C4: Matricule | D4: Nom Employe | E4: Departement | F4: Date Accident | G4: Lieu | H4: Circonstances | I4: Cause | J4: Nature Blessures | K4: Date Debut Arret | L4: Date Fin Arret | M4: Nb Jours Arret | N4: Declaration CNPS | O4: Statut
B5: AT-001 | C5: EMP-010 | D5: =IF(C5="","",VLOOKUP(C5,'_Données Employés'!$B$5:$H$18,4,FALSE)&" "&VLOOKUP(C5,'_Données Employés'!$B$5:$H$18,5,FALSE)) | E5: =IF(C5="","",VLOOKUP(C5,'_Données Employés'!$B$5:$H$18,6,FALSE)) | F5: 45762 | G5: Cuisine chaude | H5: Coupure lors de preparation | I5: Coupure/brulure | J5: Brulure main gauche | K5: 45763 | L5: 45772 | M5: 10 | N5: Oui | O5: Termine
B6: AT-002 | C6: EMP-009 | D6: =IF(C6="","",VLOOKUP(C6,'_Données Employés'!$B$5:$H$18,4,FALSE)&" "&VLOOKUP(C6,'_Données Employés'!$B$5:$H$18,5,FALSE)) | E6: =IF(C6="","",VLOOKUP(C6,'_Données Employés'!$B$5:$H$18,6,FALSE)) | F6: 45782 | G6: Sous-sol technique | H6: Chute sur sol mouille | I6: Chute | J6: Entorse cheville droit | K6: 45783 | L6: 45802 | M6: 20 | N6: Oui | O6: Termine
B7: AT-003 | C7: EMP-011 | D7: =IF(C7="","",VLOOKUP(C7,'_Données Employés'!$B$5:$H$18,4,FALSE)&" "&VLOOKUP(C7,'_Données Employés'!$B$5:$H$18,5,FALSE)) | E7: =IF(C7="","",VLOOKUP(C7,'_Données Employés'!$B$5:$H$18,6,FALSE)) | F7: 45818 | G7: Parking | H7: Manipulation carton lourd | I7: Manutention | J7: Lombalgie | K7: 45819 | L7: 45839 | M7: 20 | N7: Oui | O7: En cours
B8: =IF(C8="","AT-"&TEXT(COUNTA($C$5:C8),"000")) | M8: =IF(K8="","",L8-K8+1)
B9: =IF(C9="","AT-"&TEXT(COUNTA($C$5:C9),"000")) | M9: =IF(K9="","",L9-K9+1)
B10: =IF(C10="","AT-"&TEXT(COUNTA($C$5:C10),"000")) | M10: =IF(K10="","",L10-K10+1)
B11: =IF(C11="","AT-"&TEXT(COUNTA($C$5:C11),"000")) | M11: =IF(K11="","",L11-K11+1)
B12: =IF(C12="","AT-"&TEXT(COUNTA($C$5:C12),"000")) | M12: =IF(K12="","",L12-K12+1)
B13: =IF(C13="","AT-"&TEXT(COUNTA($C$5:C13),"000")) | M13: =IF(K13="","",L13-K13+1)
B14: =IF(C14="","AT-"&TEXT(COUNTA($C$5:C14),"000")) | M14: =IF(K14="","",L14-K14+1)
B15: =IF(C15="","AT-"&TEXT(COUNTA($C$5:C15),"000")) | M15: =IF(K15="","",L15-K15+1)
B16: =IF(C16="","AT-"&TEXT(COUNTA($C$5:C16),"000")) | M16: =IF(K16="","",L16-K16+1)
B17: =IF(C17="","AT-"&TEXT(COUNTA($C$5:C17),"000")) | M17: =IF(K17="","",L17-K17+1)
B18: =IF(C18="","AT-"&TEXT(COUNTA($C$5:C18),"000")) | M18: =IF(K18="","",L18-K18+1)
B19: =IF(C19="","AT-"&TEXT(COUNTA($C$5:C19),"000")) | M19: =IF(K19="","",L19-K19+1)
... B107: =IF(C107="","AT-"&TEXT(COUNTA($C$5:C107),"000")) | M107: =IF(K107="","",L107-K107+1)
B109: TOTAL | M109: =SUM(M5:M104)
B111: INDICATEURS (mis a jour automatiquement)
B112: Total AT | D112: Total jours arret | F112: Declarations CNPS | H112: En cours
B113: =COUNTIF(B5:B104,"<>") | D113: =SUM(M5:M104) | F113: =COUNTIF(N5:N104,"Oui") | H113: =COUNTIF(O5:O104,"En cours")

Sheet 10-Conges Maternite Paternite
B2: GESTION DES CONGES MATERNITE/PATERNITE (#60)
B3: TABLEAU DYNAMIQUE — Saisissez dans la prochaine ligne jaune. Les calculs se mettent a jour automatiquement.
B4: N° | C4: Matricule | D4: Nom Employe | E4: Departement | F4: Type | G4: Date Prevue Accouchement | H4: Date Debut Conge | I4: Date Fin Conge | J4: Nb Semaines | K4: Remplacement Prevu | L4: Visite Reprise | M4: Statut
B5: MP-001 | C5: EMP-006 | D5: =IF(C5="","",VLOOKUP(C5,'_Données Employés'!$B$5:$H$18,4,FALSE)&" "&VLOOKUP(C5,'_Données Employés'!$B$5:$H$18,5,FALSE)) | E5: =IF(C5="","",VLOOKUP(C5,'_Données Employés'!$B$5:$H$18,6,FALSE)) | F5: Conge de maternite | G5: 45884 | H5: 45870 | I5: 45984 | J5: 16 | K5: Conseiller interim | L5: Planifiee | M5: En cours
B6: MP-002 | C6: EMP-012 | D6: =IF(C6="","",VLOOKUP(C6,'_Données Employés'!$B$5:$H$18,4,FALSE)&" "&VLOOKUP(C6,'_Données Employés'!$B$5:$H$18,5,FALSE)) | E6: =IF(C6="","",VLOOKUP(C6,'_Données Employés'!$B$5:$H$18,6,FALSE)) | F6: Conge de maternite | G6: 45931 | H6: 45917 | I6: 46029 | J6: 16 | K6: Receptionniste CDD | L6: Planifiee | M6: Planifie
B7: MP-003 | C7: EMP-005 | D7: =IF(C7="","",VLOOKUP(C7,'_Données Employés'!$B$5:$H$18,4,FALSE)&" "&VLOOKUP(C7,'_Données Employés'!$B$5:$H$18,5,FALSE)) | E7: =IF(C7="","",VLOOKUP(C7,'_Données Employés'!$B$5:$H$18,6,FALSE)) | F7: Conge de paternite | G7: 45828 | H7: 45828 | I7: 45842 | J7: 2 | K7: Cuisinier stagiaire | L7: Non requise | M7: Termine
B8: =IF(C8="","MP-"&TEXT(COUNTA($C$5:C8),"000")) | J8: =IF(H8="","",ROUND((I8-H8)/7,0))
B9: =IF(C9="","MP-"&TEXT(COUNTA($C$5:C9),"000")) | J9: =IF(H9="","",ROUND((I9-H9)/7,0))
B10: =IF(C10="","MP-"&TEXT(COUNTA($C$5:C10),"000")) | J10: =IF(H10="","",ROUND((I10-H10)/7,0))
B11: =IF(C11="","MP-"&TEXT(COUNTA($C$5:C11),"000")) | J11: =IF(H11="","",ROUND((I11-H11)/7,0))
B12: =IF(C12="","MP-"&TEXT(COUNTA($C$5:C12),"000")) | J12: =IF(H12="","",ROUND((I12-H12)/7,0))
B13: =IF(C13="","MP-"&TEXT(COUNTA($C$5:C13),"000")) | J13: =IF(H13="","",ROUND((I13-H13)/7,0))
B14: =IF(C14="","MP-"&TEXT(COUNTA($C$5:C14),"000")) | J14: =IF(H14="","",ROUND((I14-H14)/7,0))
B15: =IF(C15="","MP-"&TEXT(COUNTA($C$5:C15),"000")) | J15: =IF(H15="","",ROUND((I15-H15)/7,0))
B16: =IF(C16="","MP-"&TEXT(COUNTA($C$5:C16),"000")) | J16: =IF(H16="","",ROUND((I16-H16)/7,0))
B17: =IF(C17="","MP-"&TEXT(COUNTA($C$5:C17),"000")) | J17: =IF(H17="","",ROUND((I17-H17)/7,0))
B18: =IF(C18="","MP-"&TEXT(COUNTA($C$5:C18),"000")) | J18: =IF(H18="","",ROUND((I18-H18)/7,0))
B19: =IF(C19="","MP-"&TEXT(COUNTA($C$5:C19),"000")) | J19: =IF(H19="","",ROUND((I19-H19)/7,0))
... B107: =IF(C107="","MP-"&TEXT(COUNTA($C$5:C107),"000")) | J107: =IF(H107="","",ROUND((I107-H107)/7,0))
B109: INDICATEURS (mis a jour automatiquement)
B110: Total conges | D110: Maternite | F110: Paternite | H110: En cours
B111: =COUNTIF(B5:B104,"<>") | D111: =COUNTIF(F5:F104,"Conge de maternite") | F111: =COUNTIF(F5:F104,"Conge de paternite") | H111: =COUNTIF(M5:M104,"En cours")

Sheet 11-Taux Absenteisme
B2: TAUX D'ABSENTEISME PAR SERVICE (#61)
B3: TABLEAU DYNAMIQUE — Saisissez dans la prochaine ligne jaune. Les calculs se mettent a jour automatiquement.
B4: N° | C4: Departement | D4: Mois | E4: Annee | F4: Effectif | G4: Jours Ouvrables | H4: Heures Theoriques | I4: Jours Absence (tous motifs) | J4: Jours Maladie | K4: Taux Absenteisme (%)
B5: ABS-001 | C5: Service Client | D5: Juin | E5: 2025 | F5: =COUNTIF('2-Compteur Conges Payes'!E:E,C5) | G5: 22 | H5: 110 | I5: =IFERROR(SUMPRODUCT(('17-Compteurs Absences Employe'!E5:E100=C5)*('17-Compteurs Absences Employe'!G5:G100+'17-Compteurs Absences Employe'!H5:H100+'17-Compteurs Absences Employe'!I5:I100+'17-Compteurs Absences Employe'!K5:K100)),0) | J5: =IFERROR(SUMPRODUCT(('17-Compteurs Absences Employe'!E5:E100=C5)*'17-Compteurs Absences Employe'!I5:I100),0) | K5: =IFERROR(ROUND(I5/(F5*G5)*100,1),0)
B6: ABS-002 | C6: Maintenance | D6: Juin | E6: 2025 | F6: =COUNTIF('2-Compteur Conges Payes'!E:E,C6) | G6: 22 | H6: 66 | I6: =IFERROR(SUMPRODUCT(('17-Compteurs Absences Employe'!E5:E100=C6)*('17-Compteurs Absences Employe'!G5:G100+'17-Compteurs Absences Employe'!H5:H100+'17-Compteurs Absences Employe'!I5:I100+'17-Compteurs Absences Employe'!K5:K100)),0) | J6: =IFERROR(SUMPRODUCT(('17-Compteurs Absences Employe'!E5:E100=C6)*'17-Compteurs Absences Employe'!I5:I100),0) | K6: =IFERROR(ROUND(I6/(F6*G6)*100,1),0)
B7: ABS-003 | C7: Finance & Comptabilité | D7: Juin | E7: 2025 | F7: =COUNTIF('2-Compteur Conges Payes'!E:E,C7) | G7: 22 | H7: 88 | I7: =IFERROR(SUMPRODUCT(('17-Compteurs Absences Employe'!E5:E100=C7)*('17-Compteurs Absences Employe'!G5:G100+'17-Compteurs Absences Employe'!H5:H100+'17-Compteurs Absences Employe'!I5:I100+'17-Compteurs Absences Employe'!K5:K100)),0) | J7: =IFERROR(SUMPRODUCT(('17-Compteurs Absences Employe'!E5:E100=C7)*'17-Compteurs Absences Employe'!I5:I100),0) | K7: =IFERROR(ROUND(I7/(F7*G7)*100,1),0)
B8: ABS-004 | C8: Réception & Front Office | D8: Juin | E8: 2025 | F8: =COUNTIF('2-Compteur Conges Payes'!E:E,C8) | G8: 22 | H8: 132 | I8: =IFERROR(SUMPRODUCT(('17-Compteurs Absences Employe'!E5:E100=C8)*('17-Compteurs Absences Employe'!G5:G100+'17-Compteurs Absences Employe'!H5:H100+'17-Compteurs Absences Employe'!I5:I100+'17-Compteurs Absences Employe'!K5:K100)),0) | J8: =IFERROR(SUMPRODUCT(('17-Compteurs Absences Employe'!E5:E100=C8)*'17-Compteurs Absences Employe'!I5:I100),0) | K8: =IFERROR(ROUND(I8/(F8*G8)*100,1),0)
B9: ABS-005 | C9: Cuisine & Restauration | D9: Juin | E9: 2025 | F9: =COUNTIF('2-Compteur Conges Payes'!E:E,C9) | G9: 22 | H9: 176 | I9: =IFERROR(SUMPRODUCT(('17-Compteurs Absences Employe'!E5:E100=C9)*('17-Compteurs Absences Employe'!G5:G100+'17-Compteurs Absences Employe'!H5:H100+'17-Compteurs Absences Employe'!I5:I100+'17-Compteurs Absences Employe'!K5:K100)),0) | J9: =IFERROR(SUMPRODUCT(('17-Compteurs Absences Employe'!E5:E100=C9)*'17-Compteurs Absences Employe'!I5:I100),0) | K9: =IFERROR(ROUND(I9/(F9*G9)*100,1),0)
B10: ABS-006 | C10: Maintenance | D10: Juin | E10: 2025 | F10: =COUNTIF('2-Compteur Conges Payes'!E:E,C10) | G10: 22 | H10: 132 | I10: =IFERROR(SUMPRODUCT(('17-Compteurs Absences Employe'!E5:E100=C10)*('17-Compteurs Absences Employe'!G5:G100+'17-Compteurs Absences Employe'!H5:H100+'17-Compteurs Absences Employe'!I5:I100+'17-Compteurs Absences Employe'!K5:K100)),0) | J10: =IFERROR(SUMPRODUCT(('17-Compteurs Absences Employe'!E5:E100=C10)*'17-Compteurs Absences Employe'!I5:I100),0) | K10: =IFERROR(ROUND(I10/(F10*G10)*100,1),0)
B11: ABS-007 | C11: Sécurité | D11: Juin | E11: 2025 | F11: =COUNTIF('2-Compteur Conges Payes'!E:E,C11) | G11: 22 | H11: 88 | I11: =IFERROR(SUMPRODUCT(('17-Compteurs Absences Employe'!E5:E100=C11)*('17-Compteurs Absences Employe'!G5:G100+'17-Compteurs Absences Employe'!H5:H100+'17-Compteurs Absences Employe'!I5:I100+'17-Compteurs Absences Employe'!K5:K100)),0) | J11: =IFERROR(SUMPRODUCT(('17-Compteurs Absences Employe'!E5:E100=C11)*'17-Compteurs Absences Employe'!I5:I100),0) | K11: =IFERROR(ROUND(I11/(F11*G11)*100,1),0)
B12: =IF(C12="","ABS-"&TEXT(COUNTA($C$5:C12),"000")) | K12: =IF(H12="","",IF(H12=0,"",I12/H12))
B13: =IF(C13="","ABS-"&TEXT(COUNTA($C$5:C13),"000")) | K13: =IF(H13="","",IF(H13=0,"",I13/H13))
B14: =IF(C14="","ABS-"&TEXT(COUNTA($C$5:C14),"000")) | K14: =IF(H14="","",IF(H14=0,"",I14/H14))
B15: =IF(C15="","ABS-"&TEXT(COUNTA($C$5:C15),"000")) | K15: =IF(H15="","",IF(H15=0,"",I15/H15))
B16: =IF(C16="","ABS-"&TEXT(COUNTA($C$5:C16),"000")) | K16: =IF(H16="","",IF(H16=0,"",I16/H16))
B17: =IF(C17="","ABS-"&TEXT(COUNTA($C$5:C17),"000")) | K17: =IF(H17="","",IF(H17=0,"",I17/H17))
B18: =IF(C18="","ABS-"&TEXT(COUNTA($C$5:C18),"000")) | K18: =IF(H18="","",IF(H18=0,"",I18/H18))
B19: =IF(C19="","ABS-"&TEXT(COUNTA($C$5:C19),"000")) | K19: =IF(H19="","",IF(H19=0,"",I19/H19))
B20: =IF(C20="","ABS-"&TEXT(COUNTA($C$5:C20),"000")) | K20: =IF(H20="","",IF(H20=0,"",I20/H20))
B21: =IF(C21="","ABS-"&TEXT(COUNTA($C$5:C21),"000")) | K21: =IF(H21="","",IF(H21=0,"",I21/H21))
B22: =IF(C22="","ABS-"&TEXT(COUNTA($C$5:C22),"000")) | K22: =IF(H22="","",IF(H22=0,"",I22/H22))
B23: =IF(C23="","ABS-"&TEXT(COUNTA($C$5:C23),"000")) | K23: =IF(H23="","",IF(H23=0,"",I23/H23))
... B111: =IF(C111="","ABS-"&TEXT(COUNTA($C$5:C111),"000")) | K111: =IF(H111="","",IF(H111=0,"",I111/H111))
B113: TOTAL | F113: =SUM(F5:F104) | G113: =SUM(G5:G104) | H113: =SUM(H5:H104) | I113: =SUM(I5:I104) | J113: =SUM(J5:J104)
B115: INDICATEURS (mis a jour automatiquement)
B116: Taux moyen hotel | D116: Total jours absence | F116: Total jours maladie | H116: Services suives
B117: =IFERROR(AVERAGE(K5:K104),0) | D117: =SUM(I5:I104) | F117: =SUM(J5:J104) | H117: =COUNTIF(B5:B104,"<>")

Sheet 12-Journal de Pointage
B2: TABLEAU DE PRESENCE / JOURNAL DE POINTAGE (#62)
B3: TABLEAU DYNAMIQUE — Saisissez dans la prochaine ligne jaune. Les calculs se mettent a jour automatiquement.
B4: N° | C4: Matricule | D4: Nom Employe | E4: Departement | F4: Date | G4: Heure Arrivee | H4: Heure Depart | I4: Presence (h) | J4: Absence | K4: Retard (min) | L4: Type Absence | M4: Statut
B5: JP-001 | C5: EMP-001 | D5: =IF(C5="","",VLOOKUP(C5,'_Données Employés'!$B$5:$H$18,4,FALSE)&" "&VLOOKUP(C5,'_Données Employés'!$B$5:$H$18,5,FALSE)) | E5: =IF(C5="","",VLOOKUP(C5,'_Données Employés'!$B$5:$H$18,6,FALSE)) | F5: 45810 | G5: 07h55 | H5: 17h10 | I5: 8.25 | K5: 0 | M5: Valide
B6: JP-002 | C6: EMP-002 | D6: =IF(C6="","",VLOOKUP(C6,'_Données Employés'!$B$5:$H$18,4,FALSE)&" "&VLOOKUP(C6,'_Données Employés'!$B$5:$H$18,5,FALSE)) | E6: =IF(C6="","",VLOOKUP(C6,'_Données Employés'!$B$5:$H$18,6,FALSE)) | F6: 45810 | G6: 08h15 | H6: 17h30 | I6: 8.25 | K6: 15 | M6: Valide
B7: JP-003 | C7: EMP-003 | D7: =IF(C7="","",VLOOKUP(C7,'_Données Employés'!$B$5:$H$18,4,FALSE)&" "&VLOOKUP(C7,'_Données Employés'!$B$5:$H$18,5,FALSE)) | E7: =IF(C7="","",VLOOKUP(C7,'_Données Employés'!$B$5:$H$18,6,FALSE)) | F7: 45811 | I7: 0 | J7: Arret maladie | K7: 0 | L7: Arret maladie | M7: Valide
B8: JP-004 | C8: EMP-004 | D8: =IF(C8="","",VLOOKUP(C8,'_Données Employés'!$B$5:$H$18,4,FALSE)&" "&VLOOKUP(C8,'_Données Employés'!$B$5:$H$18,5,FALSE)) | E8: =IF(C8="","",VLOOKUP(C8,'_Données Employés'!$B$5:$H$18,6,FALSE)) | F8: 45810 | G8: 06h00 | H8: 14h10 | I8: 7.67 | K8: 0 | M8: Valide
B9: JP-005 | C9: EMP-005 | D9: =IF(C9="","",VLOOKUP(C9,'_Données Employés'!$B$5:$H$18,4,FALSE)&" "&VLOOKUP(C9,'_Données Employés'!$B$5:$H$18,5,FALSE)) | E9: =IF(C9="","",VLOOKUP(C9,'_Données Employés'!$B$5:$H$18,6,FALSE)) | F9: 45810 | G9: 06h10 | H9: 14h00 | I9: 7.67 | K9: 10 | M9: Valide
B10: JP-028 | C10: EMP-028 | D10: =IF(C10="","",VLOOKUP(C10,'_Données Employés'!$B$5:$H$18,4,FALSE)&" "&VLOOKUP(C10,'_Données Employés'!$B$5:$H$18,5,FALSE)) | E10: =IF(C10="","",VLOOKUP(C10,'_Données Employés'!$B$5:$H$18,6,FALSE)) | F10: 45810 | G10: 07h00 | H10: 15h00 | I10: 8 | K10: 0 | M10: Valide
B11: JP-029 | C11: EMP-029 | D11: =IF(C11="","",VLOOKUP(C11,'_Données Employés'!$B$5:$H$18,4,FALSE)&" "&VLOOKUP(C11,'_Données Employés'!$B$5:$H$18,5,FALSE)) | E11: =IF(C11="","",VLOOKUP(C11,'_Données Employés'!$B$5:$H$18,6,FALSE)) | F11: 45810 | G11: 07h00 | H11: 15h00 | I11: 8 | K11: 0 | M11: Valide
B12: =IF(C12="","JP-"&TEXT(COUNTA($C$5:C12),"000"))
B13: =IF(C13="","JP-"&TEXT(COUNTA($C$5:C13),"000"))
B14: =IF(C14="","JP-"&TEXT(COUNTA($C$5:C14),"000"))
B15: =IF(C15="","JP-"&TEXT(COUNTA($C$5:C15),"000"))
B16: =IF(C16="","JP-"&TEXT(COUNTA($C$5:C16),"000"))
B17: =IF(C17="","JP-"&TEXT(COUNTA($C$5:C17),"000"))
B18: =IF(C18="","JP-"&TEXT(COUNTA($C$5:C18),"000"))
B19: =IF(C19="","JP-"&TEXT(COUNTA($C$5:C19),"000"))
B20: =IF(C20="","JP-"&TEXT(COUNTA($C$5:C20),"000"))
B21: =IF(C21="","JP-"&TEXT(COUNTA($C$5:C21),"000"))
B22: =IF(C22="","JP-"&TEXT(COUNTA($C$5:C22),"000"))
B23: =IF(C23="","JP-"&TEXT(COUNTA($C$5:C23),"000"))
... B109: =IF(C109="","JP-"&TEXT(COUNTA($C$5:C109),"000"))
B111: TOTAL | I111: =SUM(I5:I104) | K111: =SUM(K5:K104)
B113: INDICATEURS (mis a jour automatiquement)
B114: Pointages saisis | D114: Total heures (h) | F114: Total retards (min) | H114: Absences
B115: =COUNTIF(B5:B104,"<>") | D115: =SUM(I5:I104) | F115: =SUM(K5:K104) | H115: =COUNTIF(J5:J104,"<>")

Sheet 13-Conge Force & Repos Impose
B2: CONGE FORCE / REPOS COMPENSATOIRE IMPOSE (#63)
B3: TABLEAU DYNAMIQUE — Saisissez dans la prochaine ligne jaune. Les calculs se mettent a jour automatiquement.
B4: N° | C4: Departements Concernes | D4: Motif | E4: Date Debut | F4: Date Fin | G4: Nb Jours | H4: Nb Employes | I4: Services Maintenus | J4: Communication | K4: Statut
B5: CF-001 | C5: Cuisine, Entretien, Logistique | D5: Travaux renovation cuisine | E5: 45880 | F5: 45884 | G5: 5 | H5: 18 | I5: Reception, Securite, Room Service | J5: Note service 01/08 | K5: Planifie
B6: CF-002 | C6: Tous sauf Reception et Securite | D6: Basse saison janvier | E6: 46027 | F6: 46038 | G6: 10 | H6: 38 | I6: Reception, Securite, Room Service | J6: Note circulaire 20/12 | K6: Planifie
B7: CF-003 | C7: Production, Logistique | D7: Inventaire annuel | E7: 46020 | F7: 46022 | G7: 3 | H7: 12 | I7: Aucun | J7: Note service 15/12 | K7: Planifie
B8: =IF(C8="","CF-"&TEXT(COUNTA($C$5:C8),"000")) | G8: =IF(E8="","",F8-E8+1)
B9: =IF(C9="","CF-"&TEXT(COUNTA($C$5:C9),"000")) | G9: =IF(E9="","",F9-E9+1)
B10: =IF(C10="","CF-"&TEXT(COUNTA($C$5:C10),"000")) | G10: =IF(E10="","",F10-E10+1)
B11: =IF(C11="","CF-"&TEXT(COUNTA($C$5:C11),"000")) | G11: =IF(E11="","",F11-E11+1)
B12: =IF(C12="","CF-"&TEXT(COUNTA($C$5:C12),"000")) | G12: =IF(E12="","",F12-E12+1)
B13: =IF(C13="","CF-"&TEXT(COUNTA($C$5:C13),"000")) | G13: =IF(E13="","",F13-E13+1)
B14: =IF(C14="","CF-"&TEXT(COUNTA($C$5:C14),"000")) | G14: =IF(E14="","",F14-E14+1)
B15: =IF(C15="","CF-"&TEXT(COUNTA($C$5:C15),"000")) | G15: =IF(E15="","",F15-E15+1)
B16: =IF(C16="","CF-"&TEXT(COUNTA($C$5:C16),"000")) | G16: =IF(E16="","",F16-E16+1)
B17: =IF(C17="","CF-"&TEXT(COUNTA($C$5:C17),"000")) | G17: =IF(E17="","",F17-E17+1)
B18: =IF(C18="","CF-"&TEXT(COUNTA($C$5:C18),"000")) | G18: =IF(E18="","",F18-E18+1)
B19: =IF(C19="","CF-"&TEXT(COUNTA($C$5:C19),"000")) | G19: =IF(E19="","",F19-E19+1)
... B107: =IF(C107="","CF-"&TEXT(COUNTA($C$5:C107),"000")) | G107: =IF(E107="","",F107-E107+1)
B109: TOTAL | G109: =SUM(G5:G104) | H109: =SUM(H5:H104)
B111: INDICATEURS (mis a jour automatiquement)
B112: Periodes planifiees | D112: Total jours fermeture | F112: Employes concernes (max) | H112: Planifies
B113: =COUNTIF(B5:B104,"<>") | D113: =SUM(G5:G104) | F113: =MAX(H5:H104) | H113: =COUNTIF(K5:K104,"Planifie")

Sheet 14-Solde Conges par Dept
B2: SOLDE DE CONGES PAR DEPARTEMENT
B3: TABLEAU DYNAMIQUE — Saisissez dans la prochaine ligne jaune. Les calculs se mettent a jour automatiquement.
B4: N° | C4: Departement | D4: Mois | E4: Annee | F4: Effectif | G4: Total Droits (j) | H4: Total Pris (j) | I4: Solde Dept (j)
B5: SD-001 | C5: Service Client | D5: Juin | E5: 2025 | F5: =COUNTIF('2-Compteur Conges Payes'!E:E,C5) | G5: =IFERROR(SUMIF('2-Compteur Conges Payes'!E:E,C5,'2-Compteur Conges Payes'!G:G),0) | H5: =IFERROR(SUMIF('2-Compteur Conges Payes'!E:E,C5,'2-Compteur Conges Payes'!H:H),0) | I5: =G5-H5
B6: SD-002 | C6: Maintenance | D6: Juin | E6: 2025 | F6: =COUNTIF('2-Compteur Conges Payes'!E:E,C6) | G6: =IFERROR(SUMIF('2-Compteur Conges Payes'!E:E,C6,'2-Compteur Conges Payes'!G:G),0) | H6: =IFERROR(SUMIF('2-Compteur Conges Payes'!E:E,C6,'2-Compteur Conges Payes'!H:H),0) | I6: =G6-H6
B7: SD-003 | C7: Finance & Comptabilité | D7: Juin | E7: 2025 | F7: =COUNTIF('2-Compteur Conges Payes'!E:E,C7) | G7: =IFERROR(SUMIF('2-Compteur Conges Payes'!E:E,C7,'2-Compteur Conges Payes'!G:G),0) | H7: =IFERROR(SUMIF('2-Compteur Conges Payes'!E:E,C7,'2-Compteur Conges Payes'!H:H),0) | I7: =G7-H7
B8: SD-004 | C8: Réception & Front Office | D8: Juin | E8: 2025 | F8: =COUNTIF('2-Compteur Conges Payes'!E:E,C8) | G8: =IFERROR(SUMIF('2-Compteur Conges Payes'!E:E,C8,'2-Compteur Conges Payes'!G:G),0) | H8: =IFERROR(SUMIF('2-Compteur Conges Payes'!E:E,C8,'2-Compteur Conges Payes'!H:H),0) | I8: =G8-H8
B9: SD-005 | C9: Cuisine & Restauration | D9: Juin | E9: 2025 | F9: =COUNTIF('2-Compteur Conges Payes'!E:E,C9) | G9: =IFERROR(SUMIF('2-Compteur Conges Payes'!E:E,C9,'2-Compteur Conges Payes'!G:G),0) | H9: =IFERROR(SUMIF('2-Compteur Conges Payes'!E:E,C9,'2-Compteur Conges Payes'!H:H),0) | I9: =G9-H9
B10: SD-006 | C10: Maintenance | D10: Juin | E10: 2025 | F10: =COUNTIF('2-Compteur Conges Payes'!E:E,C10) | G10: =IFERROR(SUMIF('2-Compteur Conges Payes'!E:E,C10,'2-Compteur Conges Payes'!G:G),0) | H10: =IFERROR(SUMIF('2-Compteur Conges Payes'!E:E,C10,'2-Compteur Conges Payes'!H:H),0) | I10: =G10-H10
B11: SD-007 | C11: Sécurité | D11: Juin | E11: 2025 | F11: =COUNTIF('2-Compteur Conges Payes'!E:E,C11) | G11: =IFERROR(SUMIF('2-Compteur Conges Payes'!E:E,C11,'2-Compteur Conges Payes'!G:G),0) | H11: =IFERROR(SUMIF('2-Compteur Conges Payes'!E:E,C11,'2-Compteur Conges Payes'!H:H),0) | I11: =G11-H11
B12: =IF(C12="","SD-"&TEXT(COUNTA($C$5:C12),"000")) | I12: =IF(G12="","",G12-H12)
B13: =IF(C13="","SD-"&TEXT(COUNTA($C$5:C13),"000")) | I13: =IF(G13="","",G13-H13)
B14: =IF(C14="","SD-"&TEXT(COUNTA($C$5:C14),"000")) | I14: =IF(G14="","",G14-H14)
B15: =IF(C15="","SD-"&TEXT(COUNTA($C$5:C15),"000")) | I15: =IF(G15="","",G15-H15)
B16: =IF(C16="","SD-"&TEXT(COUNTA($C$5:C16),"000")) | I16: =IF(G16="","",G16-H16)
B17: =IF(C17="","SD-"&TEXT(COUNTA($C$5:C17),"000")) | I17: =IF(G17="","",G17-H17)
B18: =IF(C18="","SD-"&TEXT(COUNTA($C$5:C18),"000")) | I18: =IF(G18="","",G18-H18)
B19: =IF(C19="","SD-"&TEXT(COUNTA($C$5:C19),"000")) | I19: =IF(G19="","",G19-H19)
B20: =IF(C20="","SD-"&TEXT(COUNTA($C$5:C20),"000")) | I20: =IF(G20="","",G20-H20)
B21: =IF(C21="","SD-"&TEXT(COUNTA($C$5:C21),"000")) | I21: =IF(G21="","",G21-H21)
B22: =IF(C22="","SD-"&TEXT(COUNTA($C$5:C22),"000")) | I22: =IF(G22="","",G22-H22)
B23: =IF(C23="","SD-"&TEXT(COUNTA($C$5:C23),"000")) | I23: =IF(G23="","",G23-H23)
... B111: =IF(C111="","SD-"&TEXT(COUNTA($C$5:C111),"000")) | I111: =IF(G111="","",G111-H111)
B113: TOTAL | F113: =SUM(F5:F104) | G113: =SUM(G5:G104) | H113: =SUM(H5:H104) | I113: =SUM(I5:I104)
B115: INDICATEURS (mis a jour automatiquement)
B116: Solde total hotel (j) | D116: Total droits (j) | F116: Total pris (j) | H116: Taux prise moyen
B117: =SUM(I5:I104) | D117: =SUM(G5:G104) | F117: =SUM(H5:H104) | H117: =IFERROR(AVERAGE(H5:H104)/AVERAGE(G5:G104),0)

Sheet 15-Historique Presence Annuelle
B2: HISTORIQUE DE PRESENCE ANNUELLE
B3: TABLEAU DYNAMIQUE — Saisissez dans la prochaine ligne jaune. Les calculs se mettent a jour automatiquement.
B4: N° | C4: Matricule | D4: Nom Employe | E4: Departement | F4: Annee | G4: Jours Presence | H4: Jours Conges | I4: Jours Maladie | J4: Jours Absence NJ | K4: Jours Formation | L4: Taux Presence (%)
B5: HP-001 | C5: EMP-001 | D5: =IF(C5="","",VLOOKUP(C5,'_Données Employés'!$B$5:$H$18,4,FALSE)&" "&VLOOKUP(C5,'_Données Employés'!$B$5:$H$18,5,FALSE)) | E5: =IF(C5="","",VLOOKUP(C5,'_Données Employés'!$B$5:$H$18,6,FALSE)) | F5: 2025 | G5: 118 | H5: =IFERROR(SUMIF('3-Planning Departs Conge'!C:C,C5,'3-Planning Departs Conge'!I:I)+SUMIF('5-Conges Sans Solde'!C:C,C5,'5-Conges Sans Solde'!I:I),0) | I5: =IFERROR(SUMIF('8-Arrets Maladie'!C:C,C5,'8-Arrets Maladie'!I:I)+SUMIF('9-Arrets Accident Travail'!C:C,C5,'9-Arrets Accident Travail'!I:I)+SUMIF('10-Conges Maternite Paternite'!C:C,C5,'10-Conges Maternite Paternite'!J:I),0) | J5: =IFERROR(SUMIF('6-Absences Non Justifiees'!C:C,C5,'6-Absences Non Justifiees'!I:I),0) | K5: 2 | L5: =IFERROR(ROUND(G5/(G5+H5+I5+J5+K5)*100,1),0)
B6: HP-002 | C6: EMP-002 | D6: =IF(C6="","",VLOOKUP(C6,'_Données Employés'!$B$5:$H$18,4,FALSE)&" "&VLOOKUP(C6,'_Données Employés'!$B$5:$H$18,5,FALSE)) | E6: =IF(C6="","",VLOOKUP(C6,'_Données Employés'!$B$5:$H$18,6,FALSE)) | F6: 2025 | G6: 125 | H6: =IFERROR(SUMIF('3-Planning Departs Conge'!C:C,C6,'3-Planning Departs Conge'!I:I)+SUMIF('5-Conges Sans Solde'!C:C,C6,'5-Conges Sans Solde'!I:I),0) | I6: =IFERROR(SUMIF('8-Arrets Maladie'!C:C,C6,'8-Arrets Maladie'!I:I)+SUMIF('9-Arrets Accident Travail'!C:C,C6,'9-Arrets Accident Travail'!I:I)+SUMIF('10-Conges Maternite Paternite'!C:C,C6,'10-Conges Maternite Paternite'!J:I),0) | J6: =IFERROR(SUMIF('6-Absences Non Justifiees'!C:C,C6,'6-Absences Non Justifiees'!I:I),0) | K6: 1 | L6: =IFERROR(ROUND(G6/(G6+H6+I6+J6+K6)*100,1),0)
B7: HP-003 | C7: EMP-003 | D7: =IF(C7="","",VLOOKUP(C7,'_Données Employés'!$B$5:$H$18,4,FALSE)&" "&VLOOKUP(C7,'_Données Employés'!$B$5:$H$18,5,FALSE)) | E7: =IF(C7="","",VLOOKUP(C7,'_Données Employés'!$B$5:$H$18,6,FALSE)) | F7: 2025 | G7: 112 | H7: =IFERROR(SUMIF('3-Planning Departs Conge'!C:C,C7,'3-Planning Departs Conge'!I:I)+SUMIF('5-Conges Sans Solde'!C:C,C7,'5-Conges Sans Solde'!I:I),0) | I7: =IFERROR(SUMIF('8-Arrets Maladie'!C:C,C7,'8-Arrets Maladie'!I:I)+SUMIF('9-Arrets Accident Travail'!C:C,C7,'9-Arrets Accident Travail'!I:I)+SUMIF('10-Conges Maternite Paternite'!C:C,C7,'10-Conges Maternite Paternite'!J:I),0) | J7: =IFERROR(SUMIF('6-Absences Non Justifiees'!C:C,C7,'6-Absences Non Justifiees'!I:I),0) | K7: 1 | L7: =IFERROR(ROUND(G7/(G7+H7+I7+J7+K7)*100,1),0)
B8: HP-004 | C8: EMP-004 | D8: =IF(C8="","",VLOOKUP(C8,'_Données Employés'!$B$5:$H$18,4,FALSE)&" "&VLOOKUP(C8,'_Données Employés'!$B$5:$H$18,5,FALSE)) | E8: =IF(C8="","",VLOOKUP(C8,'_Données Employés'!$B$5:$H$18,6,FALSE)) | F8: 2025 | G8: 115 | H8: =IFERROR(SUMIF('3-Planning Departs Conge'!C:C,C8,'3-Planning Departs Conge'!I:I)+SUMIF('5-Conges Sans Solde'!C:C,C8,'5-Conges Sans Solde'!I:I),0) | I8: =IFERROR(SUMIF('8-Arrets Maladie'!C:C,C8,'8-Arrets Maladie'!I:I)+SUMIF('9-Arrets Accident Travail'!C:C,C8,'9-Arrets Accident Travail'!I:I)+SUMIF('10-Conges Maternite Paternite'!C:C,C8,'10-Conges Maternite Paternite'!J:I),0) | J8: =IFERROR(SUMIF('6-Absences Non Justifiees'!C:C,C8,'6-Absences Non Justifiees'!I:I),0) | K8: 0 | L8: =IFERROR(ROUND(G8/(G8+H8+I8+J8+K8)*100,1),0)
B9: HP-005 | C9: EMP-005 | D9: =IF(C9="","",VLOOKUP(C9,'_Données Employés'!$B$5:$H$18,4,FALSE)&" "&VLOOKUP(C9,'_Données Employés'!$B$5:$H$18,5,FALSE)) | E9: =IF(C9="","",VLOOKUP(C9,'_Données Employés'!$B$5:$H$18,6,FALSE)) | F9: 2025 | G9: 108 | H9: =IFERROR(SUMIF('3-Planning Departs Conge'!C:C,C9,'3-Planning Departs Conge'!I:I)+SUMIF('5-Conges Sans Solde'!C:C,C9,'5-Conges Sans Solde'!I:I),0) | I9: =IFERROR(SUMIF('8-Arrets Maladie'!C:C,C9,'8-Arrets Maladie'!I:I)+SUMIF('9-Arrets Accident Travail'!C:C,C9,'9-Arrets Accident Travail'!I:I)+SUMIF('10-Conges Maternite Paternite'!C:C,C9,'10-Conges Maternite Paternite'!J:I),0) | J9: =IFERROR(SUMIF('6-Absences Non Justifiees'!C:C,C9,'6-Absences Non Justifiees'!I:I),0) | K9: 1 | L9: =IFERROR(ROUND(G9/(G9+H9+I9+J9+K9)*100,1),0)
B10: HP-028 | C10: EMP-028 | D10: =IF(C10="","",VLOOKUP(C10,'_Données Employés'!$B$5:$H$18,4,FALSE)&" "&VLOOKUP(C10,'_Données Employés'!$B$5:$H$18,5,FALSE)) | E10: =IF(C10="","",VLOOKUP(C10,'_Données Employés'!$B$5:$H$18,6,FALSE)) | F10: 2025 | G10: 120 | H10: =IFERROR(SUMIF('3-Planning Departs Conge'!C:C,C10,'3-Planning Departs Conge'!I:I)+SUMIF('5-Conges Sans Solde'!C:C,C10,'5-Conges Sans Solde'!I:I),0) | I10: =IFERROR(SUMIF('8-Arrets Maladie'!C:C,C10,'8-Arrets Maladie'!I:I)+SUMIF('9-Arrets Accident Travail'!C:C,C10,'9-Arrets Accident Travail'!I:I)+SUMIF('10-Conges Maternite Paternite'!C:C,C10,'10-Conges Maternite Paternite'!J:I),0) | J10: =IFERROR(SUMIF('6-Absences Non Justifiees'!C:C,C10,'6-Absences Non Justifiees'!I:I),0) | K10: 0 | L10: =IFERROR(ROUND(G10/(G10+H10+I10+J10+K10)*100,1),0)
B11: HP-029 | C11: EMP-029 | D11: =IF(C11="","",VLOOKUP(C11,'_Données Employés'!$B$5:$H$18,4,FALSE)&" "&VLOOKUP(C11,'_Données Employés'!$B$5:$H$18,5,FALSE)) | E11: =IF(C11="","",VLOOKUP(C11,'_Données Employés'!$B$5:$H$18,6,FALSE)) | F11: 2025 | G11: 120 | H11: =IFERROR(SUMIF('3-Planning Departs Conge'!C:C,C11,'3-Planning Departs Conge'!I:I)+SUMIF('5-Conges Sans Solde'!C:C,C11,'5-Conges Sans Solde'!I:I),0) | I11: =IFERROR(SUMIF('8-Arrets Maladie'!C:C,C11,'8-Arrets Maladie'!I:I)+SUMIF('9-Arrets Accident Travail'!C:C,C11,'9-Arrets Accident Travail'!I:I)+SUMIF('10-Conges Maternite Paternite'!C:C,C11,'10-Conges Maternite Paternite'!J:I),0) | J11: =IFERROR(SUMIF('6-Absences Non Justifiees'!C:C,C11,'6-Absences Non Justifiees'!I:I),0) | K11: 0 | L11: =IFERROR(ROUND(G11/(G11+H11+I11+J11+K11)*100,1),0)
B12: =IF(C12="","HP-"&TEXT(COUNTA($C$5:C12),"000")) | L12: =IF(G12="","",IF((G12+H12+I12+J12+K12)=0,"",G12/(G12+H12+I12+J12+K12)))
B13: =IF(C13="","HP-"&TEXT(COUNTA($C$5:C13),"000")) | L13: =IF(G13="","",IF((G13+H13+I13+J13+K13)=0,"",G13/(G13+H13+I13+J13+K13)))
B14: =IF(C14="","HP-"&TEXT(COUNTA($C$5:C14),"000")) | L14: =IF(G14="","",IF((G14+H14+I14+J14+K14)=0,"",G14/(G14+H14+I14+J14+K14)))
B15: =IF(C15="","HP-"&TEXT(COUNTA($C$5:C15),"000")) | L15: =IF(G15="","",IF((G15+H15+I15+J15+K15)=0,"",G15/(G15+H15+I15+J15+K15)))
B16: =IF(C16="","HP-"&TEXT(COUNTA($C$5:C16),"000")) | L16: =IF(G16="","",IF((G16+H16+I16+J16+K16)=0,"",G16/(G16+H16+I16+J16+K16)))
B17: =IF(C17="","HP-"&TEXT(COUNTA($C$5:C17),"000")) | L17: =IF(G17="","",IF((G17+H17+I17+J17+K17)=0,"",G17/(G17+H17+I17+J17+K17)))
B18: =IF(C18="","HP-"&TEXT(COUNTA($C$5:C18),"000")) | L18: =IF(G18="","",IF((G18+H18+I18+J18+K18)=0,"",G18/(G18+H18+I18+J18+K18)))
B19: =IF(C19="","HP-"&TEXT(COUNTA($C$5:C19),"000")) | L19: =IF(G19="","",IF((G19+H19+I19+J19+K19)=0,"",G19/(G19+H19+I19+J19+K19)))
B20: =IF(C20="","HP-"&TEXT(COUNTA($C$5:C20),"000")) | L20: =IF(G20="","",IF((G20+H20+I20+J20+K20)=0,"",G20/(G20+H20+I20+J20+K20)))
B21: =IF(C21="","HP-"&TEXT(COUNTA($C$5:C21),"000")) | L21: =IF(G21="","",IF((G21+H21+I21+J21+K21)=0,"",G21/(G21+H21+I21+J21+K21)))
B22: =IF(C22="","HP-"&TEXT(COUNTA($C$5:C22),"000")) | L22: =IF(G22="","",IF((G22+H22+I22+J22+K22)=0,"",G22/(G22+H22+I22+J22+K22)))
B23: =IF(C23="","HP-"&TEXT(COUNTA($C$5:C23),"000")) | L23: =IF(G23="","",IF((G23+H23+I23+J23+K23)=0,"",G23/(G23+H23+I23+J23+K23)))
... B109: =IF(C109="","HP-"&TEXT(COUNTA($C$5:C109),"000")) | L109: =IF(G109="","",IF((G109+H109+I109+J109+K109)=0,"",G109/(G109+H109+I109+J109+K109)))
B111: TOTAL | G111: =SUM(G5:G104) | H111: =SUM(H5:H104) | I111: =SUM(I5:I104) | J111: =SUM(J5:J104) | K111: =SUM(K5:K104)
B113: INDICATEURS (mis a jour automatiquement)
B114: Effectif suivi | D114: Taux presence moyen | F114: Total conges (j) | H114: Total maladie (j)
B115: =COUNTIF(B5:B104,"<>") | D115: =IFERROR(AVERAGE(L5:L104),0) | F115: =SUM(H5:H104) | H115: =SUM(I5:I104)

Sheet 16-Calendrier Conges
B2: CALENDRIER MENSUEL DES CONGES & ABSENCES
B3: TABLEAU DYNAMIQUE — Saisissez dans la prochaine ligne jaune. Les calculs se mettent a jour automatiquement.
B4: N° | C4: Departement | D4: Mois | E4: Annee | F4: Nb Conges Planifies | G4: Nb Conges Effectues | H4: Nb Permissions | I4: Nb Arrets Maladie | J4: Effectif Present Moyen
B5: CAL-001 | C5: Service Client | D5: Janvier | E5: 2025 | F5: 2 | G5: 2 | H5: 0 | I5: 0 | J5: 5
B6: CAL-002 | C6: Service Client | D6: Fevrier | E6: 2025 | F6: 1 | G6: 1 | H6: 1 | I6: 0 | J6: 5
