Workbook

Sheet F01 - _Données Centrales
A2: DOMAINE 27 — GESTION DE LA SANTÉ, SÉCURITÉ ET BIEN-ÊTRE AU TRAVAIL
A3: DONNÉES CENTRALES — Base de référence (toutes les feuilles s'y réfèrent)
A5: Code SST | B5: Département | C5: Poste de Travail | D5: Zone à Risque | E5: Catégorie de Risque | F5: Exercice | G5: Budget Alloué (FCFA) | H5: Budget Consommé (FCFA) | I5: Reste à Consommer (FCFA) | J5: Taux Consommation (%) | K5: Responsable SST | L5: Statut
A6: SST-001 | B6: Cuisine & Restauration | C6: Chef cuisinier | D6: Zone cuisson | E6: Risque physique | F6: 2025 | G6: 4500000 | H6: 3200000 | I6: =G6-H6 | J6: =IFERROR(H6/G6,0) | K6: M. Tchinda | L6: En cours
A7: SST-002 | B7: Cuisine & Restauration | C7: Plongeur | D7: Zone lavage | E7: Risque chimique | F7: 2025 | G7: 1200000 | H7: 980000 | I7: =G7-H7 | J7: =IFERROR(H7/G7,0) | K7: M. Tchinda | L7: En cours
A8: SST-003 | B8: Maintenance & Technique | C8: Électricien | D8: Tableau électrique | E8: Risque électrique | F8: 2025 | G8: 3800000 | H8: 2900000 | I8: =G8-H8 | J8: =IFERROR(H8/G8,0) | K8: M. Ondo | L8: En cours
A9: SST-004 | B9: Maintenance & Technique | C9: Mécanicien | D9: Atelier | E9: Risque physique | F9: 2025 | G9: 2500000 | H9: 1850000 | I9: =G9-H9 | J9: =IFERROR(H9/G9,0) | K9: M. Ondo | L9: En cours
A10: SST-005 | B10: Réception & Front Office | C10: Réceptionniste | D10: Hall accueil | E10: Risque ergonomique | F10: 2025 | G10: 800000 | H10: 520000 | I10: =G10-H10 | J10: =IFERROR(H10/G10,0) | K10: Mme. Ngassa | L10: En cours
A11: SST-006 | B11: Sécurité | C11: Agent sécurité | D11: Poste gardiennage | E11: Risque psychosocial | F11: 2025 | G11: 1500000 | H11: 1100000 | I11: =G11-H11 | J11: =IFERROR(H11/G11,0) | K11: M. Essamba | L11: En cours
A12: SST-007 | B12: Cuisine & Restauration | C12: Serveur | D12: Salle restaurant | E12: Risque glissade | F12: 2025 | G12: 600000 | H12: 420000 | I12: =G12-H12 | J12: =IFERROR(H12/G12,0) | K12: M. Tchinda | L12: En cours
A13: SST-008 | B13: Maintenance & Technique | C13: Plombier | D13: Local technique | E13: Risque chimique | F13: 2025 | G13: 1100000 | H13: 750000 | I13: =G13-H13 | J13: =IFERROR(H13/G13,0) | K13: M. Ondo | L13: En cours
A14: SST-009 | B14: Spa & Bien-être | C14: Esthéticienne | D14: Cabine soin | E14: Risque chimique | F14: 2025 | G14: 900000 | H14: 680000 | I14: =G14-H14 | J14: =IFERROR(H14/G14,0) | K14: Mme. Fotso | L14: En cours
A15: SST-010 | B15: Commerce | C15: Vendeur | D15: Espace vente | E15: Risque ergonomique | F15: 2025 | G15: 500000 | H15: 320000 | I15: =G15-H15 | J15: =IFERROR(H15/G15,0) | K15: M. Nkoulou | L15: En cours
A16: SST-011 | B16: Tous départements | C16: Tous postes | D16: Ensemble site | E16: Risque incendie | F16: 2025 | G16: 5200000 | H16: 4100000 | I16: =G16-H16 | J16: =IFERROR(H16/G16,0) | K16: M. Ondo | L16: En cours
A17: SST-012 | B17: Tous départements | C17: Tous postes | D17: Ensemble site | E17: Risque sanitaire | F17: 2025 | G17: 3500000 | H17: 2800000 | I17: =G17-H17 | J17: =IFERROR(H17/G17,0) | K17: Dr. Manga | L17: En cours
... A20: SST-015 | B20: Finance & Comptabilité | C20: Comptables | D20: Bureaux | E20: Risque visuel | F20: 2025 | G20: 700000 | H20: 480000 | I20: =G20-H20 | J20: =IFERROR(H20/G20,0) | K20: M. Eyenga | L20: En cours

Sheet F02 - _Lists
A2: DOMAINE 27 — LISTES DE RÉFÉRENCE
A3: Valeurs pour listes déroulantes — Saisissez vos propres valeurs
A5: codes_sst | B5: departements | C5: postes_travail | D5: zones_risque | E5: categories_risque | F5: exercices | G5: statuts_sst | H5: types_accident | I5: gravites | J5: severites | K5: statuts_action | L5: niveaux_risque | M5: sources_risque | N5: types_formation | O5: types_epi | P5: frequences | Q5: statuts_conformite | R5: periodes | S5: mois | T5: types_audit
A6: SST-001 | B6: Direction Générale | C6: Chef cuisinier | D6: Zone cuisson | E6: Risque physique | F6: 2024 | G6: En cours | H6: Chute de plain-pied | I6: Mineure | J6: Faible | K6: En cours | L6: Faible | M6: Machines | N6: Habilitation électrique | O6: Casque | P6: Hebdomadaire | Q6: Conforme | R6: Janvier | S6: Janvier | T6: Interne
A7: SST-002 | B7: Ressources Humaines | C7: Plongeur | D7: Zone lavage | E7: Risque chimique | F7: 2025 | G7: Clôturé | H7: Chute de hauteur | I7: Modérée | J7: Moyenne | K7: Terminée | L7: Moyen | M7: Produits chimiques | N7: Secourisme | O7: Lunettes | P7: Mensuelle | Q7: Non conforme | R7: Février | S7: Février | T7: Externe
A8: SST-003 | B8: Finance & Comptabilité | C8: Électricien | D8: Tableau électrique | E8: Risque électrique | F8: 2026 | G8: Dépassé | H8: Blessure coupure | I8: Grave | J8: Élevée | K8: Planifiée | L8: Élevé | M8: Électricité | N8: Manipulation produits | O8: Gants | P8: Trimestrielle | Q8: En attente | R8: Mars | S8: Mars | T8: Mixte
A9: SST-004 | B9: Cuisine & Restauration | C9: Mécanicien | D9: Atelier | E9: Risque ergonomique | F9: 2027 | G9: En attente | H9: Brûlure | I9: Fatale | J9: Critique | K9: En attente | L9: Critique | M9: Ergonomie | N9: Travail en hauteur | O9: Chaussures sécurité | P9: Semestrielle | Q9: À régulariser | R9: Avril | S9: Avril | T9: Réglementaire
A10: SST-005 | B10: Réception & Front Office | C10: Réceptionniste | D10: Hall accueil | E10: Risque psychosocial | G10: Planifié | H10: Électrocution | K10: Annulée | M10: Manutention | N10: Ergonomie poste | O10: Gilet haute visibilité | P10: Annuelle | Q10: En cours de vérification | R10: Mai | S10: Mai | T10: Inopiné
A11: SST-006 | B11: Maintenance & Technique | C11: Agent sécurité | D11: Poste gardiennage | E11: Risque glissade | G11: Annulé | H11: Intoxication | K11: Reportée | M11: Circulation | N11: Incendie | O11: Masque | P11: Bisannuelle | Q11: Exempté | R11: Juin | S11: Juin | T11: Programmé
A12: SST-007 | B12: Marketing & Communication | C12: Serveur | D12: Salle restaurant | E12: Risque incendie | G12: Urgent | H12: TMS (troubles musculosquelettiques) | M12: Bruit | N12: Évacuation | O12: Bouchons antibruit | P12: Quinquennale | R12: Juillet | S12: Juillet
A13: SST-008 | B13: Revenue Management | C13: Plombier | D13: Local technique | E13: Risque sanitaire | H13: Exposition chimique | M13: Vibrations | N13: Premiers gestes | O13: Harnais | R13: Août | S13: Août
A14: SST-009 | B14: Spa & Bien-être | C14: Esthéticienne | D14: Cabine soin | E14: Risque visuel | H14: Accident véhicule | M14: Radiations | N14: TMS prévention | O14: Tablier | R14: Septembre | S14: Septembre
A15: SST-010 | B15: Sécurité | C15: Vendeur | D15: Espace vente | E15: Risque biologique | H15: Malaise | M15: Agents biologiques | N15: Gestion du stress | O15: Protège-bras | R15: Octobre | S15: Octobre
A16: SST-011 | B16: Commerce | C16: Cadre | D16: Bureaux | E16: Risque bruit | H16: Lombalgie | M16: Stress | O16: Masque à gaz | R16: Novembre | S16: Novembre
A17: SST-012 | B17: Gouvernance | C17: Comptable | D17: Parking | E17: Risque vibration | H17: Contact oculaire | M17: Chaleur | O17: Combinaison | R17: Décembre | S17: Décembre
A18: SST-013 | C18: Agent entretien | D18: Entrepôt | M18: Froid
A19: SST-014 | C19: Jardinier | D19: Jardin | M19: Humidité
A20: SST-015 | C20: Chauffeur | D20: Cuisine collective

Sheet F03 - 1-Tableau de Bord SST
A2: DOMAINE 27 — TABLEAU DE BORD SYNTHÉTIQUE SST
A3: Vue globale de la santé, sécurité et bien-être au travail
A6: Budget Total Alloué SST (FCFA) | B6: =SUM('F01 - _Données Centrales'!G6:G20) | C6: Budget Consommé SST (FCFA) | D6: =SUM('F01 - _Données Centrales'!H6:H20) | E6: Taux Consommation Global | F6: =IFERROR(SUM('F01 - _Données Centrales'!H6:H20)/SUM('F01 - _Données Centrales'!G6:G20),0) | G6: Écart Budgétaire (FCFA) | H6: =SUM('F01 - _Données Centrales'!G6:G20)-SUM('F01 - _Données Centrales'!H6:H20) | I6: Nb Accidents (Année) | J6: 12 | K6: Taux de Fréquence | L6: 8.5
A9: Nb Jours d'Arrêt Total | B9: 45 | C9: Taux de Gravité | D9: 0.35 | E9: Nb Visites Médicales | F9: 85 | G9: Formations SST Réalisées | H9: 14 | I9: Actions Correctives En Cours | J9: =COUNTIF('F01 - _Données Centrales'!L6:L20,"En cours") | K9: Nb Zones à Risque | L9: =COUNTA('F01 - _Données Centrales'!D6:D20)

Sheet F04 - 2-Registre Risques Prof.
A2: DOMAINE 27 — 2-REGISTRE DES RISQUES PROFESSIONNELS
A3: TABLEAU DYNAMIQUE — Identification et évaluation des risques par poste
A5: Code Risque | B5: Département | C5: Poste | D5: Danger Identifié | E5: Source de Risque | F5: Population Exposée | G5: Probabilité (1-5) | H5: Gravité (1-5) | I5: Criticité | J5: Mesure de Prévention | K5: Mesure de Protection | L5: Niveau Risque Résiduel | M5: Date Évaluation
A6: RP-001 | B6: Cuisine & Restauration | C6: Chef cuisinier | D6: Brûlure | E6: Machines | F6: 8 | G6: 4 | H6: 4 | I6: =G6*H6 | J6: Gants thermiques | K6: Extincteur proximité | L6: =IF(I6>=20,"Critique",IF(I6>=12,"Élevé",IF(I6>=6,"Moyen","Faible"))) | M6: 45672
A7: RP-002 | B7: Cuisine & Restauration | C7: Plongeur | D7: Dermatite | E7: Produits chimiques | F7: 6 | G7: 3 | H7: 3 | I7: =G7*H7 | J7: Gants latex | K7: Crème protectrice | L7: =IF(I7>=20,"Critique",IF(I7>=12,"Élevé",IF(I7>=6,"Moyen","Faible"))) | M7: 45672
A8: RP-003 | B8: Maintenance | C8: Électricien | D8: Électrocution | E8: Électricité | F8: 5 | G8: 4 | H8: 5 | I8: =G8*H8 | J8: LOTO systématique | K8: EPI diélectrique | L8: =IF(I8>=20,"Critique",IF(I8>=12,"Élevé",IF(I8>=6,"Moyen","Faible"))) | M8: 45677
A9: RP-004 | B9: Maintenance | C9: Mécanicien | D9: Coupure | E9: Machines | F9: 7 | G9: 3 | H9: 3 | I9: =G9*H9 | J9: Protège-mains | K9: Machine avec protecteur | L9: =IF(I9>=20,"Critique",IF(I9>=12,"Élevé",IF(I9>=6,"Moyen","Faible"))) | M9: 45677
A10: RP-005 | B10: Réception | C10: Réceptionniste | D10: Lombalgie | E10: Ergonomie | F10: 25 | G10: 2 | H10: 2 | I10: =G10*H10 | J10: Aménagement poste | K10: Chaise ergonomique | L10: =IF(I10>=20,"Critique",IF(I10>=12,"Élevé",IF(I10>=6,"Moyen","Faible"))) | M10: 45689
A11: RP-006 | B11: Sécurité | C11: Agent sécurité | D11: Stress chronique | E11: Stress | F11: 15 | G11: 3 | H11: 4 | I11: =G11*H11 | J11: Rotation postes | K11: Entretien psychologique | L11: =IF(I11>=20,"Critique",IF(I11>=12,"Élevé",IF(I11>=6,"Moyen","Faible"))) | M11: 45689
A12: RP-007 | B12: Cuisine & Restauration | C12: Serveur | D12: Glissade | E12: Circulation | F12: 12 | G12: 3 | H12: 2 | I12: =G12*H12 | J12: Revêtement antidérapant | K12: Signalisation | L12: =IF(I12>=20,"Critique",IF(I12>=12,"Élevé",IF(I12>=6,"Moyen","Faible"))) | M12: 45698
A13: RP-008 | B13: Maintenance | C13: Plombier | D13: Intoxication | E13: Produits chimiques | F13: 4 | G13: 3 | H13: 4 | I13: =G13*H13 | J13: Masque respiratoire | K13: Ventilation locale | L13: =IF(I13>=20,"Critique",IF(I13>=12,"Élevé",IF(I13>=6,"Moyen","Faible"))) | M13: 45703
A14: RP-009 | B14: Spa & Bien-être | C14: Esthéticienne | D14: Allergie cutanée | E14: Produits chimiques | F14: 6 | G14: 2 | H14: 2 | I14: =G14*H14 | J14: Gants nitrile | K14: Fiche données produit | L14: =IF(I14>=20,"Critique",IF(I14>=12,"Élevé",IF(I14>=6,"Moyen","Faible"))) | M14: 45717
A15: RP-010 | B15: Tous départements | C15: Tous | D15: Incendie | E15: Circulation | F15: 154 | G15: 1 | H15: 5 | I15: =G15*H15 | J15: Extincteurs, alarmes | K15: Plan évacuation | L15: =IF(I15>=20,"Critique",IF(I15>=12,"Élevé",IF(I15>=6,"Moyen","Faible"))) | M15: 45667
A16: RP-011 | B16: Tous départements | C16: Tous | D16: Pandémie | E16: Agents biologiques | F16: 154 | G16: 2 | H16: 4 | I16: =G16*H16 | J16: Protocole sanitaire | K16: Masks, gel hydroalcoolique | L16: =IF(I16>=20,"Critique",IF(I16>=12,"Élevé",IF(I16>=6,"Moyen","Faible"))) | M16: 45667
A17: RP-012 | B17: Commerce | C17: Vendeur | D17: TMS épaule | E17: Manutention | F17: 10 | G17: 3 | H17: 2 | I17: =G17*H17 | J17: Formation manutention | K17: Chariot aide | L17: =IF(I17>=20,"Critique",IF(I17>=12,"Élevé",IF(I17>=6,"Moyen","Faible"))) | M17: 45731
I18: =IF(G18="","",G18*H18) | L18: =IF(I18="","",IF(I18>=20,"Critique",IF(I18>=12,"Élevé",IF(I18>=6,"Moyen","Faible"))))
I19: =IF(G19="","",G19*H19) | L19: =IF(I19="","",IF(I19>=20,"Critique",IF(I19>=12,"Élevé",IF(I19>=6,"Moyen","Faible"))))
I20: =IF(G20="","",G20*H20) | L20: =IF(I20="","",IF(I20>=20,"Critique",IF(I20>=12,"Élevé",IF(I20>=6,"Moyen","Faible"))))
I21: =IF(G21="","",G21*H21) | L21: =IF(I21="","",IF(I21>=20,"Critique",IF(I21>=12,"Élevé",IF(I21>=6,"Moyen","Faible"))))
I22: =IF(G22="","",G22*H22) | L22: =IF(I22="","",IF(I22>=20,"Critique",IF(I22>=12,"Élevé",IF(I22>=6,"Moyen","Faible"))))
I23: =IF(G23="","",G23*H23) | L23: =IF(I23="","",IF(I23>=20,"Critique",IF(I23>=12,"Élevé",IF(I23>=6,"Moyen","Faible"))))
I24: =IF(G24="","",G24*H24) | L24: =IF(I24="","",IF(I24>=20,"Critique",IF(I24>=12,"Élevé",IF(I24>=6,"Moyen","Faible"))))
I25: =IF(G25="","",G25*H25) | L25: =IF(I25="","",IF(I25>=20,"Critique",IF(I25>=12,"Élevé",IF(I25>=6,"Moyen","Faible"))))
I26: =IF(G26="","",G26*H26) | L26: =IF(I26="","",IF(I26>=20,"Critique",IF(I26>=12,"Élevé",IF(I26>=6,"Moyen","Faible"))))
I27: =IF(G27="","",G27*H27) | L27: =IF(I27="","",IF(I27>=20,"Critique",IF(I27>=12,"Élevé",IF(I27>=6,"Moyen","Faible"))))
I28: =IF(G28="","",G28*H28) | L28: =IF(I28="","",IF(I28>=20,"Critique",IF(I28>=12,"Élevé",IF(I28>=6,"Moyen","Faible"))))
I29: =IF(G29="","",G29*H29) | L29: =IF(I29="","",IF(I29>=20,"Critique",IF(I29>=12,"Élevé",IF(I29>=6,"Moyen","Faible"))))
... I115: =IF(G115="","",G115*H115) | L115: =IF(I115="","",IF(I115>=20,"Critique",IF(I115>=12,"Élevé",IF(I115>=6,"Moyen","Faible"))))

Sheet F05 - 3-Suivi Accidents Travail
A2: DOMAINE 27 — 3-SUIVI DES ACCIDENTS DE TRAVAIL
A3: TABLEAU DYNAMIQUE — Enregistrement et analyse des accidents
A5: Code Accident | B5: Date | C5: Département | D5: Victime | E5: Type d'Accident | F5: Gravité | G5: Lieu Exact | H5: Description | I5: Jours d'Arrêt | J5: Coût Direct (FCFA) | K5: Coût Indirect (FCFA) | L5: Coût Total (FCFA) | M5: Enquête Menée | N5: Action Corrective | O5: Statut
A6: AT-2025-001 | B6: 45679 | C6: Cuisine & Restauration | D6: M. Kamga | E6: Brûlure | F6: Modérée | G6: Zone cuisson | H6: Brûlure 2e degré main gauche | I6: 5 | J6: 150000 | K6: 350000 | L6: =J6+K6 | M6: Oui | N6: Gants renforcés fournis | O6: Clôturé
A7: AT-2025-002 | B7: 45702 | C7: Maintenance | D7: M. Nganou | E7: Blessure coupure | F7: Mineure | G7: Atelier | H7: Coupure doigt droit scie | I7: 2 | J7: 50000 | K7: 120000 | L7: =J7+K7 | M7: Oui | N7: Protecteur de scie vérifié | O7: Clôturé
A8: AT-2025-003 | B8: 45721 | C8: Réception | D8: Mme. Awa | E8: Chute de plain-pied | F8: Modérée | G8: Hall accueil | H8: Entorse cheville droite | I8: 14 | J8: 200000 | K8: 800000 | L8: =J8+K8 | M8: Oui | N8: Tapis antidérapant posé | O8: En cours
A9: AT-2025-004 | B9: 45734 | C9: Cuisine & Restauration | D9: M. Bouba | E9: Intoxication | F9: Grave | G9: Zone stockage | H9: Intoxication alimentaire | I9: 7 | J9: 350000 | K9: 600000 | L9: =J9+K9 | M9: Oui | N9: Chaîne du froid renforcée | O9: En cours
A10: AT-2025-005 | B10: 45749 | C10: Maintenance | D10: M. Tabi | E10: Électrocution | F10: Grave | G10: Tableau électrique | H10: Choc électrique bras gauche | I10: 21 | J10: 500000 | K10: 1500000 | L10: =J10+K10 | M10: Oui | N10: LOTO obligatoire décrété | O10: En cours
A11: AT-2025-006 | B11: 45767 | C11: Commerce | D11: Mme. Djiade | E11: TMS (troubles musculosquelettiques) | F11: Modérée | G11: Espace vente | H11: Douleur épaule droite manutention | I11: 10 | J11: 120000 | K11: 400000 | L11: =J11+K11 | M11: Oui | N11: Formation manutention prévue | O11: Planifié
A12: AT-2025-007 | B12: 45785 | C12: Sécurité | D12: M. Essamba | E12: Lombalgie | F12: Mineure | G12: Poste gardiennage | H12: Lombalgie aiguë posture | I12: 3 | J12: 80000 | K12: 150000 | L12: =J12+K12 | M12: Non | N12: Siège ergonomique commandé | O12: Planifié
A13: AT-2025-008 | B13: 45792 | C13: Cuisine & Restauration | D13: Mme. Feuzeu | E13: Chute de plain-pied | F13: Mineure | G13: Salle restaurant | H13: Glissage sol mouillé | I13: 1 | J13: 30000 | K13: 60000 | L13: =J13+K13 | M13: Oui | N13: Signalisation zone humide | O13: Clôturé
A14: AT-2025-009 | B14: 45811 | C14: Maintenance | D14: M. Fotso | E14: Contact oculaire | F14: Modérée | G14: Local technique | H14: Projection produit nettoyant | I14: 4 | J14: 100000 | K14: 250000 | L14: =J14+K14 | M14: Oui | N14: Lunettes de protection fournies | O14: En cours
A15: AT-2025-010 | B15: 45820 | C15: Spa & Bien-être | D15: Mme. Ngo | E15: Exposition chimique | F15: Mineure | G15: Cabine soin | H15: Irritation cutanée produit | I15: 2 | J15: 40000 | K15: 80000 | L15: =J15+K15 | M15: Oui | N15: Substitution produit prévue | O15: Planifié
L16: =IF(J16="","",J16+K16)
L17: =IF(J17="","",J17+K17)
L18: =IF(J18="","",J18+K18)
L19: =IF(J19="","",J19+K19)
L20: =IF(J20="","",J20+K20)
L21: =IF(J21="","",J21+K21)
L22: =IF(J22="","",J22+K22)
L23: =IF(J23="","",J23+K23)
L24: =IF(J24="","",J24+K24)
L25: =IF(J25="","",J25+K25)
L26: =IF(J26="","",J26+K26)
L27: =IF(J27="","",J27+K27)
... L115: =IF(J115="","",J115+K115)

Sheet F06 - 4-Visites Médicales
A2: DOMAINE 27 — 4-VISITES MÉDICALES DU TRAVAIL
A3: TABLEAU DYNAMIQUE — Suivi des examens médicaux obligatoires
A5: Matricule | B5: Nom Complet | C5: Département | D5: Type de Visite | E5: Date Visite | F5: Médecin | G5: Résultat | H5: Aptitude | I5: Restrictions | J5: Date Prochaine Visite | K5: Rappels Médicaux (FCFA) | L5: Statut
A6: EMP-001 | B6: M. Nkoulou Paul | C6: Direction Générale | D6: Visite annuelle | E6: 45677 | F6: Dr. Manga | G6: Normal | H6: Apte | I6: Aucune | J6: 46042 | K6: 25000 | L6: Effectuée
A7: EMP-015 | B7: M. Tchinda Jean | C7: Cuisine & Restauration | D7: Visite annuelle | E7: 45698 | F7: Dr. Manga | G7: Normal | H7: Apte | I7: Aucune | J7: 46063 | K7: 25000 | L7: Effectuée
A8: EMP-023 | B8: M. Ondo André | C8: Maintenance & Technique | D8: Visite annuelle | E8: 45703 | F8: Dr. Manga | G8: Tension élevée | H8: Apte avec restrictions | I8: Pas port de charges lourdes | J8: 45884 | K8: 25000 | L8: Effectuée
A9: EMP-032 | B9: Mme. Ngassa Marie | C9: Réception & Front Office | D9: Visite de reprise | E9: 45721 | F9: Dr. Manga | G9: Convalescence | H9: Inapte temporaire | I9: Repos 2 semaines supp. | J9: 45735 | K9: 35000 | L9: En cours
A10: EMP-045 | B10: M. Kamga Ibrahim | C10: Cuisine & Restauration | D10: Visite après accident | E10: 45682 | F10: Dr. Manga | G10: Brûlure en cicatrisation | H10: Apte avec restrictions | I10: Pas manipulation chauffante | J10: 45772 | K10: 40000 | L10: Effectuée
A11: EMP-067 | B11: M. Essamba Pierre | C11: Sécurité | D11: Visite annuelle | E11: 45736 | F11: Dr. Manga | G11: Stress professionnel | H11: Apte | I11: Suivi psychologique recommandé | J11: 46101 | K11: 25000 | L11: Effectuée
A12: EMP-078 | B12: M. Nganou René | C12: Maintenance & Technique | D12: Visite après accident | E12: 45706 | F12: Dr. Manga | G12: Cicatrisation doigt | H12: Apte | I12: Aucune | J12: 45795 | K12: 35000 | L12: Effectuée
A13: EMP-089 | B13: Mme. Awa Fatou | C13: Réception & Front Office | D13: Visite de reprise | E13: 45757 | F13: Dr. Manga | G13: Entorse résolue | H13: Apte | I13: Rééducation terminée | J13: 45940 | K13: 35000 | L13: En cours
A14: EMP-092 | B14: M. Tabi Célestin | C14: Maintenance & Technique | D14: Visite après accident | E14: 45757 | F14: Dr. Manga | G14: Suivi neurologique | H14: Inapte temporaire | I14: Arrêt prolongé 3 semaines | J14: 45848 | K14: 50000 | L14: En cours
A15: EMP-110 | B15: Mme. Ngo Béatrice | C15: Spa & Bien-être | D15: Visite annuelle | E15: 45782 | F15: Dr. Manga | G15: Irritation cutanée | H15: Apte avec restrictions | I15: Port gants obligatoire | J15: 46147 | K15: 25000 | L15: Effectuée

Sheet F07 - 5-EPI Équip. Protect.
A2: DOMAINE 27 — 5-EPI ET ÉQUIPEMENTS DE PROTECTION INDIVIDUELLE
A3: TABLEAU DYNAMIQUE — Gestion des stocks et distributions EPI
A5: Code EPI | B5: Type EPI | C5: Département | D5: Quantité en Stock | E5: Quantité Distribuée | F5: Quantité Restante | G5: Seuil Minimum | H5: État Stock | I5: Coût Unitaire (FCFA) | J5: Coût Total Stock (FCFA) | K5: Date Dernier Réappro. | L5: Fournisseur | M5: Fréquence Remplacement
A6: EPI-001 | B6: Gants thermiques | C6: Cuisine & Restauration | D6: 50 | E6: 35 | F6: =D6-E6 | G6: 10 | H6: =IF(F6<=G6,"À commander","OK") | I6: 3500 | J6: =D6*I6 | K6: 45717 | L6: SecurPro SARL | M6: Mensuelle
A7: EPI-002 | B7: Gants latex | C7: Cuisine & Restauration | D7: 200 | E7: 150 | F7: =D7-E7 | G7: 50 | H7: =IF(F7<=G7,"À commander","OK") | I7: 800 | J7: =D7*I7 | K7: 45748 | L7: MediSupply | M7: Mensuelle
A8: EPI-003 | B8: Casque électrique | C8: Maintenance | D8: 15 | E8: 10 | F8: =D8-E8 | G8: 5 | H8: =IF(F8<=G8,"À commander","OK") | I8: 25000 | J8: =D8*I8 | K8: 45703 | L8: ElecSafe | M8: Annuelle
A9: EPI-004 | B9: Lunettes protection | C9: Maintenance | D9: 40 | E9: 28 | F9: =D9-E9 | G9: 10 | H9: =IF(F9<=G9,"À commander","OK") | I9: 5000 | J9: =D9*I9 | K9: 45731 | L9: SecurPro SARL | M9: Trimestrielle
A10: EPI-005 | B10: Chaussures sécurité | C10: Tous départements | D10: 80 | E10: 65 | F10: =D10-E10 | G10: 15 | H10: =IF(F10<=G10,"À commander","OK") | I10: 18000 | J10: =D10*I10 | K10: 45677 | L10: SafetyWear | M10: Annuelle
A11: EPI-006 | B11: Gilet haute visibilité | C11: Sécurité | D11: 25 | E11: 20 | F11: =D11-E11 | G11: 5 | H11: =IF(F11<=G11,"À commander","OK") | I11: 8000 | J11: =D11*I11 | K11: 45689 | L11: SafetyWear | M11: Semestrielle
A12: EPI-007 | B12: Masque respiratoire | C12: Maintenance | D12: 30 | E12: 18 | F12: =D12-E12 | G12: 8 | H12: =IF(F12<=G12,"À commander","OK") | I12: 12000 | J12: =D12*I12 | K12: 45717 | L12: ElecSafe | M12: Mensuelle
A13: EPI-008 | B13: Bouchons antibruit | C13: Maintenance | D13: 100 | E13: 72 | F13: =D13-E13 | G13: 20 | H13: =IF(F13<=G13,"À commander","OK") | I13: 1500 | J13: =D13*I13 | K13: 45748 | L13: SecurPro SARL | M13: Mensuelle
A14: EPI-009 | B14: Tablier cuisson | C14: Cuisine & Restauration | D14: 30 | E14: 22 | F14: =D14-E14 | G14: 8 | H14: =IF(F14<=G14,"À commander","OK") | I14: 7000 | J14: =D14*I14 | K14: 45698 | L14: RestoEquip | M14: Trimestrielle
A15: EPI-010 | B15: Gants nitrile | C15: Spa & Bien-être | D15: 150 | E15: 110 | F15: =D15-E15 | G15: 30 | H15: =IF(F15<=G15,"À commander","OK") | I15: 1200 | J15: =D15*I15 | K15: 45736 | L15: MediSupply | M15: Mensuelle
A16: EPI-011 | B16: Harnais sécurité | C16: Maintenance | D16: 8 | E16: 4 | F16: =D16-E16 | G16: 3 | H16: =IF(F16<=G16,"À commander","OK") | I16: 85000 | J16: =D16*I16 | K16: 45667 | L16: ElecSafe | M16: Annuelle
A17: EPI-012 | B17: Extincteur 6kg | C17: Tous départements | D17: 25 | E17: 0 | F17: =D17-E17 | G17: 5 | H17: =IF(F17<=G17,"À commander","OK") | I17: 35000 | J17: =D17*I17 | K17: 45662 | L17: FireSafe SARL | M17: Annuelle
F18: =IF(D18="","",D18-E18) | H18: =IF(OR(D18="",G18=""),"",IF(F18<=G18,"À commander","OK")) | J18: =IF(D18="","",D18*I18)
F19: =IF(D19="","",D19-E19) | H19: =IF(OR(D19="",G19=""),"",IF(F19<=G19,"À commander","OK")) | J19: =IF(D19="","",D19*I19)
F20: =IF(D20="","",D20-E20) | H20: =IF(OR(D20="",G20=""),"",IF(F20<=G20,"À commander","OK")) | J20: =IF(D20="","",D20*I20)
F21: =IF(D21="","",D21-E21) | H21: =IF(OR(D21="",G21=""),"",IF(F21<=G21,"À commander","OK")) | J21: =IF(D21="","",D21*I21)
F22: =IF(D22="","",D22-E22) | H22: =IF(OR(D22="",G22=""),"",IF(F22<=G22,"À commander","OK")) | J22: =IF(D22="","",D22*I22)
F23: =IF(D23="","",D23-E23) | H23: =IF(OR(D23="",G23=""),"",IF(F23<=G23,"À commander","OK")) | J23: =IF(D23="","",D23*I23)
F24: =IF(D24="","",D24-E24) | H24: =IF(OR(D24="",G24=""),"",IF(F24<=G24,"À commander","OK")) | J24: =IF(D24="","",D24*I24)
F25: =IF(D25="","",D25-E25) | H25: =IF(OR(D25="",G25=""),"",IF(F25<=G25,"À commander","OK")) | J25: =IF(D25="","",D25*I25)
F26: =IF(D26="","",D26-E26) | H26: =IF(OR(D26="",G26=""),"",IF(F26<=G26,"À commander","OK")) | J26: =IF(D26="","",D26*I26)
F27: =IF(D27="","",D27-E27) | H27: =IF(OR(D27="",G27=""),"",IF(F27<=G27,"À commander","OK")) | J27: =IF(D27="","",D27*I27)
F28: =IF(D28="","",D28-E28) | H28: =IF(OR(D28="",G28=""),"",IF(F28<=G28,"À commander","OK")) | J28: =IF(D28="","",D28*I28)
F29: =IF(D29="","",D29-E29) | H29: =IF(OR(D29="",G29=""),"",IF(F29<=G29,"À commander","OK")) | J29: =IF(D29="","",D29*I29)
... F115: =IF(D115="","",D115-E115) | H115: =IF(OR(D115="",G115=""),"",IF(F115<=G115,"À commander","OK")) | J115: =IF(D115="","",D115*I115)

Sheet F08 - 6-Formation Sécurité
A2: DOMAINE 27 — 6-FORMATION EN SÉCURITÉ ET SANTÉ AU TRAVAIL
A3: TABLEAU DYNAMIQUE — Plan de formation SST et suivi des effectifs formés
A5: Code Formation | B5: Type de Formation | C5: Département | D5: Formateur | E5: Nb Participants Prévus | F5: Nb Participants Réels | G5: Taux Présence (%) | H5: Date Formation | I5: Durée (heures) | J5: Coût Formation (FCFA) | K5: Coût/Participant (FCFA) | L5: Évaluation | M5: Statut
A6: FST-001 | B6: Incendie | C6: Tous départements | D6: Capitaine Mba | E6: 154 | F6: 142 | G6: =IFERROR(F6/E6,0) | H6: 45682 | I6: 3 | J6: 450000 | K6: =IFERROR(J6/F6,0) | L6: Bon | M6: Terminée
A7: FST-002 | B7: Secourisme | C7: Tous départements | D7: Dr. Manga | E7: 30 | F7: 28 | G7: =IFERROR(F7/E7,0) | H7: 45703 | I7: 8 | J7: 750000 | K7: =IFERROR(J7/F7,0) | L7: Excellent | M7: Terminée
A8: FST-003 | B8: Habilitation électrique | C8: Maintenance | D8: Ing. Owona | E8: 8 | F8: 8 | G8: =IFERROR(F8/E8,0) | H8: 45717 | I8: 16 | J8: 1200000 | K8: =IFERROR(J8/F8,0) | L8: Bon | M8: Terminée
A9: FST-004 | B9: Manipulation produits | C9: Cuisine & Restauration | D9: M. Tchinda | E9: 45 | F9: 42 | G9: =IFERROR(F9/E9,0) | H9: 45731 | I9: 4 | J9: 180000 | K9: =IFERROR(J9/F9,0) | L9: Satisfaisant | M9: Terminée
A10: FST-005 | B10: Travail en hauteur | C10: Maintenance | D10: Capitaine Mba | E10: 10 | F10: 9 | G10: =IFERROR(F10/E10,0) | H10: 45752 | I10: 6 | J10: 350000 | K10: =IFERROR(J10/F10,0) | L10: Bon | M10: Terminée
A11: FST-006 | B11: Ergonomie poste | C11: Réception & Front Office | D11: Mme. Mbarga | E11: 25 | F11: 23 | G11: =IFERROR(F11/E11,0) | H11: 45767 | I11: 3 | J11: 150000 | K11: =IFERROR(J11/F11,0) | L11: Satisfaisant | M11: Terminée
A12: FST-007 | B12: TMS prévention | C12: Commerce | D12: Dr. Manga | E12: 10 | F12: 8 | G12: =IFERROR(F12/E12,0) | H12: 45787 | I12: 4 | J12: 120000 | K12: =IFERROR(J12/F12,0) | L12: Bon | M12: En cours
A13: FST-008 | B13: Gestion du stress | C13: Sécurité | D13: Psych. Ndongo | E13: 15 | F13: 12 | G13: =IFERROR(F13/E13,0) | H13: 45802 | I13: 3 | J13: 200000 | K13: =IFERROR(J13/F13,0) | L13: Satisfaisant | M13: En cours
A14: FST-009 | B14: Évacuation | C14: Tous départements | D14: Capitaine Mba | E14: 154 | F14: 0 | G14: =IFERROR(F14/E14,0) | H14: 45853 | I14: 2 | J14: 300000 | K14: =IFERROR(J14/F14,0) | M14: Planifiée
A15: FST-010 | B15: Premiers gestes | C15: Cuisine & Restauration | D15: Dr. Manga | E15: 45 | F15: 0 | G15: =IFERROR(F15/E15,0) | H15: 45879 | I15: 4 | J15: 250000 | K15: =IFERROR(J15/F15,0) | M15: Planifiée
G16: =IF(E16="","",IFERROR(F16/E16,0)) | K16: =IF(F16="","",IFERROR(J16/F16,0))
G17: =IF(E17="","",IFERROR(F17/E17,0)) | K17: =IF(F17="","",IFERROR(J17/F17,0))
G18: =IF(E18="","",IFERROR(F18/E18,0)) | K18: =IF(F18="","",IFERROR(J18/F18,0))
G19: =IF(E19="","",IFERROR(F19/E19,0)) | K19: =IF(F19="","",IFERROR(J19/F19,0))
G20: =IF(E20="","",IFERROR(F20/E20,0)) | K20: =IF(F20="","",IFERROR(J20/F20,0))
G21: =IF(E21="","",IFERROR(F21/E21,0)) | K21: =IF(F21="","",IFERROR(J21/F21,0))
G22: =IF(E22="","",IFERROR(F22/E22,0)) | K22: =IF(F22="","",IFERROR(J22/F22,0))
G23: =IF(E23="","",IFERROR(F23/E23,0)) | K23: =IF(F23="","",IFERROR(J23/F23,0))
G24: =IF(E24="","",IFERROR(F24/E24,0)) | K24: =IF(F24="","",IFERROR(J24/F24,0))
G25: =IF(E25="","",IFERROR(F25/E25,0)) | K25: =IF(F25="","",IFERROR(J25/F25,0))
G26: =IF(E26="","",IFERROR(F26/E26,0)) | K26: =IF(F26="","",IFERROR(J26/F26,0))
G27: =IF(E27="","",IFERROR(F27/E27,0)) | K27: =IF(F27="","",IFERROR(J27/F27,0))
... G115: =IF(E115="","",IFERROR(F115/E115,0)) | K115: =IF(F115="","",IFERROR(J115/F115,0))

Sheet F09 - 7-Plan Évacuation Secours
A2: DOMAINE 27 — 7-PLAN D'ÉVACUATION ET SECOURS
A3: TABLEAU DYNAMIQUE — Consignes, équipements et exercices
A5: Code Zone | B5: Zone / Bâtiment | C5: Nb Sorties Secours | D5: Nb Extincteurs | E5: Point Rassemblement | F5: Capacité Zone | G5: Équipements Spécifiques | H5: Dernier Exercice | I5: Prochain Exercice | J5: Taux Évacuation (%) | K5: Observations
A6: ZONE-01 | B6: Bâtiment principal RDC | C6: 4 | D6: 12 | E6: Parking Nord | F6: 80 | G6: Alarme, sprinkleur, DAS | H6: 45731 | I6: 45915 | J6: 95 | K6: Évacuation en 4 min
A7: ZONE-02 | B7: Bâtiment principal Étage | C7: 3 | D7: 8 | E7: Parking Nord | F7: 60 | G7: Alarme, échelle, DAS | H7: 45731 | I7: 45915 | J7: 92 | K7: Évacuation en 5 min
A8: ZONE-03 | B8: Cuisine industrielle | C8: 2 | D8: 6 | E8: Jardin Est | F8: 45 | G8: Coupe-feu, hood, extincteur CO2 | H8: 45757 | I8: 45940 | J8: 88 | K8: Risque feu cuisine élevé
A9: ZONE-04 | B9: Atelier maintenance | C9: 2 | D9: 4 | E9: Parking Sud | F9: 18 | G9: Armoire à outils sécurité | H9: 45757 | I9: 45940 | J9: 100 | K9: Petit effectif, évacuation rapide
A10: ZONE-05 | B10: Spa & Bien-être | C10: 2 | D10: 4 | E10: Jardin Ouest | F10: 20 | G10: Trousse premiers soins | H10: 45782 | I10: 45966 | J10: 90 | K10: Clientèle à guider
A11: ZONE-06 | B11: Réception & Hall | C11: 3 | D11: 6 | E11: Parking Nord | F11: 40 | G11: Alarme visuelle, DAS | H11: 45731 | I11: 45915 | J11: 85 | K11: Public important à gérer
A12: ZONE-07 | B12: Entrepôt & Stockage | C12: 2 | D12: 6 | E12: Parking Sud | F12: 10 | G12: Détection fumée, sprinkleur | H12: 45797 | I12: 45981 | J12: 100 | K12: Accès restreint
A13: ZONE-08 | B13: Parking | C13: 2 | D13: 2 | E13: Route principale | F13: 50 | G13: extincteur véhicule, couverture | H13: 45767 | I13: 45950 | J13: 78 | K13: Zone ouverte, risque véhicule

Sheet F10 - 8-Maladies Prof.
A2: DOMAINE 27 — 8-SUIVI DES MALADIES PROFESSIONNELLES
A3: TABLEAU DYNAMIQUE — Déclaration, suivi et prévention
A5: Code Maladie | B5: Employé | C5: Département | D5: Type de Maladie | E5: Date Déclaration | F5: Date Apparition Symptômes | G5: CIM-10 | H5: Jours d'Incapacité | I5: Coût (FCFA) | J5: Reconnaissance CNPS | K5: Action de Prévention | L5: Statut
A6: MP-001 | B6: M. Ondo André | C6: Maintenance | D6: Surdité professionnelle | E6: 45689 | F6: 45444 | G6: H83.9 | H6: 60 | I6: 850000 | J6: En cours | K6: Bouchons antibruit renforcés | L6: En cours
A7: MP-002 | B7: Mme. Feuzeu Clarisse | C7: Cuisine | D7: Dermatose professionnelle | E7: 45731 | F7: 45536 | G7: L25.9 | H7: 30 | I7: 350000 | J7: En cours | K7: Substitution produit nettoyant | L7: En cours
A8: MP-003 | B8: M. Kamga Ibrahim | C8: Cuisine | D8: Brûlure chronique | E8: 45748 | F8: 45505 | G8: L59.0 | H8: 15 | I8: 200000 | J8: Reconnue | K8: Gants haute température | L8: Clôturé
A9: MP-004 | B9: M. Tabi Célestin | C9: Maintenance | D9: Névrite post-électrique | E9: 45778 | F9: 45749 | G9: G62.9 | H9: 90 | I9: 1500000 | J9: En cours | K9: Protocole LOTO renforcé | L9: En cours
A10: MP-005 | B10: Mme. Djiade Aïcha | C10: Commerce | D10: TMS épaule | E10: 45767 | F10: 45597 | G10: M75.1 | H10: 45 | I10: 600000 | J10: En cours | K10: Aide à la manutention | L10: En cours
A11: MP-006 | B11: M. Bouba Moussa | C11: Cuisine | D11: Intoxication alimentaire | E11: 45736 | F11: 45731 | G11: A05.9 | H11: 7 | I11: 150000 | J11: Reconnue | K11: Hygiène alimentaire renforcée | L11: Clôturé

Sheet F11 - 9-Inspections Audits SST
A2: DOMAINE 27 — 9-INSPECTIONS ET AUDITS SANTÉ SÉCURITÉ
A3: TABLEAU DYNAMIQUE — Planification et résultats des contrôles
A5: Code Inspection | B5: Type Audit | C5: Zone Inspectée | D5: Date Inspection | E5: Inspecteur | F5: Nb Non-Conformités | G5: Nb Critiques | H5: Taux Conformité (%) | I5: Observations Principales | J5: Plan Action | K5: Date Relance | L5: Statut
A6: INS-001 | B6: Interne | C6: Cuisine industrielle | D6: 45672 | E6: M. Ondo | F6: 3 | G6: 1 | H6: =IFERROR(1-F6/(F6+10),0) | I6: Extincteur périmé, sol glissant | J6: Remplacement extincteur + revêtement | K6: 45716 | L6: Clôturé
A7: INS-002 | B7: Interne | C7: Atelier maintenance | D7: 45677 | E7: M. Ondo | F7: 5 | G7: 2 | H7: =IFERROR(1-F7/(F7+10),0) | I7: LOTO non appliqué, EPI manquants | J7: Formation LOTO + réappro EPI | K7: 45731 | L7: Clôturé
A8: INS-003 | B8: Externe | C8: Ensemble site | D8: 45698 | E8: Bureau Veritas | F8: 8 | G8: 3 | H8: =IFERROR(1-F8/(F8+10),0) | I8: Alarmes défectueuses, sorties encombrées | J8: Réparation alarmes + dégagement sorties | K8: 45777 | L8: En cours
A9: INS-004 | B9: Réglementaire | C9: Cuisine industrielle | D9: 45721 | E9: Inspection du travail | F9: 2 | G9: 0 | H9: =IFERROR(1-F9/(F9+10),0) | I9: Fiche produit manquante | J9: Mise à jour documentation | K9: 45752 | L9: Clôturé
A10: INS-005 | B10: Interne | C10: Spa & Bien-être | D10: 45736 | E10: Mme. Fotso | F10: 4 | G10: 1 | H10: =IFERROR(1-F10/(F10+10),0) | I10: Produits non étiquetés, pas de MSDS | J10: Étiquetage + formation produits | K10: 45797 | L10: En cours
A11: INS-006 | B11: Programmé | C11: Ensemble site | D11: 45823 | E11: Capitaine Mba | F11: 0 | G11: 0 | H11: =IFERROR(1-F11/(F11+10),0) | K11: 45915 | L11: Planifié
A12: INS-007 | B12: Inopiné | C12: Entrepôt | D12: 45748 | E12: M. Ondo | F12: 6 | G12: 2 | H12: =IFERROR(1-F12/(F12+10),0) | I12: Extincteurs non vérifiés, PPE absents | J12: Vérification + commande urgente | K12: 45808 | L12: En cours
A13: INS-008 | B13: Interne | C13: Réception & Hall | D13: 45762 | E13: Mme. Ngassa | F13: 2 | G13: 0 | H13: =IFERROR(1-F13/(F13+10),0) | I13: Tapis usé, éclairage insuffisant | J13: Remplacement tapis + ampoules | K13: 45807 | L13: En cours
H14: =IF(B14="","",IFERROR(1-F14/(F14+10),0))
H15: =IF(B15="","",IFERROR(1-F15/(F15+10),0))
H16: =IF(B16="","",IFERROR(1-F16/(F16+10),0))
H17: =IF(B17="","",IFERROR(1-F17/(F17+10),0))
H18: =IF(B18="","",IFERROR(1-F18/(F18+10),0))
H19: =IF(B19="","",IFERROR(1-F19/(F19+10),0))
H20: =IF(B20="","",IFERROR(1-F20/(F20+10),0))
H21: =IF(B21="","",IFERROR(1-F21/(F21+10),0))
H22: =IF(B22="","",IFERROR(1-F22/(F22+10),0))
H23: =IF(B23="","",IFERROR(1-F23/(F23+10),0))
H24: =IF(B24="","",IFERROR(1-F24/(F24+10),0))
H25: =IF(B25="","",IFERROR(1-F25/(F25+10),0))
... H115: =IF(B115="","",IFERROR(1-F115/(F115+10),0))

Sheet F12 - 10-Taux Fréquence Gravité
A2: DOMAINE 27 — 10-INDICATEURS : TAUX DE FRÉQUENCE ET DE GRAVITÉ
A3: TABLEAU DYNAMIQUE — Calcul et suivi des indicateurs SST clés
A5: Département | B5: Effectif | C5: Heures Travailées | D5: Nb Accidents avec Arrêt | E5: Nb Jours d'Arrêt Total | F5: Taux de Fréquence (TF) | G5: Taux de Gravité (TG) | H5: Nb Accidents sans Arrêt | I5: Nb Presque-Accidents | J5: Ratio Présque-Acc/Acc | K5: Indice Fréquence Cible | L5: Écart TF | M5: Tendance
A6: Cuisine & Restauration | B6: 45 | C6: 93600 | D6: 4 | E6: 27 | F6: =IFERROR(D6*1000000/C6,0) | G6: =IFERROR(E6*1000/C6,0) | H6: 6 | I6: 12 | J6: =IF(D6=0,"",IFERROR(I6/D6,0)) | K6: 25 | L6: =F6-K6 | M6: =IF(L6>0,"Hausse",IF(L6<0,"Baisse","Stable"))
A7: Maintenance & Technique | B7: 18 | C7: 37440 | D7: 3 | E7: 27 | F7: =IFERROR(D7*1000000/C7,0) | G7: =IFERROR(E7*1000/C7,0) | H7: 4 | I7: 8 | J7: =IF(D7=0,"",IFERROR(I7/D7,0)) | K7: 30 | L7: =F7-K7 | M7: =IF(L7>0,"Hausse",IF(L7<0,"Baisse","Stable"))
A8: Réception & Front Office | B8: 25 | C8: 52000 | D8: 1 | E8: 14 | F8: =IFERROR(D8*1000000/C8,0) | G8: =IFERROR(E8*1000/C8,0) | H8: 3 | I8: 5 | J8: =IF(D8=0,"",IFERROR(I8/D8,0)) | K8: 15 | L8: =F8-K8 | M8: =IF(L8>0,"Hausse",IF(L8<0,"Baisse","Stable"))
A9: Sécurité | B9: 15 | C9: 31200 | D9: 1 | E9: 3 | F9: =IFERROR(D9*1000000/C9,0) | G9: =IFERROR(E9*1000/C9,0) | H9: 2 | I9: 4 | J9: =IF(D9=0,"",IFERROR(I9/D9,0)) | K9: 20 | L9: =F9-K9 | M9: =IF(L9>0,"Hausse",IF(L9<0,"Baisse","Stable"))
A10: Commerce | B10: 10 | C10: 20800 | D10: 1 | E10: 10 | F10: =IFERROR(D10*1000000/C10,0) | G10: =IFERROR(E10*1000/C10,0) | H10: 2 | I10: 3 | J10: =IF(D10=0,"",IFERROR(I10/D10,0)) | K10: 30 | L10: =F10-K10 | M10: =IF(L10>0,"Hausse",IF(L10<0,"Baisse","Stable"))
A11: Spa & Bien-être | B11: 8 | C11: 16640 | D11: 1 | E11: 2 | F11: =IFERROR(D11*1000000/C11,0) | G11: =IFERROR(E11*1000/C11,0) | H11: 1 | I11: 2 | J11: =IF(D11=0,"",IFERROR(I11/D11,0)) | K11: 40 | L11: =F11-K11 | M11: =IF(L11>0,"Hausse",IF(L11<0,"Baisse","Stable"))
A12: Direction Générale | B12: 5 | C12: 10400 | D12: 0 | E12: 0 | F12: =IFERROR(D12*1000000/C12,0) | G12: =IFERROR(E12*1000/C12,0) | H12: 1 | I12: 1 | J12: =IF(D12=0,"",IFERROR(I12/D12,0)) | K12: 0 | L12: =F12-K12 | M12: =IF(L12>0,"Hausse",IF(L12<0,"Baisse","Stable"))
A13: Finance & Comptabilité | B13: 10 | C13: 20800 | D13: 0 | E13: 0 | F13: =IFERROR(D13*1000000/C13,0) | G13: =IFERROR(E13*1000/C13,0) | H13: 0 | I13: 2 | J13: =IF(D13=0,"",IFERROR(I13/D13,0)) | K13: 0 | L13: =F13-K13 | M13: =IF(L13>0,"Hausse",IF(L13<0,"Baisse","Stable"))
A14: Marketing & Communication | B14: 8 | C14: 16640 | D14: 0 | E14: 0 | F14: =IFERROR(D14*1000000/C14,0) | G14: =IFERROR(E14*1000/C14,0) | H14: 1 | I14: 1 | J14: =IF(D14=0,"",IFERROR(I14/D14,0)) | K14: 0 | L14: =F14-K14 | M14: =IF(L14>0,"Hausse",IF(L14<0,"Baisse","Stable"))
A15: Revenue Management | B15: 6 | C15: 12480 | D15: 0 | E15: 0 | F15: =IFERROR(D15*1000000/C15,0) | G15: =IFERROR(E15*1000/C15,0) | H15: 0 | I15: 0 | J15: =IF(D15=0,"",IFERROR(I15/D15,0)) | K15: 0 | L15: =F15-K15 | M15: =IF(L15>0,"Hausse",IF(L15<0,"Baisse","Stable"))
F16: =IF(C16="","",IFERROR(D16*1000000/C16,0)) | G16: =IF(C16="","",IFERROR(E16*1000/C16,0)) | J16: =IF(D16="","",IFERROR(I16/D16,0)) | L16: =IF(F16="","",F16-K16) | M16: =IF(L16="","",IF(L16>0,"Hausse",IF(L16<0,"Baisse","Stable")))
F17: =IF(C17="","",IFERROR(D17*1000000/C17,0)) | G17: =IF(C17="","",IFERROR(E17*1000/C17,0)) | J17: =IF(D17="","",IFERROR(I17/D17,0)) | L17: =IF(F17="","",F17-K17) | M17: =IF(L17="","",IF(L17>0,"Hausse",IF(L17<0,"Baisse","Stable")))
F18: =IF(C18="","",IFERROR(D18*1000000/C18,0)) | G18: =IF(C18="","",IFERROR(E18*1000/C18,0)) | J18: =IF(D18="","",IFERROR(I18/D18,0)) | L18: =IF(F18="","",F18-K18) | M18: =IF(L18="","",IF(L18>0,"Hausse",IF(L18<0,"Baisse","Stable")))
F19: =IF(C19="","",IFERROR(D19*1000000/C19,0)) | G19: =IF(C19="","",IFERROR(E19*1000/C19,0)) | J19: =IF(D19="","",IFERROR(I19/D19,0)) | L19: =IF(F19="","",F19-K19) | M19: =IF(L19="","",IF(L19>0,"Hausse",IF(L19<0,"Baisse","Stable")))
F20: =IF(C20="","",IFERROR(D20*1000000/C20,0)) | G20: =IF(C20="","",IFERROR(E20*1000/C20,0)) | J20: =IF(D20="","",IFERROR(I20/D20,0)) | L20: =IF(F20="","",F20-K20) | M20: =IF(L20="","",IF(L20>0,"Hausse",IF(L20<0,"Baisse","Stable")))
F21: =IF(C21="","",IFERROR(D21*1000000/C21,0)) | G21: =IF(C21="","",IFERROR(E21*1000/C21,0)) | J21: =IF(D21="","",IFERROR(I21/D21,0)) | L21: =IF(F21="","",F21-K21) | M21: =IF(L21="","",IF(L21>0,"Hausse",IF(L21<0,"Baisse","Stable")))
F22: =IF(C22="","",IFERROR(D22*1000000/C22,0)) | G22: =IF(C22="","",IFERROR(E22*1000/C22,0)) | J22: =IF(D22="","",IFERROR(I22/D22,0)) | L22: =IF(F22="","",F22-K22) | M22: =IF(L22="","",IF(L22>0,"Hausse",IF(L22<0,"Baisse","Stable")))
F23: =IF(C23="","",IFERROR(D23*1000000/C23,0)) | G23: =IF(C23="","",IFERROR(E23*1000/C23,0)) | J23: =IF(D23="","",IFERROR(I23/D23,0)) | L23: =IF(F23="","",F23-K23) | M23: =IF(L23="","",IF(L23>0,"Hausse",IF(L23<0,"Baisse","Stable")))
F24: =IF(C24="","",IFERROR(D24*1000000/C24,0)) | G24: =IF(C24="","",IFERROR(E24*1000/C24,0)) | J24: =IF(D24="","",IFERROR(I24/D24,0)) | L24: =IF(F24="","",F24-K24) | M24: =IF(L24="","",IF(L24>0,"Hausse",IF(L24<0,"Baisse","Stable")))
F25: =IF(C25="","",IFERROR(D25*1000000/C25,0)) | G25: =IF(C25="","",IFERROR(E25*1000/C25,0)) | J25: =IF(D25="","",IFERROR(I25/D25,0)) | L25: =IF(F25="","",F25-K25) | M25: =IF(L25="","",IF(L25>0,"Hausse",IF(L25<0,"Baisse","Stable")))
F26: =IF(C26="","",IFERROR(D26*1000000/C26,0)) | G26: =IF(C26="","",IFERROR(E26*1000/C26,0)) | J26: =IF(D26="","",IFERROR(I26/D26,0)) | L26: =IF(F26="","",F26-K26) | M26: =IF(L26="","",IF(L26>0,"Hausse",IF(L26<0,"Baisse","Stable")))
F27: =IF(C27="","",IFERROR(D27*1000000/C27,0)) | G27: =IF(C27="","",IFERROR(E27*1000/C27,0)) | J27: =IF(D27="","",IFERROR(I27/D27,0)) | L27: =IF(F27="","",F27-K27) | M27: =IF(L27="","",IF(L27>0,"Hausse",IF(L27<0,"Baisse","Stable")))
... F115: =IF(C115="","",IFERROR(D115*1000000/C115,0)) | G115: =IF(C115="","",IFERROR(E115*1000/C115,0)) | J115: =IF(D115="","",IFERROR(I115/D115,0)) | L115: =IF(F115="","",F115-K115) | M115: =IF(L115="","",IF(L115>0,"Hausse",IF(L115<0,"Baisse","Stable")))

Sheet F13 - 11-Équipements Médicaux
A2: DOMAINE 27 — 11-GESTION DES ÉQUIPEMENTS MÉDICAUX ET TROUSSES DE SECOURS
A3: TABLEAU DYNAMIQUE — Inventaire, vérification et renouvellement
A5: Code Équip. | B5: Désignation | C5: Localisation | D5: Quantité | E5: Date Acquisition | F5: Date Validité | G5: État | H5: Coût (FCFA) | I5: Dernière Vérification | J5: Prochaine Vérification | K5: Responsable | L5: Observations
A6: EQM-001 | B6: Défibrillateur (DEA) | C6: Hall réception | D6: 1 | E6: 45306 | F6: 46402 | G6: Bon | H6: 850000 | I6: 45748 | J6: 45931 | K6: M. Ondo | L6: Batterie OK, électrodes en stock
A7: EQM-002 | B7: Trousse premiers soins | C7: Cuisine | D7: 2 | E7: 45667 | F7: 46032 | G7: Bon | H7: 35000 | I7: 45778 | J7: 45870 | K7: M. Tchinda | L7: Consommables à renouveler Q3
A8: EQM-003 | B8: Trousse premiers soins | C8: Maintenance | D8: 1 | E8: 45667 | F8: 46032 | G8: Bon | H8: 35000 | I8: 45778 | J8: 45870 | K8: M. Ondo | L8: Stock complet
A9: EQM-004 | B9: Tensiomètre | C9: Infirmerie | D9: 1 | E9: 45444 | F9: 46539 | G9: Bon | H9: 120000 | I9: 45717 | J9: 45901 | K9: Dr. Manga | L9: Étalonnage OK
A10: EQM-005 | B10: Oxymètre | C10: Infirmerie | D10: 2 | E10: 45505 | F10: 46600 | G10: Bon | H10: 45000 | I10: 45717 | J10: 45901 | K10: Dr. Manga | L10: Fonctionnel
A11: EQM-006 | B11: Brancard | C11: Infirmerie | D11: 1 | E11: 44986 | F11: 46813 | G11: Usé | H11: 180000 | I11: 45748 | J11: 45931 | K11: Dr. Manga | L11: Remplacement prévu 2026
A12: EQM-007 | B12: Collier cervical | C12: Infirmerie | D12: 4 | E12: 45292 | F12: 47119 | G12: Bon | H12: 15000 | I12: 45748 | J12: 45931 | K12: Dr. Manga | L12: Tailles S, M, L, XL
A13: EQM-008 | B13: Trousse brûlures | C13: Cuisine | D13: 1 | E13: 45689 | F13: 46054 | G13: Bon | H13: 25000 | I13: 45778 | J13: 45870 | K13: M. Tchinda | L13: Spécial brûlures thermiques
A14: EQM-009 | B14: Sac d'évacuation | C14: Bâtiment principal | D14: 2 | E14: 45444 | F14: 46539 | G14: Bon | H14: 95000 | I14: 45748 | J14: 45931 | K14: Capitaine Mba | L14: Contenu vérifié avril
A15: EQM-010 | B15: Stéthoscope | C15: Infirmerie | D15: 2 | E15: 45352 | F15: 47178 | G15: Bon | H15: 35000 | I15: 45717 | J15: 45901 | K15: Dr. Manga | L15: Fonctionnel

Sheet F14 - 12-Hygiène Sécurité Env.
A2: DOMAINE 27 — 12-HYGIÈNE ET SÉCURITÉ DE L'ENVIRONNEMENT DE TRAVAIL
A3: TABLEAU DYNAMIQUE — Conditions de travail, ergonomie, ambiance
A5: Code Contrôle | B5: Localisation | C5: Type de Contrôle | D5: Paramètre Mesuré | E5: Valeur Mesurée | F5: Valeur Norme | G5: Conformité | H5: Date Mesure | I5: Fréquence Contrôle | J5: Responsable | K5: Action si Non-Conforme | L5: Coût Mise en Conformité (FCFA)
A6: HYG-001 | B6: Cuisine | C6: Ambiance thermique | D6: Température (°C) | E6: 28 | F6: 25 | G6: Non conforme | H6: 45717 | I6: Trimestrielle | J6: M. Ondo | K6: Installation ventilation renforcée | L6: 2500000
A7: HYG-002 | B7: Atelier | C7: Bruit | D7: Niveau dB(A) | E7: 87 | F7: 85 | G7: Non conforme | H7: 45717 | I7: Trimestrielle | J7: M. Ondo | K7: Silencieux + bouchons obligatoires | L7: 800000
A8: HYG-003 | B8: Bureaux | C8: Éclairage | D8: Lux | E8: 350 | F8: 500 | G8: Non conforme | H8: 45731 | I8: Semestrielle | J8: M. Ondo | K8: Remplacement ampoules LED | L8: 500000
A9: HYG-004 | B9: Cuisine | C9: Qualité air | D9: CO2 (ppm) | E9: 650 | F9: 1000 | G9: Conforme | H9: 45731 | I9: Semestrielle | J9: Dr. Manga | K9: Néant | L9: 0
A10: HYG-005 | B10: Salle restaurant | C10: Hygiène sol | D10: ATP (RLU) | E10: 120 | F10: 150 | G10: Conforme | H10: 45748 | I10: Mensuelle | J10: M. Tchinda | K10: Néant | L10: 0
A11: HYG-006 | B11: Infirmerie | C11: Qualité eau | D11: Potabilité | E11: Conforme | F11: Conforme | G11: Conforme | H11: 45748 | I11: Trimestrielle | J11: Dr. Manga | K11: Néant | L11: 0
A12: HYG-007 | B12: Entrepôt | C12: Ventilation | D12: Débit air (m3/h) | E12: 800 | F12: 1000 | G12: Non conforme | H12: 45762 | I12: Semestrielle | J12: M. Ondo | K12: Installation extracteur | L12: 1200000
A13: HYG-008 | B13: Bureaux | C13: Ergonomie | D13: Taux satisfaction | E13: 72% | F13: 80% | G13: Non conforme | H13: 45778 | I13: Annuelle | J13: Mme. Mbarga | K13: Audit ergonomique complet | L13: 600000
A14: HYG-009 | B14: Spa | C14: Hygiène | D14: Bactériologie eau | E14: 0 UFC/mL | F14: < 100 UFC/mL | G14: Conforme | H14: 45778 | I14: Mensuelle | J14: Mme. Fotso | K14: Néant | L14: 0
A15: HYG-010 | B15: Parking | C15: Sécurité | D15: Éclairage lux | E15: 80 | F15: 100 | G15: Non conforme | H15: 45792 | I15: Semestrielle | J15: M. Ondo | K15: Ajout projecteurs LED | L15: 350000

Sheet F15 - 13-Budget SST
A2: DOMAINE 27 — 13-BUDGET SANTÉ, SÉCURITÉ ET BIEN-ÊTRE AU TRAVAIL
A3: TABLEAU DYNAMIQUE — Suivi budgétaire par poste et trimestre
A5: Poste Budgétaire | B5: Département | C5: Q1 Alloué (FCFA) | D5: Q1 Consommé (FCFA) | E5: Q2 Alloué (FCFA) | F5: Q2 Consommé (FCFA) | G5: Q3 Alloué (FCFA) | H5: Q3 Consommé (FCFA) | I5: Q4 Alloué (FCFA) | J5: Q4 Consommé (FCFA) | K5: Total Alloué (FCFA) | L5: Total Consommé (FCFA) | M5: Reste (FCFA) | N5: Taux Consommation (%)
A6: EPI et équipements | B6: Maintenance | C6: 800000 | D6: 650000 | E6: 800000 | F6: 720000 | G6: 600000 | H6: 0 | I6: 600000 | J6: 0 | K6: =C6+E6+G6+I6 | L6: =D6+F6+H6+J6 | M6: =K6-L6 | N6: =IFERROR(L6/K6,0)
A7: EPI et équipements | B7: Cuisine & Restauration | C7: 500000 | D7: 420000 | E7: 500000 | F7: 380000 | G7: 400000 | H7: 0 | I7: 400000 | J7: 0 | K7: =C7+E7+G7+I7 | L7: =D7+F7+H7+J7 | M7: =K7-L7 | N7: =IFERROR(L7/K7,0)
A8: Formations SST | B8: Tous départements | C8: 1500000 | D8: 1350000 | E8: 1000000 | F8: 520000 | G8: 800000 | H8: 0 | I8: 800000 | J8: 0 | K8: =C8+E8+G8+I8 | L8: =D8+F8+H8+J8 | M8: =K8-L8 | N8: =IFERROR(L8/K8,0)
A9: Visites médicales | B9: Tous départements | C9: 600000 | D9: 450000 | E9: 600000 | F9: 350000 | G9: 600000 | H9: 0 | I9: 600000 | J9: 0 | K9: =C9+E9+G9+I9 | L9: =D9+F9+H9+J9 | M9: =K9-L9 | N9: =IFERROR(L9/K9,0)
A10: Équipements médicaux | B10: Infirmerie | C10: 400000 | D10: 300000 | E10: 300000 | F10: 200000 | G10: 200000 | H10: 0 | I10: 200000 | J10: 0 | K10: =C10+E10+G10+I10 | L10: =D10+F10+H10+J10 | M10: =K10-L10 | N10: =IFERROR(L10/K10,0)
A11: Prévention incendie | B11: Ensemble site | C11: 1200000 | D11: 1000000 | E11: 800000 | F11: 500000 | G11: 800000 | H11: 0 | I11: 800000 | J11: 0 | K11: =C11+E11+G11+I11 | L11: =D11+F11+H11+J11 | M11: =K11-L11 | N11: =IFERROR(L11/K11,0)
A12: Hygiène environnement | B12: Ensemble site | C12: 500000 | D12: 350000 | E12: 500000 | F12: 420000 | G12: 400000 | H12: 0 | I12: 400000 | J12: 0 | K12: =C12+E12+G12+I12 | L12: =D12+F12+H12+J12 | M12: =K12-L12 | N12: =IFERROR(L12/K12,0)
A13: Bien-être employés | B13: Tous départements | C13: 800000 | D13: 600000 | E13: 800000 | F13: 500000 | G13: 800000 | H13: 0 | I13: 800000 | J13: 0 | K13: =C13+E13+G13+I13 | L13: =D13+F13+H13+J13 | M13: =K13-L13 | N13: =IFERROR(L13/K13,0)
A14: Audits et contrôles | B14: Ensemble site | C14: 400000 | D14: 250000 | E14: 400000 | F14: 150000 | G14: 400000 | H14: 0 | I14: 400000 | J14: 0 | K14: =C14+E14+G14+I14 | L14: =D14+F14+H14+J14 | M14: =K14-L14 | N14: =IFERROR(L14/K14,0)
A15: Indemnités AT/MP | B15: Tous départements | C15: 1500000 | D15: 1200000 | E15: 1500000 | F15: 980000 | G15: 1500000 | H15: 0 | I15: 1500000 | J15: 0 | K15: =C15+E15+G15+I15 | L15: =D15+F15+H15+J15 | M15: =K15-L15 | N15: =IFERROR(L15/K15,0)
K16: =IF(A16="","",C16+E16+G16+I16) | L16: =IF(A16="","",D16+F16+H16+J16) | M16: =IF(A16="","",K16-L16) | N16: =IF(A16="","",IFERROR(L16/K16,0))
K17: =IF(A17="","",C17+E17+G17+I17) | L17: =IF(A17="","",D17+F17+H17+J17) | M17: =IF(A17="","",K17-L17) | N17: =IF(A17="","",IFERROR(L17/K17,0))
K18: =IF(A18="","",C18+E18+G18+I18) | L18: =IF(A18="","",D18+F18+H18+J18) | M18: =IF(A18="","",K18-L18) | N18: =IF(A18="","",IFERROR(L18/K18,0))
K19: =IF(A19="","",C19+E19+G19+I19) | L19: =IF(A19="","",D19+F19+H19+J19) | M19: =IF(A19="","",K19-L19) | N19: =IF(A19="","",IFERROR(L19/K19,0))
K20: =IF(A20="","",C20+E20+G20+I20) | L20: =IF(A20="","",D20+F20+H20+J20) | M20: =IF(A20="","",K20-L20) | N20: =IF(A20="","",IFERROR(L20/K20,0))
K21: =IF(A21="","",C21+E21+G21+I21) | L21: =IF(A21="","",D21+F21+H21+J21) | M21: =IF(A21="","",K21-L21) | N21: =IF(A21="","",IFERROR(L21/K21,0))
K22: =IF(A22="","",C22+E22+G22+I22) | L22: =IF(A22="","",D22+F22+H22+J22) | M22: =IF(A22="","",K22-L22) | N22: =IF(A22="","",IFERROR(L22/K22,0))
K23: =IF(A23="","",C23+E23+G23+I23) | L23: =IF(A23="","",D23+F23+H23+J23) | M23: =IF(A23="","",K23-L23) | N23: =IF(A23="","",IFERROR(L23/K23,0))
K24: =IF(A24="","",C24+E24+G24+I24) | L24: =IF(A24="","",D24+F24+H24+J24) | M24: =IF(A24="","",K24-L24) | N24: =IF(A24="","",IFERROR(L24/K24,0))
K25: =IF(A25="","",C25+E25+G25+I25) | L25: =IF(A25="","",D25+F25+H25+J25) | M25: =IF(A25="","",K25-L25) | N25: =IF(A25="","",IFERROR(L25/K25,0))
K26: =IF(A26="","",C26+E26+G26+I26) | L26: =IF(A26="","",D26+F26+H26+J26) | M26: =IF(A26="","",K26-L26) | N26: =IF(A26="","",IFERROR(L26/K26,0))
K27: =IF(A27="","",C27+E27+G27+I27) | L27: =IF(A27="","",D27+F27+H27+J27) | M27: =IF(A27="","",K27-L27) | N27: =IF(A27="","",IFERROR(L27/K27,0))
... K115: =IF(A115="","",C115+E115+G115+I115) | L115: =IF(A115="","",D115+F115+H115+J115) | M115: =IF(A115="","",K115-L115) | N115: =IF(A115="","",IFERROR(L115/K115,0))

Sheet F16 - 14-Reporting Mensuel SST
A2: DOMAINE 27 — 14-REPORTING MENSUEL SANTÉ SÉCURITÉ
A3: TABLEAU DYNAMIQUE — Synthèse mensuelle des indicateurs SST
A5: Mois | B5: Nb Accidents | C5: Nb Jours Arrêt | D5: Nb Visites Méd. | E5: Nb Formations | F5: Nb Inspections | G5: Coût Accidents (FCFA) | H5: Coût Prévention (FCFA) | I5: Total Coûts (FCFA) | J5: Budget Mensuel (FCFA) | K5: Écart Mensuel (FCFA) | L5: Taux Fréquence | M5: Taux Gravité | N5: Cumul Accidents
A6: Janvier 2025 | B6: 1 | C6: 5 | D6: 12 | E6: 1 | F6: 1 | G6: 150000 | H6: 1200000 | I6: =G6+H6 | J6: 1800000 | K6: =J6-I6 | L6: 10.7 | M6: 0.53 | N6: =B6
A7: Février 2025 | B7: 2 | C7: 4 | D7: 10 | E7: 1 | F7: 1 | G7: 200000 | H7: 950000 | I7: =G7+H7 | J7: 1800000 | K7: =J7-I7 | L7: 15.5 | M7: 0.21 | N7: =N6+B7
A8: Mars 2025 | B8: 3 | C8: 21 | D8: 14 | E8: 2 | F8: 2 | G8: 550000 | H8: 1800000 | I8: =G8+H8 | J8: 2200000 | K8: =J8-I8 | L8: 19.1 | M8: 1.34 | N8: =N7+B8
A9: Avril 2025 | B9: 2 | C9: 25 | D9: 8 | E9: 2 | F9: 2 | G9: 600000 | H9: 1100000 | I9: =G9+H9 | J9: 2000000 | K9: =J9-I9 | L9: 12.8 | M9: 1.6 | N9: =N8+B9
A10: Mai 2025 | B10: 1 | C10: 3 | D10: 6 | E10: 1 | F10: 1 | G10: 80000 | H10: 700000 | I10: =G10+H10 | J10: 1700000 | K10: =J10-I10 | L10: 6.4 | M10: 0.19 | N10: =N9+B10
A11: Juin 2025 | B11: 1 | C11: 4 | D11: 5 | E11: 1 | F11: 0 | G11: 140000 | H11: 500000 | I11: =G11+H11 | J11: 1600000 | K11: =J11-I11 | L11: 6.4 | M11: 0.26 | N11: =N10+B11
I12: =IF(A12="","",G12+H12) | K12: =IF(A12="","",J12-I12) | N12: =IF(A12="","",B12)
I13: =IF(A13="","",G13+H13) | K13: =IF(A13="","",J13-I13) | N13: =IF(A13="","",N12+B13)
I14: =IF(A14="","",G14+H14) | K14: =IF(A14="","",J14-I14) | N14: =IF(A14="","",N13+B14)
I15: =IF(A15="","",G15+H15) | K15: =IF(A15="","",J15-I15) | N15: =IF(A15="","",N14+B15)
I16: =IF(A16="","",G16+H16) | K16: =IF(A16="","",J16-I16) | N16: =IF(A16="","",N15+B16)
I17: =IF(A17="","",G17+H17) | K17: =IF(A17="","",J17-I17) | N17: =IF(A17="","",N16+B17)
I18: =IF(A18="","",G18+H18) | K18: =IF(A18="","",J18-I18) | N18: =IF(A18="","",N17+B18)
I19: =IF(A19="","",G19+H19) | K19: =IF(A19="","",J19-I19) | N19: =IF(A19="","",N18+B19)
I20: =IF(A20="","",G20+H20) | K20: =IF(A20="","",J20-I20) | N20: =IF(A20="","",N19+B20)
I21: =IF(A21="","",G21+H21) | K21: =IF(A21="","",J21-I21) | N21: =IF(A21="","",N20+B21)
I22: =IF(A22="","",G22+H22) | K22: =IF(A22="","",J22-I22) | N22: =IF(A22="","",N21+B22)
I23: =IF(A23="","",G23+H23) | K23: =IF(A23="","",J23-I23) | N23: =IF(A23="","",N22+B23)
I24: =IF(A24="","",G24+H24) | K24: =IF(A24="","",J24-I24) | N24: =IF(A24="","",N23+B24)
... I115: =IF(A115="","",G115+H115) | K115: =IF(A115="","",J115-I115) | N115: =IF(A115="","",N114+B115)

Sheet F17 - 15-Analyse Coûts Départ.
A2: DOMAINE 27 — 15-ANALYSE DES COÛTS SST PAR DÉPARTEMENT
A3: TABLEAU DYNAMIQUE — Ventilation des coûts sécurité par département
A5: Département | B5: Coût Accidents (FCFA) | C5: Coût Prévention (FCFA) | D5: Coût EPI (FCFA) | E5: Coût Formations (FCFA) | F5: Coût Médical (FCFA) | G5: Coût Total (FCFA) | H5: Effectif | I5: Coût/Employé (FCFA) | J5: % du Total SST
A6: Cuisine & Restauration | B6: 900000 | C6: 850000 | D6: 520000 | E6: 280000 | F6: 310000 | G6: =SUM(B6:F6) | H6: 45 | I6: =IFERROR(G6/H6,0) | J6: =IFERROR(G6/SUM($G$6:$G$15),0)
A7: Maintenance & Technique | B7: 600000 | C7: 720000 | D7: 680000 | E7: 450000 | F7: 250000 | G7: =SUM(B7:F7) | H7: 18 | I7: =IFERROR(G7/H7,0) | J7: =IFERROR(G7/SUM($G$6:$G$15),0)
A8: Réception & Front Office | B8: 200000 | C8: 300000 | D8: 120000 | E8: 150000 | F8: 140000 | G8: =SUM(B8:F8) | H8: 25 | I8: =IFERROR(G8/H8,0) | J8: =IFERROR(G8/SUM($G$6:$G$15),0)
A9: Sécurité | B9: 80000 | C9: 200000 | D9: 150000 | E9: 200000 | F9: 80000 | G9: =SUM(B9:F9) | H9: 15 | I9: =IFERROR(G9/H9,0) | J9: =IFERROR(G9/SUM($G$6:$G$15),0)
A10: Commerce | B10: 120000 | C10: 150000 | D10: 80000 | E10: 120000 | F10: 60000 | G10: =SUM(B10:F10) | H10: 10 | I10: =IFERROR(G10/H10,0) | J10: =IFERROR(G10/SUM($G$6:$G$15),0)
A11: Spa & Bien-être | B11: 40000 | C11: 100000 | D11: 120000 | E11: 60000 | F11: 50000 | G11: =SUM(B11:F11) | H11: 8 | I11: =IFERROR(G11/H11,0) | J11: =IFERROR(G11/SUM($G$6:$G$15),0)
A12: Direction Générale | B12: 0 | C12: 100000 | D12: 50000 | E12: 50000 | F12: 50000 | G12: =SUM(B12:F12) | H12: 5 | I12: =IFERROR(G12/H12,0) | J12: =IFERROR(G12/SUM($G$6:$G$15),0)
A13: Finance & Comptabilité | B13: 0 | C13: 80000 | D13: 40000 | E13: 30000 | F13: 40000 | G13: =SUM(B13:F13) | H13: 10 | I13: =IFERROR(G13/H13,0) | J13: =IFERROR(G13/SUM($G$6:$G$15),0)
A14: Marketing & Communication | B14: 0 | C14: 60000 | D14: 30000 | E14: 20000 | F14: 30000 | G14: =SUM(B14:F14) | H14: 8 | I14: =IFERROR(G14/H14,0) | J14: =IFERROR(G14/SUM($G$6:$G$15),0)
A15: Revenue Management | B15: 0 | C15: 40000 | D15: 20000 | E15: 15000 | F15: 20000 | G15: =SUM(B15:F15) | H15: 6 | I15: =IFERROR(G15/H15,0) | J15: =IFERROR(G15/SUM($G$6:$G$15),0)
G16: =IF(A16="","",SUM(B16:F16)) | I16: =IF(OR(A16="",H16=""),"",IFERROR(G16/H16,0)) | J16: =IF(A16="","",IFERROR(G16/SUM($G$6:$G$115),0))
G17: =IF(A17="","",SUM(B17:F17)) | I17: =IF(OR(A17="",H17=""),"",IFERROR(G17/H17,0)) | J17: =IF(A17="","",IFERROR(G17/SUM($G$6:$G$115),0))
G18: =IF(A18="","",SUM(B18:F18)) | I18: =IF(OR(A18="",H18=""),"",IFERROR(G18/H18,0)) | J18: =IF(A18="","",IFERROR(G18/SUM($G$6:$G$115),0))
G19: =IF(A19="","",SUM(B19:F19)) | I19: =IF(OR(A19="",H19=""),"",IFERROR(G19/H19,0)) | J19: =IF(A19="","",IFERROR(G19/SUM($G$6:$G$115),0))
G20: =IF(A20="","",SUM(B20:F20)) | I20: =IF(OR(A20="",H20=""),"",IFERROR(G20/H20,0)) | J20: =IF(A20="","",IFERROR(G20/SUM($G$6:$G$115),0))
G21: =IF(A21="","",SUM(B21:F21)) | I21: =IF(OR(A21="",H21=""),"",IFERROR(G21/H21,0)) | J21: =IF(A21="","",IFERROR(G21/SUM($G$6:$G$115),0))
G22: =IF(A22="","",SUM(B22:F22)) | I22: =IF(OR(A22="",H22=""),"",IFERROR(G22/H22,0)) | J22: =IF(A22="","",IFERROR(G22/SUM($G$6:$G$115),0))
G23: =IF(A23="","",SUM(B23:F23)) | I23: =IF(OR(A23="",H23=""),"",IFERROR(G23/H23,0)) | J23: =IF(A23="","",IFERROR(G23/SUM($G$6:$G$115),0))
G24: =IF(A24="","",SUM(B24:F24)) | I24: =IF(OR(A24="",H24=""),"",IFERROR(G24/H24,0)) | J24: =IF(A24="","",IFERROR(G24/SUM($G$6:$G$115),0))
G25: =IF(A25="","",SUM(B25:F25)) | I25: =IF(OR(A25="",H25=""),"",IFERROR(G25/H25,0)) | J25: =IF(A25="","",IFERROR(G25/SUM($G$6:$G$115),0))
G26: =IF(A26="","",SUM(B26:F26)) | I26: =IF(OR(A26="",H26=""),"",IFERROR(G26/H26,0)) | J26: =IF(A26="","",IFERROR(G26/SUM($G$6:$G$115),0))
G27: =IF(A27="","",SUM(B27:F27)) | I27: =IF(OR(A27="",H27=""),"",IFERROR(G27/H27,0)) | J27: =IF(A27="","",IFERROR(G27/SUM($G$6:$G$115),0))
... G115: =IF(A115="","",SUM(B115:F115)) | I115: =IF(OR(A115="",H115=""),"",IFERROR(G115/H115,0)) | J115: =IF(A115="","",IFERROR(G115/SUM($G$6:$G$115),0))

Sheet F18 - 16-Simul. Scénar. SST
A2: DOMAINE 27 — 16-SIMULATIONS SCÉNARIOS SST
A3: TABLEAU DYNAMIQUE — Modélisation d'impacts et scénarios prévention
A5: Scénario | B5: Variable Modifiée | C5: Valeur Base | D5: Valeur Simulée | E5: Impact Coûts Accidents (FCFA) | F5: Impact Coûts Prévention (FCFA) | G5: Impact Coûts Total (FCFA) | H5: Économie/Perte | I5: Recommandation
A6: Scénario A | B6: Renforcement EPI cuisine | C6: Budget EPI: 400000 FCFA/tri | D6: Budget EPI: 600000 FCFA/tri | E6: -600000 | F6: 800000 | G6: =E6+F6 | H6: =IF(G6<0,"Économie","Perte") | I6: Réduction brûlures estimée -40%
A7: Scénario B | B7: Formation LOTO obligatoire | C7: 0% formés | D7: 100% électriciens formés | E7: -400000 | F7: 350000 | G7: =E7+F7 | H7: =IF(G7<0,"Économie","Perte") | I7: Zéro accident électrique visé
A8: Scénario C | B8: Audit ergonomique bureaux | C8: Score 72% | D8: Score 90% | E8: -200000 | F8: 600000 | G8: =E8+F8 | H8: =IF(G8<0,"Économie","Perte") | I8: Baisse TMS bureaux attendue
A9: Scénario D | B9: Externalisation sécurité | C9: 15 agents internes | D9: 8 internes + prestataire | E9: -150000 | F9: 1200000 | G9: =E9+F9 | H9: =IF(G9<0,"Économie","Perte") | I9: Transfert risque employeur
A10: Scénario E | B10: Télétravail 20% effectif | C10: 0 télétravailleurs | D10: 30 télétravailleurs | E10: -100000 | F10: 50000 | G10: =E10+F10 | H10: =IF(G10<0,"Économie","Perte") | I10: Réduction risques trajet
A11: Scénario F | B11: Système de surveillance IA | C11: Caméras analogiques | D11: Détection IA incendie | E11: -2000000 | F11: 3500000 | G11: =E11+F11 | H11: =IF(G11<0,"Économie","Perte") | I11: Réaction 30s vs 5 min
A12: Scénario G | B12: Programme bien-être | C12: 0 activités | D12: Sport + relaxation hebdo | E12: -300000 | F12: 1500000 | G12: =E12+F12 | H12: =IF(G12<0,"Économie","Perte") | I12: Baisse absentéisme -15%
G13: =IF(A13="","",E13+F13) | H13: =IF(A13="","",IF(G13<0,"Économie","Perte"))
G14: =IF(A14="","",E14+F14) | H14: =IF(A14="","",IF(G14<0,"Économie","Perte"))
G15: =IF(A15="","",E15+F15) | H15: =IF(A15="","",IF(G15<0,"Économie","Perte"))
G16: =IF(A16="","",E16+F16) | H16: =IF(A16="","",IF(G16<0,"Économie","Perte"))
G17: =IF(A17="","",E17+F17) | H17: =IF(A17="","",IF(G17<0,"Économie","Perte"))
G18: =IF(A18="","",E18+F18) | H18: =IF(A18="","",IF(G18<0,"Économie","Perte"))
G19: =IF(A19="","",E19+F19) | H19: =IF(A19="","",IF(G19<0,"Économie","Perte"))
G20: =IF(A20="","",E20+F20) | H20: =IF(A20="","",IF(G20<0,"Économie","Perte"))
G21: =IF(A21="","",E21+F21) | H21: =IF(A21="","",IF(G21<0,"Économie","Perte"))
G22: =IF(A22="","",E22+F22) | H22: =IF(A22="","",IF(G22<0,"Économie","Perte"))
G23: =IF(A23="","",E23+F23) | H23: =IF(A23="","",IF(G23<0,"Économie","Perte"))
G24: =IF(A24="","",E24+F24) | H24: =IF(A24="","",IF(G24<0,"Économie","Perte"))
... G115: =IF(A115="","",E115+F115) | H115: =IF(A115="","",IF(G115<0,"Économie","Perte"))

Sheet F19 - 17-TdB Consolidé SST
A2: DOMAINE 27 — 17-TABLEAU DE BORD CONSOLIDÉ SANTÉ SÉCURITÉ
A3: TABLEAU DYNAMIQUE — Vue consolidée trimestrielle
A5: Indicateur | B5: Janvier | C5: Février | D5: Mars | E5: T1 | F5: Avril | G5: Mai | H5: Juin | I5: T2 | J5: Juillet | K5: Août | L5: Septembre | M5: T3 | N5: Octobre | O5: Novembre | P5: Décembre | Q5: T4 | R5: Total Annuel
A6: Nb Accidents | B6: 1 | C6: 2 | D6: 3 | F6: 2 | G6: 1 | H6: 1 | I6: =SUM(F6:H6) | J6: 0 | K6: 0 | L6: 0 | M6: =SUM(J6:L6) | N6: 0 | O6: 0 | P6: 0 | Q6: =SUM(N6:P6) | R6: =E6+I6+M6+Q6
A7: Jours d'Arrêt | B7: 5 | C7: 4 | D7: 21 | F7: 25 | G7: 3 | H7: 4 | I7: =SUM(F7:H7) | J7: 0 | K7: 0 | L7: 0 | M7: =SUM(J7:L7) | N7: 0 | O7: 0 | P7: 0 | Q7: =SUM(N7:P7) | R7: =E7+I7+M7+Q7
